05/02/2018 00:00:00;0002;Server@node2;Svr;Log;Log opened
05/02/2018 00:00:00;0002;Server@node2;Svr;Server@node2;pbs_version=14.0.1
05/02/2018 00:00:00;0002;Server@node2;Svr;Server@node2;pbs_build=mach=N/A:security=N/A:configure_args=N/A
05/02/2018 00:00:00;0002;Server@node2;Svr;Server@node2;hostname=node2.supernodexp.hpc;pbs_leaf_name=N/A;pbs_mom_node_name=N/A
05/02/2018 00:00:00;0002;Server@node2;Svr;Server@node2;ipv4 interface lo: localhost localhost.localdomain localhost4 localhost4.localdomain4 
05/02/2018 00:00:00;0002;Server@node2;Svr;Server@node2;ipv4 interface br0: node2.supernodexp.hpc node2 supernodexp-cn02 
05/02/2018 00:00:00;0002;Server@node2;Svr;Server@node2;ipv4 interface ib0: node2.supernodexp.hpc 
05/02/2018 00:00:00;0002;Server@node2;Svr;Server@node2;ipv4 interface virbr0: node2.supernodexp.hpc 
05/02/2018 00:00:00;0002;Server@node2;Svr;Server@node2;ipv4 interface docker0: node2.supernodexp.hpc 
05/02/2018 00:00:00;0002;Server@node2;Svr;Server@node2;ipv6 interface lo: localhost localhost.localdomain localhost6 localhost6.localdomain6 
05/02/2018 00:00:00;0002;Server@node2;Svr;Server@node2;ipv6 interface eno49: node2.supernodexp.hpc 
05/02/2018 00:00:00;0002;Server@node2;Svr;Server@node2;ipv6 interface br0: node2.supernodexp.hpc 
05/02/2018 00:00:00;0002;Server@node2;Svr;Server@node2;ipv6 interface ib0: node2.supernodexp.hpc 
05/02/2018 00:00:00;0002;Server@node2;Svr;Server@node2;ipv6 interface veth1pl8819: node2.supernodexp.hpc 
05/02/2018 00:00:00;0002;Server@node2;Svr;Act;Account file /var/spool/pbs/server_priv/accounting/20180502 opened
05/02/2018 00:08:33;0040;Server@node2;Svr;node2.supernodexp.hpc;Scheduler sent command 3
05/02/2018 00:08:33;0040;Server@node2;Svr;node2.supernodexp.hpc;Scheduler sent command 0
05/02/2018 00:08:33;0100;Server@node2;Req;;Type 21 request received from Scheduler@node2.supernodexp.hpc, sock=16
05/02/2018 00:08:33;0100;Server@node2;Req;;Type 81 request received from Scheduler@node2.supernodexp.hpc, sock=16
05/02/2018 00:08:33;0100;Server@node2;Req;;Type 71 request received from Scheduler@node2.supernodexp.hpc, sock=16
05/02/2018 00:08:33;0100;Server@node2;Req;;Type 58 request received from Scheduler@node2.supernodexp.hpc, sock=16
05/02/2018 00:08:33;0100;Server@node2;Req;;Type 20 request received from Scheduler@node2.supernodexp.hpc, sock=16
05/02/2018 00:08:33;0100;Server@node2;Req;;Type 51 request received from Scheduler@node2.supernodexp.hpc, sock=16
05/02/2018 00:18:33;0040;Server@node2;Svr;node2.supernodexp.hpc;Scheduler sent command 3
05/02/2018 00:18:33;0040;Server@node2;Svr;node2.supernodexp.hpc;Scheduler sent command 0
05/02/2018 00:18:33;0100;Server@node2;Req;;Type 21 request received from Scheduler@node2.supernodexp.hpc, sock=16
05/02/2018 00:18:33;0100;Server@node2;Req;;Type 81 request received from Scheduler@node2.supernodexp.hpc, sock=16
05/02/2018 00:18:33;0100;Server@node2;Req;;Type 71 request received from Scheduler@node2.supernodexp.hpc, sock=16
05/02/2018 00:18:33;0100;Server@node2;Req;;Type 58 request received from Scheduler@node2.supernodexp.hpc, sock=16
05/02/2018 00:18:33;0100;Server@node2;Req;;Type 20 request received from Scheduler@node2.supernodexp.hpc, sock=16
05/02/2018 00:18:33;0100;Server@node2;Req;;Type 51 request received from Scheduler@node2.supernodexp.hpc, sock=16
05/02/2018 00:28:33;0040;Server@node2;Svr;node2.supernodexp.hpc;Scheduler sent command 3
05/02/2018 00:28:33;0040;Server@node2;Svr;node2.supernodexp.hpc;Scheduler sent command 0
05/02/2018 00:28:33;0100;Server@node2;Req;;Type 21 request received from Scheduler@node2.supernodexp.hpc, sock=16
05/02/2018 00:28:33;0100;Server@node2;Req;;Type 81 request received from Scheduler@node2.supernodexp.hpc, sock=16
05/02/2018 00:28:33;0100;Server@node2;Req;;Type 71 request received from Scheduler@node2.supernodexp.hpc, sock=16
05/02/2018 00:28:33;0100;Server@node2;Req;;Type 58 request received from Scheduler@node2.supernodexp.hpc, sock=16
05/02/2018 00:28:34;0100;Server@node2;Req;;Type 20 request received from Scheduler@node2.supernodexp.hpc, sock=16
05/02/2018 00:28:34;0100;Server@node2;Req;;Type 51 request received from Scheduler@node2.supernodexp.hpc, sock=16
05/02/2018 00:38:33;0040;Server@node2;Svr;node2.supernodexp.hpc;Scheduler sent command 3
05/02/2018 00:38:33;0040;Server@node2;Svr;node2.supernodexp.hpc;Scheduler sent command 0
05/02/2018 00:38:33;0100;Server@node2;Req;;Type 21 request received from Scheduler@node2.supernodexp.hpc, sock=16
05/02/2018 00:38:33;0100;Server@node2;Req;;Type 81 request received from Scheduler@node2.supernodexp.hpc, sock=16
05/02/2018 00:38:33;0100;Server@node2;Req;;Type 71 request received from Scheduler@node2.supernodexp.hpc, sock=16
05/02/2018 00:38:33;0100;Server@node2;Req;;Type 58 request received from Scheduler@node2.supernodexp.hpc, sock=16
05/02/2018 00:38:33;0100;Server@node2;Req;;Type 20 request received from Scheduler@node2.supernodexp.hpc, sock=16
05/02/2018 00:38:33;0100;Server@node2;Req;;Type 51 request received from Scheduler@node2.supernodexp.hpc, sock=16
05/02/2018 00:48:33;0040;Server@node2;Svr;node2.supernodexp.hpc;Scheduler sent command 3
05/02/2018 00:48:33;0040;Server@node2;Svr;node2.supernodexp.hpc;Scheduler sent command 0
05/02/2018 00:48:33;0100;Server@node2;Req;;Type 21 request received from Scheduler@node2.supernodexp.hpc, sock=16
05/02/2018 00:48:33;0100;Server@node2;Req;;Type 81 request received from Scheduler@node2.supernodexp.hpc, sock=16
05/02/2018 00:48:33;0100;Server@node2;Req;;Type 71 request received from Scheduler@node2.supernodexp.hpc, sock=16
05/02/2018 00:48:33;0100;Server@node2;Req;;Type 58 request received from Scheduler@node2.supernodexp.hpc, sock=16
05/02/2018 00:48:33;0100;Server@node2;Req;;Type 20 request received from Scheduler@node2.supernodexp.hpc, sock=16
05/02/2018 00:48:33;0100;Server@node2;Req;;Type 51 request received from Scheduler@node2.supernodexp.hpc, sock=16
05/02/2018 00:58:33;0040;Server@node2;Svr;node2.supernodexp.hpc;Scheduler sent command 3
05/02/2018 00:58:33;0040;Server@node2;Svr;node2.supernodexp.hpc;Scheduler sent command 0
05/02/2018 00:58:33;0100;Server@node2;Req;;Type 21 request received from Scheduler@node2.supernodexp.hpc, sock=16
05/02/2018 00:58:33;0100;Server@node2;Req;;Type 81 request received from Scheduler@node2.supernodexp.hpc, sock=16
05/02/2018 00:58:33;0100;Server@node2;Req;;Type 71 request received from Scheduler@node2.supernodexp.hpc, sock=16
05/02/2018 00:58:33;0100;Server@node2;Req;;Type 58 request received from Scheduler@node2.supernodexp.hpc, sock=16
05/02/2018 00:58:33;0100;Server@node2;Req;;Type 20 request received from Scheduler@node2.supernodexp.hpc, sock=16
05/02/2018 00:58:33;0100;Server@node2;Req;;Type 51 request received from Scheduler@node2.supernodexp.hpc, sock=16
05/02/2018 01:08:33;0040;Server@node2;Svr;node2.supernodexp.hpc;Scheduler sent command 3
05/02/2018 01:08:33;0040;Server@node2;Svr;node2.supernodexp.hpc;Scheduler sent command 0
05/02/2018 01:08:33;0100;Server@node2;Req;;Type 21 request received from Scheduler@node2.supernodexp.hpc, sock=16
05/02/2018 01:08:33;0100;Server@node2;Req;;Type 81 request received from Scheduler@node2.supernodexp.hpc, sock=16
05/02/2018 01:08:33;0100;Server@node2;Req;;Type 71 request received from Scheduler@node2.supernodexp.hpc, sock=16
05/02/2018 01:08:33;0100;Server@node2;Req;;Type 58 request received from Scheduler@node2.supernodexp.hpc, sock=16
05/02/2018 01:08:33;0100;Server@node2;Req;;Type 20 request received from Scheduler@node2.supernodexp.hpc, sock=16
05/02/2018 01:08:33;0100;Server@node2;Req;;Type 51 request received from Scheduler@node2.supernodexp.hpc, sock=16
05/02/2018 01:18:33;0040;Server@node2;Svr;node2.supernodexp.hpc;Scheduler sent command 3
05/02/2018 01:18:33;0040;Server@node2;Svr;node2.supernodexp.hpc;Scheduler sent command 0
05/02/2018 01:18:33;0100;Server@node2;Req;;Type 21 request received from Scheduler@node2.supernodexp.hpc, sock=16
05/02/2018 01:18:33;0100;Server@node2;Req;;Type 81 request received from Scheduler@node2.supernodexp.hpc, sock=16
05/02/2018 01:18:33;0100;Server@node2;Req;;Type 71 request received from Scheduler@node2.supernodexp.hpc, sock=16
05/02/2018 01:18:33;0100;Server@node2;Req;;Type 58 request received from Scheduler@node2.supernodexp.hpc, sock=16
05/02/2018 01:18:33;0100;Server@node2;Req;;Type 20 request received from Scheduler@node2.supernodexp.hpc, sock=16
05/02/2018 01:18:33;0100;Server@node2;Req;;Type 51 request received from Scheduler@node2.supernodexp.hpc, sock=16
05/02/2018 01:28:33;0040;Server@node2;Svr;node2.supernodexp.hpc;Scheduler sent command 3
05/02/2018 01:28:33;0040;Server@node2;Svr;node2.supernodexp.hpc;Scheduler sent command 0
05/02/2018 01:28:33;0100;Server@node2;Req;;Type 21 request received from Scheduler@node2.supernodexp.hpc, sock=16
05/02/2018 01:28:33;0100;Server@node2;Req;;Type 81 request received from Scheduler@node2.supernodexp.hpc, sock=16
05/02/2018 01:28:33;0100;Server@node2;Req;;Type 71 request received from Scheduler@node2.supernodexp.hpc, sock=16
05/02/2018 01:28:33;0100;Server@node2;Req;;Type 58 request received from Scheduler@node2.supernodexp.hpc, sock=16
05/02/2018 01:28:33;0100;Server@node2;Req;;Type 20 request received from Scheduler@node2.supernodexp.hpc, sock=16
05/02/2018 01:28:33;0100;Server@node2;Req;;Type 51 request received from Scheduler@node2.supernodexp.hpc, sock=16
05/02/2018 01:38:33;0040;Server@node2;Svr;node2.supernodexp.hpc;Scheduler sent command 3
05/02/2018 01:38:33;0040;Server@node2;Svr;node2.supernodexp.hpc;Scheduler sent command 0
05/02/2018 01:38:33;0100;Server@node2;Req;;Type 21 request received from Scheduler@node2.supernodexp.hpc, sock=16
05/02/2018 01:38:33;0100;Server@node2;Req;;Type 81 request received from Scheduler@node2.supernodexp.hpc, sock=16
05/02/2018 01:38:33;0100;Server@node2;Req;;Type 71 request received from Scheduler@node2.supernodexp.hpc, sock=16
05/02/2018 01:38:33;0100;Server@node2;Req;;Type 58 request received from Scheduler@node2.supernodexp.hpc, sock=16
05/02/2018 01:38:33;0100;Server@node2;Req;;Type 20 request received from Scheduler@node2.supernodexp.hpc, sock=16
05/02/2018 01:38:33;0100;Server@node2;Req;;Type 51 request received from Scheduler@node2.supernodexp.hpc, sock=16
05/02/2018 01:48:33;0040;Server@node2;Svr;node2.supernodexp.hpc;Scheduler sent command 3
05/02/2018 01:48:33;0040;Server@node2;Svr;node2.supernodexp.hpc;Scheduler sent command 0
05/02/2018 01:48:33;0100;Server@node2;Req;;Type 21 request received from Scheduler@node2.supernodexp.hpc, sock=16
05/02/2018 01:48:33;0100;Server@node2;Req;;Type 81 request received from Scheduler@node2.supernodexp.hpc, sock=16
05/02/2018 01:48:33;0100;Server@node2;Req;;Type 71 request received from Scheduler@node2.supernodexp.hpc, sock=16
05/02/2018 01:48:33;0100;Server@node2;Req;;Type 58 request received from Scheduler@node2.supernodexp.hpc, sock=16
05/02/2018 01:48:33;0100;Server@node2;Req;;Type 20 request received from Scheduler@node2.supernodexp.hpc, sock=16
05/02/2018 01:48:33;0100;Server@node2;Req;;Type 51 request received from Scheduler@node2.supernodexp.hpc, sock=16
05/02/2018 01:58:33;0040;Server@node2;Svr;node2.supernodexp.hpc;Scheduler sent command 3
05/02/2018 01:58:33;0040;Server@node2;Svr;node2.supernodexp.hpc;Scheduler sent command 0
05/02/2018 01:58:33;0100;Server@node2;Req;;Type 21 request received from Scheduler@node2.supernodexp.hpc, sock=16
05/02/2018 01:58:33;0100;Server@node2;Req;;Type 81 request received from Scheduler@node2.supernodexp.hpc, sock=16
05/02/2018 01:58:33;0100;Server@node2;Req;;Type 71 request received from Scheduler@node2.supernodexp.hpc, sock=16
05/02/2018 01:58:33;0100;Server@node2;Req;;Type 58 request received from Scheduler@node2.supernodexp.hpc, sock=16
05/02/2018 01:58:33;0100;Server@node2;Req;;Type 20 request received from Scheduler@node2.supernodexp.hpc, sock=16
05/02/2018 01:58:33;0100;Server@node2;Req;;Type 51 request received from Scheduler@node2.supernodexp.hpc, sock=16
05/02/2018 02:08:33;0040;Server@node2;Svr;node2.supernodexp.hpc;Scheduler sent command 3
05/02/2018 02:08:33;0040;Server@node2;Svr;node2.supernodexp.hpc;Scheduler sent command 0
05/02/2018 02:08:33;0100;Server@node2;Req;;Type 21 request received from Scheduler@node2.supernodexp.hpc, sock=16
05/02/2018 02:08:33;0100;Server@node2;Req;;Type 81 request received from Scheduler@node2.supernodexp.hpc, sock=16
05/02/2018 02:08:33;0100;Server@node2;Req;;Type 71 request received from Scheduler@node2.supernodexp.hpc, sock=16
05/02/2018 02:08:33;0100;Server@node2;Req;;Type 58 request received from Scheduler@node2.supernodexp.hpc, sock=16
05/02/2018 02:08:33;0100;Server@node2;Req;;Type 20 request received from Scheduler@node2.supernodexp.hpc, sock=16
05/02/2018 02:08:33;0100;Server@node2;Req;;Type 51 request received from Scheduler@node2.supernodexp.hpc, sock=16
05/02/2018 02:18:33;0040;Server@node2;Svr;node2.supernodexp.hpc;Scheduler sent command 3
05/02/2018 02:18:33;0040;Server@node2;Svr;node2.supernodexp.hpc;Scheduler sent command 0
05/02/2018 02:18:33;0100;Server@node2;Req;;Type 21 request received from Scheduler@node2.supernodexp.hpc, sock=16
05/02/2018 02:18:33;0100;Server@node2;Req;;Type 81 request received from Scheduler@node2.supernodexp.hpc, sock=16
05/02/2018 02:18:33;0100;Server@node2;Req;;Type 71 request received from Scheduler@node2.supernodexp.hpc, sock=16
05/02/2018 02:18:33;0100;Server@node2;Req;;Type 58 request received from Scheduler@node2.supernodexp.hpc, sock=16
05/02/2018 02:18:33;0100;Server@node2;Req;;Type 20 request received from Scheduler@node2.supernodexp.hpc, sock=16
05/02/2018 02:18:33;0100;Server@node2;Req;;Type 51 request received from Scheduler@node2.supernodexp.hpc, sock=16
05/02/2018 02:28:33;0040;Server@node2;Svr;node2.supernodexp.hpc;Scheduler sent command 3
05/02/2018 02:28:33;0040;Server@node2;Svr;node2.supernodexp.hpc;Scheduler sent command 0
05/02/2018 02:28:33;0100;Server@node2;Req;;Type 21 request received from Scheduler@node2.supernodexp.hpc, sock=16
05/02/2018 02:28:33;0100;Server@node2;Req;;Type 81 request received from Scheduler@node2.supernodexp.hpc, sock=16
05/02/2018 02:28:33;0100;Server@node2;Req;;Type 71 request received from Scheduler@node2.supernodexp.hpc, sock=16
05/02/2018 02:28:33;0100;Server@node2;Req;;Type 58 request received from Scheduler@node2.supernodexp.hpc, sock=16
05/02/2018 02:28:33;0100;Server@node2;Req;;Type 20 request received from Scheduler@node2.supernodexp.hpc, sock=16
05/02/2018 02:28:33;0100;Server@node2;Req;;Type 51 request received from Scheduler@node2.supernodexp.hpc, sock=16
05/02/2018 02:38:33;0040;Server@node2;Svr;node2.supernodexp.hpc;Scheduler sent command 3
05/02/2018 02:38:33;0040;Server@node2;Svr;node2.supernodexp.hpc;Scheduler sent command 0
05/02/2018 02:38:33;0100;Server@node2;Req;;Type 21 request received from Scheduler@node2.supernodexp.hpc, sock=16
05/02/2018 02:38:33;0100;Server@node2;Req;;Type 81 request received from Scheduler@node2.supernodexp.hpc, sock=16
05/02/2018 02:38:33;0100;Server@node2;Req;;Type 71 request received from Scheduler@node2.supernodexp.hpc, sock=16
05/02/2018 02:38:33;0100;Server@node2;Req;;Type 58 request received from Scheduler@node2.supernodexp.hpc, sock=16
05/02/2018 02:38:33;0100;Server@node2;Req;;Type 20 request received from Scheduler@node2.supernodexp.hpc, sock=16
05/02/2018 02:38:33;0100;Server@node2;Req;;Type 51 request received from Scheduler@node2.supernodexp.hpc, sock=16
05/02/2018 02:48:33;0040;Server@node2;Svr;node2.supernodexp.hpc;Scheduler sent command 3
05/02/2018 02:48:33;0040;Server@node2;Svr;node2.supernodexp.hpc;Scheduler sent command 0
05/02/2018 02:48:33;0100;Server@node2;Req;;Type 21 request received from Scheduler@node2.supernodexp.hpc, sock=16
05/02/2018 02:48:33;0100;Server@node2;Req;;Type 81 request received from Scheduler@node2.supernodexp.hpc, sock=16
05/02/2018 02:48:33;0100;Server@node2;Req;;Type 71 request received from Scheduler@node2.supernodexp.hpc, sock=16
05/02/2018 02:48:33;0100;Server@node2;Req;;Type 58 request received from Scheduler@node2.supernodexp.hpc, sock=16
05/02/2018 02:48:33;0100;Server@node2;Req;;Type 20 request received from Scheduler@node2.supernodexp.hpc, sock=16
05/02/2018 02:48:33;0100;Server@node2;Req;;Type 51 request received from Scheduler@node2.supernodexp.hpc, sock=16
05/02/2018 02:58:33;0040;Server@node2;Svr;node2.supernodexp.hpc;Scheduler sent command 3
05/02/2018 02:58:33;0040;Server@node2;Svr;node2.supernodexp.hpc;Scheduler sent command 0
05/02/2018 02:58:33;0100;Server@node2;Req;;Type 21 request received from Scheduler@node2.supernodexp.hpc, sock=16
05/02/2018 02:58:33;0100;Server@node2;Req;;Type 81 request received from Scheduler@node2.supernodexp.hpc, sock=16
05/02/2018 02:58:33;0100;Server@node2;Req;;Type 71 request received from Scheduler@node2.supernodexp.hpc, sock=16
05/02/2018 02:58:33;0100;Server@node2;Req;;Type 58 request received from Scheduler@node2.supernodexp.hpc, sock=16
05/02/2018 02:58:33;0100;Server@node2;Req;;Type 20 request received from Scheduler@node2.supernodexp.hpc, sock=16
05/02/2018 02:58:33;0100;Server@node2;Req;;Type 51 request received from Scheduler@node2.supernodexp.hpc, sock=16
05/02/2018 03:08:33;0040;Server@node2;Svr;node2.supernodexp.hpc;Scheduler sent command 3
05/02/2018 03:08:33;0040;Server@node2;Svr;node2.supernodexp.hpc;Scheduler sent command 0
05/02/2018 03:08:33;0100;Server@node2;Req;;Type 21 request received from Scheduler@node2.supernodexp.hpc, sock=16
05/02/2018 03:08:33;0100;Server@node2;Req;;Type 81 request received from Scheduler@node2.supernodexp.hpc, sock=16
05/02/2018 03:08:33;0100;Server@node2;Req;;Type 71 request received from Scheduler@node2.supernodexp.hpc, sock=16
05/02/2018 03:08:33;0100;Server@node2;Req;;Type 58 request received from Scheduler@node2.supernodexp.hpc, sock=16
05/02/2018 03:08:33;0100;Server@node2;Req;;Type 20 request received from Scheduler@node2.supernodexp.hpc, sock=16
05/02/2018 03:08:33;0100;Server@node2;Req;;Type 51 request received from Scheduler@node2.supernodexp.hpc, sock=16
05/02/2018 03:18:33;0040;Server@node2;Svr;node2.supernodexp.hpc;Scheduler sent command 3
05/02/2018 03:18:33;0040;Server@node2;Svr;node2.supernodexp.hpc;Scheduler sent command 0
05/02/2018 03:18:33;0100;Server@node2;Req;;Type 21 request received from Scheduler@node2.supernodexp.hpc, sock=16
05/02/2018 03:18:33;0100;Server@node2;Req;;Type 81 request received from Scheduler@node2.supernodexp.hpc, sock=16
05/02/2018 03:18:33;0100;Server@node2;Req;;Type 71 request received from Scheduler@node2.supernodexp.hpc, sock=16
05/02/2018 03:18:33;0100;Server@node2;Req;;Type 58 request received from Scheduler@node2.supernodexp.hpc, sock=16
05/02/2018 03:18:33;0100;Server@node2;Req;;Type 20 request received from Scheduler@node2.supernodexp.hpc, sock=16
05/02/2018 03:18:33;0100;Server@node2;Req;;Type 51 request received from Scheduler@node2.supernodexp.hpc, sock=16
05/02/2018 03:28:33;0040;Server@node2;Svr;node2.supernodexp.hpc;Scheduler sent command 3
05/02/2018 03:28:33;0040;Server@node2;Svr;node2.supernodexp.hpc;Scheduler sent command 0
05/02/2018 03:28:33;0100;Server@node2;Req;;Type 21 request received from Scheduler@node2.supernodexp.hpc, sock=16
05/02/2018 03:28:33;0100;Server@node2;Req;;Type 81 request received from Scheduler@node2.supernodexp.hpc, sock=16
05/02/2018 03:28:33;0100;Server@node2;Req;;Type 71 request received from Scheduler@node2.supernodexp.hpc, sock=16
05/02/2018 03:28:33;0100;Server@node2;Req;;Type 58 request received from Scheduler@node2.supernodexp.hpc, sock=16
05/02/2018 03:28:33;0100;Server@node2;Req;;Type 20 request received from Scheduler@node2.supernodexp.hpc, sock=16
05/02/2018 03:28:33;0100;Server@node2;Req;;Type 51 request received from Scheduler@node2.supernodexp.hpc, sock=16
05/02/2018 03:38:33;0040;Server@node2;Svr;node2.supernodexp.hpc;Scheduler sent command 3
05/02/2018 03:38:33;0040;Server@node2;Svr;node2.supernodexp.hpc;Scheduler sent command 0
05/02/2018 03:38:33;0100;Server@node2;Req;;Type 21 request received from Scheduler@node2.supernodexp.hpc, sock=16
05/02/2018 03:38:33;0100;Server@node2;Req;;Type 81 request received from Scheduler@node2.supernodexp.hpc, sock=16
05/02/2018 03:38:33;0100;Server@node2;Req;;Type 71 request received from Scheduler@node2.supernodexp.hpc, sock=16
05/02/2018 03:38:33;0100;Server@node2;Req;;Type 58 request received from Scheduler@node2.supernodexp.hpc, sock=16
05/02/2018 03:38:34;0100;Server@node2;Req;;Type 20 request received from Scheduler@node2.supernodexp.hpc, sock=16
05/02/2018 03:38:34;0100;Server@node2;Req;;Type 51 request received from Scheduler@node2.supernodexp.hpc, sock=16
05/02/2018 03:48:33;0040;Server@node2;Svr;node2.supernodexp.hpc;Scheduler sent command 3
05/02/2018 03:48:33;0040;Server@node2;Svr;node2.supernodexp.hpc;Scheduler sent command 0
05/02/2018 03:48:33;0100;Server@node2;Req;;Type 21 request received from Scheduler@node2.supernodexp.hpc, sock=16
05/02/2018 03:48:33;0100;Server@node2;Req;;Type 81 request received from Scheduler@node2.supernodexp.hpc, sock=16
05/02/2018 03:48:33;0100;Server@node2;Req;;Type 71 request received from Scheduler@node2.supernodexp.hpc, sock=16
05/02/2018 03:48:33;0100;Server@node2;Req;;Type 58 request received from Scheduler@node2.supernodexp.hpc, sock=16
05/02/2018 03:48:33;0100;Server@node2;Req;;Type 20 request received from Scheduler@node2.supernodexp.hpc, sock=16
05/02/2018 03:48:33;0100;Server@node2;Req;;Type 51 request received from Scheduler@node2.supernodexp.hpc, sock=16
05/02/2018 03:58:33;0040;Server@node2;Svr;node2.supernodexp.hpc;Scheduler sent command 3
05/02/2018 03:58:33;0040;Server@node2;Svr;node2.supernodexp.hpc;Scheduler sent command 0
05/02/2018 03:58:33;0100;Server@node2;Req;;Type 21 request received from Scheduler@node2.supernodexp.hpc, sock=16
05/02/2018 03:58:33;0100;Server@node2;Req;;Type 81 request received from Scheduler@node2.supernodexp.hpc, sock=16
05/02/2018 03:58:33;0100;Server@node2;Req;;Type 71 request received from Scheduler@node2.supernodexp.hpc, sock=16
05/02/2018 03:58:33;0100;Server@node2;Req;;Type 58 request received from Scheduler@node2.supernodexp.hpc, sock=16
05/02/2018 03:58:33;0100;Server@node2;Req;;Type 20 request received from Scheduler@node2.supernodexp.hpc, sock=16
05/02/2018 03:58:33;0100;Server@node2;Req;;Type 51 request received from Scheduler@node2.supernodexp.hpc, sock=16
05/02/2018 04:08:33;0040;Server@node2;Svr;node2.supernodexp.hpc;Scheduler sent command 3
05/02/2018 04:08:33;0040;Server@node2;Svr;node2.supernodexp.hpc;Scheduler sent command 0
05/02/2018 04:08:33;0100;Server@node2;Req;;Type 21 request received from Scheduler@node2.supernodexp.hpc, sock=16
05/02/2018 04:08:33;0100;Server@node2;Req;;Type 81 request received from Scheduler@node2.supernodexp.hpc, sock=16
05/02/2018 04:08:33;0100;Server@node2;Req;;Type 71 request received from Scheduler@node2.supernodexp.hpc, sock=16
05/02/2018 04:08:33;0100;Server@node2;Req;;Type 58 request received from Scheduler@node2.supernodexp.hpc, sock=16
05/02/2018 04:08:33;0100;Server@node2;Req;;Type 20 request received from Scheduler@node2.supernodexp.hpc, sock=16
05/02/2018 04:08:33;0100;Server@node2;Req;;Type 51 request received from Scheduler@node2.supernodexp.hpc, sock=16
05/02/2018 04:18:33;0040;Server@node2;Svr;node2.supernodexp.hpc;Scheduler sent command 3
05/02/2018 04:18:33;0040;Server@node2;Svr;node2.supernodexp.hpc;Scheduler sent command 0
05/02/2018 04:18:33;0100;Server@node2;Req;;Type 21 request received from Scheduler@node2.supernodexp.hpc, sock=16
05/02/2018 04:18:33;0100;Server@node2;Req;;Type 81 request received from Scheduler@node2.supernodexp.hpc, sock=16
05/02/2018 04:18:33;0100;Server@node2;Req;;Type 71 request received from Scheduler@node2.supernodexp.hpc, sock=16
05/02/2018 04:18:33;0100;Server@node2;Req;;Type 58 request received from Scheduler@node2.supernodexp.hpc, sock=16
05/02/2018 04:18:33;0100;Server@node2;Req;;Type 20 request received from Scheduler@node2.supernodexp.hpc, sock=16
05/02/2018 04:18:33;0100;Server@node2;Req;;Type 51 request received from Scheduler@node2.supernodexp.hpc, sock=16
05/02/2018 04:28:33;0040;Server@node2;Svr;node2.supernodexp.hpc;Scheduler sent command 3
05/02/2018 04:28:33;0040;Server@node2;Svr;node2.supernodexp.hpc;Scheduler sent command 0
05/02/2018 04:28:33;0100;Server@node2;Req;;Type 21 request received from Scheduler@node2.supernodexp.hpc, sock=16
05/02/2018 04:28:33;0100;Server@node2;Req;;Type 81 request received from Scheduler@node2.supernodexp.hpc, sock=16
05/02/2018 04:28:33;0100;Server@node2;Req;;Type 71 request received from Scheduler@node2.supernodexp.hpc, sock=16
05/02/2018 04:28:33;0100;Server@node2;Req;;Type 58 request received from Scheduler@node2.supernodexp.hpc, sock=16
05/02/2018 04:28:33;0100;Server@node2;Req;;Type 20 request received from Scheduler@node2.supernodexp.hpc, sock=16
05/02/2018 04:28:33;0100;Server@node2;Req;;Type 51 request received from Scheduler@node2.supernodexp.hpc, sock=16
05/02/2018 04:38:33;0040;Server@node2;Svr;node2.supernodexp.hpc;Scheduler sent command 3
05/02/2018 04:38:33;0040;Server@node2;Svr;node2.supernodexp.hpc;Scheduler sent command 0
05/02/2018 04:38:33;0100;Server@node2;Req;;Type 21 request received from Scheduler@node2.supernodexp.hpc, sock=16
05/02/2018 04:38:33;0100;Server@node2;Req;;Type 81 request received from Scheduler@node2.supernodexp.hpc, sock=16
05/02/2018 04:38:33;0100;Server@node2;Req;;Type 71 request received from Scheduler@node2.supernodexp.hpc, sock=16
05/02/2018 04:38:33;0100;Server@node2;Req;;Type 58 request received from Scheduler@node2.supernodexp.hpc, sock=16
05/02/2018 04:38:33;0100;Server@node2;Req;;Type 20 request received from Scheduler@node2.supernodexp.hpc, sock=16
05/02/2018 04:38:33;0100;Server@node2;Req;;Type 51 request received from Scheduler@node2.supernodexp.hpc, sock=16
05/02/2018 04:48:33;0040;Server@node2;Svr;node2.supernodexp.hpc;Scheduler sent command 3
05/02/2018 04:48:33;0040;Server@node2;Svr;node2.supernodexp.hpc;Scheduler sent command 0
05/02/2018 04:48:33;0100;Server@node2;Req;;Type 21 request received from Scheduler@node2.supernodexp.hpc, sock=16
05/02/2018 04:48:33;0100;Server@node2;Req;;Type 81 request received from Scheduler@node2.supernodexp.hpc, sock=16
05/02/2018 04:48:33;0100;Server@node2;Req;;Type 71 request received from Scheduler@node2.supernodexp.hpc, sock=16
05/02/2018 04:48:33;0100;Server@node2;Req;;Type 58 request received from Scheduler@node2.supernodexp.hpc, sock=16
05/02/2018 04:48:33;0100;Server@node2;Req;;Type 20 request received from Scheduler@node2.supernodexp.hpc, sock=16
05/02/2018 04:48:33;0100;Server@node2;Req;;Type 51 request received from Scheduler@node2.supernodexp.hpc, sock=16
05/02/2018 04:58:33;0040;Server@node2;Svr;node2.supernodexp.hpc;Scheduler sent command 3
05/02/2018 04:58:33;0040;Server@node2;Svr;node2.supernodexp.hpc;Scheduler sent command 0
05/02/2018 04:58:33;0100;Server@node2;Req;;Type 21 request received from Scheduler@node2.supernodexp.hpc, sock=16
05/02/2018 04:58:33;0100;Server@node2;Req;;Type 81 request received from Scheduler@node2.supernodexp.hpc, sock=16
05/02/2018 04:58:33;0100;Server@node2;Req;;Type 71 request received from Scheduler@node2.supernodexp.hpc, sock=16
05/02/2018 04:58:33;0100;Server@node2;Req;;Type 58 request received from Scheduler@node2.supernodexp.hpc, sock=16
05/02/2018 04:58:33;0100;Server@node2;Req;;Type 20 request received from Scheduler@node2.supernodexp.hpc, sock=16
05/02/2018 04:58:33;0100;Server@node2;Req;;Type 51 request received from Scheduler@node2.supernodexp.hpc, sock=16
05/02/2018 05:08:33;0040;Server@node2;Svr;node2.supernodexp.hpc;Scheduler sent command 3
05/02/2018 05:08:33;0040;Server@node2;Svr;node2.supernodexp.hpc;Scheduler sent command 0
05/02/2018 05:08:33;0100;Server@node2;Req;;Type 21 request received from Scheduler@node2.supernodexp.hpc, sock=16
05/02/2018 05:08:33;0100;Server@node2;Req;;Type 81 request received from Scheduler@node2.supernodexp.hpc, sock=16
05/02/2018 05:08:33;0100;Server@node2;Req;;Type 71 request received from Scheduler@node2.supernodexp.hpc, sock=16
05/02/2018 05:08:33;0100;Server@node2;Req;;Type 58 request received from Scheduler@node2.supernodexp.hpc, sock=16
05/02/2018 05:08:33;0100;Server@node2;Req;;Type 20 request received from Scheduler@node2.supernodexp.hpc, sock=16
05/02/2018 05:08:33;0100;Server@node2;Req;;Type 51 request received from Scheduler@node2.supernodexp.hpc, sock=16
05/02/2018 05:18:33;0040;Server@node2;Svr;node2.supernodexp.hpc;Scheduler sent command 3
05/02/2018 05:18:33;0040;Server@node2;Svr;node2.supernodexp.hpc;Scheduler sent command 0
05/02/2018 05:18:33;0100;Server@node2;Req;;Type 21 request received from Scheduler@node2.supernodexp.hpc, sock=16
05/02/2018 05:18:33;0100;Server@node2;Req;;Type 81 request received from Scheduler@node2.supernodexp.hpc, sock=16
05/02/2018 05:18:33;0100;Server@node2;Req;;Type 71 request received from Scheduler@node2.supernodexp.hpc, sock=16
05/02/2018 05:18:33;0100;Server@node2;Req;;Type 58 request received from Scheduler@node2.supernodexp.hpc, sock=16
05/02/2018 05:18:33;0100;Server@node2;Req;;Type 20 request received from Scheduler@node2.supernodexp.hpc, sock=16
05/02/2018 05:18:33;0100;Server@node2;Req;;Type 51 request received from Scheduler@node2.supernodexp.hpc, sock=16
05/02/2018 05:28:33;0040;Server@node2;Svr;node2.supernodexp.hpc;Scheduler sent command 3
05/02/2018 05:28:33;0040;Server@node2;Svr;node2.supernodexp.hpc;Scheduler sent command 0
05/02/2018 05:28:33;0100;Server@node2;Req;;Type 21 request received from Scheduler@node2.supernodexp.hpc, sock=16
05/02/2018 05:28:33;0100;Server@node2;Req;;Type 81 request received from Scheduler@node2.supernodexp.hpc, sock=16
05/02/2018 05:28:33;0100;Server@node2;Req;;Type 71 request received from Scheduler@node2.supernodexp.hpc, sock=16
05/02/2018 05:28:33;0100;Server@node2;Req;;Type 58 request received from Scheduler@node2.supernodexp.hpc, sock=16
05/02/2018 05:28:33;0100;Server@node2;Req;;Type 20 request received from Scheduler@node2.supernodexp.hpc, sock=16
05/02/2018 05:28:33;0100;Server@node2;Req;;Type 51 request received from Scheduler@node2.supernodexp.hpc, sock=16
05/02/2018 05:38:33;0040;Server@node2;Svr;node2.supernodexp.hpc;Scheduler sent command 3
05/02/2018 05:38:33;0040;Server@node2;Svr;node2.supernodexp.hpc;Scheduler sent command 0
05/02/2018 05:38:33;0100;Server@node2;Req;;Type 21 request received from Scheduler@node2.supernodexp.hpc, sock=16
05/02/2018 05:38:33;0100;Server@node2;Req;;Type 81 request received from Scheduler@node2.supernodexp.hpc, sock=16
05/02/2018 05:38:33;0100;Server@node2;Req;;Type 71 request received from Scheduler@node2.supernodexp.hpc, sock=16
05/02/2018 05:38:33;0100;Server@node2;Req;;Type 58 request received from Scheduler@node2.supernodexp.hpc, sock=16
05/02/2018 05:38:33;0100;Server@node2;Req;;Type 20 request received from Scheduler@node2.supernodexp.hpc, sock=16
05/02/2018 05:38:33;0100;Server@node2;Req;;Type 51 request received from Scheduler@node2.supernodexp.hpc, sock=16
05/02/2018 05:48:33;0040;Server@node2;Svr;node2.supernodexp.hpc;Scheduler sent command 3
05/02/2018 05:48:33;0040;Server@node2;Svr;node2.supernodexp.hpc;Scheduler sent command 0
05/02/2018 05:48:33;0100;Server@node2;Req;;Type 21 request received from Scheduler@node2.supernodexp.hpc, sock=16
05/02/2018 05:48:33;0100;Server@node2;Req;;Type 81 request received from Scheduler@node2.supernodexp.hpc, sock=16
05/02/2018 05:48:33;0100;Server@node2;Req;;Type 71 request received from Scheduler@node2.supernodexp.hpc, sock=16
05/02/2018 05:48:33;0100;Server@node2;Req;;Type 58 request received from Scheduler@node2.supernodexp.hpc, sock=16
05/02/2018 05:48:33;0100;Server@node2;Req;;Type 20 request received from Scheduler@node2.supernodexp.hpc, sock=16
05/02/2018 05:48:33;0100;Server@node2;Req;;Type 51 request received from Scheduler@node2.supernodexp.hpc, sock=16
05/02/2018 05:58:33;0040;Server@node2;Svr;node2.supernodexp.hpc;Scheduler sent command 3
05/02/2018 05:58:33;0040;Server@node2;Svr;node2.supernodexp.hpc;Scheduler sent command 0
05/02/2018 05:58:33;0100;Server@node2;Req;;Type 21 request received from Scheduler@node2.supernodexp.hpc, sock=16
05/02/2018 05:58:33;0100;Server@node2;Req;;Type 81 request received from Scheduler@node2.supernodexp.hpc, sock=16
05/02/2018 05:58:33;0100;Server@node2;Req;;Type 71 request received from Scheduler@node2.supernodexp.hpc, sock=16
05/02/2018 05:58:33;0100;Server@node2;Req;;Type 58 request received from Scheduler@node2.supernodexp.hpc, sock=16
05/02/2018 05:58:33;0100;Server@node2;Req;;Type 20 request received from Scheduler@node2.supernodexp.hpc, sock=16
05/02/2018 05:58:33;0100;Server@node2;Req;;Type 51 request received from Scheduler@node2.supernodexp.hpc, sock=16
05/02/2018 06:08:33;0040;Server@node2;Svr;node2.supernodexp.hpc;Scheduler sent command 3
05/02/2018 06:08:33;0040;Server@node2;Svr;node2.supernodexp.hpc;Scheduler sent command 0
05/02/2018 06:08:33;0100;Server@node2;Req;;Type 21 request received from Scheduler@node2.supernodexp.hpc, sock=16
05/02/2018 06:08:33;0100;Server@node2;Req;;Type 81 request received from Scheduler@node2.supernodexp.hpc, sock=16
05/02/2018 06:08:33;0100;Server@node2;Req;;Type 71 request received from Scheduler@node2.supernodexp.hpc, sock=16
05/02/2018 06:08:33;0100;Server@node2;Req;;Type 58 request received from Scheduler@node2.supernodexp.hpc, sock=16
05/02/2018 06:08:33;0100;Server@node2;Req;;Type 20 request received from Scheduler@node2.supernodexp.hpc, sock=16
05/02/2018 06:08:33;0100;Server@node2;Req;;Type 51 request received from Scheduler@node2.supernodexp.hpc, sock=16
05/02/2018 06:18:33;0040;Server@node2;Svr;node2.supernodexp.hpc;Scheduler sent command 3
05/02/2018 06:18:33;0040;Server@node2;Svr;node2.supernodexp.hpc;Scheduler sent command 0
05/02/2018 06:18:33;0100;Server@node2;Req;;Type 21 request received from Scheduler@node2.supernodexp.hpc, sock=16
05/02/2018 06:18:33;0100;Server@node2;Req;;Type 81 request received from Scheduler@node2.supernodexp.hpc, sock=16
05/02/2018 06:18:33;0100;Server@node2;Req;;Type 71 request received from Scheduler@node2.supernodexp.hpc, sock=16
05/02/2018 06:18:33;0100;Server@node2;Req;;Type 58 request received from Scheduler@node2.supernodexp.hpc, sock=16
05/02/2018 06:18:33;0100;Server@node2;Req;;Type 20 request received from Scheduler@node2.supernodexp.hpc, sock=16
05/02/2018 06:18:33;0100;Server@node2;Req;;Type 51 request received from Scheduler@node2.supernodexp.hpc, sock=16
05/02/2018 06:28:33;0040;Server@node2;Svr;node2.supernodexp.hpc;Scheduler sent command 3
05/02/2018 06:28:33;0040;Server@node2;Svr;node2.supernodexp.hpc;Scheduler sent command 0
05/02/2018 06:28:33;0100;Server@node2;Req;;Type 21 request received from Scheduler@node2.supernodexp.hpc, sock=16
05/02/2018 06:28:33;0100;Server@node2;Req;;Type 81 request received from Scheduler@node2.supernodexp.hpc, sock=16
05/02/2018 06:28:33;0100;Server@node2;Req;;Type 71 request received from Scheduler@node2.supernodexp.hpc, sock=16
05/02/2018 06:28:33;0100;Server@node2;Req;;Type 58 request received from Scheduler@node2.supernodexp.hpc, sock=16
05/02/2018 06:28:33;0100;Server@node2;Req;;Type 20 request received from Scheduler@node2.supernodexp.hpc, sock=16
05/02/2018 06:28:33;0100;Server@node2;Req;;Type 51 request received from Scheduler@node2.supernodexp.hpc, sock=16
05/02/2018 06:38:33;0040;Server@node2;Svr;node2.supernodexp.hpc;Scheduler sent command 3
05/02/2018 06:38:33;0040;Server@node2;Svr;node2.supernodexp.hpc;Scheduler sent command 0
05/02/2018 06:38:33;0100;Server@node2;Req;;Type 21 request received from Scheduler@node2.supernodexp.hpc, sock=16
05/02/2018 06:38:33;0100;Server@node2;Req;;Type 81 request received from Scheduler@node2.supernodexp.hpc, sock=16
05/02/2018 06:38:33;0100;Server@node2;Req;;Type 71 request received from Scheduler@node2.supernodexp.hpc, sock=16
05/02/2018 06:38:33;0100;Server@node2;Req;;Type 58 request received from Scheduler@node2.supernodexp.hpc, sock=16
05/02/2018 06:38:33;0100;Server@node2;Req;;Type 20 request received from Scheduler@node2.supernodexp.hpc, sock=16
05/02/2018 06:38:33;0100;Server@node2;Req;;Type 51 request received from Scheduler@node2.supernodexp.hpc, sock=16
05/02/2018 06:48:33;0040;Server@node2;Svr;node2.supernodexp.hpc;Scheduler sent command 3
05/02/2018 06:48:33;0040;Server@node2;Svr;node2.supernodexp.hpc;Scheduler sent command 0
05/02/2018 06:48:33;0100;Server@node2;Req;;Type 21 request received from Scheduler@node2.supernodexp.hpc, sock=16
05/02/2018 06:48:33;0100;Server@node2;Req;;Type 81 request received from Scheduler@node2.supernodexp.hpc, sock=16
05/02/2018 06:48:33;0100;Server@node2;Req;;Type 71 request received from Scheduler@node2.supernodexp.hpc, sock=16
05/02/2018 06:48:33;0100;Server@node2;Req;;Type 58 request received from Scheduler@node2.supernodexp.hpc, sock=16
05/02/2018 06:48:34;0100;Server@node2;Req;;Type 20 request received from Scheduler@node2.supernodexp.hpc, sock=16
05/02/2018 06:48:34;0100;Server@node2;Req;;Type 51 request received from Scheduler@node2.supernodexp.hpc, sock=16
05/02/2018 06:58:33;0040;Server@node2;Svr;node2.supernodexp.hpc;Scheduler sent command 3
05/02/2018 06:58:33;0040;Server@node2;Svr;node2.supernodexp.hpc;Scheduler sent command 0
05/02/2018 06:58:33;0100;Server@node2;Req;;Type 21 request received from Scheduler@node2.supernodexp.hpc, sock=16
05/02/2018 06:58:33;0100;Server@node2;Req;;Type 81 request received from Scheduler@node2.supernodexp.hpc, sock=16
05/02/2018 06:58:33;0100;Server@node2;Req;;Type 71 request received from Scheduler@node2.supernodexp.hpc, sock=16
05/02/2018 06:58:33;0100;Server@node2;Req;;Type 58 request received from Scheduler@node2.supernodexp.hpc, sock=16
05/02/2018 06:58:33;0100;Server@node2;Req;;Type 20 request received from Scheduler@node2.supernodexp.hpc, sock=16
05/02/2018 06:58:33;0100;Server@node2;Req;;Type 51 request received from Scheduler@node2.supernodexp.hpc, sock=16
05/02/2018 07:08:33;0040;Server@node2;Svr;node2.supernodexp.hpc;Scheduler sent command 3
05/02/2018 07:08:33;0040;Server@node2;Svr;node2.supernodexp.hpc;Scheduler sent command 0
05/02/2018 07:08:33;0100;Server@node2;Req;;Type 21 request received from Scheduler@node2.supernodexp.hpc, sock=16
05/02/2018 07:08:33;0100;Server@node2;Req;;Type 81 request received from Scheduler@node2.supernodexp.hpc, sock=16
05/02/2018 07:08:33;0100;Server@node2;Req;;Type 71 request received from Scheduler@node2.supernodexp.hpc, sock=16
05/02/2018 07:08:33;0100;Server@node2;Req;;Type 58 request received from Scheduler@node2.supernodexp.hpc, sock=16
05/02/2018 07:08:33;0100;Server@node2;Req;;Type 20 request received from Scheduler@node2.supernodexp.hpc, sock=16
05/02/2018 07:08:33;0100;Server@node2;Req;;Type 51 request received from Scheduler@node2.supernodexp.hpc, sock=16
05/02/2018 07:18:33;0040;Server@node2;Svr;node2.supernodexp.hpc;Scheduler sent command 3
05/02/2018 07:18:33;0040;Server@node2;Svr;node2.supernodexp.hpc;Scheduler sent command 0
05/02/2018 07:18:33;0100;Server@node2;Req;;Type 21 request received from Scheduler@node2.supernodexp.hpc, sock=16
05/02/2018 07:18:33;0100;Server@node2;Req;;Type 81 request received from Scheduler@node2.supernodexp.hpc, sock=16
05/02/2018 07:18:33;0100;Server@node2;Req;;Type 71 request received from Scheduler@node2.supernodexp.hpc, sock=16
05/02/2018 07:18:33;0100;Server@node2;Req;;Type 58 request received from Scheduler@node2.supernodexp.hpc, sock=16
05/02/2018 07:18:33;0100;Server@node2;Req;;Type 20 request received from Scheduler@node2.supernodexp.hpc, sock=16
05/02/2018 07:18:33;0100;Server@node2;Req;;Type 51 request received from Scheduler@node2.supernodexp.hpc, sock=16
05/02/2018 07:28:33;0040;Server@node2;Svr;node2.supernodexp.hpc;Scheduler sent command 3
05/02/2018 07:28:33;0040;Server@node2;Svr;node2.supernodexp.hpc;Scheduler sent command 0
05/02/2018 07:28:33;0100;Server@node2;Req;;Type 21 request received from Scheduler@node2.supernodexp.hpc, sock=16
05/02/2018 07:28:33;0100;Server@node2;Req;;Type 81 request received from Scheduler@node2.supernodexp.hpc, sock=16
05/02/2018 07:28:33;0100;Server@node2;Req;;Type 71 request received from Scheduler@node2.supernodexp.hpc, sock=16
05/02/2018 07:28:33;0100;Server@node2;Req;;Type 58 request received from Scheduler@node2.supernodexp.hpc, sock=16
05/02/2018 07:28:33;0100;Server@node2;Req;;Type 20 request received from Scheduler@node2.supernodexp.hpc, sock=16
05/02/2018 07:28:33;0100;Server@node2;Req;;Type 51 request received from Scheduler@node2.supernodexp.hpc, sock=16
05/02/2018 07:38:33;0040;Server@node2;Svr;node2.supernodexp.hpc;Scheduler sent command 3
05/02/2018 07:38:33;0040;Server@node2;Svr;node2.supernodexp.hpc;Scheduler sent command 0
05/02/2018 07:38:33;0100;Server@node2;Req;;Type 21 request received from Scheduler@node2.supernodexp.hpc, sock=16
05/02/2018 07:38:33;0100;Server@node2;Req;;Type 81 request received from Scheduler@node2.supernodexp.hpc, sock=16
05/02/2018 07:38:33;0100;Server@node2;Req;;Type 71 request received from Scheduler@node2.supernodexp.hpc, sock=16
05/02/2018 07:38:33;0100;Server@node2;Req;;Type 58 request received from Scheduler@node2.supernodexp.hpc, sock=16
05/02/2018 07:38:33;0100;Server@node2;Req;;Type 20 request received from Scheduler@node2.supernodexp.hpc, sock=16
05/02/2018 07:38:33;0100;Server@node2;Req;;Type 51 request received from Scheduler@node2.supernodexp.hpc, sock=16
05/02/2018 07:48:33;0040;Server@node2;Svr;node2.supernodexp.hpc;Scheduler sent command 3
05/02/2018 07:48:33;0040;Server@node2;Svr;node2.supernodexp.hpc;Scheduler sent command 0
05/02/2018 07:48:33;0100;Server@node2;Req;;Type 21 request received from Scheduler@node2.supernodexp.hpc, sock=16
05/02/2018 07:48:33;0100;Server@node2;Req;;Type 81 request received from Scheduler@node2.supernodexp.hpc, sock=16
05/02/2018 07:48:33;0100;Server@node2;Req;;Type 71 request received from Scheduler@node2.supernodexp.hpc, sock=16
05/02/2018 07:48:33;0100;Server@node2;Req;;Type 58 request received from Scheduler@node2.supernodexp.hpc, sock=16
05/02/2018 07:48:33;0100;Server@node2;Req;;Type 20 request received from Scheduler@node2.supernodexp.hpc, sock=16
05/02/2018 07:48:33;0100;Server@node2;Req;;Type 51 request received from Scheduler@node2.supernodexp.hpc, sock=16
05/02/2018 07:58:33;0040;Server@node2;Svr;node2.supernodexp.hpc;Scheduler sent command 3
05/02/2018 07:58:33;0040;Server@node2;Svr;node2.supernodexp.hpc;Scheduler sent command 0
05/02/2018 07:58:33;0100;Server@node2;Req;;Type 21 request received from Scheduler@node2.supernodexp.hpc, sock=16
05/02/2018 07:58:33;0100;Server@node2;Req;;Type 81 request received from Scheduler@node2.supernodexp.hpc, sock=16
05/02/2018 07:58:33;0100;Server@node2;Req;;Type 71 request received from Scheduler@node2.supernodexp.hpc, sock=16
05/02/2018 07:58:33;0100;Server@node2;Req;;Type 58 request received from Scheduler@node2.supernodexp.hpc, sock=16
05/02/2018 07:58:33;0100;Server@node2;Req;;Type 20 request received from Scheduler@node2.supernodexp.hpc, sock=16
05/02/2018 07:58:33;0100;Server@node2;Req;;Type 51 request received from Scheduler@node2.supernodexp.hpc, sock=16
05/02/2018 08:08:33;0040;Server@node2;Svr;node2.supernodexp.hpc;Scheduler sent command 3
05/02/2018 08:08:33;0040;Server@node2;Svr;node2.supernodexp.hpc;Scheduler sent command 0
05/02/2018 08:08:33;0100;Server@node2;Req;;Type 21 request received from Scheduler@node2.supernodexp.hpc, sock=16
05/02/2018 08:08:33;0100;Server@node2;Req;;Type 81 request received from Scheduler@node2.supernodexp.hpc, sock=16
05/02/2018 08:08:33;0100;Server@node2;Req;;Type 71 request received from Scheduler@node2.supernodexp.hpc, sock=16
05/02/2018 08:08:33;0100;Server@node2;Req;;Type 58 request received from Scheduler@node2.supernodexp.hpc, sock=16
05/02/2018 08:08:33;0100;Server@node2;Req;;Type 20 request received from Scheduler@node2.supernodexp.hpc, sock=16
05/02/2018 08:08:33;0100;Server@node2;Req;;Type 51 request received from Scheduler@node2.supernodexp.hpc, sock=16
05/02/2018 08:18:33;0040;Server@node2;Svr;node2.supernodexp.hpc;Scheduler sent command 3
05/02/2018 08:18:33;0040;Server@node2;Svr;node2.supernodexp.hpc;Scheduler sent command 0
05/02/2018 08:18:33;0100;Server@node2;Req;;Type 21 request received from Scheduler@node2.supernodexp.hpc, sock=16
05/02/2018 08:18:33;0100;Server@node2;Req;;Type 81 request received from Scheduler@node2.supernodexp.hpc, sock=16
05/02/2018 08:18:33;0100;Server@node2;Req;;Type 71 request received from Scheduler@node2.supernodexp.hpc, sock=16
05/02/2018 08:18:33;0100;Server@node2;Req;;Type 58 request received from Scheduler@node2.supernodexp.hpc, sock=16
05/02/2018 08:18:33;0100;Server@node2;Req;;Type 20 request received from Scheduler@node2.supernodexp.hpc, sock=16
05/02/2018 08:18:33;0100;Server@node2;Req;;Type 51 request received from Scheduler@node2.supernodexp.hpc, sock=16
05/02/2018 08:28:33;0040;Server@node2;Svr;node2.supernodexp.hpc;Scheduler sent command 3
05/02/2018 08:28:33;0040;Server@node2;Svr;node2.supernodexp.hpc;Scheduler sent command 0
05/02/2018 08:28:33;0100;Server@node2;Req;;Type 21 request received from Scheduler@node2.supernodexp.hpc, sock=16
05/02/2018 08:28:33;0100;Server@node2;Req;;Type 81 request received from Scheduler@node2.supernodexp.hpc, sock=16
05/02/2018 08:28:33;0100;Server@node2;Req;;Type 71 request received from Scheduler@node2.supernodexp.hpc, sock=16
05/02/2018 08:28:33;0100;Server@node2;Req;;Type 58 request received from Scheduler@node2.supernodexp.hpc, sock=16
05/02/2018 08:28:33;0100;Server@node2;Req;;Type 20 request received from Scheduler@node2.supernodexp.hpc, sock=16
05/02/2018 08:28:33;0100;Server@node2;Req;;Type 51 request received from Scheduler@node2.supernodexp.hpc, sock=16
05/02/2018 08:37:14;0100;Server@node2;Req;;Type 0 request received from root@node2.supernodexp.hpc, sock=16
05/02/2018 08:37:14;0100;Server@node2;Req;;Type 49 request received from root@node2.supernodexp.hpc, sock=19
05/02/2018 08:37:14;0100;Server@node2;Req;;Type 21 request received from root@node2.supernodexp.hpc, sock=16
05/02/2018 08:37:14;0100;Server@node2;Req;;Type 19 request received from root@node2.supernodexp.hpc, sock=16
05/02/2018 08:38:33;0040;Server@node2;Svr;node2.supernodexp.hpc;Scheduler sent command 3
05/02/2018 08:38:33;0040;Server@node2;Svr;node2.supernodexp.hpc;Scheduler sent command 0
05/02/2018 08:38:33;0100;Server@node2;Req;;Type 21 request received from Scheduler@node2.supernodexp.hpc, sock=16
05/02/2018 08:38:33;0100;Server@node2;Req;;Type 81 request received from Scheduler@node2.supernodexp.hpc, sock=16
05/02/2018 08:38:33;0100;Server@node2;Req;;Type 71 request received from Scheduler@node2.supernodexp.hpc, sock=16
05/02/2018 08:38:33;0100;Server@node2;Req;;Type 58 request received from Scheduler@node2.supernodexp.hpc, sock=16
05/02/2018 08:38:33;0100;Server@node2;Req;;Type 20 request received from Scheduler@node2.supernodexp.hpc, sock=16
05/02/2018 08:38:33;0100;Server@node2;Req;;Type 51 request received from Scheduler@node2.supernodexp.hpc, sock=16
05/02/2018 08:44:12;0100;Server@node2;Req;;Type 0 request received from root@node2.supernodexp.hpc, sock=16
05/02/2018 08:44:12;0100;Server@node2;Req;;Type 49 request received from root@node2.supernodexp.hpc, sock=19
05/02/2018 08:44:14;0100;Server@node2;Req;;Type 82 request received from root@node2.supernodexp.hpc, sock=16
05/02/2018 08:44:14;0100;Server@node2;Req;;Type 20 request received from root@node2.supernodexp.hpc, sock=16
05/02/2018 08:44:14;0100;Server@node2;Req;;Type 71 request received from root@node2.supernodexp.hpc, sock=16
05/02/2018 08:44:14;0100;Server@node2;Req;;Type 21 request received from root@node2.supernodexp.hpc, sock=16
05/02/2018 08:48:33;0040;Server@node2;Svr;node2.supernodexp.hpc;Scheduler sent command 3
05/02/2018 08:48:33;0040;Server@node2;Svr;node2.supernodexp.hpc;Scheduler sent command 0
05/02/2018 08:48:33;0100;Server@node2;Req;;Type 21 request received from Scheduler@node2.supernodexp.hpc, sock=19
05/02/2018 08:48:33;0100;Server@node2;Req;;Type 81 request received from Scheduler@node2.supernodexp.hpc, sock=19
05/02/2018 08:48:33;0100;Server@node2;Req;;Type 71 request received from Scheduler@node2.supernodexp.hpc, sock=19
05/02/2018 08:48:33;0100;Server@node2;Req;;Type 58 request received from Scheduler@node2.supernodexp.hpc, sock=19
05/02/2018 08:48:34;0100;Server@node2;Req;;Type 20 request received from Scheduler@node2.supernodexp.hpc, sock=19
05/02/2018 08:48:34;0100;Server@node2;Req;;Type 51 request received from Scheduler@node2.supernodexp.hpc, sock=19
05/02/2018 08:49:26;0100;Server@node2;Req;;Type 0 request received from ctminh@node2.supernodexp.hpc, sock=16
05/02/2018 08:49:26;0100;Server@node2;Req;;Type 49 request received from ctminh@node2.supernodexp.hpc, sock=19
05/02/2018 08:49:26;0100;Server@node2;Req;;Type 21 request received from ctminh@node2.supernodexp.hpc, sock=16
05/02/2018 08:49:26;0100;Server@node2;Req;;Type 1 request received from ctminh@node2.supernodexp.hpc, sock=16
05/02/2018 08:49:26;0100;Server@node2;Req;;Type 3 request received from ctminh@node2.supernodexp.hpc, sock=16
05/02/2018 08:49:26;0100;Server@node2;Req;;Type 5 request received from ctminh@node2.supernodexp.hpc, sock=16
05/02/2018 08:49:26;0100;Server@node2;Job;13241.node2.supernodexp.hpc;enqueuing into workq, state 1 hop 1
05/02/2018 08:49:26;0008;Server@node2;Job;13241.node2.supernodexp.hpc;Job Queued at request of ctminh@node2.supernodexp.hpc, owner = ctminh@node2.supernodexp.hpc, job name = telemac1, queue = workq
05/02/2018 08:49:26;0040;Server@node2;Svr;node2.supernodexp.hpc;Scheduler sent command 1
05/02/2018 08:49:26;0040;Server@node2;Svr;node2.supernodexp.hpc;Scheduler sent command 0
05/02/2018 08:49:26;0100;Server@node2;Req;;Type 21 request received from Scheduler@node2.supernodexp.hpc, sock=19
05/02/2018 08:49:26;0100;Server@node2;Req;;Type 81 request received from Scheduler@node2.supernodexp.hpc, sock=19
05/02/2018 08:49:26;0100;Server@node2;Req;;Type 71 request received from Scheduler@node2.supernodexp.hpc, sock=19
05/02/2018 08:49:26;0100;Server@node2;Req;;Type 58 request received from Scheduler@node2.supernodexp.hpc, sock=19
05/02/2018 08:49:26;0100;Server@node2;Req;;Type 1 request received from ctminh@node2.supernodexp.hpc, sock=16
05/02/2018 08:49:26;0100;Server@node2;Req;;Type 3 request received from ctminh@node2.supernodexp.hpc, sock=16
05/02/2018 08:49:26;0100;Server@node2;Req;;Type 5 request received from ctminh@node2.supernodexp.hpc, sock=16
05/02/2018 08:49:26;0100;Server@node2;Job;13242.node2.supernodexp.hpc;enqueuing into workq, state 1 hop 1
05/02/2018 08:49:26;0008;Server@node2;Job;13242.node2.supernodexp.hpc;Job Queued at request of ctminh@node2.supernodexp.hpc, owner = ctminh@node2.supernodexp.hpc, job name = telemac1, queue = workq
05/02/2018 08:49:26;0100;Server@node2;Req;;Type 1 request received from ctminh@node2.supernodexp.hpc, sock=16
05/02/2018 08:49:26;0100;Server@node2;Req;;Type 3 request received from ctminh@node2.supernodexp.hpc, sock=16
05/02/2018 08:49:26;0100;Server@node2;Req;;Type 5 request received from ctminh@node2.supernodexp.hpc, sock=16
05/02/2018 08:49:26;0100;Server@node2;Job;13243.node2.supernodexp.hpc;enqueuing into workq, state 1 hop 1
05/02/2018 08:49:26;0008;Server@node2;Job;13243.node2.supernodexp.hpc;Job Queued at request of ctminh@node2.supernodexp.hpc, owner = ctminh@node2.supernodexp.hpc, job name = telemac2, queue = workq
05/02/2018 08:49:26;0100;Server@node2;Req;;Type 1 request received from ctminh@node2.supernodexp.hpc, sock=16
05/02/2018 08:49:26;0100;Server@node2;Req;;Type 3 request received from ctminh@node2.supernodexp.hpc, sock=16
05/02/2018 08:49:26;0100;Server@node2;Req;;Type 5 request received from ctminh@node2.supernodexp.hpc, sock=16
05/02/2018 08:49:26;0100;Server@node2;Job;13244.node2.supernodexp.hpc;enqueuing into workq, state 1 hop 1
05/02/2018 08:49:26;0008;Server@node2;Job;13244.node2.supernodexp.hpc;Job Queued at request of ctminh@node2.supernodexp.hpc, owner = ctminh@node2.supernodexp.hpc, job name = telemac2, queue = workq
05/02/2018 08:49:26;0100;Server@node2;Req;;Type 20 request received from Scheduler@node2.supernodexp.hpc, sock=19
05/02/2018 08:49:26;0100;Server@node2;Req;;Type 51 request received from Scheduler@node2.supernodexp.hpc, sock=19
05/02/2018 08:49:26;0100;Server@node2;Req;;Type 1 request received from ctminh@node2.supernodexp.hpc, sock=16
05/02/2018 08:49:26;0100;Server@node2;Req;;Type 3 request received from ctminh@node2.supernodexp.hpc, sock=16
05/02/2018 08:49:26;0100;Server@node2;Req;;Type 5 request received from ctminh@node2.supernodexp.hpc, sock=16
05/02/2018 08:49:26;0100;Server@node2;Job;13245.node2.supernodexp.hpc;enqueuing into workq, state 1 hop 1
05/02/2018 08:49:26;0008;Server@node2;Job;13245.node2.supernodexp.hpc;Job Queued at request of ctminh@node2.supernodexp.hpc, owner = ctminh@node2.supernodexp.hpc, job name = telemac3, queue = workq
05/02/2018 08:49:26;0100;Server@node2;Req;;Type 1 request received from ctminh@node2.supernodexp.hpc, sock=16
05/02/2018 08:49:26;0100;Server@node2;Req;;Type 3 request received from ctminh@node2.supernodexp.hpc, sock=16
05/02/2018 08:49:26;0100;Server@node2;Req;;Type 5 request received from ctminh@node2.supernodexp.hpc, sock=16
05/02/2018 08:49:26;0100;Server@node2;Job;13246.node2.supernodexp.hpc;enqueuing into workq, state 1 hop 1
05/02/2018 08:49:26;0008;Server@node2;Job;13246.node2.supernodexp.hpc;Job Queued at request of ctminh@node2.supernodexp.hpc, owner = ctminh@node2.supernodexp.hpc, job name = telemac3, queue = workq
05/02/2018 08:49:26;0100;Server@node2;Req;;Type 1 request received from ctminh@node2.supernodexp.hpc, sock=16
05/02/2018 08:49:26;0100;Server@node2;Req;;Type 3 request received from ctminh@node2.supernodexp.hpc, sock=16
05/02/2018 08:49:26;0100;Server@node2;Req;;Type 5 request received from ctminh@node2.supernodexp.hpc, sock=16
05/02/2018 08:49:26;0100;Server@node2;Job;13247.node2.supernodexp.hpc;enqueuing into workq, state 1 hop 1
05/02/2018 08:49:26;0008;Server@node2;Job;13247.node2.supernodexp.hpc;Job Queued at request of ctminh@node2.supernodexp.hpc, owner = ctminh@node2.supernodexp.hpc, job name = telemac1, queue = workq
05/02/2018 08:49:26;0100;Server@node2;Req;;Type 1 request received from ctminh@node2.supernodexp.hpc, sock=16
05/02/2018 08:49:26;0100;Server@node2;Req;;Type 3 request received from ctminh@node2.supernodexp.hpc, sock=16
05/02/2018 08:49:26;0100;Server@node2;Req;;Type 5 request received from ctminh@node2.supernodexp.hpc, sock=16
05/02/2018 08:49:26;0100;Server@node2;Job;13248.node2.supernodexp.hpc;enqueuing into workq, state 1 hop 1
05/02/2018 08:49:26;0008;Server@node2;Job;13248.node2.supernodexp.hpc;Job Queued at request of ctminh@node2.supernodexp.hpc, owner = ctminh@node2.supernodexp.hpc, job name = telemac2, queue = workq
05/02/2018 08:49:26;0100;Server@node2;Req;;Type 1 request received from ctminh@node2.supernodexp.hpc, sock=16
05/02/2018 08:49:26;0100;Server@node2;Req;;Type 3 request received from ctminh@node2.supernodexp.hpc, sock=16
05/02/2018 08:49:26;0100;Server@node2;Req;;Type 5 request received from ctminh@node2.supernodexp.hpc, sock=16
05/02/2018 08:49:26;0100;Server@node2;Job;13249.node2.supernodexp.hpc;enqueuing into workq, state 1 hop 1
05/02/2018 08:49:26;0008;Server@node2;Job;13249.node2.supernodexp.hpc;Job Queued at request of ctminh@node2.supernodexp.hpc, owner = ctminh@node2.supernodexp.hpc, job name = telemac3, queue = workq
05/02/2018 08:49:26;0100;Server@node2;Req;;Type 23 request received from Scheduler@node2.supernodexp.hpc, sock=19
05/02/2018 08:49:26;0008;Server@node2;Job;13241.node2.supernodexp.hpc;Job Run at request of Scheduler@node2.supernodexp.hpc on exec_vnode (node3:ncpus=24:mpiprocs=24:mem=2097152kb)
05/02/2018 08:49:26;0001;Server@node2;Svr;Server@node2;Success (0) in req_runjob2, return value of svr_startjob is 0
05/02/2018 08:49:26;0100;Server@node2;Req;;Type 23 request received from Scheduler@node2.supernodexp.hpc, sock=19
05/02/2018 08:49:26;0008;Server@node2;Job;13242.node2.supernodexp.hpc;Job Run at request of Scheduler@node2.supernodexp.hpc on exec_vnode (node3:ncpus=24:mpiprocs=24:mem=2097152kb)
05/02/2018 08:49:26;0001;Server@node2;Svr;Server@node2;Success (0) in req_runjob2, return value of svr_startjob is 0
05/02/2018 08:49:26;0100;Server@node2;Req;;Type 23 request received from Scheduler@node2.supernodexp.hpc, sock=19
05/02/2018 08:49:26;0008;Server@node2;Job;13243.node2.supernodexp.hpc;Job Run at request of Scheduler@node2.supernodexp.hpc on exec_vnode (node14:ncpus=16:mpiprocs=16:mem=8388608kb)
05/02/2018 08:49:26;0001;Server@node2;Svr;Server@node2;Success (0) in req_runjob2, return value of svr_startjob is 0
05/02/2018 08:49:26;0100;Server@node2;Req;;Type 23 request received from Scheduler@node2.supernodexp.hpc, sock=19
05/02/2018 08:49:26;0008;Server@node2;Job;13244.node2.supernodexp.hpc;Job Run at request of Scheduler@node2.supernodexp.hpc on exec_vnode (node14:ncpus=16:mpiprocs=16:mem=8388608kb)
05/02/2018 08:49:27;0001;Server@node2;Svr;Server@node2;Success (0) in req_runjob2, return value of svr_startjob is 0
05/02/2018 08:49:27;0040;Server@node2;Svr;node2.supernodexp.hpc;Scheduler sent command 1
05/02/2018 08:49:27;0040;Server@node2;Svr;node2.supernodexp.hpc;Scheduler sent command 0
05/02/2018 08:49:27;0100;Server@node2;Req;;Type 21 request received from Scheduler@node2.supernodexp.hpc, sock=19
05/02/2018 08:49:27;0100;Server@node2;Req;;Type 81 request received from Scheduler@node2.supernodexp.hpc, sock=19
05/02/2018 08:49:27;0100;Server@node2;Req;;Type 71 request received from Scheduler@node2.supernodexp.hpc, sock=19
05/02/2018 08:49:27;0100;Server@node2;Req;;Type 58 request received from Scheduler@node2.supernodexp.hpc, sock=19
05/02/2018 08:49:27;0100;Server@node2;Req;;Type 20 request received from Scheduler@node2.supernodexp.hpc, sock=19
05/02/2018 08:49:27;0100;Server@node2;Req;;Type 51 request received from Scheduler@node2.supernodexp.hpc, sock=19
05/02/2018 08:49:27;0100;Server@node2;Req;;Type 23 request received from Scheduler@node2.supernodexp.hpc, sock=19
05/02/2018 08:49:27;0008;Server@node2;Job;13245.node2.supernodexp.hpc;Job Run at request of Scheduler@node2.supernodexp.hpc on exec_vnode (node13:ncpus=24:mpiprocs=24:mem=4194304kb)+(node13:ncpus=24:mpiprocs=24:mem=4194304kb)
05/02/2018 08:49:27;0001;Server@node2;Svr;Server@node2;Success (0) in req_runjob2, return value of svr_startjob is 0
05/02/2018 08:49:27;0100;Server@node2;Req;;Type 11 request received from Scheduler@node2.supernodexp.hpc, sock=19
05/02/2018 08:49:27;0008;Server@node2;Job;13249.node2.supernodexp.hpc;Job Modified at request of Scheduler@node2.supernodexp.hpc
05/02/2018 08:49:27;0100;Server@node2;Req;;Type 11 request received from Scheduler@node2.supernodexp.hpc, sock=19
05/02/2018 08:49:27;0008;Server@node2;Job;13247.node2.supernodexp.hpc;Job Modified at request of Scheduler@node2.supernodexp.hpc
05/02/2018 08:49:27;0100;Server@node2;Req;;Type 11 request received from Scheduler@node2.supernodexp.hpc, sock=19
05/02/2018 08:49:27;0008;Server@node2;Job;13248.node2.supernodexp.hpc;Job Modified at request of Scheduler@node2.supernodexp.hpc
05/02/2018 08:49:27;0100;Server@node2;Req;;Type 11 request received from Scheduler@node2.supernodexp.hpc, sock=19
05/02/2018 08:49:27;0008;Server@node2;Job;13246.node2.supernodexp.hpc;Job Modified at request of Scheduler@node2.supernodexp.hpc
05/02/2018 08:49:30;0080;Server@node2;Job;13243.node2.supernodexp.hpc;Obit received momhop:1 serverhop:1 state:4 substate:42
05/02/2018 08:49:31;0100;Server@node2;Req;;Type 0 request received from ctminh@node2.supernodexp.hpc, sock=19
05/02/2018 08:49:31;0100;Server@node2;Req;;Type 49 request received from ctminh@node2.supernodexp.hpc, sock=20
05/02/2018 08:49:31;0100;Server@node2;Req;;Type 21 request received from ctminh@node2.supernodexp.hpc, sock=19
05/02/2018 08:49:31;0100;Server@node2;Req;;Type 19 request received from ctminh@node2.supernodexp.hpc, sock=19
05/02/2018 08:49:35;0080;Server@node2;Job;13242.node2.supernodexp.hpc;Obit received momhop:1 serverhop:1 state:4 substate:42
05/02/2018 08:49:36;0010;Server@node2;Job;13243.node2.supernodexp.hpc;Exit_status=1 resources_used.cpupercent=133 resources_used.cput=00:00:04 resources_used.mem=0kb resources_used.ncpus=16 resources_used.vmem=0kb resources_used.walltime=00:00:05
05/02/2018 08:49:36;0100;Server@node2;Job;13243.node2.supernodexp.hpc;dequeuing from workq, state 5
05/02/2018 08:49:36;0040;Server@node2;Svr;node2.supernodexp.hpc;Scheduler sent command 2
05/02/2018 08:49:36;0040;Server@node2;Svr;node2.supernodexp.hpc;Scheduler sent command 0
05/02/2018 08:49:36;0100;Server@node2;Req;;Type 21 request received from Scheduler@node2.supernodexp.hpc, sock=19
05/02/2018 08:49:36;0100;Server@node2;Req;;Type 81 request received from Scheduler@node2.supernodexp.hpc, sock=19
05/02/2018 08:49:36;0100;Server@node2;Req;;Type 71 request received from Scheduler@node2.supernodexp.hpc, sock=19
05/02/2018 08:49:36;0100;Server@node2;Req;;Type 58 request received from Scheduler@node2.supernodexp.hpc, sock=19
05/02/2018 08:49:36;0100;Server@node2;Req;;Type 20 request received from Scheduler@node2.supernodexp.hpc, sock=19
05/02/2018 08:49:36;0100;Server@node2;Req;;Type 51 request received from Scheduler@node2.supernodexp.hpc, sock=19
05/02/2018 08:49:36;0100;Server@node2;Req;;Type 11 request received from Scheduler@node2.supernodexp.hpc, sock=19
05/02/2018 08:49:36;0008;Server@node2;Job;13246.node2.supernodexp.hpc;Job Modified at request of Scheduler@node2.supernodexp.hpc
05/02/2018 08:49:36;0010;Server@node2;Job;13242.node2.supernodexp.hpc;Exit_status=1 resources_used.cpupercent=50 resources_used.cput=00:00:04 resources_used.mem=0kb resources_used.ncpus=24 resources_used.vmem=0kb resources_used.walltime=00:00:10
05/02/2018 08:49:36;0100;Server@node2;Job;13242.node2.supernodexp.hpc;dequeuing from workq, state 5
05/02/2018 08:49:36;0040;Server@node2;Svr;node2.supernodexp.hpc;Scheduler sent command 2
05/02/2018 08:49:36;0040;Server@node2;Svr;node2.supernodexp.hpc;Scheduler sent command 0
05/02/2018 08:49:36;0100;Server@node2;Req;;Type 21 request received from Scheduler@node2.supernodexp.hpc, sock=19
05/02/2018 08:49:36;0100;Server@node2;Req;;Type 81 request received from Scheduler@node2.supernodexp.hpc, sock=19
05/02/2018 08:49:36;0100;Server@node2;Req;;Type 71 request received from Scheduler@node2.supernodexp.hpc, sock=19
05/02/2018 08:49:36;0100;Server@node2;Req;;Type 58 request received from Scheduler@node2.supernodexp.hpc, sock=19
05/02/2018 08:49:36;0100;Server@node2;Req;;Type 20 request received from Scheduler@node2.supernodexp.hpc, sock=19
05/02/2018 08:49:36;0100;Server@node2;Req;;Type 51 request received from Scheduler@node2.supernodexp.hpc, sock=19
05/02/2018 08:49:37;0100;Server@node2;Req;;Type 23 request received from Scheduler@node2.supernodexp.hpc, sock=19
05/02/2018 08:49:37;0008;Server@node2;Job;13246.node2.supernodexp.hpc;Job Run at request of Scheduler@node2.supernodexp.hpc on exec_vnode (node3:ncpus=24:mpiprocs=24:mem=4194304kb)+(node14:ncpus=24:mpiprocs=24:mem=4194304kb)
05/02/2018 08:49:37;0001;Server@node2;Svr;Server@node2;Success (0) in req_runjob2, return value of svr_startjob is 0
05/02/2018 08:49:37;0100;Server@node2;Req;;Type 11 request received from Scheduler@node2.supernodexp.hpc, sock=19
05/02/2018 08:49:37;0008;Server@node2;Job;13249.node2.supernodexp.hpc;Job Modified at request of Scheduler@node2.supernodexp.hpc
05/02/2018 08:49:37;0100;Server@node2;Req;;Type 0 request received from ctminh@node2.supernodexp.hpc, sock=19
05/02/2018 08:49:37;0100;Server@node2;Req;;Type 49 request received from ctminh@node2.supernodexp.hpc, sock=20
05/02/2018 08:49:37;0100;Server@node2;Req;;Type 21 request received from ctminh@node2.supernodexp.hpc, sock=19
05/02/2018 08:49:37;0100;Server@node2;Req;;Type 19 request received from ctminh@node2.supernodexp.hpc, sock=19
05/02/2018 08:49:40;0100;Server@node2;Req;;Type 0 request received from ctminh@node2.supernodexp.hpc, sock=19
05/02/2018 08:49:40;0100;Server@node2;Req;;Type 49 request received from ctminh@node2.supernodexp.hpc, sock=20
05/02/2018 08:49:40;0100;Server@node2;Req;;Type 21 request received from ctminh@node2.supernodexp.hpc, sock=19
05/02/2018 08:49:40;0100;Server@node2;Req;;Type 19 request received from ctminh@node2.supernodexp.hpc, sock=19
05/02/2018 08:49:51;0100;Server@node2;Req;;Type 0 request received from ctminh@node2.supernodexp.hpc, sock=19
05/02/2018 08:49:51;0100;Server@node2;Req;;Type 49 request received from ctminh@node2.supernodexp.hpc, sock=20
05/02/2018 08:49:51;0100;Server@node2;Req;;Type 21 request received from ctminh@node2.supernodexp.hpc, sock=19
05/02/2018 08:49:51;0100;Server@node2;Req;;Type 19 request received from ctminh@node2.supernodexp.hpc, sock=19
05/02/2018 08:49:52;0100;Server@node2;Req;;Type 0 request received from ctminh@node2.supernodexp.hpc, sock=19
05/02/2018 08:49:52;0100;Server@node2;Req;;Type 49 request received from ctminh@node2.supernodexp.hpc, sock=20
05/02/2018 08:49:52;0100;Server@node2;Req;;Type 21 request received from ctminh@node2.supernodexp.hpc, sock=19
05/02/2018 08:49:52;0100;Server@node2;Req;;Type 19 request received from ctminh@node2.supernodexp.hpc, sock=19
05/02/2018 08:49:53;0100;Server@node2;Req;;Type 0 request received from ctminh@node2.supernodexp.hpc, sock=19
05/02/2018 08:49:53;0100;Server@node2;Req;;Type 49 request received from ctminh@node2.supernodexp.hpc, sock=20
05/02/2018 08:49:53;0100;Server@node2;Req;;Type 21 request received from ctminh@node2.supernodexp.hpc, sock=19
05/02/2018 08:49:53;0100;Server@node2;Req;;Type 19 request received from ctminh@node2.supernodexp.hpc, sock=19
05/02/2018 08:51:52;0080;Server@node2;Job;13245.node2.supernodexp.hpc;Obit received momhop:1 serverhop:1 state:4 substate:42
05/02/2018 08:51:53;0010;Server@node2;Job;13245.node2.supernodexp.hpc;Exit_status=0 resources_used.cpupercent=1808 resources_used.cput=01:45:59 resources_used.mem=3250716kb resources_used.ncpus=48 resources_used.vmem=33620012kb resources_used.walltime=00:02:26
05/02/2018 08:51:53;0100;Server@node2;Job;13245.node2.supernodexp.hpc;dequeuing from workq, state 5
05/02/2018 08:51:53;0040;Server@node2;Svr;node2.supernodexp.hpc;Scheduler sent command 2
05/02/2018 08:51:53;0040;Server@node2;Svr;node2.supernodexp.hpc;Scheduler sent command 0
05/02/2018 08:51:53;0100;Server@node2;Req;;Type 21 request received from Scheduler@node2.supernodexp.hpc, sock=16
05/02/2018 08:51:53;0100;Server@node2;Req;;Type 81 request received from Scheduler@node2.supernodexp.hpc, sock=16
05/02/2018 08:51:53;0100;Server@node2;Req;;Type 71 request received from Scheduler@node2.supernodexp.hpc, sock=16
05/02/2018 08:51:53;0100;Server@node2;Req;;Type 58 request received from Scheduler@node2.supernodexp.hpc, sock=16
05/02/2018 08:51:53;0100;Server@node2;Req;;Type 20 request received from Scheduler@node2.supernodexp.hpc, sock=16
05/02/2018 08:51:53;0100;Server@node2;Req;;Type 51 request received from Scheduler@node2.supernodexp.hpc, sock=16
05/02/2018 08:51:53;0100;Server@node2;Req;;Type 23 request received from Scheduler@node2.supernodexp.hpc, sock=16
05/02/2018 08:51:53;0008;Server@node2;Job;13249.node2.supernodexp.hpc;Job Run at request of Scheduler@node2.supernodexp.hpc on exec_vnode (node13:ncpus=24:mpiprocs=24:mem=4194304kb)+(node13:ncpus=24:mpiprocs=24:mem=4194304kb)
05/02/2018 08:51:53;0001;Server@node2;Svr;Server@node2;Success (0) in req_runjob2, return value of svr_startjob is 0
05/02/2018 08:51:53;0100;Server@node2;Req;;Type 11 request received from Scheduler@node2.supernodexp.hpc, sock=16
05/02/2018 08:51:53;0008;Server@node2;Job;13247.node2.supernodexp.hpc;Job Modified at request of Scheduler@node2.supernodexp.hpc
05/02/2018 08:52:31;0080;Server@node2;Job;13244.node2.supernodexp.hpc;Obit received momhop:1 serverhop:1 state:4 substate:42
05/02/2018 08:52:32;0010;Server@node2;Job;13244.node2.supernodexp.hpc;Exit_status=0 resources_used.cpupercent=807 resources_used.cput=00:47:09 resources_used.mem=1118116kb resources_used.ncpus=16 resources_used.vmem=10375000kb resources_used.walltime=00:03:06
05/02/2018 08:52:32;0100;Server@node2;Job;13244.node2.supernodexp.hpc;dequeuing from workq, state 5
05/02/2018 08:52:32;0040;Server@node2;Svr;node2.supernodexp.hpc;Scheduler sent command 2
05/02/2018 08:52:32;0040;Server@node2;Svr;node2.supernodexp.hpc;Scheduler sent command 0
05/02/2018 08:52:32;0100;Server@node2;Req;;Type 21 request received from Scheduler@node2.supernodexp.hpc, sock=16
05/02/2018 08:52:32;0100;Server@node2;Req;;Type 81 request received from Scheduler@node2.supernodexp.hpc, sock=16
05/02/2018 08:52:32;0100;Server@node2;Req;;Type 71 request received from Scheduler@node2.supernodexp.hpc, sock=16
05/02/2018 08:52:32;0100;Server@node2;Req;;Type 58 request received from Scheduler@node2.supernodexp.hpc, sock=16
05/02/2018 08:52:32;0100;Server@node2;Req;;Type 20 request received from Scheduler@node2.supernodexp.hpc, sock=16
05/02/2018 08:52:32;0100;Server@node2;Req;;Type 51 request received from Scheduler@node2.supernodexp.hpc, sock=16
05/02/2018 08:52:32;0100;Server@node2;Req;;Type 23 request received from Scheduler@node2.supernodexp.hpc, sock=16
05/02/2018 08:52:32;0008;Server@node2;Job;13247.node2.supernodexp.hpc;Job Run at request of Scheduler@node2.supernodexp.hpc on exec_vnode (node14:ncpus=24:mpiprocs=24:mem=2097152kb)
05/02/2018 08:52:32;0001;Server@node2;Svr;Server@node2;Success (0) in req_runjob2, return value of svr_startjob is 0
05/02/2018 08:52:32;0100;Server@node2;Req;;Type 11 request received from Scheduler@node2.supernodexp.hpc, sock=16
05/02/2018 08:52:32;0008;Server@node2;Job;13248.node2.supernodexp.hpc;Job Modified at request of Scheduler@node2.supernodexp.hpc
05/02/2018 08:52:35;0080;Server@node2;Job;13241.node2.supernodexp.hpc;Obit received momhop:1 serverhop:1 state:4 substate:42
05/02/2018 08:52:36;0010;Server@node2;Job;13241.node2.supernodexp.hpc;Exit_status=0 resources_used.cpupercent=1117 resources_used.cput=01:09:59 resources_used.mem=1642960kb resources_used.ncpus=24 resources_used.vmem=15000400kb resources_used.walltime=00:03:10
05/02/2018 08:52:36;0100;Server@node2;Job;13241.node2.supernodexp.hpc;dequeuing from workq, state 5
05/02/2018 08:52:36;0040;Server@node2;Svr;node2.supernodexp.hpc;Scheduler sent command 2
05/02/2018 08:52:36;0040;Server@node2;Svr;node2.supernodexp.hpc;Scheduler sent command 0
05/02/2018 08:52:36;0100;Server@node2;Req;;Type 21 request received from Scheduler@node2.supernodexp.hpc, sock=16
05/02/2018 08:52:36;0100;Server@node2;Req;;Type 81 request received from Scheduler@node2.supernodexp.hpc, sock=16
05/02/2018 08:52:36;0100;Server@node2;Req;;Type 71 request received from Scheduler@node2.supernodexp.hpc, sock=16
05/02/2018 08:52:36;0100;Server@node2;Req;;Type 58 request received from Scheduler@node2.supernodexp.hpc, sock=16
05/02/2018 08:52:36;0100;Server@node2;Req;;Type 20 request received from Scheduler@node2.supernodexp.hpc, sock=16
05/02/2018 08:52:36;0100;Server@node2;Req;;Type 51 request received from Scheduler@node2.supernodexp.hpc, sock=16
05/02/2018 08:52:36;0100;Server@node2;Req;;Type 23 request received from Scheduler@node2.supernodexp.hpc, sock=16
05/02/2018 08:52:36;0008;Server@node2;Job;13248.node2.supernodexp.hpc;Job Run at request of Scheduler@node2.supernodexp.hpc on exec_vnode (node3:ncpus=16:mpiprocs=16:mem=8388608kb)
05/02/2018 08:52:36;0001;Server@node2;Svr;Server@node2;Success (0) in req_runjob2, return value of svr_startjob is 0
05/02/2018 08:52:40;0080;Server@node2;Job;13246.node2.supernodexp.hpc;Obit received momhop:1 serverhop:1 state:4 substate:42
05/02/2018 08:52:41;0010;Server@node2;Job;13246.node2.supernodexp.hpc;Exit_status=0 resources_used.cpupercent=1042 resources_used.cput=01:02:50 resources_used.mem=1685236kb resources_used.ncpus=48 resources_used.vmem=15428728kb resources_used.walltime=00:03:03
05/02/2018 08:52:41;0100;Server@node2;Job;13246.node2.supernodexp.hpc;dequeuing from workq, state 5
05/02/2018 08:52:41;0040;Server@node2;Svr;node2.supernodexp.hpc;Scheduler sent command 2
05/02/2018 08:52:41;0040;Server@node2;Svr;node2.supernodexp.hpc;Scheduler sent command 0
05/02/2018 08:52:41;0100;Server@node2;Req;;Type 21 request received from Scheduler@node2.supernodexp.hpc, sock=16
05/02/2018 08:52:41;0100;Server@node2;Req;;Type 81 request received from Scheduler@node2.supernodexp.hpc, sock=16
05/02/2018 08:52:41;0100;Server@node2;Req;;Type 71 request received from Scheduler@node2.supernodexp.hpc, sock=16
05/02/2018 08:52:41;0100;Server@node2;Req;;Type 58 request received from Scheduler@node2.supernodexp.hpc, sock=16
05/02/2018 08:52:41;0100;Server@node2;Req;;Type 20 request received from Scheduler@node2.supernodexp.hpc, sock=16
05/02/2018 08:52:41;0100;Server@node2;Req;;Type 51 request received from Scheduler@node2.supernodexp.hpc, sock=16
05/02/2018 08:53:48;0100;Server@node2;Req;;Type 0 request received from ctminh@node2.supernodexp.hpc, sock=16
05/02/2018 08:53:48;0100;Server@node2;Req;;Type 49 request received from ctminh@node2.supernodexp.hpc, sock=19
05/02/2018 08:53:48;0100;Server@node2;Req;;Type 21 request received from ctminh@node2.supernodexp.hpc, sock=16
05/02/2018 08:53:48;0100;Server@node2;Req;;Type 19 request received from ctminh@node2.supernodexp.hpc, sock=16
05/02/2018 08:53:51;0100;Server@node2;Req;;Type 0 request received from ctminh@node2.supernodexp.hpc, sock=16
05/02/2018 08:53:51;0100;Server@node2;Req;;Type 49 request received from ctminh@node2.supernodexp.hpc, sock=19
05/02/2018 08:53:51;0100;Server@node2;Req;;Type 21 request received from ctminh@node2.supernodexp.hpc, sock=16
05/02/2018 08:53:51;0100;Server@node2;Req;;Type 19 request received from ctminh@node2.supernodexp.hpc, sock=16
05/02/2018 08:54:12;0080;Server@node2;Job;13247.node2.supernodexp.hpc;Obit received momhop:1 serverhop:1 state:4 substate:42
05/02/2018 08:54:13;0010;Server@node2;Job;13247.node2.supernodexp.hpc;Exit_status=0 resources_used.cpupercent=1742 resources_used.cput=00:38:03 resources_used.mem=1645296kb resources_used.ncpus=24 resources_used.vmem=15834396kb resources_used.walltime=00:01:40
05/02/2018 08:54:13;0100;Server@node2;Job;13247.node2.supernodexp.hpc;dequeuing from workq, state 5
05/02/2018 08:54:13;0040;Server@node2;Svr;node2.supernodexp.hpc;Scheduler sent command 2
05/02/2018 08:54:13;0040;Server@node2;Svr;node2.supernodexp.hpc;Scheduler sent command 0
05/02/2018 08:54:13;0100;Server@node2;Req;;Type 21 request received from Scheduler@node2.supernodexp.hpc, sock=16
05/02/2018 08:54:13;0100;Server@node2;Req;;Type 81 request received from Scheduler@node2.supernodexp.hpc, sock=16
05/02/2018 08:54:13;0100;Server@node2;Req;;Type 71 request received from Scheduler@node2.supernodexp.hpc, sock=16
05/02/2018 08:54:13;0100;Server@node2;Req;;Type 58 request received from Scheduler@node2.supernodexp.hpc, sock=16
05/02/2018 08:54:13;0100;Server@node2;Req;;Type 20 request received from Scheduler@node2.supernodexp.hpc, sock=16
05/02/2018 08:54:13;0100;Server@node2;Req;;Type 51 request received from Scheduler@node2.supernodexp.hpc, sock=16
05/02/2018 08:54:21;0080;Server@node2;Job;13249.node2.supernodexp.hpc;Obit received momhop:1 serverhop:1 state:4 substate:42
05/02/2018 08:54:22;0010;Server@node2;Job;13249.node2.supernodexp.hpc;Exit_status=0 resources_used.cpupercent=2441 resources_used.cput=01:51:15 resources_used.mem=3250204kb resources_used.ncpus=48 resources_used.vmem=33619952kb resources_used.walltime=00:02:28
05/02/2018 08:54:22;0100;Server@node2;Job;13249.node2.supernodexp.hpc;dequeuing from workq, state 5
05/02/2018 08:54:22;0040;Server@node2;Svr;node2.supernodexp.hpc;Scheduler sent command 2
05/02/2018 08:54:22;0040;Server@node2;Svr;node2.supernodexp.hpc;Scheduler sent command 0
05/02/2018 08:54:22;0100;Server@node2;Req;;Type 21 request received from Scheduler@node2.supernodexp.hpc, sock=16
05/02/2018 08:54:22;0100;Server@node2;Req;;Type 81 request received from Scheduler@node2.supernodexp.hpc, sock=16
05/02/2018 08:54:22;0100;Server@node2;Req;;Type 71 request received from Scheduler@node2.supernodexp.hpc, sock=16
05/02/2018 08:54:22;0100;Server@node2;Req;;Type 58 request received from Scheduler@node2.supernodexp.hpc, sock=16
05/02/2018 08:54:22;0100;Server@node2;Req;;Type 20 request received from Scheduler@node2.supernodexp.hpc, sock=16
05/02/2018 08:54:22;0100;Server@node2;Req;;Type 51 request received from Scheduler@node2.supernodexp.hpc, sock=16
05/02/2018 08:54:26;0100;Server@node2;Req;;Type 0 request received from ctminh@node2.supernodexp.hpc, sock=16
05/02/2018 08:54:26;0100;Server@node2;Req;;Type 49 request received from ctminh@node2.supernodexp.hpc, sock=19
05/02/2018 08:54:26;0100;Server@node2;Req;;Type 21 request received from ctminh@node2.supernodexp.hpc, sock=16
05/02/2018 08:54:26;0100;Server@node2;Req;;Type 19 request received from ctminh@node2.supernodexp.hpc, sock=16
05/02/2018 08:54:50;0080;Server@node2;Job;13248.node2.supernodexp.hpc;Obit received momhop:1 serverhop:1 state:4 substate:42
05/02/2018 08:54:51;0010;Server@node2;Job;13248.node2.supernodexp.hpc;Exit_status=0 resources_used.cpupercent=609 resources_used.cput=00:33:48 resources_used.mem=1115032kb resources_used.ncpus=16 resources_used.vmem=9812008kb resources_used.walltime=00:02:14
05/02/2018 08:54:51;0100;Server@node2;Job;13248.node2.supernodexp.hpc;dequeuing from workq, state 5
05/02/2018 08:54:51;0040;Server@node2;Svr;node2.supernodexp.hpc;Scheduler sent command 2
05/02/2018 08:54:51;0040;Server@node2;Svr;node2.supernodexp.hpc;Scheduler sent command 0
05/02/2018 08:54:51;0100;Server@node2;Req;;Type 21 request received from Scheduler@node2.supernodexp.hpc, sock=16
05/02/2018 08:54:51;0100;Server@node2;Req;;Type 81 request received from Scheduler@node2.supernodexp.hpc, sock=16
05/02/2018 08:54:51;0100;Server@node2;Req;;Type 71 request received from Scheduler@node2.supernodexp.hpc, sock=16
05/02/2018 08:54:51;0100;Server@node2;Req;;Type 58 request received from Scheduler@node2.supernodexp.hpc, sock=16
05/02/2018 08:54:51;0100;Server@node2;Req;;Type 20 request received from Scheduler@node2.supernodexp.hpc, sock=16
05/02/2018 08:54:51;0100;Server@node2;Req;;Type 51 request received from Scheduler@node2.supernodexp.hpc, sock=16
05/02/2018 08:55:22;0100;Server@node2;Req;;Type 0 request received from ctminh@node2.supernodexp.hpc, sock=16
05/02/2018 08:55:22;0100;Server@node2;Req;;Type 49 request received from ctminh@node2.supernodexp.hpc, sock=19
05/02/2018 08:55:22;0100;Server@node2;Req;;Type 21 request received from ctminh@node2.supernodexp.hpc, sock=16
05/02/2018 08:55:22;0100;Server@node2;Req;;Type 19 request received from ctminh@node2.supernodexp.hpc, sock=16
05/02/2018 08:57:26;0100;Server@node2;Req;;Type 0 request received from ctminh@node2.supernodexp.hpc, sock=16
05/02/2018 08:57:26;0100;Server@node2;Req;;Type 49 request received from ctminh@node2.supernodexp.hpc, sock=19
05/02/2018 08:57:26;0100;Server@node2;Req;;Type 21 request received from ctminh@node2.supernodexp.hpc, sock=16
05/02/2018 08:57:26;0100;Server@node2;Req;;Type 1 request received from ctminh@node2.supernodexp.hpc, sock=16
05/02/2018 08:57:26;0100;Server@node2;Req;;Type 3 request received from ctminh@node2.supernodexp.hpc, sock=16
05/02/2018 08:57:26;0100;Server@node2;Req;;Type 5 request received from ctminh@node2.supernodexp.hpc, sock=16
05/02/2018 08:57:26;0100;Server@node2;Job;13250.node2.supernodexp.hpc;enqueuing into workq, state 1 hop 1
05/02/2018 08:57:26;0008;Server@node2;Job;13250.node2.supernodexp.hpc;Job Queued at request of ctminh@node2.supernodexp.hpc, owner = ctminh@node2.supernodexp.hpc, job name = telemac1, queue = workq
05/02/2018 08:57:26;0040;Server@node2;Svr;node2.supernodexp.hpc;Scheduler sent command 1
05/02/2018 08:57:26;0040;Server@node2;Svr;node2.supernodexp.hpc;Scheduler sent command 0
05/02/2018 08:57:26;0100;Server@node2;Req;;Type 21 request received from Scheduler@node2.supernodexp.hpc, sock=19
05/02/2018 08:57:26;0100;Server@node2;Req;;Type 81 request received from Scheduler@node2.supernodexp.hpc, sock=19
05/02/2018 08:57:26;0100;Server@node2;Req;;Type 71 request received from Scheduler@node2.supernodexp.hpc, sock=19
05/02/2018 08:57:26;0100;Server@node2;Req;;Type 58 request received from Scheduler@node2.supernodexp.hpc, sock=19
05/02/2018 08:57:27;0100;Server@node2;Req;;Type 20 request received from Scheduler@node2.supernodexp.hpc, sock=19
05/02/2018 08:57:27;0100;Server@node2;Req;;Type 51 request received from Scheduler@node2.supernodexp.hpc, sock=19
05/02/2018 08:57:27;0100;Server@node2;Req;;Type 23 request received from Scheduler@node2.supernodexp.hpc, sock=19
05/02/2018 08:57:27;0008;Server@node2;Job;13250.node2.supernodexp.hpc;Job Run at request of Scheduler@node2.supernodexp.hpc on exec_vnode (node3:ncpus=24:mpiprocs=24:mem=2097152kb)
05/02/2018 08:57:27;0001;Server@node2;Svr;Server@node2;Success (0) in req_runjob2, return value of svr_startjob is 0
05/02/2018 08:57:31;0100;Server@node2;Req;;Type 0 request received from ctminh@node2.supernodexp.hpc, sock=19
05/02/2018 08:57:31;0100;Server@node2;Req;;Type 49 request received from ctminh@node2.supernodexp.hpc, sock=20
05/02/2018 08:57:31;0100;Server@node2;Req;;Type 21 request received from ctminh@node2.supernodexp.hpc, sock=19
05/02/2018 08:57:31;0100;Server@node2;Req;;Type 19 request received from ctminh@node2.supernodexp.hpc, sock=19
05/02/2018 08:59:20;0080;Server@node2;Job;13250.node2.supernodexp.hpc;Obit received momhop:1 serverhop:1 state:4 substate:42
05/02/2018 08:59:21;0010;Server@node2;Job;13250.node2.supernodexp.hpc;Exit_status=0 resources_used.cpupercent=1257 resources_used.cput=00:42:20 resources_used.mem=1642460kb resources_used.ncpus=24 resources_used.vmem=15000428kb resources_used.walltime=00:01:55
05/02/2018 08:59:21;0100;Server@node2;Job;13250.node2.supernodexp.hpc;dequeuing from workq, state 5
05/02/2018 08:59:21;0040;Server@node2;Svr;node2.supernodexp.hpc;Scheduler sent command 2
05/02/2018 08:59:21;0040;Server@node2;Svr;node2.supernodexp.hpc;Scheduler sent command 0
05/02/2018 08:59:21;0100;Server@node2;Req;;Type 21 request received from Scheduler@node2.supernodexp.hpc, sock=16
05/02/2018 08:59:21;0100;Server@node2;Req;;Type 81 request received from Scheduler@node2.supernodexp.hpc, sock=16
05/02/2018 08:59:21;0100;Server@node2;Req;;Type 71 request received from Scheduler@node2.supernodexp.hpc, sock=16
05/02/2018 08:59:21;0100;Server@node2;Req;;Type 58 request received from Scheduler@node2.supernodexp.hpc, sock=16
05/02/2018 08:59:21;0100;Server@node2;Req;;Type 20 request received from Scheduler@node2.supernodexp.hpc, sock=16
05/02/2018 08:59:21;0100;Server@node2;Req;;Type 51 request received from Scheduler@node2.supernodexp.hpc, sock=16
05/02/2018 09:00:00;0100;Server@node2;Req;;Type 0 request received from ctminh@node2.supernodexp.hpc, sock=16
05/02/2018 09:00:00;0100;Server@node2;Req;;Type 49 request received from ctminh@node2.supernodexp.hpc, sock=19
05/02/2018 09:00:00;0100;Server@node2;Req;;Type 21 request received from ctminh@node2.supernodexp.hpc, sock=16
05/02/2018 09:00:00;0100;Server@node2;Req;;Type 19 request received from ctminh@node2.supernodexp.hpc, sock=16
05/02/2018 09:00:03;0100;Server@node2;Req;;Type 0 request received from ctminh@node2.supernodexp.hpc, sock=16
05/02/2018 09:00:03;0100;Server@node2;Req;;Type 49 request received from ctminh@node2.supernodexp.hpc, sock=19
05/02/2018 09:00:03;0100;Server@node2;Req;;Type 21 request received from ctminh@node2.supernodexp.hpc, sock=16
05/02/2018 09:00:03;0100;Server@node2;Req;;Type 1 request received from ctminh@node2.supernodexp.hpc, sock=16
05/02/2018 09:00:03;0100;Server@node2;Req;;Type 3 request received from ctminh@node2.supernodexp.hpc, sock=16
05/02/2018 09:00:03;0100;Server@node2;Req;;Type 5 request received from ctminh@node2.supernodexp.hpc, sock=16
05/02/2018 09:00:03;0100;Server@node2;Job;13251.node2.supernodexp.hpc;enqueuing into workq, state 1 hop 1
05/02/2018 09:00:03;0008;Server@node2;Job;13251.node2.supernodexp.hpc;Job Queued at request of ctminh@node2.supernodexp.hpc, owner = ctminh@node2.supernodexp.hpc, job name = telemac1, queue = workq
05/02/2018 09:00:03;0040;Server@node2;Svr;node2.supernodexp.hpc;Scheduler sent command 1
05/02/2018 09:00:03;0040;Server@node2;Svr;node2.supernodexp.hpc;Scheduler sent command 0
05/02/2018 09:00:03;0100;Server@node2;Req;;Type 21 request received from Scheduler@node2.supernodexp.hpc, sock=19
05/02/2018 09:00:03;0100;Server@node2;Req;;Type 81 request received from Scheduler@node2.supernodexp.hpc, sock=19
05/02/2018 09:00:03;0100;Server@node2;Req;;Type 71 request received from Scheduler@node2.supernodexp.hpc, sock=19
05/02/2018 09:00:03;0100;Server@node2;Req;;Type 58 request received from Scheduler@node2.supernodexp.hpc, sock=19
05/02/2018 09:00:03;0100;Server@node2;Req;;Type 20 request received from Scheduler@node2.supernodexp.hpc, sock=19
05/02/2018 09:00:03;0100;Server@node2;Req;;Type 51 request received from Scheduler@node2.supernodexp.hpc, sock=19
05/02/2018 09:00:03;0100;Server@node2;Req;;Type 23 request received from Scheduler@node2.supernodexp.hpc, sock=19
05/02/2018 09:00:03;0008;Server@node2;Job;13251.node2.supernodexp.hpc;Job Run at request of Scheduler@node2.supernodexp.hpc on exec_vnode (node3:ncpus=24:mpiprocs=24:mem=2097152kb)
05/02/2018 09:00:03;0001;Server@node2;Svr;Server@node2;Success (0) in req_runjob2, return value of svr_startjob is 0
05/02/2018 09:00:08;0100;Server@node2;Req;;Type 1 request received from ctminh@node2.supernodexp.hpc, sock=16
05/02/2018 09:00:08;0100;Server@node2;Req;;Type 3 request received from ctminh@node2.supernodexp.hpc, sock=16
05/02/2018 09:00:08;0100;Server@node2;Req;;Type 5 request received from ctminh@node2.supernodexp.hpc, sock=16
05/02/2018 09:00:08;0100;Server@node2;Job;13252.node2.supernodexp.hpc;enqueuing into workq, state 1 hop 1
05/02/2018 09:00:08;0008;Server@node2;Job;13252.node2.supernodexp.hpc;Job Queued at request of ctminh@node2.supernodexp.hpc, owner = ctminh@node2.supernodexp.hpc, job name = telemac1, queue = workq
05/02/2018 09:00:08;0040;Server@node2;Svr;node2.supernodexp.hpc;Scheduler sent command 1
05/02/2018 09:00:08;0040;Server@node2;Svr;node2.supernodexp.hpc;Scheduler sent command 0
05/02/2018 09:00:08;0100;Server@node2;Req;;Type 21 request received from Scheduler@node2.supernodexp.hpc, sock=19
05/02/2018 09:00:08;0100;Server@node2;Req;;Type 81 request received from Scheduler@node2.supernodexp.hpc, sock=19
05/02/2018 09:00:08;0100;Server@node2;Req;;Type 71 request received from Scheduler@node2.supernodexp.hpc, sock=19
05/02/2018 09:00:08;0100;Server@node2;Req;;Type 58 request received from Scheduler@node2.supernodexp.hpc, sock=19
05/02/2018 09:00:08;0100;Server@node2;Req;;Type 20 request received from Scheduler@node2.supernodexp.hpc, sock=19
05/02/2018 09:00:08;0100;Server@node2;Req;;Type 51 request received from Scheduler@node2.supernodexp.hpc, sock=19
05/02/2018 09:00:08;0100;Server@node2;Req;;Type 23 request received from Scheduler@node2.supernodexp.hpc, sock=19
05/02/2018 09:00:08;0008;Server@node2;Job;13252.node2.supernodexp.hpc;Job Run at request of Scheduler@node2.supernodexp.hpc on exec_vnode (node3:ncpus=24:mpiprocs=24:mem=2097152kb)
05/02/2018 09:00:08;0001;Server@node2;Svr;Server@node2;Success (0) in req_runjob2, return value of svr_startjob is 0
05/02/2018 09:00:13;0100;Server@node2;Req;;Type 1 request received from ctminh@node2.supernodexp.hpc, sock=16
05/02/2018 09:00:13;0100;Server@node2;Req;;Type 3 request received from ctminh@node2.supernodexp.hpc, sock=16
05/02/2018 09:00:13;0100;Server@node2;Req;;Type 5 request received from ctminh@node2.supernodexp.hpc, sock=16
05/02/2018 09:00:13;0100;Server@node2;Job;13253.node2.supernodexp.hpc;enqueuing into workq, state 1 hop 1
05/02/2018 09:00:13;0008;Server@node2;Job;13253.node2.supernodexp.hpc;Job Queued at request of ctminh@node2.supernodexp.hpc, owner = ctminh@node2.supernodexp.hpc, job name = telemac2, queue = workq
05/02/2018 09:00:13;0040;Server@node2;Svr;node2.supernodexp.hpc;Scheduler sent command 1
05/02/2018 09:00:13;0040;Server@node2;Svr;node2.supernodexp.hpc;Scheduler sent command 0
05/02/2018 09:00:13;0100;Server@node2;Req;;Type 21 request received from Scheduler@node2.supernodexp.hpc, sock=19
05/02/2018 09:00:13;0100;Server@node2;Req;;Type 81 request received from Scheduler@node2.supernodexp.hpc, sock=19
05/02/2018 09:00:13;0100;Server@node2;Req;;Type 71 request received from Scheduler@node2.supernodexp.hpc, sock=19
05/02/2018 09:00:13;0100;Server@node2;Req;;Type 58 request received from Scheduler@node2.supernodexp.hpc, sock=19
05/02/2018 09:00:13;0100;Server@node2;Req;;Type 20 request received from Scheduler@node2.supernodexp.hpc, sock=19
05/02/2018 09:00:13;0100;Server@node2;Req;;Type 51 request received from Scheduler@node2.supernodexp.hpc, sock=19
05/02/2018 09:00:13;0100;Server@node2;Req;;Type 23 request received from Scheduler@node2.supernodexp.hpc, sock=19
05/02/2018 09:00:13;0008;Server@node2;Job;13253.node2.supernodexp.hpc;Job Run at request of Scheduler@node2.supernodexp.hpc on exec_vnode (node14:ncpus=16:mpiprocs=16:mem=8388608kb)
05/02/2018 09:00:13;0001;Server@node2;Svr;Server@node2;Success (0) in req_runjob2, return value of svr_startjob is 0
05/02/2018 09:00:18;0100;Server@node2;Req;;Type 1 request received from ctminh@node2.supernodexp.hpc, sock=16
05/02/2018 09:00:18;0100;Server@node2;Req;;Type 3 request received from ctminh@node2.supernodexp.hpc, sock=16
05/02/2018 09:00:18;0100;Server@node2;Req;;Type 5 request received from ctminh@node2.supernodexp.hpc, sock=16
05/02/2018 09:00:18;0100;Server@node2;Job;13254.node2.supernodexp.hpc;enqueuing into workq, state 1 hop 1
05/02/2018 09:00:18;0008;Server@node2;Job;13254.node2.supernodexp.hpc;Job Queued at request of ctminh@node2.supernodexp.hpc, owner = ctminh@node2.supernodexp.hpc, job name = telemac2, queue = workq
05/02/2018 09:00:18;0040;Server@node2;Svr;node2.supernodexp.hpc;Scheduler sent command 1
05/02/2018 09:00:18;0040;Server@node2;Svr;node2.supernodexp.hpc;Scheduler sent command 0
05/02/2018 09:00:18;0100;Server@node2;Req;;Type 21 request received from Scheduler@node2.supernodexp.hpc, sock=19
05/02/2018 09:00:18;0100;Server@node2;Req;;Type 81 request received from Scheduler@node2.supernodexp.hpc, sock=19
05/02/2018 09:00:18;0100;Server@node2;Req;;Type 71 request received from Scheduler@node2.supernodexp.hpc, sock=19
05/02/2018 09:00:18;0100;Server@node2;Req;;Type 58 request received from Scheduler@node2.supernodexp.hpc, sock=19
05/02/2018 09:00:18;0100;Server@node2;Req;;Type 20 request received from Scheduler@node2.supernodexp.hpc, sock=19
05/02/2018 09:00:18;0100;Server@node2;Req;;Type 51 request received from Scheduler@node2.supernodexp.hpc, sock=19
05/02/2018 09:00:18;0100;Server@node2;Req;;Type 23 request received from Scheduler@node2.supernodexp.hpc, sock=19
05/02/2018 09:00:18;0008;Server@node2;Job;13254.node2.supernodexp.hpc;Job Run at request of Scheduler@node2.supernodexp.hpc on exec_vnode (node14:ncpus=16:mpiprocs=16:mem=8388608kb)
05/02/2018 09:00:18;0001;Server@node2;Svr;Server@node2;Success (0) in req_runjob2, return value of svr_startjob is 0
05/02/2018 09:00:23;0100;Server@node2;Req;;Type 1 request received from ctminh@node2.supernodexp.hpc, sock=16
05/02/2018 09:00:23;0100;Server@node2;Req;;Type 3 request received from ctminh@node2.supernodexp.hpc, sock=16
05/02/2018 09:00:23;0100;Server@node2;Req;;Type 5 request received from ctminh@node2.supernodexp.hpc, sock=16
05/02/2018 09:00:23;0100;Server@node2;Job;13255.node2.supernodexp.hpc;enqueuing into workq, state 1 hop 1
05/02/2018 09:00:23;0008;Server@node2;Job;13255.node2.supernodexp.hpc;Job Queued at request of ctminh@node2.supernodexp.hpc, owner = ctminh@node2.supernodexp.hpc, job name = telemac3, queue = workq
05/02/2018 09:00:23;0040;Server@node2;Svr;node2.supernodexp.hpc;Scheduler sent command 1
05/02/2018 09:00:23;0040;Server@node2;Svr;node2.supernodexp.hpc;Scheduler sent command 0
05/02/2018 09:00:23;0100;Server@node2;Req;;Type 21 request received from Scheduler@node2.supernodexp.hpc, sock=19
05/02/2018 09:00:23;0100;Server@node2;Req;;Type 81 request received from Scheduler@node2.supernodexp.hpc, sock=19
05/02/2018 09:00:23;0100;Server@node2;Req;;Type 71 request received from Scheduler@node2.supernodexp.hpc, sock=19
05/02/2018 09:00:23;0100;Server@node2;Req;;Type 58 request received from Scheduler@node2.supernodexp.hpc, sock=19
05/02/2018 09:00:23;0100;Server@node2;Req;;Type 20 request received from Scheduler@node2.supernodexp.hpc, sock=19
05/02/2018 09:00:23;0100;Server@node2;Req;;Type 51 request received from Scheduler@node2.supernodexp.hpc, sock=19
05/02/2018 09:00:23;0100;Server@node2;Req;;Type 23 request received from Scheduler@node2.supernodexp.hpc, sock=19
05/02/2018 09:00:23;0008;Server@node2;Job;13255.node2.supernodexp.hpc;Job Run at request of Scheduler@node2.supernodexp.hpc on exec_vnode (node13:ncpus=24:mpiprocs=24:mem=4194304kb)+(node13:ncpus=24:mpiprocs=24:mem=4194304kb)
05/02/2018 09:00:23;0001;Server@node2;Svr;Server@node2;Success (0) in req_runjob2, return value of svr_startjob is 0
05/02/2018 09:00:28;0100;Server@node2;Req;;Type 1 request received from ctminh@node2.supernodexp.hpc, sock=16
05/02/2018 09:00:28;0100;Server@node2;Req;;Type 3 request received from ctminh@node2.supernodexp.hpc, sock=16
05/02/2018 09:00:28;0100;Server@node2;Req;;Type 5 request received from ctminh@node2.supernodexp.hpc, sock=16
05/02/2018 09:00:28;0100;Server@node2;Job;13256.node2.supernodexp.hpc;enqueuing into workq, state 1 hop 1
05/02/2018 09:00:28;0008;Server@node2;Job;13256.node2.supernodexp.hpc;Job Queued at request of ctminh@node2.supernodexp.hpc, owner = ctminh@node2.supernodexp.hpc, job name = telemac3, queue = workq
05/02/2018 09:00:28;0040;Server@node2;Svr;node2.supernodexp.hpc;Scheduler sent command 1
05/02/2018 09:00:28;0040;Server@node2;Svr;node2.supernodexp.hpc;Scheduler sent command 0
05/02/2018 09:00:28;0100;Server@node2;Req;;Type 21 request received from Scheduler@node2.supernodexp.hpc, sock=19
05/02/2018 09:00:28;0100;Server@node2;Req;;Type 81 request received from Scheduler@node2.supernodexp.hpc, sock=19
05/02/2018 09:00:28;0100;Server@node2;Req;;Type 71 request received from Scheduler@node2.supernodexp.hpc, sock=19
05/02/2018 09:00:28;0100;Server@node2;Req;;Type 58 request received from Scheduler@node2.supernodexp.hpc, sock=19
05/02/2018 09:00:28;0100;Server@node2;Req;;Type 20 request received from Scheduler@node2.supernodexp.hpc, sock=19
05/02/2018 09:00:28;0100;Server@node2;Req;;Type 51 request received from Scheduler@node2.supernodexp.hpc, sock=19
05/02/2018 09:00:28;0100;Server@node2;Req;;Type 11 request received from Scheduler@node2.supernodexp.hpc, sock=19
05/02/2018 09:00:28;0008;Server@node2;Job;13256.node2.supernodexp.hpc;Job Modified at request of Scheduler@node2.supernodexp.hpc
05/02/2018 09:00:33;0100;Server@node2;Req;;Type 1 request received from ctminh@node2.supernodexp.hpc, sock=16
05/02/2018 09:00:33;0100;Server@node2;Req;;Type 3 request received from ctminh@node2.supernodexp.hpc, sock=16
05/02/2018 09:00:33;0100;Server@node2;Req;;Type 5 request received from ctminh@node2.supernodexp.hpc, sock=16
05/02/2018 09:00:33;0100;Server@node2;Job;13257.node2.supernodexp.hpc;enqueuing into workq, state 1 hop 1
05/02/2018 09:00:33;0008;Server@node2;Job;13257.node2.supernodexp.hpc;Job Queued at request of ctminh@node2.supernodexp.hpc, owner = ctminh@node2.supernodexp.hpc, job name = telemac1, queue = workq
05/02/2018 09:00:33;0040;Server@node2;Svr;node2.supernodexp.hpc;Scheduler sent command 1
05/02/2018 09:00:33;0040;Server@node2;Svr;node2.supernodexp.hpc;Scheduler sent command 0
05/02/2018 09:00:33;0100;Server@node2;Req;;Type 21 request received from Scheduler@node2.supernodexp.hpc, sock=19
05/02/2018 09:00:33;0100;Server@node2;Req;;Type 81 request received from Scheduler@node2.supernodexp.hpc, sock=19
05/02/2018 09:00:33;0100;Server@node2;Req;;Type 71 request received from Scheduler@node2.supernodexp.hpc, sock=19
05/02/2018 09:00:33;0100;Server@node2;Req;;Type 58 request received from Scheduler@node2.supernodexp.hpc, sock=19
05/02/2018 09:00:33;0100;Server@node2;Req;;Type 20 request received from Scheduler@node2.supernodexp.hpc, sock=19
05/02/2018 09:00:33;0100;Server@node2;Req;;Type 51 request received from Scheduler@node2.supernodexp.hpc, sock=19
05/02/2018 09:00:33;0100;Server@node2;Req;;Type 11 request received from Scheduler@node2.supernodexp.hpc, sock=19
05/02/2018 09:00:33;0008;Server@node2;Job;13257.node2.supernodexp.hpc;Job Modified at request of Scheduler@node2.supernodexp.hpc
05/02/2018 09:00:35;0100;Server@node2;Req;;Type 0 request received from root@node2.supernodexp.hpc, sock=19
05/02/2018 09:00:35;0100;Server@node2;Req;;Type 49 request received from root@node2.supernodexp.hpc, sock=20
05/02/2018 09:00:35;0100;Server@node2;Req;;Type 21 request received from root@node2.supernodexp.hpc, sock=19
05/02/2018 09:00:35;0100;Server@node2;Req;;Type 19 request received from root@node2.supernodexp.hpc, sock=19
05/02/2018 09:00:38;0100;Server@node2;Req;;Type 1 request received from ctminh@node2.supernodexp.hpc, sock=16
05/02/2018 09:00:38;0100;Server@node2;Req;;Type 3 request received from ctminh@node2.supernodexp.hpc, sock=16
05/02/2018 09:00:38;0100;Server@node2;Req;;Type 5 request received from ctminh@node2.supernodexp.hpc, sock=16
05/02/2018 09:00:38;0100;Server@node2;Job;13258.node2.supernodexp.hpc;enqueuing into workq, state 1 hop 1
05/02/2018 09:00:38;0008;Server@node2;Job;13258.node2.supernodexp.hpc;Job Queued at request of ctminh@node2.supernodexp.hpc, owner = ctminh@node2.supernodexp.hpc, job name = telemac2, queue = workq
05/02/2018 09:00:38;0040;Server@node2;Svr;node2.supernodexp.hpc;Scheduler sent command 1
05/02/2018 09:00:38;0040;Server@node2;Svr;node2.supernodexp.hpc;Scheduler sent command 0
05/02/2018 09:00:38;0100;Server@node2;Req;;Type 21 request received from Scheduler@node2.supernodexp.hpc, sock=19
05/02/2018 09:00:38;0100;Server@node2;Req;;Type 81 request received from Scheduler@node2.supernodexp.hpc, sock=19
05/02/2018 09:00:38;0100;Server@node2;Req;;Type 71 request received from Scheduler@node2.supernodexp.hpc, sock=19
05/02/2018 09:00:38;0100;Server@node2;Req;;Type 58 request received from Scheduler@node2.supernodexp.hpc, sock=19
05/02/2018 09:00:38;0100;Server@node2;Req;;Type 20 request received from Scheduler@node2.supernodexp.hpc, sock=19
05/02/2018 09:00:38;0100;Server@node2;Req;;Type 51 request received from Scheduler@node2.supernodexp.hpc, sock=19
05/02/2018 09:00:38;0100;Server@node2;Req;;Type 11 request received from Scheduler@node2.supernodexp.hpc, sock=19
05/02/2018 09:00:38;0008;Server@node2;Job;13258.node2.supernodexp.hpc;Job Modified at request of Scheduler@node2.supernodexp.hpc
05/02/2018 09:00:40;0100;Server@node2;Req;;Type 0 request received from root@node2.supernodexp.hpc, sock=19
05/02/2018 09:00:40;0100;Server@node2;Req;;Type 49 request received from root@node2.supernodexp.hpc, sock=20
05/02/2018 09:00:40;0100;Server@node2;Req;;Type 21 request received from root@node2.supernodexp.hpc, sock=19
05/02/2018 09:00:40;0100;Server@node2;Req;;Type 19 request received from root@node2.supernodexp.hpc, sock=19
05/02/2018 09:00:41;0100;Server@node2;Req;;Type 0 request received from root@node2.supernodexp.hpc, sock=19
05/02/2018 09:00:41;0100;Server@node2;Req;;Type 49 request received from root@node2.supernodexp.hpc, sock=20
05/02/2018 09:00:41;0100;Server@node2;Req;;Type 21 request received from root@node2.supernodexp.hpc, sock=19
05/02/2018 09:00:41;0100;Server@node2;Req;;Type 19 request received from root@node2.supernodexp.hpc, sock=19
05/02/2018 09:00:43;0100;Server@node2;Req;;Type 0 request received from root@node2.supernodexp.hpc, sock=19
05/02/2018 09:00:43;0100;Server@node2;Req;;Type 49 request received from root@node2.supernodexp.hpc, sock=20
05/02/2018 09:00:43;0100;Server@node2;Req;;Type 21 request received from root@node2.supernodexp.hpc, sock=19
05/02/2018 09:00:43;0100;Server@node2;Req;;Type 19 request received from root@node2.supernodexp.hpc, sock=19
05/02/2018 09:00:43;0100;Server@node2;Req;;Type 1 request received from ctminh@node2.supernodexp.hpc, sock=16
05/02/2018 09:00:43;0100;Server@node2;Req;;Type 3 request received from ctminh@node2.supernodexp.hpc, sock=16
05/02/2018 09:00:43;0100;Server@node2;Req;;Type 5 request received from ctminh@node2.supernodexp.hpc, sock=16
05/02/2018 09:00:43;0100;Server@node2;Job;13259.node2.supernodexp.hpc;enqueuing into workq, state 1 hop 1
05/02/2018 09:00:43;0008;Server@node2;Job;13259.node2.supernodexp.hpc;Job Queued at request of ctminh@node2.supernodexp.hpc, owner = ctminh@node2.supernodexp.hpc, job name = telemac3, queue = workq
05/02/2018 09:00:43;0040;Server@node2;Svr;node2.supernodexp.hpc;Scheduler sent command 1
05/02/2018 09:00:43;0040;Server@node2;Svr;node2.supernodexp.hpc;Scheduler sent command 0
05/02/2018 09:00:43;0100;Server@node2;Req;;Type 21 request received from Scheduler@node2.supernodexp.hpc, sock=19
05/02/2018 09:00:43;0100;Server@node2;Req;;Type 81 request received from Scheduler@node2.supernodexp.hpc, sock=19
05/02/2018 09:00:43;0100;Server@node2;Req;;Type 71 request received from Scheduler@node2.supernodexp.hpc, sock=19
05/02/2018 09:00:43;0100;Server@node2;Req;;Type 58 request received from Scheduler@node2.supernodexp.hpc, sock=19
05/02/2018 09:00:43;0100;Server@node2;Req;;Type 20 request received from Scheduler@node2.supernodexp.hpc, sock=19
05/02/2018 09:00:43;0100;Server@node2;Req;;Type 51 request received from Scheduler@node2.supernodexp.hpc, sock=19
05/02/2018 09:00:43;0100;Server@node2;Req;;Type 11 request received from Scheduler@node2.supernodexp.hpc, sock=19
05/02/2018 09:00:43;0008;Server@node2;Job;13259.node2.supernodexp.hpc;Job Modified at request of Scheduler@node2.supernodexp.hpc
05/02/2018 09:00:45;0100;Server@node2;Req;;Type 0 request received from root@node2.supernodexp.hpc, sock=19
05/02/2018 09:00:45;0100;Server@node2;Req;;Type 49 request received from root@node2.supernodexp.hpc, sock=20
05/02/2018 09:00:45;0100;Server@node2;Req;;Type 21 request received from root@node2.supernodexp.hpc, sock=19
05/02/2018 09:00:45;0100;Server@node2;Req;;Type 19 request received from root@node2.supernodexp.hpc, sock=19
05/02/2018 09:00:46;0100;Server@node2;Req;;Type 0 request received from root@node2.supernodexp.hpc, sock=19
05/02/2018 09:00:46;0100;Server@node2;Req;;Type 49 request received from root@node2.supernodexp.hpc, sock=20
05/02/2018 09:00:46;0100;Server@node2;Req;;Type 21 request received from root@node2.supernodexp.hpc, sock=19
05/02/2018 09:00:46;0100;Server@node2;Req;;Type 19 request received from root@node2.supernodexp.hpc, sock=19
05/02/2018 09:00:57;0100;Server@node2;Req;;Type 0 request received from root@node2.supernodexp.hpc, sock=19
05/02/2018 09:00:57;0100;Server@node2;Req;;Type 49 request received from root@node2.supernodexp.hpc, sock=20
05/02/2018 09:00:57;0100;Server@node2;Req;;Type 21 request received from root@node2.supernodexp.hpc, sock=19
05/02/2018 09:00:57;0100;Server@node2;Req;;Type 19 request received from root@node2.supernodexp.hpc, sock=19
05/02/2018 09:00:59;0100;Server@node2;Req;;Type 0 request received from root@node2.supernodexp.hpc, sock=19
05/02/2018 09:00:59;0100;Server@node2;Req;;Type 49 request received from root@node2.supernodexp.hpc, sock=20
05/02/2018 09:00:59;0100;Server@node2;Req;;Type 21 request received from root@node2.supernodexp.hpc, sock=19
05/02/2018 09:00:59;0100;Server@node2;Req;;Type 19 request received from root@node2.supernodexp.hpc, sock=19
05/02/2018 09:01:01;0100;Server@node2;Req;;Type 0 request received from root@node2.supernodexp.hpc, sock=19
05/02/2018 09:01:01;0100;Server@node2;Req;;Type 49 request received from root@node2.supernodexp.hpc, sock=20
05/02/2018 09:01:01;0100;Server@node2;Req;;Type 21 request received from root@node2.supernodexp.hpc, sock=19
05/02/2018 09:01:01;0100;Server@node2;Req;;Type 19 request received from root@node2.supernodexp.hpc, sock=19
05/02/2018 09:01:08;0100;Server@node2;Req;;Type 0 request received from root@node2.supernodexp.hpc, sock=19
05/02/2018 09:01:08;0100;Server@node2;Req;;Type 49 request received from root@node2.supernodexp.hpc, sock=20
05/02/2018 09:01:08;0100;Server@node2;Req;;Type 21 request received from root@node2.supernodexp.hpc, sock=19
05/02/2018 09:01:08;0100;Server@node2;Req;;Type 19 request received from root@node2.supernodexp.hpc, sock=19
05/02/2018 09:01:09;0100;Server@node2;Req;;Type 0 request received from root@node2.supernodexp.hpc, sock=19
05/02/2018 09:01:09;0100;Server@node2;Req;;Type 49 request received from root@node2.supernodexp.hpc, sock=20
05/02/2018 09:01:09;0100;Server@node2;Req;;Type 21 request received from root@node2.supernodexp.hpc, sock=19
05/02/2018 09:01:09;0100;Server@node2;Req;;Type 19 request received from root@node2.supernodexp.hpc, sock=19
05/02/2018 09:01:10;0100;Server@node2;Req;;Type 0 request received from root@node2.supernodexp.hpc, sock=19
05/02/2018 09:01:10;0100;Server@node2;Req;;Type 49 request received from root@node2.supernodexp.hpc, sock=20
05/02/2018 09:01:10;0100;Server@node2;Req;;Type 21 request received from root@node2.supernodexp.hpc, sock=19
05/02/2018 09:01:10;0100;Server@node2;Req;;Type 19 request received from root@node2.supernodexp.hpc, sock=19
05/02/2018 09:01:11;0100;Server@node2;Req;;Type 0 request received from root@node2.supernodexp.hpc, sock=19
05/02/2018 09:01:11;0100;Server@node2;Req;;Type 49 request received from root@node2.supernodexp.hpc, sock=20
05/02/2018 09:01:11;0100;Server@node2;Req;;Type 21 request received from root@node2.supernodexp.hpc, sock=19
05/02/2018 09:01:11;0100;Server@node2;Req;;Type 19 request received from root@node2.supernodexp.hpc, sock=19
05/02/2018 09:01:12;0100;Server@node2;Req;;Type 0 request received from root@node2.supernodexp.hpc, sock=19
05/02/2018 09:01:12;0100;Server@node2;Req;;Type 49 request received from root@node2.supernodexp.hpc, sock=20
05/02/2018 09:01:12;0100;Server@node2;Req;;Type 21 request received from root@node2.supernodexp.hpc, sock=19
05/02/2018 09:01:12;0100;Server@node2;Req;;Type 19 request received from root@node2.supernodexp.hpc, sock=19
05/02/2018 09:01:13;0100;Server@node2;Req;;Type 0 request received from root@node2.supernodexp.hpc, sock=19
05/02/2018 09:01:13;0100;Server@node2;Req;;Type 49 request received from root@node2.supernodexp.hpc, sock=20
05/02/2018 09:01:13;0100;Server@node2;Req;;Type 21 request received from root@node2.supernodexp.hpc, sock=19
05/02/2018 09:01:13;0100;Server@node2;Req;;Type 19 request received from root@node2.supernodexp.hpc, sock=19
05/02/2018 09:01:14;0100;Server@node2;Req;;Type 0 request received from root@node2.supernodexp.hpc, sock=19
05/02/2018 09:01:14;0100;Server@node2;Req;;Type 49 request received from root@node2.supernodexp.hpc, sock=20
05/02/2018 09:01:14;0100;Server@node2;Req;;Type 21 request received from root@node2.supernodexp.hpc, sock=19
05/02/2018 09:01:14;0100;Server@node2;Req;;Type 19 request received from root@node2.supernodexp.hpc, sock=19
05/02/2018 09:01:16;0100;Server@node2;Req;;Type 0 request received from root@node2.supernodexp.hpc, sock=19
05/02/2018 09:01:16;0100;Server@node2;Req;;Type 49 request received from root@node2.supernodexp.hpc, sock=20
05/02/2018 09:01:16;0100;Server@node2;Req;;Type 21 request received from root@node2.supernodexp.hpc, sock=19
05/02/2018 09:01:16;0100;Server@node2;Req;;Type 19 request received from root@node2.supernodexp.hpc, sock=19
05/02/2018 09:01:17;0100;Server@node2;Req;;Type 0 request received from root@node2.supernodexp.hpc, sock=19
05/02/2018 09:01:17;0100;Server@node2;Req;;Type 49 request received from root@node2.supernodexp.hpc, sock=20
05/02/2018 09:01:17;0100;Server@node2;Req;;Type 21 request received from root@node2.supernodexp.hpc, sock=19
05/02/2018 09:01:17;0100;Server@node2;Req;;Type 19 request received from root@node2.supernodexp.hpc, sock=19
05/02/2018 09:01:18;0100;Server@node2;Req;;Type 0 request received from root@node2.supernodexp.hpc, sock=19
05/02/2018 09:01:18;0100;Server@node2;Req;;Type 49 request received from root@node2.supernodexp.hpc, sock=20
05/02/2018 09:01:18;0100;Server@node2;Req;;Type 21 request received from root@node2.supernodexp.hpc, sock=19
05/02/2018 09:01:18;0100;Server@node2;Req;;Type 19 request received from root@node2.supernodexp.hpc, sock=19
05/02/2018 09:01:19;0100;Server@node2;Req;;Type 0 request received from root@node2.supernodexp.hpc, sock=19
05/02/2018 09:01:19;0100;Server@node2;Req;;Type 49 request received from root@node2.supernodexp.hpc, sock=20
05/02/2018 09:01:19;0100;Server@node2;Req;;Type 21 request received from root@node2.supernodexp.hpc, sock=19
05/02/2018 09:01:19;0100;Server@node2;Req;;Type 19 request received from root@node2.supernodexp.hpc, sock=19
05/02/2018 09:01:20;0100;Server@node2;Req;;Type 0 request received from root@node2.supernodexp.hpc, sock=19
05/02/2018 09:01:20;0100;Server@node2;Req;;Type 49 request received from root@node2.supernodexp.hpc, sock=20
05/02/2018 09:01:20;0100;Server@node2;Req;;Type 21 request received from root@node2.supernodexp.hpc, sock=19
05/02/2018 09:01:20;0100;Server@node2;Req;;Type 19 request received from root@node2.supernodexp.hpc, sock=19
05/02/2018 09:01:21;0100;Server@node2;Req;;Type 0 request received from root@node2.supernodexp.hpc, sock=19
05/02/2018 09:01:21;0100;Server@node2;Req;;Type 49 request received from root@node2.supernodexp.hpc, sock=20
05/02/2018 09:01:21;0100;Server@node2;Req;;Type 21 request received from root@node2.supernodexp.hpc, sock=19
05/02/2018 09:01:21;0100;Server@node2;Req;;Type 19 request received from root@node2.supernodexp.hpc, sock=19
05/02/2018 09:01:22;0100;Server@node2;Req;;Type 0 request received from root@node2.supernodexp.hpc, sock=19
05/02/2018 09:01:22;0100;Server@node2;Req;;Type 49 request received from root@node2.supernodexp.hpc, sock=20
05/02/2018 09:01:22;0100;Server@node2;Req;;Type 21 request received from root@node2.supernodexp.hpc, sock=19
05/02/2018 09:01:22;0100;Server@node2;Req;;Type 19 request received from root@node2.supernodexp.hpc, sock=19
05/02/2018 09:01:23;0100;Server@node2;Req;;Type 0 request received from root@node2.supernodexp.hpc, sock=19
05/02/2018 09:01:23;0100;Server@node2;Req;;Type 49 request received from root@node2.supernodexp.hpc, sock=20
05/02/2018 09:01:23;0100;Server@node2;Req;;Type 21 request received from root@node2.supernodexp.hpc, sock=19
05/02/2018 09:01:23;0100;Server@node2;Req;;Type 19 request received from root@node2.supernodexp.hpc, sock=19
05/02/2018 09:01:24;0100;Server@node2;Req;;Type 0 request received from root@node2.supernodexp.hpc, sock=19
05/02/2018 09:01:24;0100;Server@node2;Req;;Type 49 request received from root@node2.supernodexp.hpc, sock=20
05/02/2018 09:01:24;0100;Server@node2;Req;;Type 21 request received from root@node2.supernodexp.hpc, sock=19
05/02/2018 09:01:24;0100;Server@node2;Req;;Type 19 request received from root@node2.supernodexp.hpc, sock=19
05/02/2018 09:01:24;0100;Server@node2;Req;;Type 0 request received from root@node2.supernodexp.hpc, sock=19
05/02/2018 09:01:24;0100;Server@node2;Req;;Type 49 request received from root@node2.supernodexp.hpc, sock=20
05/02/2018 09:01:24;0100;Server@node2;Req;;Type 21 request received from root@node2.supernodexp.hpc, sock=19
05/02/2018 09:01:24;0100;Server@node2;Req;;Type 19 request received from root@node2.supernodexp.hpc, sock=19
05/02/2018 09:01:25;0100;Server@node2;Req;;Type 0 request received from root@node2.supernodexp.hpc, sock=19
05/02/2018 09:01:25;0100;Server@node2;Req;;Type 49 request received from root@node2.supernodexp.hpc, sock=20
05/02/2018 09:01:25;0100;Server@node2;Req;;Type 21 request received from root@node2.supernodexp.hpc, sock=19
05/02/2018 09:01:25;0100;Server@node2;Req;;Type 19 request received from root@node2.supernodexp.hpc, sock=19
05/02/2018 09:01:26;0100;Server@node2;Req;;Type 0 request received from root@node2.supernodexp.hpc, sock=19
05/02/2018 09:01:26;0100;Server@node2;Req;;Type 49 request received from root@node2.supernodexp.hpc, sock=20
05/02/2018 09:01:26;0100;Server@node2;Req;;Type 21 request received from root@node2.supernodexp.hpc, sock=19
05/02/2018 09:01:26;0100;Server@node2;Req;;Type 19 request received from root@node2.supernodexp.hpc, sock=19
05/02/2018 09:01:27;0100;Server@node2;Req;;Type 0 request received from root@node2.supernodexp.hpc, sock=19
05/02/2018 09:01:27;0100;Server@node2;Req;;Type 49 request received from root@node2.supernodexp.hpc, sock=20
05/02/2018 09:01:27;0100;Server@node2;Req;;Type 21 request received from root@node2.supernodexp.hpc, sock=19
05/02/2018 09:01:27;0100;Server@node2;Req;;Type 19 request received from root@node2.supernodexp.hpc, sock=19
05/02/2018 09:01:28;0100;Server@node2;Req;;Type 0 request received from root@node2.supernodexp.hpc, sock=19
05/02/2018 09:01:28;0100;Server@node2;Req;;Type 49 request received from root@node2.supernodexp.hpc, sock=20
05/02/2018 09:01:28;0100;Server@node2;Req;;Type 21 request received from root@node2.supernodexp.hpc, sock=19
05/02/2018 09:01:28;0100;Server@node2;Req;;Type 19 request received from root@node2.supernodexp.hpc, sock=19
05/02/2018 09:01:29;0100;Server@node2;Req;;Type 0 request received from root@node2.supernodexp.hpc, sock=19
05/02/2018 09:01:29;0100;Server@node2;Req;;Type 49 request received from root@node2.supernodexp.hpc, sock=20
05/02/2018 09:01:29;0100;Server@node2;Req;;Type 21 request received from root@node2.supernodexp.hpc, sock=19
05/02/2018 09:01:29;0100;Server@node2;Req;;Type 19 request received from root@node2.supernodexp.hpc, sock=19
05/02/2018 09:01:30;0100;Server@node2;Req;;Type 0 request received from root@node2.supernodexp.hpc, sock=19
05/02/2018 09:01:30;0100;Server@node2;Req;;Type 49 request received from root@node2.supernodexp.hpc, sock=20
05/02/2018 09:01:30;0100;Server@node2;Req;;Type 21 request received from root@node2.supernodexp.hpc, sock=19
05/02/2018 09:01:30;0100;Server@node2;Req;;Type 19 request received from root@node2.supernodexp.hpc, sock=19
05/02/2018 09:01:31;0100;Server@node2;Req;;Type 0 request received from root@node2.supernodexp.hpc, sock=19
05/02/2018 09:01:31;0100;Server@node2;Req;;Type 49 request received from root@node2.supernodexp.hpc, sock=20
05/02/2018 09:01:31;0100;Server@node2;Req;;Type 21 request received from root@node2.supernodexp.hpc, sock=19
05/02/2018 09:01:31;0100;Server@node2;Req;;Type 19 request received from root@node2.supernodexp.hpc, sock=19
05/02/2018 09:01:32;0100;Server@node2;Req;;Type 0 request received from root@node2.supernodexp.hpc, sock=19
05/02/2018 09:01:32;0100;Server@node2;Req;;Type 49 request received from root@node2.supernodexp.hpc, sock=20
05/02/2018 09:01:32;0100;Server@node2;Req;;Type 21 request received from root@node2.supernodexp.hpc, sock=19
05/02/2018 09:01:32;0100;Server@node2;Req;;Type 19 request received from root@node2.supernodexp.hpc, sock=19
05/02/2018 09:01:33;0100;Server@node2;Req;;Type 0 request received from root@node2.supernodexp.hpc, sock=19
05/02/2018 09:01:33;0100;Server@node2;Req;;Type 49 request received from root@node2.supernodexp.hpc, sock=20
05/02/2018 09:01:33;0100;Server@node2;Req;;Type 21 request received from root@node2.supernodexp.hpc, sock=19
05/02/2018 09:01:33;0100;Server@node2;Req;;Type 19 request received from root@node2.supernodexp.hpc, sock=19
05/02/2018 09:01:33;0100;Server@node2;Req;;Type 0 request received from root@node2.supernodexp.hpc, sock=19
05/02/2018 09:01:33;0100;Server@node2;Req;;Type 49 request received from root@node2.supernodexp.hpc, sock=20
05/02/2018 09:01:33;0100;Server@node2;Req;;Type 21 request received from root@node2.supernodexp.hpc, sock=19
05/02/2018 09:01:33;0100;Server@node2;Req;;Type 19 request received from root@node2.supernodexp.hpc, sock=19
05/02/2018 09:01:34;0100;Server@node2;Req;;Type 0 request received from root@node2.supernodexp.hpc, sock=19
05/02/2018 09:01:34;0100;Server@node2;Req;;Type 49 request received from root@node2.supernodexp.hpc, sock=20
05/02/2018 09:01:34;0100;Server@node2;Req;;Type 21 request received from root@node2.supernodexp.hpc, sock=19
05/02/2018 09:01:34;0100;Server@node2;Req;;Type 19 request received from root@node2.supernodexp.hpc, sock=19
05/02/2018 09:01:35;0100;Server@node2;Req;;Type 0 request received from root@node2.supernodexp.hpc, sock=19
05/02/2018 09:01:35;0100;Server@node2;Req;;Type 49 request received from root@node2.supernodexp.hpc, sock=20
05/02/2018 09:01:35;0100;Server@node2;Req;;Type 21 request received from root@node2.supernodexp.hpc, sock=19
05/02/2018 09:01:35;0100;Server@node2;Req;;Type 19 request received from root@node2.supernodexp.hpc, sock=19
05/02/2018 09:01:36;0100;Server@node2;Req;;Type 0 request received from root@node2.supernodexp.hpc, sock=19
05/02/2018 09:01:36;0100;Server@node2;Req;;Type 49 request received from root@node2.supernodexp.hpc, sock=20
05/02/2018 09:01:36;0100;Server@node2;Req;;Type 21 request received from root@node2.supernodexp.hpc, sock=19
05/02/2018 09:01:36;0100;Server@node2;Req;;Type 19 request received from root@node2.supernodexp.hpc, sock=19
05/02/2018 09:01:37;0100;Server@node2;Req;;Type 0 request received from root@node2.supernodexp.hpc, sock=19
05/02/2018 09:01:37;0100;Server@node2;Req;;Type 49 request received from root@node2.supernodexp.hpc, sock=20
05/02/2018 09:01:37;0100;Server@node2;Req;;Type 21 request received from root@node2.supernodexp.hpc, sock=19
05/02/2018 09:01:37;0100;Server@node2;Req;;Type 19 request received from root@node2.supernodexp.hpc, sock=19
05/02/2018 09:01:41;0100;Server@node2;Req;;Type 0 request received from root@node2.supernodexp.hpc, sock=19
05/02/2018 09:01:41;0100;Server@node2;Req;;Type 49 request received from root@node2.supernodexp.hpc, sock=20
05/02/2018 09:01:41;0100;Server@node2;Req;;Type 21 request received from root@node2.supernodexp.hpc, sock=19
05/02/2018 09:01:41;0100;Server@node2;Req;;Type 19 request received from root@node2.supernodexp.hpc, sock=19
05/02/2018 09:01:41;0100;Server@node2;Req;;Type 0 request received from root@node2.supernodexp.hpc, sock=19
05/02/2018 09:01:41;0100;Server@node2;Req;;Type 49 request received from root@node2.supernodexp.hpc, sock=20
05/02/2018 09:01:41;0100;Server@node2;Req;;Type 21 request received from root@node2.supernodexp.hpc, sock=19
05/02/2018 09:01:41;0100;Server@node2;Req;;Type 19 request received from root@node2.supernodexp.hpc, sock=19
05/02/2018 09:01:44;0100;Server@node2;Req;;Type 0 request received from root@node2.supernodexp.hpc, sock=16
05/02/2018 09:01:44;0100;Server@node2;Req;;Type 49 request received from root@node2.supernodexp.hpc, sock=19
05/02/2018 09:01:44;0100;Server@node2;Req;;Type 21 request received from root@node2.supernodexp.hpc, sock=16
05/02/2018 09:01:44;0100;Server@node2;Req;;Type 19 request received from root@node2.supernodexp.hpc, sock=16
05/02/2018 09:01:45;0100;Server@node2;Req;;Type 0 request received from root@node2.supernodexp.hpc, sock=16
05/02/2018 09:01:45;0100;Server@node2;Req;;Type 49 request received from root@node2.supernodexp.hpc, sock=19
05/02/2018 09:01:45;0100;Server@node2;Req;;Type 21 request received from root@node2.supernodexp.hpc, sock=16
05/02/2018 09:01:45;0100;Server@node2;Req;;Type 19 request received from root@node2.supernodexp.hpc, sock=16
05/02/2018 09:01:48;0100;Server@node2;Req;;Type 0 request received from root@node2.supernodexp.hpc, sock=16
05/02/2018 09:01:48;0100;Server@node2;Req;;Type 49 request received from root@node2.supernodexp.hpc, sock=19
05/02/2018 09:01:48;0100;Server@node2;Req;;Type 21 request received from root@node2.supernodexp.hpc, sock=16
05/02/2018 09:01:48;0100;Server@node2;Req;;Type 19 request received from root@node2.supernodexp.hpc, sock=16
05/02/2018 09:01:49;0100;Server@node2;Req;;Type 0 request received from root@node2.supernodexp.hpc, sock=16
05/02/2018 09:01:49;0100;Server@node2;Req;;Type 49 request received from root@node2.supernodexp.hpc, sock=19
05/02/2018 09:01:49;0100;Server@node2;Req;;Type 21 request received from root@node2.supernodexp.hpc, sock=16
05/02/2018 09:01:49;0100;Server@node2;Req;;Type 19 request received from root@node2.supernodexp.hpc, sock=16
05/02/2018 09:01:50;0100;Server@node2;Req;;Type 0 request received from root@node2.supernodexp.hpc, sock=16
05/02/2018 09:01:50;0100;Server@node2;Req;;Type 49 request received from root@node2.supernodexp.hpc, sock=19
05/02/2018 09:01:50;0100;Server@node2;Req;;Type 21 request received from root@node2.supernodexp.hpc, sock=16
05/02/2018 09:01:50;0100;Server@node2;Req;;Type 19 request received from root@node2.supernodexp.hpc, sock=16
05/02/2018 09:01:51;0100;Server@node2;Req;;Type 0 request received from root@node2.supernodexp.hpc, sock=16
05/02/2018 09:01:51;0100;Server@node2;Req;;Type 49 request received from root@node2.supernodexp.hpc, sock=19
05/02/2018 09:01:51;0100;Server@node2;Req;;Type 21 request received from root@node2.supernodexp.hpc, sock=16
05/02/2018 09:01:51;0100;Server@node2;Req;;Type 19 request received from root@node2.supernodexp.hpc, sock=16
05/02/2018 09:01:52;0100;Server@node2;Req;;Type 0 request received from root@node2.supernodexp.hpc, sock=16
05/02/2018 09:01:52;0100;Server@node2;Req;;Type 49 request received from root@node2.supernodexp.hpc, sock=19
05/02/2018 09:01:52;0100;Server@node2;Req;;Type 21 request received from root@node2.supernodexp.hpc, sock=16
05/02/2018 09:01:52;0100;Server@node2;Req;;Type 19 request received from root@node2.supernodexp.hpc, sock=16
05/02/2018 09:01:52;0100;Server@node2;Req;;Type 0 request received from root@node2.supernodexp.hpc, sock=16
05/02/2018 09:01:52;0100;Server@node2;Req;;Type 49 request received from root@node2.supernodexp.hpc, sock=19
05/02/2018 09:01:52;0100;Server@node2;Req;;Type 21 request received from root@node2.supernodexp.hpc, sock=16
05/02/2018 09:01:52;0100;Server@node2;Req;;Type 19 request received from root@node2.supernodexp.hpc, sock=16
05/02/2018 09:01:53;0100;Server@node2;Req;;Type 0 request received from root@node2.supernodexp.hpc, sock=16
05/02/2018 09:01:53;0100;Server@node2;Req;;Type 49 request received from root@node2.supernodexp.hpc, sock=19
05/02/2018 09:01:53;0100;Server@node2;Req;;Type 21 request received from root@node2.supernodexp.hpc, sock=16
05/02/2018 09:01:53;0100;Server@node2;Req;;Type 19 request received from root@node2.supernodexp.hpc, sock=16
05/02/2018 09:01:53;0100;Server@node2;Req;;Type 0 request received from root@node2.supernodexp.hpc, sock=16
05/02/2018 09:01:53;0100;Server@node2;Req;;Type 49 request received from root@node2.supernodexp.hpc, sock=19
05/02/2018 09:01:53;0100;Server@node2;Req;;Type 21 request received from root@node2.supernodexp.hpc, sock=16
05/02/2018 09:01:53;0100;Server@node2;Req;;Type 19 request received from root@node2.supernodexp.hpc, sock=16
05/02/2018 09:01:54;0100;Server@node2;Req;;Type 0 request received from root@node2.supernodexp.hpc, sock=16
05/02/2018 09:01:54;0100;Server@node2;Req;;Type 49 request received from root@node2.supernodexp.hpc, sock=19
05/02/2018 09:01:54;0100;Server@node2;Req;;Type 21 request received from root@node2.supernodexp.hpc, sock=16
05/02/2018 09:01:54;0100;Server@node2;Req;;Type 19 request received from root@node2.supernodexp.hpc, sock=16
05/02/2018 09:01:55;0100;Server@node2;Req;;Type 0 request received from root@node2.supernodexp.hpc, sock=16
05/02/2018 09:01:55;0100;Server@node2;Req;;Type 49 request received from root@node2.supernodexp.hpc, sock=19
05/02/2018 09:01:55;0100;Server@node2;Req;;Type 21 request received from root@node2.supernodexp.hpc, sock=16
05/02/2018 09:01:55;0100;Server@node2;Req;;Type 19 request received from root@node2.supernodexp.hpc, sock=16
05/02/2018 09:01:56;0100;Server@node2;Req;;Type 0 request received from root@node2.supernodexp.hpc, sock=16
05/02/2018 09:01:56;0100;Server@node2;Req;;Type 49 request received from root@node2.supernodexp.hpc, sock=19
05/02/2018 09:01:56;0100;Server@node2;Req;;Type 21 request received from root@node2.supernodexp.hpc, sock=16
05/02/2018 09:01:56;0100;Server@node2;Req;;Type 19 request received from root@node2.supernodexp.hpc, sock=16
05/02/2018 09:01:56;0100;Server@node2;Req;;Type 0 request received from root@node2.supernodexp.hpc, sock=16
05/02/2018 09:01:56;0100;Server@node2;Req;;Type 49 request received from root@node2.supernodexp.hpc, sock=19
05/02/2018 09:01:56;0100;Server@node2;Req;;Type 21 request received from root@node2.supernodexp.hpc, sock=16
05/02/2018 09:01:56;0100;Server@node2;Req;;Type 19 request received from root@node2.supernodexp.hpc, sock=16
05/02/2018 09:01:57;0100;Server@node2;Req;;Type 0 request received from root@node2.supernodexp.hpc, sock=16
05/02/2018 09:01:57;0100;Server@node2;Req;;Type 49 request received from root@node2.supernodexp.hpc, sock=19
05/02/2018 09:01:57;0100;Server@node2;Req;;Type 21 request received from root@node2.supernodexp.hpc, sock=16
05/02/2018 09:01:57;0100;Server@node2;Req;;Type 19 request received from root@node2.supernodexp.hpc, sock=16
05/02/2018 09:01:58;0100;Server@node2;Req;;Type 0 request received from root@node2.supernodexp.hpc, sock=16
05/02/2018 09:01:58;0100;Server@node2;Req;;Type 49 request received from root@node2.supernodexp.hpc, sock=19
05/02/2018 09:01:58;0100;Server@node2;Req;;Type 21 request received from root@node2.supernodexp.hpc, sock=16
05/02/2018 09:01:58;0100;Server@node2;Req;;Type 19 request received from root@node2.supernodexp.hpc, sock=16
05/02/2018 09:01:59;0100;Server@node2;Req;;Type 0 request received from root@node2.supernodexp.hpc, sock=16
05/02/2018 09:01:59;0100;Server@node2;Req;;Type 49 request received from root@node2.supernodexp.hpc, sock=19
05/02/2018 09:01:59;0100;Server@node2;Req;;Type 21 request received from root@node2.supernodexp.hpc, sock=16
05/02/2018 09:01:59;0100;Server@node2;Req;;Type 19 request received from root@node2.supernodexp.hpc, sock=16
05/02/2018 09:02:00;0100;Server@node2;Req;;Type 0 request received from root@node2.supernodexp.hpc, sock=16
05/02/2018 09:02:00;0100;Server@node2;Req;;Type 49 request received from root@node2.supernodexp.hpc, sock=19
05/02/2018 09:02:00;0100;Server@node2;Req;;Type 21 request received from root@node2.supernodexp.hpc, sock=16
05/02/2018 09:02:00;0100;Server@node2;Req;;Type 19 request received from root@node2.supernodexp.hpc, sock=16
05/02/2018 09:02:01;0100;Server@node2;Req;;Type 0 request received from root@node2.supernodexp.hpc, sock=16
05/02/2018 09:02:01;0100;Server@node2;Req;;Type 49 request received from root@node2.supernodexp.hpc, sock=19
05/02/2018 09:02:01;0100;Server@node2;Req;;Type 21 request received from root@node2.supernodexp.hpc, sock=16
05/02/2018 09:02:01;0100;Server@node2;Req;;Type 19 request received from root@node2.supernodexp.hpc, sock=16
05/02/2018 09:02:02;0100;Server@node2;Req;;Type 0 request received from root@node2.supernodexp.hpc, sock=16
05/02/2018 09:02:02;0100;Server@node2;Req;;Type 49 request received from root@node2.supernodexp.hpc, sock=19
05/02/2018 09:02:02;0100;Server@node2;Req;;Type 21 request received from root@node2.supernodexp.hpc, sock=16
05/02/2018 09:02:02;0100;Server@node2;Req;;Type 19 request received from root@node2.supernodexp.hpc, sock=16
05/02/2018 09:02:03;0100;Server@node2;Req;;Type 0 request received from root@node2.supernodexp.hpc, sock=16
05/02/2018 09:02:03;0100;Server@node2;Req;;Type 49 request received from root@node2.supernodexp.hpc, sock=19
05/02/2018 09:02:03;0100;Server@node2;Req;;Type 21 request received from root@node2.supernodexp.hpc, sock=16
05/02/2018 09:02:03;0100;Server@node2;Req;;Type 19 request received from root@node2.supernodexp.hpc, sock=16
05/02/2018 09:02:04;0100;Server@node2;Req;;Type 0 request received from root@node2.supernodexp.hpc, sock=16
05/02/2018 09:02:04;0100;Server@node2;Req;;Type 49 request received from root@node2.supernodexp.hpc, sock=19
05/02/2018 09:02:04;0100;Server@node2;Req;;Type 21 request received from root@node2.supernodexp.hpc, sock=16
05/02/2018 09:02:04;0100;Server@node2;Req;;Type 19 request received from root@node2.supernodexp.hpc, sock=16
05/02/2018 09:02:05;0100;Server@node2;Req;;Type 0 request received from root@node2.supernodexp.hpc, sock=16
05/02/2018 09:02:05;0100;Server@node2;Req;;Type 49 request received from root@node2.supernodexp.hpc, sock=19
05/02/2018 09:02:05;0100;Server@node2;Req;;Type 21 request received from root@node2.supernodexp.hpc, sock=16
05/02/2018 09:02:05;0100;Server@node2;Req;;Type 19 request received from root@node2.supernodexp.hpc, sock=16
05/02/2018 09:02:06;0100;Server@node2;Req;;Type 0 request received from root@node2.supernodexp.hpc, sock=16
05/02/2018 09:02:06;0100;Server@node2;Req;;Type 49 request received from root@node2.supernodexp.hpc, sock=19
05/02/2018 09:02:06;0100;Server@node2;Req;;Type 21 request received from root@node2.supernodexp.hpc, sock=16
05/02/2018 09:02:06;0100;Server@node2;Req;;Type 19 request received from root@node2.supernodexp.hpc, sock=16
05/02/2018 09:02:08;0100;Server@node2;Req;;Type 0 request received from root@node2.supernodexp.hpc, sock=16
05/02/2018 09:02:08;0100;Server@node2;Req;;Type 49 request received from root@node2.supernodexp.hpc, sock=19
05/02/2018 09:02:08;0100;Server@node2;Req;;Type 21 request received from root@node2.supernodexp.hpc, sock=16
05/02/2018 09:02:08;0100;Server@node2;Req;;Type 19 request received from root@node2.supernodexp.hpc, sock=16
05/02/2018 09:02:09;0100;Server@node2;Req;;Type 0 request received from root@node2.supernodexp.hpc, sock=16
05/02/2018 09:02:09;0100;Server@node2;Req;;Type 49 request received from root@node2.supernodexp.hpc, sock=19
05/02/2018 09:02:09;0100;Server@node2;Req;;Type 21 request received from root@node2.supernodexp.hpc, sock=16
05/02/2018 09:02:09;0100;Server@node2;Req;;Type 19 request received from root@node2.supernodexp.hpc, sock=16
05/02/2018 09:02:10;0100;Server@node2;Req;;Type 0 request received from root@node2.supernodexp.hpc, sock=16
05/02/2018 09:02:10;0100;Server@node2;Req;;Type 49 request received from root@node2.supernodexp.hpc, sock=19
05/02/2018 09:02:10;0100;Server@node2;Req;;Type 21 request received from root@node2.supernodexp.hpc, sock=16
05/02/2018 09:02:10;0100;Server@node2;Req;;Type 19 request received from root@node2.supernodexp.hpc, sock=16
05/02/2018 09:02:11;0100;Server@node2;Req;;Type 0 request received from root@node2.supernodexp.hpc, sock=16
05/02/2018 09:02:11;0100;Server@node2;Req;;Type 49 request received from root@node2.supernodexp.hpc, sock=19
05/02/2018 09:02:11;0100;Server@node2;Req;;Type 21 request received from root@node2.supernodexp.hpc, sock=16
05/02/2018 09:02:11;0100;Server@node2;Req;;Type 19 request received from root@node2.supernodexp.hpc, sock=16
05/02/2018 09:02:12;0100;Server@node2;Req;;Type 0 request received from root@node2.supernodexp.hpc, sock=16
05/02/2018 09:02:12;0100;Server@node2;Req;;Type 49 request received from root@node2.supernodexp.hpc, sock=19
05/02/2018 09:02:12;0100;Server@node2;Req;;Type 21 request received from root@node2.supernodexp.hpc, sock=16
05/02/2018 09:02:12;0100;Server@node2;Req;;Type 19 request received from root@node2.supernodexp.hpc, sock=16
05/02/2018 09:02:13;0100;Server@node2;Req;;Type 0 request received from root@node2.supernodexp.hpc, sock=16
05/02/2018 09:02:13;0100;Server@node2;Req;;Type 49 request received from root@node2.supernodexp.hpc, sock=19
05/02/2018 09:02:13;0100;Server@node2;Req;;Type 21 request received from root@node2.supernodexp.hpc, sock=16
05/02/2018 09:02:13;0100;Server@node2;Req;;Type 19 request received from root@node2.supernodexp.hpc, sock=16
05/02/2018 09:02:13;0100;Server@node2;Req;;Type 0 request received from root@node2.supernodexp.hpc, sock=16
05/02/2018 09:02:13;0100;Server@node2;Req;;Type 49 request received from root@node2.supernodexp.hpc, sock=19
05/02/2018 09:02:13;0100;Server@node2;Req;;Type 21 request received from root@node2.supernodexp.hpc, sock=16
05/02/2018 09:02:13;0100;Server@node2;Req;;Type 19 request received from root@node2.supernodexp.hpc, sock=16
05/02/2018 09:02:14;0100;Server@node2;Req;;Type 0 request received from root@node2.supernodexp.hpc, sock=16
05/02/2018 09:02:14;0100;Server@node2;Req;;Type 49 request received from root@node2.supernodexp.hpc, sock=19
05/02/2018 09:02:14;0100;Server@node2;Req;;Type 21 request received from root@node2.supernodexp.hpc, sock=16
05/02/2018 09:02:14;0100;Server@node2;Req;;Type 19 request received from root@node2.supernodexp.hpc, sock=16
05/02/2018 09:02:15;0100;Server@node2;Req;;Type 0 request received from root@node2.supernodexp.hpc, sock=16
05/02/2018 09:02:15;0100;Server@node2;Req;;Type 49 request received from root@node2.supernodexp.hpc, sock=19
05/02/2018 09:02:15;0100;Server@node2;Req;;Type 21 request received from root@node2.supernodexp.hpc, sock=16
05/02/2018 09:02:15;0100;Server@node2;Req;;Type 19 request received from root@node2.supernodexp.hpc, sock=16
05/02/2018 09:02:16;0100;Server@node2;Req;;Type 0 request received from root@node2.supernodexp.hpc, sock=16
05/02/2018 09:02:16;0100;Server@node2;Req;;Type 49 request received from root@node2.supernodexp.hpc, sock=19
05/02/2018 09:02:16;0100;Server@node2;Req;;Type 21 request received from root@node2.supernodexp.hpc, sock=16
05/02/2018 09:02:16;0100;Server@node2;Req;;Type 19 request received from root@node2.supernodexp.hpc, sock=16
05/02/2018 09:02:17;0100;Server@node2;Req;;Type 0 request received from root@node2.supernodexp.hpc, sock=16
05/02/2018 09:02:17;0100;Server@node2;Req;;Type 49 request received from root@node2.supernodexp.hpc, sock=19
05/02/2018 09:02:17;0100;Server@node2;Req;;Type 21 request received from root@node2.supernodexp.hpc, sock=16
05/02/2018 09:02:17;0100;Server@node2;Req;;Type 19 request received from root@node2.supernodexp.hpc, sock=16
05/02/2018 09:02:18;0100;Server@node2;Req;;Type 0 request received from root@node2.supernodexp.hpc, sock=16
05/02/2018 09:02:18;0100;Server@node2;Req;;Type 49 request received from root@node2.supernodexp.hpc, sock=19
05/02/2018 09:02:18;0100;Server@node2;Req;;Type 21 request received from root@node2.supernodexp.hpc, sock=16
05/02/2018 09:02:18;0100;Server@node2;Req;;Type 19 request received from root@node2.supernodexp.hpc, sock=16
05/02/2018 09:02:19;0100;Server@node2;Req;;Type 0 request received from root@node2.supernodexp.hpc, sock=16
05/02/2018 09:02:19;0100;Server@node2;Req;;Type 49 request received from root@node2.supernodexp.hpc, sock=19
05/02/2018 09:02:19;0100;Server@node2;Req;;Type 21 request received from root@node2.supernodexp.hpc, sock=16
05/02/2018 09:02:19;0100;Server@node2;Req;;Type 19 request received from root@node2.supernodexp.hpc, sock=16
05/02/2018 09:02:19;0100;Server@node2;Req;;Type 0 request received from root@node2.supernodexp.hpc, sock=16
05/02/2018 09:02:19;0100;Server@node2;Req;;Type 49 request received from root@node2.supernodexp.hpc, sock=19
05/02/2018 09:02:19;0100;Server@node2;Req;;Type 21 request received from root@node2.supernodexp.hpc, sock=16
05/02/2018 09:02:19;0100;Server@node2;Req;;Type 19 request received from root@node2.supernodexp.hpc, sock=16
05/02/2018 09:02:20;0100;Server@node2;Req;;Type 0 request received from root@node2.supernodexp.hpc, sock=16
05/02/2018 09:02:20;0100;Server@node2;Req;;Type 49 request received from root@node2.supernodexp.hpc, sock=19
05/02/2018 09:02:20;0100;Server@node2;Req;;Type 21 request received from root@node2.supernodexp.hpc, sock=16
05/02/2018 09:02:20;0100;Server@node2;Req;;Type 19 request received from root@node2.supernodexp.hpc, sock=16
05/02/2018 09:02:21;0100;Server@node2;Req;;Type 0 request received from root@node2.supernodexp.hpc, sock=16
05/02/2018 09:02:21;0100;Server@node2;Req;;Type 49 request received from root@node2.supernodexp.hpc, sock=19
05/02/2018 09:02:21;0100;Server@node2;Req;;Type 21 request received from root@node2.supernodexp.hpc, sock=16
05/02/2018 09:02:21;0100;Server@node2;Req;;Type 19 request received from root@node2.supernodexp.hpc, sock=16
05/02/2018 09:02:22;0100;Server@node2;Req;;Type 0 request received from root@node2.supernodexp.hpc, sock=16
05/02/2018 09:02:22;0100;Server@node2;Req;;Type 49 request received from root@node2.supernodexp.hpc, sock=19
05/02/2018 09:02:22;0100;Server@node2;Req;;Type 21 request received from root@node2.supernodexp.hpc, sock=16
05/02/2018 09:02:22;0100;Server@node2;Req;;Type 19 request received from root@node2.supernodexp.hpc, sock=16
05/02/2018 09:02:23;0100;Server@node2;Req;;Type 0 request received from root@node2.supernodexp.hpc, sock=16
05/02/2018 09:02:23;0100;Server@node2;Req;;Type 49 request received from root@node2.supernodexp.hpc, sock=19
05/02/2018 09:02:23;0100;Server@node2;Req;;Type 21 request received from root@node2.supernodexp.hpc, sock=16
05/02/2018 09:02:23;0100;Server@node2;Req;;Type 19 request received from root@node2.supernodexp.hpc, sock=16
05/02/2018 09:02:24;0100;Server@node2;Req;;Type 0 request received from root@node2.supernodexp.hpc, sock=16
05/02/2018 09:02:24;0100;Server@node2;Req;;Type 49 request received from root@node2.supernodexp.hpc, sock=19
05/02/2018 09:02:24;0100;Server@node2;Req;;Type 21 request received from root@node2.supernodexp.hpc, sock=16
05/02/2018 09:02:24;0100;Server@node2;Req;;Type 19 request received from root@node2.supernodexp.hpc, sock=16
05/02/2018 09:02:25;0100;Server@node2;Req;;Type 0 request received from root@node2.supernodexp.hpc, sock=16
05/02/2018 09:02:25;0100;Server@node2;Req;;Type 49 request received from root@node2.supernodexp.hpc, sock=19
05/02/2018 09:02:25;0100;Server@node2;Req;;Type 21 request received from root@node2.supernodexp.hpc, sock=16
05/02/2018 09:02:25;0100;Server@node2;Req;;Type 19 request received from root@node2.supernodexp.hpc, sock=16
05/02/2018 09:02:26;0100;Server@node2;Req;;Type 0 request received from root@node2.supernodexp.hpc, sock=16
05/02/2018 09:02:26;0100;Server@node2;Req;;Type 49 request received from root@node2.supernodexp.hpc, sock=19
05/02/2018 09:02:26;0100;Server@node2;Req;;Type 21 request received from root@node2.supernodexp.hpc, sock=16
05/02/2018 09:02:26;0100;Server@node2;Req;;Type 19 request received from root@node2.supernodexp.hpc, sock=16
05/02/2018 09:02:27;0100;Server@node2;Req;;Type 0 request received from root@node2.supernodexp.hpc, sock=16
05/02/2018 09:02:27;0100;Server@node2;Req;;Type 49 request received from root@node2.supernodexp.hpc, sock=19
05/02/2018 09:02:27;0100;Server@node2;Req;;Type 21 request received from root@node2.supernodexp.hpc, sock=16
05/02/2018 09:02:27;0100;Server@node2;Req;;Type 19 request received from root@node2.supernodexp.hpc, sock=16
05/02/2018 09:02:28;0100;Server@node2;Req;;Type 0 request received from root@node2.supernodexp.hpc, sock=16
05/02/2018 09:02:28;0100;Server@node2;Req;;Type 49 request received from root@node2.supernodexp.hpc, sock=19
05/02/2018 09:02:28;0100;Server@node2;Req;;Type 21 request received from root@node2.supernodexp.hpc, sock=16
05/02/2018 09:02:28;0100;Server@node2;Req;;Type 19 request received from root@node2.supernodexp.hpc, sock=16
05/02/2018 09:02:28;0100;Server@node2;Req;;Type 0 request received from root@node2.supernodexp.hpc, sock=16
05/02/2018 09:02:28;0100;Server@node2;Req;;Type 49 request received from root@node2.supernodexp.hpc, sock=19
05/02/2018 09:02:28;0100;Server@node2;Req;;Type 21 request received from root@node2.supernodexp.hpc, sock=16
05/02/2018 09:02:28;0100;Server@node2;Req;;Type 19 request received from root@node2.supernodexp.hpc, sock=16
05/02/2018 09:02:29;0100;Server@node2;Req;;Type 0 request received from root@node2.supernodexp.hpc, sock=16
05/02/2018 09:02:29;0100;Server@node2;Req;;Type 49 request received from root@node2.supernodexp.hpc, sock=19
05/02/2018 09:02:29;0100;Server@node2;Req;;Type 21 request received from root@node2.supernodexp.hpc, sock=16
05/02/2018 09:02:29;0100;Server@node2;Req;;Type 19 request received from root@node2.supernodexp.hpc, sock=16
05/02/2018 09:02:30;0100;Server@node2;Req;;Type 0 request received from root@node2.supernodexp.hpc, sock=16
05/02/2018 09:02:30;0100;Server@node2;Req;;Type 49 request received from root@node2.supernodexp.hpc, sock=19
05/02/2018 09:02:30;0100;Server@node2;Req;;Type 21 request received from root@node2.supernodexp.hpc, sock=16
05/02/2018 09:02:30;0100;Server@node2;Req;;Type 19 request received from root@node2.supernodexp.hpc, sock=16
05/02/2018 09:02:31;0100;Server@node2;Req;;Type 0 request received from root@node2.supernodexp.hpc, sock=16
05/02/2018 09:02:31;0100;Server@node2;Req;;Type 49 request received from root@node2.supernodexp.hpc, sock=19
05/02/2018 09:02:31;0100;Server@node2;Req;;Type 21 request received from root@node2.supernodexp.hpc, sock=16
05/02/2018 09:02:31;0100;Server@node2;Req;;Type 19 request received from root@node2.supernodexp.hpc, sock=16
05/02/2018 09:02:32;0100;Server@node2;Req;;Type 0 request received from root@node2.supernodexp.hpc, sock=16
05/02/2018 09:02:32;0100;Server@node2;Req;;Type 49 request received from root@node2.supernodexp.hpc, sock=19
05/02/2018 09:02:32;0100;Server@node2;Req;;Type 21 request received from root@node2.supernodexp.hpc, sock=16
05/02/2018 09:02:32;0100;Server@node2;Req;;Type 19 request received from root@node2.supernodexp.hpc, sock=16
05/02/2018 09:02:33;0100;Server@node2;Req;;Type 0 request received from root@node2.supernodexp.hpc, sock=16
05/02/2018 09:02:33;0100;Server@node2;Req;;Type 49 request received from root@node2.supernodexp.hpc, sock=19
05/02/2018 09:02:33;0100;Server@node2;Req;;Type 21 request received from root@node2.supernodexp.hpc, sock=16
05/02/2018 09:02:33;0100;Server@node2;Req;;Type 19 request received from root@node2.supernodexp.hpc, sock=16
05/02/2018 09:02:33;0100;Server@node2;Req;;Type 0 request received from root@node2.supernodexp.hpc, sock=16
05/02/2018 09:02:33;0100;Server@node2;Req;;Type 49 request received from root@node2.supernodexp.hpc, sock=19
05/02/2018 09:02:33;0100;Server@node2;Req;;Type 21 request received from root@node2.supernodexp.hpc, sock=16
05/02/2018 09:02:33;0100;Server@node2;Req;;Type 19 request received from root@node2.supernodexp.hpc, sock=16
05/02/2018 09:02:34;0100;Server@node2;Req;;Type 0 request received from root@node2.supernodexp.hpc, sock=16
05/02/2018 09:02:34;0100;Server@node2;Req;;Type 49 request received from root@node2.supernodexp.hpc, sock=19
05/02/2018 09:02:34;0100;Server@node2;Req;;Type 21 request received from root@node2.supernodexp.hpc, sock=16
05/02/2018 09:02:34;0100;Server@node2;Req;;Type 19 request received from root@node2.supernodexp.hpc, sock=16
05/02/2018 09:02:35;0100;Server@node2;Req;;Type 0 request received from root@node2.supernodexp.hpc, sock=16
05/02/2018 09:02:35;0100;Server@node2;Req;;Type 49 request received from root@node2.supernodexp.hpc, sock=19
05/02/2018 09:02:35;0100;Server@node2;Req;;Type 21 request received from root@node2.supernodexp.hpc, sock=16
05/02/2018 09:02:35;0100;Server@node2;Req;;Type 19 request received from root@node2.supernodexp.hpc, sock=16
05/02/2018 09:02:35;0100;Server@node2;Req;;Type 0 request received from root@node2.supernodexp.hpc, sock=16
05/02/2018 09:02:35;0100;Server@node2;Req;;Type 49 request received from root@node2.supernodexp.hpc, sock=19
05/02/2018 09:02:35;0100;Server@node2;Req;;Type 21 request received from root@node2.supernodexp.hpc, sock=16
05/02/2018 09:02:35;0100;Server@node2;Req;;Type 19 request received from root@node2.supernodexp.hpc, sock=16
05/02/2018 09:02:36;0100;Server@node2;Req;;Type 0 request received from root@node2.supernodexp.hpc, sock=16
05/02/2018 09:02:36;0100;Server@node2;Req;;Type 49 request received from root@node2.supernodexp.hpc, sock=19
05/02/2018 09:02:36;0100;Server@node2;Req;;Type 21 request received from root@node2.supernodexp.hpc, sock=16
05/02/2018 09:02:36;0100;Server@node2;Req;;Type 19 request received from root@node2.supernodexp.hpc, sock=16
05/02/2018 09:02:37;0100;Server@node2;Req;;Type 0 request received from root@node2.supernodexp.hpc, sock=16
05/02/2018 09:02:37;0100;Server@node2;Req;;Type 49 request received from root@node2.supernodexp.hpc, sock=19
05/02/2018 09:02:37;0100;Server@node2;Req;;Type 21 request received from root@node2.supernodexp.hpc, sock=16
05/02/2018 09:02:37;0100;Server@node2;Req;;Type 19 request received from root@node2.supernodexp.hpc, sock=16
05/02/2018 09:02:38;0100;Server@node2;Req;;Type 0 request received from root@node2.supernodexp.hpc, sock=16
05/02/2018 09:02:38;0100;Server@node2;Req;;Type 49 request received from root@node2.supernodexp.hpc, sock=19
05/02/2018 09:02:38;0100;Server@node2;Req;;Type 21 request received from root@node2.supernodexp.hpc, sock=16
05/02/2018 09:02:38;0100;Server@node2;Req;;Type 19 request received from root@node2.supernodexp.hpc, sock=16
05/02/2018 09:02:39;0100;Server@node2;Req;;Type 0 request received from root@node2.supernodexp.hpc, sock=16
05/02/2018 09:02:39;0100;Server@node2;Req;;Type 49 request received from root@node2.supernodexp.hpc, sock=19
05/02/2018 09:02:39;0100;Server@node2;Req;;Type 21 request received from root@node2.supernodexp.hpc, sock=16
05/02/2018 09:02:39;0100;Server@node2;Req;;Type 19 request received from root@node2.supernodexp.hpc, sock=16
05/02/2018 09:02:39;0100;Server@node2;Req;;Type 0 request received from root@node2.supernodexp.hpc, sock=16
05/02/2018 09:02:39;0100;Server@node2;Req;;Type 49 request received from root@node2.supernodexp.hpc, sock=19
05/02/2018 09:02:39;0100;Server@node2;Req;;Type 21 request received from root@node2.supernodexp.hpc, sock=16
05/02/2018 09:02:39;0100;Server@node2;Req;;Type 19 request received from root@node2.supernodexp.hpc, sock=16
05/02/2018 09:02:40;0100;Server@node2;Req;;Type 0 request received from root@node2.supernodexp.hpc, sock=16
05/02/2018 09:02:40;0100;Server@node2;Req;;Type 49 request received from root@node2.supernodexp.hpc, sock=19
05/02/2018 09:02:40;0100;Server@node2;Req;;Type 21 request received from root@node2.supernodexp.hpc, sock=16
05/02/2018 09:02:40;0100;Server@node2;Req;;Type 19 request received from root@node2.supernodexp.hpc, sock=16
05/02/2018 09:02:41;0100;Server@node2;Req;;Type 0 request received from root@node2.supernodexp.hpc, sock=16
05/02/2018 09:02:41;0100;Server@node2;Req;;Type 49 request received from root@node2.supernodexp.hpc, sock=19
05/02/2018 09:02:41;0100;Server@node2;Req;;Type 21 request received from root@node2.supernodexp.hpc, sock=16
05/02/2018 09:02:41;0100;Server@node2;Req;;Type 19 request received from root@node2.supernodexp.hpc, sock=16
05/02/2018 09:02:42;0100;Server@node2;Req;;Type 0 request received from root@node2.supernodexp.hpc, sock=16
05/02/2018 09:02:42;0100;Server@node2;Req;;Type 49 request received from root@node2.supernodexp.hpc, sock=19
05/02/2018 09:02:42;0100;Server@node2;Req;;Type 21 request received from root@node2.supernodexp.hpc, sock=16
05/02/2018 09:02:42;0100;Server@node2;Req;;Type 19 request received from root@node2.supernodexp.hpc, sock=16
05/02/2018 09:02:43;0100;Server@node2;Req;;Type 0 request received from root@node2.supernodexp.hpc, sock=16
05/02/2018 09:02:43;0100;Server@node2;Req;;Type 49 request received from root@node2.supernodexp.hpc, sock=19
05/02/2018 09:02:43;0100;Server@node2;Req;;Type 21 request received from root@node2.supernodexp.hpc, sock=16
05/02/2018 09:02:43;0100;Server@node2;Req;;Type 19 request received from root@node2.supernodexp.hpc, sock=16
05/02/2018 09:02:44;0100;Server@node2;Req;;Type 0 request received from root@node2.supernodexp.hpc, sock=16
05/02/2018 09:02:44;0100;Server@node2;Req;;Type 49 request received from root@node2.supernodexp.hpc, sock=19
05/02/2018 09:02:44;0100;Server@node2;Req;;Type 21 request received from root@node2.supernodexp.hpc, sock=16
05/02/2018 09:02:44;0100;Server@node2;Req;;Type 19 request received from root@node2.supernodexp.hpc, sock=16
05/02/2018 09:02:44;0100;Server@node2;Req;;Type 0 request received from root@node2.supernodexp.hpc, sock=16
05/02/2018 09:02:44;0100;Server@node2;Req;;Type 49 request received from root@node2.supernodexp.hpc, sock=19
05/02/2018 09:02:44;0100;Server@node2;Req;;Type 21 request received from root@node2.supernodexp.hpc, sock=16
05/02/2018 09:02:44;0100;Server@node2;Req;;Type 19 request received from root@node2.supernodexp.hpc, sock=16
05/02/2018 09:02:45;0100;Server@node2;Req;;Type 0 request received from root@node2.supernodexp.hpc, sock=16
05/02/2018 09:02:46;0100;Server@node2;Req;;Type 49 request received from root@node2.supernodexp.hpc, sock=19
05/02/2018 09:02:46;0100;Server@node2;Req;;Type 21 request received from root@node2.supernodexp.hpc, sock=16
05/02/2018 09:02:46;0100;Server@node2;Req;;Type 19 request received from root@node2.supernodexp.hpc, sock=16
05/02/2018 09:02:46;0080;Server@node2;Job;13255.node2.supernodexp.hpc;Obit received momhop:1 serverhop:1 state:4 substate:42
05/02/2018 09:02:46;0100;Server@node2;Req;;Type 0 request received from root@node2.supernodexp.hpc, sock=16
05/02/2018 09:02:46;0100;Server@node2;Req;;Type 49 request received from root@node2.supernodexp.hpc, sock=19
05/02/2018 09:02:46;0100;Server@node2;Req;;Type 21 request received from root@node2.supernodexp.hpc, sock=16
05/02/2018 09:02:46;0100;Server@node2;Req;;Type 19 request received from root@node2.supernodexp.hpc, sock=16
05/02/2018 09:02:47;0010;Server@node2;Job;13255.node2.supernodexp.hpc;Exit_status=0 resources_used.cpupercent=2394 resources_used.cput=01:46:38 resources_used.mem=3250520kb resources_used.ncpus=48 resources_used.vmem=33619764kb resources_used.walltime=00:02:23
05/02/2018 09:02:47;0100;Server@node2;Job;13255.node2.supernodexp.hpc;dequeuing from workq, state 5
05/02/2018 09:02:47;0040;Server@node2;Svr;node2.supernodexp.hpc;Scheduler sent command 2
05/02/2018 09:02:47;0040;Server@node2;Svr;node2.supernodexp.hpc;Scheduler sent command 0
05/02/2018 09:02:47;0100;Server@node2;Req;;Type 21 request received from Scheduler@node2.supernodexp.hpc, sock=16
05/02/2018 09:02:47;0100;Server@node2;Req;;Type 81 request received from Scheduler@node2.supernodexp.hpc, sock=16
05/02/2018 09:02:47;0100;Server@node2;Req;;Type 71 request received from Scheduler@node2.supernodexp.hpc, sock=16
05/02/2018 09:02:47;0100;Server@node2;Req;;Type 58 request received from Scheduler@node2.supernodexp.hpc, sock=16
05/02/2018 09:02:47;0100;Server@node2;Req;;Type 20 request received from Scheduler@node2.supernodexp.hpc, sock=16
05/02/2018 09:02:47;0100;Server@node2;Req;;Type 51 request received from Scheduler@node2.supernodexp.hpc, sock=16
05/02/2018 09:02:47;0100;Server@node2;Req;;Type 23 request received from Scheduler@node2.supernodexp.hpc, sock=16
05/02/2018 09:02:47;0008;Server@node2;Job;13256.node2.supernodexp.hpc;Job Run at request of Scheduler@node2.supernodexp.hpc on exec_vnode (node13:ncpus=24:mpiprocs=24:mem=4194304kb)+(node13:ncpus=24:mpiprocs=24:mem=4194304kb)
05/02/2018 09:02:47;0001;Server@node2;Svr;Server@node2;Success (0) in req_runjob2, return value of svr_startjob is 0
05/02/2018 09:02:47;0100;Server@node2;Req;;Type 11 request received from Scheduler@node2.supernodexp.hpc, sock=16
05/02/2018 09:02:47;0008;Server@node2;Job;13259.node2.supernodexp.hpc;Job Modified at request of Scheduler@node2.supernodexp.hpc
05/02/2018 09:02:48;0100;Server@node2;Req;;Type 0 request received from root@node2.supernodexp.hpc, sock=16
05/02/2018 09:02:48;0100;Server@node2;Req;;Type 49 request received from root@node2.supernodexp.hpc, sock=19
05/02/2018 09:02:48;0100;Server@node2;Req;;Type 21 request received from root@node2.supernodexp.hpc, sock=16
05/02/2018 09:02:48;0100;Server@node2;Req;;Type 19 request received from root@node2.supernodexp.hpc, sock=16
05/02/2018 09:02:49;0100;Server@node2;Req;;Type 0 request received from root@node2.supernodexp.hpc, sock=16
05/02/2018 09:02:49;0100;Server@node2;Req;;Type 49 request received from root@node2.supernodexp.hpc, sock=19
05/02/2018 09:02:49;0100;Server@node2;Req;;Type 21 request received from root@node2.supernodexp.hpc, sock=16
05/02/2018 09:02:49;0100;Server@node2;Req;;Type 19 request received from root@node2.supernodexp.hpc, sock=16
05/02/2018 09:02:51;0100;Server@node2;Req;;Type 0 request received from root@node2.supernodexp.hpc, sock=16
05/02/2018 09:02:51;0100;Server@node2;Req;;Type 49 request received from root@node2.supernodexp.hpc, sock=19
05/02/2018 09:02:51;0100;Server@node2;Req;;Type 21 request received from root@node2.supernodexp.hpc, sock=16
05/02/2018 09:02:51;0100;Server@node2;Req;;Type 19 request received from root@node2.supernodexp.hpc, sock=16
05/02/2018 09:02:52;0100;Server@node2;Req;;Type 0 request received from root@node2.supernodexp.hpc, sock=16
05/02/2018 09:02:52;0100;Server@node2;Req;;Type 49 request received from root@node2.supernodexp.hpc, sock=19
05/02/2018 09:02:52;0100;Server@node2;Req;;Type 21 request received from root@node2.supernodexp.hpc, sock=16
05/02/2018 09:02:52;0100;Server@node2;Req;;Type 19 request received from root@node2.supernodexp.hpc, sock=16
05/02/2018 09:02:53;0100;Server@node2;Req;;Type 0 request received from root@node2.supernodexp.hpc, sock=16
05/02/2018 09:02:53;0100;Server@node2;Req;;Type 49 request received from root@node2.supernodexp.hpc, sock=19
05/02/2018 09:02:53;0100;Server@node2;Req;;Type 21 request received from root@node2.supernodexp.hpc, sock=16
05/02/2018 09:02:53;0100;Server@node2;Req;;Type 19 request received from root@node2.supernodexp.hpc, sock=16
05/02/2018 09:02:54;0100;Server@node2;Req;;Type 0 request received from root@node2.supernodexp.hpc, sock=16
05/02/2018 09:02:54;0100;Server@node2;Req;;Type 49 request received from root@node2.supernodexp.hpc, sock=19
05/02/2018 09:02:54;0100;Server@node2;Req;;Type 21 request received from root@node2.supernodexp.hpc, sock=16
05/02/2018 09:02:54;0100;Server@node2;Req;;Type 19 request received from root@node2.supernodexp.hpc, sock=16
05/02/2018 09:02:56;0100;Server@node2;Req;;Type 0 request received from root@node2.supernodexp.hpc, sock=16
05/02/2018 09:02:56;0100;Server@node2;Req;;Type 49 request received from root@node2.supernodexp.hpc, sock=19
05/02/2018 09:02:56;0100;Server@node2;Req;;Type 21 request received from root@node2.supernodexp.hpc, sock=16
05/02/2018 09:02:56;0100;Server@node2;Req;;Type 19 request received from root@node2.supernodexp.hpc, sock=16
05/02/2018 09:02:57;0100;Server@node2;Req;;Type 0 request received from root@node2.supernodexp.hpc, sock=16
05/02/2018 09:02:57;0100;Server@node2;Req;;Type 49 request received from root@node2.supernodexp.hpc, sock=19
05/02/2018 09:02:57;0100;Server@node2;Req;;Type 21 request received from root@node2.supernodexp.hpc, sock=16
05/02/2018 09:02:57;0100;Server@node2;Req;;Type 19 request received from root@node2.supernodexp.hpc, sock=16
05/02/2018 09:02:58;0100;Server@node2;Req;;Type 0 request received from root@node2.supernodexp.hpc, sock=16
05/02/2018 09:02:58;0100;Server@node2;Req;;Type 49 request received from root@node2.supernodexp.hpc, sock=19
05/02/2018 09:02:58;0100;Server@node2;Req;;Type 21 request received from root@node2.supernodexp.hpc, sock=16
05/02/2018 09:02:58;0100;Server@node2;Req;;Type 19 request received from root@node2.supernodexp.hpc, sock=16
05/02/2018 09:02:59;0100;Server@node2;Req;;Type 0 request received from root@node2.supernodexp.hpc, sock=16
05/02/2018 09:02:59;0100;Server@node2;Req;;Type 49 request received from root@node2.supernodexp.hpc, sock=19
05/02/2018 09:02:59;0100;Server@node2;Req;;Type 21 request received from root@node2.supernodexp.hpc, sock=16
05/02/2018 09:02:59;0100;Server@node2;Req;;Type 19 request received from root@node2.supernodexp.hpc, sock=16
05/02/2018 09:03:00;0100;Server@node2;Req;;Type 0 request received from root@node2.supernodexp.hpc, sock=16
05/02/2018 09:03:00;0100;Server@node2;Req;;Type 49 request received from root@node2.supernodexp.hpc, sock=19
05/02/2018 09:03:00;0100;Server@node2;Req;;Type 21 request received from root@node2.supernodexp.hpc, sock=16
05/02/2018 09:03:00;0100;Server@node2;Req;;Type 19 request received from root@node2.supernodexp.hpc, sock=16
05/02/2018 09:03:01;0100;Server@node2;Req;;Type 0 request received from root@node2.supernodexp.hpc, sock=16
05/02/2018 09:03:01;0100;Server@node2;Req;;Type 49 request received from root@node2.supernodexp.hpc, sock=19
05/02/2018 09:03:01;0100;Server@node2;Req;;Type 21 request received from root@node2.supernodexp.hpc, sock=16
05/02/2018 09:03:01;0100;Server@node2;Req;;Type 19 request received from root@node2.supernodexp.hpc, sock=16
05/02/2018 09:03:02;0100;Server@node2;Req;;Type 0 request received from root@node2.supernodexp.hpc, sock=16
05/02/2018 09:03:02;0100;Server@node2;Req;;Type 49 request received from root@node2.supernodexp.hpc, sock=19
05/02/2018 09:03:02;0100;Server@node2;Req;;Type 21 request received from root@node2.supernodexp.hpc, sock=16
05/02/2018 09:03:02;0100;Server@node2;Req;;Type 19 request received from root@node2.supernodexp.hpc, sock=16
05/02/2018 09:03:04;0100;Server@node2;Req;;Type 0 request received from root@node2.supernodexp.hpc, sock=16
05/02/2018 09:03:04;0100;Server@node2;Req;;Type 49 request received from root@node2.supernodexp.hpc, sock=19
05/02/2018 09:03:04;0100;Server@node2;Req;;Type 21 request received from root@node2.supernodexp.hpc, sock=16
05/02/2018 09:03:04;0100;Server@node2;Req;;Type 19 request received from root@node2.supernodexp.hpc, sock=16
05/02/2018 09:03:04;0100;Server@node2;Req;;Type 0 request received from root@node2.supernodexp.hpc, sock=16
05/02/2018 09:03:04;0100;Server@node2;Req;;Type 49 request received from root@node2.supernodexp.hpc, sock=19
05/02/2018 09:03:04;0100;Server@node2;Req;;Type 21 request received from root@node2.supernodexp.hpc, sock=16
05/02/2018 09:03:04;0100;Server@node2;Req;;Type 19 request received from root@node2.supernodexp.hpc, sock=16
05/02/2018 09:03:05;0100;Server@node2;Req;;Type 0 request received from root@node2.supernodexp.hpc, sock=16
05/02/2018 09:03:05;0100;Server@node2;Req;;Type 49 request received from root@node2.supernodexp.hpc, sock=19
05/02/2018 09:03:05;0100;Server@node2;Req;;Type 21 request received from root@node2.supernodexp.hpc, sock=16
05/02/2018 09:03:05;0100;Server@node2;Req;;Type 19 request received from root@node2.supernodexp.hpc, sock=16
05/02/2018 09:03:06;0100;Server@node2;Req;;Type 0 request received from root@node2.supernodexp.hpc, sock=16
05/02/2018 09:03:06;0100;Server@node2;Req;;Type 49 request received from root@node2.supernodexp.hpc, sock=19
05/02/2018 09:03:06;0100;Server@node2;Req;;Type 21 request received from root@node2.supernodexp.hpc, sock=16
05/02/2018 09:03:06;0100;Server@node2;Req;;Type 19 request received from root@node2.supernodexp.hpc, sock=16
05/02/2018 09:03:07;0100;Server@node2;Req;;Type 0 request received from root@node2.supernodexp.hpc, sock=16
05/02/2018 09:03:07;0100;Server@node2;Req;;Type 49 request received from root@node2.supernodexp.hpc, sock=19
05/02/2018 09:03:07;0100;Server@node2;Req;;Type 21 request received from root@node2.supernodexp.hpc, sock=16
05/02/2018 09:03:07;0100;Server@node2;Req;;Type 19 request received from root@node2.supernodexp.hpc, sock=16
05/02/2018 09:03:08;0100;Server@node2;Req;;Type 0 request received from root@node2.supernodexp.hpc, sock=16
05/02/2018 09:03:08;0100;Server@node2;Req;;Type 49 request received from root@node2.supernodexp.hpc, sock=19
05/02/2018 09:03:08;0100;Server@node2;Req;;Type 21 request received from root@node2.supernodexp.hpc, sock=16
05/02/2018 09:03:08;0100;Server@node2;Req;;Type 19 request received from root@node2.supernodexp.hpc, sock=16
05/02/2018 09:03:10;0100;Server@node2;Req;;Type 0 request received from root@node2.supernodexp.hpc, sock=16
05/02/2018 09:03:10;0100;Server@node2;Req;;Type 49 request received from root@node2.supernodexp.hpc, sock=19
05/02/2018 09:03:10;0100;Server@node2;Req;;Type 21 request received from root@node2.supernodexp.hpc, sock=16
05/02/2018 09:03:10;0100;Server@node2;Req;;Type 19 request received from root@node2.supernodexp.hpc, sock=16
05/02/2018 09:03:11;0100;Server@node2;Req;;Type 0 request received from root@node2.supernodexp.hpc, sock=16
05/02/2018 09:03:11;0100;Server@node2;Req;;Type 49 request received from root@node2.supernodexp.hpc, sock=19
05/02/2018 09:03:11;0100;Server@node2;Req;;Type 21 request received from root@node2.supernodexp.hpc, sock=16
05/02/2018 09:03:11;0100;Server@node2;Req;;Type 19 request received from root@node2.supernodexp.hpc, sock=16
05/02/2018 09:03:12;0100;Server@node2;Req;;Type 0 request received from root@node2.supernodexp.hpc, sock=16
05/02/2018 09:03:12;0100;Server@node2;Req;;Type 49 request received from root@node2.supernodexp.hpc, sock=19
05/02/2018 09:03:12;0100;Server@node2;Req;;Type 21 request received from root@node2.supernodexp.hpc, sock=16
05/02/2018 09:03:12;0100;Server@node2;Req;;Type 19 request received from root@node2.supernodexp.hpc, sock=16
05/02/2018 09:03:13;0100;Server@node2;Req;;Type 0 request received from root@node2.supernodexp.hpc, sock=16
05/02/2018 09:03:13;0100;Server@node2;Req;;Type 49 request received from root@node2.supernodexp.hpc, sock=19
05/02/2018 09:03:13;0100;Server@node2;Req;;Type 21 request received from root@node2.supernodexp.hpc, sock=16
05/02/2018 09:03:13;0100;Server@node2;Req;;Type 19 request received from root@node2.supernodexp.hpc, sock=16
05/02/2018 09:03:14;0080;Server@node2;Job;13251.node2.supernodexp.hpc;Obit received momhop:1 serverhop:1 state:4 substate:42
05/02/2018 09:03:14;0100;Server@node2;Req;;Type 0 request received from root@node2.supernodexp.hpc, sock=16
05/02/2018 09:03:14;0100;Server@node2;Req;;Type 49 request received from root@node2.supernodexp.hpc, sock=19
05/02/2018 09:03:14;0100;Server@node2;Req;;Type 21 request received from root@node2.supernodexp.hpc, sock=16
05/02/2018 09:03:14;0100;Server@node2;Req;;Type 19 request received from root@node2.supernodexp.hpc, sock=16
05/02/2018 09:03:15;0010;Server@node2;Job;13251.node2.supernodexp.hpc;Exit_status=0 resources_used.cpupercent=1634 resources_used.cput=01:12:34 resources_used.mem=1642392kb resources_used.ncpus=24 resources_used.vmem=15000432kb resources_used.walltime=00:03:12
05/02/2018 09:03:15;0100;Server@node2;Job;13251.node2.supernodexp.hpc;dequeuing from workq, state 5
05/02/2018 09:03:15;0040;Server@node2;Svr;node2.supernodexp.hpc;Scheduler sent command 2
05/02/2018 09:03:15;0040;Server@node2;Svr;node2.supernodexp.hpc;Scheduler sent command 0
05/02/2018 09:03:15;0100;Server@node2;Req;;Type 21 request received from Scheduler@node2.supernodexp.hpc, sock=16
05/02/2018 09:03:15;0100;Server@node2;Req;;Type 81 request received from Scheduler@node2.supernodexp.hpc, sock=16
05/02/2018 09:03:15;0100;Server@node2;Req;;Type 71 request received from Scheduler@node2.supernodexp.hpc, sock=16
05/02/2018 09:03:15;0100;Server@node2;Req;;Type 58 request received from Scheduler@node2.supernodexp.hpc, sock=16
05/02/2018 09:03:15;0100;Server@node2;Req;;Type 20 request received from Scheduler@node2.supernodexp.hpc, sock=16
05/02/2018 09:03:15;0100;Server@node2;Req;;Type 51 request received from Scheduler@node2.supernodexp.hpc, sock=16
05/02/2018 09:03:15;0100;Server@node2;Req;;Type 11 request received from Scheduler@node2.supernodexp.hpc, sock=16
05/02/2018 09:03:15;0008;Server@node2;Job;13259.node2.supernodexp.hpc;Job Modified at request of Scheduler@node2.supernodexp.hpc
05/02/2018 09:03:15;0100;Server@node2;Req;;Type 0 request received from root@node2.supernodexp.hpc, sock=16
05/02/2018 09:03:15;0100;Server@node2;Req;;Type 49 request received from root@node2.supernodexp.hpc, sock=19
05/02/2018 09:03:15;0100;Server@node2;Req;;Type 21 request received from root@node2.supernodexp.hpc, sock=16
05/02/2018 09:03:15;0100;Server@node2;Req;;Type 19 request received from root@node2.supernodexp.hpc, sock=16
05/02/2018 09:03:16;0100;Server@node2;Req;;Type 0 request received from root@node2.supernodexp.hpc, sock=16
05/02/2018 09:03:16;0100;Server@node2;Req;;Type 49 request received from root@node2.supernodexp.hpc, sock=19
05/02/2018 09:03:16;0100;Server@node2;Req;;Type 21 request received from root@node2.supernodexp.hpc, sock=16
05/02/2018 09:03:16;0100;Server@node2;Req;;Type 19 request received from root@node2.supernodexp.hpc, sock=16
05/02/2018 09:03:17;0100;Server@node2;Req;;Type 0 request received from root@node2.supernodexp.hpc, sock=16
05/02/2018 09:03:17;0080;Server@node2;Job;13252.node2.supernodexp.hpc;Obit received momhop:1 serverhop:1 state:4 substate:42
05/02/2018 09:03:17;0100;Server@node2;Req;;Type 49 request received from root@node2.supernodexp.hpc, sock=19
05/02/2018 09:03:17;0100;Server@node2;Req;;Type 21 request received from root@node2.supernodexp.hpc, sock=16
05/02/2018 09:03:17;0100;Server@node2;Req;;Type 19 request received from root@node2.supernodexp.hpc, sock=16
05/02/2018 09:03:18;0010;Server@node2;Job;13252.node2.supernodexp.hpc;Exit_status=0 resources_used.cpupercent=1278 resources_used.cput=01:11:44 resources_used.mem=1642648kb resources_used.ncpus=24 resources_used.vmem=15000456kb resources_used.walltime=00:03:10
05/02/2018 09:03:18;0100;Server@node2;Job;13252.node2.supernodexp.hpc;dequeuing from workq, state 5
05/02/2018 09:03:18;0040;Server@node2;Svr;node2.supernodexp.hpc;Scheduler sent command 2
05/02/2018 09:03:18;0040;Server@node2;Svr;node2.supernodexp.hpc;Scheduler sent command 0
05/02/2018 09:03:18;0100;Server@node2;Req;;Type 21 request received from Scheduler@node2.supernodexp.hpc, sock=16
05/02/2018 09:03:18;0100;Server@node2;Req;;Type 81 request received from Scheduler@node2.supernodexp.hpc, sock=16
05/02/2018 09:03:18;0100;Server@node2;Req;;Type 71 request received from Scheduler@node2.supernodexp.hpc, sock=16
05/02/2018 09:03:18;0100;Server@node2;Req;;Type 58 request received from Scheduler@node2.supernodexp.hpc, sock=16
05/02/2018 09:03:18;0100;Server@node2;Req;;Type 20 request received from Scheduler@node2.supernodexp.hpc, sock=16
05/02/2018 09:03:18;0100;Server@node2;Req;;Type 51 request received from Scheduler@node2.supernodexp.hpc, sock=16
05/02/2018 09:03:18;0100;Server@node2;Req;;Type 23 request received from Scheduler@node2.supernodexp.hpc, sock=16
05/02/2018 09:03:18;0008;Server@node2;Job;13259.node2.supernodexp.hpc;Job Run at request of Scheduler@node2.supernodexp.hpc on exec_vnode (node3:ncpus=24:mpiprocs=24:mem=4194304kb)+(node3:ncpus=24:mpiprocs=24:mem=4194304kb)
05/02/2018 09:03:18;0001;Server@node2;Svr;Server@node2;Success (0) in req_runjob2, return value of svr_startjob is 0
05/02/2018 09:03:18;0100;Server@node2;Req;;Type 11 request received from Scheduler@node2.supernodexp.hpc, sock=16
05/02/2018 09:03:18;0008;Server@node2;Job;13257.node2.supernodexp.hpc;Job Modified at request of Scheduler@node2.supernodexp.hpc
05/02/2018 09:03:18;0100;Server@node2;Req;;Type 0 request received from root@node2.supernodexp.hpc, sock=16
05/02/2018 09:03:18;0100;Server@node2;Req;;Type 49 request received from root@node2.supernodexp.hpc, sock=19
05/02/2018 09:03:18;0100;Server@node2;Req;;Type 21 request received from root@node2.supernodexp.hpc, sock=16
05/02/2018 09:03:18;0100;Server@node2;Req;;Type 19 request received from root@node2.supernodexp.hpc, sock=16
05/02/2018 09:03:20;0100;Server@node2;Req;;Type 0 request received from root@node2.supernodexp.hpc, sock=16
05/02/2018 09:03:20;0100;Server@node2;Req;;Type 49 request received from root@node2.supernodexp.hpc, sock=19
05/02/2018 09:03:20;0100;Server@node2;Req;;Type 21 request received from root@node2.supernodexp.hpc, sock=16
05/02/2018 09:03:20;0100;Server@node2;Req;;Type 19 request received from root@node2.supernodexp.hpc, sock=16
05/02/2018 09:03:20;0080;Server@node2;Job;13253.node2.supernodexp.hpc;Obit received momhop:1 serverhop:1 state:4 substate:42
05/02/2018 09:03:21;0100;Server@node2;Req;;Type 0 request received from root@node2.supernodexp.hpc, sock=16
05/02/2018 09:03:21;0100;Server@node2;Req;;Type 49 request received from root@node2.supernodexp.hpc, sock=19
05/02/2018 09:03:21;0100;Server@node2;Req;;Type 21 request received from root@node2.supernodexp.hpc, sock=16
05/02/2018 09:03:21;0100;Server@node2;Req;;Type 19 request received from root@node2.supernodexp.hpc, sock=16
05/02/2018 09:03:21;0010;Server@node2;Job;13253.node2.supernodexp.hpc;Exit_status=0 resources_used.cpupercent=1379 resources_used.cput=00:48:36 resources_used.mem=1122936kb resources_used.ncpus=16 resources_used.vmem=10375160kb resources_used.walltime=00:03:08
05/02/2018 09:03:21;0100;Server@node2;Job;13253.node2.supernodexp.hpc;dequeuing from workq, state 5
05/02/2018 09:03:21;0040;Server@node2;Svr;node2.supernodexp.hpc;Scheduler sent command 2
05/02/2018 09:03:21;0040;Server@node2;Svr;node2.supernodexp.hpc;Scheduler sent command 0
05/02/2018 09:03:21;0100;Server@node2;Req;;Type 21 request received from Scheduler@node2.supernodexp.hpc, sock=16
05/02/2018 09:03:21;0100;Server@node2;Req;;Type 81 request received from Scheduler@node2.supernodexp.hpc, sock=16
05/02/2018 09:03:21;0100;Server@node2;Req;;Type 71 request received from Scheduler@node2.supernodexp.hpc, sock=16
05/02/2018 09:03:21;0100;Server@node2;Req;;Type 58 request received from Scheduler@node2.supernodexp.hpc, sock=16
05/02/2018 09:03:21;0100;Server@node2;Req;;Type 20 request received from Scheduler@node2.supernodexp.hpc, sock=16
05/02/2018 09:03:21;0100;Server@node2;Req;;Type 51 request received from Scheduler@node2.supernodexp.hpc, sock=16
05/02/2018 09:03:21;0100;Server@node2;Req;;Type 23 request received from Scheduler@node2.supernodexp.hpc, sock=16
05/02/2018 09:03:21;0008;Server@node2;Job;13257.node2.supernodexp.hpc;Job Run at request of Scheduler@node2.supernodexp.hpc on exec_vnode (node14:ncpus=24:mpiprocs=24:mem=2097152kb)
05/02/2018 09:03:21;0001;Server@node2;Svr;Server@node2;Success (0) in req_runjob2, return value of svr_startjob is 0
05/02/2018 09:03:21;0100;Server@node2;Req;;Type 11 request received from Scheduler@node2.supernodexp.hpc, sock=16
05/02/2018 09:03:21;0008;Server@node2;Job;13258.node2.supernodexp.hpc;Job Modified at request of Scheduler@node2.supernodexp.hpc
05/02/2018 09:03:22;0100;Server@node2;Req;;Type 0 request received from root@node2.supernodexp.hpc, sock=16
05/02/2018 09:03:22;0100;Server@node2;Req;;Type 49 request received from root@node2.supernodexp.hpc, sock=19
05/02/2018 09:03:22;0100;Server@node2;Req;;Type 21 request received from root@node2.supernodexp.hpc, sock=16
05/02/2018 09:03:22;0100;Server@node2;Req;;Type 19 request received from root@node2.supernodexp.hpc, sock=16
05/02/2018 09:03:23;0100;Server@node2;Req;;Type 0 request received from root@node2.supernodexp.hpc, sock=16
05/02/2018 09:03:23;0100;Server@node2;Req;;Type 49 request received from root@node2.supernodexp.hpc, sock=19
05/02/2018 09:03:23;0100;Server@node2;Req;;Type 21 request received from root@node2.supernodexp.hpc, sock=16
05/02/2018 09:03:23;0100;Server@node2;Req;;Type 19 request received from root@node2.supernodexp.hpc, sock=16
05/02/2018 09:03:24;0100;Server@node2;Req;;Type 0 request received from root@node2.supernodexp.hpc, sock=16
05/02/2018 09:03:24;0100;Server@node2;Req;;Type 49 request received from root@node2.supernodexp.hpc, sock=19
05/02/2018 09:03:24;0100;Server@node2;Req;;Type 21 request received from root@node2.supernodexp.hpc, sock=16
05/02/2018 09:03:24;0100;Server@node2;Req;;Type 19 request received from root@node2.supernodexp.hpc, sock=16
05/02/2018 09:03:25;0100;Server@node2;Req;;Type 0 request received from root@node2.supernodexp.hpc, sock=16
05/02/2018 09:03:25;0100;Server@node2;Req;;Type 49 request received from root@node2.supernodexp.hpc, sock=19
05/02/2018 09:03:25;0100;Server@node2;Req;;Type 21 request received from root@node2.supernodexp.hpc, sock=16
05/02/2018 09:03:25;0100;Server@node2;Req;;Type 19 request received from root@node2.supernodexp.hpc, sock=16
05/02/2018 09:03:26;0100;Server@node2;Req;;Type 0 request received from root@node2.supernodexp.hpc, sock=16
05/02/2018 09:03:26;0100;Server@node2;Req;;Type 49 request received from root@node2.supernodexp.hpc, sock=19
05/02/2018 09:03:26;0100;Server@node2;Req;;Type 21 request received from root@node2.supernodexp.hpc, sock=16
05/02/2018 09:03:26;0100;Server@node2;Req;;Type 19 request received from root@node2.supernodexp.hpc, sock=16
05/02/2018 09:03:27;0100;Server@node2;Req;;Type 0 request received from root@node2.supernodexp.hpc, sock=16
05/02/2018 09:03:27;0100;Server@node2;Req;;Type 49 request received from root@node2.supernodexp.hpc, sock=19
05/02/2018 09:03:27;0100;Server@node2;Req;;Type 21 request received from root@node2.supernodexp.hpc, sock=16
05/02/2018 09:03:27;0100;Server@node2;Req;;Type 19 request received from root@node2.supernodexp.hpc, sock=16
05/02/2018 09:03:28;0100;Server@node2;Req;;Type 0 request received from root@node2.supernodexp.hpc, sock=16
05/02/2018 09:03:28;0100;Server@node2;Req;;Type 49 request received from root@node2.supernodexp.hpc, sock=19
05/02/2018 09:03:28;0100;Server@node2;Req;;Type 21 request received from root@node2.supernodexp.hpc, sock=16
05/02/2018 09:03:28;0100;Server@node2;Req;;Type 19 request received from root@node2.supernodexp.hpc, sock=16
05/02/2018 09:03:29;0100;Server@node2;Req;;Type 0 request received from root@node2.supernodexp.hpc, sock=16
05/02/2018 09:03:29;0100;Server@node2;Req;;Type 49 request received from root@node2.supernodexp.hpc, sock=19
05/02/2018 09:03:29;0100;Server@node2;Req;;Type 21 request received from root@node2.supernodexp.hpc, sock=16
05/02/2018 09:03:29;0100;Server@node2;Req;;Type 19 request received from root@node2.supernodexp.hpc, sock=16
05/02/2018 09:03:32;0080;Server@node2;Job;13254.node2.supernodexp.hpc;Obit received momhop:1 serverhop:1 state:4 substate:42
05/02/2018 09:03:33;0010;Server@node2;Job;13254.node2.supernodexp.hpc;Exit_status=0 resources_used.cpupercent=1225 resources_used.cput=00:50:05 resources_used.mem=1117152kb resources_used.ncpus=16 resources_used.vmem=10374792kb resources_used.walltime=00:03:15
05/02/2018 09:03:33;0100;Server@node2;Job;13254.node2.supernodexp.hpc;dequeuing from workq, state 5
05/02/2018 09:03:33;0040;Server@node2;Svr;node2.supernodexp.hpc;Scheduler sent command 2
05/02/2018 09:03:33;0040;Server@node2;Svr;node2.supernodexp.hpc;Scheduler sent command 0
05/02/2018 09:03:33;0100;Server@node2;Req;;Type 21 request received from Scheduler@node2.supernodexp.hpc, sock=16
05/02/2018 09:03:33;0100;Server@node2;Req;;Type 81 request received from Scheduler@node2.supernodexp.hpc, sock=16
05/02/2018 09:03:33;0100;Server@node2;Req;;Type 71 request received from Scheduler@node2.supernodexp.hpc, sock=16
05/02/2018 09:03:33;0100;Server@node2;Req;;Type 58 request received from Scheduler@node2.supernodexp.hpc, sock=16
05/02/2018 09:03:33;0100;Server@node2;Req;;Type 20 request received from Scheduler@node2.supernodexp.hpc, sock=16
05/02/2018 09:03:33;0100;Server@node2;Req;;Type 51 request received from Scheduler@node2.supernodexp.hpc, sock=16
05/02/2018 09:03:33;0100;Server@node2;Req;;Type 23 request received from Scheduler@node2.supernodexp.hpc, sock=16
05/02/2018 09:03:33;0008;Server@node2;Job;13258.node2.supernodexp.hpc;Job Run at request of Scheduler@node2.supernodexp.hpc on exec_vnode (node14:ncpus=16:mpiprocs=16:mem=8388608kb)
05/02/2018 09:03:33;0001;Server@node2;Svr;Server@node2;Success (0) in req_runjob2, return value of svr_startjob is 0
05/02/2018 09:05:17;0080;Server@node2;Job;13256.node2.supernodexp.hpc;Obit received momhop:1 serverhop:1 state:4 substate:42
05/02/2018 09:05:18;0010;Server@node2;Job;13256.node2.supernodexp.hpc;Exit_status=0 resources_used.cpupercent=2215 resources_used.cput=01:52:45 resources_used.mem=3250220kb resources_used.ncpus=48 resources_used.vmem=33619580kb resources_used.walltime=00:02:31
05/02/2018 09:05:18;0100;Server@node2;Job;13256.node2.supernodexp.hpc;dequeuing from workq, state 5
05/02/2018 09:05:18;0040;Server@node2;Svr;node2.supernodexp.hpc;Scheduler sent command 2
05/02/2018 09:05:18;0040;Server@node2;Svr;node2.supernodexp.hpc;Scheduler sent command 0
05/02/2018 09:05:18;0100;Server@node2;Req;;Type 21 request received from Scheduler@node2.supernodexp.hpc, sock=16
05/02/2018 09:05:18;0100;Server@node2;Req;;Type 81 request received from Scheduler@node2.supernodexp.hpc, sock=16
05/02/2018 09:05:18;0100;Server@node2;Req;;Type 71 request received from Scheduler@node2.supernodexp.hpc, sock=16
05/02/2018 09:05:18;0100;Server@node2;Req;;Type 58 request received from Scheduler@node2.supernodexp.hpc, sock=16
05/02/2018 09:05:18;0100;Server@node2;Req;;Type 20 request received from Scheduler@node2.supernodexp.hpc, sock=16
05/02/2018 09:05:18;0100;Server@node2;Req;;Type 51 request received from Scheduler@node2.supernodexp.hpc, sock=16
05/02/2018 09:06:00;0080;Server@node2;Job;13259.node2.supernodexp.hpc;Obit received momhop:1 serverhop:1 state:4 substate:42
05/02/2018 09:06:01;0010;Server@node2;Job;13259.node2.supernodexp.hpc;Exit_status=0 resources_used.cpupercent=1962 resources_used.cput=01:57:45 resources_used.mem=3253532kb resources_used.ncpus=48 resources_used.vmem=33724968kb resources_used.walltime=00:02:42
05/02/2018 09:06:01;0100;Server@node2;Job;13259.node2.supernodexp.hpc;dequeuing from workq, state 5
05/02/2018 09:06:01;0040;Server@node2;Svr;node2.supernodexp.hpc;Scheduler sent command 2
05/02/2018 09:06:01;0040;Server@node2;Svr;node2.supernodexp.hpc;Scheduler sent command 0
05/02/2018 09:06:01;0100;Server@node2;Req;;Type 21 request received from Scheduler@node2.supernodexp.hpc, sock=16
05/02/2018 09:06:01;0100;Server@node2;Req;;Type 81 request received from Scheduler@node2.supernodexp.hpc, sock=16
05/02/2018 09:06:01;0100;Server@node2;Req;;Type 71 request received from Scheduler@node2.supernodexp.hpc, sock=16
05/02/2018 09:06:01;0100;Server@node2;Req;;Type 58 request received from Scheduler@node2.supernodexp.hpc, sock=16
05/02/2018 09:06:01;0100;Server@node2;Req;;Type 20 request received from Scheduler@node2.supernodexp.hpc, sock=16
05/02/2018 09:06:01;0100;Server@node2;Req;;Type 51 request received from Scheduler@node2.supernodexp.hpc, sock=16
05/02/2018 09:06:09;0080;Server@node2;Job;13257.node2.supernodexp.hpc;Obit received momhop:1 serverhop:1 state:4 substate:42
05/02/2018 09:06:10;0010;Server@node2;Job;13257.node2.supernodexp.hpc;Exit_status=0 resources_used.cpupercent=1415 resources_used.cput=01:03:56 resources_used.mem=1648916kb resources_used.ncpus=24 resources_used.vmem=15834036kb resources_used.walltime=00:02:48
05/02/2018 09:06:10;0100;Server@node2;Job;13257.node2.supernodexp.hpc;dequeuing from workq, state 5
05/02/2018 09:06:10;0040;Server@node2;Svr;node2.supernodexp.hpc;Scheduler sent command 2
05/02/2018 09:06:10;0040;Server@node2;Svr;node2.supernodexp.hpc;Scheduler sent command 0
05/02/2018 09:06:10;0100;Server@node2;Req;;Type 21 request received from Scheduler@node2.supernodexp.hpc, sock=16
05/02/2018 09:06:10;0100;Server@node2;Req;;Type 81 request received from Scheduler@node2.supernodexp.hpc, sock=16
05/02/2018 09:06:10;0100;Server@node2;Req;;Type 71 request received from Scheduler@node2.supernodexp.hpc, sock=16
05/02/2018 09:06:10;0100;Server@node2;Req;;Type 58 request received from Scheduler@node2.supernodexp.hpc, sock=16
05/02/2018 09:06:10;0100;Server@node2;Req;;Type 20 request received from Scheduler@node2.supernodexp.hpc, sock=16
05/02/2018 09:06:10;0100;Server@node2;Req;;Type 51 request received from Scheduler@node2.supernodexp.hpc, sock=16
05/02/2018 09:06:39;0080;Server@node2;Job;13258.node2.supernodexp.hpc;Obit received momhop:1 serverhop:1 state:4 substate:42
05/02/2018 09:06:39;0010;Server@node2;Job;13258.node2.supernodexp.hpc;Exit_status=0 resources_used.cpupercent=1026 resources_used.cput=00:47:26 resources_used.mem=1122392kb resources_used.ncpus=16 resources_used.vmem=10374872kb resources_used.walltime=00:03:05
05/02/2018 09:06:39;0100;Server@node2;Job;13258.node2.supernodexp.hpc;dequeuing from workq, state 5
05/02/2018 09:06:39;0040;Server@node2;Svr;node2.supernodexp.hpc;Scheduler sent command 2
05/02/2018 09:06:39;0040;Server@node2;Svr;node2.supernodexp.hpc;Scheduler sent command 0
05/02/2018 09:06:39;0100;Server@node2;Req;;Type 21 request received from Scheduler@node2.supernodexp.hpc, sock=16
05/02/2018 09:06:39;0100;Server@node2;Req;;Type 81 request received from Scheduler@node2.supernodexp.hpc, sock=16
05/02/2018 09:06:39;0100;Server@node2;Req;;Type 71 request received from Scheduler@node2.supernodexp.hpc, sock=16
05/02/2018 09:06:39;0100;Server@node2;Req;;Type 58 request received from Scheduler@node2.supernodexp.hpc, sock=16
05/02/2018 09:06:39;0100;Server@node2;Req;;Type 20 request received from Scheduler@node2.supernodexp.hpc, sock=16
05/02/2018 09:06:39;0100;Server@node2;Req;;Type 51 request received from Scheduler@node2.supernodexp.hpc, sock=16
05/02/2018 09:16:39;0040;Server@node2;Svr;node2.supernodexp.hpc;Scheduler sent command 3
05/02/2018 09:16:39;0040;Server@node2;Svr;node2.supernodexp.hpc;Scheduler sent command 0
05/02/2018 09:16:39;0100;Server@node2;Req;;Type 21 request received from Scheduler@node2.supernodexp.hpc, sock=16
05/02/2018 09:16:39;0100;Server@node2;Req;;Type 81 request received from Scheduler@node2.supernodexp.hpc, sock=16
05/02/2018 09:16:39;0100;Server@node2;Req;;Type 71 request received from Scheduler@node2.supernodexp.hpc, sock=16
05/02/2018 09:16:39;0100;Server@node2;Req;;Type 58 request received from Scheduler@node2.supernodexp.hpc, sock=16
05/02/2018 09:16:39;0100;Server@node2;Req;;Type 20 request received from Scheduler@node2.supernodexp.hpc, sock=16
05/02/2018 09:16:39;0100;Server@node2;Req;;Type 51 request received from Scheduler@node2.supernodexp.hpc, sock=16
05/02/2018 09:23:15;0100;Server@node2;Req;;Type 0 request received from baovo@node2.supernodexp.hpc, sock=16
05/02/2018 09:23:15;0100;Server@node2;Req;;Type 49 request received from baovo@node2.supernodexp.hpc, sock=19
05/02/2018 09:23:15;0100;Server@node2;Req;;Type 21 request received from baovo@node2.supernodexp.hpc, sock=16
05/02/2018 09:23:15;0100;Server@node2;Req;;Type 19 request received from baovo@node2.supernodexp.hpc, sock=16
05/02/2018 09:23:17;0100;Server@node2;Req;;Type 0 request received from baovo@node2.supernodexp.hpc, sock=16
05/02/2018 09:23:17;0100;Server@node2;Req;;Type 49 request received from baovo@node2.supernodexp.hpc, sock=19
05/02/2018 09:23:17;0100;Server@node2;Req;;Type 21 request received from baovo@node2.supernodexp.hpc, sock=16
05/02/2018 09:23:17;0100;Server@node2;Req;;Type 19 request received from baovo@node2.supernodexp.hpc, sock=16
05/02/2018 09:23:19;0100;Server@node2;Req;;Type 0 request received from baovo@node2.supernodexp.hpc, sock=16
05/02/2018 09:23:19;0100;Server@node2;Req;;Type 49 request received from baovo@node2.supernodexp.hpc, sock=19
05/02/2018 09:23:19;0100;Server@node2;Req;;Type 21 request received from baovo@node2.supernodexp.hpc, sock=16
05/02/2018 09:23:19;0100;Server@node2;Req;;Type 19 request received from baovo@node2.supernodexp.hpc, sock=16
05/02/2018 09:26:39;0040;Server@node2;Svr;node2.supernodexp.hpc;Scheduler sent command 3
05/02/2018 09:26:39;0040;Server@node2;Svr;node2.supernodexp.hpc;Scheduler sent command 0
05/02/2018 09:26:39;0100;Server@node2;Req;;Type 21 request received from Scheduler@node2.supernodexp.hpc, sock=16
05/02/2018 09:26:39;0100;Server@node2;Req;;Type 81 request received from Scheduler@node2.supernodexp.hpc, sock=16
05/02/2018 09:26:39;0100;Server@node2;Req;;Type 71 request received from Scheduler@node2.supernodexp.hpc, sock=16
05/02/2018 09:26:39;0100;Server@node2;Req;;Type 58 request received from Scheduler@node2.supernodexp.hpc, sock=16
05/02/2018 09:26:39;0100;Server@node2;Req;;Type 20 request received from Scheduler@node2.supernodexp.hpc, sock=16
05/02/2018 09:26:39;0100;Server@node2;Req;;Type 51 request received from Scheduler@node2.supernodexp.hpc, sock=16
05/02/2018 09:27:23;0100;Server@node2;Req;;Type 0 request received from baovo@node2.supernodexp.hpc, sock=16
05/02/2018 09:27:23;0100;Server@node2;Req;;Type 49 request received from baovo@node2.supernodexp.hpc, sock=19
05/02/2018 09:27:23;0100;Server@node2;Req;;Type 21 request received from baovo@node2.supernodexp.hpc, sock=16
05/02/2018 09:27:23;0100;Server@node2;Req;;Type 1 request received from baovo@node2.supernodexp.hpc, sock=16
05/02/2018 09:27:23;0100;Server@node2;Req;;Type 3 request received from baovo@node2.supernodexp.hpc, sock=16
05/02/2018 09:27:23;0100;Server@node2;Req;;Type 5 request received from baovo@node2.supernodexp.hpc, sock=16
05/02/2018 09:27:23;0100;Server@node2;Job;13260.node2.supernodexp.hpc;enqueuing into workq, state 1 hop 1
05/02/2018 09:27:23;0008;Server@node2;Job;13260.node2.supernodexp.hpc;Job Queued at request of baovo@node2.supernodexp.hpc, owner = baovo@node2.supernodexp.hpc, job name = shared-vir-mem, queue = workq
05/02/2018 09:27:23;0040;Server@node2;Svr;node2.supernodexp.hpc;Scheduler sent command 1
05/02/2018 09:27:23;0040;Server@node2;Svr;node2.supernodexp.hpc;Scheduler sent command 0
05/02/2018 09:27:23;0100;Server@node2;Req;;Type 21 request received from Scheduler@node2.supernodexp.hpc, sock=19
05/02/2018 09:27:23;0100;Server@node2;Req;;Type 81 request received from Scheduler@node2.supernodexp.hpc, sock=19
05/02/2018 09:27:23;0100;Server@node2;Req;;Type 71 request received from Scheduler@node2.supernodexp.hpc, sock=19
05/02/2018 09:27:23;0100;Server@node2;Req;;Type 58 request received from Scheduler@node2.supernodexp.hpc, sock=19
05/02/2018 09:27:23;0100;Server@node2;Req;;Type 1 request received from baovo@node2.supernodexp.hpc, sock=16
05/02/2018 09:27:23;0100;Server@node2;Req;;Type 3 request received from baovo@node2.supernodexp.hpc, sock=16
05/02/2018 09:27:23;0100;Server@node2;Req;;Type 5 request received from baovo@node2.supernodexp.hpc, sock=16
05/02/2018 09:27:23;0100;Server@node2;Job;13261.node2.supernodexp.hpc;enqueuing into workq, state 1 hop 1
05/02/2018 09:27:23;0008;Server@node2;Job;13261.node2.supernodexp.hpc;Job Queued at request of baovo@node2.supernodexp.hpc, owner = baovo@node2.supernodexp.hpc, job name = shared-vir-mem, queue = workq
05/02/2018 09:27:23;0100;Server@node2;Req;;Type 20 request received from Scheduler@node2.supernodexp.hpc, sock=19
05/02/2018 09:27:23;0100;Server@node2;Req;;Type 51 request received from Scheduler@node2.supernodexp.hpc, sock=19
05/02/2018 09:27:23;0100;Server@node2;Req;;Type 23 request received from Scheduler@node2.supernodexp.hpc, sock=19
05/02/2018 09:27:23;0008;Server@node2;Job;13260.node2.supernodexp.hpc;Job Run at request of Scheduler@node2.supernodexp.hpc on exec_vnode (node3:nmics=2:ncpus=2:mem=2097152kb)
05/02/2018 09:27:23;0001;Server@node2;Svr;Server@node2;Success (0) in req_runjob2, return value of svr_startjob is 0
05/02/2018 09:27:23;0100;Server@node2;Req;;Type 23 request received from Scheduler@node2.supernodexp.hpc, sock=19
05/02/2018 09:27:23;0008;Server@node2;Job;13261.node2.supernodexp.hpc;Job Run at request of Scheduler@node2.supernodexp.hpc on exec_vnode (node14:nmics=2:ncpus=2:mem=2097152kb)
05/02/2018 09:27:23;0001;Server@node2;Svr;Server@node2;Success (0) in req_runjob2, return value of svr_startjob is 0
05/02/2018 09:27:23;0040;Server@node2;Svr;node2.supernodexp.hpc;Scheduler sent command 1
05/02/2018 09:27:23;0040;Server@node2;Svr;node2.supernodexp.hpc;Scheduler sent command 0
05/02/2018 09:27:23;0100;Server@node2;Req;;Type 21 request received from Scheduler@node2.supernodexp.hpc, sock=19
05/02/2018 09:27:23;0100;Server@node2;Req;;Type 81 request received from Scheduler@node2.supernodexp.hpc, sock=19
05/02/2018 09:27:23;0100;Server@node2;Req;;Type 71 request received from Scheduler@node2.supernodexp.hpc, sock=19
05/02/2018 09:27:23;0100;Server@node2;Req;;Type 58 request received from Scheduler@node2.supernodexp.hpc, sock=19
05/02/2018 09:27:23;0100;Server@node2;Req;;Type 20 request received from Scheduler@node2.supernodexp.hpc, sock=19
05/02/2018 09:27:23;0100;Server@node2;Req;;Type 51 request received from Scheduler@node2.supernodexp.hpc, sock=19
05/02/2018 09:27:24;0100;Server@node2;Req;;Type 1 request received from baovo@node2.supernodexp.hpc, sock=16
05/02/2018 09:27:24;0100;Server@node2;Req;;Type 3 request received from baovo@node2.supernodexp.hpc, sock=16
05/02/2018 09:27:24;0100;Server@node2;Req;;Type 5 request received from baovo@node2.supernodexp.hpc, sock=16
05/02/2018 09:27:24;0100;Server@node2;Job;13262.node2.supernodexp.hpc;enqueuing into workq, state 1 hop 1
05/02/2018 09:27:24;0008;Server@node2;Job;13262.node2.supernodexp.hpc;Job Queued at request of baovo@node2.supernodexp.hpc, owner = baovo@node2.supernodexp.hpc, job name = parallelism-sweep-cpu8, queue = workq
05/02/2018 09:27:24;0040;Server@node2;Svr;node2.supernodexp.hpc;Scheduler sent command 1
05/02/2018 09:27:24;0040;Server@node2;Svr;node2.supernodexp.hpc;Scheduler sent command 0
05/02/2018 09:27:24;0100;Server@node2;Req;;Type 21 request received from Scheduler@node2.supernodexp.hpc, sock=19
05/02/2018 09:27:24;0100;Server@node2;Req;;Type 81 request received from Scheduler@node2.supernodexp.hpc, sock=19
05/02/2018 09:27:24;0100;Server@node2;Req;;Type 71 request received from Scheduler@node2.supernodexp.hpc, sock=19
05/02/2018 09:27:24;0100;Server@node2;Req;;Type 58 request received from Scheduler@node2.supernodexp.hpc, sock=19
05/02/2018 09:27:24;0100;Server@node2;Req;;Type 20 request received from Scheduler@node2.supernodexp.hpc, sock=19
05/02/2018 09:27:24;0100;Server@node2;Req;;Type 51 request received from Scheduler@node2.supernodexp.hpc, sock=19
05/02/2018 09:27:24;0100;Server@node2;Req;;Type 23 request received from Scheduler@node2.supernodexp.hpc, sock=19
05/02/2018 09:27:24;0008;Server@node2;Job;13262.node2.supernodexp.hpc;Job Run at request of Scheduler@node2.supernodexp.hpc on exec_vnode (node3:ncpus=8:mem=20971520kb)
05/02/2018 09:27:24;0001;Server@node2;Svr;Server@node2;Success (0) in req_runjob2, return value of svr_startjob is 0
05/02/2018 09:27:28;0080;Server@node2;Job;13261.node2.supernodexp.hpc;Obit received momhop:1 serverhop:1 state:4 substate:42
05/02/2018 09:27:28;0010;Server@node2;Job;13261.node2.supernodexp.hpc;Exit_status=0 resources_used.cpupercent=0 resources_used.cput=00:00:00 resources_used.mem=0kb resources_used.ncpus=2 resources_used.vmem=0kb resources_used.walltime=00:00:05
05/02/2018 09:27:28;0100;Server@node2;Job;13261.node2.supernodexp.hpc;dequeuing from workq, state 5
05/02/2018 09:27:28;0040;Server@node2;Svr;node2.supernodexp.hpc;Scheduler sent command 2
05/02/2018 09:27:28;0040;Server@node2;Svr;node2.supernodexp.hpc;Scheduler sent command 0
05/02/2018 09:27:28;0100;Server@node2;Req;;Type 21 request received from Scheduler@node2.supernodexp.hpc, sock=19
05/02/2018 09:27:28;0100;Server@node2;Req;;Type 81 request received from Scheduler@node2.supernodexp.hpc, sock=19
05/02/2018 09:27:28;0100;Server@node2;Req;;Type 71 request received from Scheduler@node2.supernodexp.hpc, sock=19
05/02/2018 09:27:28;0100;Server@node2;Req;;Type 58 request received from Scheduler@node2.supernodexp.hpc, sock=19
05/02/2018 09:27:28;0100;Server@node2;Req;;Type 20 request received from Scheduler@node2.supernodexp.hpc, sock=19
05/02/2018 09:27:28;0100;Server@node2;Req;;Type 51 request received from Scheduler@node2.supernodexp.hpc, sock=19
05/02/2018 09:27:30;0080;Server@node2;Job;13260.node2.supernodexp.hpc;Obit received momhop:1 serverhop:1 state:4 substate:42
05/02/2018 09:27:31;0010;Server@node2;Job;13260.node2.supernodexp.hpc;Exit_status=0 resources_used.cpupercent=0 resources_used.cput=00:00:00 resources_used.mem=0kb resources_used.ncpus=2 resources_used.vmem=0kb resources_used.walltime=00:00:09
05/02/2018 09:27:31;0100;Server@node2;Job;13260.node2.supernodexp.hpc;dequeuing from workq, state 5
05/02/2018 09:27:31;0080;Server@node2;Job;13262.node2.supernodexp.hpc;Obit received momhop:1 serverhop:1 state:4 substate:42
05/02/2018 09:27:31;0040;Server@node2;Svr;node2.supernodexp.hpc;Scheduler sent command 2
05/02/2018 09:27:31;0040;Server@node2;Svr;node2.supernodexp.hpc;Scheduler sent command 0
05/02/2018 09:27:31;0100;Server@node2;Req;;Type 21 request received from Scheduler@node2.supernodexp.hpc, sock=19
05/02/2018 09:27:31;0100;Server@node2;Req;;Type 81 request received from Scheduler@node2.supernodexp.hpc, sock=19
05/02/2018 09:27:31;0100;Server@node2;Req;;Type 71 request received from Scheduler@node2.supernodexp.hpc, sock=19
05/02/2018 09:27:31;0100;Server@node2;Req;;Type 58 request received from Scheduler@node2.supernodexp.hpc, sock=19
05/02/2018 09:27:31;0100;Server@node2;Req;;Type 20 request received from Scheduler@node2.supernodexp.hpc, sock=19
05/02/2018 09:27:31;0100;Server@node2;Req;;Type 51 request received from Scheduler@node2.supernodexp.hpc, sock=19
05/02/2018 09:27:32;0010;Server@node2;Job;13262.node2.supernodexp.hpc;Exit_status=0 resources_used.cpupercent=0 resources_used.cput=00:00:00 resources_used.mem=9096kb resources_used.ncpus=8 resources_used.vmem=105088kb resources_used.walltime=00:00:06
05/02/2018 09:27:32;0100;Server@node2;Job;13262.node2.supernodexp.hpc;dequeuing from workq, state 5
05/02/2018 09:27:32;0040;Server@node2;Svr;node2.supernodexp.hpc;Scheduler sent command 2
05/02/2018 09:27:32;0040;Server@node2;Svr;node2.supernodexp.hpc;Scheduler sent command 0
05/02/2018 09:27:32;0100;Server@node2;Req;;Type 21 request received from Scheduler@node2.supernodexp.hpc, sock=19
05/02/2018 09:27:32;0100;Server@node2;Req;;Type 81 request received from Scheduler@node2.supernodexp.hpc, sock=19
05/02/2018 09:27:32;0100;Server@node2;Req;;Type 71 request received from Scheduler@node2.supernodexp.hpc, sock=19
05/02/2018 09:27:32;0100;Server@node2;Req;;Type 58 request received from Scheduler@node2.supernodexp.hpc, sock=19
05/02/2018 09:27:32;0100;Server@node2;Req;;Type 20 request received from Scheduler@node2.supernodexp.hpc, sock=19
05/02/2018 09:27:32;0100;Server@node2;Req;;Type 51 request received from Scheduler@node2.supernodexp.hpc, sock=19
05/02/2018 09:27:55;0100;Server@node2;Req;;Type 1 request received from baovo@node2.supernodexp.hpc, sock=16
05/02/2018 09:27:55;0100;Server@node2;Req;;Type 3 request received from baovo@node2.supernodexp.hpc, sock=16
05/02/2018 09:27:55;0100;Server@node2;Req;;Type 5 request received from baovo@node2.supernodexp.hpc, sock=16
05/02/2018 09:27:55;0100;Server@node2;Job;13263.node2.supernodexp.hpc;enqueuing into workq, state 1 hop 1
05/02/2018 09:27:55;0008;Server@node2;Job;13263.node2.supernodexp.hpc;Job Queued at request of baovo@node2.supernodexp.hpc, owner = baovo@node2.supernodexp.hpc, job name = fft, queue = workq
05/02/2018 09:27:55;0040;Server@node2;Svr;node2.supernodexp.hpc;Scheduler sent command 1
05/02/2018 09:27:55;0040;Server@node2;Svr;node2.supernodexp.hpc;Scheduler sent command 0
05/02/2018 09:27:55;0100;Server@node2;Req;;Type 21 request received from Scheduler@node2.supernodexp.hpc, sock=19
05/02/2018 09:27:55;0100;Server@node2;Req;;Type 81 request received from Scheduler@node2.supernodexp.hpc, sock=19
05/02/2018 09:27:55;0100;Server@node2;Req;;Type 71 request received from Scheduler@node2.supernodexp.hpc, sock=19
05/02/2018 09:27:55;0100;Server@node2;Req;;Type 58 request received from Scheduler@node2.supernodexp.hpc, sock=19
05/02/2018 09:27:55;0100;Server@node2;Req;;Type 20 request received from Scheduler@node2.supernodexp.hpc, sock=19
05/02/2018 09:27:55;0100;Server@node2;Req;;Type 51 request received from Scheduler@node2.supernodexp.hpc, sock=19
05/02/2018 09:27:55;0100;Server@node2;Req;;Type 23 request received from Scheduler@node2.supernodexp.hpc, sock=19
05/02/2018 09:27:55;0008;Server@node2;Job;13263.node2.supernodexp.hpc;Job Run at request of Scheduler@node2.supernodexp.hpc on exec_vnode (node3:ncpus=12:mem=20971520kb)
05/02/2018 09:27:55;0001;Server@node2;Svr;Server@node2;Success (0) in req_runjob2, return value of svr_startjob is 0
05/02/2018 09:28:05;0100;Server@node2;Req;;Type 1 request received from baovo@node2.supernodexp.hpc, sock=16
05/02/2018 09:28:05;0100;Server@node2;Req;;Type 3 request received from baovo@node2.supernodexp.hpc, sock=16
05/02/2018 09:28:05;0100;Server@node2;Req;;Type 5 request received from baovo@node2.supernodexp.hpc, sock=16
05/02/2018 09:28:05;0100;Server@node2;Job;13264.node2.supernodexp.hpc;enqueuing into workq, state 1 hop 1
05/02/2018 09:28:05;0008;Server@node2;Job;13264.node2.supernodexp.hpc;Job Queued at request of baovo@node2.supernodexp.hpc, owner = baovo@node2.supernodexp.hpc, job name = nbody-100000, queue = workq
05/02/2018 09:28:05;0040;Server@node2;Svr;node2.supernodexp.hpc;Scheduler sent command 1
05/02/2018 09:28:05;0040;Server@node2;Svr;node2.supernodexp.hpc;Scheduler sent command 0
05/02/2018 09:28:05;0100;Server@node2;Req;;Type 21 request received from Scheduler@node2.supernodexp.hpc, sock=19
05/02/2018 09:28:05;0100;Server@node2;Req;;Type 81 request received from Scheduler@node2.supernodexp.hpc, sock=19
05/02/2018 09:28:05;0100;Server@node2;Req;;Type 71 request received from Scheduler@node2.supernodexp.hpc, sock=19
05/02/2018 09:28:05;0100;Server@node2;Req;;Type 58 request received from Scheduler@node2.supernodexp.hpc, sock=19
05/02/2018 09:28:05;0100;Server@node2;Req;;Type 20 request received from Scheduler@node2.supernodexp.hpc, sock=19
05/02/2018 09:28:05;0100;Server@node2;Req;;Type 51 request received from Scheduler@node2.supernodexp.hpc, sock=19
05/02/2018 09:28:05;0100;Server@node2;Req;;Type 23 request received from Scheduler@node2.supernodexp.hpc, sock=19
05/02/2018 09:28:05;0008;Server@node2;Job;13264.node2.supernodexp.hpc;Job Run at request of Scheduler@node2.supernodexp.hpc on exec_vnode (node3:ncpus=24:mem=5242880kb)
05/02/2018 09:28:05;0001;Server@node2;Svr;Server@node2;Success (0) in req_runjob2, return value of svr_startjob is 0
05/02/2018 09:28:08;0100;Server@node2;Req;;Type 1 request received from baovo@node2.supernodexp.hpc, sock=16
05/02/2018 09:28:08;0100;Server@node2;Req;;Type 3 request received from baovo@node2.supernodexp.hpc, sock=16
05/02/2018 09:28:08;0100;Server@node2;Req;;Type 5 request received from baovo@node2.supernodexp.hpc, sock=16
05/02/2018 09:28:08;0100;Server@node2;Job;13265.node2.supernodexp.hpc;enqueuing into workq, state 1 hop 1
05/02/2018 09:28:08;0008;Server@node2;Job;13265.node2.supernodexp.hpc;Job Queued at request of baovo@node2.supernodexp.hpc, owner = baovo@node2.supernodexp.hpc, job name = benchmark-offload, queue = workq
05/02/2018 09:28:08;0040;Server@node2;Svr;node2.supernodexp.hpc;Scheduler sent command 1
05/02/2018 09:28:08;0040;Server@node2;Svr;node2.supernodexp.hpc;Scheduler sent command 0
05/02/2018 09:28:08;0100;Server@node2;Req;;Type 21 request received from Scheduler@node2.supernodexp.hpc, sock=19
05/02/2018 09:28:08;0100;Server@node2;Req;;Type 81 request received from Scheduler@node2.supernodexp.hpc, sock=19
05/02/2018 09:28:08;0100;Server@node2;Req;;Type 71 request received from Scheduler@node2.supernodexp.hpc, sock=19
05/02/2018 09:28:08;0100;Server@node2;Req;;Type 58 request received from Scheduler@node2.supernodexp.hpc, sock=19
05/02/2018 09:28:08;0100;Server@node2;Req;;Type 20 request received from Scheduler@node2.supernodexp.hpc, sock=19
05/02/2018 09:28:08;0100;Server@node2;Req;;Type 51 request received from Scheduler@node2.supernodexp.hpc, sock=19
05/02/2018 09:28:08;0100;Server@node2;Req;;Type 23 request received from Scheduler@node2.supernodexp.hpc, sock=19
05/02/2018 09:28:08;0008;Server@node2;Job;13265.node2.supernodexp.hpc;Job Run at request of Scheduler@node2.supernodexp.hpc on exec_vnode (node3:nmics=2:ncpus=2:mem=41943040kb)
05/02/2018 09:28:08;0001;Server@node2;Svr;Server@node2;Success (0) in req_runjob2, return value of svr_startjob is 0
05/02/2018 09:28:10;0100;Server@node2;Req;;Type 0 request received from baovo@node2.supernodexp.hpc, sock=19
05/02/2018 09:28:10;0100;Server@node2;Req;;Type 49 request received from baovo@node2.supernodexp.hpc, sock=20
05/02/2018 09:28:10;0100;Server@node2;Req;;Type 21 request received from baovo@node2.supernodexp.hpc, sock=19
05/02/2018 09:28:10;0100;Server@node2;Req;;Type 19 request received from baovo@node2.supernodexp.hpc, sock=19
05/02/2018 09:28:11;0100;Server@node2;Req;;Type 0 request received from baovo@node2.supernodexp.hpc, sock=19
05/02/2018 09:28:11;0100;Server@node2;Req;;Type 49 request received from baovo@node2.supernodexp.hpc, sock=20
05/02/2018 09:28:11;0100;Server@node2;Req;;Type 21 request received from baovo@node2.supernodexp.hpc, sock=19
05/02/2018 09:28:11;0100;Server@node2;Req;;Type 19 request received from baovo@node2.supernodexp.hpc, sock=19
05/02/2018 09:28:12;0100;Server@node2;Req;;Type 0 request received from baovo@node2.supernodexp.hpc, sock=19
05/02/2018 09:28:12;0100;Server@node2;Req;;Type 49 request received from baovo@node2.supernodexp.hpc, sock=20
05/02/2018 09:28:12;0100;Server@node2;Req;;Type 21 request received from baovo@node2.supernodexp.hpc, sock=19
05/02/2018 09:28:12;0100;Server@node2;Req;;Type 19 request received from baovo@node2.supernodexp.hpc, sock=19
05/02/2018 09:28:12;0080;Server@node2;Job;13264.node2.supernodexp.hpc;Obit received momhop:1 serverhop:1 state:4 substate:42
05/02/2018 09:28:13;0100;Server@node2;Req;;Type 0 request received from baovo@node2.supernodexp.hpc, sock=19
05/02/2018 09:28:13;0100;Server@node2;Req;;Type 49 request received from baovo@node2.supernodexp.hpc, sock=20
05/02/2018 09:28:13;0100;Server@node2;Req;;Type 21 request received from baovo@node2.supernodexp.hpc, sock=19
05/02/2018 09:28:13;0100;Server@node2;Req;;Type 19 request received from baovo@node2.supernodexp.hpc, sock=19
05/02/2018 09:28:13;0010;Server@node2;Job;13264.node2.supernodexp.hpc;Exit_status=0 resources_used.cpupercent=0 resources_used.cput=00:00:00 resources_used.mem=0kb resources_used.ncpus=24 resources_used.vmem=0kb resources_used.walltime=00:00:09
05/02/2018 09:28:13;0100;Server@node2;Job;13264.node2.supernodexp.hpc;dequeuing from workq, state 5
05/02/2018 09:28:13;0040;Server@node2;Svr;node2.supernodexp.hpc;Scheduler sent command 2
05/02/2018 09:28:13;0040;Server@node2;Svr;node2.supernodexp.hpc;Scheduler sent command 0
05/02/2018 09:28:13;0100;Server@node2;Req;;Type 21 request received from Scheduler@node2.supernodexp.hpc, sock=19
05/02/2018 09:28:13;0100;Server@node2;Req;;Type 81 request received from Scheduler@node2.supernodexp.hpc, sock=19
05/02/2018 09:28:13;0100;Server@node2;Req;;Type 71 request received from Scheduler@node2.supernodexp.hpc, sock=19
05/02/2018 09:28:13;0100;Server@node2;Req;;Type 58 request received from Scheduler@node2.supernodexp.hpc, sock=19
05/02/2018 09:28:13;0100;Server@node2;Req;;Type 20 request received from Scheduler@node2.supernodexp.hpc, sock=19
05/02/2018 09:28:13;0100;Server@node2;Req;;Type 51 request received from Scheduler@node2.supernodexp.hpc, sock=19
05/02/2018 09:28:14;0100;Server@node2;Req;;Type 0 request received from baovo@node2.supernodexp.hpc, sock=19
05/02/2018 09:28:14;0100;Server@node2;Req;;Type 49 request received from baovo@node2.supernodexp.hpc, sock=20
05/02/2018 09:28:14;0100;Server@node2;Req;;Type 21 request received from baovo@node2.supernodexp.hpc, sock=19
05/02/2018 09:28:14;0100;Server@node2;Req;;Type 19 request received from baovo@node2.supernodexp.hpc, sock=19
05/02/2018 09:28:15;0100;Server@node2;Req;;Type 0 request received from baovo@node2.supernodexp.hpc, sock=19
05/02/2018 09:28:15;0100;Server@node2;Req;;Type 49 request received from baovo@node2.supernodexp.hpc, sock=20
05/02/2018 09:28:15;0100;Server@node2;Req;;Type 21 request received from baovo@node2.supernodexp.hpc, sock=19
05/02/2018 09:28:15;0100;Server@node2;Req;;Type 19 request received from baovo@node2.supernodexp.hpc, sock=19
05/02/2018 09:28:15;0100;Server@node2;Req;;Type 0 request received from baovo@node2.supernodexp.hpc, sock=19
05/02/2018 09:28:15;0100;Server@node2;Req;;Type 49 request received from baovo@node2.supernodexp.hpc, sock=20
05/02/2018 09:28:15;0100;Server@node2;Req;;Type 21 request received from baovo@node2.supernodexp.hpc, sock=19
05/02/2018 09:28:15;0100;Server@node2;Req;;Type 19 request received from baovo@node2.supernodexp.hpc, sock=19
05/02/2018 09:28:16;0100;Server@node2;Req;;Type 0 request received from baovo@node2.supernodexp.hpc, sock=19
05/02/2018 09:28:16;0100;Server@node2;Req;;Type 49 request received from baovo@node2.supernodexp.hpc, sock=20
05/02/2018 09:28:16;0100;Server@node2;Req;;Type 21 request received from baovo@node2.supernodexp.hpc, sock=19
05/02/2018 09:28:16;0100;Server@node2;Req;;Type 19 request received from baovo@node2.supernodexp.hpc, sock=19
05/02/2018 09:28:20;0100;Server@node2;Req;;Type 1 request received from baovo@node2.supernodexp.hpc, sock=16
05/02/2018 09:28:20;0100;Server@node2;Req;;Type 3 request received from baovo@node2.supernodexp.hpc, sock=16
05/02/2018 09:28:20;0100;Server@node2;Req;;Type 5 request received from baovo@node2.supernodexp.hpc, sock=16
05/02/2018 09:28:20;0100;Server@node2;Job;13266.node2.supernodexp.hpc;enqueuing into workq, state 1 hop 1
05/02/2018 09:28:20;0008;Server@node2;Job;13266.node2.supernodexp.hpc;Job Queued at request of baovo@node2.supernodexp.hpc, owner = baovo@node2.supernodexp.hpc, job name = mkl-25000, queue = workq
05/02/2018 09:28:20;0040;Server@node2;Svr;node2.supernodexp.hpc;Scheduler sent command 1
05/02/2018 09:28:20;0040;Server@node2;Svr;node2.supernodexp.hpc;Scheduler sent command 0
05/02/2018 09:28:20;0100;Server@node2;Req;;Type 21 request received from Scheduler@node2.supernodexp.hpc, sock=19
05/02/2018 09:28:20;0100;Server@node2;Req;;Type 81 request received from Scheduler@node2.supernodexp.hpc, sock=19
05/02/2018 09:28:20;0100;Server@node2;Req;;Type 71 request received from Scheduler@node2.supernodexp.hpc, sock=19
05/02/2018 09:28:20;0100;Server@node2;Req;;Type 58 request received from Scheduler@node2.supernodexp.hpc, sock=19
05/02/2018 09:28:20;0100;Server@node2;Req;;Type 20 request received from Scheduler@node2.supernodexp.hpc, sock=19
05/02/2018 09:28:20;0100;Server@node2;Req;;Type 51 request received from Scheduler@node2.supernodexp.hpc, sock=19
05/02/2018 09:28:20;0100;Server@node2;Req;;Type 23 request received from Scheduler@node2.supernodexp.hpc, sock=19
05/02/2018 09:28:20;0008;Server@node2;Job;13266.node2.supernodexp.hpc;Job Run at request of Scheduler@node2.supernodexp.hpc on exec_vnode (node3:ncpus=12:mem=20971520kb)
05/02/2018 09:28:20;0001;Server@node2;Svr;Server@node2;Success (0) in req_runjob2, return value of svr_startjob is 0
05/02/2018 09:28:22;0100;Server@node2;Req;;Type 1 request received from baovo@node2.supernodexp.hpc, sock=16
05/02/2018 09:28:22;0100;Server@node2;Req;;Type 3 request received from baovo@node2.supernodexp.hpc, sock=16
05/02/2018 09:28:22;0100;Server@node2;Req;;Type 5 request received from baovo@node2.supernodexp.hpc, sock=16
05/02/2018 09:28:22;0100;Server@node2;Job;13267.node2.supernodexp.hpc;enqueuing into workq, state 1 hop 1
05/02/2018 09:28:22;0008;Server@node2;Job;13267.node2.supernodexp.hpc;Job Queued at request of baovo@node2.supernodexp.hpc, owner = baovo@node2.supernodexp.hpc, job name = lu-decomp-100000-mem20, queue = workq
05/02/2018 09:28:22;0040;Server@node2;Svr;node2.supernodexp.hpc;Scheduler sent command 1
05/02/2018 09:28:22;0040;Server@node2;Svr;node2.supernodexp.hpc;Scheduler sent command 0
05/02/2018 09:28:22;0100;Server@node2;Req;;Type 21 request received from Scheduler@node2.supernodexp.hpc, sock=19
05/02/2018 09:28:22;0100;Server@node2;Req;;Type 81 request received from Scheduler@node2.supernodexp.hpc, sock=19
05/02/2018 09:28:22;0100;Server@node2;Req;;Type 71 request received from Scheduler@node2.supernodexp.hpc, sock=19
05/02/2018 09:28:22;0100;Server@node2;Req;;Type 58 request received from Scheduler@node2.supernodexp.hpc, sock=19
05/02/2018 09:28:22;0100;Server@node2;Req;;Type 20 request received from Scheduler@node2.supernodexp.hpc, sock=19
05/02/2018 09:28:22;0100;Server@node2;Req;;Type 51 request received from Scheduler@node2.supernodexp.hpc, sock=19
05/02/2018 09:28:22;0100;Server@node2;Req;;Type 23 request received from Scheduler@node2.supernodexp.hpc, sock=19
05/02/2018 09:28:22;0008;Server@node2;Job;13267.node2.supernodexp.hpc;Job Run at request of Scheduler@node2.supernodexp.hpc on exec_vnode (node3:ncpus=8:mem=20971520kb)
05/02/2018 09:28:22;0001;Server@node2;Svr;Server@node2;Success (0) in req_runjob2, return value of svr_startjob is 0
05/02/2018 09:28:33;0100;Server@node2;Req;;Type 0 request received from baovo@node2.supernodexp.hpc, sock=19
05/02/2018 09:28:33;0100;Server@node2;Req;;Type 49 request received from baovo@node2.supernodexp.hpc, sock=20
05/02/2018 09:28:33;0100;Server@node2;Req;;Type 21 request received from baovo@node2.supernodexp.hpc, sock=19
05/02/2018 09:28:33;0100;Server@node2;Req;;Type 19 request received from baovo@node2.supernodexp.hpc, sock=19
05/02/2018 09:28:34;0100;Server@node2;Req;;Type 0 request received from baovo@node2.supernodexp.hpc, sock=19
05/02/2018 09:28:34;0100;Server@node2;Req;;Type 49 request received from baovo@node2.supernodexp.hpc, sock=20
05/02/2018 09:28:34;0100;Server@node2;Req;;Type 21 request received from baovo@node2.supernodexp.hpc, sock=19
05/02/2018 09:28:34;0100;Server@node2;Req;;Type 19 request received from baovo@node2.supernodexp.hpc, sock=19
05/02/2018 09:28:42;0100;Server@node2;Req;;Type 1 request received from baovo@node2.supernodexp.hpc, sock=16
05/02/2018 09:28:42;0100;Server@node2;Req;;Type 3 request received from baovo@node2.supernodexp.hpc, sock=16
05/02/2018 09:28:42;0100;Server@node2;Req;;Type 5 request received from baovo@node2.supernodexp.hpc, sock=16
05/02/2018 09:28:42;0100;Server@node2;Job;13268.node2.supernodexp.hpc;enqueuing into workq, state 1 hop 1
05/02/2018 09:28:42;0008;Server@node2;Job;13268.node2.supernodexp.hpc;Job Queued at request of baovo@node2.supernodexp.hpc, owner = baovo@node2.supernodexp.hpc, job name = lu-decomp-100000-mem5, queue = workq
05/02/2018 09:28:42;0040;Server@node2;Svr;node2.supernodexp.hpc;Scheduler sent command 1
05/02/2018 09:28:42;0040;Server@node2;Svr;node2.supernodexp.hpc;Scheduler sent command 0
05/02/2018 09:28:42;0100;Server@node2;Req;;Type 21 request received from Scheduler@node2.supernodexp.hpc, sock=19
05/02/2018 09:28:42;0100;Server@node2;Req;;Type 81 request received from Scheduler@node2.supernodexp.hpc, sock=19
05/02/2018 09:28:42;0100;Server@node2;Req;;Type 71 request received from Scheduler@node2.supernodexp.hpc, sock=19
05/02/2018 09:28:42;0100;Server@node2;Req;;Type 58 request received from Scheduler@node2.supernodexp.hpc, sock=19
05/02/2018 09:28:42;0100;Server@node2;Req;;Type 20 request received from Scheduler@node2.supernodexp.hpc, sock=19
05/02/2018 09:28:42;0100;Server@node2;Req;;Type 51 request received from Scheduler@node2.supernodexp.hpc, sock=19
05/02/2018 09:28:42;0100;Server@node2;Req;;Type 23 request received from Scheduler@node2.supernodexp.hpc, sock=19
05/02/2018 09:28:42;0008;Server@node2;Job;13268.node2.supernodexp.hpc;Job Run at request of Scheduler@node2.supernodexp.hpc on exec_vnode (node3:ncpus=8:mem=5242880kb)
05/02/2018 09:28:42;0001;Server@node2;Svr;Server@node2;Success (0) in req_runjob2, return value of svr_startjob is 0
05/02/2018 09:28:57;0080;Server@node2;Job;13267.node2.supernodexp.hpc;Obit received momhop:1 serverhop:1 state:4 substate:42
05/02/2018 09:28:58;0010;Server@node2;Job;13267.node2.supernodexp.hpc;Exit_status=0 resources_used.cpupercent=0 resources_used.cput=00:00:00 resources_used.mem=9068kb resources_used.ncpus=8 resources_used.vmem=105344kb resources_used.walltime=00:00:35
05/02/2018 09:28:58;0100;Server@node2;Job;13267.node2.supernodexp.hpc;dequeuing from workq, state 5
05/02/2018 09:28:58;0040;Server@node2;Svr;node2.supernodexp.hpc;Scheduler sent command 2
05/02/2018 09:28:58;0040;Server@node2;Svr;node2.supernodexp.hpc;Scheduler sent command 0
05/02/2018 09:28:58;0100;Server@node2;Req;;Type 21 request received from Scheduler@node2.supernodexp.hpc, sock=19
05/02/2018 09:28:58;0100;Server@node2;Req;;Type 81 request received from Scheduler@node2.supernodexp.hpc, sock=19
05/02/2018 09:28:58;0100;Server@node2;Req;;Type 71 request received from Scheduler@node2.supernodexp.hpc, sock=19
05/02/2018 09:28:58;0100;Server@node2;Req;;Type 58 request received from Scheduler@node2.supernodexp.hpc, sock=19
05/02/2018 09:28:58;0100;Server@node2;Req;;Type 20 request received from Scheduler@node2.supernodexp.hpc, sock=19
05/02/2018 09:28:58;0100;Server@node2;Req;;Type 51 request received from Scheduler@node2.supernodexp.hpc, sock=19
05/02/2018 09:29:05;0080;Server@node2;Job;13268.node2.supernodexp.hpc;Obit received momhop:1 serverhop:1 state:4 substate:42
05/02/2018 09:29:06;0010;Server@node2;Job;13268.node2.supernodexp.hpc;Exit_status=0 resources_used.cpupercent=0 resources_used.cput=00:00:00 resources_used.mem=9084kb resources_used.ncpus=8 resources_used.vmem=172288kb resources_used.walltime=00:00:23
05/02/2018 09:29:06;0100;Server@node2;Job;13268.node2.supernodexp.hpc;dequeuing from workq, state 5
05/02/2018 09:29:06;0040;Server@node2;Svr;node2.supernodexp.hpc;Scheduler sent command 2
05/02/2018 09:29:06;0040;Server@node2;Svr;node2.supernodexp.hpc;Scheduler sent command 0
05/02/2018 09:29:06;0100;Server@node2;Req;;Type 21 request received from Scheduler@node2.supernodexp.hpc, sock=19
05/02/2018 09:29:06;0100;Server@node2;Req;;Type 81 request received from Scheduler@node2.supernodexp.hpc, sock=19
05/02/2018 09:29:06;0100;Server@node2;Req;;Type 71 request received from Scheduler@node2.supernodexp.hpc, sock=19
05/02/2018 09:29:06;0100;Server@node2;Req;;Type 58 request received from Scheduler@node2.supernodexp.hpc, sock=19
05/02/2018 09:29:06;0100;Server@node2;Req;;Type 20 request received from Scheduler@node2.supernodexp.hpc, sock=19
05/02/2018 09:29:06;0100;Server@node2;Req;;Type 51 request received from Scheduler@node2.supernodexp.hpc, sock=19
05/02/2018 09:29:06;0100;Server@node2;Req;;Type 1 request received from baovo@node2.supernodexp.hpc, sock=16
05/02/2018 09:29:06;0100;Server@node2;Req;;Type 3 request received from baovo@node2.supernodexp.hpc, sock=16
05/02/2018 09:29:06;0100;Server@node2;Req;;Type 5 request received from baovo@node2.supernodexp.hpc, sock=16
05/02/2018 09:29:06;0100;Server@node2;Job;13269.node2.supernodexp.hpc;enqueuing into workq, state 1 hop 1
05/02/2018 09:29:06;0008;Server@node2;Job;13269.node2.supernodexp.hpc;Job Queued at request of baovo@node2.supernodexp.hpc, owner = baovo@node2.supernodexp.hpc, job name = lu-decomp-100000-mem10, queue = workq
05/02/2018 09:29:06;0040;Server@node2;Svr;node2.supernodexp.hpc;Scheduler sent command 1
05/02/2018 09:29:06;0040;Server@node2;Svr;node2.supernodexp.hpc;Scheduler sent command 0
05/02/2018 09:29:06;0100;Server@node2;Req;;Type 21 request received from Scheduler@node2.supernodexp.hpc, sock=19
05/02/2018 09:29:06;0100;Server@node2;Req;;Type 81 request received from Scheduler@node2.supernodexp.hpc, sock=19
05/02/2018 09:29:06;0100;Server@node2;Req;;Type 71 request received from Scheduler@node2.supernodexp.hpc, sock=19
05/02/2018 09:29:06;0100;Server@node2;Req;;Type 58 request received from Scheduler@node2.supernodexp.hpc, sock=19
05/02/2018 09:29:06;0100;Server@node2;Req;;Type 20 request received from Scheduler@node2.supernodexp.hpc, sock=19
05/02/2018 09:29:06;0100;Server@node2;Req;;Type 51 request received from Scheduler@node2.supernodexp.hpc, sock=19
05/02/2018 09:29:06;0100;Server@node2;Req;;Type 23 request received from Scheduler@node2.supernodexp.hpc, sock=19
05/02/2018 09:29:06;0008;Server@node2;Job;13269.node2.supernodexp.hpc;Job Run at request of Scheduler@node2.supernodexp.hpc on exec_vnode (node3:ncpus=8:mem=10485760kb)
05/02/2018 09:29:06;0001;Server@node2;Svr;Server@node2;Success (0) in req_runjob2, return value of svr_startjob is 0
05/02/2018 09:29:17;0100;Server@node2;Req;;Type 1 request received from baovo@node2.supernodexp.hpc, sock=16
05/02/2018 09:29:17;0100;Server@node2;Req;;Type 3 request received from baovo@node2.supernodexp.hpc, sock=16
05/02/2018 09:29:17;0100;Server@node2;Req;;Type 5 request received from baovo@node2.supernodexp.hpc, sock=16
05/02/2018 09:29:17;0100;Server@node2;Job;13270.node2.supernodexp.hpc;enqueuing into workq, state 1 hop 1
05/02/2018 09:29:17;0008;Server@node2;Job;13270.node2.supernodexp.hpc;Job Queued at request of baovo@node2.supernodexp.hpc, owner = baovo@node2.supernodexp.hpc, job name = shared-vir-mem, queue = workq
05/02/2018 09:29:17;0040;Server@node2;Svr;node2.supernodexp.hpc;Scheduler sent command 1
05/02/2018 09:29:17;0040;Server@node2;Svr;node2.supernodexp.hpc;Scheduler sent command 0
05/02/2018 09:29:17;0100;Server@node2;Req;;Type 21 request received from Scheduler@node2.supernodexp.hpc, sock=19
05/02/2018 09:29:17;0100;Server@node2;Req;;Type 81 request received from Scheduler@node2.supernodexp.hpc, sock=19
05/02/2018 09:29:17;0100;Server@node2;Req;;Type 71 request received from Scheduler@node2.supernodexp.hpc, sock=19
05/02/2018 09:29:17;0100;Server@node2;Req;;Type 58 request received from Scheduler@node2.supernodexp.hpc, sock=19
05/02/2018 09:29:17;0100;Server@node2;Req;;Type 20 request received from Scheduler@node2.supernodexp.hpc, sock=19
05/02/2018 09:29:17;0100;Server@node2;Req;;Type 51 request received from Scheduler@node2.supernodexp.hpc, sock=19
05/02/2018 09:29:17;0100;Server@node2;Req;;Type 23 request received from Scheduler@node2.supernodexp.hpc, sock=19
05/02/2018 09:29:17;0008;Server@node2;Job;13270.node2.supernodexp.hpc;Job Run at request of Scheduler@node2.supernodexp.hpc on exec_vnode (node14:nmics=2:ncpus=2:mem=2097152kb)
05/02/2018 09:29:17;0001;Server@node2;Svr;Server@node2;Success (0) in req_runjob2, return value of svr_startjob is 0
05/02/2018 09:29:22;0080;Server@node2;Job;13270.node2.supernodexp.hpc;Obit received momhop:1 serverhop:1 state:4 substate:42
05/02/2018 09:29:22;0010;Server@node2;Job;13270.node2.supernodexp.hpc;Exit_status=0 resources_used.cpupercent=0 resources_used.cput=00:00:00 resources_used.mem=0kb resources_used.ncpus=2 resources_used.vmem=0kb resources_used.walltime=00:00:06
05/02/2018 09:29:22;0100;Server@node2;Job;13270.node2.supernodexp.hpc;dequeuing from workq, state 5
05/02/2018 09:29:22;0040;Server@node2;Svr;node2.supernodexp.hpc;Scheduler sent command 2
05/02/2018 09:29:22;0040;Server@node2;Svr;node2.supernodexp.hpc;Scheduler sent command 0
05/02/2018 09:29:22;0100;Server@node2;Req;;Type 21 request received from Scheduler@node2.supernodexp.hpc, sock=19
05/02/2018 09:29:22;0100;Server@node2;Req;;Type 81 request received from Scheduler@node2.supernodexp.hpc, sock=19
05/02/2018 09:29:22;0100;Server@node2;Req;;Type 71 request received from Scheduler@node2.supernodexp.hpc, sock=19
05/02/2018 09:29:22;0100;Server@node2;Req;;Type 58 request received from Scheduler@node2.supernodexp.hpc, sock=19
05/02/2018 09:29:22;0100;Server@node2;Req;;Type 20 request received from Scheduler@node2.supernodexp.hpc, sock=19
05/02/2018 09:29:22;0100;Server@node2;Req;;Type 51 request received from Scheduler@node2.supernodexp.hpc, sock=19
05/02/2018 09:29:27;0100;Server@node2;Req;;Type 1 request received from baovo@node2.supernodexp.hpc, sock=16
05/02/2018 09:29:27;0100;Server@node2;Req;;Type 3 request received from baovo@node2.supernodexp.hpc, sock=16
05/02/2018 09:29:27;0100;Server@node2;Req;;Type 5 request received from baovo@node2.supernodexp.hpc, sock=16
05/02/2018 09:29:27;0100;Server@node2;Job;13271.node2.supernodexp.hpc;enqueuing into workq, state 1 hop 1
05/02/2018 09:29:27;0008;Server@node2;Job;13271.node2.supernodexp.hpc;Job Queued at request of baovo@node2.supernodexp.hpc, owner = baovo@node2.supernodexp.hpc, job name = md, queue = workq
05/02/2018 09:29:27;0040;Server@node2;Svr;node2.supernodexp.hpc;Scheduler sent command 1
05/02/2018 09:29:27;0040;Server@node2;Svr;node2.supernodexp.hpc;Scheduler sent command 0
05/02/2018 09:29:27;0100;Server@node2;Req;;Type 21 request received from Scheduler@node2.supernodexp.hpc, sock=19
05/02/2018 09:29:27;0100;Server@node2;Req;;Type 81 request received from Scheduler@node2.supernodexp.hpc, sock=19
05/02/2018 09:29:27;0100;Server@node2;Req;;Type 71 request received from Scheduler@node2.supernodexp.hpc, sock=19
05/02/2018 09:29:27;0100;Server@node2;Req;;Type 58 request received from Scheduler@node2.supernodexp.hpc, sock=19
05/02/2018 09:29:27;0100;Server@node2;Req;;Type 20 request received from Scheduler@node2.supernodexp.hpc, sock=19
05/02/2018 09:29:27;0100;Server@node2;Req;;Type 51 request received from Scheduler@node2.supernodexp.hpc, sock=19
05/02/2018 09:29:27;0100;Server@node2;Req;;Type 23 request received from Scheduler@node2.supernodexp.hpc, sock=19
05/02/2018 09:29:27;0008;Server@node2;Job;13271.node2.supernodexp.hpc;Job Run at request of Scheduler@node2.supernodexp.hpc on exec_vnode (node3:ncpus=8:mem=3145728kb)
05/02/2018 09:29:27;0001;Server@node2;Svr;Server@node2;Success (0) in req_runjob2, return value of svr_startjob is 0
05/02/2018 09:29:28;0100;Server@node2;Req;;Type 1 request received from baovo@node2.supernodexp.hpc, sock=16
05/02/2018 09:29:28;0100;Server@node2;Req;;Type 3 request received from baovo@node2.supernodexp.hpc, sock=16
05/02/2018 09:29:28;0100;Server@node2;Req;;Type 5 request received from baovo@node2.supernodexp.hpc, sock=16
05/02/2018 09:29:28;0100;Server@node2;Job;13272.node2.supernodexp.hpc;enqueuing into workq, state 1 hop 1
05/02/2018 09:29:28;0008;Server@node2;Job;13272.node2.supernodexp.hpc;Job Queued at request of baovo@node2.supernodexp.hpc, owner = baovo@node2.supernodexp.hpc, job name = vec-data-cpu4, queue = workq
05/02/2018 09:29:28;0040;Server@node2;Svr;node2.supernodexp.hpc;Scheduler sent command 1
05/02/2018 09:29:28;0040;Server@node2;Svr;node2.supernodexp.hpc;Scheduler sent command 0
05/02/2018 09:29:28;0100;Server@node2;Req;;Type 21 request received from Scheduler@node2.supernodexp.hpc, sock=19
05/02/2018 09:29:28;0100;Server@node2;Req;;Type 81 request received from Scheduler@node2.supernodexp.hpc, sock=19
05/02/2018 09:29:28;0100;Server@node2;Req;;Type 71 request received from Scheduler@node2.supernodexp.hpc, sock=19
05/02/2018 09:29:28;0100;Server@node2;Req;;Type 58 request received from Scheduler@node2.supernodexp.hpc, sock=19
05/02/2018 09:29:28;0100;Server@node2;Req;;Type 20 request received from Scheduler@node2.supernodexp.hpc, sock=19
05/02/2018 09:29:28;0100;Server@node2;Req;;Type 51 request received from Scheduler@node2.supernodexp.hpc, sock=19
05/02/2018 09:29:28;0100;Server@node2;Req;;Type 23 request received from Scheduler@node2.supernodexp.hpc, sock=19
05/02/2018 09:29:28;0008;Server@node2;Job;13272.node2.supernodexp.hpc;Job Run at request of Scheduler@node2.supernodexp.hpc on exec_vnode (node3:ncpus=4:mem=5242880kb)
05/02/2018 09:29:28;0001;Server@node2;Svr;Server@node2;Success (0) in req_runjob2, return value of svr_startjob is 0
05/02/2018 09:29:36;0080;Server@node2;Job;13269.node2.supernodexp.hpc;Obit received momhop:1 serverhop:1 state:4 substate:42
05/02/2018 09:29:37;0010;Server@node2;Job;13269.node2.supernodexp.hpc;Exit_status=0 resources_used.cpupercent=0 resources_used.cput=00:00:00 resources_used.mem=9348kb resources_used.ncpus=8 resources_used.vmem=103292kb resources_used.walltime=00:00:31
05/02/2018 09:29:37;0100;Server@node2;Job;13269.node2.supernodexp.hpc;dequeuing from workq, state 5
05/02/2018 09:29:37;0040;Server@node2;Svr;node2.supernodexp.hpc;Scheduler sent command 2
05/02/2018 09:29:37;0040;Server@node2;Svr;node2.supernodexp.hpc;Scheduler sent command 0
05/02/2018 09:29:37;0100;Server@node2;Req;;Type 21 request received from Scheduler@node2.supernodexp.hpc, sock=19
05/02/2018 09:29:37;0100;Server@node2;Req;;Type 81 request received from Scheduler@node2.supernodexp.hpc, sock=19
05/02/2018 09:29:37;0100;Server@node2;Req;;Type 71 request received from Scheduler@node2.supernodexp.hpc, sock=19
05/02/2018 09:29:37;0100;Server@node2;Req;;Type 58 request received from Scheduler@node2.supernodexp.hpc, sock=19
05/02/2018 09:29:37;0100;Server@node2;Req;;Type 20 request received from Scheduler@node2.supernodexp.hpc, sock=19
05/02/2018 09:29:37;0100;Server@node2;Req;;Type 51 request received from Scheduler@node2.supernodexp.hpc, sock=19
05/02/2018 09:29:58;0080;Server@node2;Job;13265.node2.supernodexp.hpc;Obit received momhop:1 serverhop:1 state:4 substate:42
05/02/2018 09:29:59;0010;Server@node2;Job;13265.node2.supernodexp.hpc;Exit_status=0 resources_used.cpupercent=0 resources_used.cput=00:00:00 resources_used.mem=9068kb resources_used.ncpus=2 resources_used.vmem=172288kb resources_used.walltime=00:01:50
05/02/2018 09:29:59;0100;Server@node2;Job;13265.node2.supernodexp.hpc;dequeuing from workq, state 5
05/02/2018 09:29:59;0040;Server@node2;Svr;node2.supernodexp.hpc;Scheduler sent command 2
05/02/2018 09:29:59;0040;Server@node2;Svr;node2.supernodexp.hpc;Scheduler sent command 0
05/02/2018 09:29:59;0100;Server@node2;Req;;Type 21 request received from Scheduler@node2.supernodexp.hpc, sock=19
05/02/2018 09:29:59;0100;Server@node2;Req;;Type 81 request received from Scheduler@node2.supernodexp.hpc, sock=19
05/02/2018 09:29:59;0100;Server@node2;Req;;Type 71 request received from Scheduler@node2.supernodexp.hpc, sock=19
05/02/2018 09:29:59;0100;Server@node2;Req;;Type 58 request received from Scheduler@node2.supernodexp.hpc, sock=19
05/02/2018 09:29:59;0100;Server@node2;Req;;Type 20 request received from Scheduler@node2.supernodexp.hpc, sock=19
05/02/2018 09:29:59;0100;Server@node2;Req;;Type 51 request received from Scheduler@node2.supernodexp.hpc, sock=19
05/02/2018 09:30:08;0080;Server@node2;Job;13272.node2.supernodexp.hpc;Obit received momhop:1 serverhop:1 state:4 substate:42
05/02/2018 09:30:09;0010;Server@node2;Job;13272.node2.supernodexp.hpc;Exit_status=0 resources_used.cpupercent=0 resources_used.cput=00:00:00 resources_used.mem=9088kb resources_used.ncpus=4 resources_used.vmem=172196kb resources_used.walltime=00:00:39
05/02/2018 09:30:09;0100;Server@node2;Job;13272.node2.supernodexp.hpc;dequeuing from workq, state 5
05/02/2018 09:30:09;0040;Server@node2;Svr;node2.supernodexp.hpc;Scheduler sent command 2
05/02/2018 09:30:09;0040;Server@node2;Svr;node2.supernodexp.hpc;Scheduler sent command 0
05/02/2018 09:30:09;0100;Server@node2;Req;;Type 21 request received from Scheduler@node2.supernodexp.hpc, sock=19
05/02/2018 09:30:09;0100;Server@node2;Req;;Type 81 request received from Scheduler@node2.supernodexp.hpc, sock=19
05/02/2018 09:30:09;0100;Server@node2;Req;;Type 71 request received from Scheduler@node2.supernodexp.hpc, sock=19
05/02/2018 09:30:09;0100;Server@node2;Req;;Type 58 request received from Scheduler@node2.supernodexp.hpc, sock=19
05/02/2018 09:30:09;0100;Server@node2;Req;;Type 20 request received from Scheduler@node2.supernodexp.hpc, sock=19
05/02/2018 09:30:09;0100;Server@node2;Req;;Type 51 request received from Scheduler@node2.supernodexp.hpc, sock=19
05/02/2018 09:33:28;0100;Server@node2;Req;;Type 0 request received from baovo@node2.supernodexp.hpc, sock=16
05/02/2018 09:33:28;0100;Server@node2;Req;;Type 49 request received from baovo@node2.supernodexp.hpc, sock=19
05/02/2018 09:33:28;0100;Server@node2;Req;;Type 21 request received from baovo@node2.supernodexp.hpc, sock=16
05/02/2018 09:33:28;0100;Server@node2;Req;;Type 19 request received from baovo@node2.supernodexp.hpc, sock=16
05/02/2018 09:33:30;0100;Server@node2;Req;;Type 0 request received from baovo@node2.supernodexp.hpc, sock=16
05/02/2018 09:33:30;0100;Server@node2;Req;;Type 49 request received from baovo@node2.supernodexp.hpc, sock=19
05/02/2018 09:33:30;0100;Server@node2;Req;;Type 21 request received from baovo@node2.supernodexp.hpc, sock=16
05/02/2018 09:33:30;0100;Server@node2;Req;;Type 19 request received from baovo@node2.supernodexp.hpc, sock=16
05/02/2018 09:34:28;0080;Server@node2;Job;13263.node2.supernodexp.hpc;Obit received momhop:1 serverhop:1 state:4 substate:42
05/02/2018 09:34:28;0100;Server@node2;Req;;Type 0 request received from baovo@node2.supernodexp.hpc, sock=16
05/02/2018 09:34:28;0100;Server@node2;Req;;Type 49 request received from baovo@node2.supernodexp.hpc, sock=19
05/02/2018 09:34:28;0100;Server@node2;Req;;Type 21 request received from baovo@node2.supernodexp.hpc, sock=16
05/02/2018 09:34:28;0100;Server@node2;Req;;Type 1 request received from baovo@node2.supernodexp.hpc, sock=16
05/02/2018 09:34:28;0100;Server@node2;Req;;Type 3 request received from baovo@node2.supernodexp.hpc, sock=16
05/02/2018 09:34:28;0100;Server@node2;Req;;Type 5 request received from baovo@node2.supernodexp.hpc, sock=16
05/02/2018 09:34:28;0100;Server@node2;Job;13273.node2.supernodexp.hpc;enqueuing into workq, state 1 hop 1
05/02/2018 09:34:28;0008;Server@node2;Job;13273.node2.supernodexp.hpc;Job Queued at request of baovo@node2.supernodexp.hpc, owner = baovo@node2.supernodexp.hpc, job name = shared-vir-mem, queue = workq
05/02/2018 09:34:28;0040;Server@node2;Svr;node2.supernodexp.hpc;Scheduler sent command 1
05/02/2018 09:34:28;0040;Server@node2;Svr;node2.supernodexp.hpc;Scheduler sent command 0
05/02/2018 09:34:28;0100;Server@node2;Req;;Type 21 request received from Scheduler@node2.supernodexp.hpc, sock=19
05/02/2018 09:34:28;0100;Server@node2;Req;;Type 81 request received from Scheduler@node2.supernodexp.hpc, sock=19
05/02/2018 09:34:28;0100;Server@node2;Req;;Type 71 request received from Scheduler@node2.supernodexp.hpc, sock=19
05/02/2018 09:34:28;0100;Server@node2;Req;;Type 58 request received from Scheduler@node2.supernodexp.hpc, sock=19
05/02/2018 09:34:28;0100;Server@node2;Req;;Type 20 request received from Scheduler@node2.supernodexp.hpc, sock=19
05/02/2018 09:34:28;0100;Server@node2;Req;;Type 51 request received from Scheduler@node2.supernodexp.hpc, sock=19
05/02/2018 09:34:28;0010;Server@node2;Job;13263.node2.supernodexp.hpc;Exit_status=0 resources_used.cpupercent=0 resources_used.cput=00:00:00 resources_used.mem=9468kb resources_used.ncpus=12 resources_used.vmem=172288kb resources_used.walltime=00:06:33
05/02/2018 09:34:28;0100;Server@node2;Job;13263.node2.supernodexp.hpc;dequeuing from workq, state 5
05/02/2018 09:34:28;0100;Server@node2;Req;;Type 23 request received from Scheduler@node2.supernodexp.hpc, sock=19
05/02/2018 09:34:28;0008;Server@node2;Job;13273.node2.supernodexp.hpc;Job Run at request of Scheduler@node2.supernodexp.hpc on exec_vnode (node3:nmics=2:ncpus=2:mem=2097152kb)
05/02/2018 09:34:29;0001;Server@node2;Svr;Server@node2;Success (0) in req_runjob2, return value of svr_startjob is 0
05/02/2018 09:34:29;0040;Server@node2;Svr;node2.supernodexp.hpc;Scheduler sent command 2
05/02/2018 09:34:29;0040;Server@node2;Svr;node2.supernodexp.hpc;Scheduler sent command 0
05/02/2018 09:34:29;0100;Server@node2;Req;;Type 21 request received from Scheduler@node2.supernodexp.hpc, sock=19
05/02/2018 09:34:29;0100;Server@node2;Req;;Type 81 request received from Scheduler@node2.supernodexp.hpc, sock=19
05/02/2018 09:34:29;0100;Server@node2;Req;;Type 71 request received from Scheduler@node2.supernodexp.hpc, sock=19
05/02/2018 09:34:29;0100;Server@node2;Req;;Type 58 request received from Scheduler@node2.supernodexp.hpc, sock=19
05/02/2018 09:34:29;0100;Server@node2;Req;;Type 20 request received from Scheduler@node2.supernodexp.hpc, sock=19
05/02/2018 09:34:29;0100;Server@node2;Req;;Type 51 request received from Scheduler@node2.supernodexp.hpc, sock=19
05/02/2018 09:34:35;0080;Server@node2;Job;13273.node2.supernodexp.hpc;Obit received momhop:1 serverhop:1 state:4 substate:42
05/02/2018 09:34:35;0100;Server@node2;Req;;Type 1 request received from baovo@node2.supernodexp.hpc, sock=16
05/02/2018 09:34:35;0100;Server@node2;Req;;Type 3 request received from baovo@node2.supernodexp.hpc, sock=16
05/02/2018 09:34:35;0100;Server@node2;Req;;Type 5 request received from baovo@node2.supernodexp.hpc, sock=16
05/02/2018 09:34:35;0100;Server@node2;Job;13274.node2.supernodexp.hpc;enqueuing into workq, state 1 hop 1
05/02/2018 09:34:35;0008;Server@node2;Job;13274.node2.supernodexp.hpc;Job Queued at request of baovo@node2.supernodexp.hpc, owner = baovo@node2.supernodexp.hpc, job name = lu-decomp-100000-mem10, queue = workq
05/02/2018 09:34:35;0040;Server@node2;Svr;node2.supernodexp.hpc;Scheduler sent command 1
05/02/2018 09:34:35;0040;Server@node2;Svr;node2.supernodexp.hpc;Scheduler sent command 0
05/02/2018 09:34:35;0100;Server@node2;Req;;Type 21 request received from Scheduler@node2.supernodexp.hpc, sock=19
05/02/2018 09:34:35;0100;Server@node2;Req;;Type 81 request received from Scheduler@node2.supernodexp.hpc, sock=19
05/02/2018 09:34:35;0100;Server@node2;Req;;Type 71 request received from Scheduler@node2.supernodexp.hpc, sock=19
05/02/2018 09:34:35;0100;Server@node2;Req;;Type 58 request received from Scheduler@node2.supernodexp.hpc, sock=19
05/02/2018 09:34:35;0100;Server@node2;Req;;Type 20 request received from Scheduler@node2.supernodexp.hpc, sock=19
05/02/2018 09:34:35;0100;Server@node2;Req;;Type 51 request received from Scheduler@node2.supernodexp.hpc, sock=19
05/02/2018 09:34:36;0100;Server@node2;Req;;Type 23 request received from Scheduler@node2.supernodexp.hpc, sock=19
05/02/2018 09:34:36;0008;Server@node2;Job;13274.node2.supernodexp.hpc;Job Run at request of Scheduler@node2.supernodexp.hpc on exec_vnode (node3:ncpus=8:mem=10485760kb)
05/02/2018 09:34:36;0001;Server@node2;Svr;Server@node2;Success (0) in req_runjob2, return value of svr_startjob is 0
05/02/2018 09:34:36;0010;Server@node2;Job;13273.node2.supernodexp.hpc;Exit_status=0 resources_used.cpupercent=0 resources_used.cput=00:00:00 resources_used.mem=0kb resources_used.ncpus=2 resources_used.vmem=0kb resources_used.walltime=00:00:07
05/02/2018 09:34:36;0100;Server@node2;Job;13273.node2.supernodexp.hpc;dequeuing from workq, state 5
05/02/2018 09:34:36;0040;Server@node2;Svr;node2.supernodexp.hpc;Scheduler sent command 2
05/02/2018 09:34:36;0040;Server@node2;Svr;node2.supernodexp.hpc;Scheduler sent command 0
05/02/2018 09:34:36;0100;Server@node2;Req;;Type 21 request received from Scheduler@node2.supernodexp.hpc, sock=19
05/02/2018 09:34:36;0100;Server@node2;Req;;Type 81 request received from Scheduler@node2.supernodexp.hpc, sock=19
05/02/2018 09:34:36;0100;Server@node2;Req;;Type 71 request received from Scheduler@node2.supernodexp.hpc, sock=19
05/02/2018 09:34:36;0100;Server@node2;Req;;Type 58 request received from Scheduler@node2.supernodexp.hpc, sock=19
05/02/2018 09:34:36;0100;Server@node2;Req;;Type 20 request received from Scheduler@node2.supernodexp.hpc, sock=19
05/02/2018 09:34:36;0100;Server@node2;Req;;Type 51 request received from Scheduler@node2.supernodexp.hpc, sock=19
05/02/2018 09:34:52;0100;Server@node2;Req;;Type 1 request received from baovo@node2.supernodexp.hpc, sock=16
05/02/2018 09:34:52;0100;Server@node2;Req;;Type 3 request received from baovo@node2.supernodexp.hpc, sock=16
05/02/2018 09:34:52;0100;Server@node2;Req;;Type 5 request received from baovo@node2.supernodexp.hpc, sock=16
05/02/2018 09:34:52;0100;Server@node2;Job;13275.node2.supernodexp.hpc;enqueuing into workq, state 1 hop 1
05/02/2018 09:34:52;0008;Server@node2;Job;13275.node2.supernodexp.hpc;Job Queued at request of baovo@node2.supernodexp.hpc, owner = baovo@node2.supernodexp.hpc, job name = md, queue = workq
05/02/2018 09:34:52;0040;Server@node2;Svr;node2.supernodexp.hpc;Scheduler sent command 1
05/02/2018 09:34:52;0040;Server@node2;Svr;node2.supernodexp.hpc;Scheduler sent command 0
05/02/2018 09:34:52;0100;Server@node2;Req;;Type 21 request received from Scheduler@node2.supernodexp.hpc, sock=19
05/02/2018 09:34:52;0100;Server@node2;Req;;Type 81 request received from Scheduler@node2.supernodexp.hpc, sock=19
05/02/2018 09:34:52;0100;Server@node2;Req;;Type 71 request received from Scheduler@node2.supernodexp.hpc, sock=19
05/02/2018 09:34:52;0100;Server@node2;Req;;Type 58 request received from Scheduler@node2.supernodexp.hpc, sock=19
05/02/2018 09:34:52;0100;Server@node2;Req;;Type 1 request received from baovo@node2.supernodexp.hpc, sock=16
05/02/2018 09:34:52;0100;Server@node2;Req;;Type 3 request received from baovo@node2.supernodexp.hpc, sock=16
05/02/2018 09:34:52;0100;Server@node2;Req;;Type 5 request received from baovo@node2.supernodexp.hpc, sock=16
05/02/2018 09:34:52;0100;Server@node2;Job;13276.node2.supernodexp.hpc;enqueuing into workq, state 1 hop 1
05/02/2018 09:34:52;0008;Server@node2;Job;13276.node2.supernodexp.hpc;Job Queued at request of baovo@node2.supernodexp.hpc, owner = baovo@node2.supernodexp.hpc, job name = md, queue = workq
05/02/2018 09:34:52;0100;Server@node2;Req;;Type 20 request received from Scheduler@node2.supernodexp.hpc, sock=19
05/02/2018 09:34:52;0100;Server@node2;Req;;Type 51 request received from Scheduler@node2.supernodexp.hpc, sock=19
05/02/2018 09:34:53;0100;Server@node2;Req;;Type 23 request received from Scheduler@node2.supernodexp.hpc, sock=19
05/02/2018 09:34:53;0008;Server@node2;Job;13275.node2.supernodexp.hpc;Job Run at request of Scheduler@node2.supernodexp.hpc on exec_vnode (node3:ncpus=8:mem=3145728kb)
05/02/2018 09:34:53;0001;Server@node2;Svr;Server@node2;Success (0) in req_runjob2, return value of svr_startjob is 0
05/02/2018 09:34:53;0100;Server@node2;Req;;Type 23 request received from Scheduler@node2.supernodexp.hpc, sock=19
05/02/2018 09:34:53;0008;Server@node2;Job;13276.node2.supernodexp.hpc;Job Run at request of Scheduler@node2.supernodexp.hpc on exec_vnode (node3:ncpus=8:mem=3145728kb)
05/02/2018 09:34:53;0001;Server@node2;Svr;Server@node2;Success (0) in req_runjob2, return value of svr_startjob is 0
05/02/2018 09:34:53;0040;Server@node2;Svr;node2.supernodexp.hpc;Scheduler sent command 1
05/02/2018 09:34:53;0040;Server@node2;Svr;node2.supernodexp.hpc;Scheduler sent command 0
05/02/2018 09:34:53;0100;Server@node2;Req;;Type 21 request received from Scheduler@node2.supernodexp.hpc, sock=19
05/02/2018 09:34:53;0100;Server@node2;Req;;Type 81 request received from Scheduler@node2.supernodexp.hpc, sock=19
05/02/2018 09:34:53;0100;Server@node2;Req;;Type 71 request received from Scheduler@node2.supernodexp.hpc, sock=19
05/02/2018 09:34:53;0100;Server@node2;Req;;Type 58 request received from Scheduler@node2.supernodexp.hpc, sock=19
05/02/2018 09:34:53;0100;Server@node2;Req;;Type 20 request received from Scheduler@node2.supernodexp.hpc, sock=19
05/02/2018 09:34:53;0100;Server@node2;Req;;Type 51 request received from Scheduler@node2.supernodexp.hpc, sock=19
05/02/2018 09:34:55;0100;Server@node2;Req;;Type 1 request received from baovo@node2.supernodexp.hpc, sock=16
05/02/2018 09:34:55;0100;Server@node2;Req;;Type 3 request received from baovo@node2.supernodexp.hpc, sock=16
05/02/2018 09:34:55;0100;Server@node2;Req;;Type 5 request received from baovo@node2.supernodexp.hpc, sock=16
05/02/2018 09:34:55;0100;Server@node2;Job;13277.node2.supernodexp.hpc;enqueuing into workq, state 1 hop 1
05/02/2018 09:34:55;0008;Server@node2;Job;13277.node2.supernodexp.hpc;Job Queued at request of baovo@node2.supernodexp.hpc, owner = baovo@node2.supernodexp.hpc, job name = lu-decomp-100000-mem10, queue = workq
05/02/2018 09:34:55;0040;Server@node2;Svr;node2.supernodexp.hpc;Scheduler sent command 1
05/02/2018 09:34:55;0040;Server@node2;Svr;node2.supernodexp.hpc;Scheduler sent command 0
05/02/2018 09:34:55;0100;Server@node2;Req;;Type 21 request received from Scheduler@node2.supernodexp.hpc, sock=19
05/02/2018 09:34:55;0100;Server@node2;Req;;Type 81 request received from Scheduler@node2.supernodexp.hpc, sock=19
05/02/2018 09:34:55;0100;Server@node2;Req;;Type 71 request received from Scheduler@node2.supernodexp.hpc, sock=19
05/02/2018 09:34:55;0100;Server@node2;Req;;Type 58 request received from Scheduler@node2.supernodexp.hpc, sock=19
05/02/2018 09:34:55;0100;Server@node2;Req;;Type 1 request received from baovo@node2.supernodexp.hpc, sock=16
05/02/2018 09:34:55;0100;Server@node2;Req;;Type 3 request received from baovo@node2.supernodexp.hpc, sock=16
05/02/2018 09:34:55;0100;Server@node2;Req;;Type 5 request received from baovo@node2.supernodexp.hpc, sock=16
05/02/2018 09:34:55;0100;Server@node2;Job;13278.node2.supernodexp.hpc;enqueuing into workq, state 1 hop 1
05/02/2018 09:34:55;0008;Server@node2;Job;13278.node2.supernodexp.hpc;Job Queued at request of baovo@node2.supernodexp.hpc, owner = baovo@node2.supernodexp.hpc, job name = lu-decomp-100000-mem5, queue = workq
05/02/2018 09:34:56;0100;Server@node2;Req;;Type 20 request received from Scheduler@node2.supernodexp.hpc, sock=19
05/02/2018 09:34:56;0100;Server@node2;Req;;Type 51 request received from Scheduler@node2.supernodexp.hpc, sock=19
05/02/2018 09:34:56;0100;Server@node2;Req;;Type 23 request received from Scheduler@node2.supernodexp.hpc, sock=19
05/02/2018 09:34:56;0008;Server@node2;Job;13278.node2.supernodexp.hpc;Job Run at request of Scheduler@node2.supernodexp.hpc on exec_vnode (node14:ncpus=8:mem=5242880kb)
05/02/2018 09:34:56;0001;Server@node2;Svr;Server@node2;Success (0) in req_runjob2, return value of svr_startjob is 0
05/02/2018 09:34:56;0100;Server@node2;Req;;Type 23 request received from Scheduler@node2.supernodexp.hpc, sock=19
05/02/2018 09:34:56;0008;Server@node2;Job;13277.node2.supernodexp.hpc;Job Run at request of Scheduler@node2.supernodexp.hpc on exec_vnode (node14:ncpus=8:mem=10485760kb)
05/02/2018 09:34:56;0001;Server@node2;Svr;Server@node2;Success (0) in req_runjob2, return value of svr_startjob is 0
05/02/2018 09:34:56;0040;Server@node2;Svr;node2.supernodexp.hpc;Scheduler sent command 1
05/02/2018 09:34:56;0040;Server@node2;Svr;node2.supernodexp.hpc;Scheduler sent command 0
05/02/2018 09:34:56;0100;Server@node2;Req;;Type 21 request received from Scheduler@node2.supernodexp.hpc, sock=19
05/02/2018 09:34:56;0100;Server@node2;Req;;Type 81 request received from Scheduler@node2.supernodexp.hpc, sock=19
05/02/2018 09:34:56;0100;Server@node2;Req;;Type 71 request received from Scheduler@node2.supernodexp.hpc, sock=19
05/02/2018 09:34:56;0100;Server@node2;Req;;Type 58 request received from Scheduler@node2.supernodexp.hpc, sock=19
05/02/2018 09:34:56;0100;Server@node2;Req;;Type 20 request received from Scheduler@node2.supernodexp.hpc, sock=19
05/02/2018 09:34:56;0100;Server@node2;Req;;Type 51 request received from Scheduler@node2.supernodexp.hpc, sock=19
05/02/2018 09:34:59;0100;Server@node2;Req;;Type 1 request received from baovo@node2.supernodexp.hpc, sock=16
05/02/2018 09:34:59;0100;Server@node2;Req;;Type 3 request received from baovo@node2.supernodexp.hpc, sock=16
05/02/2018 09:34:59;0100;Server@node2;Req;;Type 5 request received from baovo@node2.supernodexp.hpc, sock=16
05/02/2018 09:34:59;0100;Server@node2;Job;13279.node2.supernodexp.hpc;enqueuing into workq, state 1 hop 1
05/02/2018 09:35:00;0008;Server@node2;Job;13279.node2.supernodexp.hpc;Job Queued at request of baovo@node2.supernodexp.hpc, owner = baovo@node2.supernodexp.hpc, job name = lu-decomp-100000-mem10, queue = workq
05/02/2018 09:35:00;0040;Server@node2;Svr;node2.supernodexp.hpc;Scheduler sent command 1
05/02/2018 09:35:00;0040;Server@node2;Svr;node2.supernodexp.hpc;Scheduler sent command 0
05/02/2018 09:35:00;0100;Server@node2;Req;;Type 21 request received from Scheduler@node2.supernodexp.hpc, sock=19
05/02/2018 09:35:00;0100;Server@node2;Req;;Type 81 request received from Scheduler@node2.supernodexp.hpc, sock=19
05/02/2018 09:35:00;0100;Server@node2;Req;;Type 71 request received from Scheduler@node2.supernodexp.hpc, sock=19
05/02/2018 09:35:00;0100;Server@node2;Req;;Type 58 request received from Scheduler@node2.supernodexp.hpc, sock=19
05/02/2018 09:35:00;0100;Server@node2;Req;;Type 20 request received from Scheduler@node2.supernodexp.hpc, sock=19
05/02/2018 09:35:00;0100;Server@node2;Req;;Type 51 request received from Scheduler@node2.supernodexp.hpc, sock=19
05/02/2018 09:35:00;0100;Server@node2;Req;;Type 23 request received from Scheduler@node2.supernodexp.hpc, sock=19
05/02/2018 09:35:00;0008;Server@node2;Job;13279.node2.supernodexp.hpc;Job Run at request of Scheduler@node2.supernodexp.hpc on exec_vnode (node14:ncpus=8:mem=10485760kb)
05/02/2018 09:35:00;0001;Server@node2;Svr;Server@node2;Success (0) in req_runjob2, return value of svr_startjob is 0
05/02/2018 09:35:07;0100;Server@node2;Req;;Type 1 request received from baovo@node2.supernodexp.hpc, sock=16
05/02/2018 09:35:07;0100;Server@node2;Req;;Type 3 request received from baovo@node2.supernodexp.hpc, sock=16
05/02/2018 09:35:07;0100;Server@node2;Req;;Type 5 request received from baovo@node2.supernodexp.hpc, sock=16
05/02/2018 09:35:07;0100;Server@node2;Job;13280.node2.supernodexp.hpc;enqueuing into workq, state 1 hop 1
05/02/2018 09:35:07;0008;Server@node2;Job;13280.node2.supernodexp.hpc;Job Queued at request of baovo@node2.supernodexp.hpc, owner = baovo@node2.supernodexp.hpc, job name = mkl-20000, queue = workq
05/02/2018 09:35:07;0040;Server@node2;Svr;node2.supernodexp.hpc;Scheduler sent command 1
05/02/2018 09:35:07;0040;Server@node2;Svr;node2.supernodexp.hpc;Scheduler sent command 0
05/02/2018 09:35:07;0100;Server@node2;Req;;Type 21 request received from Scheduler@node2.supernodexp.hpc, sock=19
05/02/2018 09:35:07;0100;Server@node2;Req;;Type 81 request received from Scheduler@node2.supernodexp.hpc, sock=19
05/02/2018 09:35:07;0100;Server@node2;Req;;Type 71 request received from Scheduler@node2.supernodexp.hpc, sock=19
05/02/2018 09:35:07;0100;Server@node2;Req;;Type 58 request received from Scheduler@node2.supernodexp.hpc, sock=19
05/02/2018 09:35:07;0100;Server@node2;Req;;Type 20 request received from Scheduler@node2.supernodexp.hpc, sock=19
05/02/2018 09:35:07;0100;Server@node2;Req;;Type 51 request received from Scheduler@node2.supernodexp.hpc, sock=19
05/02/2018 09:35:07;0100;Server@node2;Req;;Type 23 request received from Scheduler@node2.supernodexp.hpc, sock=19
05/02/2018 09:35:07;0008;Server@node2;Job;13280.node2.supernodexp.hpc;Job Run at request of Scheduler@node2.supernodexp.hpc on exec_vnode (node14:ncpus=8:mem=15728640kb)
05/02/2018 09:35:07;0001;Server@node2;Svr;Server@node2;Success (0) in req_runjob2, return value of svr_startjob is 0
05/02/2018 09:35:10;0100;Server@node2;Req;;Type 1 request received from baovo@node2.supernodexp.hpc, sock=16
05/02/2018 09:35:10;0100;Server@node2;Req;;Type 3 request received from baovo@node2.supernodexp.hpc, sock=16
05/02/2018 09:35:10;0100;Server@node2;Req;;Type 5 request received from baovo@node2.supernodexp.hpc, sock=16
05/02/2018 09:35:10;0100;Server@node2;Job;13281.node2.supernodexp.hpc;enqueuing into workq, state 1 hop 1
05/02/2018 09:35:10;0008;Server@node2;Job;13281.node2.supernodexp.hpc;Job Queued at request of baovo@node2.supernodexp.hpc, owner = baovo@node2.supernodexp.hpc, job name = parallelism-sweep-cpu8, queue = workq
05/02/2018 09:35:10;0040;Server@node2;Svr;node2.supernodexp.hpc;Scheduler sent command 1
05/02/2018 09:35:10;0040;Server@node2;Svr;node2.supernodexp.hpc;Scheduler sent command 0
05/02/2018 09:35:10;0100;Server@node2;Req;;Type 21 request received from Scheduler@node2.supernodexp.hpc, sock=19
05/02/2018 09:35:10;0100;Server@node2;Req;;Type 81 request received from Scheduler@node2.supernodexp.hpc, sock=19
05/02/2018 09:35:10;0100;Server@node2;Req;;Type 71 request received from Scheduler@node2.supernodexp.hpc, sock=19
05/02/2018 09:35:10;0100;Server@node2;Req;;Type 58 request received from Scheduler@node2.supernodexp.hpc, sock=19
05/02/2018 09:35:10;0100;Server@node2;Req;;Type 20 request received from Scheduler@node2.supernodexp.hpc, sock=19
05/02/2018 09:35:10;0100;Server@node2;Req;;Type 51 request received from Scheduler@node2.supernodexp.hpc, sock=19
05/02/2018 09:35:10;0100;Server@node2;Req;;Type 23 request received from Scheduler@node2.supernodexp.hpc, sock=19
05/02/2018 09:35:10;0008;Server@node2;Job;13281.node2.supernodexp.hpc;Job Run at request of Scheduler@node2.supernodexp.hpc on exec_vnode (node14:ncpus=8:mem=20971520kb)
05/02/2018 09:35:10;0001;Server@node2;Svr;Server@node2;Success (0) in req_runjob2, return value of svr_startjob is 0
05/02/2018 09:35:10;0080;Server@node2;Job;13278.node2.supernodexp.hpc;Obit received momhop:1 serverhop:1 state:4 substate:42
05/02/2018 09:35:11;0100;Server@node2;Req;;Type 1 request received from baovo@node2.supernodexp.hpc, sock=16
05/02/2018 09:35:11;0100;Server@node2;Req;;Type 3 request received from baovo@node2.supernodexp.hpc, sock=16
05/02/2018 09:35:11;0100;Server@node2;Req;;Type 5 request received from baovo@node2.supernodexp.hpc, sock=16
05/02/2018 09:35:11;0100;Server@node2;Job;13282.node2.supernodexp.hpc;enqueuing into workq, state 1 hop 1
05/02/2018 09:35:11;0008;Server@node2;Job;13282.node2.supernodexp.hpc;Job Queued at request of baovo@node2.supernodexp.hpc, owner = baovo@node2.supernodexp.hpc, job name = mkl-25000, queue = workq
05/02/2018 09:35:11;0040;Server@node2;Svr;node2.supernodexp.hpc;Scheduler sent command 1
05/02/2018 09:35:11;0040;Server@node2;Svr;node2.supernodexp.hpc;Scheduler sent command 0
05/02/2018 09:35:11;0100;Server@node2;Req;;Type 21 request received from Scheduler@node2.supernodexp.hpc, sock=19
05/02/2018 09:35:11;0100;Server@node2;Req;;Type 81 request received from Scheduler@node2.supernodexp.hpc, sock=19
05/02/2018 09:35:11;0100;Server@node2;Req;;Type 71 request received from Scheduler@node2.supernodexp.hpc, sock=19
05/02/2018 09:35:11;0100;Server@node2;Req;;Type 58 request received from Scheduler@node2.supernodexp.hpc, sock=19
05/02/2018 09:35:11;0100;Server@node2;Req;;Type 20 request received from Scheduler@node2.supernodexp.hpc, sock=19
05/02/2018 09:35:11;0100;Server@node2;Req;;Type 51 request received from Scheduler@node2.supernodexp.hpc, sock=19
05/02/2018 09:35:11;0100;Server@node2;Req;;Type 23 request received from Scheduler@node2.supernodexp.hpc, sock=19
05/02/2018 09:35:11;0008;Server@node2;Job;13282.node2.supernodexp.hpc;Job Run at request of Scheduler@node2.supernodexp.hpc on exec_vnode (node13:ncpus=12:mem=20971520kb)
05/02/2018 09:35:11;0001;Server@node2;Svr;Server@node2;Success (0) in req_runjob2, return value of svr_startjob is 0
05/02/2018 09:35:12;0100;Server@node2;Req;;Type 1 request received from baovo@node2.supernodexp.hpc, sock=16
05/02/2018 09:35:12;0100;Server@node2;Req;;Type 3 request received from baovo@node2.supernodexp.hpc, sock=16
05/02/2018 09:35:12;0100;Server@node2;Req;;Type 5 request received from baovo@node2.supernodexp.hpc, sock=16
05/02/2018 09:35:12;0100;Server@node2;Job;13283.node2.supernodexp.hpc;enqueuing into workq, state 1 hop 1
05/02/2018 09:35:12;0008;Server@node2;Job;13283.node2.supernodexp.hpc;Job Queued at request of baovo@node2.supernodexp.hpc, owner = baovo@node2.supernodexp.hpc, job name = shared-vir-mem, queue = workq
05/02/2018 09:35:12;0040;Server@node2;Svr;node2.supernodexp.hpc;Scheduler sent command 1
05/02/2018 09:35:12;0040;Server@node2;Svr;node2.supernodexp.hpc;Scheduler sent command 0
05/02/2018 09:35:12;0100;Server@node2;Req;;Type 21 request received from Scheduler@node2.supernodexp.hpc, sock=19
05/02/2018 09:35:12;0100;Server@node2;Req;;Type 81 request received from Scheduler@node2.supernodexp.hpc, sock=19
05/02/2018 09:35:12;0100;Server@node2;Req;;Type 71 request received from Scheduler@node2.supernodexp.hpc, sock=19
05/02/2018 09:35:12;0100;Server@node2;Req;;Type 58 request received from Scheduler@node2.supernodexp.hpc, sock=19
05/02/2018 09:35:12;0100;Server@node2;Req;;Type 20 request received from Scheduler@node2.supernodexp.hpc, sock=19
05/02/2018 09:35:12;0100;Server@node2;Req;;Type 51 request received from Scheduler@node2.supernodexp.hpc, sock=19
05/02/2018 09:35:12;0100;Server@node2;Req;;Type 23 request received from Scheduler@node2.supernodexp.hpc, sock=19
05/02/2018 09:35:12;0008;Server@node2;Job;13283.node2.supernodexp.hpc;Job Run at request of Scheduler@node2.supernodexp.hpc on exec_vnode (node3:nmics=2:ncpus=2:mem=2097152kb)
05/02/2018 09:35:12;0001;Server@node2;Svr;Server@node2;Success (0) in req_runjob2, return value of svr_startjob is 0
05/02/2018 09:35:13;0010;Server@node2;Job;13278.node2.supernodexp.hpc;Exit_status=0 resources_used.cpupercent=0 resources_used.cput=00:00:00 resources_used.mem=0kb resources_used.ncpus=8 resources_used.vmem=0kb resources_used.walltime=00:00:16
05/02/2018 09:35:13;0100;Server@node2;Job;13278.node2.supernodexp.hpc;dequeuing from workq, state 5
05/02/2018 09:35:13;0040;Server@node2;Svr;node2.supernodexp.hpc;Scheduler sent command 2
05/02/2018 09:35:13;0040;Server@node2;Svr;node2.supernodexp.hpc;Scheduler sent command 0
05/02/2018 09:35:13;0100;Server@node2;Req;;Type 21 request received from Scheduler@node2.supernodexp.hpc, sock=19
05/02/2018 09:35:13;0100;Server@node2;Req;;Type 81 request received from Scheduler@node2.supernodexp.hpc, sock=19
05/02/2018 09:35:13;0100;Server@node2;Req;;Type 71 request received from Scheduler@node2.supernodexp.hpc, sock=19
05/02/2018 09:35:13;0100;Server@node2;Req;;Type 58 request received from Scheduler@node2.supernodexp.hpc, sock=19
05/02/2018 09:35:13;0100;Server@node2;Req;;Type 20 request received from Scheduler@node2.supernodexp.hpc, sock=19
05/02/2018 09:35:13;0100;Server@node2;Req;;Type 51 request received from Scheduler@node2.supernodexp.hpc, sock=19
05/02/2018 09:35:14;0080;Server@node2;Job;13281.node2.supernodexp.hpc;Obit received momhop:1 serverhop:1 state:4 substate:42
05/02/2018 09:35:15;0010;Server@node2;Job;13281.node2.supernodexp.hpc;Exit_status=0 resources_used.cpupercent=0 resources_used.cput=00:00:00 resources_used.mem=9380kb resources_used.ncpus=8 resources_used.vmem=172216kb resources_used.walltime=00:00:04
05/02/2018 09:35:15;0100;Server@node2;Job;13281.node2.supernodexp.hpc;dequeuing from workq, state 5
05/02/2018 09:35:15;0040;Server@node2;Svr;node2.supernodexp.hpc;Scheduler sent command 2
05/02/2018 09:35:15;0040;Server@node2;Svr;node2.supernodexp.hpc;Scheduler sent command 0
05/02/2018 09:35:15;0100;Server@node2;Req;;Type 21 request received from Scheduler@node2.supernodexp.hpc, sock=19
05/02/2018 09:35:15;0100;Server@node2;Req;;Type 81 request received from Scheduler@node2.supernodexp.hpc, sock=19
05/02/2018 09:35:15;0100;Server@node2;Req;;Type 71 request received from Scheduler@node2.supernodexp.hpc, sock=19
05/02/2018 09:35:15;0100;Server@node2;Req;;Type 58 request received from Scheduler@node2.supernodexp.hpc, sock=19
05/02/2018 09:35:15;0100;Server@node2;Req;;Type 20 request received from Scheduler@node2.supernodexp.hpc, sock=19
05/02/2018 09:35:15;0100;Server@node2;Req;;Type 51 request received from Scheduler@node2.supernodexp.hpc, sock=19
05/02/2018 09:35:17;0080;Server@node2;Job;13274.node2.supernodexp.hpc;Obit received momhop:1 serverhop:1 state:4 substate:42
05/02/2018 09:35:17;0010;Server@node2;Job;13274.node2.supernodexp.hpc;Exit_status=0 resources_used.cpupercent=0 resources_used.cput=00:00:00 resources_used.mem=9092kb resources_used.ncpus=8 resources_used.vmem=105088kb resources_used.walltime=00:00:42
05/02/2018 09:35:17;0100;Server@node2;Job;13274.node2.supernodexp.hpc;dequeuing from workq, state 5
05/02/2018 09:35:17;0040;Server@node2;Svr;node2.supernodexp.hpc;Scheduler sent command 2
05/02/2018 09:35:17;0040;Server@node2;Svr;node2.supernodexp.hpc;Scheduler sent command 0
05/02/2018 09:35:17;0100;Server@node2;Req;;Type 21 request received from Scheduler@node2.supernodexp.hpc, sock=19
05/02/2018 09:35:17;0100;Server@node2;Req;;Type 81 request received from Scheduler@node2.supernodexp.hpc, sock=19
05/02/2018 09:35:17;0100;Server@node2;Req;;Type 71 request received from Scheduler@node2.supernodexp.hpc, sock=19
05/02/2018 09:35:17;0100;Server@node2;Req;;Type 58 request received from Scheduler@node2.supernodexp.hpc, sock=19
05/02/2018 09:35:18;0100;Server@node2;Req;;Type 20 request received from Scheduler@node2.supernodexp.hpc, sock=19
05/02/2018 09:35:18;0100;Server@node2;Req;;Type 51 request received from Scheduler@node2.supernodexp.hpc, sock=19
05/02/2018 09:35:19;0080;Server@node2;Job;13283.node2.supernodexp.hpc;Obit received momhop:1 serverhop:1 state:4 substate:42
05/02/2018 09:35:20;0010;Server@node2;Job;13283.node2.supernodexp.hpc;Exit_status=0 resources_used.cpupercent=0 resources_used.cput=00:00:00 resources_used.mem=9096kb resources_used.ncpus=2 resources_used.vmem=105344kb resources_used.walltime=00:00:07
05/02/2018 09:35:20;0100;Server@node2;Job;13283.node2.supernodexp.hpc;dequeuing from workq, state 5
05/02/2018 09:35:20;0040;Server@node2;Svr;node2.supernodexp.hpc;Scheduler sent command 2
05/02/2018 09:35:20;0040;Server@node2;Svr;node2.supernodexp.hpc;Scheduler sent command 0
05/02/2018 09:35:20;0100;Server@node2;Req;;Type 21 request received from Scheduler@node2.supernodexp.hpc, sock=19
05/02/2018 09:35:20;0100;Server@node2;Req;;Type 81 request received from Scheduler@node2.supernodexp.hpc, sock=19
05/02/2018 09:35:20;0100;Server@node2;Req;;Type 71 request received from Scheduler@node2.supernodexp.hpc, sock=19
05/02/2018 09:35:20;0100;Server@node2;Req;;Type 58 request received from Scheduler@node2.supernodexp.hpc, sock=19
05/02/2018 09:35:20;0100;Server@node2;Req;;Type 20 request received from Scheduler@node2.supernodexp.hpc, sock=19
05/02/2018 09:35:20;0100;Server@node2;Req;;Type 51 request received from Scheduler@node2.supernodexp.hpc, sock=19
05/02/2018 09:35:21;0100;Server@node2;Req;;Type 1 request received from baovo@node2.supernodexp.hpc, sock=16
05/02/2018 09:35:21;0100;Server@node2;Req;;Type 3 request received from baovo@node2.supernodexp.hpc, sock=16
05/02/2018 09:35:21;0100;Server@node2;Req;;Type 5 request received from baovo@node2.supernodexp.hpc, sock=16
05/02/2018 09:35:21;0100;Server@node2;Job;13284.node2.supernodexp.hpc;enqueuing into workq, state 1 hop 1
05/02/2018 09:35:21;0008;Server@node2;Job;13284.node2.supernodexp.hpc;Job Queued at request of baovo@node2.supernodexp.hpc, owner = baovo@node2.supernodexp.hpc, job name = sgefa, queue = workq
05/02/2018 09:35:21;0040;Server@node2;Svr;node2.supernodexp.hpc;Scheduler sent command 1
05/02/2018 09:35:21;0040;Server@node2;Svr;node2.supernodexp.hpc;Scheduler sent command 0
05/02/2018 09:35:21;0100;Server@node2;Req;;Type 21 request received from Scheduler@node2.supernodexp.hpc, sock=19
05/02/2018 09:35:21;0100;Server@node2;Req;;Type 81 request received from Scheduler@node2.supernodexp.hpc, sock=19
05/02/2018 09:35:21;0100;Server@node2;Req;;Type 71 request received from Scheduler@node2.supernodexp.hpc, sock=19
05/02/2018 09:35:21;0100;Server@node2;Req;;Type 58 request received from Scheduler@node2.supernodexp.hpc, sock=19
05/02/2018 09:35:21;0100;Server@node2;Req;;Type 20 request received from Scheduler@node2.supernodexp.hpc, sock=19
05/02/2018 09:35:21;0100;Server@node2;Req;;Type 51 request received from Scheduler@node2.supernodexp.hpc, sock=19
05/02/2018 09:35:21;0100;Server@node2;Req;;Type 23 request received from Scheduler@node2.supernodexp.hpc, sock=19
05/02/2018 09:35:21;0008;Server@node2;Job;13284.node2.supernodexp.hpc;Job Run at request of Scheduler@node2.supernodexp.hpc on exec_vnode (node14:ncpus=24:mem=5242880kb)
05/02/2018 09:35:21;0001;Server@node2;Svr;Server@node2;Success (0) in req_runjob2, return value of svr_startjob is 0
05/02/2018 09:35:21;0080;Server@node2;Job;13277.node2.supernodexp.hpc;Obit received momhop:1 serverhop:1 state:4 substate:42
05/02/2018 09:35:22;0010;Server@node2;Job;13277.node2.supernodexp.hpc;Exit_status=0 resources_used.cpupercent=0 resources_used.cput=00:00:00 resources_used.mem=9412kb resources_used.ncpus=8 resources_used.vmem=104628kb resources_used.walltime=00:00:25
05/02/2018 09:35:22;0100;Server@node2;Job;13277.node2.supernodexp.hpc;dequeuing from workq, state 5
05/02/2018 09:35:22;0040;Server@node2;Svr;node2.supernodexp.hpc;Scheduler sent command 2
05/02/2018 09:35:22;0040;Server@node2;Svr;node2.supernodexp.hpc;Scheduler sent command 0
05/02/2018 09:35:22;0100;Server@node2;Req;;Type 21 request received from Scheduler@node2.supernodexp.hpc, sock=19
05/02/2018 09:35:22;0100;Server@node2;Req;;Type 81 request received from Scheduler@node2.supernodexp.hpc, sock=19
05/02/2018 09:35:22;0100;Server@node2;Req;;Type 71 request received from Scheduler@node2.supernodexp.hpc, sock=19
05/02/2018 09:35:22;0100;Server@node2;Req;;Type 58 request received from Scheduler@node2.supernodexp.hpc, sock=19
05/02/2018 09:35:22;0100;Server@node2;Req;;Type 20 request received from Scheduler@node2.supernodexp.hpc, sock=19
05/02/2018 09:35:22;0100;Server@node2;Req;;Type 51 request received from Scheduler@node2.supernodexp.hpc, sock=19
05/02/2018 09:35:25;0100;Server@node2;Req;;Type 1 request received from baovo@node2.supernodexp.hpc, sock=16
05/02/2018 09:35:25;0100;Server@node2;Req;;Type 3 request received from baovo@node2.supernodexp.hpc, sock=16
05/02/2018 09:35:25;0100;Server@node2;Req;;Type 5 request received from baovo@node2.supernodexp.hpc, sock=16
05/02/2018 09:35:25;0100;Server@node2;Job;13285.node2.supernodexp.hpc;enqueuing into workq, state 1 hop 1
05/02/2018 09:35:25;0008;Server@node2;Job;13285.node2.supernodexp.hpc;Job Queued at request of baovo@node2.supernodexp.hpc, owner = baovo@node2.supernodexp.hpc, job name = lu-decomp-100000-mem20, queue = workq
05/02/2018 09:35:25;0040;Server@node2;Svr;node2.supernodexp.hpc;Scheduler sent command 1
05/02/2018 09:35:25;0040;Server@node2;Svr;node2.supernodexp.hpc;Scheduler sent command 0
05/02/2018 09:35:25;0100;Server@node2;Req;;Type 21 request received from Scheduler@node2.supernodexp.hpc, sock=19
05/02/2018 09:35:25;0100;Server@node2;Req;;Type 81 request received from Scheduler@node2.supernodexp.hpc, sock=19
05/02/2018 09:35:25;0100;Server@node2;Req;;Type 71 request received from Scheduler@node2.supernodexp.hpc, sock=19
05/02/2018 09:35:25;0100;Server@node2;Req;;Type 58 request received from Scheduler@node2.supernodexp.hpc, sock=19
05/02/2018 09:35:25;0100;Server@node2;Req;;Type 20 request received from Scheduler@node2.supernodexp.hpc, sock=19
05/02/2018 09:35:25;0100;Server@node2;Req;;Type 51 request received from Scheduler@node2.supernodexp.hpc, sock=19
05/02/2018 09:35:25;0100;Server@node2;Req;;Type 23 request received from Scheduler@node2.supernodexp.hpc, sock=19
05/02/2018 09:35:25;0008;Server@node2;Job;13285.node2.supernodexp.hpc;Job Run at request of Scheduler@node2.supernodexp.hpc on exec_vnode (node3:ncpus=8:mem=20971520kb)
05/02/2018 09:35:25;0001;Server@node2;Svr;Server@node2;Success (0) in req_runjob2, return value of svr_startjob is 0
05/02/2018 09:35:25;0080;Server@node2;Job;13279.node2.supernodexp.hpc;Obit received momhop:1 serverhop:1 state:4 substate:42
05/02/2018 09:35:26;0010;Server@node2;Job;13279.node2.supernodexp.hpc;Exit_status=0 resources_used.cpupercent=0 resources_used.cput=00:00:00 resources_used.mem=9628kb resources_used.ncpus=8 resources_used.vmem=237752kb resources_used.walltime=00:00:26
05/02/2018 09:35:26;0100;Server@node2;Job;13279.node2.supernodexp.hpc;dequeuing from workq, state 5
05/02/2018 09:35:26;0040;Server@node2;Svr;node2.supernodexp.hpc;Scheduler sent command 2
05/02/2018 09:35:26;0040;Server@node2;Svr;node2.supernodexp.hpc;Scheduler sent command 0
05/02/2018 09:35:26;0100;Server@node2;Req;;Type 21 request received from Scheduler@node2.supernodexp.hpc, sock=19
05/02/2018 09:35:26;0100;Server@node2;Req;;Type 81 request received from Scheduler@node2.supernodexp.hpc, sock=19
05/02/2018 09:35:26;0100;Server@node2;Req;;Type 71 request received from Scheduler@node2.supernodexp.hpc, sock=19
05/02/2018 09:35:26;0100;Server@node2;Req;;Type 58 request received from Scheduler@node2.supernodexp.hpc, sock=19
05/02/2018 09:35:26;0100;Server@node2;Req;;Type 20 request received from Scheduler@node2.supernodexp.hpc, sock=19
05/02/2018 09:35:26;0100;Server@node2;Req;;Type 51 request received from Scheduler@node2.supernodexp.hpc, sock=19
05/02/2018 09:35:27;0100;Server@node2;Req;;Type 1 request received from baovo@node2.supernodexp.hpc, sock=16
05/02/2018 09:35:27;0100;Server@node2;Req;;Type 3 request received from baovo@node2.supernodexp.hpc, sock=16
05/02/2018 09:35:27;0100;Server@node2;Req;;Type 5 request received from baovo@node2.supernodexp.hpc, sock=16
05/02/2018 09:35:27;0100;Server@node2;Job;13286.node2.supernodexp.hpc;enqueuing into workq, state 1 hop 1
05/02/2018 09:35:27;0008;Server@node2;Job;13286.node2.supernodexp.hpc;Job Queued at request of baovo@node2.supernodexp.hpc, owner = baovo@node2.supernodexp.hpc, job name = vec-data-cpu4, queue = workq
05/02/2018 09:35:27;0040;Server@node2;Svr;node2.supernodexp.hpc;Scheduler sent command 1
05/02/2018 09:35:27;0040;Server@node2;Svr;node2.supernodexp.hpc;Scheduler sent command 0
05/02/2018 09:35:27;0100;Server@node2;Req;;Type 21 request received from Scheduler@node2.supernodexp.hpc, sock=19
05/02/2018 09:35:27;0100;Server@node2;Req;;Type 81 request received from Scheduler@node2.supernodexp.hpc, sock=19
05/02/2018 09:35:27;0100;Server@node2;Req;;Type 71 request received from Scheduler@node2.supernodexp.hpc, sock=19
05/02/2018 09:35:27;0100;Server@node2;Req;;Type 58 request received from Scheduler@node2.supernodexp.hpc, sock=19
05/02/2018 09:35:27;0100;Server@node2;Req;;Type 20 request received from Scheduler@node2.supernodexp.hpc, sock=19
05/02/2018 09:35:27;0100;Server@node2;Req;;Type 51 request received from Scheduler@node2.supernodexp.hpc, sock=19
05/02/2018 09:35:27;0100;Server@node2;Req;;Type 23 request received from Scheduler@node2.supernodexp.hpc, sock=19
05/02/2018 09:35:27;0008;Server@node2;Job;13286.node2.supernodexp.hpc;Job Run at request of Scheduler@node2.supernodexp.hpc on exec_vnode (node3:ncpus=4:mem=5242880kb)
05/02/2018 09:35:27;0001;Server@node2;Svr;Server@node2;Success (0) in req_runjob2, return value of svr_startjob is 0
05/02/2018 09:35:29;0100;Server@node2;Req;;Type 1 request received from baovo@node2.supernodexp.hpc, sock=16
05/02/2018 09:35:29;0100;Server@node2;Req;;Type 3 request received from baovo@node2.supernodexp.hpc, sock=16
05/02/2018 09:35:29;0100;Server@node2;Req;;Type 5 request received from baovo@node2.supernodexp.hpc, sock=16
05/02/2018 09:35:29;0100;Server@node2;Job;13287.node2.supernodexp.hpc;enqueuing into workq, state 1 hop 1
05/02/2018 09:35:29;0008;Server@node2;Job;13287.node2.supernodexp.hpc;Job Queued at request of baovo@node2.supernodexp.hpc, owner = baovo@node2.supernodexp.hpc, job name = lu-decomp-100000-mem10, queue = workq
05/02/2018 09:35:29;0040;Server@node2;Svr;node2.supernodexp.hpc;Scheduler sent command 1
05/02/2018 09:35:29;0040;Server@node2;Svr;node2.supernodexp.hpc;Scheduler sent command 0
05/02/2018 09:35:29;0100;Server@node2;Req;;Type 21 request received from Scheduler@node2.supernodexp.hpc, sock=19
05/02/2018 09:35:29;0100;Server@node2;Req;;Type 81 request received from Scheduler@node2.supernodexp.hpc, sock=19
05/02/2018 09:35:29;0100;Server@node2;Req;;Type 71 request received from Scheduler@node2.supernodexp.hpc, sock=19
05/02/2018 09:35:29;0100;Server@node2;Req;;Type 58 request received from Scheduler@node2.supernodexp.hpc, sock=19
05/02/2018 09:35:29;0100;Server@node2;Req;;Type 1 request received from baovo@node2.supernodexp.hpc, sock=16
05/02/2018 09:35:29;0100;Server@node2;Req;;Type 3 request received from baovo@node2.supernodexp.hpc, sock=16
05/02/2018 09:35:29;0100;Server@node2;Req;;Type 5 request received from baovo@node2.supernodexp.hpc, sock=16
05/02/2018 09:35:29;0100;Server@node2;Job;13288.node2.supernodexp.hpc;enqueuing into workq, state 1 hop 1
05/02/2018 09:35:29;0008;Server@node2;Job;13288.node2.supernodexp.hpc;Job Queued at request of baovo@node2.supernodexp.hpc, owner = baovo@node2.supernodexp.hpc, job name = vec-data-cpu4, queue = workq
05/02/2018 09:35:29;0100;Server@node2;Req;;Type 1 request received from baovo@node2.supernodexp.hpc, sock=16
05/02/2018 09:35:29;0100;Server@node2;Req;;Type 3 request received from baovo@node2.supernodexp.hpc, sock=16
05/02/2018 09:35:29;0100;Server@node2;Req;;Type 5 request received from baovo@node2.supernodexp.hpc, sock=16
05/02/2018 09:35:29;0100;Server@node2;Job;13289.node2.supernodexp.hpc;enqueuing into workq, state 1 hop 1
05/02/2018 09:35:29;0008;Server@node2;Job;13289.node2.supernodexp.hpc;Job Queued at request of baovo@node2.supernodexp.hpc, owner = baovo@node2.supernodexp.hpc, job name = parallelism-sweep-cpu8, queue = workq
05/02/2018 09:35:29;0100;Server@node2;Req;;Type 20 request received from Scheduler@node2.supernodexp.hpc, sock=19
05/02/2018 09:35:29;0100;Server@node2;Req;;Type 51 request received from Scheduler@node2.supernodexp.hpc, sock=19
05/02/2018 09:35:29;0100;Server@node2;Req;;Type 23 request received from Scheduler@node2.supernodexp.hpc, sock=19
05/02/2018 09:35:29;0008;Server@node2;Job;13289.node2.supernodexp.hpc;Job Run at request of Scheduler@node2.supernodexp.hpc on exec_vnode (node14:ncpus=8:mem=20971520kb)
05/02/2018 09:35:29;0001;Server@node2;Svr;Server@node2;Success (0) in req_runjob2, return value of svr_startjob is 0
05/02/2018 09:35:29;0100;Server@node2;Req;;Type 23 request received from Scheduler@node2.supernodexp.hpc, sock=19
05/02/2018 09:35:29;0008;Server@node2;Job;13288.node2.supernodexp.hpc;Job Run at request of Scheduler@node2.supernodexp.hpc on exec_vnode (node14:ncpus=4:mem=5242880kb)
05/02/2018 09:35:29;0001;Server@node2;Svr;Server@node2;Success (0) in req_runjob2, return value of svr_startjob is 0
05/02/2018 09:35:29;0100;Server@node2;Req;;Type 23 request received from Scheduler@node2.supernodexp.hpc, sock=19
05/02/2018 09:35:29;0008;Server@node2;Job;13287.node2.supernodexp.hpc;Job Run at request of Scheduler@node2.supernodexp.hpc on exec_vnode (node13:ncpus=8:mem=10485760kb)
05/02/2018 09:35:29;0001;Server@node2;Svr;Server@node2;Success (0) in req_runjob2, return value of svr_startjob is 0
05/02/2018 09:35:29;0040;Server@node2;Svr;node2.supernodexp.hpc;Scheduler sent command 1
05/02/2018 09:35:29;0040;Server@node2;Svr;node2.supernodexp.hpc;Scheduler sent command 0
05/02/2018 09:35:29;0100;Server@node2;Req;;Type 21 request received from Scheduler@node2.supernodexp.hpc, sock=19
05/02/2018 09:35:29;0100;Server@node2;Req;;Type 81 request received from Scheduler@node2.supernodexp.hpc, sock=19
05/02/2018 09:35:29;0100;Server@node2;Req;;Type 71 request received from Scheduler@node2.supernodexp.hpc, sock=19
05/02/2018 09:35:29;0100;Server@node2;Req;;Type 58 request received from Scheduler@node2.supernodexp.hpc, sock=19
05/02/2018 09:35:29;0100;Server@node2;Req;;Type 20 request received from Scheduler@node2.supernodexp.hpc, sock=19
05/02/2018 09:35:29;0100;Server@node2;Req;;Type 51 request received from Scheduler@node2.supernodexp.hpc, sock=19
05/02/2018 09:35:31;0100;Server@node2;Req;;Type 1 request received from baovo@node2.supernodexp.hpc, sock=16
05/02/2018 09:35:31;0100;Server@node2;Req;;Type 3 request received from baovo@node2.supernodexp.hpc, sock=16
05/02/2018 09:35:31;0100;Server@node2;Req;;Type 5 request received from baovo@node2.supernodexp.hpc, sock=16
05/02/2018 09:35:31;0100;Server@node2;Job;13290.node2.supernodexp.hpc;enqueuing into workq, state 1 hop 1
05/02/2018 09:35:31;0008;Server@node2;Job;13290.node2.supernodexp.hpc;Job Queued at request of baovo@node2.supernodexp.hpc, owner = baovo@node2.supernodexp.hpc, job name = fft, queue = workq
05/02/2018 09:35:31;0040;Server@node2;Svr;node2.supernodexp.hpc;Scheduler sent command 1
05/02/2018 09:35:31;0040;Server@node2;Svr;node2.supernodexp.hpc;Scheduler sent command 0
05/02/2018 09:35:31;0100;Server@node2;Req;;Type 21 request received from Scheduler@node2.supernodexp.hpc, sock=19
05/02/2018 09:35:31;0100;Server@node2;Req;;Type 81 request received from Scheduler@node2.supernodexp.hpc, sock=19
05/02/2018 09:35:31;0100;Server@node2;Req;;Type 71 request received from Scheduler@node2.supernodexp.hpc, sock=19
05/02/2018 09:35:31;0100;Server@node2;Req;;Type 58 request received from Scheduler@node2.supernodexp.hpc, sock=19
05/02/2018 09:35:31;0100;Server@node2;Req;;Type 1 request received from baovo@node2.supernodexp.hpc, sock=16
05/02/2018 09:35:31;0100;Server@node2;Req;;Type 3 request received from baovo@node2.supernodexp.hpc, sock=16
05/02/2018 09:35:31;0100;Server@node2;Req;;Type 5 request received from baovo@node2.supernodexp.hpc, sock=16
05/02/2018 09:35:31;0100;Server@node2;Job;13291.node2.supernodexp.hpc;enqueuing into workq, state 1 hop 1
05/02/2018 09:35:31;0008;Server@node2;Job;13291.node2.supernodexp.hpc;Job Queued at request of baovo@node2.supernodexp.hpc, owner = baovo@node2.supernodexp.hpc, job name = md, queue = workq
05/02/2018 09:35:31;0100;Server@node2;Req;;Type 20 request received from Scheduler@node2.supernodexp.hpc, sock=19
05/02/2018 09:35:31;0100;Server@node2;Req;;Type 51 request received from Scheduler@node2.supernodexp.hpc, sock=19
05/02/2018 09:35:31;0100;Server@node2;Req;;Type 23 request received from Scheduler@node2.supernodexp.hpc, sock=19
05/02/2018 09:35:31;0008;Server@node2;Job;13291.node2.supernodexp.hpc;Job Run at request of Scheduler@node2.supernodexp.hpc on exec_vnode (node13:ncpus=8:mem=3145728kb)
05/02/2018 09:35:31;0001;Server@node2;Svr;Server@node2;Success (0) in req_runjob2, return value of svr_startjob is 0
05/02/2018 09:35:31;0100;Server@node2;Req;;Type 23 request received from Scheduler@node2.supernodexp.hpc, sock=19
05/02/2018 09:35:31;0008;Server@node2;Job;13290.node2.supernodexp.hpc;Job Run at request of Scheduler@node2.supernodexp.hpc on exec_vnode (node13:ncpus=12:mem=20971520kb)
05/02/2018 09:35:31;0001;Server@node2;Svr;Server@node2;Success (0) in req_runjob2, return value of svr_startjob is 0
05/02/2018 09:35:31;0040;Server@node2;Svr;node2.supernodexp.hpc;Scheduler sent command 1
05/02/2018 09:35:31;0040;Server@node2;Svr;node2.supernodexp.hpc;Scheduler sent command 0
05/02/2018 09:35:31;0100;Server@node2;Req;;Type 21 request received from Scheduler@node2.supernodexp.hpc, sock=19
05/02/2018 09:35:31;0100;Server@node2;Req;;Type 81 request received from Scheduler@node2.supernodexp.hpc, sock=19
05/02/2018 09:35:31;0100;Server@node2;Req;;Type 71 request received from Scheduler@node2.supernodexp.hpc, sock=19
05/02/2018 09:35:31;0100;Server@node2;Req;;Type 58 request received from Scheduler@node2.supernodexp.hpc, sock=19
05/02/2018 09:35:31;0100;Server@node2;Req;;Type 20 request received from Scheduler@node2.supernodexp.hpc, sock=19
05/02/2018 09:35:31;0100;Server@node2;Req;;Type 51 request received from Scheduler@node2.supernodexp.hpc, sock=19
05/02/2018 09:35:33;0100;Server@node2;Req;;Type 1 request received from baovo@node2.supernodexp.hpc, sock=16
05/02/2018 09:35:33;0100;Server@node2;Req;;Type 3 request received from baovo@node2.supernodexp.hpc, sock=16
05/02/2018 09:35:33;0100;Server@node2;Req;;Type 5 request received from baovo@node2.supernodexp.hpc, sock=16
05/02/2018 09:35:33;0100;Server@node2;Job;13292.node2.supernodexp.hpc;enqueuing into workq, state 1 hop 1
05/02/2018 09:35:33;0008;Server@node2;Job;13292.node2.supernodexp.hpc;Job Queued at request of baovo@node2.supernodexp.hpc, owner = baovo@node2.supernodexp.hpc, job name = threading-misc-histogram, queue = workq
05/02/2018 09:35:33;0040;Server@node2;Svr;node2.supernodexp.hpc;Scheduler sent command 1
05/02/2018 09:35:33;0040;Server@node2;Svr;node2.supernodexp.hpc;Scheduler sent command 0
05/02/2018 09:35:33;0100;Server@node2;Req;;Type 21 request received from Scheduler@node2.supernodexp.hpc, sock=19
05/02/2018 09:35:33;0100;Server@node2;Req;;Type 81 request received from Scheduler@node2.supernodexp.hpc, sock=19
05/02/2018 09:35:33;0100;Server@node2;Req;;Type 71 request received from Scheduler@node2.supernodexp.hpc, sock=19
05/02/2018 09:35:33;0100;Server@node2;Req;;Type 58 request received from Scheduler@node2.supernodexp.hpc, sock=19
05/02/2018 09:35:33;0100;Server@node2;Req;;Type 20 request received from Scheduler@node2.supernodexp.hpc, sock=19
05/02/2018 09:35:33;0100;Server@node2;Req;;Type 51 request received from Scheduler@node2.supernodexp.hpc, sock=19
05/02/2018 09:35:33;0100;Server@node2;Req;;Type 23 request received from Scheduler@node2.supernodexp.hpc, sock=19
05/02/2018 09:35:33;0008;Server@node2;Job;13292.node2.supernodexp.hpc;Job Run at request of Scheduler@node2.supernodexp.hpc on exec_vnode (node14:ncpus=2:mem=2097152kb)
05/02/2018 09:35:33;0001;Server@node2;Svr;Server@node2;Success (0) in req_runjob2, return value of svr_startjob is 0
05/02/2018 09:35:33;0080;Server@node2;Job;13289.node2.supernodexp.hpc;Obit received momhop:1 serverhop:1 state:4 substate:42
05/02/2018 09:35:34;0010;Server@node2;Job;13289.node2.supernodexp.hpc;Exit_status=0 resources_used.cpupercent=0 resources_used.cput=00:00:00 resources_used.mem=0kb resources_used.ncpus=8 resources_used.vmem=0kb resources_used.walltime=00:00:06
05/02/2018 09:35:34;0100;Server@node2;Job;13289.node2.supernodexp.hpc;dequeuing from workq, state 5
05/02/2018 09:35:34;0040;Server@node2;Svr;node2.supernodexp.hpc;Scheduler sent command 2
05/02/2018 09:35:34;0040;Server@node2;Svr;node2.supernodexp.hpc;Scheduler sent command 0
05/02/2018 09:35:34;0100;Server@node2;Req;;Type 21 request received from Scheduler@node2.supernodexp.hpc, sock=19
05/02/2018 09:35:34;0100;Server@node2;Req;;Type 81 request received from Scheduler@node2.supernodexp.hpc, sock=19
05/02/2018 09:35:34;0100;Server@node2;Req;;Type 71 request received from Scheduler@node2.supernodexp.hpc, sock=19
05/02/2018 09:35:34;0100;Server@node2;Req;;Type 58 request received from Scheduler@node2.supernodexp.hpc, sock=19
05/02/2018 09:35:34;0100;Server@node2;Req;;Type 20 request received from Scheduler@node2.supernodexp.hpc, sock=19
05/02/2018 09:35:34;0100;Server@node2;Req;;Type 51 request received from Scheduler@node2.supernodexp.hpc, sock=19
05/02/2018 09:35:36;0080;Server@node2;Job;13292.node2.supernodexp.hpc;Obit received momhop:1 serverhop:1 state:4 substate:42
05/02/2018 09:35:36;0010;Server@node2;Job;13292.node2.supernodexp.hpc;Exit_status=0 resources_used.cpupercent=0 resources_used.cput=00:00:00 resources_used.mem=9872kb resources_used.ncpus=2 resources_used.vmem=450612kb resources_used.walltime=00:00:04
05/02/2018 09:35:36;0100;Server@node2;Job;13292.node2.supernodexp.hpc;dequeuing from workq, state 5
05/02/2018 09:35:36;0040;Server@node2;Svr;node2.supernodexp.hpc;Scheduler sent command 2
05/02/2018 09:35:36;0040;Server@node2;Svr;node2.supernodexp.hpc;Scheduler sent command 0
05/02/2018 09:35:36;0100;Server@node2;Req;;Type 21 request received from Scheduler@node2.supernodexp.hpc, sock=19
05/02/2018 09:35:36;0100;Server@node2;Req;;Type 81 request received from Scheduler@node2.supernodexp.hpc, sock=19
05/02/2018 09:35:36;0100;Server@node2;Req;;Type 71 request received from Scheduler@node2.supernodexp.hpc, sock=19
05/02/2018 09:35:36;0100;Server@node2;Req;;Type 58 request received from Scheduler@node2.supernodexp.hpc, sock=19
05/02/2018 09:35:36;0100;Server@node2;Req;;Type 20 request received from Scheduler@node2.supernodexp.hpc, sock=19
05/02/2018 09:35:36;0100;Server@node2;Req;;Type 51 request received from Scheduler@node2.supernodexp.hpc, sock=19
05/02/2018 09:35:38;0100;Server@node2;Req;;Type 1 request received from baovo@node2.supernodexp.hpc, sock=16
05/02/2018 09:35:38;0100;Server@node2;Req;;Type 3 request received from baovo@node2.supernodexp.hpc, sock=16
05/02/2018 09:35:38;0100;Server@node2;Req;;Type 5 request received from baovo@node2.supernodexp.hpc, sock=16
05/02/2018 09:35:38;0100;Server@node2;Job;13293.node2.supernodexp.hpc;enqueuing into workq, state 1 hop 1
05/02/2018 09:35:38;0008;Server@node2;Job;13293.node2.supernodexp.hpc;Job Queued at request of baovo@node2.supernodexp.hpc, owner = baovo@node2.supernodexp.hpc, job name = vtune, queue = workq
05/02/2018 09:35:38;0040;Server@node2;Svr;node2.supernodexp.hpc;Scheduler sent command 1
05/02/2018 09:35:38;0040;Server@node2;Svr;node2.supernodexp.hpc;Scheduler sent command 0
05/02/2018 09:35:38;0100;Server@node2;Req;;Type 21 request received from Scheduler@node2.supernodexp.hpc, sock=19
05/02/2018 09:35:38;0100;Server@node2;Req;;Type 81 request received from Scheduler@node2.supernodexp.hpc, sock=19
05/02/2018 09:35:38;0100;Server@node2;Req;;Type 71 request received from Scheduler@node2.supernodexp.hpc, sock=19
05/02/2018 09:35:38;0100;Server@node2;Req;;Type 58 request received from Scheduler@node2.supernodexp.hpc, sock=19
05/02/2018 09:35:38;0100;Server@node2;Req;;Type 20 request received from Scheduler@node2.supernodexp.hpc, sock=19
05/02/2018 09:35:38;0100;Server@node2;Req;;Type 51 request received from Scheduler@node2.supernodexp.hpc, sock=19
05/02/2018 09:35:38;0100;Server@node2;Req;;Type 23 request received from Scheduler@node2.supernodexp.hpc, sock=19
05/02/2018 09:35:38;0008;Server@node2;Job;13293.node2.supernodexp.hpc;Job Run at request of Scheduler@node2.supernodexp.hpc on exec_vnode (node14:nmics=2:ncpus=12:mem=41943040kb)
05/02/2018 09:35:38;0001;Server@node2;Svr;Server@node2;Success (0) in req_runjob2, return value of svr_startjob is 0
05/02/2018 09:35:40;0100;Server@node2;Req;;Type 1 request received from baovo@node2.supernodexp.hpc, sock=16
05/02/2018 09:35:40;0100;Server@node2;Req;;Type 3 request received from baovo@node2.supernodexp.hpc, sock=16
05/02/2018 09:35:40;0100;Server@node2;Req;;Type 5 request received from baovo@node2.supernodexp.hpc, sock=16
05/02/2018 09:35:40;0100;Server@node2;Job;13294.node2.supernodexp.hpc;enqueuing into workq, state 1 hop 1
05/02/2018 09:35:40;0008;Server@node2;Job;13294.node2.supernodexp.hpc;Job Queued at request of baovo@node2.supernodexp.hpc, owner = baovo@node2.supernodexp.hpc, job name = sgefa, queue = workq
05/02/2018 09:35:40;0040;Server@node2;Svr;node2.supernodexp.hpc;Scheduler sent command 1
05/02/2018 09:35:40;0040;Server@node2;Svr;node2.supernodexp.hpc;Scheduler sent command 0
05/02/2018 09:35:40;0100;Server@node2;Req;;Type 21 request received from Scheduler@node2.supernodexp.hpc, sock=19
05/02/2018 09:35:40;0100;Server@node2;Req;;Type 81 request received from Scheduler@node2.supernodexp.hpc, sock=19
05/02/2018 09:35:40;0100;Server@node2;Req;;Type 71 request received from Scheduler@node2.supernodexp.hpc, sock=19
05/02/2018 09:35:40;0100;Server@node2;Req;;Type 58 request received from Scheduler@node2.supernodexp.hpc, sock=19
05/02/2018 09:35:40;0100;Server@node2;Req;;Type 20 request received from Scheduler@node2.supernodexp.hpc, sock=19
05/02/2018 09:35:40;0100;Server@node2;Req;;Type 51 request received from Scheduler@node2.supernodexp.hpc, sock=19
05/02/2018 09:35:40;0100;Server@node2;Req;;Type 11 request received from Scheduler@node2.supernodexp.hpc, sock=19
05/02/2018 09:35:40;0008;Server@node2;Job;13294.node2.supernodexp.hpc;Job Modified at request of Scheduler@node2.supernodexp.hpc
05/02/2018 09:35:43;0080;Server@node2;Job;13288.node2.supernodexp.hpc;Obit received momhop:1 serverhop:1 state:4 substate:42
05/02/2018 09:35:44;0100;Server@node2;Req;;Type 1 request received from baovo@node2.supernodexp.hpc, sock=16
05/02/2018 09:35:44;0100;Server@node2;Req;;Type 3 request received from baovo@node2.supernodexp.hpc, sock=16
05/02/2018 09:35:44;0100;Server@node2;Req;;Type 5 request received from baovo@node2.supernodexp.hpc, sock=16
05/02/2018 09:35:44;0100;Server@node2;Job;13295.node2.supernodexp.hpc;enqueuing into workq, state 1 hop 1
05/02/2018 09:35:44;0008;Server@node2;Job;13295.node2.supernodexp.hpc;Job Queued at request of baovo@node2.supernodexp.hpc, owner = baovo@node2.supernodexp.hpc, job name = threading-misc-histogram, queue = workq
05/02/2018 09:35:44;0040;Server@node2;Svr;node2.supernodexp.hpc;Scheduler sent command 1
05/02/2018 09:35:44;0040;Server@node2;Svr;node2.supernodexp.hpc;Scheduler sent command 0
05/02/2018 09:35:44;0100;Server@node2;Req;;Type 21 request received from Scheduler@node2.supernodexp.hpc, sock=19
05/02/2018 09:35:44;0100;Server@node2;Req;;Type 81 request received from Scheduler@node2.supernodexp.hpc, sock=19
05/02/2018 09:35:44;0100;Server@node2;Req;;Type 71 request received from Scheduler@node2.supernodexp.hpc, sock=19
05/02/2018 09:35:44;0100;Server@node2;Req;;Type 58 request received from Scheduler@node2.supernodexp.hpc, sock=19
05/02/2018 09:35:44;0100;Server@node2;Req;;Type 1 request received from baovo@node2.supernodexp.hpc, sock=16
05/02/2018 09:35:44;0100;Server@node2;Req;;Type 3 request received from baovo@node2.supernodexp.hpc, sock=16
05/02/2018 09:35:44;0100;Server@node2;Req;;Type 5 request received from baovo@node2.supernodexp.hpc, sock=16
05/02/2018 09:35:44;0100;Server@node2;Job;13296.node2.supernodexp.hpc;enqueuing into workq, state 1 hop 1
05/02/2018 09:35:44;0008;Server@node2;Job;13296.node2.supernodexp.hpc;Job Queued at request of baovo@node2.supernodexp.hpc, owner = baovo@node2.supernodexp.hpc, job name = sgefa, queue = workq
05/02/2018 09:35:44;0100;Server@node2;Req;;Type 20 request received from Scheduler@node2.supernodexp.hpc, sock=19
05/02/2018 09:35:44;0100;Server@node2;Req;;Type 51 request received from Scheduler@node2.supernodexp.hpc, sock=19
05/02/2018 09:35:44;0100;Server@node2;Req;;Type 23 request received from Scheduler@node2.supernodexp.hpc, sock=19
05/02/2018 09:35:44;0008;Server@node2;Job;13295.node2.supernodexp.hpc;Job Run at request of Scheduler@node2.supernodexp.hpc on exec_vnode (node13:ncpus=2:mem=2097152kb)
05/02/2018 09:35:44;0001;Server@node2;Svr;Server@node2;Success (0) in req_runjob2, return value of svr_startjob is 0
05/02/2018 09:35:44;0100;Server@node2;Req;;Type 11 request received from Scheduler@node2.supernodexp.hpc, sock=19
05/02/2018 09:35:44;0008;Server@node2;Job;13296.node2.supernodexp.hpc;Job Modified at request of Scheduler@node2.supernodexp.hpc
05/02/2018 09:35:44;0100;Server@node2;Req;;Type 11 request received from Scheduler@node2.supernodexp.hpc, sock=19
05/02/2018 09:35:44;0008;Server@node2;Job;13294.node2.supernodexp.hpc;Job Modified at request of Scheduler@node2.supernodexp.hpc
05/02/2018 09:35:44;0040;Server@node2;Svr;node2.supernodexp.hpc;Scheduler sent command 1
05/02/2018 09:35:44;0040;Server@node2;Svr;node2.supernodexp.hpc;Scheduler sent command 0
05/02/2018 09:35:44;0100;Server@node2;Req;;Type 21 request received from Scheduler@node2.supernodexp.hpc, sock=19
05/02/2018 09:35:44;0100;Server@node2;Req;;Type 81 request received from Scheduler@node2.supernodexp.hpc, sock=19
05/02/2018 09:35:44;0100;Server@node2;Req;;Type 71 request received from Scheduler@node2.supernodexp.hpc, sock=19
05/02/2018 09:35:44;0100;Server@node2;Req;;Type 58 request received from Scheduler@node2.supernodexp.hpc, sock=19
05/02/2018 09:35:44;0100;Server@node2;Req;;Type 20 request received from Scheduler@node2.supernodexp.hpc, sock=19
05/02/2018 09:35:44;0100;Server@node2;Req;;Type 51 request received from Scheduler@node2.supernodexp.hpc, sock=19
05/02/2018 09:35:44;0010;Server@node2;Job;13288.node2.supernodexp.hpc;Exit_status=0 resources_used.cpupercent=0 resources_used.cput=00:00:00 resources_used.mem=9636kb resources_used.ncpus=4 resources_used.vmem=171960kb resources_used.walltime=00:00:14
05/02/2018 09:35:44;0100;Server@node2;Job;13288.node2.supernodexp.hpc;dequeuing from workq, state 5
05/02/2018 09:35:44;0040;Server@node2;Svr;node2.supernodexp.hpc;Scheduler sent command 2
05/02/2018 09:35:44;0040;Server@node2;Svr;node2.supernodexp.hpc;Scheduler sent command 0
05/02/2018 09:35:44;0100;Server@node2;Req;;Type 21 request received from Scheduler@node2.supernodexp.hpc, sock=19
05/02/2018 09:35:44;0100;Server@node2;Req;;Type 81 request received from Scheduler@node2.supernodexp.hpc, sock=19
05/02/2018 09:35:44;0100;Server@node2;Req;;Type 71 request received from Scheduler@node2.supernodexp.hpc, sock=19
05/02/2018 09:35:44;0100;Server@node2;Req;;Type 58 request received from Scheduler@node2.supernodexp.hpc, sock=19
05/02/2018 09:35:44;0100;Server@node2;Req;;Type 20 request received from Scheduler@node2.supernodexp.hpc, sock=19
05/02/2018 09:35:44;0100;Server@node2;Req;;Type 51 request received from Scheduler@node2.supernodexp.hpc, sock=19
05/02/2018 09:35:44;0100;Server@node2;Req;;Type 11 request received from Scheduler@node2.supernodexp.hpc, sock=19
05/02/2018 09:35:44;0008;Server@node2;Job;13294.node2.supernodexp.hpc;Job Modified at request of Scheduler@node2.supernodexp.hpc
05/02/2018 09:35:47;0080;Server@node2;Job;13295.node2.supernodexp.hpc;Obit received momhop:1 serverhop:1 state:4 substate:42
05/02/2018 09:35:48;0010;Server@node2;Job;13295.node2.supernodexp.hpc;Exit_status=0 resources_used.cpupercent=0 resources_used.cput=00:00:00 resources_used.mem=0kb resources_used.ncpus=2 resources_used.vmem=0kb resources_used.walltime=00:00:03
05/02/2018 09:35:48;0100;Server@node2;Job;13295.node2.supernodexp.hpc;dequeuing from workq, state 5
05/02/2018 09:35:48;0040;Server@node2;Svr;node2.supernodexp.hpc;Scheduler sent command 2
05/02/2018 09:35:48;0040;Server@node2;Svr;node2.supernodexp.hpc;Scheduler sent command 0
05/02/2018 09:35:48;0100;Server@node2;Req;;Type 21 request received from Scheduler@node2.supernodexp.hpc, sock=19
05/02/2018 09:35:48;0100;Server@node2;Req;;Type 81 request received from Scheduler@node2.supernodexp.hpc, sock=19
05/02/2018 09:35:48;0100;Server@node2;Req;;Type 71 request received from Scheduler@node2.supernodexp.hpc, sock=19
05/02/2018 09:35:48;0100;Server@node2;Req;;Type 58 request received from Scheduler@node2.supernodexp.hpc, sock=19
05/02/2018 09:35:48;0100;Server@node2;Req;;Type 20 request received from Scheduler@node2.supernodexp.hpc, sock=19
05/02/2018 09:35:48;0100;Server@node2;Req;;Type 51 request received from Scheduler@node2.supernodexp.hpc, sock=19
05/02/2018 09:35:48;0100;Server@node2;Req;;Type 11 request received from Scheduler@node2.supernodexp.hpc, sock=19
05/02/2018 09:35:48;0008;Server@node2;Job;13294.node2.supernodexp.hpc;Job Modified at request of Scheduler@node2.supernodexp.hpc
05/02/2018 09:35:50;0100;Server@node2;Req;;Type 1 request received from baovo@node2.supernodexp.hpc, sock=16
05/02/2018 09:35:50;0100;Server@node2;Req;;Type 3 request received from baovo@node2.supernodexp.hpc, sock=16
05/02/2018 09:35:50;0100;Server@node2;Req;;Type 5 request received from baovo@node2.supernodexp.hpc, sock=16
05/02/2018 09:35:50;0100;Server@node2;Job;13297.node2.supernodexp.hpc;enqueuing into workq, state 1 hop 1
05/02/2018 09:35:50;0008;Server@node2;Job;13297.node2.supernodexp.hpc;Job Queued at request of baovo@node2.supernodexp.hpc, owner = baovo@node2.supernodexp.hpc, job name = lu-decomp-100000-mem20, queue = workq
05/02/2018 09:35:50;0040;Server@node2;Svr;node2.supernodexp.hpc;Scheduler sent command 1
05/02/2018 09:35:50;0040;Server@node2;Svr;node2.supernodexp.hpc;Scheduler sent command 0
05/02/2018 09:35:50;0100;Server@node2;Req;;Type 21 request received from Scheduler@node2.supernodexp.hpc, sock=19
05/02/2018 09:35:50;0100;Server@node2;Req;;Type 81 request received from Scheduler@node2.supernodexp.hpc, sock=19
05/02/2018 09:35:50;0100;Server@node2;Req;;Type 71 request received from Scheduler@node2.supernodexp.hpc, sock=19
05/02/2018 09:35:50;0100;Server@node2;Req;;Type 58 request received from Scheduler@node2.supernodexp.hpc, sock=19
05/02/2018 09:35:50;0100;Server@node2;Req;;Type 1 request received from baovo@node2.supernodexp.hpc, sock=16
05/02/2018 09:35:50;0100;Server@node2;Req;;Type 3 request received from baovo@node2.supernodexp.hpc, sock=16
05/02/2018 09:35:50;0100;Server@node2;Req;;Type 5 request received from baovo@node2.supernodexp.hpc, sock=16
05/02/2018 09:35:50;0100;Server@node2;Job;13298.node2.supernodexp.hpc;enqueuing into workq, state 1 hop 1
05/02/2018 09:35:50;0008;Server@node2;Job;13298.node2.supernodexp.hpc;Job Queued at request of baovo@node2.supernodexp.hpc, owner = baovo@node2.supernodexp.hpc, job name = lu-decomp-100000-mem10, queue = workq
05/02/2018 09:35:50;0100;Server@node2;Req;;Type 20 request received from Scheduler@node2.supernodexp.hpc, sock=19
05/02/2018 09:35:50;0100;Server@node2;Req;;Type 51 request received from Scheduler@node2.supernodexp.hpc, sock=19
05/02/2018 09:35:50;0100;Server@node2;Req;;Type 23 request received from Scheduler@node2.supernodexp.hpc, sock=19
05/02/2018 09:35:50;0008;Server@node2;Job;13297.node2.supernodexp.hpc;Job Run at request of Scheduler@node2.supernodexp.hpc on exec_vnode (node13:ncpus=8:mem=20971520kb)
05/02/2018 09:35:50;0001;Server@node2;Svr;Server@node2;Success (0) in req_runjob2, return value of svr_startjob is 0
05/02/2018 09:35:50;0100;Server@node2;Req;;Type 11 request received from Scheduler@node2.supernodexp.hpc, sock=19
05/02/2018 09:35:50;0008;Server@node2;Job;13294.node2.supernodexp.hpc;Job Modified at request of Scheduler@node2.supernodexp.hpc
05/02/2018 09:35:50;0100;Server@node2;Req;;Type 11 request received from Scheduler@node2.supernodexp.hpc, sock=19
05/02/2018 09:35:50;0008;Server@node2;Job;13298.node2.supernodexp.hpc;Job Modified at request of Scheduler@node2.supernodexp.hpc
05/02/2018 09:35:50;0040;Server@node2;Svr;node2.supernodexp.hpc;Scheduler sent command 1
05/02/2018 09:35:50;0040;Server@node2;Svr;node2.supernodexp.hpc;Scheduler sent command 0
05/02/2018 09:35:50;0100;Server@node2;Req;;Type 21 request received from Scheduler@node2.supernodexp.hpc, sock=19
05/02/2018 09:35:50;0100;Server@node2;Req;;Type 81 request received from Scheduler@node2.supernodexp.hpc, sock=19
05/02/2018 09:35:50;0100;Server@node2;Req;;Type 71 request received from Scheduler@node2.supernodexp.hpc, sock=19
05/02/2018 09:35:50;0100;Server@node2;Req;;Type 58 request received from Scheduler@node2.supernodexp.hpc, sock=19
05/02/2018 09:35:50;0100;Server@node2;Req;;Type 20 request received from Scheduler@node2.supernodexp.hpc, sock=19
05/02/2018 09:35:50;0100;Server@node2;Req;;Type 51 request received from Scheduler@node2.supernodexp.hpc, sock=19
05/02/2018 09:35:51;0100;Server@node2;Req;;Type 1 request received from baovo@node2.supernodexp.hpc, sock=16
05/02/2018 09:35:51;0100;Server@node2;Req;;Type 3 request received from baovo@node2.supernodexp.hpc, sock=16
05/02/2018 09:35:51;0100;Server@node2;Req;;Type 5 request received from baovo@node2.supernodexp.hpc, sock=16
05/02/2018 09:35:51;0100;Server@node2;Job;13299.node2.supernodexp.hpc;enqueuing into workq, state 1 hop 1
05/02/2018 09:35:51;0008;Server@node2;Job;13299.node2.supernodexp.hpc;Job Queued at request of baovo@node2.supernodexp.hpc, owner = baovo@node2.supernodexp.hpc, job name = benchmark-offload, queue = workq
05/02/2018 09:35:51;0040;Server@node2;Svr;node2.supernodexp.hpc;Scheduler sent command 1
05/02/2018 09:35:51;0040;Server@node2;Svr;node2.supernodexp.hpc;Scheduler sent command 0
05/02/2018 09:35:51;0100;Server@node2;Req;;Type 21 request received from Scheduler@node2.supernodexp.hpc, sock=19
05/02/2018 09:35:51;0100;Server@node2;Req;;Type 81 request received from Scheduler@node2.supernodexp.hpc, sock=19
05/02/2018 09:35:51;0100;Server@node2;Req;;Type 71 request received from Scheduler@node2.supernodexp.hpc, sock=19
05/02/2018 09:35:51;0100;Server@node2;Req;;Type 58 request received from Scheduler@node2.supernodexp.hpc, sock=19
05/02/2018 09:35:51;0100;Server@node2;Req;;Type 1 request received from baovo@node2.supernodexp.hpc, sock=16
05/02/2018 09:35:51;0100;Server@node2;Req;;Type 3 request received from baovo@node2.supernodexp.hpc, sock=16
05/02/2018 09:35:51;0100;Server@node2;Req;;Type 5 request received from baovo@node2.supernodexp.hpc, sock=16
05/02/2018 09:35:51;0100;Server@node2;Job;13300.node2.supernodexp.hpc;enqueuing into workq, state 1 hop 1
05/02/2018 09:35:51;0008;Server@node2;Job;13300.node2.supernodexp.hpc;Job Queued at request of baovo@node2.supernodexp.hpc, owner = baovo@node2.supernodexp.hpc, job name = benchmark-offload, queue = workq
05/02/2018 09:35:51;0100;Server@node2;Req;;Type 1 request received from baovo@node2.supernodexp.hpc, sock=16
05/02/2018 09:35:51;0100;Server@node2;Req;;Type 3 request received from baovo@node2.supernodexp.hpc, sock=16
05/02/2018 09:35:51;0100;Server@node2;Req;;Type 5 request received from baovo@node2.supernodexp.hpc, sock=16
05/02/2018 09:35:51;0100;Server@node2;Job;13301.node2.supernodexp.hpc;enqueuing into workq, state 1 hop 1
05/02/2018 09:35:51;0008;Server@node2;Job;13301.node2.supernodexp.hpc;Job Queued at request of baovo@node2.supernodexp.hpc, owner = baovo@node2.supernodexp.hpc, job name = lu-decomp-100000-mem10, queue = workq
05/02/2018 09:35:51;0100;Server@node2;Req;;Type 1 request received from baovo@node2.supernodexp.hpc, sock=16
05/02/2018 09:35:51;0100;Server@node2;Req;;Type 3 request received from baovo@node2.supernodexp.hpc, sock=16
05/02/2018 09:35:51;0100;Server@node2;Req;;Type 5 request received from baovo@node2.supernodexp.hpc, sock=16
05/02/2018 09:35:51;0100;Server@node2;Job;13302.node2.supernodexp.hpc;enqueuing into workq, state 1 hop 1
05/02/2018 09:35:51;0008;Server@node2;Job;13302.node2.supernodexp.hpc;Job Queued at request of baovo@node2.supernodexp.hpc, owner = baovo@node2.supernodexp.hpc, job name = lu-decomp-100000-mem10, queue = workq
05/02/2018 09:35:51;0100;Server@node2;Req;;Type 20 request received from Scheduler@node2.supernodexp.hpc, sock=19
05/02/2018 09:35:51;0100;Server@node2;Req;;Type 51 request received from Scheduler@node2.supernodexp.hpc, sock=19
05/02/2018 09:35:51;0100;Server@node2;Req;;Type 11 request received from Scheduler@node2.supernodexp.hpc, sock=19
05/02/2018 09:35:51;0008;Server@node2;Job;13301.node2.supernodexp.hpc;Job Modified at request of Scheduler@node2.supernodexp.hpc
05/02/2018 09:35:51;0100;Server@node2;Req;;Type 11 request received from Scheduler@node2.supernodexp.hpc, sock=19
05/02/2018 09:35:51;0008;Server@node2;Job;13302.node2.supernodexp.hpc;Job Modified at request of Scheduler@node2.supernodexp.hpc
05/02/2018 09:35:51;0100;Server@node2;Req;;Type 11 request received from Scheduler@node2.supernodexp.hpc, sock=19
05/02/2018 09:35:51;0008;Server@node2;Job;13299.node2.supernodexp.hpc;Job Modified at request of Scheduler@node2.supernodexp.hpc
05/02/2018 09:35:51;0100;Server@node2;Req;;Type 11 request received from Scheduler@node2.supernodexp.hpc, sock=19
05/02/2018 09:35:51;0008;Server@node2;Job;13300.node2.supernodexp.hpc;Job Modified at request of Scheduler@node2.supernodexp.hpc
05/02/2018 09:35:51;0040;Server@node2;Svr;node2.supernodexp.hpc;Scheduler sent command 1
05/02/2018 09:35:51;0040;Server@node2;Svr;node2.supernodexp.hpc;Scheduler sent command 0
05/02/2018 09:35:51;0100;Server@node2;Req;;Type 21 request received from Scheduler@node2.supernodexp.hpc, sock=19
05/02/2018 09:35:51;0100;Server@node2;Req;;Type 81 request received from Scheduler@node2.supernodexp.hpc, sock=19
05/02/2018 09:35:51;0100;Server@node2;Req;;Type 71 request received from Scheduler@node2.supernodexp.hpc, sock=19
05/02/2018 09:35:51;0100;Server@node2;Req;;Type 58 request received from Scheduler@node2.supernodexp.hpc, sock=19
05/02/2018 09:35:51;0100;Server@node2;Req;;Type 20 request received from Scheduler@node2.supernodexp.hpc, sock=19
05/02/2018 09:35:51;0100;Server@node2;Req;;Type 51 request received from Scheduler@node2.supernodexp.hpc, sock=19
05/02/2018 09:35:53;0080;Server@node2;Job;13286.node2.supernodexp.hpc;Obit received momhop:1 serverhop:1 state:4 substate:42
05/02/2018 09:35:54;0010;Server@node2;Job;13286.node2.supernodexp.hpc;Exit_status=0 resources_used.cpupercent=0 resources_used.cput=00:00:00 resources_used.mem=9084kb resources_used.ncpus=4 resources_used.vmem=105760kb resources_used.walltime=00:00:28
05/02/2018 09:35:54;0100;Server@node2;Job;13286.node2.supernodexp.hpc;dequeuing from workq, state 5
05/02/2018 09:35:54;0040;Server@node2;Svr;node2.supernodexp.hpc;Scheduler sent command 2
05/02/2018 09:35:54;0040;Server@node2;Svr;node2.supernodexp.hpc;Scheduler sent command 0
05/02/2018 09:35:54;0100;Server@node2;Req;;Type 21 request received from Scheduler@node2.supernodexp.hpc, sock=19
05/02/2018 09:35:54;0100;Server@node2;Req;;Type 81 request received from Scheduler@node2.supernodexp.hpc, sock=19
05/02/2018 09:35:54;0100;Server@node2;Req;;Type 71 request received from Scheduler@node2.supernodexp.hpc, sock=19
05/02/2018 09:35:54;0100;Server@node2;Req;;Type 58 request received from Scheduler@node2.supernodexp.hpc, sock=19
05/02/2018 09:35:54;0100;Server@node2;Req;;Type 20 request received from Scheduler@node2.supernodexp.hpc, sock=19
05/02/2018 09:35:54;0100;Server@node2;Req;;Type 51 request received from Scheduler@node2.supernodexp.hpc, sock=19
05/02/2018 09:35:54;0100;Server@node2;Req;;Type 11 request received from Scheduler@node2.supernodexp.hpc, sock=19
05/02/2018 09:35:54;0008;Server@node2;Job;13298.node2.supernodexp.hpc;Job Modified at request of Scheduler@node2.supernodexp.hpc
05/02/2018 09:35:55;0100;Server@node2;Req;;Type 1 request received from baovo@node2.supernodexp.hpc, sock=16
05/02/2018 09:35:55;0100;Server@node2;Req;;Type 3 request received from baovo@node2.supernodexp.hpc, sock=16
05/02/2018 09:35:55;0100;Server@node2;Req;;Type 5 request received from baovo@node2.supernodexp.hpc, sock=16
05/02/2018 09:35:55;0100;Server@node2;Job;13303.node2.supernodexp.hpc;enqueuing into workq, state 1 hop 1
05/02/2018 09:35:55;0008;Server@node2;Job;13303.node2.supernodexp.hpc;Job Queued at request of baovo@node2.supernodexp.hpc, owner = baovo@node2.supernodexp.hpc, job name = mkl-20000, queue = workq
05/02/2018 09:35:55;0040;Server@node2;Svr;node2.supernodexp.hpc;Scheduler sent command 1
05/02/2018 09:35:55;0040;Server@node2;Svr;node2.supernodexp.hpc;Scheduler sent command 0
05/02/2018 09:35:55;0100;Server@node2;Req;;Type 21 request received from Scheduler@node2.supernodexp.hpc, sock=19
05/02/2018 09:35:55;0100;Server@node2;Req;;Type 81 request received from Scheduler@node2.supernodexp.hpc, sock=19
05/02/2018 09:35:55;0100;Server@node2;Req;;Type 71 request received from Scheduler@node2.supernodexp.hpc, sock=19
05/02/2018 09:35:55;0100;Server@node2;Req;;Type 58 request received from Scheduler@node2.supernodexp.hpc, sock=19
05/02/2018 09:35:55;0100;Server@node2;Req;;Type 20 request received from Scheduler@node2.supernodexp.hpc, sock=19
05/02/2018 09:35:55;0100;Server@node2;Req;;Type 51 request received from Scheduler@node2.supernodexp.hpc, sock=19
05/02/2018 09:35:55;0100;Server@node2;Req;;Type 11 request received from Scheduler@node2.supernodexp.hpc, sock=19
05/02/2018 09:35:55;0008;Server@node2;Job;13303.node2.supernodexp.hpc;Job Modified at request of Scheduler@node2.supernodexp.hpc
05/02/2018 09:35:59;0100;Server@node2;Req;;Type 1 request received from baovo@node2.supernodexp.hpc, sock=16
05/02/2018 09:35:59;0100;Server@node2;Req;;Type 3 request received from baovo@node2.supernodexp.hpc, sock=16
05/02/2018 09:35:59;0100;Server@node2;Req;;Type 5 request received from baovo@node2.supernodexp.hpc, sock=16
05/02/2018 09:35:59;0100;Server@node2;Job;13304.node2.supernodexp.hpc;enqueuing into workq, state 1 hop 1
05/02/2018 09:35:59;0008;Server@node2;Job;13304.node2.supernodexp.hpc;Job Queued at request of baovo@node2.supernodexp.hpc, owner = baovo@node2.supernodexp.hpc, job name = qe_mic_test, queue = workq
05/02/2018 09:35:59;0040;Server@node2;Svr;node2.supernodexp.hpc;Scheduler sent command 1
05/02/2018 09:35:59;0040;Server@node2;Svr;node2.supernodexp.hpc;Scheduler sent command 0
05/02/2018 09:35:59;0100;Server@node2;Req;;Type 21 request received from Scheduler@node2.supernodexp.hpc, sock=19
05/02/2018 09:35:59;0100;Server@node2;Req;;Type 81 request received from Scheduler@node2.supernodexp.hpc, sock=19
05/02/2018 09:35:59;0100;Server@node2;Req;;Type 71 request received from Scheduler@node2.supernodexp.hpc, sock=19
05/02/2018 09:35:59;0100;Server@node2;Req;;Type 58 request received from Scheduler@node2.supernodexp.hpc, sock=19
05/02/2018 09:35:59;0100;Server@node2;Req;;Type 20 request received from Scheduler@node2.supernodexp.hpc, sock=19
05/02/2018 09:35:59;0100;Server@node2;Req;;Type 51 request received from Scheduler@node2.supernodexp.hpc, sock=19
05/02/2018 09:35:59;0100;Server@node2;Req;;Type 11 request received from Scheduler@node2.supernodexp.hpc, sock=19
05/02/2018 09:35:59;0008;Server@node2;Job;13304.node2.supernodexp.hpc;Job Modified at request of Scheduler@node2.supernodexp.hpc
05/02/2018 09:36:00;0100;Server@node2;Req;;Type 1 request received from baovo@node2.supernodexp.hpc, sock=16
05/02/2018 09:36:00;0100;Server@node2;Req;;Type 3 request received from baovo@node2.supernodexp.hpc, sock=16
05/02/2018 09:36:00;0100;Server@node2;Req;;Type 5 request received from baovo@node2.supernodexp.hpc, sock=16
05/02/2018 09:36:00;0100;Server@node2;Job;13305.node2.supernodexp.hpc;enqueuing into workq, state 1 hop 1
05/02/2018 09:36:00;0008;Server@node2;Job;13305.node2.supernodexp.hpc;Job Queued at request of baovo@node2.supernodexp.hpc, owner = baovo@node2.supernodexp.hpc, job name = nbody-700000, queue = workq
05/02/2018 09:36:00;0040;Server@node2;Svr;node2.supernodexp.hpc;Scheduler sent command 1
05/02/2018 09:36:00;0040;Server@node2;Svr;node2.supernodexp.hpc;Scheduler sent command 0
05/02/2018 09:36:00;0100;Server@node2;Req;;Type 21 request received from Scheduler@node2.supernodexp.hpc, sock=19
05/02/2018 09:36:00;0100;Server@node2;Req;;Type 81 request received from Scheduler@node2.supernodexp.hpc, sock=19
05/02/2018 09:36:00;0100;Server@node2;Req;;Type 71 request received from Scheduler@node2.supernodexp.hpc, sock=19
05/02/2018 09:36:00;0100;Server@node2;Req;;Type 58 request received from Scheduler@node2.supernodexp.hpc, sock=19
05/02/2018 09:36:00;0100;Server@node2;Req;;Type 1 request received from baovo@node2.supernodexp.hpc, sock=16
05/02/2018 09:36:00;0100;Server@node2;Req;;Type 3 request received from baovo@node2.supernodexp.hpc, sock=16
05/02/2018 09:36:00;0100;Server@node2;Req;;Type 5 request received from baovo@node2.supernodexp.hpc, sock=16
05/02/2018 09:36:00;0100;Server@node2;Job;13306.node2.supernodexp.hpc;enqueuing into workq, state 1 hop 1
05/02/2018 09:36:00;0008;Server@node2;Job;13306.node2.supernodexp.hpc;Job Queued at request of baovo@node2.supernodexp.hpc, owner = baovo@node2.supernodexp.hpc, job name = qe_mic_test, queue = workq
05/02/2018 09:36:00;0100;Server@node2;Req;;Type 20 request received from Scheduler@node2.supernodexp.hpc, sock=19
05/02/2018 09:36:00;0100;Server@node2;Req;;Type 51 request received from Scheduler@node2.supernodexp.hpc, sock=19
05/02/2018 09:36:00;0100;Server@node2;Req;;Type 11 request received from Scheduler@node2.supernodexp.hpc, sock=19
05/02/2018 09:36:00;0008;Server@node2;Job;13305.node2.supernodexp.hpc;Job Modified at request of Scheduler@node2.supernodexp.hpc
05/02/2018 09:36:00;0100;Server@node2;Req;;Type 11 request received from Scheduler@node2.supernodexp.hpc, sock=19
05/02/2018 09:36:00;0008;Server@node2;Job;13306.node2.supernodexp.hpc;Job Modified at request of Scheduler@node2.supernodexp.hpc
05/02/2018 09:36:00;0040;Server@node2;Svr;node2.supernodexp.hpc;Scheduler sent command 1
05/02/2018 09:36:00;0040;Server@node2;Svr;node2.supernodexp.hpc;Scheduler sent command 0
05/02/2018 09:36:00;0100;Server@node2;Req;;Type 21 request received from Scheduler@node2.supernodexp.hpc, sock=19
05/02/2018 09:36:00;0100;Server@node2;Req;;Type 81 request received from Scheduler@node2.supernodexp.hpc, sock=19
05/02/2018 09:36:00;0100;Server@node2;Req;;Type 71 request received from Scheduler@node2.supernodexp.hpc, sock=19
05/02/2018 09:36:00;0100;Server@node2;Req;;Type 58 request received from Scheduler@node2.supernodexp.hpc, sock=19
05/02/2018 09:36:00;0100;Server@node2;Req;;Type 20 request received from Scheduler@node2.supernodexp.hpc, sock=19
05/02/2018 09:36:00;0100;Server@node2;Req;;Type 51 request received from Scheduler@node2.supernodexp.hpc, sock=19
05/02/2018 09:36:01;0080;Server@node2;Job;13287.node2.supernodexp.hpc;Obit received momhop:1 serverhop:1 state:4 substate:42
05/02/2018 09:36:02;0010;Server@node2;Job;13287.node2.supernodexp.hpc;Exit_status=0 resources_used.cpupercent=0 resources_used.cput=00:00:00 resources_used.mem=9408kb resources_used.ncpus=8 resources_used.vmem=102576kb resources_used.walltime=00:00:34
05/02/2018 09:36:02;0100;Server@node2;Job;13287.node2.supernodexp.hpc;dequeuing from workq, state 5
05/02/2018 09:36:02;0040;Server@node2;Svr;node2.supernodexp.hpc;Scheduler sent command 2
05/02/2018 09:36:02;0040;Server@node2;Svr;node2.supernodexp.hpc;Scheduler sent command 0
05/02/2018 09:36:02;0100;Server@node2;Req;;Type 21 request received from Scheduler@node2.supernodexp.hpc, sock=19
05/02/2018 09:36:02;0100;Server@node2;Req;;Type 81 request received from Scheduler@node2.supernodexp.hpc, sock=19
05/02/2018 09:36:02;0100;Server@node2;Req;;Type 71 request received from Scheduler@node2.supernodexp.hpc, sock=19
05/02/2018 09:36:02;0100;Server@node2;Req;;Type 58 request received from Scheduler@node2.supernodexp.hpc, sock=19
05/02/2018 09:36:02;0100;Server@node2;Req;;Type 20 request received from Scheduler@node2.supernodexp.hpc, sock=19
05/02/2018 09:36:02;0100;Server@node2;Req;;Type 51 request received from Scheduler@node2.supernodexp.hpc, sock=19
05/02/2018 09:36:02;0100;Server@node2;Req;;Type 23 request received from Scheduler@node2.supernodexp.hpc, sock=19
05/02/2018 09:36:02;0008;Server@node2;Job;13298.node2.supernodexp.hpc;Job Run at request of Scheduler@node2.supernodexp.hpc on exec_vnode (node13:ncpus=8:mem=10485760kb)
05/02/2018 09:36:02;0001;Server@node2;Svr;Server@node2;Success (0) in req_runjob2, return value of svr_startjob is 0
05/02/2018 09:36:02;0100;Server@node2;Req;;Type 11 request received from Scheduler@node2.supernodexp.hpc, sock=19
05/02/2018 09:36:02;0008;Server@node2;Job;13301.node2.supernodexp.hpc;Job Modified at request of Scheduler@node2.supernodexp.hpc
05/02/2018 09:36:08;0080;Server@node2;Job;13285.node2.supernodexp.hpc;Obit received momhop:1 serverhop:1 state:4 substate:42
05/02/2018 09:36:09;0010;Server@node2;Job;13285.node2.supernodexp.hpc;Exit_status=0 resources_used.cpupercent=0 resources_used.cput=00:00:00 resources_used.mem=9340kb resources_used.ncpus=8 resources_used.vmem=35448kb resources_used.walltime=00:00:43
05/02/2018 09:36:09;0100;Server@node2;Job;13285.node2.supernodexp.hpc;dequeuing from workq, state 5
05/02/2018 09:36:09;0040;Server@node2;Svr;node2.supernodexp.hpc;Scheduler sent command 2
05/02/2018 09:36:09;0040;Server@node2;Svr;node2.supernodexp.hpc;Scheduler sent command 0
05/02/2018 09:36:09;0100;Server@node2;Req;;Type 21 request received from Scheduler@node2.supernodexp.hpc, sock=19
05/02/2018 09:36:09;0100;Server@node2;Req;;Type 81 request received from Scheduler@node2.supernodexp.hpc, sock=19
05/02/2018 09:36:09;0100;Server@node2;Req;;Type 71 request received from Scheduler@node2.supernodexp.hpc, sock=19
05/02/2018 09:36:09;0100;Server@node2;Req;;Type 58 request received from Scheduler@node2.supernodexp.hpc, sock=19
05/02/2018 09:36:09;0100;Server@node2;Req;;Type 20 request received from Scheduler@node2.supernodexp.hpc, sock=19
05/02/2018 09:36:09;0100;Server@node2;Req;;Type 51 request received from Scheduler@node2.supernodexp.hpc, sock=19
05/02/2018 09:36:09;0100;Server@node2;Req;;Type 23 request received from Scheduler@node2.supernodexp.hpc, sock=19
05/02/2018 09:36:09;0008;Server@node2;Job;13301.node2.supernodexp.hpc;Job Run at request of Scheduler@node2.supernodexp.hpc on exec_vnode (node3:ncpus=8:mem=10485760kb)
05/02/2018 09:36:09;0001;Server@node2;Svr;Server@node2;Success (0) in req_runjob2, return value of svr_startjob is 0
05/02/2018 09:36:09;0100;Server@node2;Req;;Type 11 request received from Scheduler@node2.supernodexp.hpc, sock=19
05/02/2018 09:36:09;0008;Server@node2;Job;13302.node2.supernodexp.hpc;Job Modified at request of Scheduler@node2.supernodexp.hpc
05/02/2018 09:36:24;0080;Server@node2;Job;13271.node2.supernodexp.hpc;Obit received momhop:1 serverhop:1 state:4 substate:42
05/02/2018 09:36:25;0010;Server@node2;Job;13271.node2.supernodexp.hpc;Exit_status=271 resources_used.cpupercent=0 resources_used.cput=00:00:00 resources_used.mem=9104kb resources_used.ncpus=8 resources_used.vmem=105088kb resources_used.walltime=00:06:57
05/02/2018 09:36:25;0100;Server@node2;Job;13271.node2.supernodexp.hpc;dequeuing from workq, state 5
05/02/2018 09:36:25;0040;Server@node2;Svr;node2.supernodexp.hpc;Scheduler sent command 2
05/02/2018 09:36:25;0040;Server@node2;Svr;node2.supernodexp.hpc;Scheduler sent command 0
05/02/2018 09:36:25;0100;Server@node2;Req;;Type 21 request received from Scheduler@node2.supernodexp.hpc, sock=19
05/02/2018 09:36:25;0100;Server@node2;Req;;Type 81 request received from Scheduler@node2.supernodexp.hpc, sock=19
05/02/2018 09:36:25;0100;Server@node2;Req;;Type 71 request received from Scheduler@node2.supernodexp.hpc, sock=19
05/02/2018 09:36:25;0100;Server@node2;Req;;Type 58 request received from Scheduler@node2.supernodexp.hpc, sock=19
05/02/2018 09:36:25;0100;Server@node2;Req;;Type 20 request received from Scheduler@node2.supernodexp.hpc, sock=19
05/02/2018 09:36:25;0100;Server@node2;Req;;Type 51 request received from Scheduler@node2.supernodexp.hpc, sock=19
05/02/2018 09:36:25;0100;Server@node2;Req;;Type 23 request received from Scheduler@node2.supernodexp.hpc, sock=19
05/02/2018 09:36:25;0008;Server@node2;Job;13302.node2.supernodexp.hpc;Job Run at request of Scheduler@node2.supernodexp.hpc on exec_vnode (node3:ncpus=8:mem=10485760kb)
05/02/2018 09:36:25;0001;Server@node2;Svr;Server@node2;Success (0) in req_runjob2, return value of svr_startjob is 0
05/02/2018 09:36:25;0100;Server@node2;Req;;Type 23 request received from Scheduler@node2.supernodexp.hpc, sock=19
05/02/2018 09:36:25;0008;Server@node2;Job;13299.node2.supernodexp.hpc;Job Run at request of Scheduler@node2.supernodexp.hpc on exec_vnode (node3:nmics=2:ncpus=2:mem=41943040kb)
05/02/2018 09:36:25;0001;Server@node2;Svr;Server@node2;Success (0) in req_runjob2, return value of svr_startjob is 0
05/02/2018 09:36:25;0100;Server@node2;Req;;Type 11 request received from Scheduler@node2.supernodexp.hpc, sock=19
05/02/2018 09:36:25;0008;Server@node2;Job;13300.node2.supernodexp.hpc;Job Modified at request of Scheduler@node2.supernodexp.hpc
05/02/2018 09:36:26;0080;Server@node2;Job;13297.node2.supernodexp.hpc;Obit received momhop:1 serverhop:1 state:4 substate:42
05/02/2018 09:36:27;0010;Server@node2;Job;13297.node2.supernodexp.hpc;Exit_status=0 resources_used.cpupercent=0 resources_used.cput=00:00:00 resources_used.mem=9192kb resources_used.ncpus=8 resources_used.vmem=173368kb resources_used.walltime=00:00:37
05/02/2018 09:36:27;0100;Server@node2;Job;13297.node2.supernodexp.hpc;dequeuing from workq, state 5
05/02/2018 09:36:27;0040;Server@node2;Svr;node2.supernodexp.hpc;Scheduler sent command 2
05/02/2018 09:36:27;0040;Server@node2;Svr;node2.supernodexp.hpc;Scheduler sent command 0
05/02/2018 09:36:27;0100;Server@node2;Req;;Type 21 request received from Scheduler@node2.supernodexp.hpc, sock=19
05/02/2018 09:36:27;0100;Server@node2;Req;;Type 81 request received from Scheduler@node2.supernodexp.hpc, sock=19
05/02/2018 09:36:27;0100;Server@node2;Req;;Type 71 request received from Scheduler@node2.supernodexp.hpc, sock=19
05/02/2018 09:36:27;0100;Server@node2;Req;;Type 58 request received from Scheduler@node2.supernodexp.hpc, sock=19
05/02/2018 09:36:27;0100;Server@node2;Req;;Type 20 request received from Scheduler@node2.supernodexp.hpc, sock=19
05/02/2018 09:36:27;0100;Server@node2;Req;;Type 51 request received from Scheduler@node2.supernodexp.hpc, sock=19
05/02/2018 09:36:27;0100;Server@node2;Req;;Type 23 request received from Scheduler@node2.supernodexp.hpc, sock=19
05/02/2018 09:36:27;0008;Server@node2;Job;13300.node2.supernodexp.hpc;Job Run at request of Scheduler@node2.supernodexp.hpc on exec_vnode (node13:nmics=2:ncpus=2:mem=41943040kb)
05/02/2018 09:36:27;0001;Server@node2;Svr;Server@node2;Success (0) in req_runjob2, return value of svr_startjob is 0
05/02/2018 09:36:27;0100;Server@node2;Req;;Type 11 request received from Scheduler@node2.supernodexp.hpc, sock=19
05/02/2018 09:36:27;0008;Server@node2;Job;13294.node2.supernodexp.hpc;Job Modified at request of Scheduler@node2.supernodexp.hpc
05/02/2018 09:36:38;0080;Server@node2;Job;13298.node2.supernodexp.hpc;Obit received momhop:1 serverhop:1 state:4 substate:42
05/02/2018 09:36:39;0010;Server@node2;Job;13298.node2.supernodexp.hpc;Exit_status=0 resources_used.cpupercent=0 resources_used.cput=00:00:00 resources_used.mem=9392kb resources_used.ncpus=8 resources_used.vmem=171960kb resources_used.walltime=00:00:36
05/02/2018 09:36:39;0100;Server@node2;Job;13298.node2.supernodexp.hpc;dequeuing from workq, state 5
05/02/2018 09:36:39;0040;Server@node2;Svr;node2.supernodexp.hpc;Scheduler sent command 2
05/02/2018 09:36:39;0040;Server@node2;Svr;node2.supernodexp.hpc;Scheduler sent command 0
05/02/2018 09:36:39;0100;Server@node2;Req;;Type 21 request received from Scheduler@node2.supernodexp.hpc, sock=19
05/02/2018 09:36:39;0100;Server@node2;Req;;Type 81 request received from Scheduler@node2.supernodexp.hpc, sock=19
05/02/2018 09:36:39;0100;Server@node2;Req;;Type 71 request received from Scheduler@node2.supernodexp.hpc, sock=19
05/02/2018 09:36:39;0100;Server@node2;Req;;Type 58 request received from Scheduler@node2.supernodexp.hpc, sock=19
05/02/2018 09:36:39;0100;Server@node2;Req;;Type 20 request received from Scheduler@node2.supernodexp.hpc, sock=19
05/02/2018 09:36:39;0100;Server@node2;Req;;Type 51 request received from Scheduler@node2.supernodexp.hpc, sock=19
05/02/2018 09:36:39;0100;Server@node2;Req;;Type 11 request received from Scheduler@node2.supernodexp.hpc, sock=19
05/02/2018 09:36:39;0008;Server@node2;Job;13294.node2.supernodexp.hpc;Job Modified at request of Scheduler@node2.supernodexp.hpc
05/02/2018 09:36:52;0080;Server@node2;Job;13301.node2.supernodexp.hpc;Obit received momhop:1 serverhop:1 state:4 substate:42
05/02/2018 09:36:53;0010;Server@node2;Job;13301.node2.supernodexp.hpc;Exit_status=0 resources_used.cpupercent=0 resources_used.cput=00:00:00 resources_used.mem=9096kb resources_used.ncpus=8 resources_used.vmem=172288kb resources_used.walltime=00:00:43
05/02/2018 09:36:53;0100;Server@node2;Job;13301.node2.supernodexp.hpc;dequeuing from workq, state 5
05/02/2018 09:36:53;0040;Server@node2;Svr;node2.supernodexp.hpc;Scheduler sent command 2
05/02/2018 09:36:53;0040;Server@node2;Svr;node2.supernodexp.hpc;Scheduler sent command 0
05/02/2018 09:36:53;0100;Server@node2;Req;;Type 21 request received from Scheduler@node2.supernodexp.hpc, sock=19
05/02/2018 09:36:53;0100;Server@node2;Req;;Type 81 request received from Scheduler@node2.supernodexp.hpc, sock=19
05/02/2018 09:36:53;0100;Server@node2;Req;;Type 71 request received from Scheduler@node2.supernodexp.hpc, sock=19
05/02/2018 09:36:53;0100;Server@node2;Req;;Type 58 request received from Scheduler@node2.supernodexp.hpc, sock=19
05/02/2018 09:36:53;0100;Server@node2;Req;;Type 20 request received from Scheduler@node2.supernodexp.hpc, sock=19
05/02/2018 09:36:53;0100;Server@node2;Req;;Type 51 request received from Scheduler@node2.supernodexp.hpc, sock=19
05/02/2018 09:36:53;0100;Server@node2;Req;;Type 11 request received from Scheduler@node2.supernodexp.hpc, sock=19
05/02/2018 09:36:53;0008;Server@node2;Job;13294.node2.supernodexp.hpc;Job Modified at request of Scheduler@node2.supernodexp.hpc
05/02/2018 09:37:09;0080;Server@node2;Job;13302.node2.supernodexp.hpc;Obit received momhop:1 serverhop:1 state:4 substate:42
05/02/2018 09:37:10;0010;Server@node2;Job;13302.node2.supernodexp.hpc;Exit_status=0 resources_used.cpupercent=0 resources_used.cput=00:00:00 resources_used.mem=9328kb resources_used.ncpus=8 resources_used.vmem=172288kb resources_used.walltime=00:00:44
05/02/2018 09:37:10;0100;Server@node2;Job;13302.node2.supernodexp.hpc;dequeuing from workq, state 5
05/02/2018 09:37:10;0040;Server@node2;Svr;node2.supernodexp.hpc;Scheduler sent command 2
05/02/2018 09:37:10;0040;Server@node2;Svr;node2.supernodexp.hpc;Scheduler sent command 0
05/02/2018 09:37:10;0100;Server@node2;Req;;Type 21 request received from Scheduler@node2.supernodexp.hpc, sock=16
05/02/2018 09:37:10;0100;Server@node2;Req;;Type 81 request received from Scheduler@node2.supernodexp.hpc, sock=16
05/02/2018 09:37:10;0100;Server@node2;Req;;Type 71 request received from Scheduler@node2.supernodexp.hpc, sock=16
05/02/2018 09:37:10;0100;Server@node2;Req;;Type 58 request received from Scheduler@node2.supernodexp.hpc, sock=16
05/02/2018 09:37:10;0100;Server@node2;Req;;Type 20 request received from Scheduler@node2.supernodexp.hpc, sock=16
05/02/2018 09:37:10;0100;Server@node2;Req;;Type 51 request received from Scheduler@node2.supernodexp.hpc, sock=16
05/02/2018 09:38:17;0080;Server@node2;Job;13299.node2.supernodexp.hpc;Obit received momhop:1 serverhop:1 state:4 substate:42
05/02/2018 09:38:18;0010;Server@node2;Job;13299.node2.supernodexp.hpc;Exit_status=0 resources_used.cpupercent=0 resources_used.cput=00:00:00 resources_used.mem=9092kb resources_used.ncpus=2 resources_used.vmem=103036kb resources_used.walltime=00:01:52
05/02/2018 09:38:18;0100;Server@node2;Job;13299.node2.supernodexp.hpc;dequeuing from workq, state 5
05/02/2018 09:38:18;0040;Server@node2;Svr;node2.supernodexp.hpc;Scheduler sent command 2
05/02/2018 09:38:18;0040;Server@node2;Svr;node2.supernodexp.hpc;Scheduler sent command 0
05/02/2018 09:38:18;0100;Server@node2;Req;;Type 21 request received from Scheduler@node2.supernodexp.hpc, sock=16
05/02/2018 09:38:18;0100;Server@node2;Req;;Type 81 request received from Scheduler@node2.supernodexp.hpc, sock=16
05/02/2018 09:38:18;0100;Server@node2;Req;;Type 71 request received from Scheduler@node2.supernodexp.hpc, sock=16
05/02/2018 09:38:18;0100;Server@node2;Req;;Type 58 request received from Scheduler@node2.supernodexp.hpc, sock=16
05/02/2018 09:38:18;0100;Server@node2;Req;;Type 20 request received from Scheduler@node2.supernodexp.hpc, sock=16
05/02/2018 09:38:18;0100;Server@node2;Req;;Type 51 request received from Scheduler@node2.supernodexp.hpc, sock=16
05/02/2018 09:38:21;0080;Server@node2;Job;13300.node2.supernodexp.hpc;Obit received momhop:1 serverhop:1 state:4 substate:42
05/02/2018 09:38:22;0010;Server@node2;Job;13300.node2.supernodexp.hpc;Exit_status=0 resources_used.cpupercent=0 resources_used.cput=00:00:00 resources_used.mem=9624kb resources_used.ncpus=2 resources_used.vmem=172216kb resources_used.walltime=00:01:54
05/02/2018 09:38:22;0100;Server@node2;Job;13300.node2.supernodexp.hpc;dequeuing from workq, state 5
05/02/2018 09:38:22;0040;Server@node2;Svr;node2.supernodexp.hpc;Scheduler sent command 2
05/02/2018 09:38:22;0040;Server@node2;Svr;node2.supernodexp.hpc;Scheduler sent command 0
05/02/2018 09:38:22;0100;Server@node2;Req;;Type 21 request received from Scheduler@node2.supernodexp.hpc, sock=16
05/02/2018 09:38:22;0100;Server@node2;Req;;Type 81 request received from Scheduler@node2.supernodexp.hpc, sock=16
05/02/2018 09:38:22;0100;Server@node2;Req;;Type 71 request received from Scheduler@node2.supernodexp.hpc, sock=16
05/02/2018 09:38:22;0100;Server@node2;Req;;Type 58 request received from Scheduler@node2.supernodexp.hpc, sock=16
05/02/2018 09:38:22;0100;Server@node2;Req;;Type 20 request received from Scheduler@node2.supernodexp.hpc, sock=16
05/02/2018 09:38:22;0100;Server@node2;Req;;Type 51 request received from Scheduler@node2.supernodexp.hpc, sock=16
05/02/2018 09:40:16;0100;Server@node2;Req;;Type 0 request received from baovo@node2.supernodexp.hpc, sock=16
05/02/2018 09:40:16;0100;Server@node2;Req;;Type 49 request received from baovo@node2.supernodexp.hpc, sock=19
05/02/2018 09:40:16;0100;Server@node2;Req;;Type 21 request received from baovo@node2.supernodexp.hpc, sock=16
05/02/2018 09:40:16;0100;Server@node2;Req;;Type 1 request received from baovo@node2.supernodexp.hpc, sock=16
05/02/2018 09:40:16;0100;Server@node2;Req;;Type 3 request received from baovo@node2.supernodexp.hpc, sock=16
05/02/2018 09:40:16;0100;Server@node2;Req;;Type 5 request received from baovo@node2.supernodexp.hpc, sock=16
05/02/2018 09:40:16;0100;Server@node2;Job;13307.node2.supernodexp.hpc;enqueuing into workq, state 1 hop 1
05/02/2018 09:40:16;0008;Server@node2;Job;13307.node2.supernodexp.hpc;Job Queued at request of baovo@node2.supernodexp.hpc, owner = baovo@node2.supernodexp.hpc, job name = vtune, queue = workq
05/02/2018 09:40:16;0040;Server@node2;Svr;node2.supernodexp.hpc;Scheduler sent command 1
05/02/2018 09:40:16;0040;Server@node2;Svr;node2.supernodexp.hpc;Scheduler sent command 0
05/02/2018 09:40:16;0100;Server@node2;Req;;Type 21 request received from Scheduler@node2.supernodexp.hpc, sock=19
05/02/2018 09:40:16;0100;Server@node2;Req;;Type 81 request received from Scheduler@node2.supernodexp.hpc, sock=19
05/02/2018 09:40:16;0100;Server@node2;Req;;Type 71 request received from Scheduler@node2.supernodexp.hpc, sock=19
05/02/2018 09:40:16;0100;Server@node2;Req;;Type 58 request received from Scheduler@node2.supernodexp.hpc, sock=19
05/02/2018 09:40:16;0100;Server@node2;Req;;Type 20 request received from Scheduler@node2.supernodexp.hpc, sock=19
05/02/2018 09:40:16;0100;Server@node2;Req;;Type 51 request received from Scheduler@node2.supernodexp.hpc, sock=19
05/02/2018 09:40:16;0100;Server@node2;Req;;Type 11 request received from Scheduler@node2.supernodexp.hpc, sock=19
05/02/2018 09:40:16;0008;Server@node2;Job;13307.node2.supernodexp.hpc;Job Modified at request of Scheduler@node2.supernodexp.hpc
05/02/2018 09:40:18;0080;Server@node2;Job;13284.node2.supernodexp.hpc;Obit received momhop:1 serverhop:1 state:4 substate:42
05/02/2018 09:40:18;0010;Server@node2;Job;13284.node2.supernodexp.hpc;Exit_status=0 resources_used.cpupercent=0 resources_used.cput=00:00:00 resources_used.mem=11460kb resources_used.ncpus=24 resources_used.vmem=104628kb resources_used.walltime=00:04:58
05/02/2018 09:40:18;0100;Server@node2;Job;13284.node2.supernodexp.hpc;dequeuing from workq, state 5
05/02/2018 09:40:18;0040;Server@node2;Svr;node2.supernodexp.hpc;Scheduler sent command 2
05/02/2018 09:40:18;0040;Server@node2;Svr;node2.supernodexp.hpc;Scheduler sent command 0
05/02/2018 09:40:18;0100;Server@node2;Req;;Type 21 request received from Scheduler@node2.supernodexp.hpc, sock=19
05/02/2018 09:40:18;0100;Server@node2;Req;;Type 81 request received from Scheduler@node2.supernodexp.hpc, sock=19
05/02/2018 09:40:18;0100;Server@node2;Req;;Type 71 request received from Scheduler@node2.supernodexp.hpc, sock=19
05/02/2018 09:40:18;0100;Server@node2;Req;;Type 58 request received from Scheduler@node2.supernodexp.hpc, sock=19
05/02/2018 09:40:18;0100;Server@node2;Req;;Type 20 request received from Scheduler@node2.supernodexp.hpc, sock=19
05/02/2018 09:40:18;0100;Server@node2;Req;;Type 51 request received from Scheduler@node2.supernodexp.hpc, sock=19
05/02/2018 09:40:18;0100;Server@node2;Req;;Type 23 request received from Scheduler@node2.supernodexp.hpc, sock=19
05/02/2018 09:40:18;0008;Server@node2;Job;13294.node2.supernodexp.hpc;Job Run at request of Scheduler@node2.supernodexp.hpc on exec_vnode (node14:ncpus=24:mem=5242880kb)
05/02/2018 09:40:18;0001;Server@node2;Svr;Server@node2;Success (0) in req_runjob2, return value of svr_startjob is 0
05/02/2018 09:40:18;0100;Server@node2;Req;;Type 11 request received from Scheduler@node2.supernodexp.hpc, sock=19
05/02/2018 09:40:18;0008;Server@node2;Job;13296.node2.supernodexp.hpc;Job Modified at request of Scheduler@node2.supernodexp.hpc
05/02/2018 09:41:01;0100;Server@node2;Req;;Type 1 request received from baovo@node2.supernodexp.hpc, sock=16
05/02/2018 09:41:01;0100;Server@node2;Req;;Type 3 request received from baovo@node2.supernodexp.hpc, sock=16
05/02/2018 09:41:01;0100;Server@node2;Req;;Type 5 request received from baovo@node2.supernodexp.hpc, sock=16
05/02/2018 09:41:01;0100;Server@node2;Job;13308.node2.supernodexp.hpc;enqueuing into workq, state 1 hop 1
05/02/2018 09:41:01;0008;Server@node2;Job;13308.node2.supernodexp.hpc;Job Queued at request of baovo@node2.supernodexp.hpc, owner = baovo@node2.supernodexp.hpc, job name = threading-misc-histogram, queue = workq
05/02/2018 09:41:01;0040;Server@node2;Svr;node2.supernodexp.hpc;Scheduler sent command 1
05/02/2018 09:41:01;0040;Server@node2;Svr;node2.supernodexp.hpc;Scheduler sent command 0
05/02/2018 09:41:01;0100;Server@node2;Req;;Type 21 request received from Scheduler@node2.supernodexp.hpc, sock=19
05/02/2018 09:41:01;0100;Server@node2;Req;;Type 81 request received from Scheduler@node2.supernodexp.hpc, sock=19
05/02/2018 09:41:01;0100;Server@node2;Req;;Type 71 request received from Scheduler@node2.supernodexp.hpc, sock=19
05/02/2018 09:41:01;0100;Server@node2;Req;;Type 58 request received from Scheduler@node2.supernodexp.hpc, sock=19
05/02/2018 09:41:01;0100;Server@node2;Req;;Type 20 request received from Scheduler@node2.supernodexp.hpc, sock=19
05/02/2018 09:41:01;0100;Server@node2;Req;;Type 51 request received from Scheduler@node2.supernodexp.hpc, sock=19
05/02/2018 09:41:01;0100;Server@node2;Req;;Type 23 request received from Scheduler@node2.supernodexp.hpc, sock=19
05/02/2018 09:41:01;0008;Server@node2;Job;13308.node2.supernodexp.hpc;Job Run at request of Scheduler@node2.supernodexp.hpc on exec_vnode (node3:ncpus=2:mem=2097152kb)
05/02/2018 09:41:01;0001;Server@node2;Svr;Server@node2;Success (0) in req_runjob2, return value of svr_startjob is 0
05/02/2018 09:41:06;0080;Server@node2;Job;13308.node2.supernodexp.hpc;Obit received momhop:1 serverhop:1 state:4 substate:42
05/02/2018 09:41:07;0010;Server@node2;Job;13308.node2.supernodexp.hpc;Exit_status=0 resources_used.cpupercent=0 resources_used.cput=00:00:00 resources_used.mem=0kb resources_used.ncpus=2 resources_used.vmem=0kb resources_used.walltime=00:00:05
05/02/2018 09:41:07;0100;Server@node2;Job;13308.node2.supernodexp.hpc;dequeuing from workq, state 5
05/02/2018 09:41:07;0040;Server@node2;Svr;node2.supernodexp.hpc;Scheduler sent command 2
05/02/2018 09:41:07;0040;Server@node2;Svr;node2.supernodexp.hpc;Scheduler sent command 0
05/02/2018 09:41:07;0100;Server@node2;Req;;Type 21 request received from Scheduler@node2.supernodexp.hpc, sock=19
05/02/2018 09:41:07;0100;Server@node2;Req;;Type 81 request received from Scheduler@node2.supernodexp.hpc, sock=19
05/02/2018 09:41:07;0100;Server@node2;Req;;Type 71 request received from Scheduler@node2.supernodexp.hpc, sock=19
05/02/2018 09:41:07;0100;Server@node2;Req;;Type 58 request received from Scheduler@node2.supernodexp.hpc, sock=19
05/02/2018 09:41:07;0100;Server@node2;Req;;Type 20 request received from Scheduler@node2.supernodexp.hpc, sock=19
05/02/2018 09:41:07;0100;Server@node2;Req;;Type 51 request received from Scheduler@node2.supernodexp.hpc, sock=19
05/02/2018 09:41:12;0100;Server@node2;Req;;Type 1 request received from baovo@node2.supernodexp.hpc, sock=16
05/02/2018 09:41:12;0100;Server@node2;Req;;Type 3 request received from baovo@node2.supernodexp.hpc, sock=16
05/02/2018 09:41:12;0100;Server@node2;Req;;Type 5 request received from baovo@node2.supernodexp.hpc, sock=16
05/02/2018 09:41:12;0100;Server@node2;Job;13309.node2.supernodexp.hpc;enqueuing into workq, state 1 hop 1
05/02/2018 09:41:12;0008;Server@node2;Job;13309.node2.supernodexp.hpc;Job Queued at request of baovo@node2.supernodexp.hpc, owner = baovo@node2.supernodexp.hpc, job name = benchmark-offload, queue = workq
05/02/2018 09:41:12;0040;Server@node2;Svr;node2.supernodexp.hpc;Scheduler sent command 1
05/02/2018 09:41:12;0040;Server@node2;Svr;node2.supernodexp.hpc;Scheduler sent command 0
05/02/2018 09:41:12;0100;Server@node2;Req;;Type 21 request received from Scheduler@node2.supernodexp.hpc, sock=19
05/02/2018 09:41:12;0100;Server@node2;Req;;Type 81 request received from Scheduler@node2.supernodexp.hpc, sock=19
05/02/2018 09:41:12;0100;Server@node2;Req;;Type 71 request received from Scheduler@node2.supernodexp.hpc, sock=19
05/02/2018 09:41:12;0100;Server@node2;Req;;Type 58 request received from Scheduler@node2.supernodexp.hpc, sock=19
05/02/2018 09:41:12;0100;Server@node2;Req;;Type 20 request received from Scheduler@node2.supernodexp.hpc, sock=19
05/02/2018 09:41:12;0100;Server@node2;Req;;Type 51 request received from Scheduler@node2.supernodexp.hpc, sock=19
05/02/2018 09:41:12;0100;Server@node2;Req;;Type 23 request received from Scheduler@node2.supernodexp.hpc, sock=19
05/02/2018 09:41:12;0008;Server@node2;Job;13309.node2.supernodexp.hpc;Job Run at request of Scheduler@node2.supernodexp.hpc on exec_vnode (node3:nmics=2:ncpus=2:mem=41943040kb)
05/02/2018 09:41:12;0001;Server@node2;Svr;Server@node2;Success (0) in req_runjob2, return value of svr_startjob is 0
05/02/2018 09:41:13;0100;Server@node2;Req;;Type 1 request received from baovo@node2.supernodexp.hpc, sock=16
05/02/2018 09:41:13;0100;Server@node2;Req;;Type 3 request received from baovo@node2.supernodexp.hpc, sock=16
05/02/2018 09:41:13;0100;Server@node2;Req;;Type 5 request received from baovo@node2.supernodexp.hpc, sock=16
05/02/2018 09:41:13;0100;Server@node2;Job;13310.node2.supernodexp.hpc;enqueuing into workq, state 1 hop 1
05/02/2018 09:41:13;0008;Server@node2;Job;13310.node2.supernodexp.hpc;Job Queued at request of baovo@node2.supernodexp.hpc, owner = baovo@node2.supernodexp.hpc, job name = lu-decomp-100000-mem10, queue = workq
05/02/2018 09:41:13;0040;Server@node2;Svr;node2.supernodexp.hpc;Scheduler sent command 1
05/02/2018 09:41:13;0040;Server@node2;Svr;node2.supernodexp.hpc;Scheduler sent command 0
05/02/2018 09:41:13;0100;Server@node2;Req;;Type 21 request received from Scheduler@node2.supernodexp.hpc, sock=19
05/02/2018 09:41:13;0100;Server@node2;Req;;Type 81 request received from Scheduler@node2.supernodexp.hpc, sock=19
05/02/2018 09:41:13;0100;Server@node2;Req;;Type 71 request received from Scheduler@node2.supernodexp.hpc, sock=19
05/02/2018 09:41:13;0100;Server@node2;Req;;Type 58 request received from Scheduler@node2.supernodexp.hpc, sock=19
05/02/2018 09:41:13;0100;Server@node2;Req;;Type 20 request received from Scheduler@node2.supernodexp.hpc, sock=19
05/02/2018 09:41:13;0100;Server@node2;Req;;Type 51 request received from Scheduler@node2.supernodexp.hpc, sock=19
05/02/2018 09:41:13;0100;Server@node2;Req;;Type 23 request received from Scheduler@node2.supernodexp.hpc, sock=19
05/02/2018 09:41:13;0008;Server@node2;Job;13310.node2.supernodexp.hpc;Job Run at request of Scheduler@node2.supernodexp.hpc on exec_vnode (node3:ncpus=8:mem=10485760kb)
05/02/2018 09:41:13;0001;Server@node2;Svr;Server@node2;Success (0) in req_runjob2, return value of svr_startjob is 0
05/02/2018 09:41:15;0100;Server@node2;Req;;Type 1 request received from baovo@node2.supernodexp.hpc, sock=16
05/02/2018 09:41:15;0100;Server@node2;Req;;Type 3 request received from baovo@node2.supernodexp.hpc, sock=16
05/02/2018 09:41:15;0100;Server@node2;Req;;Type 5 request received from baovo@node2.supernodexp.hpc, sock=16
05/02/2018 09:41:15;0100;Server@node2;Job;13311.node2.supernodexp.hpc;enqueuing into workq, state 1 hop 1
05/02/2018 09:41:15;0008;Server@node2;Job;13311.node2.supernodexp.hpc;Job Queued at request of baovo@node2.supernodexp.hpc, owner = baovo@node2.supernodexp.hpc, job name = benchmark-offload, queue = workq
05/02/2018 09:41:15;0040;Server@node2;Svr;node2.supernodexp.hpc;Scheduler sent command 1
05/02/2018 09:41:15;0040;Server@node2;Svr;node2.supernodexp.hpc;Scheduler sent command 0
05/02/2018 09:41:15;0100;Server@node2;Req;;Type 21 request received from Scheduler@node2.supernodexp.hpc, sock=19
05/02/2018 09:41:15;0100;Server@node2;Req;;Type 81 request received from Scheduler@node2.supernodexp.hpc, sock=19
05/02/2018 09:41:15;0100;Server@node2;Req;;Type 71 request received from Scheduler@node2.supernodexp.hpc, sock=19
05/02/2018 09:41:15;0100;Server@node2;Req;;Type 58 request received from Scheduler@node2.supernodexp.hpc, sock=19
05/02/2018 09:41:15;0100;Server@node2;Req;;Type 20 request received from Scheduler@node2.supernodexp.hpc, sock=19
05/02/2018 09:41:15;0100;Server@node2;Req;;Type 51 request received from Scheduler@node2.supernodexp.hpc, sock=19
05/02/2018 09:41:15;0100;Server@node2;Req;;Type 23 request received from Scheduler@node2.supernodexp.hpc, sock=19
05/02/2018 09:41:15;0008;Server@node2;Job;13311.node2.supernodexp.hpc;Job Run at request of Scheduler@node2.supernodexp.hpc on exec_vnode (node13:nmics=2:ncpus=2:mem=41943040kb)
05/02/2018 09:41:15;0001;Server@node2;Svr;Server@node2;Success (0) in req_runjob2, return value of svr_startjob is 0
05/02/2018 09:41:17;0100;Server@node2;Req;;Type 1 request received from baovo@node2.supernodexp.hpc, sock=16
05/02/2018 09:41:17;0100;Server@node2;Req;;Type 3 request received from baovo@node2.supernodexp.hpc, sock=16
05/02/2018 09:41:17;0100;Server@node2;Req;;Type 5 request received from baovo@node2.supernodexp.hpc, sock=16
05/02/2018 09:41:17;0100;Server@node2;Job;13312.node2.supernodexp.hpc;enqueuing into workq, state 1 hop 1
05/02/2018 09:41:17;0008;Server@node2;Job;13312.node2.supernodexp.hpc;Job Queued at request of baovo@node2.supernodexp.hpc, owner = baovo@node2.supernodexp.hpc, job name = benchmark-offload, queue = workq
05/02/2018 09:41:17;0040;Server@node2;Svr;node2.supernodexp.hpc;Scheduler sent command 1
05/02/2018 09:41:17;0040;Server@node2;Svr;node2.supernodexp.hpc;Scheduler sent command 0
05/02/2018 09:41:17;0100;Server@node2;Req;;Type 21 request received from Scheduler@node2.supernodexp.hpc, sock=19
05/02/2018 09:41:17;0100;Server@node2;Req;;Type 81 request received from Scheduler@node2.supernodexp.hpc, sock=19
05/02/2018 09:41:17;0100;Server@node2;Req;;Type 71 request received from Scheduler@node2.supernodexp.hpc, sock=19
05/02/2018 09:41:17;0100;Server@node2;Req;;Type 58 request received from Scheduler@node2.supernodexp.hpc, sock=19
05/02/2018 09:41:17;0100;Server@node2;Req;;Type 20 request received from Scheduler@node2.supernodexp.hpc, sock=19
05/02/2018 09:41:17;0100;Server@node2;Req;;Type 51 request received from Scheduler@node2.supernodexp.hpc, sock=19
05/02/2018 09:41:17;0100;Server@node2;Req;;Type 11 request received from Scheduler@node2.supernodexp.hpc, sock=19
05/02/2018 09:41:17;0008;Server@node2;Job;13296.node2.supernodexp.hpc;Job Modified at request of Scheduler@node2.supernodexp.hpc
05/02/2018 09:41:17;0100;Server@node2;Req;;Type 11 request received from Scheduler@node2.supernodexp.hpc, sock=19
05/02/2018 09:41:17;0008;Server@node2;Job;13312.node2.supernodexp.hpc;Job Modified at request of Scheduler@node2.supernodexp.hpc
05/02/2018 09:41:18;0100;Server@node2;Req;;Type 1 request received from baovo@node2.supernodexp.hpc, sock=16
05/02/2018 09:41:18;0100;Server@node2;Req;;Type 3 request received from baovo@node2.supernodexp.hpc, sock=16
05/02/2018 09:41:18;0100;Server@node2;Req;;Type 5 request received from baovo@node2.supernodexp.hpc, sock=16
05/02/2018 09:41:18;0100;Server@node2;Job;13313.node2.supernodexp.hpc;enqueuing into workq, state 1 hop 1
05/02/2018 09:41:18;0008;Server@node2;Job;13313.node2.supernodexp.hpc;Job Queued at request of baovo@node2.supernodexp.hpc, owner = baovo@node2.supernodexp.hpc, job name = lu-decomp-100000-mem20, queue = workq
05/02/2018 09:41:18;0040;Server@node2;Svr;node2.supernodexp.hpc;Scheduler sent command 1
05/02/2018 09:41:18;0040;Server@node2;Svr;node2.supernodexp.hpc;Scheduler sent command 0
05/02/2018 09:41:18;0100;Server@node2;Req;;Type 21 request received from Scheduler@node2.supernodexp.hpc, sock=19
05/02/2018 09:41:18;0100;Server@node2;Req;;Type 81 request received from Scheduler@node2.supernodexp.hpc, sock=19
05/02/2018 09:41:18;0100;Server@node2;Req;;Type 71 request received from Scheduler@node2.supernodexp.hpc, sock=19
05/02/2018 09:41:18;0100;Server@node2;Req;;Type 58 request received from Scheduler@node2.supernodexp.hpc, sock=19
05/02/2018 09:41:18;0100;Server@node2;Req;;Type 20 request received from Scheduler@node2.supernodexp.hpc, sock=19
05/02/2018 09:41:18;0100;Server@node2;Req;;Type 51 request received from Scheduler@node2.supernodexp.hpc, sock=19
05/02/2018 09:41:18;0100;Server@node2;Req;;Type 23 request received from Scheduler@node2.supernodexp.hpc, sock=19
05/02/2018 09:41:18;0008;Server@node2;Job;13313.node2.supernodexp.hpc;Job Run at request of Scheduler@node2.supernodexp.hpc on exec_vnode (node3:ncpus=8:mem=20971520kb)
05/02/2018 09:41:18;0001;Server@node2;Svr;Server@node2;Success (0) in req_runjob2, return value of svr_startjob is 0
05/02/2018 09:41:22;0100;Server@node2;Req;;Type 1 request received from baovo@node2.supernodexp.hpc, sock=16
05/02/2018 09:41:22;0100;Server@node2;Req;;Type 3 request received from baovo@node2.supernodexp.hpc, sock=16
05/02/2018 09:41:22;0100;Server@node2;Req;;Type 5 request received from baovo@node2.supernodexp.hpc, sock=16
05/02/2018 09:41:22;0100;Server@node2;Job;13314.node2.supernodexp.hpc;enqueuing into workq, state 1 hop 1
05/02/2018 09:41:22;0008;Server@node2;Job;13314.node2.supernodexp.hpc;Job Queued at request of baovo@node2.supernodexp.hpc, owner = baovo@node2.supernodexp.hpc, job name = shared-vir-mem, queue = workq
05/02/2018 09:41:22;0040;Server@node2;Svr;node2.supernodexp.hpc;Scheduler sent command 1
05/02/2018 09:41:22;0040;Server@node2;Svr;node2.supernodexp.hpc;Scheduler sent command 0
05/02/2018 09:41:22;0100;Server@node2;Req;;Type 21 request received from Scheduler@node2.supernodexp.hpc, sock=19
05/02/2018 09:41:22;0100;Server@node2;Req;;Type 81 request received from Scheduler@node2.supernodexp.hpc, sock=19
05/02/2018 09:41:22;0100;Server@node2;Req;;Type 71 request received from Scheduler@node2.supernodexp.hpc, sock=19
05/02/2018 09:41:22;0100;Server@node2;Req;;Type 58 request received from Scheduler@node2.supernodexp.hpc, sock=19
05/02/2018 09:41:22;0100;Server@node2;Req;;Type 1 request received from baovo@node2.supernodexp.hpc, sock=16
05/02/2018 09:41:22;0100;Server@node2;Req;;Type 3 request received from baovo@node2.supernodexp.hpc, sock=16
05/02/2018 09:41:22;0100;Server@node2;Req;;Type 5 request received from baovo@node2.supernodexp.hpc, sock=16
05/02/2018 09:41:22;0100;Server@node2;Job;13315.node2.supernodexp.hpc;enqueuing into workq, state 1 hop 1
05/02/2018 09:41:22;0008;Server@node2;Job;13315.node2.supernodexp.hpc;Job Queued at request of baovo@node2.supernodexp.hpc, owner = baovo@node2.supernodexp.hpc, job name = vec-data-cpu4, queue = workq
05/02/2018 09:41:22;0100;Server@node2;Req;;Type 1 request received from baovo@node2.supernodexp.hpc, sock=16
05/02/2018 09:41:22;0100;Server@node2;Req;;Type 3 request received from baovo@node2.supernodexp.hpc, sock=16
05/02/2018 09:41:22;0100;Server@node2;Req;;Type 5 request received from baovo@node2.supernodexp.hpc, sock=16
05/02/2018 09:41:22;0100;Server@node2;Job;13316.node2.supernodexp.hpc;enqueuing into workq, state 1 hop 1
05/02/2018 09:41:22;0008;Server@node2;Job;13316.node2.supernodexp.hpc;Job Queued at request of baovo@node2.supernodexp.hpc, owner = baovo@node2.supernodexp.hpc, job name = lu-decomp-100000-mem20, queue = workq
05/02/2018 09:41:22;0100;Server@node2;Req;;Type 1 request received from baovo@node2.supernodexp.hpc, sock=16
05/02/2018 09:41:22;0100;Server@node2;Req;;Type 3 request received from baovo@node2.supernodexp.hpc, sock=16
05/02/2018 09:41:22;0100;Server@node2;Req;;Type 5 request received from baovo@node2.supernodexp.hpc, sock=16
05/02/2018 09:41:22;0100;Server@node2;Job;13317.node2.supernodexp.hpc;enqueuing into workq, state 1 hop 1
05/02/2018 09:41:22;0008;Server@node2;Job;13317.node2.supernodexp.hpc;Job Queued at request of baovo@node2.supernodexp.hpc, owner = baovo@node2.supernodexp.hpc, job name = mkl-20000, queue = workq
05/02/2018 09:41:22;0100;Server@node2;Req;;Type 20 request received from Scheduler@node2.supernodexp.hpc, sock=19
05/02/2018 09:41:22;0100;Server@node2;Req;;Type 51 request received from Scheduler@node2.supernodexp.hpc, sock=19
05/02/2018 09:41:22;0100;Server@node2;Req;;Type 11 request received from Scheduler@node2.supernodexp.hpc, sock=19
05/02/2018 09:41:22;0008;Server@node2;Job;13315.node2.supernodexp.hpc;Job Modified at request of Scheduler@node2.supernodexp.hpc
05/02/2018 09:41:22;0100;Server@node2;Req;;Type 11 request received from Scheduler@node2.supernodexp.hpc, sock=19
05/02/2018 09:41:22;0008;Server@node2;Job;13316.node2.supernodexp.hpc;Job Modified at request of Scheduler@node2.supernodexp.hpc
05/02/2018 09:41:22;0100;Server@node2;Req;;Type 11 request received from Scheduler@node2.supernodexp.hpc, sock=19
05/02/2018 09:41:22;0008;Server@node2;Job;13312.node2.supernodexp.hpc;Job Modified at request of Scheduler@node2.supernodexp.hpc
05/02/2018 09:41:22;0100;Server@node2;Req;;Type 11 request received from Scheduler@node2.supernodexp.hpc, sock=19
05/02/2018 09:41:22;0008;Server@node2;Job;13317.node2.supernodexp.hpc;Job Modified at request of Scheduler@node2.supernodexp.hpc
05/02/2018 09:41:22;0100;Server@node2;Req;;Type 11 request received from Scheduler@node2.supernodexp.hpc, sock=19
05/02/2018 09:41:22;0008;Server@node2;Job;13314.node2.supernodexp.hpc;Job Modified at request of Scheduler@node2.supernodexp.hpc
05/02/2018 09:41:22;0040;Server@node2;Svr;node2.supernodexp.hpc;Scheduler sent command 1
05/02/2018 09:41:22;0040;Server@node2;Svr;node2.supernodexp.hpc;Scheduler sent command 0
05/02/2018 09:41:22;0100;Server@node2;Req;;Type 21 request received from Scheduler@node2.supernodexp.hpc, sock=19
05/02/2018 09:41:22;0100;Server@node2;Req;;Type 81 request received from Scheduler@node2.supernodexp.hpc, sock=19
05/02/2018 09:41:22;0100;Server@node2;Req;;Type 71 request received from Scheduler@node2.supernodexp.hpc, sock=19
05/02/2018 09:41:22;0100;Server@node2;Req;;Type 58 request received from Scheduler@node2.supernodexp.hpc, sock=19
05/02/2018 09:41:22;0100;Server@node2;Req;;Type 20 request received from Scheduler@node2.supernodexp.hpc, sock=19
05/02/2018 09:41:22;0100;Server@node2;Req;;Type 51 request received from Scheduler@node2.supernodexp.hpc, sock=19
05/02/2018 09:41:23;0100;Server@node2;Req;;Type 1 request received from baovo@node2.supernodexp.hpc, sock=16
05/02/2018 09:41:23;0100;Server@node2;Req;;Type 3 request received from baovo@node2.supernodexp.hpc, sock=16
05/02/2018 09:41:23;0100;Server@node2;Req;;Type 5 request received from baovo@node2.supernodexp.hpc, sock=16
05/02/2018 09:41:23;0100;Server@node2;Job;13318.node2.supernodexp.hpc;enqueuing into workq, state 1 hop 1
05/02/2018 09:41:23;0008;Server@node2;Job;13318.node2.supernodexp.hpc;Job Queued at request of baovo@node2.supernodexp.hpc, owner = baovo@node2.supernodexp.hpc, job name = nbody-700000, queue = workq
05/02/2018 09:41:23;0040;Server@node2;Svr;node2.supernodexp.hpc;Scheduler sent command 1
05/02/2018 09:41:23;0040;Server@node2;Svr;node2.supernodexp.hpc;Scheduler sent command 0
05/02/2018 09:41:23;0100;Server@node2;Req;;Type 21 request received from Scheduler@node2.supernodexp.hpc, sock=19
05/02/2018 09:41:23;0100;Server@node2;Req;;Type 81 request received from Scheduler@node2.supernodexp.hpc, sock=19
05/02/2018 09:41:23;0100;Server@node2;Req;;Type 71 request received from Scheduler@node2.supernodexp.hpc, sock=19
05/02/2018 09:41:23;0100;Server@node2;Req;;Type 58 request received from Scheduler@node2.supernodexp.hpc, sock=19
05/02/2018 09:41:23;0100;Server@node2;Req;;Type 20 request received from Scheduler@node2.supernodexp.hpc, sock=19
05/02/2018 09:41:23;0100;Server@node2;Req;;Type 51 request received from Scheduler@node2.supernodexp.hpc, sock=19
05/02/2018 09:41:23;0100;Server@node2;Req;;Type 11 request received from Scheduler@node2.supernodexp.hpc, sock=19
05/02/2018 09:41:23;0008;Server@node2;Job;13318.node2.supernodexp.hpc;Job Modified at request of Scheduler@node2.supernodexp.hpc
05/02/2018 09:41:25;0100;Server@node2;Req;;Type 1 request received from baovo@node2.supernodexp.hpc, sock=16
05/02/2018 09:41:25;0100;Server@node2;Req;;Type 3 request received from baovo@node2.supernodexp.hpc, sock=16
05/02/2018 09:41:25;0100;Server@node2;Req;;Type 5 request received from baovo@node2.supernodexp.hpc, sock=16
05/02/2018 09:41:25;0100;Server@node2;Job;13319.node2.supernodexp.hpc;enqueuing into workq, state 1 hop 1
05/02/2018 09:41:25;0008;Server@node2;Job;13319.node2.supernodexp.hpc;Job Queued at request of baovo@node2.supernodexp.hpc, owner = baovo@node2.supernodexp.hpc, job name = mkl-25000, queue = workq
05/02/2018 09:41:25;0040;Server@node2;Svr;node2.supernodexp.hpc;Scheduler sent command 1
05/02/2018 09:41:25;0040;Server@node2;Svr;node2.supernodexp.hpc;Scheduler sent command 0
05/02/2018 09:41:25;0100;Server@node2;Req;;Type 21 request received from Scheduler@node2.supernodexp.hpc, sock=19
05/02/2018 09:41:25;0100;Server@node2;Req;;Type 81 request received from Scheduler@node2.supernodexp.hpc, sock=19
05/02/2018 09:41:25;0100;Server@node2;Req;;Type 71 request received from Scheduler@node2.supernodexp.hpc, sock=19
05/02/2018 09:41:25;0100;Server@node2;Req;;Type 58 request received from Scheduler@node2.supernodexp.hpc, sock=19
05/02/2018 09:41:25;0100;Server@node2;Req;;Type 20 request received from Scheduler@node2.supernodexp.hpc, sock=19
05/02/2018 09:41:25;0100;Server@node2;Req;;Type 51 request received from Scheduler@node2.supernodexp.hpc, sock=19
05/02/2018 09:41:25;0100;Server@node2;Req;;Type 11 request received from Scheduler@node2.supernodexp.hpc, sock=19
05/02/2018 09:41:25;0008;Server@node2;Job;13319.node2.supernodexp.hpc;Job Modified at request of Scheduler@node2.supernodexp.hpc
05/02/2018 09:41:26;0100;Server@node2;Req;;Type 1 request received from baovo@node2.supernodexp.hpc, sock=16
05/02/2018 09:41:26;0100;Server@node2;Req;;Type 3 request received from baovo@node2.supernodexp.hpc, sock=16
05/02/2018 09:41:26;0100;Server@node2;Req;;Type 5 request received from baovo@node2.supernodexp.hpc, sock=16
05/02/2018 09:41:26;0100;Server@node2;Job;13320.node2.supernodexp.hpc;enqueuing into workq, state 1 hop 1
05/02/2018 09:41:26;0008;Server@node2;Job;13320.node2.supernodexp.hpc;Job Queued at request of baovo@node2.supernodexp.hpc, owner = baovo@node2.supernodexp.hpc, job name = threading-misc-histogram, queue = workq
05/02/2018 09:41:26;0040;Server@node2;Svr;node2.supernodexp.hpc;Scheduler sent command 1
05/02/2018 09:41:26;0040;Server@node2;Svr;node2.supernodexp.hpc;Scheduler sent command 0
05/02/2018 09:41:26;0100;Server@node2;Req;;Type 21 request received from Scheduler@node2.supernodexp.hpc, sock=19
05/02/2018 09:41:26;0100;Server@node2;Req;;Type 81 request received from Scheduler@node2.supernodexp.hpc, sock=19
05/02/2018 09:41:26;0100;Server@node2;Req;;Type 71 request received from Scheduler@node2.supernodexp.hpc, sock=19
05/02/2018 09:41:26;0100;Server@node2;Req;;Type 58 request received from Scheduler@node2.supernodexp.hpc, sock=19
05/02/2018 09:41:26;0100;Server@node2;Req;;Type 20 request received from Scheduler@node2.supernodexp.hpc, sock=19
05/02/2018 09:41:26;0100;Server@node2;Req;;Type 51 request received from Scheduler@node2.supernodexp.hpc, sock=19
05/02/2018 09:41:26;0100;Server@node2;Req;;Type 11 request received from Scheduler@node2.supernodexp.hpc, sock=19
05/02/2018 09:41:26;0008;Server@node2;Job;13320.node2.supernodexp.hpc;Job Modified at request of Scheduler@node2.supernodexp.hpc
05/02/2018 09:41:27;0100;Server@node2;Req;;Type 1 request received from baovo@node2.supernodexp.hpc, sock=16
05/02/2018 09:41:27;0100;Server@node2;Req;;Type 3 request received from baovo@node2.supernodexp.hpc, sock=16
05/02/2018 09:41:27;0100;Server@node2;Req;;Type 5 request received from baovo@node2.supernodexp.hpc, sock=16
05/02/2018 09:41:27;0100;Server@node2;Job;13321.node2.supernodexp.hpc;enqueuing into workq, state 1 hop 1
05/02/2018 09:41:27;0008;Server@node2;Job;13321.node2.supernodexp.hpc;Job Queued at request of baovo@node2.supernodexp.hpc, owner = baovo@node2.supernodexp.hpc, job name = lu-decomp-100000-mem5, queue = workq
05/02/2018 09:41:27;0040;Server@node2;Svr;node2.supernodexp.hpc;Scheduler sent command 1
05/02/2018 09:41:27;0040;Server@node2;Svr;node2.supernodexp.hpc;Scheduler sent command 0
05/02/2018 09:41:27;0100;Server@node2;Req;;Type 21 request received from Scheduler@node2.supernodexp.hpc, sock=19
05/02/2018 09:41:27;0100;Server@node2;Req;;Type 81 request received from Scheduler@node2.supernodexp.hpc, sock=19
05/02/2018 09:41:27;0100;Server@node2;Req;;Type 71 request received from Scheduler@node2.supernodexp.hpc, sock=19
05/02/2018 09:41:27;0100;Server@node2;Req;;Type 58 request received from Scheduler@node2.supernodexp.hpc, sock=19
05/02/2018 09:41:27;0100;Server@node2;Req;;Type 20 request received from Scheduler@node2.supernodexp.hpc, sock=19
05/02/2018 09:41:27;0100;Server@node2;Req;;Type 51 request received from Scheduler@node2.supernodexp.hpc, sock=19
05/02/2018 09:41:27;0100;Server@node2;Req;;Type 11 request received from Scheduler@node2.supernodexp.hpc, sock=19
05/02/2018 09:41:27;0008;Server@node2;Job;13321.node2.supernodexp.hpc;Job Modified at request of Scheduler@node2.supernodexp.hpc
05/02/2018 09:41:29;0100;Server@node2;Req;;Type 1 request received from baovo@node2.supernodexp.hpc, sock=16
05/02/2018 09:41:29;0100;Server@node2;Req;;Type 3 request received from baovo@node2.supernodexp.hpc, sock=16
05/02/2018 09:41:29;0100;Server@node2;Req;;Type 5 request received from baovo@node2.supernodexp.hpc, sock=16
05/02/2018 09:41:29;0100;Server@node2;Job;13322.node2.supernodexp.hpc;enqueuing into workq, state 1 hop 1
05/02/2018 09:41:29;0008;Server@node2;Job;13322.node2.supernodexp.hpc;Job Queued at request of baovo@node2.supernodexp.hpc, owner = baovo@node2.supernodexp.hpc, job name = fft, queue = workq
05/02/2018 09:41:29;0040;Server@node2;Svr;node2.supernodexp.hpc;Scheduler sent command 1
05/02/2018 09:41:29;0040;Server@node2;Svr;node2.supernodexp.hpc;Scheduler sent command 0
05/02/2018 09:41:29;0100;Server@node2;Req;;Type 21 request received from Scheduler@node2.supernodexp.hpc, sock=19
05/02/2018 09:41:29;0100;Server@node2;Req;;Type 81 request received from Scheduler@node2.supernodexp.hpc, sock=19
05/02/2018 09:41:29;0100;Server@node2;Req;;Type 71 request received from Scheduler@node2.supernodexp.hpc, sock=19
05/02/2018 09:41:29;0100;Server@node2;Req;;Type 58 request received from Scheduler@node2.supernodexp.hpc, sock=19
05/02/2018 09:41:29;0100;Server@node2;Req;;Type 20 request received from Scheduler@node2.supernodexp.hpc, sock=19
05/02/2018 09:41:29;0100;Server@node2;Req;;Type 51 request received from Scheduler@node2.supernodexp.hpc, sock=19
05/02/2018 09:41:29;0100;Server@node2;Req;;Type 11 request received from Scheduler@node2.supernodexp.hpc, sock=19
05/02/2018 09:41:29;0008;Server@node2;Job;13322.node2.supernodexp.hpc;Job Modified at request of Scheduler@node2.supernodexp.hpc
05/02/2018 09:41:30;0100;Server@node2;Req;;Type 1 request received from baovo@node2.supernodexp.hpc, sock=16
05/02/2018 09:41:30;0100;Server@node2;Req;;Type 3 request received from baovo@node2.supernodexp.hpc, sock=16
05/02/2018 09:41:30;0100;Server@node2;Req;;Type 5 request received from baovo@node2.supernodexp.hpc, sock=16
05/02/2018 09:41:30;0100;Server@node2;Job;13323.node2.supernodexp.hpc;enqueuing into workq, state 1 hop 1
05/02/2018 09:41:30;0008;Server@node2;Job;13323.node2.supernodexp.hpc;Job Queued at request of baovo@node2.supernodexp.hpc, owner = baovo@node2.supernodexp.hpc, job name = qe_mic_test, queue = workq
05/02/2018 09:41:30;0040;Server@node2;Svr;node2.supernodexp.hpc;Scheduler sent command 1
05/02/2018 09:41:30;0040;Server@node2;Svr;node2.supernodexp.hpc;Scheduler sent command 0
05/02/2018 09:41:30;0100;Server@node2;Req;;Type 21 request received from Scheduler@node2.supernodexp.hpc, sock=19
05/02/2018 09:41:30;0100;Server@node2;Req;;Type 81 request received from Scheduler@node2.supernodexp.hpc, sock=19
05/02/2018 09:41:30;0100;Server@node2;Req;;Type 71 request received from Scheduler@node2.supernodexp.hpc, sock=19
05/02/2018 09:41:30;0100;Server@node2;Req;;Type 58 request received from Scheduler@node2.supernodexp.hpc, sock=19
05/02/2018 09:41:30;0100;Server@node2;Req;;Type 1 request received from baovo@node2.supernodexp.hpc, sock=16
05/02/2018 09:41:30;0100;Server@node2;Req;;Type 3 request received from baovo@node2.supernodexp.hpc, sock=16
05/02/2018 09:41:30;0100;Server@node2;Req;;Type 5 request received from baovo@node2.supernodexp.hpc, sock=16
05/02/2018 09:41:30;0100;Server@node2;Job;13324.node2.supernodexp.hpc;enqueuing into workq, state 1 hop 1
05/02/2018 09:41:30;0008;Server@node2;Job;13324.node2.supernodexp.hpc;Job Queued at request of baovo@node2.supernodexp.hpc, owner = baovo@node2.supernodexp.hpc, job name = vec-data-cpu4, queue = workq
05/02/2018 09:41:30;0100;Server@node2;Req;;Type 20 request received from Scheduler@node2.supernodexp.hpc, sock=19
05/02/2018 09:41:30;0100;Server@node2;Req;;Type 51 request received from Scheduler@node2.supernodexp.hpc, sock=19
05/02/2018 09:41:30;0100;Server@node2;Req;;Type 11 request received from Scheduler@node2.supernodexp.hpc, sock=19
05/02/2018 09:41:30;0008;Server@node2;Job;13324.node2.supernodexp.hpc;Job Modified at request of Scheduler@node2.supernodexp.hpc
05/02/2018 09:41:30;0100;Server@node2;Req;;Type 11 request received from Scheduler@node2.supernodexp.hpc, sock=19
05/02/2018 09:41:30;0008;Server@node2;Job;13323.node2.supernodexp.hpc;Job Modified at request of Scheduler@node2.supernodexp.hpc
05/02/2018 09:41:30;0040;Server@node2;Svr;node2.supernodexp.hpc;Scheduler sent command 1
05/02/2018 09:41:30;0040;Server@node2;Svr;node2.supernodexp.hpc;Scheduler sent command 0
05/02/2018 09:41:30;0100;Server@node2;Req;;Type 21 request received from Scheduler@node2.supernodexp.hpc, sock=19
05/02/2018 09:41:30;0100;Server@node2;Req;;Type 81 request received from Scheduler@node2.supernodexp.hpc, sock=19
05/02/2018 09:41:30;0100;Server@node2;Req;;Type 71 request received from Scheduler@node2.supernodexp.hpc, sock=19
05/02/2018 09:41:30;0100;Server@node2;Req;;Type 58 request received from Scheduler@node2.supernodexp.hpc, sock=19
05/02/2018 09:41:30;0100;Server@node2;Req;;Type 20 request received from Scheduler@node2.supernodexp.hpc, sock=19
05/02/2018 09:41:30;0100;Server@node2;Req;;Type 51 request received from Scheduler@node2.supernodexp.hpc, sock=19
05/02/2018 09:41:31;0100;Server@node2;Req;;Type 1 request received from baovo@node2.supernodexp.hpc, sock=16
05/02/2018 09:41:31;0100;Server@node2;Req;;Type 3 request received from baovo@node2.supernodexp.hpc, sock=16
05/02/2018 09:41:31;0100;Server@node2;Req;;Type 5 request received from baovo@node2.supernodexp.hpc, sock=16
05/02/2018 09:41:31;0100;Server@node2;Job;13325.node2.supernodexp.hpc;enqueuing into workq, state 1 hop 1
05/02/2018 09:41:31;0008;Server@node2;Job;13325.node2.supernodexp.hpc;Job Queued at request of baovo@node2.supernodexp.hpc, owner = baovo@node2.supernodexp.hpc, job name = fft, queue = workq
05/02/2018 09:41:31;0040;Server@node2;Svr;node2.supernodexp.hpc;Scheduler sent command 1
05/02/2018 09:41:31;0040;Server@node2;Svr;node2.supernodexp.hpc;Scheduler sent command 0
05/02/2018 09:41:31;0100;Server@node2;Req;;Type 21 request received from Scheduler@node2.supernodexp.hpc, sock=19
05/02/2018 09:41:31;0100;Server@node2;Req;;Type 81 request received from Scheduler@node2.supernodexp.hpc, sock=19
05/02/2018 09:41:31;0100;Server@node2;Req;;Type 71 request received from Scheduler@node2.supernodexp.hpc, sock=19
05/02/2018 09:41:31;0100;Server@node2;Req;;Type 58 request received from Scheduler@node2.supernodexp.hpc, sock=19
05/02/2018 09:41:31;0100;Server@node2;Req;;Type 1 request received from baovo@node2.supernodexp.hpc, sock=16
05/02/2018 09:41:31;0100;Server@node2;Req;;Type 3 request received from baovo@node2.supernodexp.hpc, sock=16
05/02/2018 09:41:31;0100;Server@node2;Req;;Type 5 request received from baovo@node2.supernodexp.hpc, sock=16
05/02/2018 09:41:31;0100;Server@node2;Job;13326.node2.supernodexp.hpc;enqueuing into workq, state 1 hop 1
05/02/2018 09:41:31;0008;Server@node2;Job;13326.node2.supernodexp.hpc;Job Queued at request of baovo@node2.supernodexp.hpc, owner = baovo@node2.supernodexp.hpc, job name = nbody-100000, queue = workq
05/02/2018 09:41:31;0100;Server@node2;Req;;Type 1 request received from baovo@node2.supernodexp.hpc, sock=16
05/02/2018 09:41:31;0100;Server@node2;Req;;Type 3 request received from baovo@node2.supernodexp.hpc, sock=16
05/02/2018 09:41:31;0100;Server@node2;Req;;Type 5 request received from baovo@node2.supernodexp.hpc, sock=16
05/02/2018 09:41:31;0100;Server@node2;Job;13327.node2.supernodexp.hpc;enqueuing into workq, state 1 hop 1
05/02/2018 09:41:31;0008;Server@node2;Job;13327.node2.supernodexp.hpc;Job Queued at request of baovo@node2.supernodexp.hpc, owner = baovo@node2.supernodexp.hpc, job name = fft, queue = workq
05/02/2018 09:41:31;0100;Server@node2;Req;;Type 1 request received from baovo@node2.supernodexp.hpc, sock=16
05/02/2018 09:41:31;0100;Server@node2;Req;;Type 3 request received from baovo@node2.supernodexp.hpc, sock=16
05/02/2018 09:41:31;0100;Server@node2;Req;;Type 5 request received from baovo@node2.supernodexp.hpc, sock=16
05/02/2018 09:41:31;0100;Server@node2;Job;13328.node2.supernodexp.hpc;enqueuing into workq, state 1 hop 1
05/02/2018 09:41:31;0008;Server@node2;Job;13328.node2.supernodexp.hpc;Job Queued at request of baovo@node2.supernodexp.hpc, owner = baovo@node2.supernodexp.hpc, job name = lu-decomp-100000-mem10, queue = workq
05/02/2018 09:41:31;0100;Server@node2;Req;;Type 20 request received from Scheduler@node2.supernodexp.hpc, sock=19
05/02/2018 09:41:31;0100;Server@node2;Req;;Type 51 request received from Scheduler@node2.supernodexp.hpc, sock=19
05/02/2018 09:41:31;0100;Server@node2;Req;;Type 11 request received from Scheduler@node2.supernodexp.hpc, sock=19
05/02/2018 09:41:31;0008;Server@node2;Job;13326.node2.supernodexp.hpc;Job Modified at request of Scheduler@node2.supernodexp.hpc
05/02/2018 09:41:31;0100;Server@node2;Req;;Type 11 request received from Scheduler@node2.supernodexp.hpc, sock=19
05/02/2018 09:41:31;0008;Server@node2;Job;13328.node2.supernodexp.hpc;Job Modified at request of Scheduler@node2.supernodexp.hpc
05/02/2018 09:41:31;0100;Server@node2;Req;;Type 11 request received from Scheduler@node2.supernodexp.hpc, sock=19
05/02/2018 09:41:31;0008;Server@node2;Job;13325.node2.supernodexp.hpc;Job Modified at request of Scheduler@node2.supernodexp.hpc
05/02/2018 09:41:31;0100;Server@node2;Req;;Type 11 request received from Scheduler@node2.supernodexp.hpc, sock=19
05/02/2018 09:41:31;0008;Server@node2;Job;13327.node2.supernodexp.hpc;Job Modified at request of Scheduler@node2.supernodexp.hpc
05/02/2018 09:41:31;0040;Server@node2;Svr;node2.supernodexp.hpc;Scheduler sent command 1
05/02/2018 09:41:31;0040;Server@node2;Svr;node2.supernodexp.hpc;Scheduler sent command 0
05/02/2018 09:41:31;0100;Server@node2;Req;;Type 21 request received from Scheduler@node2.supernodexp.hpc, sock=19
05/02/2018 09:41:31;0100;Server@node2;Req;;Type 81 request received from Scheduler@node2.supernodexp.hpc, sock=19
05/02/2018 09:41:31;0100;Server@node2;Req;;Type 71 request received from Scheduler@node2.supernodexp.hpc, sock=19
05/02/2018 09:41:31;0100;Server@node2;Req;;Type 58 request received from Scheduler@node2.supernodexp.hpc, sock=19
05/02/2018 09:41:32;0100;Server@node2;Req;;Type 20 request received from Scheduler@node2.supernodexp.hpc, sock=19
05/02/2018 09:41:32;0100;Server@node2;Req;;Type 51 request received from Scheduler@node2.supernodexp.hpc, sock=19
05/02/2018 09:41:32;0100;Server@node2;Req;;Type 1 request received from baovo@node2.supernodexp.hpc, sock=16
05/02/2018 09:41:32;0100;Server@node2;Req;;Type 3 request received from baovo@node2.supernodexp.hpc, sock=16
05/02/2018 09:41:32;0100;Server@node2;Req;;Type 5 request received from baovo@node2.supernodexp.hpc, sock=16
05/02/2018 09:41:32;0100;Server@node2;Job;13329.node2.supernodexp.hpc;enqueuing into workq, state 1 hop 1
05/02/2018 09:41:32;0008;Server@node2;Job;13329.node2.supernodexp.hpc;Job Queued at request of baovo@node2.supernodexp.hpc, owner = baovo@node2.supernodexp.hpc, job name = qe_mic_test, queue = workq
05/02/2018 09:41:32;0040;Server@node2;Svr;node2.supernodexp.hpc;Scheduler sent command 1
05/02/2018 09:41:32;0040;Server@node2;Svr;node2.supernodexp.hpc;Scheduler sent command 0
05/02/2018 09:41:32;0100;Server@node2;Req;;Type 21 request received from Scheduler@node2.supernodexp.hpc, sock=19
05/02/2018 09:41:32;0100;Server@node2;Req;;Type 81 request received from Scheduler@node2.supernodexp.hpc, sock=19
05/02/2018 09:41:32;0100;Server@node2;Req;;Type 71 request received from Scheduler@node2.supernodexp.hpc, sock=19
05/02/2018 09:41:32;0100;Server@node2;Req;;Type 58 request received from Scheduler@node2.supernodexp.hpc, sock=19
05/02/2018 09:41:32;0100;Server@node2;Req;;Type 20 request received from Scheduler@node2.supernodexp.hpc, sock=19
05/02/2018 09:41:32;0100;Server@node2;Req;;Type 51 request received from Scheduler@node2.supernodexp.hpc, sock=19
05/02/2018 09:41:33;0100;Server@node2;Req;;Type 11 request received from Scheduler@node2.supernodexp.hpc, sock=19
05/02/2018 09:41:33;0008;Server@node2;Job;13329.node2.supernodexp.hpc;Job Modified at request of Scheduler@node2.supernodexp.hpc
05/02/2018 09:41:49;0080;Server@node2;Job;13275.node2.supernodexp.hpc;Obit received momhop:1 serverhop:1 state:4 substate:42
05/02/2018 09:41:49;0080;Server@node2;Job;13276.node2.supernodexp.hpc;Obit received momhop:1 serverhop:1 state:4 substate:42
05/02/2018 09:41:51;0010;Server@node2;Job;13276.node2.supernodexp.hpc;Exit_status=271 resources_used.cpupercent=0 resources_used.cput=00:00:00 resources_used.mem=9368kb resources_used.ncpus=8 resources_used.vmem=104700kb resources_used.walltime=00:06:56
05/02/2018 09:41:51;0100;Server@node2;Job;13276.node2.supernodexp.hpc;dequeuing from workq, state 5
05/02/2018 09:41:51;0040;Server@node2;Svr;node2.supernodexp.hpc;Scheduler sent command 2
05/02/2018 09:41:51;0040;Server@node2;Svr;node2.supernodexp.hpc;Scheduler sent command 0
05/02/2018 09:41:51;0100;Server@node2;Req;;Type 21 request received from Scheduler@node2.supernodexp.hpc, sock=19
05/02/2018 09:41:51;0100;Server@node2;Req;;Type 81 request received from Scheduler@node2.supernodexp.hpc, sock=19
05/02/2018 09:41:51;0100;Server@node2;Req;;Type 71 request received from Scheduler@node2.supernodexp.hpc, sock=19
05/02/2018 09:41:51;0100;Server@node2;Req;;Type 58 request received from Scheduler@node2.supernodexp.hpc, sock=19
05/02/2018 09:41:51;0010;Server@node2;Job;13275.node2.supernodexp.hpc;Exit_status=271 resources_used.cpupercent=0 resources_used.cput=00:00:00 resources_used.mem=8832kb resources_used.ncpus=8 resources_used.vmem=172288kb resources_used.walltime=00:06:58
05/02/2018 09:41:51;0100;Server@node2;Job;13275.node2.supernodexp.hpc;dequeuing from workq, state 5
05/02/2018 09:41:51;0100;Server@node2;Req;;Type 20 request received from Scheduler@node2.supernodexp.hpc, sock=19
05/02/2018 09:41:51;0100;Server@node2;Req;;Type 51 request received from Scheduler@node2.supernodexp.hpc, sock=19
05/02/2018 09:41:51;0040;Server@node2;Svr;node2.supernodexp.hpc;Scheduler sent command 2
05/02/2018 09:41:51;0040;Server@node2;Svr;node2.supernodexp.hpc;Scheduler sent command 0
05/02/2018 09:41:51;0100;Server@node2;Req;;Type 21 request received from Scheduler@node2.supernodexp.hpc, sock=19
05/02/2018 09:41:51;0100;Server@node2;Req;;Type 81 request received from Scheduler@node2.supernodexp.hpc, sock=19
05/02/2018 09:41:51;0100;Server@node2;Req;;Type 71 request received from Scheduler@node2.supernodexp.hpc, sock=19
05/02/2018 09:41:51;0100;Server@node2;Req;;Type 58 request received from Scheduler@node2.supernodexp.hpc, sock=19
05/02/2018 09:41:51;0100;Server@node2;Req;;Type 20 request received from Scheduler@node2.supernodexp.hpc, sock=19
05/02/2018 09:41:51;0100;Server@node2;Req;;Type 51 request received from Scheduler@node2.supernodexp.hpc, sock=19
05/02/2018 09:41:54;0080;Server@node2;Job;13310.node2.supernodexp.hpc;Obit received momhop:1 serverhop:1 state:4 substate:42
05/02/2018 09:41:55;0010;Server@node2;Job;13310.node2.supernodexp.hpc;Exit_status=0 resources_used.cpupercent=0 resources_used.cput=00:00:00 resources_used.mem=9084kb resources_used.ncpus=8 resources_used.vmem=105088kb resources_used.walltime=00:00:41
05/02/2018 09:41:55;0100;Server@node2;Job;13310.node2.supernodexp.hpc;dequeuing from workq, state 5
05/02/2018 09:41:55;0040;Server@node2;Svr;node2.supernodexp.hpc;Scheduler sent command 2
05/02/2018 09:41:55;0040;Server@node2;Svr;node2.supernodexp.hpc;Scheduler sent command 0
05/02/2018 09:41:55;0100;Server@node2;Req;;Type 21 request received from Scheduler@node2.supernodexp.hpc, sock=19
05/02/2018 09:41:55;0100;Server@node2;Req;;Type 81 request received from Scheduler@node2.supernodexp.hpc, sock=19
05/02/2018 09:41:55;0100;Server@node2;Req;;Type 71 request received from Scheduler@node2.supernodexp.hpc, sock=19
05/02/2018 09:41:55;0100;Server@node2;Req;;Type 58 request received from Scheduler@node2.supernodexp.hpc, sock=19
05/02/2018 09:41:55;0100;Server@node2;Req;;Type 20 request received from Scheduler@node2.supernodexp.hpc, sock=19
05/02/2018 09:41:55;0100;Server@node2;Req;;Type 51 request received from Scheduler@node2.supernodexp.hpc, sock=19
05/02/2018 09:41:57;0080;Server@node2;Job;13291.node2.supernodexp.hpc;Obit received momhop:1 serverhop:1 state:4 substate:42
05/02/2018 09:41:57;0010;Server@node2;Job;13291.node2.supernodexp.hpc;Exit_status=0 resources_used.cpupercent=0 resources_used.cput=00:00:00 resources_used.mem=9944kb resources_used.ncpus=8 resources_used.vmem=318292kb resources_used.walltime=00:06:25
05/02/2018 09:41:57;0100;Server@node2;Job;13291.node2.supernodexp.hpc;dequeuing from workq, state 5
05/02/2018 09:41:57;0040;Server@node2;Svr;node2.supernodexp.hpc;Scheduler sent command 2
05/02/2018 09:41:57;0040;Server@node2;Svr;node2.supernodexp.hpc;Scheduler sent command 0
05/02/2018 09:41:57;0100;Server@node2;Req;;Type 21 request received from Scheduler@node2.supernodexp.hpc, sock=19
05/02/2018 09:41:57;0100;Server@node2;Req;;Type 81 request received from Scheduler@node2.supernodexp.hpc, sock=19
05/02/2018 09:41:57;0100;Server@node2;Req;;Type 71 request received from Scheduler@node2.supernodexp.hpc, sock=19
05/02/2018 09:41:57;0100;Server@node2;Req;;Type 58 request received from Scheduler@node2.supernodexp.hpc, sock=19
05/02/2018 09:41:57;0100;Server@node2;Req;;Type 20 request received from Scheduler@node2.supernodexp.hpc, sock=19
05/02/2018 09:41:57;0100;Server@node2;Req;;Type 51 request received from Scheduler@node2.supernodexp.hpc, sock=19
05/02/2018 09:41:58;0080;Server@node2;Job;13313.node2.supernodexp.hpc;Obit received momhop:1 serverhop:1 state:4 substate:42
05/02/2018 09:41:58;0010;Server@node2;Job;13313.node2.supernodexp.hpc;Exit_status=0 resources_used.cpupercent=0 resources_used.cput=00:00:00 resources_used.mem=9092kb resources_used.ncpus=8 resources_used.vmem=103036kb resources_used.walltime=00:00:40
05/02/2018 09:41:58;0100;Server@node2;Job;13313.node2.supernodexp.hpc;dequeuing from workq, state 5
05/02/2018 09:41:58;0040;Server@node2;Svr;node2.supernodexp.hpc;Scheduler sent command 2
05/02/2018 09:41:58;0040;Server@node2;Svr;node2.supernodexp.hpc;Scheduler sent command 0
05/02/2018 09:41:58;0100;Server@node2;Req;;Type 21 request received from Scheduler@node2.supernodexp.hpc, sock=19
05/02/2018 09:41:58;0100;Server@node2;Req;;Type 81 request received from Scheduler@node2.supernodexp.hpc, sock=19
05/02/2018 09:41:58;0100;Server@node2;Req;;Type 71 request received from Scheduler@node2.supernodexp.hpc, sock=19
05/02/2018 09:41:58;0100;Server@node2;Req;;Type 58 request received from Scheduler@node2.supernodexp.hpc, sock=19
05/02/2018 09:41:58;0100;Server@node2;Req;;Type 20 request received from Scheduler@node2.supernodexp.hpc, sock=19
05/02/2018 09:41:58;0100;Server@node2;Req;;Type 51 request received from Scheduler@node2.supernodexp.hpc, sock=19
05/02/2018 09:42:14;0080;Server@node2;Job;13290.node2.supernodexp.hpc;Obit received momhop:1 serverhop:1 state:4 substate:42
05/02/2018 09:42:15;0010;Server@node2;Job;13290.node2.supernodexp.hpc;Exit_status=0 resources_used.cpupercent=0 resources_used.cput=00:00:00 resources_used.mem=9420kb resources_used.ncpus=12 resources_used.vmem=237496kb resources_used.walltime=00:06:43
05/02/2018 09:42:15;0100;Server@node2;Job;13290.node2.supernodexp.hpc;dequeuing from workq, state 5
05/02/2018 09:42:15;0040;Server@node2;Svr;node2.supernodexp.hpc;Scheduler sent command 2
05/02/2018 09:42:15;0040;Server@node2;Svr;node2.supernodexp.hpc;Scheduler sent command 0
05/02/2018 09:42:15;0100;Server@node2;Req;;Type 21 request received from Scheduler@node2.supernodexp.hpc, sock=19
05/02/2018 09:42:15;0100;Server@node2;Req;;Type 81 request received from Scheduler@node2.supernodexp.hpc, sock=19
05/02/2018 09:42:15;0100;Server@node2;Req;;Type 71 request received from Scheduler@node2.supernodexp.hpc, sock=19
05/02/2018 09:42:15;0100;Server@node2;Req;;Type 58 request received from Scheduler@node2.supernodexp.hpc, sock=19
05/02/2018 09:42:15;0100;Server@node2;Req;;Type 20 request received from Scheduler@node2.supernodexp.hpc, sock=19
05/02/2018 09:42:15;0100;Server@node2;Req;;Type 51 request received from Scheduler@node2.supernodexp.hpc, sock=19
05/02/2018 09:42:34;0100;Server@node2;Req;;Type 0 request received from baovo@node2.supernodexp.hpc, sock=16
05/02/2018 09:42:34;0100;Server@node2;Req;;Type 49 request received from baovo@node2.supernodexp.hpc, sock=19
05/02/2018 09:42:34;0100;Server@node2;Req;;Type 21 request received from baovo@node2.supernodexp.hpc, sock=16
05/02/2018 09:42:34;0100;Server@node2;Req;;Type 1 request received from baovo@node2.supernodexp.hpc, sock=16
05/02/2018 09:42:34;0100;Server@node2;Req;;Type 3 request received from baovo@node2.supernodexp.hpc, sock=16
05/02/2018 09:42:34;0100;Server@node2;Req;;Type 5 request received from baovo@node2.supernodexp.hpc, sock=16
05/02/2018 09:42:34;0100;Server@node2;Job;13330.node2.supernodexp.hpc;enqueuing into workq, state 1 hop 1
05/02/2018 09:42:34;0008;Server@node2;Job;13330.node2.supernodexp.hpc;Job Queued at request of baovo@node2.supernodexp.hpc, owner = baovo@node2.supernodexp.hpc, job name = vec-data-cpu4, queue = workq
05/02/2018 09:42:34;0040;Server@node2;Svr;node2.supernodexp.hpc;Scheduler sent command 1
05/02/2018 09:42:34;0040;Server@node2;Svr;node2.supernodexp.hpc;Scheduler sent command 0
05/02/2018 09:42:34;0100;Server@node2;Req;;Type 21 request received from Scheduler@node2.supernodexp.hpc, sock=19
05/02/2018 09:42:34;0100;Server@node2;Req;;Type 81 request received from Scheduler@node2.supernodexp.hpc, sock=19
05/02/2018 09:42:34;0100;Server@node2;Req;;Type 71 request received from Scheduler@node2.supernodexp.hpc, sock=19
05/02/2018 09:42:34;0100;Server@node2;Req;;Type 58 request received from Scheduler@node2.supernodexp.hpc, sock=19
05/02/2018 09:42:35;0100;Server@node2;Req;;Type 20 request received from Scheduler@node2.supernodexp.hpc, sock=19
05/02/2018 09:42:35;0100;Server@node2;Req;;Type 51 request received from Scheduler@node2.supernodexp.hpc, sock=19
05/02/2018 09:42:35;0100;Server@node2;Req;;Type 11 request received from Scheduler@node2.supernodexp.hpc, sock=19
05/02/2018 09:42:35;0008;Server@node2;Job;13330.node2.supernodexp.hpc;Job Modified at request of Scheduler@node2.supernodexp.hpc
05/02/2018 09:42:37;0100;Server@node2;Req;;Type 1 request received from baovo@node2.supernodexp.hpc, sock=16
05/02/2018 09:42:37;0100;Server@node2;Req;;Type 3 request received from baovo@node2.supernodexp.hpc, sock=16
05/02/2018 09:42:37;0100;Server@node2;Req;;Type 5 request received from baovo@node2.supernodexp.hpc, sock=16
05/02/2018 09:42:37;0100;Server@node2;Job;13331.node2.supernodexp.hpc;enqueuing into workq, state 1 hop 1
05/02/2018 09:42:38;0008;Server@node2;Job;13331.node2.supernodexp.hpc;Job Queued at request of baovo@node2.supernodexp.hpc, owner = baovo@node2.supernodexp.hpc, job name = sgefa, queue = workq
05/02/2018 09:42:38;0040;Server@node2;Svr;node2.supernodexp.hpc;Scheduler sent command 1
05/02/2018 09:42:38;0040;Server@node2;Svr;node2.supernodexp.hpc;Scheduler sent command 0
05/02/2018 09:42:38;0100;Server@node2;Req;;Type 21 request received from Scheduler@node2.supernodexp.hpc, sock=19
05/02/2018 09:42:38;0100;Server@node2;Req;;Type 81 request received from Scheduler@node2.supernodexp.hpc, sock=19
05/02/2018 09:42:38;0100;Server@node2;Req;;Type 71 request received from Scheduler@node2.supernodexp.hpc, sock=19
05/02/2018 09:42:38;0100;Server@node2;Req;;Type 58 request received from Scheduler@node2.supernodexp.hpc, sock=19
05/02/2018 09:42:38;0100;Server@node2;Req;;Type 1 request received from baovo@node2.supernodexp.hpc, sock=16
05/02/2018 09:42:38;0100;Server@node2;Req;;Type 3 request received from baovo@node2.supernodexp.hpc, sock=16
05/02/2018 09:42:38;0100;Server@node2;Req;;Type 5 request received from baovo@node2.supernodexp.hpc, sock=16
05/02/2018 09:42:38;0100;Server@node2;Job;13332.node2.supernodexp.hpc;enqueuing into workq, state 1 hop 1
05/02/2018 09:42:38;0008;Server@node2;Job;13332.node2.supernodexp.hpc;Job Queued at request of baovo@node2.supernodexp.hpc, owner = baovo@node2.supernodexp.hpc, job name = lu-decomp-100000-mem10, queue = workq
05/02/2018 09:42:38;0100;Server@node2;Req;;Type 20 request received from Scheduler@node2.supernodexp.hpc, sock=19
05/02/2018 09:42:38;0100;Server@node2;Req;;Type 51 request received from Scheduler@node2.supernodexp.hpc, sock=19
05/02/2018 09:42:38;0100;Server@node2;Req;;Type 11 request received from Scheduler@node2.supernodexp.hpc, sock=19
05/02/2018 09:42:38;0008;Server@node2;Job;13332.node2.supernodexp.hpc;Job Modified at request of Scheduler@node2.supernodexp.hpc
05/02/2018 09:42:38;0100;Server@node2;Req;;Type 11 request received from Scheduler@node2.supernodexp.hpc, sock=19
05/02/2018 09:42:38;0008;Server@node2;Job;13331.node2.supernodexp.hpc;Job Modified at request of Scheduler@node2.supernodexp.hpc
05/02/2018 09:42:38;0040;Server@node2;Svr;node2.supernodexp.hpc;Scheduler sent command 1
05/02/2018 09:42:38;0040;Server@node2;Svr;node2.supernodexp.hpc;Scheduler sent command 0
05/02/2018 09:42:38;0100;Server@node2;Req;;Type 21 request received from Scheduler@node2.supernodexp.hpc, sock=19
05/02/2018 09:42:38;0100;Server@node2;Req;;Type 81 request received from Scheduler@node2.supernodexp.hpc, sock=19
05/02/2018 09:42:38;0100;Server@node2;Req;;Type 71 request received from Scheduler@node2.supernodexp.hpc, sock=19
05/02/2018 09:42:38;0100;Server@node2;Req;;Type 58 request received from Scheduler@node2.supernodexp.hpc, sock=19
05/02/2018 09:42:38;0100;Server@node2;Req;;Type 20 request received from Scheduler@node2.supernodexp.hpc, sock=19
05/02/2018 09:42:38;0100;Server@node2;Req;;Type 51 request received from Scheduler@node2.supernodexp.hpc, sock=19
05/02/2018 09:42:40;0100;Server@node2;Req;;Type 1 request received from baovo@node2.supernodexp.hpc, sock=16
05/02/2018 09:42:40;0100;Server@node2;Req;;Type 3 request received from baovo@node2.supernodexp.hpc, sock=16
05/02/2018 09:42:40;0100;Server@node2;Req;;Type 5 request received from baovo@node2.supernodexp.hpc, sock=16
05/02/2018 09:42:40;0100;Server@node2;Job;13333.node2.supernodexp.hpc;enqueuing into workq, state 1 hop 1
05/02/2018 09:42:40;0008;Server@node2;Job;13333.node2.supernodexp.hpc;Job Queued at request of baovo@node2.supernodexp.hpc, owner = baovo@node2.supernodexp.hpc, job name = lu-decomp-100000-mem20, queue = workq
05/02/2018 09:42:40;0040;Server@node2;Svr;node2.supernodexp.hpc;Scheduler sent command 1
05/02/2018 09:42:40;0040;Server@node2;Svr;node2.supernodexp.hpc;Scheduler sent command 0
05/02/2018 09:42:40;0100;Server@node2;Req;;Type 21 request received from Scheduler@node2.supernodexp.hpc, sock=19
05/02/2018 09:42:40;0100;Server@node2;Req;;Type 81 request received from Scheduler@node2.supernodexp.hpc, sock=19
05/02/2018 09:42:40;0100;Server@node2;Req;;Type 71 request received from Scheduler@node2.supernodexp.hpc, sock=19
05/02/2018 09:42:40;0100;Server@node2;Req;;Type 58 request received from Scheduler@node2.supernodexp.hpc, sock=19
05/02/2018 09:42:40;0100;Server@node2;Req;;Type 20 request received from Scheduler@node2.supernodexp.hpc, sock=19
05/02/2018 09:42:40;0100;Server@node2;Req;;Type 51 request received from Scheduler@node2.supernodexp.hpc, sock=19
05/02/2018 09:42:40;0100;Server@node2;Req;;Type 11 request received from Scheduler@node2.supernodexp.hpc, sock=19
05/02/2018 09:42:40;0008;Server@node2;Job;13333.node2.supernodexp.hpc;Job Modified at request of Scheduler@node2.supernodexp.hpc
05/02/2018 09:42:46;0100;Server@node2;Req;;Type 1 request received from baovo@node2.supernodexp.hpc, sock=16
05/02/2018 09:42:46;0100;Server@node2;Req;;Type 3 request received from baovo@node2.supernodexp.hpc, sock=16
05/02/2018 09:42:46;0100;Server@node2;Req;;Type 5 request received from baovo@node2.supernodexp.hpc, sock=16
05/02/2018 09:42:46;0100;Server@node2;Job;13334.node2.supernodexp.hpc;enqueuing into workq, state 1 hop 1
05/02/2018 09:42:46;0008;Server@node2;Job;13334.node2.supernodexp.hpc;Job Queued at request of baovo@node2.supernodexp.hpc, owner = baovo@node2.supernodexp.hpc, job name = lu-decomp-100000-mem20, queue = workq
05/02/2018 09:42:46;0040;Server@node2;Svr;node2.supernodexp.hpc;Scheduler sent command 1
05/02/2018 09:42:46;0040;Server@node2;Svr;node2.supernodexp.hpc;Scheduler sent command 0
05/02/2018 09:42:46;0100;Server@node2;Req;;Type 21 request received from Scheduler@node2.supernodexp.hpc, sock=19
05/02/2018 09:42:46;0100;Server@node2;Req;;Type 81 request received from Scheduler@node2.supernodexp.hpc, sock=19
05/02/2018 09:42:46;0100;Server@node2;Req;;Type 71 request received from Scheduler@node2.supernodexp.hpc, sock=19
05/02/2018 09:42:46;0100;Server@node2;Req;;Type 58 request received from Scheduler@node2.supernodexp.hpc, sock=19
05/02/2018 09:42:46;0100;Server@node2;Req;;Type 20 request received from Scheduler@node2.supernodexp.hpc, sock=19
05/02/2018 09:42:46;0100;Server@node2;Req;;Type 51 request received from Scheduler@node2.supernodexp.hpc, sock=19
05/02/2018 09:42:46;0100;Server@node2;Req;;Type 11 request received from Scheduler@node2.supernodexp.hpc, sock=19
05/02/2018 09:42:46;0008;Server@node2;Job;13334.node2.supernodexp.hpc;Job Modified at request of Scheduler@node2.supernodexp.hpc
05/02/2018 09:42:49;0100;Server@node2;Req;;Type 1 request received from baovo@node2.supernodexp.hpc, sock=16
05/02/2018 09:42:49;0100;Server@node2;Req;;Type 3 request received from baovo@node2.supernodexp.hpc, sock=16
05/02/2018 09:42:49;0100;Server@node2;Req;;Type 5 request received from baovo@node2.supernodexp.hpc, sock=16
05/02/2018 09:42:49;0100;Server@node2;Job;13335.node2.supernodexp.hpc;enqueuing into workq, state 1 hop 1
05/02/2018 09:42:49;0008;Server@node2;Job;13335.node2.supernodexp.hpc;Job Queued at request of baovo@node2.supernodexp.hpc, owner = baovo@node2.supernodexp.hpc, job name = vec-data-cpu4, queue = workq
05/02/2018 09:42:49;0040;Server@node2;Svr;node2.supernodexp.hpc;Scheduler sent command 1
05/02/2018 09:42:49;0040;Server@node2;Svr;node2.supernodexp.hpc;Scheduler sent command 0
05/02/2018 09:42:49;0100;Server@node2;Req;;Type 21 request received from Scheduler@node2.supernodexp.hpc, sock=19
05/02/2018 09:42:49;0100;Server@node2;Req;;Type 81 request received from Scheduler@node2.supernodexp.hpc, sock=19
05/02/2018 09:42:49;0100;Server@node2;Req;;Type 71 request received from Scheduler@node2.supernodexp.hpc, sock=19
05/02/2018 09:42:49;0100;Server@node2;Req;;Type 58 request received from Scheduler@node2.supernodexp.hpc, sock=19
05/02/2018 09:42:49;0100;Server@node2;Req;;Type 20 request received from Scheduler@node2.supernodexp.hpc, sock=19
05/02/2018 09:42:49;0100;Server@node2;Req;;Type 51 request received from Scheduler@node2.supernodexp.hpc, sock=19
05/02/2018 09:42:49;0100;Server@node2;Req;;Type 11 request received from Scheduler@node2.supernodexp.hpc, sock=19
05/02/2018 09:42:49;0008;Server@node2;Job;13335.node2.supernodexp.hpc;Job Modified at request of Scheduler@node2.supernodexp.hpc
05/02/2018 09:42:55;0100;Server@node2;Req;;Type 1 request received from baovo@node2.supernodexp.hpc, sock=16
05/02/2018 09:42:55;0100;Server@node2;Req;;Type 3 request received from baovo@node2.supernodexp.hpc, sock=16
05/02/2018 09:42:55;0100;Server@node2;Req;;Type 5 request received from baovo@node2.supernodexp.hpc, sock=16
05/02/2018 09:42:55;0100;Server@node2;Job;13336.node2.supernodexp.hpc;enqueuing into workq, state 1 hop 1
05/02/2018 09:42:55;0008;Server@node2;Job;13336.node2.supernodexp.hpc;Job Queued at request of baovo@node2.supernodexp.hpc, owner = baovo@node2.supernodexp.hpc, job name = shared-vir-mem, queue = workq
05/02/2018 09:42:55;0040;Server@node2;Svr;node2.supernodexp.hpc;Scheduler sent command 1
05/02/2018 09:42:55;0040;Server@node2;Svr;node2.supernodexp.hpc;Scheduler sent command 0
05/02/2018 09:42:55;0100;Server@node2;Req;;Type 21 request received from Scheduler@node2.supernodexp.hpc, sock=19
05/02/2018 09:42:55;0100;Server@node2;Req;;Type 81 request received from Scheduler@node2.supernodexp.hpc, sock=19
05/02/2018 09:42:55;0100;Server@node2;Req;;Type 71 request received from Scheduler@node2.supernodexp.hpc, sock=19
05/02/2018 09:42:55;0100;Server@node2;Req;;Type 58 request received from Scheduler@node2.supernodexp.hpc, sock=19
05/02/2018 09:42:55;0100;Server@node2;Req;;Type 20 request received from Scheduler@node2.supernodexp.hpc, sock=19
05/02/2018 09:42:55;0100;Server@node2;Req;;Type 51 request received from Scheduler@node2.supernodexp.hpc, sock=19
05/02/2018 09:42:55;0100;Server@node2;Req;;Type 11 request received from Scheduler@node2.supernodexp.hpc, sock=19
05/02/2018 09:42:55;0008;Server@node2;Job;13336.node2.supernodexp.hpc;Job Modified at request of Scheduler@node2.supernodexp.hpc
05/02/2018 09:43:02;0080;Server@node2;Job;13309.node2.supernodexp.hpc;Obit received momhop:1 serverhop:1 state:4 substate:42
05/02/2018 09:43:03;0010;Server@node2;Job;13309.node2.supernodexp.hpc;Exit_status=0 resources_used.cpupercent=0 resources_used.cput=00:00:00 resources_used.mem=9320kb resources_used.ncpus=2 resources_used.vmem=172288kb resources_used.walltime=00:01:50
05/02/2018 09:43:03;0100;Server@node2;Job;13309.node2.supernodexp.hpc;dequeuing from workq, state 5
05/02/2018 09:43:03;0040;Server@node2;Svr;node2.supernodexp.hpc;Scheduler sent command 2
05/02/2018 09:43:03;0040;Server@node2;Svr;node2.supernodexp.hpc;Scheduler sent command 0
05/02/2018 09:43:03;0100;Server@node2;Req;;Type 21 request received from Scheduler@node2.supernodexp.hpc, sock=19
05/02/2018 09:43:03;0100;Server@node2;Req;;Type 81 request received from Scheduler@node2.supernodexp.hpc, sock=19
05/02/2018 09:43:03;0100;Server@node2;Req;;Type 71 request received from Scheduler@node2.supernodexp.hpc, sock=19
05/02/2018 09:43:03;0100;Server@node2;Req;;Type 58 request received from Scheduler@node2.supernodexp.hpc, sock=19
05/02/2018 09:43:03;0100;Server@node2;Req;;Type 20 request received from Scheduler@node2.supernodexp.hpc, sock=19
05/02/2018 09:43:03;0100;Server@node2;Req;;Type 51 request received from Scheduler@node2.supernodexp.hpc, sock=19
05/02/2018 09:43:03;0100;Server@node2;Req;;Type 23 request received from Scheduler@node2.supernodexp.hpc, sock=19
05/02/2018 09:43:03;0008;Server@node2;Job;13314.node2.supernodexp.hpc;Job Run at request of Scheduler@node2.supernodexp.hpc on exec_vnode (node3:nmics=2:ncpus=2:mem=2097152kb)
05/02/2018 09:43:03;0001;Server@node2;Svr;Server@node2;Success (0) in req_runjob2, return value of svr_startjob is 0
05/02/2018 09:43:03;0100;Server@node2;Req;;Type 23 request received from Scheduler@node2.supernodexp.hpc, sock=19
05/02/2018 09:43:03;0008;Server@node2;Job;13320.node2.supernodexp.hpc;Job Run at request of Scheduler@node2.supernodexp.hpc on exec_vnode (node3:ncpus=2:mem=2097152kb)
05/02/2018 09:43:03;0001;Server@node2;Svr;Server@node2;Success (0) in req_runjob2, return value of svr_startjob is 0
05/02/2018 09:43:03;0100;Server@node2;Req;;Type 23 request received from Scheduler@node2.supernodexp.hpc, sock=19
05/02/2018 09:43:03;0008;Server@node2;Job;13326.node2.supernodexp.hpc;Job Run at request of Scheduler@node2.supernodexp.hpc on exec_vnode (node3:ncpus=24:mem=5242880kb)
05/02/2018 09:43:03;0001;Server@node2;Svr;Server@node2;Success (0) in req_runjob2, return value of svr_startjob is 0
05/02/2018 09:43:03;0100;Server@node2;Req;;Type 11 request received from Scheduler@node2.supernodexp.hpc, sock=19
05/02/2018 09:43:03;0008;Server@node2;Job;13336.node2.supernodexp.hpc;Job Modified at request of Scheduler@node2.supernodexp.hpc
05/02/2018 09:43:07;0100;Server@node2;Req;;Type 1 request received from baovo@node2.supernodexp.hpc, sock=16
05/02/2018 09:43:07;0100;Server@node2;Req;;Type 3 request received from baovo@node2.supernodexp.hpc, sock=16
05/02/2018 09:43:07;0100;Server@node2;Req;;Type 5 request received from baovo@node2.supernodexp.hpc, sock=16
05/02/2018 09:43:07;0100;Server@node2;Job;13337.node2.supernodexp.hpc;enqueuing into workq, state 1 hop 1
05/02/2018 09:43:07;0008;Server@node2;Job;13337.node2.supernodexp.hpc;Job Queued at request of baovo@node2.supernodexp.hpc, owner = baovo@node2.supernodexp.hpc, job name = nbody-700000, queue = workq
05/02/2018 09:43:07;0040;Server@node2;Svr;node2.supernodexp.hpc;Scheduler sent command 1
05/02/2018 09:43:07;0040;Server@node2;Svr;node2.supernodexp.hpc;Scheduler sent command 0
05/02/2018 09:43:07;0100;Server@node2;Req;;Type 21 request received from Scheduler@node2.supernodexp.hpc, sock=19
05/02/2018 09:43:07;0100;Server@node2;Req;;Type 81 request received from Scheduler@node2.supernodexp.hpc, sock=19
05/02/2018 09:43:07;0100;Server@node2;Req;;Type 71 request received from Scheduler@node2.supernodexp.hpc, sock=19
05/02/2018 09:43:07;0100;Server@node2;Req;;Type 58 request received from Scheduler@node2.supernodexp.hpc, sock=19
05/02/2018 09:43:07;0100;Server@node2;Req;;Type 20 request received from Scheduler@node2.supernodexp.hpc, sock=19
05/02/2018 09:43:07;0100;Server@node2;Req;;Type 51 request received from Scheduler@node2.supernodexp.hpc, sock=19
05/02/2018 09:43:07;0100;Server@node2;Req;;Type 11 request received from Scheduler@node2.supernodexp.hpc, sock=19
05/02/2018 09:43:07;0008;Server@node2;Job;13337.node2.supernodexp.hpc;Job Modified at request of Scheduler@node2.supernodexp.hpc
05/02/2018 09:43:08;0080;Server@node2;Job;13311.node2.supernodexp.hpc;Obit received momhop:1 serverhop:1 state:4 substate:42
05/02/2018 09:43:08;0100;Server@node2;Req;;Type 1 request received from baovo@node2.supernodexp.hpc, sock=16
05/02/2018 09:43:08;0100;Server@node2;Req;;Type 3 request received from baovo@node2.supernodexp.hpc, sock=16
05/02/2018 09:43:08;0100;Server@node2;Req;;Type 5 request received from baovo@node2.supernodexp.hpc, sock=16
05/02/2018 09:43:08;0100;Server@node2;Job;13338.node2.supernodexp.hpc;enqueuing into workq, state 1 hop 1
05/02/2018 09:43:08;0008;Server@node2;Job;13338.node2.supernodexp.hpc;Job Queued at request of baovo@node2.supernodexp.hpc, owner = baovo@node2.supernodexp.hpc, job name = qe_mic_test, queue = workq
05/02/2018 09:43:08;0040;Server@node2;Svr;node2.supernodexp.hpc;Scheduler sent command 1
05/02/2018 09:43:08;0040;Server@node2;Svr;node2.supernodexp.hpc;Scheduler sent command 0
05/02/2018 09:43:08;0100;Server@node2;Req;;Type 21 request received from Scheduler@node2.supernodexp.hpc, sock=19
05/02/2018 09:43:08;0100;Server@node2;Req;;Type 81 request received from Scheduler@node2.supernodexp.hpc, sock=19
05/02/2018 09:43:08;0100;Server@node2;Req;;Type 71 request received from Scheduler@node2.supernodexp.hpc, sock=19
05/02/2018 09:43:08;0100;Server@node2;Req;;Type 58 request received from Scheduler@node2.supernodexp.hpc, sock=19
05/02/2018 09:43:08;0100;Server@node2;Req;;Type 20 request received from Scheduler@node2.supernodexp.hpc, sock=19
05/02/2018 09:43:08;0100;Server@node2;Req;;Type 51 request received from Scheduler@node2.supernodexp.hpc, sock=19
05/02/2018 09:43:08;0100;Server@node2;Req;;Type 11 request received from Scheduler@node2.supernodexp.hpc, sock=19
05/02/2018 09:43:08;0008;Server@node2;Job;13338.node2.supernodexp.hpc;Job Modified at request of Scheduler@node2.supernodexp.hpc
05/02/2018 09:43:09;0010;Server@node2;Job;13311.node2.supernodexp.hpc;Exit_status=0 resources_used.cpupercent=0 resources_used.cput=00:00:00 resources_used.mem=9412kb resources_used.ncpus=2 resources_used.vmem=171960kb resources_used.walltime=00:01:54
05/02/2018 09:43:09;0100;Server@node2;Job;13311.node2.supernodexp.hpc;dequeuing from workq, state 5
05/02/2018 09:43:09;0040;Server@node2;Svr;node2.supernodexp.hpc;Scheduler sent command 2
05/02/2018 09:43:09;0040;Server@node2;Svr;node2.supernodexp.hpc;Scheduler sent command 0
05/02/2018 09:43:09;0100;Server@node2;Req;;Type 21 request received from Scheduler@node2.supernodexp.hpc, sock=19
05/02/2018 09:43:09;0100;Server@node2;Req;;Type 81 request received from Scheduler@node2.supernodexp.hpc, sock=19
05/02/2018 09:43:09;0100;Server@node2;Req;;Type 71 request received from Scheduler@node2.supernodexp.hpc, sock=19
05/02/2018 09:43:09;0100;Server@node2;Req;;Type 58 request received from Scheduler@node2.supernodexp.hpc, sock=19
05/02/2018 09:43:09;0100;Server@node2;Req;;Type 20 request received from Scheduler@node2.supernodexp.hpc, sock=19
05/02/2018 09:43:09;0100;Server@node2;Req;;Type 51 request received from Scheduler@node2.supernodexp.hpc, sock=19
05/02/2018 09:43:09;0100;Server@node2;Req;;Type 23 request received from Scheduler@node2.supernodexp.hpc, sock=19
05/02/2018 09:43:09;0008;Server@node2;Job;13336.node2.supernodexp.hpc;Job Run at request of Scheduler@node2.supernodexp.hpc on exec_vnode (node13:nmics=2:ncpus=2:mem=2097152kb)
05/02/2018 09:43:09;0001;Server@node2;Svr;Server@node2;Success (0) in req_runjob2, return value of svr_startjob is 0
05/02/2018 09:43:09;0100;Server@node2;Req;;Type 23 request received from Scheduler@node2.supernodexp.hpc, sock=19
05/02/2018 09:43:09;0008;Server@node2;Job;13315.node2.supernodexp.hpc;Job Run at request of Scheduler@node2.supernodexp.hpc on exec_vnode (node3:ncpus=4:mem=5242880kb)
05/02/2018 09:43:09;0001;Server@node2;Svr;Server@node2;Success (0) in req_runjob2, return value of svr_startjob is 0
05/02/2018 09:43:09;0100;Server@node2;Req;;Type 23 request received from Scheduler@node2.supernodexp.hpc, sock=19
05/02/2018 09:43:09;0008;Server@node2;Job;13321.node2.supernodexp.hpc;Job Run at request of Scheduler@node2.supernodexp.hpc on exec_vnode (node13:ncpus=8:mem=5242880kb)
05/02/2018 09:43:09;0001;Server@node2;Svr;Server@node2;Success (0) in req_runjob2, return value of svr_startjob is 0
05/02/2018 09:43:09;0100;Server@node2;Req;;Type 1 request received from baovo@node2.supernodexp.hpc, sock=16
05/02/2018 09:43:09;0100;Server@node2;Req;;Type 23 request received from Scheduler@node2.supernodexp.hpc, sock=19
05/02/2018 09:43:09;0008;Server@node2;Job;13324.node2.supernodexp.hpc;Job Run at request of Scheduler@node2.supernodexp.hpc on exec_vnode (node3:ncpus=4:mem=5242880kb)
05/02/2018 09:43:09;0001;Server@node2;Svr;Server@node2;Success (0) in req_runjob2, return value of svr_startjob is 0
05/02/2018 09:43:09;0100;Server@node2;Req;;Type 3 request received from baovo@node2.supernodexp.hpc, sock=16
05/02/2018 09:43:09;0100;Server@node2;Req;;Type 23 request received from Scheduler@node2.supernodexp.hpc, sock=19
05/02/2018 09:43:09;0008;Server@node2;Job;13330.node2.supernodexp.hpc;Job Run at request of Scheduler@node2.supernodexp.hpc on exec_vnode (node14:ncpus=4:mem=5242880kb)
05/02/2018 09:43:09;0001;Server@node2;Svr;Server@node2;Success (0) in req_runjob2, return value of svr_startjob is 0
05/02/2018 09:43:09;0100;Server@node2;Req;;Type 5 request received from baovo@node2.supernodexp.hpc, sock=16
05/02/2018 09:43:09;0100;Server@node2;Job;13339.node2.supernodexp.hpc;enqueuing into workq, state 1 hop 1
05/02/2018 09:43:09;0008;Server@node2;Job;13339.node2.supernodexp.hpc;Job Queued at request of baovo@node2.supernodexp.hpc, owner = baovo@node2.supernodexp.hpc, job name = nbody-100000, queue = workq
05/02/2018 09:43:09;0100;Server@node2;Req;;Type 23 request received from Scheduler@node2.supernodexp.hpc, sock=19
05/02/2018 09:43:09;0008;Server@node2;Job;13335.node2.supernodexp.hpc;Job Run at request of Scheduler@node2.supernodexp.hpc on exec_vnode (node13:ncpus=4:mem=5242880kb)
05/02/2018 09:43:09;0001;Server@node2;Svr;Server@node2;Success (0) in req_runjob2, return value of svr_startjob is 0
05/02/2018 09:43:09;0100;Server@node2;Req;;Type 1 request received from baovo@node2.supernodexp.hpc, sock=16
05/02/2018 09:43:09;0100;Server@node2;Req;;Type 23 request received from Scheduler@node2.supernodexp.hpc, sock=19
05/02/2018 09:43:09;0008;Server@node2;Job;13316.node2.supernodexp.hpc;Job Run at request of Scheduler@node2.supernodexp.hpc on exec_vnode (node13:ncpus=8:mem=20971520kb)
05/02/2018 09:43:09;0001;Server@node2;Svr;Server@node2;Success (0) in req_runjob2, return value of svr_startjob is 0
05/02/2018 09:43:09;0100;Server@node2;Req;;Type 3 request received from baovo@node2.supernodexp.hpc, sock=16
05/02/2018 09:43:09;0100;Server@node2;Req;;Type 23 request received from Scheduler@node2.supernodexp.hpc, sock=19
05/02/2018 09:43:09;0008;Server@node2;Job;13328.node2.supernodexp.hpc;Job Run at request of Scheduler@node2.supernodexp.hpc on exec_vnode (node13:ncpus=8:mem=10485760kb)
05/02/2018 09:43:09;0001;Server@node2;Svr;Server@node2;Success (0) in req_runjob2, return value of svr_startjob is 0
05/02/2018 09:43:09;0100;Server@node2;Req;;Type 5 request received from baovo@node2.supernodexp.hpc, sock=16
05/02/2018 09:43:09;0100;Server@node2;Job;13340.node2.supernodexp.hpc;enqueuing into workq, state 1 hop 1
05/02/2018 09:43:09;0008;Server@node2;Job;13340.node2.supernodexp.hpc;Job Queued at request of baovo@node2.supernodexp.hpc, owner = baovo@node2.supernodexp.hpc, job name = vec-data-cpu4, queue = workq
05/02/2018 09:43:09;0100;Server@node2;Req;;Type 11 request received from Scheduler@node2.supernodexp.hpc, sock=19
05/02/2018 09:43:09;0008;Server@node2;Job;13332.node2.supernodexp.hpc;Job Modified at request of Scheduler@node2.supernodexp.hpc
05/02/2018 09:43:09;0040;Server@node2;Svr;node2.supernodexp.hpc;Scheduler sent command 1
05/02/2018 09:43:09;0040;Server@node2;Svr;node2.supernodexp.hpc;Scheduler sent command 0
05/02/2018 09:43:09;0100;Server@node2;Req;;Type 21 request received from Scheduler@node2.supernodexp.hpc, sock=19
05/02/2018 09:43:09;0100;Server@node2;Req;;Type 81 request received from Scheduler@node2.supernodexp.hpc, sock=19
05/02/2018 09:43:09;0100;Server@node2;Req;;Type 71 request received from Scheduler@node2.supernodexp.hpc, sock=19
05/02/2018 09:43:09;0100;Server@node2;Req;;Type 58 request received from Scheduler@node2.supernodexp.hpc, sock=19
05/02/2018 09:43:09;0100;Server@node2;Req;;Type 1 request received from baovo@node2.supernodexp.hpc, sock=16
05/02/2018 09:43:09;0100;Server@node2;Req;;Type 3 request received from baovo@node2.supernodexp.hpc, sock=16
05/02/2018 09:43:09;0100;Server@node2;Req;;Type 5 request received from baovo@node2.supernodexp.hpc, sock=16
05/02/2018 09:43:09;0100;Server@node2;Job;13341.node2.supernodexp.hpc;enqueuing into workq, state 1 hop 1
05/02/2018 09:43:09;0008;Server@node2;Job;13341.node2.supernodexp.hpc;Job Queued at request of baovo@node2.supernodexp.hpc, owner = baovo@node2.supernodexp.hpc, job name = threading-misc-histogram, queue = workq
05/02/2018 09:43:09;0100;Server@node2;Req;;Type 20 request received from Scheduler@node2.supernodexp.hpc, sock=19
05/02/2018 09:43:09;0100;Server@node2;Req;;Type 51 request received from Scheduler@node2.supernodexp.hpc, sock=19
05/02/2018 09:43:09;0100;Server@node2;Req;;Type 11 request received from Scheduler@node2.supernodexp.hpc, sock=19
05/02/2018 09:43:09;0008;Server@node2;Job;13341.node2.supernodexp.hpc;Job Modified at request of Scheduler@node2.supernodexp.hpc
05/02/2018 09:43:09;0100;Server@node2;Req;;Type 11 request received from Scheduler@node2.supernodexp.hpc, sock=19
05/02/2018 09:43:09;0008;Server@node2;Job;13340.node2.supernodexp.hpc;Job Modified at request of Scheduler@node2.supernodexp.hpc
05/02/2018 09:43:09;0100;Server@node2;Req;;Type 11 request received from Scheduler@node2.supernodexp.hpc, sock=19
05/02/2018 09:43:09;0008;Server@node2;Job;13332.node2.supernodexp.hpc;Job Modified at request of Scheduler@node2.supernodexp.hpc
05/02/2018 09:43:09;0100;Server@node2;Req;;Type 11 request received from Scheduler@node2.supernodexp.hpc, sock=19
05/02/2018 09:43:09;0008;Server@node2;Job;13339.node2.supernodexp.hpc;Job Modified at request of Scheduler@node2.supernodexp.hpc
05/02/2018 09:43:09;0040;Server@node2;Svr;node2.supernodexp.hpc;Scheduler sent command 1
05/02/2018 09:43:09;0040;Server@node2;Svr;node2.supernodexp.hpc;Scheduler sent command 0
05/02/2018 09:43:09;0100;Server@node2;Req;;Type 21 request received from Scheduler@node2.supernodexp.hpc, sock=19
05/02/2018 09:43:09;0100;Server@node2;Req;;Type 81 request received from Scheduler@node2.supernodexp.hpc, sock=19
05/02/2018 09:43:09;0100;Server@node2;Req;;Type 71 request received from Scheduler@node2.supernodexp.hpc, sock=19
05/02/2018 09:43:09;0100;Server@node2;Req;;Type 58 request received from Scheduler@node2.supernodexp.hpc, sock=19
05/02/2018 09:43:09;0100;Server@node2;Req;;Type 20 request received from Scheduler@node2.supernodexp.hpc, sock=19
05/02/2018 09:43:09;0100;Server@node2;Req;;Type 51 request received from Scheduler@node2.supernodexp.hpc, sock=19
05/02/2018 09:43:10;0100;Server@node2;Req;;Type 1 request received from baovo@node2.supernodexp.hpc, sock=16
05/02/2018 09:43:10;0100;Server@node2;Req;;Type 3 request received from baovo@node2.supernodexp.hpc, sock=16
05/02/2018 09:43:10;0100;Server@node2;Req;;Type 5 request received from baovo@node2.supernodexp.hpc, sock=16
05/02/2018 09:43:10;0100;Server@node2;Job;13342.node2.supernodexp.hpc;enqueuing into workq, state 1 hop 1
05/02/2018 09:43:10;0008;Server@node2;Job;13342.node2.supernodexp.hpc;Job Queued at request of baovo@node2.supernodexp.hpc, owner = baovo@node2.supernodexp.hpc, job name = threading-misc-histogram, queue = workq
05/02/2018 09:43:10;0040;Server@node2;Svr;node2.supernodexp.hpc;Scheduler sent command 1
05/02/2018 09:43:10;0040;Server@node2;Svr;node2.supernodexp.hpc;Scheduler sent command 0
05/02/2018 09:43:10;0100;Server@node2;Req;;Type 21 request received from Scheduler@node2.supernodexp.hpc, sock=19
