04/24/2018 00:00:00;0002;Server@node2;Svr;Log;Log opened
04/24/2018 00:00:00;0002;Server@node2;Svr;Server@node2;pbs_version=14.0.1
04/24/2018 00:00:00;0002;Server@node2;Svr;Server@node2;pbs_build=mach=N/A:security=N/A:configure_args=N/A
04/24/2018 00:00:00;0002;Server@node2;Svr;Server@node2;hostname=node2.supernodexp.hpc;pbs_leaf_name=N/A;pbs_mom_node_name=N/A
04/24/2018 00:00:00;0002;Server@node2;Svr;Server@node2;ipv4 interface lo: localhost localhost.localdomain localhost4 localhost4.localdomain4 
04/24/2018 00:00:00;0002;Server@node2;Svr;Server@node2;ipv4 interface br0: node2.supernodexp.hpc node2 supernodexp-cn02 
04/24/2018 00:00:00;0002;Server@node2;Svr;Server@node2;ipv4 interface ib0: node2.supernodexp.hpc 
04/24/2018 00:00:00;0002;Server@node2;Svr;Server@node2;ipv4 interface virbr0: node2.supernodexp.hpc 
04/24/2018 00:00:00;0002;Server@node2;Svr;Server@node2;ipv4 interface docker0: node2.supernodexp.hpc 
04/24/2018 00:00:00;0002;Server@node2;Svr;Server@node2;ipv6 interface lo: localhost localhost.localdomain localhost6 localhost6.localdomain6 
04/24/2018 00:00:00;0002;Server@node2;Svr;Server@node2;ipv6 interface eno49: node2.supernodexp.hpc 
04/24/2018 00:00:00;0002;Server@node2;Svr;Server@node2;ipv6 interface br0: node2.supernodexp.hpc 
04/24/2018 00:00:00;0002;Server@node2;Svr;Server@node2;ipv6 interface ib0: node2.supernodexp.hpc 
04/24/2018 00:00:00;0002;Server@node2;Svr;Server@node2;ipv6 interface veth1pl8819: node2.supernodexp.hpc 
04/24/2018 00:00:00;0002;Server@node2;Svr;Act;Account file /var/spool/pbs/server_priv/accounting/20180424 opened
04/24/2018 00:01:36;0080;Server@node2;Job;12185.node2.supernodexp.hpc;Obit received momhop:1 serverhop:1 state:4 substate:42
04/24/2018 00:01:36;0010;Server@node2;Job;12185.node2.supernodexp.hpc;Exit_status=0 resources_used.cpupercent=0 resources_used.cput=00:00:00 resources_used.mem=10240kb resources_used.ncpus=24 resources_used.vmem=170164kb resources_used.walltime=00:04:44
04/24/2018 00:01:36;0100;Server@node2;Job;12185.node2.supernodexp.hpc;dequeuing from workq, state 5
04/24/2018 00:01:37;0040;Server@node2;Svr;node2.supernodexp.hpc;Scheduler sent command 2
04/24/2018 00:01:37;0040;Server@node2;Svr;node2.supernodexp.hpc;Scheduler sent command 0
04/24/2018 00:01:37;0100;Server@node2;Req;;Type 21 request received from Scheduler@node2.supernodexp.hpc, sock=16
04/24/2018 00:01:37;0100;Server@node2;Req;;Type 81 request received from Scheduler@node2.supernodexp.hpc, sock=16
04/24/2018 00:01:37;0100;Server@node2;Req;;Type 71 request received from Scheduler@node2.supernodexp.hpc, sock=16
04/24/2018 00:01:37;0100;Server@node2;Req;;Type 58 request received from Scheduler@node2.supernodexp.hpc, sock=16
04/24/2018 00:01:37;0100;Server@node2;Req;;Type 20 request received from Scheduler@node2.supernodexp.hpc, sock=16
04/24/2018 00:01:37;0100;Server@node2;Req;;Type 51 request received from Scheduler@node2.supernodexp.hpc, sock=16
04/24/2018 00:02:07;0080;Server@node2;Job;12175.node2.supernodexp.hpc;Obit received momhop:1 serverhop:1 state:4 substate:42
04/24/2018 00:02:08;0010;Server@node2;Job;12175.node2.supernodexp.hpc;Exit_status=0 resources_used.cpupercent=0 resources_used.cput=00:00:00 resources_used.mem=9100kb resources_used.ncpus=24 resources_used.vmem=105088kb resources_used.walltime=00:05:35
04/24/2018 00:02:08;0100;Server@node2;Job;12175.node2.supernodexp.hpc;dequeuing from workq, state 5
04/24/2018 00:02:08;0040;Server@node2;Svr;node2.supernodexp.hpc;Scheduler sent command 2
04/24/2018 00:02:08;0040;Server@node2;Svr;node2.supernodexp.hpc;Scheduler sent command 0
04/24/2018 00:02:08;0100;Server@node2;Req;;Type 21 request received from Scheduler@node2.supernodexp.hpc, sock=16
04/24/2018 00:02:08;0100;Server@node2;Req;;Type 81 request received from Scheduler@node2.supernodexp.hpc, sock=16
04/24/2018 00:02:08;0100;Server@node2;Req;;Type 71 request received from Scheduler@node2.supernodexp.hpc, sock=16
04/24/2018 00:02:08;0100;Server@node2;Req;;Type 58 request received from Scheduler@node2.supernodexp.hpc, sock=16
04/24/2018 00:02:08;0100;Server@node2;Req;;Type 20 request received from Scheduler@node2.supernodexp.hpc, sock=16
04/24/2018 00:02:08;0100;Server@node2;Req;;Type 51 request received from Scheduler@node2.supernodexp.hpc, sock=16
04/24/2018 00:05:50;0080;Server@node2;Job;12183.node2.supernodexp.hpc;Obit received momhop:1 serverhop:1 state:4 substate:42
04/24/2018 00:05:51;0010;Server@node2;Job;12183.node2.supernodexp.hpc;Exit_status=0 resources_used.cpupercent=0 resources_used.cput=00:00:00 resources_used.mem=9428kb resources_used.ncpus=8 resources_used.vmem=170880kb resources_used.walltime=00:09:09
04/24/2018 00:05:51;0100;Server@node2;Job;12183.node2.supernodexp.hpc;dequeuing from workq, state 5
04/24/2018 00:05:51;0040;Server@node2;Svr;node2.supernodexp.hpc;Scheduler sent command 2
04/24/2018 00:05:51;0040;Server@node2;Svr;node2.supernodexp.hpc;Scheduler sent command 0
04/24/2018 00:05:51;0100;Server@node2;Req;;Type 21 request received from Scheduler@node2.supernodexp.hpc, sock=16
04/24/2018 00:05:51;0100;Server@node2;Req;;Type 81 request received from Scheduler@node2.supernodexp.hpc, sock=16
04/24/2018 00:05:51;0100;Server@node2;Req;;Type 71 request received from Scheduler@node2.supernodexp.hpc, sock=16
04/24/2018 00:05:51;0100;Server@node2;Req;;Type 58 request received from Scheduler@node2.supernodexp.hpc, sock=16
04/24/2018 00:05:51;0100;Server@node2;Req;;Type 20 request received from Scheduler@node2.supernodexp.hpc, sock=16
04/24/2018 00:05:51;0100;Server@node2;Req;;Type 51 request received from Scheduler@node2.supernodexp.hpc, sock=16
04/24/2018 00:08:11;0080;Server@node2;Job;12171.node2.supernodexp.hpc;Obit received momhop:1 serverhop:1 state:4 substate:42
04/24/2018 00:08:12;0010;Server@node2;Job;12171.node2.supernodexp.hpc;Exit_status=0 resources_used.cpupercent=0 resources_used.cput=00:00:00 resources_used.mem=9584kb resources_used.ncpus=12 resources_used.vmem=171940kb resources_used.walltime=00:15:02
04/24/2018 00:08:12;0100;Server@node2;Job;12171.node2.supernodexp.hpc;dequeuing from workq, state 5
04/24/2018 00:08:12;0040;Server@node2;Svr;node2.supernodexp.hpc;Scheduler sent command 2
04/24/2018 00:08:12;0040;Server@node2;Svr;node2.supernodexp.hpc;Scheduler sent command 0
04/24/2018 00:08:12;0100;Server@node2;Req;;Type 21 request received from Scheduler@node2.supernodexp.hpc, sock=16
04/24/2018 00:08:12;0100;Server@node2;Req;;Type 81 request received from Scheduler@node2.supernodexp.hpc, sock=16
04/24/2018 00:08:12;0100;Server@node2;Req;;Type 71 request received from Scheduler@node2.supernodexp.hpc, sock=16
04/24/2018 00:08:12;0100;Server@node2;Req;;Type 58 request received from Scheduler@node2.supernodexp.hpc, sock=16
04/24/2018 00:08:12;0100;Server@node2;Req;;Type 20 request received from Scheduler@node2.supernodexp.hpc, sock=16
04/24/2018 00:08:12;0100;Server@node2;Req;;Type 51 request received from Scheduler@node2.supernodexp.hpc, sock=16
04/24/2018 00:08:12;0100;Server@node2;Req;;Type 23 request received from Scheduler@node2.supernodexp.hpc, sock=16
04/24/2018 00:08:12;0008;Server@node2;Job;12186.node2.supernodexp.hpc;Job Run at request of Scheduler@node2.supernodexp.hpc on exec_vnode (node3:nmics=2:ncpus=2:mem=41943040kb)
04/24/2018 00:08:12;0001;Server@node2;Svr;Server@node2;Success (0) in req_runjob2, return value of svr_startjob is 0
04/24/2018 00:08:12;0100;Server@node2;Req;;Type 23 request received from Scheduler@node2.supernodexp.hpc, sock=16
04/24/2018 00:08:12;0008;Server@node2;Job;12187.node2.supernodexp.hpc;Job Run at request of Scheduler@node2.supernodexp.hpc on exec_vnode (node3:ncpus=8:mem=3145728kb)
04/24/2018 00:08:12;0001;Server@node2;Svr;Server@node2;Success (0) in req_runjob2, return value of svr_startjob is 0
04/24/2018 00:08:12;0100;Server@node2;Req;;Type 11 request received from Scheduler@node2.supernodexp.hpc, sock=16
04/24/2018 00:08:12;0008;Server@node2;Job;12188.node2.supernodexp.hpc;Job Modified at request of Scheduler@node2.supernodexp.hpc
04/24/2018 00:10:00;0080;Server@node2;Job;12186.node2.supernodexp.hpc;Obit received momhop:1 serverhop:1 state:4 substate:42
04/24/2018 00:10:00;0010;Server@node2;Job;12186.node2.supernodexp.hpc;Exit_status=0 resources_used.cpupercent=0 resources_used.cput=00:00:00 resources_used.mem=9096kb resources_used.ncpus=2 resources_used.vmem=105344kb resources_used.walltime=00:01:47
04/24/2018 00:10:00;0100;Server@node2;Job;12186.node2.supernodexp.hpc;dequeuing from workq, state 5
04/24/2018 00:10:00;0040;Server@node2;Svr;node2.supernodexp.hpc;Scheduler sent command 2
04/24/2018 00:10:00;0040;Server@node2;Svr;node2.supernodexp.hpc;Scheduler sent command 0
04/24/2018 00:10:00;0100;Server@node2;Req;;Type 21 request received from Scheduler@node2.supernodexp.hpc, sock=16
04/24/2018 00:10:00;0100;Server@node2;Req;;Type 81 request received from Scheduler@node2.supernodexp.hpc, sock=16
04/24/2018 00:10:00;0100;Server@node2;Req;;Type 71 request received from Scheduler@node2.supernodexp.hpc, sock=16
04/24/2018 00:10:00;0100;Server@node2;Req;;Type 58 request received from Scheduler@node2.supernodexp.hpc, sock=16
04/24/2018 00:10:00;0100;Server@node2;Req;;Type 20 request received from Scheduler@node2.supernodexp.hpc, sock=16
04/24/2018 00:10:00;0100;Server@node2;Req;;Type 51 request received from Scheduler@node2.supernodexp.hpc, sock=16
04/24/2018 00:10:00;0100;Server@node2;Req;;Type 23 request received from Scheduler@node2.supernodexp.hpc, sock=16
04/24/2018 00:10:00;0008;Server@node2;Job;12188.node2.supernodexp.hpc;Job Run at request of Scheduler@node2.supernodexp.hpc on exec_vnode (node3:nmics=2:ncpus=2:mem=2097152kb)
04/24/2018 00:10:01;0001;Server@node2;Svr;Server@node2;Success (0) in req_runjob2, return value of svr_startjob is 0
04/24/2018 00:10:01;0100;Server@node2;Req;;Type 23 request received from Scheduler@node2.supernodexp.hpc, sock=16
04/24/2018 00:10:01;0008;Server@node2;Job;12189.node2.supernodexp.hpc;Job Run at request of Scheduler@node2.supernodexp.hpc on exec_vnode (node3:ncpus=2:mem=2097152kb)
04/24/2018 00:10:01;0001;Server@node2;Svr;Server@node2;Success (0) in req_runjob2, return value of svr_startjob is 0
04/24/2018 00:10:01;0100;Server@node2;Req;;Type 23 request received from Scheduler@node2.supernodexp.hpc, sock=16
04/24/2018 00:10:01;0008;Server@node2;Job;12190.node2.supernodexp.hpc;Job Run at request of Scheduler@node2.supernodexp.hpc on exec_vnode (node3:ncpus=8:mem=15728640kb)
04/24/2018 00:10:01;0001;Server@node2;Svr;Server@node2;Success (0) in req_runjob2, return value of svr_startjob is 0
04/24/2018 00:10:01;0100;Server@node2;Req;;Type 23 request received from Scheduler@node2.supernodexp.hpc, sock=16
04/24/2018 00:10:01;0008;Server@node2;Job;12191.node2.supernodexp.hpc;Job Run at request of Scheduler@node2.supernodexp.hpc on exec_vnode (node3:ncpus=8:mem=10485760kb)
04/24/2018 00:10:01;0001;Server@node2;Svr;Server@node2;Success (0) in req_runjob2, return value of svr_startjob is 0
04/24/2018 00:10:01;0100;Server@node2;Req;;Type 23 request received from Scheduler@node2.supernodexp.hpc, sock=16
04/24/2018 00:10:01;0008;Server@node2;Job;12192.node2.supernodexp.hpc;Job Run at request of Scheduler@node2.supernodexp.hpc on exec_vnode (node3:ncpus=2:mem=2097152kb)
04/24/2018 00:10:01;0001;Server@node2;Svr;Server@node2;Success (0) in req_runjob2, return value of svr_startjob is 0
04/24/2018 00:10:01;0100;Server@node2;Req;;Type 23 request received from Scheduler@node2.supernodexp.hpc, sock=16
04/24/2018 00:10:01;0008;Server@node2;Job;12193.node2.supernodexp.hpc;Job Run at request of Scheduler@node2.supernodexp.hpc on exec_vnode (node3:ncpus=8:mem=20971520kb)
04/24/2018 00:10:01;0001;Server@node2;Svr;Server@node2;Success (0) in req_runjob2, return value of svr_startjob is 0
04/24/2018 00:10:01;0100;Server@node2;Req;;Type 11 request received from Scheduler@node2.supernodexp.hpc, sock=16
04/24/2018 00:10:01;0008;Server@node2;Job;12194.node2.supernodexp.hpc;Job Modified at request of Scheduler@node2.supernodexp.hpc
04/24/2018 00:10:10;0080;Server@node2;Job;12188.node2.supernodexp.hpc;Obit received momhop:1 serverhop:1 state:4 substate:42
04/24/2018 00:10:10;0080;Server@node2;Job;12189.node2.supernodexp.hpc;Obit received momhop:1 serverhop:1 state:4 substate:42
04/24/2018 00:10:11;0010;Server@node2;Job;12188.node2.supernodexp.hpc;Exit_status=0 resources_used.cpupercent=0 resources_used.cput=00:00:00 resources_used.mem=0kb resources_used.ncpus=2 resources_used.vmem=0kb resources_used.walltime=00:00:10
04/24/2018 00:10:11;0100;Server@node2;Job;12188.node2.supernodexp.hpc;dequeuing from workq, state 5
04/24/2018 00:10:11;0040;Server@node2;Svr;node2.supernodexp.hpc;Scheduler sent command 2
04/24/2018 00:10:11;0040;Server@node2;Svr;node2.supernodexp.hpc;Scheduler sent command 0
04/24/2018 00:10:11;0100;Server@node2;Req;;Type 21 request received from Scheduler@node2.supernodexp.hpc, sock=16
04/24/2018 00:10:11;0100;Server@node2;Req;;Type 81 request received from Scheduler@node2.supernodexp.hpc, sock=16
04/24/2018 00:10:11;0100;Server@node2;Req;;Type 71 request received from Scheduler@node2.supernodexp.hpc, sock=16
04/24/2018 00:10:11;0100;Server@node2;Req;;Type 58 request received from Scheduler@node2.supernodexp.hpc, sock=16
04/24/2018 00:10:11;0100;Server@node2;Req;;Type 20 request received from Scheduler@node2.supernodexp.hpc, sock=16
04/24/2018 00:10:11;0100;Server@node2;Req;;Type 51 request received from Scheduler@node2.supernodexp.hpc, sock=16
04/24/2018 00:10:11;0100;Server@node2;Req;;Type 23 request received from Scheduler@node2.supernodexp.hpc, sock=16
04/24/2018 00:10:11;0008;Server@node2;Job;12194.node2.supernodexp.hpc;Job Run at request of Scheduler@node2.supernodexp.hpc on exec_vnode (node3:nmics=2:ncpus=2:mem=41943040kb)
04/24/2018 00:10:11;0001;Server@node2;Svr;Server@node2;Success (0) in req_runjob2, return value of svr_startjob is 0
04/24/2018 00:10:11;0100;Server@node2;Req;;Type 23 request received from Scheduler@node2.supernodexp.hpc, sock=16
04/24/2018 00:10:11;0008;Server@node2;Job;12195.node2.supernodexp.hpc;Job Run at request of Scheduler@node2.supernodexp.hpc on exec_vnode (node3:ncpus=8:mem=3145728kb)
04/24/2018 00:10:11;0001;Server@node2;Svr;Server@node2;Success (0) in req_runjob2, return value of svr_startjob is 0
04/24/2018 00:10:11;0100;Server@node2;Req;;Type 23 request received from Scheduler@node2.supernodexp.hpc, sock=16
04/24/2018 00:10:11;0008;Server@node2;Job;12196.node2.supernodexp.hpc;Job Run at request of Scheduler@node2.supernodexp.hpc on exec_vnode (node13:ncpus=8:mem=3145728kb)
04/24/2018 00:10:11;0001;Server@node2;Svr;Server@node2;Success (0) in req_runjob2, return value of svr_startjob is 0
04/24/2018 00:10:11;0100;Server@node2;Req;;Type 23 request received from Scheduler@node2.supernodexp.hpc, sock=16
04/24/2018 00:10:11;0008;Server@node2;Job;12197.node2.supernodexp.hpc;Job Run at request of Scheduler@node2.supernodexp.hpc on exec_vnode (node13:ncpus=8:mem=20971520kb)
04/24/2018 00:10:11;0001;Server@node2;Svr;Server@node2;Success (0) in req_runjob2, return value of svr_startjob is 0
04/24/2018 00:10:11;0100;Server@node2;Req;;Type 23 request received from Scheduler@node2.supernodexp.hpc, sock=16
04/24/2018 00:10:11;0008;Server@node2;Job;12198.node2.supernodexp.hpc;Job Run at request of Scheduler@node2.supernodexp.hpc on exec_vnode (node13:ncpus=8:mem=20971520kb)
04/24/2018 00:10:11;0001;Server@node2;Svr;Server@node2;Success (0) in req_runjob2, return value of svr_startjob is 0
04/24/2018 00:10:11;0100;Server@node2;Req;;Type 23 request received from Scheduler@node2.supernodexp.hpc, sock=16
04/24/2018 00:10:11;0008;Server@node2;Job;12199.node2.supernodexp.hpc;Job Run at request of Scheduler@node2.supernodexp.hpc on exec_vnode (node13:ncpus=8:mem=5242880kb)
04/24/2018 00:10:11;0001;Server@node2;Svr;Server@node2;Success (0) in req_runjob2, return value of svr_startjob is 0
04/24/2018 00:10:11;0100;Server@node2;Req;;Type 11 request received from Scheduler@node2.supernodexp.hpc, sock=16
04/24/2018 00:10:11;0008;Server@node2;Job;12200.node2.supernodexp.hpc;Job Modified at request of Scheduler@node2.supernodexp.hpc
04/24/2018 00:10:12;0010;Server@node2;Job;12189.node2.supernodexp.hpc;Exit_status=0 resources_used.cpupercent=0 resources_used.cput=00:00:00 resources_used.mem=9092kb resources_used.ncpus=2 resources_used.vmem=103036kb resources_used.walltime=00:00:10
04/24/2018 00:10:12;0100;Server@node2;Job;12189.node2.supernodexp.hpc;dequeuing from workq, state 5
04/24/2018 00:10:12;0040;Server@node2;Svr;node2.supernodexp.hpc;Scheduler sent command 2
04/24/2018 00:10:12;0040;Server@node2;Svr;node2.supernodexp.hpc;Scheduler sent command 0
04/24/2018 00:10:12;0100;Server@node2;Req;;Type 21 request received from Scheduler@node2.supernodexp.hpc, sock=16
04/24/2018 00:10:12;0100;Server@node2;Req;;Type 81 request received from Scheduler@node2.supernodexp.hpc, sock=16
04/24/2018 00:10:12;0100;Server@node2;Req;;Type 71 request received from Scheduler@node2.supernodexp.hpc, sock=16
04/24/2018 00:10:12;0100;Server@node2;Req;;Type 58 request received from Scheduler@node2.supernodexp.hpc, sock=16
04/24/2018 00:10:12;0100;Server@node2;Req;;Type 20 request received from Scheduler@node2.supernodexp.hpc, sock=16
04/24/2018 00:10:12;0100;Server@node2;Req;;Type 51 request received from Scheduler@node2.supernodexp.hpc, sock=16
04/24/2018 00:10:16;0080;Server@node2;Job;12172.node2.supernodexp.hpc;Obit received momhop:1 serverhop:1 state:4 substate:42
04/24/2018 00:10:17;0010;Server@node2;Job;12172.node2.supernodexp.hpc;Exit_status=0 resources_used.cpupercent=0 resources_used.cput=00:00:00 resources_used.mem=10016kb resources_used.ncpus=12 resources_used.vmem=104628kb resources_used.walltime=00:14:59
04/24/2018 00:10:17;0100;Server@node2;Job;12172.node2.supernodexp.hpc;dequeuing from workq, state 5
04/24/2018 00:10:17;0040;Server@node2;Svr;node2.supernodexp.hpc;Scheduler sent command 2
04/24/2018 00:10:17;0040;Server@node2;Svr;node2.supernodexp.hpc;Scheduler sent command 0
04/24/2018 00:10:17;0100;Server@node2;Req;;Type 21 request received from Scheduler@node2.supernodexp.hpc, sock=16
04/24/2018 00:10:17;0100;Server@node2;Req;;Type 81 request received from Scheduler@node2.supernodexp.hpc, sock=16
04/24/2018 00:10:17;0100;Server@node2;Req;;Type 71 request received from Scheduler@node2.supernodexp.hpc, sock=16
04/24/2018 00:10:17;0100;Server@node2;Req;;Type 58 request received from Scheduler@node2.supernodexp.hpc, sock=16
04/24/2018 00:10:18;0100;Server@node2;Req;;Type 20 request received from Scheduler@node2.supernodexp.hpc, sock=16
04/24/2018 00:10:18;0100;Server@node2;Req;;Type 51 request received from Scheduler@node2.supernodexp.hpc, sock=16
04/24/2018 00:10:18;0100;Server@node2;Req;;Type 23 request received from Scheduler@node2.supernodexp.hpc, sock=16
04/24/2018 00:10:18;0008;Server@node2;Job;12200.node2.supernodexp.hpc;Job Run at request of Scheduler@node2.supernodexp.hpc on exec_vnode (node13:ncpus=8:mem=10485760kb)
04/24/2018 00:10:18;0001;Server@node2;Svr;Server@node2;Success (0) in req_runjob2, return value of svr_startjob is 0
04/24/2018 00:10:18;0100;Server@node2;Req;;Type 23 request received from Scheduler@node2.supernodexp.hpc, sock=16
04/24/2018 00:10:18;0008;Server@node2;Job;12201.node2.supernodexp.hpc;Job Run at request of Scheduler@node2.supernodexp.hpc on exec_vnode (node13:ncpus=8:mem=20971520kb)
04/24/2018 00:10:18;0001;Server@node2;Svr;Server@node2;Success (0) in req_runjob2, return value of svr_startjob is 0
04/24/2018 00:10:18;0100;Server@node2;Req;;Type 11 request received from Scheduler@node2.supernodexp.hpc, sock=16
04/24/2018 00:10:18;0008;Server@node2;Job;12202.node2.supernodexp.hpc;Job Modified at request of Scheduler@node2.supernodexp.hpc
04/24/2018 00:10:18;0080;Server@node2;Job;12192.node2.supernodexp.hpc;Obit received momhop:1 serverhop:1 state:4 substate:42
04/24/2018 00:10:19;0010;Server@node2;Job;12192.node2.supernodexp.hpc;Exit_status=0 resources_used.cpupercent=0 resources_used.cput=00:00:00 resources_used.mem=9092kb resources_used.ncpus=2 resources_used.vmem=105344kb resources_used.walltime=00:00:18
04/24/2018 00:10:19;0100;Server@node2;Job;12192.node2.supernodexp.hpc;dequeuing from workq, state 5
04/24/2018 00:10:19;0040;Server@node2;Svr;node2.supernodexp.hpc;Scheduler sent command 2
04/24/2018 00:10:19;0040;Server@node2;Svr;node2.supernodexp.hpc;Scheduler sent command 0
04/24/2018 00:10:19;0100;Server@node2;Req;;Type 21 request received from Scheduler@node2.supernodexp.hpc, sock=16
04/24/2018 00:10:19;0100;Server@node2;Req;;Type 81 request received from Scheduler@node2.supernodexp.hpc, sock=16
04/24/2018 00:10:19;0100;Server@node2;Req;;Type 71 request received from Scheduler@node2.supernodexp.hpc, sock=16
04/24/2018 00:10:19;0100;Server@node2;Req;;Type 58 request received from Scheduler@node2.supernodexp.hpc, sock=16
04/24/2018 00:10:19;0100;Server@node2;Req;;Type 20 request received from Scheduler@node2.supernodexp.hpc, sock=16
04/24/2018 00:10:19;0100;Server@node2;Req;;Type 51 request received from Scheduler@node2.supernodexp.hpc, sock=16
04/24/2018 00:10:22;0080;Server@node2;Job;12201.node2.supernodexp.hpc;Obit received momhop:1 serverhop:1 state:4 substate:42
04/24/2018 00:10:23;0010;Server@node2;Job;12201.node2.supernodexp.hpc;Exit_status=0 resources_used.cpupercent=0 resources_used.cput=00:00:00 resources_used.mem=0kb resources_used.ncpus=8 resources_used.vmem=0kb resources_used.walltime=00:00:04
04/24/2018 00:10:23;0100;Server@node2;Job;12201.node2.supernodexp.hpc;dequeuing from workq, state 5
04/24/2018 00:10:23;0040;Server@node2;Svr;node2.supernodexp.hpc;Scheduler sent command 2
04/24/2018 00:10:23;0040;Server@node2;Svr;node2.supernodexp.hpc;Scheduler sent command 0
04/24/2018 00:10:23;0100;Server@node2;Req;;Type 21 request received from Scheduler@node2.supernodexp.hpc, sock=16
04/24/2018 00:10:23;0100;Server@node2;Req;;Type 81 request received from Scheduler@node2.supernodexp.hpc, sock=16
04/24/2018 00:10:23;0100;Server@node2;Req;;Type 71 request received from Scheduler@node2.supernodexp.hpc, sock=16
04/24/2018 00:10:23;0100;Server@node2;Req;;Type 58 request received from Scheduler@node2.supernodexp.hpc, sock=16
04/24/2018 00:10:23;0100;Server@node2;Req;;Type 20 request received from Scheduler@node2.supernodexp.hpc, sock=16
04/24/2018 00:10:23;0100;Server@node2;Req;;Type 51 request received from Scheduler@node2.supernodexp.hpc, sock=16
04/24/2018 00:10:23;0100;Server@node2;Req;;Type 23 request received from Scheduler@node2.supernodexp.hpc, sock=16
04/24/2018 00:10:23;0008;Server@node2;Job;12202.node2.supernodexp.hpc;Job Run at request of Scheduler@node2.supernodexp.hpc on exec_vnode (node13:nmics=2:ncpus=2:mem=41943040kb)
04/24/2018 00:10:23;0001;Server@node2;Svr;Server@node2;Success (0) in req_runjob2, return value of svr_startjob is 0
04/24/2018 00:10:23;0100;Server@node2;Req;;Type 11 request received from Scheduler@node2.supernodexp.hpc, sock=16
04/24/2018 00:10:23;0008;Server@node2;Job;12203.node2.supernodexp.hpc;Job Modified at request of Scheduler@node2.supernodexp.hpc
04/24/2018 00:10:32;0080;Server@node2;Job;12199.node2.supernodexp.hpc;Obit received momhop:1 serverhop:1 state:4 substate:42
04/24/2018 00:10:33;0010;Server@node2;Job;12199.node2.supernodexp.hpc;Exit_status=0 resources_used.cpupercent=0 resources_used.cput=00:00:00 resources_used.mem=9620kb resources_used.ncpus=8 resources_used.vmem=104628kb resources_used.walltime=00:00:23
04/24/2018 00:10:33;0100;Server@node2;Job;12199.node2.supernodexp.hpc;dequeuing from workq, state 5
04/24/2018 00:10:33;0040;Server@node2;Svr;node2.supernodexp.hpc;Scheduler sent command 2
04/24/2018 00:10:33;0040;Server@node2;Svr;node2.supernodexp.hpc;Scheduler sent command 0
04/24/2018 00:10:33;0100;Server@node2;Req;;Type 21 request received from Scheduler@node2.supernodexp.hpc, sock=16
04/24/2018 00:10:33;0100;Server@node2;Req;;Type 81 request received from Scheduler@node2.supernodexp.hpc, sock=16
04/24/2018 00:10:33;0100;Server@node2;Req;;Type 71 request received from Scheduler@node2.supernodexp.hpc, sock=16
04/24/2018 00:10:33;0100;Server@node2;Req;;Type 58 request received from Scheduler@node2.supernodexp.hpc, sock=16
04/24/2018 00:10:33;0100;Server@node2;Req;;Type 20 request received from Scheduler@node2.supernodexp.hpc, sock=16
04/24/2018 00:10:33;0100;Server@node2;Req;;Type 51 request received from Scheduler@node2.supernodexp.hpc, sock=16
04/24/2018 00:10:33;0100;Server@node2;Req;;Type 11 request received from Scheduler@node2.supernodexp.hpc, sock=16
04/24/2018 00:10:33;0008;Server@node2;Job;12203.node2.supernodexp.hpc;Job Modified at request of Scheduler@node2.supernodexp.hpc
04/24/2018 00:10:34;0080;Server@node2;Job;12191.node2.supernodexp.hpc;Obit received momhop:1 serverhop:1 state:4 substate:42
04/24/2018 00:10:35;0010;Server@node2;Job;12191.node2.supernodexp.hpc;Exit_status=0 resources_used.cpupercent=0 resources_used.cput=00:00:00 resources_used.mem=9096kb resources_used.ncpus=8 resources_used.vmem=170880kb resources_used.walltime=00:00:34
04/24/2018 00:10:35;0100;Server@node2;Job;12191.node2.supernodexp.hpc;dequeuing from workq, state 5
04/24/2018 00:10:35;0040;Server@node2;Svr;node2.supernodexp.hpc;Scheduler sent command 2
04/24/2018 00:10:35;0040;Server@node2;Svr;node2.supernodexp.hpc;Scheduler sent command 0
04/24/2018 00:10:35;0100;Server@node2;Req;;Type 21 request received from Scheduler@node2.supernodexp.hpc, sock=16
04/24/2018 00:10:35;0100;Server@node2;Req;;Type 81 request received from Scheduler@node2.supernodexp.hpc, sock=16
04/24/2018 00:10:35;0100;Server@node2;Req;;Type 71 request received from Scheduler@node2.supernodexp.hpc, sock=16
04/24/2018 00:10:35;0100;Server@node2;Req;;Type 58 request received from Scheduler@node2.supernodexp.hpc, sock=16
04/24/2018 00:10:35;0100;Server@node2;Req;;Type 20 request received from Scheduler@node2.supernodexp.hpc, sock=16
04/24/2018 00:10:35;0100;Server@node2;Req;;Type 51 request received from Scheduler@node2.supernodexp.hpc, sock=16
04/24/2018 00:10:44;0080;Server@node2;Job;12198.node2.supernodexp.hpc;Obit received momhop:1 serverhop:1 state:4 substate:42
04/24/2018 00:10:44;0080;Server@node2;Job;12197.node2.supernodexp.hpc;Obit received momhop:1 serverhop:1 state:4 substate:42
04/24/2018 00:10:45;0010;Server@node2;Job;12198.node2.supernodexp.hpc;Exit_status=0 resources_used.cpupercent=0 resources_used.cput=00:00:00 resources_used.mem=11916kb resources_used.ncpus=8 resources_used.vmem=448816kb resources_used.walltime=00:00:34
04/24/2018 00:10:45;0100;Server@node2;Job;12198.node2.supernodexp.hpc;dequeuing from workq, state 5
04/24/2018 00:10:45;0040;Server@node2;Svr;node2.supernodexp.hpc;Scheduler sent command 2
04/24/2018 00:10:45;0040;Server@node2;Svr;node2.supernodexp.hpc;Scheduler sent command 0
04/24/2018 00:10:45;0100;Server@node2;Req;;Type 21 request received from Scheduler@node2.supernodexp.hpc, sock=16
04/24/2018 00:10:45;0100;Server@node2;Req;;Type 81 request received from Scheduler@node2.supernodexp.hpc, sock=16
04/24/2018 00:10:45;0100;Server@node2;Req;;Type 71 request received from Scheduler@node2.supernodexp.hpc, sock=16
04/24/2018 00:10:45;0100;Server@node2;Req;;Type 58 request received from Scheduler@node2.supernodexp.hpc, sock=16
04/24/2018 00:10:45;0100;Server@node2;Req;;Type 20 request received from Scheduler@node2.supernodexp.hpc, sock=16
04/24/2018 00:10:45;0100;Server@node2;Req;;Type 51 request received from Scheduler@node2.supernodexp.hpc, sock=16
04/24/2018 00:10:45;0010;Server@node2;Job;12197.node2.supernodexp.hpc;Exit_status=0 resources_used.cpupercent=0 resources_used.cput=00:00:00 resources_used.mem=9400kb resources_used.ncpus=8 resources_used.vmem=173624kb resources_used.walltime=00:00:35
04/24/2018 00:10:45;0100;Server@node2;Job;12197.node2.supernodexp.hpc;dequeuing from workq, state 5
04/24/2018 00:10:45;0040;Server@node2;Svr;node2.supernodexp.hpc;Scheduler sent command 2
04/24/2018 00:10:45;0040;Server@node2;Svr;node2.supernodexp.hpc;Scheduler sent command 0
04/24/2018 00:10:45;0100;Server@node2;Req;;Type 21 request received from Scheduler@node2.supernodexp.hpc, sock=16
04/24/2018 00:10:45;0100;Server@node2;Req;;Type 81 request received from Scheduler@node2.supernodexp.hpc, sock=16
04/24/2018 00:10:45;0100;Server@node2;Req;;Type 71 request received from Scheduler@node2.supernodexp.hpc, sock=16
04/24/2018 00:10:45;0100;Server@node2;Req;;Type 58 request received from Scheduler@node2.supernodexp.hpc, sock=16
04/24/2018 00:10:45;0100;Server@node2;Req;;Type 20 request received from Scheduler@node2.supernodexp.hpc, sock=16
04/24/2018 00:10:45;0100;Server@node2;Req;;Type 51 request received from Scheduler@node2.supernodexp.hpc, sock=16
04/24/2018 00:10:45;0100;Server@node2;Req;;Type 23 request received from Scheduler@node2.supernodexp.hpc, sock=16
04/24/2018 00:10:45;0008;Server@node2;Job;12203.node2.supernodexp.hpc;Job Run at request of Scheduler@node2.supernodexp.hpc on exec_vnode (node13:ncpus=24:mem=5242880kb)
04/24/2018 00:10:45;0001;Server@node2;Svr;Server@node2;Success (0) in req_runjob2, return value of svr_startjob is 0
04/24/2018 00:10:45;0100;Server@node2;Req;;Type 23 request received from Scheduler@node2.supernodexp.hpc, sock=16
04/24/2018 00:10:45;0008;Server@node2;Job;12204.node2.supernodexp.hpc;Job Run at request of Scheduler@node2.supernodexp.hpc on exec_vnode (node3:ncpus=12:mem=20971520kb)
04/24/2018 00:10:45;0001;Server@node2;Svr;Server@node2;Success (0) in req_runjob2, return value of svr_startjob is 0
04/24/2018 00:10:45;0100;Server@node2;Req;;Type 11 request received from Scheduler@node2.supernodexp.hpc, sock=16
04/24/2018 00:10:45;0008;Server@node2;Job;12205.node2.supernodexp.hpc;Job Modified at request of Scheduler@node2.supernodexp.hpc
04/24/2018 00:10:48;0080;Server@node2;Job;12200.node2.supernodexp.hpc;Obit received momhop:1 serverhop:1 state:4 substate:42
04/24/2018 00:10:48;0080;Server@node2;Job;12193.node2.supernodexp.hpc;Obit received momhop:1 serverhop:1 state:4 substate:42
04/24/2018 00:10:49;0010;Server@node2;Job;12200.node2.supernodexp.hpc;Exit_status=0 resources_used.cpupercent=0 resources_used.cput=00:00:00 resources_used.mem=9620kb resources_used.ncpus=8 resources_used.vmem=108088kb resources_used.walltime=00:00:31
04/24/2018 00:10:49;0100;Server@node2;Job;12200.node2.supernodexp.hpc;dequeuing from workq, state 5
04/24/2018 00:10:49;0040;Server@node2;Svr;node2.supernodexp.hpc;Scheduler sent command 2
04/24/2018 00:10:49;0040;Server@node2;Svr;node2.supernodexp.hpc;Scheduler sent command 0
04/24/2018 00:10:49;0100;Server@node2;Req;;Type 21 request received from Scheduler@node2.supernodexp.hpc, sock=16
04/24/2018 00:10:49;0100;Server@node2;Req;;Type 81 request received from Scheduler@node2.supernodexp.hpc, sock=16
04/24/2018 00:10:49;0100;Server@node2;Req;;Type 71 request received from Scheduler@node2.supernodexp.hpc, sock=16
04/24/2018 00:10:49;0100;Server@node2;Req;;Type 58 request received from Scheduler@node2.supernodexp.hpc, sock=16
04/24/2018 00:10:49;0100;Server@node2;Req;;Type 20 request received from Scheduler@node2.supernodexp.hpc, sock=16
04/24/2018 00:10:49;0100;Server@node2;Req;;Type 51 request received from Scheduler@node2.supernodexp.hpc, sock=16
04/24/2018 00:10:50;0010;Server@node2;Job;12193.node2.supernodexp.hpc;Exit_status=0 resources_used.cpupercent=0 resources_used.cput=00:00:00 resources_used.mem=9052kb resources_used.ncpus=8 resources_used.vmem=172288kb resources_used.walltime=00:00:48
04/24/2018 00:10:50;0100;Server@node2;Job;12193.node2.supernodexp.hpc;dequeuing from workq, state 5
04/24/2018 00:10:50;0040;Server@node2;Svr;node2.supernodexp.hpc;Scheduler sent command 2
04/24/2018 00:10:50;0040;Server@node2;Svr;node2.supernodexp.hpc;Scheduler sent command 0
04/24/2018 00:10:50;0100;Server@node2;Req;;Type 21 request received from Scheduler@node2.supernodexp.hpc, sock=16
04/24/2018 00:10:50;0100;Server@node2;Req;;Type 81 request received from Scheduler@node2.supernodexp.hpc, sock=16
04/24/2018 00:10:50;0100;Server@node2;Req;;Type 71 request received from Scheduler@node2.supernodexp.hpc, sock=16
04/24/2018 00:10:50;0100;Server@node2;Req;;Type 58 request received from Scheduler@node2.supernodexp.hpc, sock=16
04/24/2018 00:10:50;0100;Server@node2;Req;;Type 20 request received from Scheduler@node2.supernodexp.hpc, sock=16
04/24/2018 00:10:50;0100;Server@node2;Req;;Type 51 request received from Scheduler@node2.supernodexp.hpc, sock=16
04/24/2018 00:12:07;0080;Server@node2;Job;12194.node2.supernodexp.hpc;Obit received momhop:1 serverhop:1 state:4 substate:42
04/24/2018 00:12:07;0010;Server@node2;Job;12194.node2.supernodexp.hpc;Exit_status=0 resources_used.cpupercent=0 resources_used.cput=00:00:00 resources_used.mem=9324kb resources_used.ncpus=2 resources_used.vmem=172032kb resources_used.walltime=00:01:56
04/24/2018 00:12:07;0100;Server@node2;Job;12194.node2.supernodexp.hpc;dequeuing from workq, state 5
04/24/2018 00:12:07;0040;Server@node2;Svr;node2.supernodexp.hpc;Scheduler sent command 2
04/24/2018 00:12:07;0040;Server@node2;Svr;node2.supernodexp.hpc;Scheduler sent command 0
04/24/2018 00:12:07;0100;Server@node2;Req;;Type 21 request received from Scheduler@node2.supernodexp.hpc, sock=16
04/24/2018 00:12:07;0100;Server@node2;Req;;Type 81 request received from Scheduler@node2.supernodexp.hpc, sock=16
04/24/2018 00:12:07;0100;Server@node2;Req;;Type 71 request received from Scheduler@node2.supernodexp.hpc, sock=16
04/24/2018 00:12:07;0100;Server@node2;Req;;Type 58 request received from Scheduler@node2.supernodexp.hpc, sock=16
04/24/2018 00:12:08;0100;Server@node2;Req;;Type 20 request received from Scheduler@node2.supernodexp.hpc, sock=16
04/24/2018 00:12:08;0100;Server@node2;Req;;Type 51 request received from Scheduler@node2.supernodexp.hpc, sock=16
04/24/2018 00:12:08;0100;Server@node2;Req;;Type 23 request received from Scheduler@node2.supernodexp.hpc, sock=16
04/24/2018 00:12:08;0008;Server@node2;Job;12205.node2.supernodexp.hpc;Job Run at request of Scheduler@node2.supernodexp.hpc on exec_vnode (node3:nmics=2:ncpus=2:mem=2097152kb)
04/24/2018 00:12:08;0001;Server@node2;Svr;Server@node2;Success (0) in req_runjob2, return value of svr_startjob is 0
04/24/2018 00:12:08;0100;Server@node2;Req;;Type 23 request received from Scheduler@node2.supernodexp.hpc, sock=16
04/24/2018 00:12:08;0008;Server@node2;Job;12206.node2.supernodexp.hpc;Job Run at request of Scheduler@node2.supernodexp.hpc on exec_vnode (node3:ncpus=8:mem=5242880kb)
04/24/2018 00:12:08;0001;Server@node2;Svr;Server@node2;Success (0) in req_runjob2, return value of svr_startjob is 0
04/24/2018 00:12:08;0100;Server@node2;Req;;Type 23 request received from Scheduler@node2.supernodexp.hpc, sock=16
04/24/2018 00:12:08;0008;Server@node2;Job;12207.node2.supernodexp.hpc;Job Run at request of Scheduler@node2.supernodexp.hpc on exec_vnode (node14:ncpus=4:mem=5242880kb)
04/24/2018 00:12:08;0001;Server@node2;Svr;Server@node2;Success (0) in req_runjob2, return value of svr_startjob is 0
04/24/2018 00:12:08;0100;Server@node2;Req;;Type 23 request received from Scheduler@node2.supernodexp.hpc, sock=16
04/24/2018 00:12:08;0008;Server@node2;Job;12208.node2.supernodexp.hpc;Job Run at request of Scheduler@node2.supernodexp.hpc on exec_vnode (node13:ncpus=12:mem=20971520kb)
04/24/2018 00:12:08;0001;Server@node2;Svr;Server@node2;Success (0) in req_runjob2, return value of svr_startjob is 0
04/24/2018 00:12:08;0100;Server@node2;Req;;Type 11 request received from Scheduler@node2.supernodexp.hpc, sock=16
04/24/2018 00:12:08;0008;Server@node2;Job;12209.node2.supernodexp.hpc;Job Modified at request of Scheduler@node2.supernodexp.hpc
04/24/2018 00:12:12;0080;Server@node2;Job;12202.node2.supernodexp.hpc;Obit received momhop:1 serverhop:1 state:4 substate:42
04/24/2018 00:12:13;0010;Server@node2;Job;12202.node2.supernodexp.hpc;Exit_status=0 resources_used.cpupercent=0 resources_used.cput=00:00:00 resources_used.mem=9616kb resources_used.ncpus=2 resources_used.vmem=172216kb resources_used.walltime=00:01:50
04/24/2018 00:12:13;0100;Server@node2;Job;12202.node2.supernodexp.hpc;dequeuing from workq, state 5
04/24/2018 00:12:13;0040;Server@node2;Svr;node2.supernodexp.hpc;Scheduler sent command 2
04/24/2018 00:12:13;0040;Server@node2;Svr;node2.supernodexp.hpc;Scheduler sent command 0
04/24/2018 00:12:13;0100;Server@node2;Req;;Type 21 request received from Scheduler@node2.supernodexp.hpc, sock=16
04/24/2018 00:12:13;0100;Server@node2;Req;;Type 81 request received from Scheduler@node2.supernodexp.hpc, sock=16
04/24/2018 00:12:13;0100;Server@node2;Req;;Type 71 request received from Scheduler@node2.supernodexp.hpc, sock=16
04/24/2018 00:12:13;0100;Server@node2;Req;;Type 58 request received from Scheduler@node2.supernodexp.hpc, sock=16
04/24/2018 00:12:13;0100;Server@node2;Req;;Type 20 request received from Scheduler@node2.supernodexp.hpc, sock=16
04/24/2018 00:12:13;0100;Server@node2;Req;;Type 51 request received from Scheduler@node2.supernodexp.hpc, sock=16
04/24/2018 00:12:13;0100;Server@node2;Req;;Type 11 request received from Scheduler@node2.supernodexp.hpc, sock=16
04/24/2018 00:12:13;0008;Server@node2;Job;12209.node2.supernodexp.hpc;Job Modified at request of Scheduler@node2.supernodexp.hpc
04/24/2018 00:12:22;0080;Server@node2;Job;12207.node2.supernodexp.hpc;Obit received momhop:1 serverhop:1 state:4 substate:42
04/24/2018 00:12:23;0010;Server@node2;Job;12207.node2.supernodexp.hpc;Exit_status=0 resources_used.cpupercent=0 resources_used.cput=00:00:00 resources_used.mem=9384kb resources_used.ncpus=4 resources_used.vmem=102576kb resources_used.walltime=00:00:16
04/24/2018 00:12:23;0100;Server@node2;Job;12207.node2.supernodexp.hpc;dequeuing from workq, state 5
04/24/2018 00:12:23;0040;Server@node2;Svr;node2.supernodexp.hpc;Scheduler sent command 2
04/24/2018 00:12:23;0040;Server@node2;Svr;node2.supernodexp.hpc;Scheduler sent command 0
04/24/2018 00:12:23;0100;Server@node2;Req;;Type 21 request received from Scheduler@node2.supernodexp.hpc, sock=16
04/24/2018 00:12:23;0100;Server@node2;Req;;Type 81 request received from Scheduler@node2.supernodexp.hpc, sock=16
04/24/2018 00:12:23;0100;Server@node2;Req;;Type 71 request received from Scheduler@node2.supernodexp.hpc, sock=16
04/24/2018 00:12:23;0100;Server@node2;Req;;Type 58 request received from Scheduler@node2.supernodexp.hpc, sock=16
04/24/2018 00:12:23;0100;Server@node2;Req;;Type 20 request received from Scheduler@node2.supernodexp.hpc, sock=16
04/24/2018 00:12:23;0100;Server@node2;Req;;Type 51 request received from Scheduler@node2.supernodexp.hpc, sock=16
04/24/2018 00:12:23;0100;Server@node2;Req;;Type 11 request received from Scheduler@node2.supernodexp.hpc, sock=16
04/24/2018 00:12:23;0008;Server@node2;Job;12209.node2.supernodexp.hpc;Job Modified at request of Scheduler@node2.supernodexp.hpc
04/24/2018 00:12:26;0080;Server@node2;Job;12205.node2.supernodexp.hpc;Obit received momhop:1 serverhop:1 state:4 substate:42
04/24/2018 00:12:27;0010;Server@node2;Job;12205.node2.supernodexp.hpc;Exit_status=0 resources_used.cpupercent=0 resources_used.cput=00:00:00 resources_used.mem=0kb resources_used.ncpus=2 resources_used.vmem=0kb resources_used.walltime=00:00:19
04/24/2018 00:12:27;0100;Server@node2;Job;12205.node2.supernodexp.hpc;dequeuing from workq, state 5
04/24/2018 00:12:27;0040;Server@node2;Svr;node2.supernodexp.hpc;Scheduler sent command 2
04/24/2018 00:12:27;0040;Server@node2;Svr;node2.supernodexp.hpc;Scheduler sent command 0
04/24/2018 00:12:27;0100;Server@node2;Req;;Type 21 request received from Scheduler@node2.supernodexp.hpc, sock=16
04/24/2018 00:12:27;0100;Server@node2;Req;;Type 81 request received from Scheduler@node2.supernodexp.hpc, sock=16
04/24/2018 00:12:27;0100;Server@node2;Req;;Type 71 request received from Scheduler@node2.supernodexp.hpc, sock=16
04/24/2018 00:12:27;0100;Server@node2;Req;;Type 58 request received from Scheduler@node2.supernodexp.hpc, sock=16
04/24/2018 00:12:27;0100;Server@node2;Req;;Type 20 request received from Scheduler@node2.supernodexp.hpc, sock=16
04/24/2018 00:12:27;0100;Server@node2;Req;;Type 51 request received from Scheduler@node2.supernodexp.hpc, sock=16
04/24/2018 00:12:27;0100;Server@node2;Req;;Type 11 request received from Scheduler@node2.supernodexp.hpc, sock=16
04/24/2018 00:12:27;0008;Server@node2;Job;12209.node2.supernodexp.hpc;Job Modified at request of Scheduler@node2.supernodexp.hpc
04/24/2018 00:12:35;0080;Server@node2;Job;12206.node2.supernodexp.hpc;Obit received momhop:1 serverhop:1 state:4 substate:42
04/24/2018 00:12:36;0010;Server@node2;Job;12206.node2.supernodexp.hpc;Exit_status=0 resources_used.cpupercent=0 resources_used.cput=00:00:00 resources_used.mem=9348kb resources_used.ncpus=8 resources_used.vmem=106752kb resources_used.walltime=00:00:27
04/24/2018 00:12:36;0100;Server@node2;Job;12206.node2.supernodexp.hpc;dequeuing from workq, state 5
04/24/2018 00:12:36;0040;Server@node2;Svr;node2.supernodexp.hpc;Scheduler sent command 2
04/24/2018 00:12:36;0040;Server@node2;Svr;node2.supernodexp.hpc;Scheduler sent command 0
04/24/2018 00:12:36;0100;Server@node2;Req;;Type 21 request received from Scheduler@node2.supernodexp.hpc, sock=16
04/24/2018 00:12:36;0100;Server@node2;Req;;Type 81 request received from Scheduler@node2.supernodexp.hpc, sock=16
04/24/2018 00:12:36;0100;Server@node2;Req;;Type 71 request received from Scheduler@node2.supernodexp.hpc, sock=16
04/24/2018 00:12:36;0100;Server@node2;Req;;Type 58 request received from Scheduler@node2.supernodexp.hpc, sock=16
04/24/2018 00:12:36;0100;Server@node2;Req;;Type 20 request received from Scheduler@node2.supernodexp.hpc, sock=16
04/24/2018 00:12:36;0100;Server@node2;Req;;Type 51 request received from Scheduler@node2.supernodexp.hpc, sock=16
04/24/2018 00:12:36;0100;Server@node2;Req;;Type 23 request received from Scheduler@node2.supernodexp.hpc, sock=16
04/24/2018 00:12:36;0008;Server@node2;Job;12209.node2.supernodexp.hpc;Job Run at request of Scheduler@node2.supernodexp.hpc on exec_vnode (node3:ncpus=12:mem=5242880kb)
04/24/2018 00:12:36;0001;Server@node2;Svr;Server@node2;Success (0) in req_runjob2, return value of svr_startjob is 0
04/24/2018 00:12:36;0100;Server@node2;Req;;Type 11 request received from Scheduler@node2.supernodexp.hpc, sock=16
04/24/2018 00:12:36;0008;Server@node2;Job;12210.node2.supernodexp.hpc;Job Modified at request of Scheduler@node2.supernodexp.hpc
04/24/2018 00:15:11;0080;Server@node2;Job;12187.node2.supernodexp.hpc;Obit received momhop:1 serverhop:1 state:4 substate:42
04/24/2018 00:15:12;0010;Server@node2;Job;12187.node2.supernodexp.hpc;Exit_status=271 resources_used.cpupercent=0 resources_used.cput=00:00:00 resources_used.mem=9104kb resources_used.ncpus=8 resources_used.vmem=171940kb resources_used.walltime=00:06:59
04/24/2018 00:15:12;0100;Server@node2;Job;12187.node2.supernodexp.hpc;dequeuing from workq, state 5
04/24/2018 00:15:12;0040;Server@node2;Svr;node2.supernodexp.hpc;Scheduler sent command 2
04/24/2018 00:15:12;0040;Server@node2;Svr;node2.supernodexp.hpc;Scheduler sent command 0
04/24/2018 00:15:12;0100;Server@node2;Req;;Type 21 request received from Scheduler@node2.supernodexp.hpc, sock=16
04/24/2018 00:15:12;0100;Server@node2;Req;;Type 81 request received from Scheduler@node2.supernodexp.hpc, sock=16
04/24/2018 00:15:12;0100;Server@node2;Req;;Type 71 request received from Scheduler@node2.supernodexp.hpc, sock=16
04/24/2018 00:15:12;0100;Server@node2;Req;;Type 58 request received from Scheduler@node2.supernodexp.hpc, sock=16
04/24/2018 00:15:12;0100;Server@node2;Req;;Type 20 request received from Scheduler@node2.supernodexp.hpc, sock=16
04/24/2018 00:15:12;0100;Server@node2;Req;;Type 51 request received from Scheduler@node2.supernodexp.hpc, sock=16
04/24/2018 00:15:12;0100;Server@node2;Req;;Type 11 request received from Scheduler@node2.supernodexp.hpc, sock=16
04/24/2018 00:15:12;0008;Server@node2;Job;12210.node2.supernodexp.hpc;Job Modified at request of Scheduler@node2.supernodexp.hpc
04/24/2018 00:15:52;0080;Server@node2;Job;12203.node2.supernodexp.hpc;Obit received momhop:1 serverhop:1 state:4 substate:42
04/24/2018 00:15:53;0010;Server@node2;Job;12203.node2.supernodexp.hpc;Exit_status=0 resources_used.cpupercent=0 resources_used.cput=00:00:00 resources_used.mem=9200kb resources_used.ncpus=24 resources_used.vmem=102576kb resources_used.walltime=00:05:07
04/24/2018 00:15:53;0100;Server@node2;Job;12203.node2.supernodexp.hpc;dequeuing from workq, state 5
04/24/2018 00:15:53;0040;Server@node2;Svr;node2.supernodexp.hpc;Scheduler sent command 2
04/24/2018 00:15:53;0040;Server@node2;Svr;node2.supernodexp.hpc;Scheduler sent command 0
04/24/2018 00:15:53;0100;Server@node2;Req;;Type 21 request received from Scheduler@node2.supernodexp.hpc, sock=16
04/24/2018 00:15:53;0100;Server@node2;Req;;Type 81 request received from Scheduler@node2.supernodexp.hpc, sock=16
04/24/2018 00:15:53;0100;Server@node2;Req;;Type 71 request received from Scheduler@node2.supernodexp.hpc, sock=16
04/24/2018 00:15:53;0100;Server@node2;Req;;Type 58 request received from Scheduler@node2.supernodexp.hpc, sock=16
04/24/2018 00:15:53;0100;Server@node2;Req;;Type 20 request received from Scheduler@node2.supernodexp.hpc, sock=16
04/24/2018 00:15:53;0100;Server@node2;Req;;Type 51 request received from Scheduler@node2.supernodexp.hpc, sock=16
04/24/2018 00:15:53;0100;Server@node2;Req;;Type 23 request received from Scheduler@node2.supernodexp.hpc, sock=16
04/24/2018 00:15:53;0008;Server@node2;Job;12210.node2.supernodexp.hpc;Job Run at request of Scheduler@node2.supernodexp.hpc on exec_vnode (node13:ncpus=12:mem=5242880kb)
04/24/2018 00:15:53;0001;Server@node2;Svr;Server@node2;Success (0) in req_runjob2, return value of svr_startjob is 0
04/24/2018 00:15:53;0100;Server@node2;Req;;Type 23 request received from Scheduler@node2.supernodexp.hpc, sock=16
04/24/2018 00:15:53;0008;Server@node2;Job;12211.node2.supernodexp.hpc;Job Run at request of Scheduler@node2.supernodexp.hpc on exec_vnode (node13:nmics=2:ncpus=12:mem=41943040kb)
04/24/2018 00:15:53;0001;Server@node2;Svr;Server@node2;Success (0) in req_runjob2, return value of svr_startjob is 0
04/24/2018 00:15:53;0100;Server@node2;Req;;Type 23 request received from Scheduler@node2.supernodexp.hpc, sock=16
04/24/2018 00:15:53;0008;Server@node2;Job;12212.node2.supernodexp.hpc;Job Run at request of Scheduler@node2.supernodexp.hpc on exec_vnode (node3:nmics=2:ncpus=2:mem=2097152kb)
04/24/2018 00:15:53;0001;Server@node2;Svr;Server@node2;Success (0) in req_runjob2, return value of svr_startjob is 0
04/24/2018 00:15:53;0100;Server@node2;Req;;Type 11 request received from Scheduler@node2.supernodexp.hpc, sock=16
04/24/2018 00:15:53;0008;Server@node2;Job;12213.node2.supernodexp.hpc;Job Modified at request of Scheduler@node2.supernodexp.hpc
04/24/2018 00:15:54;0080;Server@node2;Job;12196.node2.supernodexp.hpc;Obit received momhop:1 serverhop:1 state:4 substate:42
04/24/2018 00:15:55;0010;Server@node2;Job;12196.node2.supernodexp.hpc;Exit_status=0 resources_used.cpupercent=0 resources_used.cput=00:00:00 resources_used.mem=9648kb resources_used.ncpus=8 resources_used.vmem=171960kb resources_used.walltime=00:05:44
04/24/2018 00:15:55;0100;Server@node2;Job;12196.node2.supernodexp.hpc;dequeuing from workq, state 5
04/24/2018 00:15:55;0040;Server@node2;Svr;node2.supernodexp.hpc;Scheduler sent command 2
04/24/2018 00:15:55;0040;Server@node2;Svr;node2.supernodexp.hpc;Scheduler sent command 0
04/24/2018 00:15:55;0100;Server@node2;Req;;Type 21 request received from Scheduler@node2.supernodexp.hpc, sock=16
04/24/2018 00:15:55;0100;Server@node2;Req;;Type 81 request received from Scheduler@node2.supernodexp.hpc, sock=16
04/24/2018 00:15:55;0100;Server@node2;Req;;Type 71 request received from Scheduler@node2.supernodexp.hpc, sock=16
04/24/2018 00:15:55;0100;Server@node2;Req;;Type 58 request received from Scheduler@node2.supernodexp.hpc, sock=16
04/24/2018 00:15:55;0100;Server@node2;Req;;Type 20 request received from Scheduler@node2.supernodexp.hpc, sock=16
04/24/2018 00:15:55;0100;Server@node2;Req;;Type 51 request received from Scheduler@node2.supernodexp.hpc, sock=16
04/24/2018 00:15:55;0100;Server@node2;Req;;Type 23 request received from Scheduler@node2.supernodexp.hpc, sock=16
04/24/2018 00:15:55;0008;Server@node2;Job;12213.node2.supernodexp.hpc;Job Run at request of Scheduler@node2.supernodexp.hpc on exec_vnode (node13:ncpus=12:mem=20971520kb)
04/24/2018 00:15:55;0001;Server@node2;Svr;Server@node2;Success (0) in req_runjob2, return value of svr_startjob is 0
04/24/2018 00:15:55;0100;Server@node2;Req;;Type 11 request received from Scheduler@node2.supernodexp.hpc, sock=16
04/24/2018 00:15:55;0008;Server@node2;Job;12214.node2.supernodexp.hpc;Job Modified at request of Scheduler@node2.supernodexp.hpc
04/24/2018 00:15:59;0080;Server@node2;Job;12212.node2.supernodexp.hpc;Obit received momhop:1 serverhop:1 state:4 substate:42
04/24/2018 00:16:00;0010;Server@node2;Job;12212.node2.supernodexp.hpc;Exit_status=0 resources_used.cpupercent=0 resources_used.cput=00:00:00 resources_used.mem=0kb resources_used.ncpus=2 resources_used.vmem=0kb resources_used.walltime=00:00:06
04/24/2018 00:16:00;0100;Server@node2;Job;12212.node2.supernodexp.hpc;dequeuing from workq, state 5
04/24/2018 00:16:00;0040;Server@node2;Svr;node2.supernodexp.hpc;Scheduler sent command 2
04/24/2018 00:16:00;0040;Server@node2;Svr;node2.supernodexp.hpc;Scheduler sent command 0
04/24/2018 00:16:00;0100;Server@node2;Req;;Type 21 request received from Scheduler@node2.supernodexp.hpc, sock=16
04/24/2018 00:16:00;0100;Server@node2;Req;;Type 81 request received from Scheduler@node2.supernodexp.hpc, sock=16
04/24/2018 00:16:00;0100;Server@node2;Req;;Type 71 request received from Scheduler@node2.supernodexp.hpc, sock=16
04/24/2018 00:16:00;0100;Server@node2;Req;;Type 58 request received from Scheduler@node2.supernodexp.hpc, sock=16
04/24/2018 00:16:00;0100;Server@node2;Req;;Type 20 request received from Scheduler@node2.supernodexp.hpc, sock=16
04/24/2018 00:16:00;0100;Server@node2;Req;;Type 51 request received from Scheduler@node2.supernodexp.hpc, sock=16
04/24/2018 00:16:00;0100;Server@node2;Req;;Type 11 request received from Scheduler@node2.supernodexp.hpc, sock=16
04/24/2018 00:16:00;0008;Server@node2;Job;12214.node2.supernodexp.hpc;Job Modified at request of Scheduler@node2.supernodexp.hpc
04/24/2018 00:16:46;0080;Server@node2;Job;12181.node2.supernodexp.hpc;Obit received momhop:1 serverhop:1 state:4 substate:42
04/24/2018 00:16:46;0010;Server@node2;Job;12181.node2.supernodexp.hpc;Exit_status=0 resources_used.cpupercent=0 resources_used.cput=00:00:00 resources_used.mem=9652kb resources_used.ncpus=12 resources_used.vmem=170164kb resources_used.walltime=00:20:06
04/24/2018 00:16:46;0100;Server@node2;Job;12181.node2.supernodexp.hpc;dequeuing from workq, state 5
04/24/2018 00:16:46;0040;Server@node2;Svr;node2.supernodexp.hpc;Scheduler sent command 2
04/24/2018 00:16:46;0040;Server@node2;Svr;node2.supernodexp.hpc;Scheduler sent command 0
04/24/2018 00:16:46;0100;Server@node2;Req;;Type 21 request received from Scheduler@node2.supernodexp.hpc, sock=16
04/24/2018 00:16:46;0100;Server@node2;Req;;Type 81 request received from Scheduler@node2.supernodexp.hpc, sock=16
04/24/2018 00:16:46;0100;Server@node2;Req;;Type 71 request received from Scheduler@node2.supernodexp.hpc, sock=16
04/24/2018 00:16:46;0100;Server@node2;Req;;Type 58 request received from Scheduler@node2.supernodexp.hpc, sock=16
04/24/2018 00:16:46;0100;Server@node2;Req;;Type 20 request received from Scheduler@node2.supernodexp.hpc, sock=16
04/24/2018 00:16:46;0100;Server@node2;Req;;Type 51 request received from Scheduler@node2.supernodexp.hpc, sock=16
04/24/2018 00:16:47;0100;Server@node2;Req;;Type 23 request received from Scheduler@node2.supernodexp.hpc, sock=16
04/24/2018 00:16:47;0008;Server@node2;Job;12214.node2.supernodexp.hpc;Job Run at request of Scheduler@node2.supernodexp.hpc on exec_vnode (node14:ncpus=12:mem=20971520kb)
04/24/2018 00:16:47;0001;Server@node2;Svr;Server@node2;Success (0) in req_runjob2, return value of svr_startjob is 0
04/24/2018 00:16:47;0100;Server@node2;Req;;Type 23 request received from Scheduler@node2.supernodexp.hpc, sock=16
04/24/2018 00:16:47;0008;Server@node2;Job;12215.node2.supernodexp.hpc;Job Run at request of Scheduler@node2.supernodexp.hpc on exec_vnode (node3:nmics=2:ncpus=2:mem=2097152kb)
04/24/2018 00:16:47;0001;Server@node2;Svr;Server@node2;Success (0) in req_runjob2, return value of svr_startjob is 0
04/24/2018 00:16:47;0100;Server@node2;Req;;Type 23 request received from Scheduler@node2.supernodexp.hpc, sock=16
04/24/2018 00:16:47;0008;Server@node2;Job;12216.node2.supernodexp.hpc;Job Run at request of Scheduler@node2.supernodexp.hpc on exec_vnode (node3:ncpus=4:mem=5242880kb)
04/24/2018 00:16:47;0001;Server@node2;Svr;Server@node2;Success (0) in req_runjob2, return value of svr_startjob is 0
04/24/2018 00:16:47;0100;Server@node2;Req;;Type 11 request received from Scheduler@node2.supernodexp.hpc, sock=16
04/24/2018 00:16:47;0008;Server@node2;Job;12217.node2.supernodexp.hpc;Job Modified at request of Scheduler@node2.supernodexp.hpc
04/24/2018 00:16:55;0080;Server@node2;Job;12215.node2.supernodexp.hpc;Obit received momhop:1 serverhop:1 state:4 substate:42
04/24/2018 00:16:56;0080;Server@node2;Job;12204.node2.supernodexp.hpc;Obit received momhop:1 serverhop:1 state:4 substate:42
04/24/2018 00:16:56;0010;Server@node2;Job;12215.node2.supernodexp.hpc;Exit_status=0 resources_used.cpupercent=0 resources_used.cput=00:00:00 resources_used.mem=0kb resources_used.ncpus=2 resources_used.vmem=0kb resources_used.walltime=00:00:10
04/24/2018 00:16:56;0100;Server@node2;Job;12215.node2.supernodexp.hpc;dequeuing from workq, state 5
04/24/2018 00:16:56;0040;Server@node2;Svr;node2.supernodexp.hpc;Scheduler sent command 2
04/24/2018 00:16:56;0040;Server@node2;Svr;node2.supernodexp.hpc;Scheduler sent command 0
04/24/2018 00:16:56;0100;Server@node2;Req;;Type 21 request received from Scheduler@node2.supernodexp.hpc, sock=16
04/24/2018 00:16:56;0100;Server@node2;Req;;Type 81 request received from Scheduler@node2.supernodexp.hpc, sock=16
04/24/2018 00:16:56;0100;Server@node2;Req;;Type 71 request received from Scheduler@node2.supernodexp.hpc, sock=16
04/24/2018 00:16:56;0100;Server@node2;Req;;Type 58 request received from Scheduler@node2.supernodexp.hpc, sock=16
04/24/2018 00:16:56;0100;Server@node2;Req;;Type 20 request received from Scheduler@node2.supernodexp.hpc, sock=16
04/24/2018 00:16:56;0100;Server@node2;Req;;Type 51 request received from Scheduler@node2.supernodexp.hpc, sock=16
04/24/2018 00:16:56;0100;Server@node2;Req;;Type 11 request received from Scheduler@node2.supernodexp.hpc, sock=16
04/24/2018 00:16:56;0008;Server@node2;Job;12217.node2.supernodexp.hpc;Job Modified at request of Scheduler@node2.supernodexp.hpc
04/24/2018 00:16:57;0010;Server@node2;Job;12204.node2.supernodexp.hpc;Exit_status=0 resources_used.cpupercent=0 resources_used.cput=00:00:00 resources_used.mem=9092kb resources_used.ncpus=12 resources_used.vmem=103292kb resources_used.walltime=00:06:11
04/24/2018 00:16:57;0100;Server@node2;Job;12204.node2.supernodexp.hpc;dequeuing from workq, state 5
04/24/2018 00:16:57;0040;Server@node2;Svr;node2.supernodexp.hpc;Scheduler sent command 2
04/24/2018 00:16:57;0040;Server@node2;Svr;node2.supernodexp.hpc;Scheduler sent command 0
04/24/2018 00:16:57;0100;Server@node2;Req;;Type 21 request received from Scheduler@node2.supernodexp.hpc, sock=16
04/24/2018 00:16:57;0100;Server@node2;Req;;Type 81 request received from Scheduler@node2.supernodexp.hpc, sock=16
04/24/2018 00:16:57;0100;Server@node2;Req;;Type 71 request received from Scheduler@node2.supernodexp.hpc, sock=16
04/24/2018 00:16:57;0100;Server@node2;Req;;Type 58 request received from Scheduler@node2.supernodexp.hpc, sock=16
04/24/2018 00:16:57;0100;Server@node2;Req;;Type 20 request received from Scheduler@node2.supernodexp.hpc, sock=16
04/24/2018 00:16:57;0100;Server@node2;Req;;Type 51 request received from Scheduler@node2.supernodexp.hpc, sock=16
04/24/2018 00:16:57;0100;Server@node2;Req;;Type 23 request received from Scheduler@node2.supernodexp.hpc, sock=16
04/24/2018 00:16:57;0008;Server@node2;Job;12217.node2.supernodexp.hpc;Job Run at request of Scheduler@node2.supernodexp.hpc on exec_vnode (node3:ncpus=12:mem=20971520kb)
04/24/2018 00:16:57;0001;Server@node2;Svr;Server@node2;Success (0) in req_runjob2, return value of svr_startjob is 0
04/24/2018 00:16:57;0100;Server@node2;Req;;Type 11 request received from Scheduler@node2.supernodexp.hpc, sock=16
04/24/2018 00:16:57;0008;Server@node2;Job;12218.node2.supernodexp.hpc;Job Modified at request of Scheduler@node2.supernodexp.hpc
04/24/2018 00:17:11;0080;Server@node2;Job;12195.node2.supernodexp.hpc;Obit received momhop:1 serverhop:1 state:4 substate:42
04/24/2018 00:17:11;0080;Server@node2;Job;12216.node2.supernodexp.hpc;Obit received momhop:1 serverhop:1 state:4 substate:42
04/24/2018 00:17:12;0010;Server@node2;Job;12216.node2.supernodexp.hpc;Exit_status=0 resources_used.cpupercent=0 resources_used.cput=00:00:00 resources_used.mem=11148kb resources_used.ncpus=4 resources_used.vmem=103036kb resources_used.walltime=00:00:26
04/24/2018 00:17:12;0100;Server@node2;Job;12216.node2.supernodexp.hpc;dequeuing from workq, state 5
04/24/2018 00:17:12;0040;Server@node2;Svr;node2.supernodexp.hpc;Scheduler sent command 2
04/24/2018 00:17:12;0040;Server@node2;Svr;node2.supernodexp.hpc;Scheduler sent command 0
04/24/2018 00:17:12;0100;Server@node2;Req;;Type 21 request received from Scheduler@node2.supernodexp.hpc, sock=16
04/24/2018 00:17:12;0100;Server@node2;Req;;Type 81 request received from Scheduler@node2.supernodexp.hpc, sock=16
04/24/2018 00:17:12;0100;Server@node2;Req;;Type 71 request received from Scheduler@node2.supernodexp.hpc, sock=16
04/24/2018 00:17:12;0100;Server@node2;Req;;Type 58 request received from Scheduler@node2.supernodexp.hpc, sock=16
04/24/2018 00:17:12;0100;Server@node2;Req;;Type 20 request received from Scheduler@node2.supernodexp.hpc, sock=16
04/24/2018 00:17:12;0100;Server@node2;Req;;Type 51 request received from Scheduler@node2.supernodexp.hpc, sock=16
04/24/2018 00:17:12;0010;Server@node2;Job;12195.node2.supernodexp.hpc;Exit_status=271 resources_used.cpupercent=0 resources_used.cput=00:00:00 resources_used.mem=9064kb resources_used.ncpus=8 resources_used.vmem=104444kb resources_used.walltime=00:07:00
04/24/2018 00:17:12;0100;Server@node2;Job;12195.node2.supernodexp.hpc;dequeuing from workq, state 5
04/24/2018 00:17:12;0100;Server@node2;Req;;Type 11 request received from Scheduler@node2.supernodexp.hpc, sock=16
04/24/2018 00:17:12;0008;Server@node2;Job;12218.node2.supernodexp.hpc;Job Modified at request of Scheduler@node2.supernodexp.hpc
04/24/2018 00:17:12;0040;Server@node2;Svr;node2.supernodexp.hpc;Scheduler sent command 2
04/24/2018 00:17:12;0040;Server@node2;Svr;node2.supernodexp.hpc;Scheduler sent command 0
04/24/2018 00:17:12;0100;Server@node2;Req;;Type 21 request received from Scheduler@node2.supernodexp.hpc, sock=16
04/24/2018 00:17:12;0100;Server@node2;Req;;Type 81 request received from Scheduler@node2.supernodexp.hpc, sock=16
04/24/2018 00:17:12;0100;Server@node2;Req;;Type 71 request received from Scheduler@node2.supernodexp.hpc, sock=16
04/24/2018 00:17:12;0100;Server@node2;Req;;Type 58 request received from Scheduler@node2.supernodexp.hpc, sock=16
04/24/2018 00:17:12;0100;Server@node2;Req;;Type 20 request received from Scheduler@node2.supernodexp.hpc, sock=16
04/24/2018 00:17:12;0100;Server@node2;Req;;Type 51 request received from Scheduler@node2.supernodexp.hpc, sock=16
04/24/2018 00:17:12;0100;Server@node2;Req;;Type 11 request received from Scheduler@node2.supernodexp.hpc, sock=16
04/24/2018 00:17:12;0008;Server@node2;Job;12218.node2.supernodexp.hpc;Job Modified at request of Scheduler@node2.supernodexp.hpc
04/24/2018 00:18:32;0080;Server@node2;Job;12208.node2.supernodexp.hpc;Obit received momhop:1 serverhop:1 state:4 substate:42
04/24/2018 00:18:34;0080;Server@node2;Job;12174.node2.supernodexp.hpc;Obit received momhop:1 serverhop:1 state:4 substate:42
04/24/2018 00:18:35;0010;Server@node2;Job;12208.node2.supernodexp.hpc;Exit_status=0 resources_used.cpupercent=0 resources_used.cput=00:00:00 resources_used.mem=9448kb resources_used.ncpus=12 resources_used.vmem=169908kb resources_used.walltime=00:06:26
04/24/2018 00:18:35;0100;Server@node2;Job;12208.node2.supernodexp.hpc;dequeuing from workq, state 5
04/24/2018 00:18:35;0040;Server@node2;Svr;node2.supernodexp.hpc;Scheduler sent command 2
04/24/2018 00:18:35;0040;Server@node2;Svr;node2.supernodexp.hpc;Scheduler sent command 0
04/24/2018 00:18:35;0100;Server@node2;Req;;Type 21 request received from Scheduler@node2.supernodexp.hpc, sock=16
04/24/2018 00:18:35;0100;Server@node2;Req;;Type 81 request received from Scheduler@node2.supernodexp.hpc, sock=16
04/24/2018 00:18:35;0100;Server@node2;Req;;Type 71 request received from Scheduler@node2.supernodexp.hpc, sock=16
04/24/2018 00:18:35;0100;Server@node2;Req;;Type 58 request received from Scheduler@node2.supernodexp.hpc, sock=16
04/24/2018 00:18:35;0100;Server@node2;Req;;Type 20 request received from Scheduler@node2.supernodexp.hpc, sock=16
04/24/2018 00:18:35;0100;Server@node2;Req;;Type 51 request received from Scheduler@node2.supernodexp.hpc, sock=16
04/24/2018 00:18:35;0100;Server@node2;Req;;Type 11 request received from Scheduler@node2.supernodexp.hpc, sock=16
04/24/2018 00:18:35;0008;Server@node2;Job;12218.node2.supernodexp.hpc;Job Modified at request of Scheduler@node2.supernodexp.hpc
04/24/2018 00:18:35;0010;Server@node2;Job;12174.node2.supernodexp.hpc;Exit_status=2 resources_used.cpupercent=0 resources_used.cput=00:00:00 resources_used.mem=10012kb resources_used.ncpus=32 resources_used.vmem=106036kb resources_used.walltime=00:22:03
04/24/2018 00:18:35;0100;Server@node2;Job;12174.node2.supernodexp.hpc;dequeuing from workq, state 5
04/24/2018 00:18:35;0040;Server@node2;Svr;node2.supernodexp.hpc;Scheduler sent command 2
04/24/2018 00:18:35;0040;Server@node2;Svr;node2.supernodexp.hpc;Scheduler sent command 0
04/24/2018 00:18:35;0100;Server@node2;Req;;Type 21 request received from Scheduler@node2.supernodexp.hpc, sock=16
04/24/2018 00:18:35;0100;Server@node2;Req;;Type 81 request received from Scheduler@node2.supernodexp.hpc, sock=16
04/24/2018 00:18:35;0100;Server@node2;Req;;Type 71 request received from Scheduler@node2.supernodexp.hpc, sock=16
04/24/2018 00:18:35;0100;Server@node2;Req;;Type 58 request received from Scheduler@node2.supernodexp.hpc, sock=16
04/24/2018 00:18:35;0100;Server@node2;Req;;Type 20 request received from Scheduler@node2.supernodexp.hpc, sock=16
04/24/2018 00:18:35;0100;Server@node2;Req;;Type 51 request received from Scheduler@node2.supernodexp.hpc, sock=16
04/24/2018 00:18:35;0100;Server@node2;Req;;Type 23 request received from Scheduler@node2.supernodexp.hpc, sock=16
04/24/2018 00:18:35;0008;Server@node2;Job;12218.node2.supernodexp.hpc;Job Run at request of Scheduler@node2.supernodexp.hpc on exec_vnode (node14:ncpus=24:mem=5242880kb)
04/24/2018 00:18:35;0001;Server@node2;Svr;Server@node2;Success (0) in req_runjob2, return value of svr_startjob is 0
04/24/2018 00:18:35;0100;Server@node2;Req;;Type 11 request received from Scheduler@node2.supernodexp.hpc, sock=16
04/24/2018 00:18:35;0008;Server@node2;Job;12219.node2.supernodexp.hpc;Job Modified at request of Scheduler@node2.supernodexp.hpc
04/24/2018 00:18:41;0080;Server@node2;Job;12218.node2.supernodexp.hpc;Obit received momhop:1 serverhop:1 state:4 substate:42
04/24/2018 00:18:42;0010;Server@node2;Job;12218.node2.supernodexp.hpc;Exit_status=0 resources_used.cpupercent=0 resources_used.cput=00:00:00 resources_used.mem=0kb resources_used.ncpus=24 resources_used.vmem=0kb resources_used.walltime=00:00:06
04/24/2018 00:18:42;0100;Server@node2;Job;12218.node2.supernodexp.hpc;dequeuing from workq, state 5
04/24/2018 00:18:42;0040;Server@node2;Svr;node2.supernodexp.hpc;Scheduler sent command 2
04/24/2018 00:18:42;0040;Server@node2;Svr;node2.supernodexp.hpc;Scheduler sent command 0
04/24/2018 00:18:42;0100;Server@node2;Req;;Type 21 request received from Scheduler@node2.supernodexp.hpc, sock=16
04/24/2018 00:18:42;0100;Server@node2;Req;;Type 81 request received from Scheduler@node2.supernodexp.hpc, sock=16
04/24/2018 00:18:42;0100;Server@node2;Req;;Type 71 request received from Scheduler@node2.supernodexp.hpc, sock=16
04/24/2018 00:18:42;0100;Server@node2;Req;;Type 58 request received from Scheduler@node2.supernodexp.hpc, sock=16
04/24/2018 00:18:42;0100;Server@node2;Req;;Type 20 request received from Scheduler@node2.supernodexp.hpc, sock=16
04/24/2018 00:18:42;0100;Server@node2;Req;;Type 51 request received from Scheduler@node2.supernodexp.hpc, sock=16
04/24/2018 00:18:42;0100;Server@node2;Req;;Type 23 request received from Scheduler@node2.supernodexp.hpc, sock=16
04/24/2018 00:18:42;0008;Server@node2;Job;12219.node2.supernodexp.hpc;Job Run at request of Scheduler@node2.supernodexp.hpc on exec_vnode (node14:ncpus=32:nmics=2:mem=31457280kb)
04/24/2018 00:18:42;0001;Server@node2;Svr;Server@node2;Success (0) in req_runjob2, return value of svr_startjob is 0
04/24/2018 00:18:42;0100;Server@node2;Req;;Type 23 request received from Scheduler@node2.supernodexp.hpc, sock=16
04/24/2018 00:18:42;0008;Server@node2;Job;12220.node2.supernodexp.hpc;Job Run at request of Scheduler@node2.supernodexp.hpc on exec_vnode (node3:ncpus=12:mem=20971520kb)
04/24/2018 00:18:42;0001;Server@node2;Svr;Server@node2;Success (0) in req_runjob2, return value of svr_startjob is 0
04/24/2018 00:18:42;0100;Server@node2;Req;;Type 23 request received from Scheduler@node2.supernodexp.hpc, sock=16
04/24/2018 00:18:42;0008;Server@node2;Job;12221.node2.supernodexp.hpc;Job Run at request of Scheduler@node2.supernodexp.hpc on exec_vnode (node13:ncpus=8:mem=10485760kb)
04/24/2018 00:18:42;0001;Server@node2;Svr;Server@node2;Success (0) in req_runjob2, return value of svr_startjob is 0
04/24/2018 00:18:42;0100;Server@node2;Req;;Type 23 request received from Scheduler@node2.supernodexp.hpc, sock=16
04/24/2018 00:18:42;0008;Server@node2;Job;12222.node2.supernodexp.hpc;Job Run at request of Scheduler@node2.supernodexp.hpc on exec_vnode (node3:nmics=2:ncpus=2:mem=2097152kb)
04/24/2018 00:18:42;0001;Server@node2;Svr;Server@node2;Success (0) in req_runjob2, return value of svr_startjob is 0
04/24/2018 00:18:42;0100;Server@node2;Req;;Type 11 request received from Scheduler@node2.supernodexp.hpc, sock=16
04/24/2018 00:18:42;0008;Server@node2;Job;12223.node2.supernodexp.hpc;Job Modified at request of Scheduler@node2.supernodexp.hpc
04/24/2018 00:18:50;0080;Server@node2;Job;12222.node2.supernodexp.hpc;Obit received momhop:1 serverhop:1 state:4 substate:42
04/24/2018 00:18:51;0010;Server@node2;Job;12222.node2.supernodexp.hpc;Exit_status=0 resources_used.cpupercent=0 resources_used.cput=00:00:00 resources_used.mem=0kb resources_used.ncpus=2 resources_used.vmem=0kb resources_used.walltime=00:00:08
04/24/2018 00:18:51;0100;Server@node2;Job;12222.node2.supernodexp.hpc;dequeuing from workq, state 5
04/24/2018 00:18:51;0040;Server@node2;Svr;node2.supernodexp.hpc;Scheduler sent command 2
04/24/2018 00:18:51;0040;Server@node2;Svr;node2.supernodexp.hpc;Scheduler sent command 0
04/24/2018 00:18:51;0100;Server@node2;Req;;Type 21 request received from Scheduler@node2.supernodexp.hpc, sock=16
04/24/2018 00:18:51;0100;Server@node2;Req;;Type 81 request received from Scheduler@node2.supernodexp.hpc, sock=16
04/24/2018 00:18:51;0100;Server@node2;Req;;Type 71 request received from Scheduler@node2.supernodexp.hpc, sock=16
04/24/2018 00:18:51;0100;Server@node2;Req;;Type 58 request received from Scheduler@node2.supernodexp.hpc, sock=16
04/24/2018 00:18:51;0100;Server@node2;Req;;Type 20 request received from Scheduler@node2.supernodexp.hpc, sock=16
04/24/2018 00:18:51;0100;Server@node2;Req;;Type 51 request received from Scheduler@node2.supernodexp.hpc, sock=16
04/24/2018 00:19:19;0080;Server@node2;Job;12221.node2.supernodexp.hpc;Obit received momhop:1 serverhop:1 state:4 substate:42
04/24/2018 00:19:20;0010;Server@node2;Job;12221.node2.supernodexp.hpc;Exit_status=0 resources_used.cpupercent=0 resources_used.cput=00:00:00 resources_used.mem=9608kb resources_used.ncpus=8 resources_used.vmem=172216kb resources_used.walltime=00:00:36
04/24/2018 00:19:20;0100;Server@node2;Job;12221.node2.supernodexp.hpc;dequeuing from workq, state 5
04/24/2018 00:19:20;0040;Server@node2;Svr;node2.supernodexp.hpc;Scheduler sent command 2
04/24/2018 00:19:20;0040;Server@node2;Svr;node2.supernodexp.hpc;Scheduler sent command 0
04/24/2018 00:19:20;0100;Server@node2;Req;;Type 21 request received from Scheduler@node2.supernodexp.hpc, sock=16
04/24/2018 00:19:20;0100;Server@node2;Req;;Type 81 request received from Scheduler@node2.supernodexp.hpc, sock=16
04/24/2018 00:19:20;0100;Server@node2;Req;;Type 71 request received from Scheduler@node2.supernodexp.hpc, sock=16
04/24/2018 00:19:20;0100;Server@node2;Req;;Type 58 request received from Scheduler@node2.supernodexp.hpc, sock=16
04/24/2018 00:19:20;0100;Server@node2;Req;;Type 20 request received from Scheduler@node2.supernodexp.hpc, sock=16
04/24/2018 00:19:20;0100;Server@node2;Req;;Type 51 request received from Scheduler@node2.supernodexp.hpc, sock=16
04/24/2018 00:19:20;0100;Server@node2;Req;;Type 23 request received from Scheduler@node2.supernodexp.hpc, sock=16
04/24/2018 00:19:20;0008;Server@node2;Job;12223.node2.supernodexp.hpc;Job Run at request of Scheduler@node2.supernodexp.hpc on exec_vnode (node13:ncpus=8:mem=3145728kb)
04/24/2018 00:19:20;0001;Server@node2;Svr;Server@node2;Success (0) in req_runjob2, return value of svr_startjob is 0
04/24/2018 00:19:20;0100;Server@node2;Req;;Type 11 request received from Scheduler@node2.supernodexp.hpc, sock=16
04/24/2018 00:19:20;0008;Server@node2;Job;12224.node2.supernodexp.hpc;Job Modified at request of Scheduler@node2.supernodexp.hpc
04/24/2018 00:20:00;0080;Server@node2;Job;12209.node2.supernodexp.hpc;Obit received momhop:1 serverhop:1 state:4 substate:42
04/24/2018 00:20:01;0010;Server@node2;Job;12209.node2.supernodexp.hpc;Exit_status=0 resources_used.cpupercent=0 resources_used.cput=00:00:00 resources_used.mem=9080kb resources_used.ncpus=12 resources_used.vmem=103036kb resources_used.walltime=00:07:24
04/24/2018 00:20:01;0100;Server@node2;Job;12209.node2.supernodexp.hpc;dequeuing from workq, state 5
04/24/2018 00:20:01;0040;Server@node2;Svr;node2.supernodexp.hpc;Scheduler sent command 2
04/24/2018 00:20:01;0040;Server@node2;Svr;node2.supernodexp.hpc;Scheduler sent command 0
04/24/2018 00:20:01;0100;Server@node2;Req;;Type 21 request received from Scheduler@node2.supernodexp.hpc, sock=16
04/24/2018 00:20:01;0100;Server@node2;Req;;Type 81 request received from Scheduler@node2.supernodexp.hpc, sock=16
04/24/2018 00:20:01;0100;Server@node2;Req;;Type 71 request received from Scheduler@node2.supernodexp.hpc, sock=16
04/24/2018 00:20:01;0100;Server@node2;Req;;Type 58 request received from Scheduler@node2.supernodexp.hpc, sock=16
04/24/2018 00:20:01;0100;Server@node2;Req;;Type 20 request received from Scheduler@node2.supernodexp.hpc, sock=16
04/24/2018 00:20:01;0100;Server@node2;Req;;Type 51 request received from Scheduler@node2.supernodexp.hpc, sock=16
04/24/2018 00:20:01;0100;Server@node2;Req;;Type 23 request received from Scheduler@node2.supernodexp.hpc, sock=16
04/24/2018 00:20:01;0008;Server@node2;Job;12224.node2.supernodexp.hpc;Job Run at request of Scheduler@node2.supernodexp.hpc on exec_vnode (node3:ncpus=8:mem=5242880kb)
04/24/2018 00:20:01;0001;Server@node2;Svr;Server@node2;Success (0) in req_runjob2, return value of svr_startjob is 0
04/24/2018 00:20:01;0100;Server@node2;Req;;Type 23 request received from Scheduler@node2.supernodexp.hpc, sock=16
04/24/2018 00:20:01;0008;Server@node2;Job;12225.node2.supernodexp.hpc;Job Run at request of Scheduler@node2.supernodexp.hpc on exec_vnode (node3:ncpus=4:mem=5242880kb)
04/24/2018 00:20:01;0001;Server@node2;Svr;Server@node2;Success (0) in req_runjob2, return value of svr_startjob is 0
04/24/2018 00:20:01;0100;Server@node2;Req;;Type 11 request received from Scheduler@node2.supernodexp.hpc, sock=16
04/24/2018 00:20:01;0008;Server@node2;Job;12226.node2.supernodexp.hpc;Job Modified at request of Scheduler@node2.supernodexp.hpc
04/24/2018 00:20:27;0080;Server@node2;Job;12225.node2.supernodexp.hpc;Obit received momhop:1 serverhop:1 state:4 substate:42
04/24/2018 00:20:28;0010;Server@node2;Job;12225.node2.supernodexp.hpc;Exit_status=0 resources_used.cpupercent=0 resources_used.cput=00:00:00 resources_used.mem=9328kb resources_used.ncpus=4 resources_used.vmem=104444kb resources_used.walltime=00:00:25
04/24/2018 00:20:28;0100;Server@node2;Job;12225.node2.supernodexp.hpc;dequeuing from workq, state 5
04/24/2018 00:20:28;0040;Server@node2;Svr;node2.supernodexp.hpc;Scheduler sent command 2
04/24/2018 00:20:28;0040;Server@node2;Svr;node2.supernodexp.hpc;Scheduler sent command 0
04/24/2018 00:20:28;0100;Server@node2;Req;;Type 21 request received from Scheduler@node2.supernodexp.hpc, sock=16
04/24/2018 00:20:28;0100;Server@node2;Req;;Type 81 request received from Scheduler@node2.supernodexp.hpc, sock=16
04/24/2018 00:20:28;0100;Server@node2;Req;;Type 71 request received from Scheduler@node2.supernodexp.hpc, sock=16
04/24/2018 00:20:28;0100;Server@node2;Req;;Type 58 request received from Scheduler@node2.supernodexp.hpc, sock=16
04/24/2018 00:20:28;0100;Server@node2;Req;;Type 20 request received from Scheduler@node2.supernodexp.hpc, sock=16
04/24/2018 00:20:28;0100;Server@node2;Req;;Type 51 request received from Scheduler@node2.supernodexp.hpc, sock=16
04/24/2018 00:20:28;0100;Server@node2;Req;;Type 11 request received from Scheduler@node2.supernodexp.hpc, sock=16
04/24/2018 00:20:28;0008;Server@node2;Job;12226.node2.supernodexp.hpc;Job Modified at request of Scheduler@node2.supernodexp.hpc
04/24/2018 00:20:30;0080;Server@node2;Job;12224.node2.supernodexp.hpc;Obit received momhop:1 serverhop:1 state:4 substate:42
04/24/2018 00:20:31;0010;Server@node2;Job;12224.node2.supernodexp.hpc;Exit_status=0 resources_used.cpupercent=0 resources_used.cput=00:00:00 resources_used.mem=9088kb resources_used.ncpus=8 resources_used.vmem=105088kb resources_used.walltime=00:00:29
04/24/2018 00:20:31;0100;Server@node2;Job;12224.node2.supernodexp.hpc;dequeuing from workq, state 5
04/24/2018 00:20:31;0040;Server@node2;Svr;node2.supernodexp.hpc;Scheduler sent command 2
04/24/2018 00:20:31;0040;Server@node2;Svr;node2.supernodexp.hpc;Scheduler sent command 0
04/24/2018 00:20:31;0100;Server@node2;Req;;Type 21 request received from Scheduler@node2.supernodexp.hpc, sock=16
04/24/2018 00:20:31;0100;Server@node2;Req;;Type 81 request received from Scheduler@node2.supernodexp.hpc, sock=16
04/24/2018 00:20:31;0100;Server@node2;Req;;Type 71 request received from Scheduler@node2.supernodexp.hpc, sock=16
04/24/2018 00:20:31;0100;Server@node2;Req;;Type 58 request received from Scheduler@node2.supernodexp.hpc, sock=16
04/24/2018 00:20:31;0100;Server@node2;Req;;Type 20 request received from Scheduler@node2.supernodexp.hpc, sock=16
04/24/2018 00:20:31;0100;Server@node2;Req;;Type 51 request received from Scheduler@node2.supernodexp.hpc, sock=16
04/24/2018 00:20:31;0100;Server@node2;Req;;Type 11 request received from Scheduler@node2.supernodexp.hpc, sock=16
04/24/2018 00:20:31;0008;Server@node2;Job;12226.node2.supernodexp.hpc;Job Modified at request of Scheduler@node2.supernodexp.hpc
04/24/2018 00:21:20;0080;Server@node2;Job;12210.node2.supernodexp.hpc;Obit received momhop:1 serverhop:1 state:4 substate:42
04/24/2018 00:21:21;0010;Server@node2;Job;12210.node2.supernodexp.hpc;Exit_status=0 resources_used.cpupercent=0 resources_used.cput=00:00:00 resources_used.mem=9420kb resources_used.ncpus=12 resources_used.vmem=102320kb resources_used.walltime=00:05:27
04/24/2018 00:21:21;0100;Server@node2;Job;12210.node2.supernodexp.hpc;dequeuing from workq, state 5
04/24/2018 00:21:21;0040;Server@node2;Svr;node2.supernodexp.hpc;Scheduler sent command 2
04/24/2018 00:21:21;0040;Server@node2;Svr;node2.supernodexp.hpc;Scheduler sent command 0
04/24/2018 00:21:21;0100;Server@node2;Req;;Type 21 request received from Scheduler@node2.supernodexp.hpc, sock=16
04/24/2018 00:21:21;0100;Server@node2;Req;;Type 81 request received from Scheduler@node2.supernodexp.hpc, sock=16
04/24/2018 00:21:21;0100;Server@node2;Req;;Type 71 request received from Scheduler@node2.supernodexp.hpc, sock=16
04/24/2018 00:21:21;0100;Server@node2;Req;;Type 58 request received from Scheduler@node2.supernodexp.hpc, sock=16
04/24/2018 00:21:21;0100;Server@node2;Req;;Type 20 request received from Scheduler@node2.supernodexp.hpc, sock=16
04/24/2018 00:21:21;0100;Server@node2;Req;;Type 51 request received from Scheduler@node2.supernodexp.hpc, sock=16
04/24/2018 00:21:22;0100;Server@node2;Req;;Type 11 request received from Scheduler@node2.supernodexp.hpc, sock=16
04/24/2018 00:21:22;0008;Server@node2;Job;12226.node2.supernodexp.hpc;Job Modified at request of Scheduler@node2.supernodexp.hpc
04/24/2018 00:21:48;0080;Server@node2;Job;12213.node2.supernodexp.hpc;Obit received momhop:1 serverhop:1 state:4 substate:42
04/24/2018 00:21:49;0010;Server@node2;Job;12213.node2.supernodexp.hpc;Exit_status=0 resources_used.cpupercent=0 resources_used.cput=00:00:00 resources_used.mem=9872kb resources_used.ncpus=12 resources_used.vmem=455036kb resources_used.walltime=00:05:54
04/24/2018 00:21:49;0100;Server@node2;Job;12213.node2.supernodexp.hpc;dequeuing from workq, state 5
04/24/2018 00:21:49;0040;Server@node2;Svr;node2.supernodexp.hpc;Scheduler sent command 2
04/24/2018 00:21:49;0040;Server@node2;Svr;node2.supernodexp.hpc;Scheduler sent command 0
04/24/2018 00:21:49;0100;Server@node2;Req;;Type 21 request received from Scheduler@node2.supernodexp.hpc, sock=16
04/24/2018 00:21:49;0100;Server@node2;Req;;Type 81 request received from Scheduler@node2.supernodexp.hpc, sock=16
04/24/2018 00:21:49;0100;Server@node2;Req;;Type 71 request received from Scheduler@node2.supernodexp.hpc, sock=16
04/24/2018 00:21:49;0100;Server@node2;Req;;Type 58 request received from Scheduler@node2.supernodexp.hpc, sock=16
04/24/2018 00:21:49;0100;Server@node2;Req;;Type 20 request received from Scheduler@node2.supernodexp.hpc, sock=16
04/24/2018 00:21:49;0100;Server@node2;Req;;Type 51 request received from Scheduler@node2.supernodexp.hpc, sock=16
04/24/2018 00:23:08;0080;Server@node2;Job;12217.node2.supernodexp.hpc;Obit received momhop:1 serverhop:1 state:4 substate:42
04/24/2018 00:23:09;0010;Server@node2;Job;12217.node2.supernodexp.hpc;Exit_status=0 resources_used.cpupercent=0 resources_used.cput=00:00:00 resources_used.mem=9064kb resources_used.ncpus=12 resources_used.vmem=104700kb resources_used.walltime=00:06:11
04/24/2018 00:23:09;0100;Server@node2;Job;12217.node2.supernodexp.hpc;dequeuing from workq, state 5
04/24/2018 00:23:09;0040;Server@node2;Svr;node2.supernodexp.hpc;Scheduler sent command 2
04/24/2018 00:23:09;0040;Server@node2;Svr;node2.supernodexp.hpc;Scheduler sent command 0
04/24/2018 00:23:09;0100;Server@node2;Req;;Type 21 request received from Scheduler@node2.supernodexp.hpc, sock=16
04/24/2018 00:23:09;0100;Server@node2;Req;;Type 81 request received from Scheduler@node2.supernodexp.hpc, sock=16
04/24/2018 00:23:09;0100;Server@node2;Req;;Type 71 request received from Scheduler@node2.supernodexp.hpc, sock=16
04/24/2018 00:23:09;0100;Server@node2;Req;;Type 58 request received from Scheduler@node2.supernodexp.hpc, sock=16
04/24/2018 00:23:09;0100;Server@node2;Req;;Type 20 request received from Scheduler@node2.supernodexp.hpc, sock=16
04/24/2018 00:23:09;0100;Server@node2;Req;;Type 51 request received from Scheduler@node2.supernodexp.hpc, sock=16
04/24/2018 00:24:18;0080;Server@node2;Job;12223.node2.supernodexp.hpc;Obit received momhop:1 serverhop:1 state:4 substate:42
04/24/2018 00:24:19;0010;Server@node2;Job;12223.node2.supernodexp.hpc;Exit_status=0 resources_used.cpupercent=0 resources_used.cput=00:00:00 resources_used.mem=9636kb resources_used.ncpus=8 resources_used.vmem=239160kb resources_used.walltime=00:04:59
04/24/2018 00:24:19;0100;Server@node2;Job;12223.node2.supernodexp.hpc;dequeuing from workq, state 5
04/24/2018 00:24:19;0040;Server@node2;Svr;node2.supernodexp.hpc;Scheduler sent command 2
04/24/2018 00:24:19;0040;Server@node2;Svr;node2.supernodexp.hpc;Scheduler sent command 0
04/24/2018 00:24:19;0100;Server@node2;Req;;Type 21 request received from Scheduler@node2.supernodexp.hpc, sock=16
04/24/2018 00:24:19;0100;Server@node2;Req;;Type 81 request received from Scheduler@node2.supernodexp.hpc, sock=16
04/24/2018 00:24:19;0100;Server@node2;Req;;Type 71 request received from Scheduler@node2.supernodexp.hpc, sock=16
04/24/2018 00:24:19;0100;Server@node2;Req;;Type 58 request received from Scheduler@node2.supernodexp.hpc, sock=16
04/24/2018 00:24:19;0100;Server@node2;Req;;Type 20 request received from Scheduler@node2.supernodexp.hpc, sock=16
04/24/2018 00:24:19;0100;Server@node2;Req;;Type 51 request received from Scheduler@node2.supernodexp.hpc, sock=16
04/24/2018 00:24:19;0100;Server@node2;Req;;Type 11 request received from Scheduler@node2.supernodexp.hpc, sock=16
04/24/2018 00:24:19;0008;Server@node2;Job;12226.node2.supernodexp.hpc;Job Modified at request of Scheduler@node2.supernodexp.hpc
04/24/2018 00:25:33;0080;Server@node2;Job;12190.node2.supernodexp.hpc;Obit received momhop:1 serverhop:1 state:4 substate:42
04/24/2018 00:25:34;0010;Server@node2;Job;12190.node2.supernodexp.hpc;Exit_status=0 resources_used.cpupercent=0 resources_used.cput=00:00:00 resources_used.mem=9424kb resources_used.ncpus=8 resources_used.vmem=105344kb resources_used.walltime=00:15:33
04/24/2018 00:25:34;0100;Server@node2;Job;12190.node2.supernodexp.hpc;dequeuing from workq, state 5
04/24/2018 00:25:34;0040;Server@node2;Svr;node2.supernodexp.hpc;Scheduler sent command 2
04/24/2018 00:25:34;0040;Server@node2;Svr;node2.supernodexp.hpc;Scheduler sent command 0
04/24/2018 00:25:34;0100;Server@node2;Req;;Type 21 request received from Scheduler@node2.supernodexp.hpc, sock=16
04/24/2018 00:25:34;0100;Server@node2;Req;;Type 81 request received from Scheduler@node2.supernodexp.hpc, sock=16
04/24/2018 00:25:34;0100;Server@node2;Req;;Type 71 request received from Scheduler@node2.supernodexp.hpc, sock=16
04/24/2018 00:25:34;0100;Server@node2;Req;;Type 58 request received from Scheduler@node2.supernodexp.hpc, sock=16
04/24/2018 00:25:34;0100;Server@node2;Req;;Type 20 request received from Scheduler@node2.supernodexp.hpc, sock=16
04/24/2018 00:25:34;0100;Server@node2;Req;;Type 51 request received from Scheduler@node2.supernodexp.hpc, sock=16
04/24/2018 00:25:34;0100;Server@node2;Req;;Type 23 request received from Scheduler@node2.supernodexp.hpc, sock=16
04/24/2018 00:25:34;0008;Server@node2;Job;12226.node2.supernodexp.hpc;Job Run at request of Scheduler@node2.supernodexp.hpc on exec_vnode (node3:ncpus=32:nmics=2:mem=31457280kb)
04/24/2018 00:25:34;0001;Server@node2;Svr;Server@node2;Success (0) in req_runjob2, return value of svr_startjob is 0
04/24/2018 00:25:34;0100;Server@node2;Req;;Type 23 request received from Scheduler@node2.supernodexp.hpc, sock=16
04/24/2018 00:25:34;0008;Server@node2;Job;12227.node2.supernodexp.hpc;Job Run at request of Scheduler@node2.supernodexp.hpc on exec_vnode (node13:ncpus=24:mem=5242880kb)
04/24/2018 00:25:34;0001;Server@node2;Svr;Server@node2;Success (0) in req_runjob2, return value of svr_startjob is 0
04/24/2018 00:25:34;0100;Server@node2;Req;;Type 23 request received from Scheduler@node2.supernodexp.hpc, sock=16
04/24/2018 00:25:34;0008;Server@node2;Job;12228.node2.supernodexp.hpc;Job Run at request of Scheduler@node2.supernodexp.hpc on exec_vnode (node13:ncpus=12:mem=5242880kb)
04/24/2018 00:25:34;0001;Server@node2;Svr;Server@node2;Success (0) in req_runjob2, return value of svr_startjob is 0
04/24/2018 00:25:34;0100;Server@node2;Req;;Type 11 request received from Scheduler@node2.supernodexp.hpc, sock=16
04/24/2018 00:25:34;0008;Server@node2;Job;12229.node2.supernodexp.hpc;Job Modified at request of Scheduler@node2.supernodexp.hpc
04/24/2018 00:25:40;0080;Server@node2;Job;12227.node2.supernodexp.hpc;Obit received momhop:1 serverhop:1 state:4 substate:42
04/24/2018 00:25:41;0010;Server@node2;Job;12227.node2.supernodexp.hpc;Exit_status=0 resources_used.cpupercent=0 resources_used.cput=00:00:00 resources_used.mem=0kb resources_used.ncpus=24 resources_used.vmem=0kb resources_used.walltime=00:00:07
04/24/2018 00:25:41;0100;Server@node2;Job;12227.node2.supernodexp.hpc;dequeuing from workq, state 5
04/24/2018 00:25:41;0040;Server@node2;Svr;node2.supernodexp.hpc;Scheduler sent command 2
04/24/2018 00:25:41;0040;Server@node2;Svr;node2.supernodexp.hpc;Scheduler sent command 0
04/24/2018 00:25:41;0100;Server@node2;Req;;Type 21 request received from Scheduler@node2.supernodexp.hpc, sock=16
04/24/2018 00:25:41;0100;Server@node2;Req;;Type 81 request received from Scheduler@node2.supernodexp.hpc, sock=16
04/24/2018 00:25:41;0100;Server@node2;Req;;Type 71 request received from Scheduler@node2.supernodexp.hpc, sock=16
04/24/2018 00:25:41;0100;Server@node2;Req;;Type 58 request received from Scheduler@node2.supernodexp.hpc, sock=16
04/24/2018 00:25:41;0100;Server@node2;Req;;Type 20 request received from Scheduler@node2.supernodexp.hpc, sock=16
04/24/2018 00:25:41;0100;Server@node2;Req;;Type 51 request received from Scheduler@node2.supernodexp.hpc, sock=16
04/24/2018 00:25:41;0100;Server@node2;Req;;Type 23 request received from Scheduler@node2.supernodexp.hpc, sock=16
04/24/2018 00:25:41;0008;Server@node2;Job;12229.node2.supernodexp.hpc;Job Run at request of Scheduler@node2.supernodexp.hpc on exec_vnode (node13:ncpus=24:mem=5242880kb)
04/24/2018 00:25:41;0001;Server@node2;Svr;Server@node2;Success (0) in req_runjob2, return value of svr_startjob is 0
04/24/2018 00:25:41;0100;Server@node2;Req;;Type 11 request received from Scheduler@node2.supernodexp.hpc, sock=16
04/24/2018 00:25:41;0008;Server@node2;Job;12230.node2.supernodexp.hpc;Job Modified at request of Scheduler@node2.supernodexp.hpc
04/24/2018 00:25:46;0080;Server@node2;Job;12229.node2.supernodexp.hpc;Obit received momhop:1 serverhop:1 state:4 substate:42
04/24/2018 00:25:47;0010;Server@node2;Job;12229.node2.supernodexp.hpc;Exit_status=0 resources_used.cpupercent=0 resources_used.cput=00:00:00 resources_used.mem=0kb resources_used.ncpus=24 resources_used.vmem=0kb resources_used.walltime=00:00:05
04/24/2018 00:25:47;0100;Server@node2;Job;12229.node2.supernodexp.hpc;dequeuing from workq, state 5
04/24/2018 00:25:47;0040;Server@node2;Svr;node2.supernodexp.hpc;Scheduler sent command 2
04/24/2018 00:25:47;0040;Server@node2;Svr;node2.supernodexp.hpc;Scheduler sent command 0
04/24/2018 00:25:47;0100;Server@node2;Req;;Type 21 request received from Scheduler@node2.supernodexp.hpc, sock=16
04/24/2018 00:25:47;0100;Server@node2;Req;;Type 81 request received from Scheduler@node2.supernodexp.hpc, sock=16
04/24/2018 00:25:47;0100;Server@node2;Req;;Type 71 request received from Scheduler@node2.supernodexp.hpc, sock=16
04/24/2018 00:25:47;0100;Server@node2;Req;;Type 58 request received from Scheduler@node2.supernodexp.hpc, sock=16
04/24/2018 00:25:47;0100;Server@node2;Req;;Type 20 request received from Scheduler@node2.supernodexp.hpc, sock=16
04/24/2018 00:25:47;0100;Server@node2;Req;;Type 51 request received from Scheduler@node2.supernodexp.hpc, sock=16
04/24/2018 00:25:47;0100;Server@node2;Req;;Type 23 request received from Scheduler@node2.supernodexp.hpc, sock=16
04/24/2018 00:25:47;0008;Server@node2;Job;12230.node2.supernodexp.hpc;Job Run at request of Scheduler@node2.supernodexp.hpc on exec_vnode (node13:ncpus=24:mem=5242880kb)
04/24/2018 00:25:47;0001;Server@node2;Svr;Server@node2;Success (0) in req_runjob2, return value of svr_startjob is 0
04/24/2018 00:25:47;0100;Server@node2;Req;;Type 11 request received from Scheduler@node2.supernodexp.hpc, sock=16
04/24/2018 00:25:47;0008;Server@node2;Job;12231.node2.supernodexp.hpc;Job Modified at request of Scheduler@node2.supernodexp.hpc
04/24/2018 00:25:50;0080;Server@node2;Job;12220.node2.supernodexp.hpc;Obit received momhop:1 serverhop:1 state:4 substate:42
04/24/2018 00:25:51;0010;Server@node2;Job;12220.node2.supernodexp.hpc;Exit_status=271 resources_used.cpupercent=0 resources_used.cput=00:00:00 resources_used.mem=9096kb resources_used.ncpus=12 resources_used.vmem=105088kb resources_used.walltime=00:07:08
04/24/2018 00:25:51;0100;Server@node2;Job;12220.node2.supernodexp.hpc;dequeuing from workq, state 5
04/24/2018 00:25:51;0040;Server@node2;Svr;node2.supernodexp.hpc;Scheduler sent command 2
04/24/2018 00:25:51;0040;Server@node2;Svr;node2.supernodexp.hpc;Scheduler sent command 0
04/24/2018 00:25:51;0100;Server@node2;Req;;Type 21 request received from Scheduler@node2.supernodexp.hpc, sock=16
04/24/2018 00:25:51;0100;Server@node2;Req;;Type 81 request received from Scheduler@node2.supernodexp.hpc, sock=16
04/24/2018 00:25:51;0100;Server@node2;Req;;Type 71 request received from Scheduler@node2.supernodexp.hpc, sock=16
04/24/2018 00:25:51;0100;Server@node2;Req;;Type 58 request received from Scheduler@node2.supernodexp.hpc, sock=16
04/24/2018 00:25:51;0100;Server@node2;Req;;Type 20 request received from Scheduler@node2.supernodexp.hpc, sock=16
04/24/2018 00:25:51;0100;Server@node2;Req;;Type 51 request received from Scheduler@node2.supernodexp.hpc, sock=16
04/24/2018 00:25:51;0100;Server@node2;Req;;Type 11 request received from Scheduler@node2.supernodexp.hpc, sock=16
04/24/2018 00:25:51;0008;Server@node2;Job;12231.node2.supernodexp.hpc;Job Modified at request of Scheduler@node2.supernodexp.hpc
04/24/2018 00:30:44;0080;Server@node2;Job;12228.node2.supernodexp.hpc;Obit received momhop:1 serverhop:1 state:4 substate:42
04/24/2018 00:30:45;0010;Server@node2;Job;12228.node2.supernodexp.hpc;Exit_status=0 resources_used.cpupercent=0 resources_used.cput=00:00:00 resources_used.mem=9656kb resources_used.ncpus=12 resources_used.vmem=171960kb resources_used.walltime=00:05:11
04/24/2018 00:30:45;0100;Server@node2;Job;12228.node2.supernodexp.hpc;dequeuing from workq, state 5
04/24/2018 00:30:45;0040;Server@node2;Svr;node2.supernodexp.hpc;Scheduler sent command 2
04/24/2018 00:30:45;0040;Server@node2;Svr;node2.supernodexp.hpc;Scheduler sent command 0
04/24/2018 00:30:45;0100;Server@node2;Req;;Type 21 request received from Scheduler@node2.supernodexp.hpc, sock=16
04/24/2018 00:30:45;0100;Server@node2;Req;;Type 81 request received from Scheduler@node2.supernodexp.hpc, sock=16
04/24/2018 00:30:45;0100;Server@node2;Req;;Type 71 request received from Scheduler@node2.supernodexp.hpc, sock=16
04/24/2018 00:30:45;0100;Server@node2;Req;;Type 58 request received from Scheduler@node2.supernodexp.hpc, sock=16
04/24/2018 00:30:45;0100;Server@node2;Req;;Type 20 request received from Scheduler@node2.supernodexp.hpc, sock=16
04/24/2018 00:30:45;0100;Server@node2;Req;;Type 51 request received from Scheduler@node2.supernodexp.hpc, sock=16
04/24/2018 00:30:48;0080;Server@node2;Job;12211.node2.supernodexp.hpc;Obit received momhop:1 serverhop:1 state:4 substate:42
04/24/2018 00:30:48;0010;Server@node2;Job;12211.node2.supernodexp.hpc;Exit_status=0 resources_used.cpupercent=0 resources_used.cput=00:00:00 resources_used.mem=11648kb resources_used.ncpus=12 resources_used.vmem=172216kb resources_used.walltime=00:14:54
04/24/2018 00:30:48;0100;Server@node2;Job;12211.node2.supernodexp.hpc;dequeuing from workq, state 5
04/24/2018 00:30:48;0040;Server@node2;Svr;node2.supernodexp.hpc;Scheduler sent command 2
04/24/2018 00:30:48;0040;Server@node2;Svr;node2.supernodexp.hpc;Scheduler sent command 0
04/24/2018 00:30:48;0100;Server@node2;Req;;Type 21 request received from Scheduler@node2.supernodexp.hpc, sock=16
04/24/2018 00:30:48;0100;Server@node2;Req;;Type 81 request received from Scheduler@node2.supernodexp.hpc, sock=16
04/24/2018 00:30:48;0100;Server@node2;Req;;Type 71 request received from Scheduler@node2.supernodexp.hpc, sock=16
04/24/2018 00:30:48;0100;Server@node2;Req;;Type 58 request received from Scheduler@node2.supernodexp.hpc, sock=16
04/24/2018 00:30:49;0100;Server@node2;Req;;Type 20 request received from Scheduler@node2.supernodexp.hpc, sock=16
04/24/2018 00:30:49;0100;Server@node2;Req;;Type 51 request received from Scheduler@node2.supernodexp.hpc, sock=16
04/24/2018 00:30:49;0100;Server@node2;Req;;Type 23 request received from Scheduler@node2.supernodexp.hpc, sock=16
04/24/2018 00:30:49;0008;Server@node2;Job;12231.node2.supernodexp.hpc;Job Run at request of Scheduler@node2.supernodexp.hpc on exec_vnode (node13:nmics=2:ncpus=12:mem=41943040kb)
04/24/2018 00:30:49;0001;Server@node2;Svr;Server@node2;Success (0) in req_runjob2, return value of svr_startjob is 0
04/24/2018 00:30:49;0100;Server@node2;Req;;Type 11 request received from Scheduler@node2.supernodexp.hpc, sock=16
04/24/2018 00:30:49;0008;Server@node2;Job;12232.node2.supernodexp.hpc;Job Modified at request of Scheduler@node2.supernodexp.hpc
04/24/2018 00:31:03;0080;Server@node2;Job;12230.node2.supernodexp.hpc;Obit received momhop:1 serverhop:1 state:4 substate:42
04/24/2018 00:31:04;0010;Server@node2;Job;12230.node2.supernodexp.hpc;Exit_status=0 resources_used.cpupercent=0 resources_used.cput=00:00:00 resources_used.mem=9400kb resources_used.ncpus=24 resources_used.vmem=172216kb resources_used.walltime=00:05:17
04/24/2018 00:31:04;0100;Server@node2;Job;12230.node2.supernodexp.hpc;dequeuing from workq, state 5
04/24/2018 00:31:04;0040;Server@node2;Svr;node2.supernodexp.hpc;Scheduler sent command 2
04/24/2018 00:31:04;0040;Server@node2;Svr;node2.supernodexp.hpc;Scheduler sent command 0
04/24/2018 00:31:04;0100;Server@node2;Req;;Type 21 request received from Scheduler@node2.supernodexp.hpc, sock=16
04/24/2018 00:31:04;0100;Server@node2;Req;;Type 81 request received from Scheduler@node2.supernodexp.hpc, sock=16
04/24/2018 00:31:04;0100;Server@node2;Req;;Type 71 request received from Scheduler@node2.supernodexp.hpc, sock=16
04/24/2018 00:31:04;0100;Server@node2;Req;;Type 58 request received from Scheduler@node2.supernodexp.hpc, sock=16
04/24/2018 00:31:04;0100;Server@node2;Req;;Type 20 request received from Scheduler@node2.supernodexp.hpc, sock=16
04/24/2018 00:31:04;0100;Server@node2;Req;;Type 51 request received from Scheduler@node2.supernodexp.hpc, sock=16
04/24/2018 00:31:04;0100;Server@node2;Req;;Type 23 request received from Scheduler@node2.supernodexp.hpc, sock=16
04/24/2018 00:31:04;0008;Server@node2;Job;12232.node2.supernodexp.hpc;Job Run at request of Scheduler@node2.supernodexp.hpc on exec_vnode (node13:ncpus=24:mem=5242880kb)
04/24/2018 00:31:04;0001;Server@node2;Svr;Server@node2;Success (0) in req_runjob2, return value of svr_startjob is 0
04/24/2018 00:31:04;0100;Server@node2;Req;;Type 23 request received from Scheduler@node2.supernodexp.hpc, sock=16
04/24/2018 00:31:04;0008;Server@node2;Job;12233.node2.supernodexp.hpc;Job Run at request of Scheduler@node2.supernodexp.hpc on exec_vnode (node3:ncpus=12:mem=20971520kb)
04/24/2018 00:31:04;0001;Server@node2;Svr;Server@node2;Success (0) in req_runjob2, return value of svr_startjob is 0
04/24/2018 00:31:04;0100;Server@node2;Req;;Type 23 request received from Scheduler@node2.supernodexp.hpc, sock=16
04/24/2018 00:31:04;0008;Server@node2;Job;12234.node2.supernodexp.hpc;Job Run at request of Scheduler@node2.supernodexp.hpc on exec_vnode (node13:ncpus=12:mem=20971520kb)
04/24/2018 00:31:04;0001;Server@node2;Svr;Server@node2;Success (0) in req_runjob2, return value of svr_startjob is 0
04/24/2018 00:31:04;0100;Server@node2;Req;;Type 11 request received from Scheduler@node2.supernodexp.hpc, sock=16
04/24/2018 00:31:04;0008;Server@node2;Job;12235.node2.supernodexp.hpc;Job Modified at request of Scheduler@node2.supernodexp.hpc
04/24/2018 00:31:09;0080;Server@node2;Job;12232.node2.supernodexp.hpc;Obit received momhop:1 serverhop:1 state:4 substate:42
04/24/2018 00:31:10;0010;Server@node2;Job;12232.node2.supernodexp.hpc;Exit_status=0 resources_used.cpupercent=0 resources_used.cput=00:00:00 resources_used.mem=0kb resources_used.ncpus=24 resources_used.vmem=0kb resources_used.walltime=00:00:04
04/24/2018 00:31:10;0100;Server@node2;Job;12232.node2.supernodexp.hpc;dequeuing from workq, state 5
04/24/2018 00:31:10;0040;Server@node2;Svr;node2.supernodexp.hpc;Scheduler sent command 2
04/24/2018 00:31:10;0040;Server@node2;Svr;node2.supernodexp.hpc;Scheduler sent command 0
04/24/2018 00:31:10;0100;Server@node2;Req;;Type 21 request received from Scheduler@node2.supernodexp.hpc, sock=16
04/24/2018 00:31:10;0100;Server@node2;Req;;Type 81 request received from Scheduler@node2.supernodexp.hpc, sock=16
04/24/2018 00:31:10;0100;Server@node2;Req;;Type 71 request received from Scheduler@node2.supernodexp.hpc, sock=16
04/24/2018 00:31:10;0100;Server@node2;Req;;Type 58 request received from Scheduler@node2.supernodexp.hpc, sock=16
04/24/2018 00:31:10;0100;Server@node2;Req;;Type 20 request received from Scheduler@node2.supernodexp.hpc, sock=16
04/24/2018 00:31:10;0100;Server@node2;Req;;Type 51 request received from Scheduler@node2.supernodexp.hpc, sock=16
04/24/2018 00:31:10;0100;Server@node2;Req;;Type 23 request received from Scheduler@node2.supernodexp.hpc, sock=16
04/24/2018 00:31:10;0008;Server@node2;Job;12235.node2.supernodexp.hpc;Job Run at request of Scheduler@node2.supernodexp.hpc on exec_vnode (node13:ncpus=8:mem=20971520kb)
04/24/2018 00:31:10;0001;Server@node2;Svr;Server@node2;Success (0) in req_runjob2, return value of svr_startjob is 0
04/24/2018 00:31:10;0100;Server@node2;Req;;Type 23 request received from Scheduler@node2.supernodexp.hpc, sock=16
04/24/2018 00:31:10;0008;Server@node2;Job;12236.node2.supernodexp.hpc;Job Run at request of Scheduler@node2.supernodexp.hpc on exec_vnode (node13:ncpus=8:mem=3145728kb)
04/24/2018 00:31:10;0001;Server@node2;Svr;Server@node2;Success (0) in req_runjob2, return value of svr_startjob is 0
04/24/2018 00:31:10;0100;Server@node2;Req;;Type 23 request received from Scheduler@node2.supernodexp.hpc, sock=16
04/24/2018 00:31:10;0008;Server@node2;Job;12237.node2.supernodexp.hpc;Job Run at request of Scheduler@node2.supernodexp.hpc on exec_vnode (node13:ncpus=8:mem=3145728kb)
04/24/2018 00:31:10;0001;Server@node2;Svr;Server@node2;Success (0) in req_runjob2, return value of svr_startjob is 0
04/24/2018 00:31:10;0100;Server@node2;Req;;Type 23 request received from Scheduler@node2.supernodexp.hpc, sock=16
04/24/2018 00:31:10;0008;Server@node2;Job;12238.node2.supernodexp.hpc;Job Run at request of Scheduler@node2.supernodexp.hpc on exec_vnode (node3:ncpus=4:mem=5242880kb)
04/24/2018 00:31:10;0001;Server@node2;Svr;Server@node2;Success (0) in req_runjob2, return value of svr_startjob is 0
04/24/2018 00:31:10;0100;Server@node2;Req;;Type 23 request received from Scheduler@node2.supernodexp.hpc, sock=16
04/24/2018 00:31:10;0008;Server@node2;Job;12239.node2.supernodexp.hpc;Job Run at request of Scheduler@node2.supernodexp.hpc on exec_vnode (node14:ncpus=2:mem=2097152kb)
04/24/2018 00:31:10;0001;Server@node2;Svr;Server@node2;Success (0) in req_runjob2, return value of svr_startjob is 0
04/24/2018 00:31:10;0100;Server@node2;Req;;Type 11 request received from Scheduler@node2.supernodexp.hpc, sock=16
04/24/2018 00:31:10;0008;Server@node2;Job;12240.node2.supernodexp.hpc;Job Modified at request of Scheduler@node2.supernodexp.hpc
04/24/2018 00:31:13;0080;Server@node2;Job;12239.node2.supernodexp.hpc;Obit received momhop:1 serverhop:1 state:4 substate:42
04/24/2018 00:31:13;0080;Server@node2;Job;12235.node2.supernodexp.hpc;Obit received momhop:1 serverhop:1 state:4 substate:42
04/24/2018 00:31:14;0010;Server@node2;Job;12239.node2.supernodexp.hpc;Exit_status=0 resources_used.cpupercent=0 resources_used.cput=00:00:00 resources_used.mem=0kb resources_used.ncpus=2 resources_used.vmem=0kb resources_used.walltime=00:00:05
04/24/2018 00:31:14;0100;Server@node2;Job;12239.node2.supernodexp.hpc;dequeuing from workq, state 5
04/24/2018 00:31:14;0040;Server@node2;Svr;node2.supernodexp.hpc;Scheduler sent command 2
04/24/2018 00:31:14;0040;Server@node2;Svr;node2.supernodexp.hpc;Scheduler sent command 0
04/24/2018 00:31:14;0100;Server@node2;Req;;Type 21 request received from Scheduler@node2.supernodexp.hpc, sock=16
04/24/2018 00:31:14;0100;Server@node2;Req;;Type 81 request received from Scheduler@node2.supernodexp.hpc, sock=16
04/24/2018 00:31:14;0100;Server@node2;Req;;Type 71 request received from Scheduler@node2.supernodexp.hpc, sock=16
04/24/2018 00:31:14;0100;Server@node2;Req;;Type 58 request received from Scheduler@node2.supernodexp.hpc, sock=16
04/24/2018 00:31:14;0100;Server@node2;Req;;Type 20 request received from Scheduler@node2.supernodexp.hpc, sock=16
04/24/2018 00:31:14;0100;Server@node2;Req;;Type 51 request received from Scheduler@node2.supernodexp.hpc, sock=16
04/24/2018 00:31:14;0100;Server@node2;Req;;Type 11 request received from Scheduler@node2.supernodexp.hpc, sock=16
04/24/2018 00:31:14;0008;Server@node2;Job;12240.node2.supernodexp.hpc;Job Modified at request of Scheduler@node2.supernodexp.hpc
04/24/2018 00:31:14;0010;Server@node2;Job;12235.node2.supernodexp.hpc;Exit_status=0 resources_used.cpupercent=0 resources_used.cput=00:00:00 resources_used.mem=0kb resources_used.ncpus=8 resources_used.vmem=0kb resources_used.walltime=00:00:03
04/24/2018 00:31:14;0100;Server@node2;Job;12235.node2.supernodexp.hpc;dequeuing from workq, state 5
04/24/2018 00:31:14;0040;Server@node2;Svr;node2.supernodexp.hpc;Scheduler sent command 2
04/24/2018 00:31:14;0040;Server@node2;Svr;node2.supernodexp.hpc;Scheduler sent command 0
04/24/2018 00:31:14;0100;Server@node2;Req;;Type 21 request received from Scheduler@node2.supernodexp.hpc, sock=16
04/24/2018 00:31:14;0100;Server@node2;Req;;Type 81 request received from Scheduler@node2.supernodexp.hpc, sock=16
04/24/2018 00:31:14;0100;Server@node2;Req;;Type 71 request received from Scheduler@node2.supernodexp.hpc, sock=16
04/24/2018 00:31:14;0100;Server@node2;Req;;Type 58 request received from Scheduler@node2.supernodexp.hpc, sock=16
04/24/2018 00:31:14;0100;Server@node2;Req;;Type 20 request received from Scheduler@node2.supernodexp.hpc, sock=16
04/24/2018 00:31:14;0100;Server@node2;Req;;Type 51 request received from Scheduler@node2.supernodexp.hpc, sock=16
04/24/2018 00:31:14;0100;Server@node2;Req;;Type 23 request received from Scheduler@node2.supernodexp.hpc, sock=16
04/24/2018 00:31:14;0008;Server@node2;Job;12240.node2.supernodexp.hpc;Job Run at request of Scheduler@node2.supernodexp.hpc on exec_vnode (node13:ncpus=8:mem=3145728kb)
04/24/2018 00:31:14;0001;Server@node2;Svr;Server@node2;Success (0) in req_runjob2, return value of svr_startjob is 0
04/24/2018 00:31:14;0100;Server@node2;Req;;Type 11 request received from Scheduler@node2.supernodexp.hpc, sock=16
04/24/2018 00:31:14;0008;Server@node2;Job;12241.node2.supernodexp.hpc;Job Modified at request of Scheduler@node2.supernodexp.hpc
04/24/2018 00:31:31;0080;Server@node2;Job;12238.node2.supernodexp.hpc;Obit received momhop:1 serverhop:1 state:4 substate:42
04/24/2018 00:31:32;0010;Server@node2;Job;12238.node2.supernodexp.hpc;Exit_status=0 resources_used.cpupercent=0 resources_used.cput=00:00:00 resources_used.mem=9336kb resources_used.ncpus=4 resources_used.vmem=104444kb resources_used.walltime=00:00:23
04/24/2018 00:31:32;0100;Server@node2;Job;12238.node2.supernodexp.hpc;dequeuing from workq, state 5
04/24/2018 00:31:32;0040;Server@node2;Svr;node2.supernodexp.hpc;Scheduler sent command 2
04/24/2018 00:31:32;0040;Server@node2;Svr;node2.supernodexp.hpc;Scheduler sent command 0
04/24/2018 00:31:32;0100;Server@node2;Req;;Type 21 request received from Scheduler@node2.supernodexp.hpc, sock=16
04/24/2018 00:31:32;0100;Server@node2;Req;;Type 81 request received from Scheduler@node2.supernodexp.hpc, sock=16
04/24/2018 00:31:32;0100;Server@node2;Req;;Type 71 request received from Scheduler@node2.supernodexp.hpc, sock=16
04/24/2018 00:31:32;0100;Server@node2;Req;;Type 58 request received from Scheduler@node2.supernodexp.hpc, sock=16
04/24/2018 00:31:32;0100;Server@node2;Req;;Type 20 request received from Scheduler@node2.supernodexp.hpc, sock=16
04/24/2018 00:31:32;0100;Server@node2;Req;;Type 51 request received from Scheduler@node2.supernodexp.hpc, sock=16
04/24/2018 00:31:32;0100;Server@node2;Req;;Type 11 request received from Scheduler@node2.supernodexp.hpc, sock=16
04/24/2018 00:31:32;0008;Server@node2;Job;12241.node2.supernodexp.hpc;Job Modified at request of Scheduler@node2.supernodexp.hpc
04/24/2018 00:36:45;0080;Server@node2;Job;12233.node2.supernodexp.hpc;Obit received momhop:1 serverhop:1 state:4 substate:42
04/24/2018 00:36:45;0010;Server@node2;Job;12233.node2.supernodexp.hpc;Exit_status=0 resources_used.cpupercent=0 resources_used.cput=00:00:00 resources_used.mem=9096kb resources_used.ncpus=12 resources_used.vmem=170880kb resources_used.walltime=00:05:43
04/24/2018 00:36:45;0100;Server@node2;Job;12233.node2.supernodexp.hpc;dequeuing from workq, state 5
04/24/2018 00:36:45;0040;Server@node2;Svr;node2.supernodexp.hpc;Scheduler sent command 2
04/24/2018 00:36:45;0040;Server@node2;Svr;node2.supernodexp.hpc;Scheduler sent command 0
04/24/2018 00:36:45;0100;Server@node2;Req;;Type 21 request received from Scheduler@node2.supernodexp.hpc, sock=16
04/24/2018 00:36:45;0100;Server@node2;Req;;Type 81 request received from Scheduler@node2.supernodexp.hpc, sock=16
04/24/2018 00:36:45;0100;Server@node2;Req;;Type 71 request received from Scheduler@node2.supernodexp.hpc, sock=16
04/24/2018 00:36:45;0100;Server@node2;Req;;Type 58 request received from Scheduler@node2.supernodexp.hpc, sock=16
04/24/2018 00:36:45;0100;Server@node2;Req;;Type 20 request received from Scheduler@node2.supernodexp.hpc, sock=16
04/24/2018 00:36:45;0100;Server@node2;Req;;Type 51 request received from Scheduler@node2.supernodexp.hpc, sock=16
04/24/2018 00:36:46;0100;Server@node2;Req;;Type 23 request received from Scheduler@node2.supernodexp.hpc, sock=16
04/24/2018 00:36:46;0008;Server@node2;Job;12241.node2.supernodexp.hpc;Job Run at request of Scheduler@node2.supernodexp.hpc on exec_vnode (node3:ncpus=12:mem=5242880kb)
04/24/2018 00:36:46;0001;Server@node2;Svr;Server@node2;Success (0) in req_runjob2, return value of svr_startjob is 0
04/24/2018 00:36:46;0100;Server@node2;Req;;Type 11 request received from Scheduler@node2.supernodexp.hpc, sock=16
04/24/2018 00:36:46;0008;Server@node2;Job;12242.node2.supernodexp.hpc;Job Modified at request of Scheduler@node2.supernodexp.hpc
04/24/2018 00:36:51;0080;Server@node2;Job;12214.node2.supernodexp.hpc;Obit received momhop:1 serverhop:1 state:4 substate:42
04/24/2018 00:36:52;0010;Server@node2;Job;12214.node2.supernodexp.hpc;Exit_status=0 resources_used.cpupercent=0 resources_used.cput=00:00:00 resources_used.mem=10264kb resources_used.ncpus=12 resources_used.vmem=604156kb resources_used.walltime=00:20:04
04/24/2018 00:36:52;0100;Server@node2;Job;12214.node2.supernodexp.hpc;dequeuing from workq, state 5
04/24/2018 00:36:52;0040;Server@node2;Svr;node2.supernodexp.hpc;Scheduler sent command 2
04/24/2018 00:36:52;0040;Server@node2;Svr;node2.supernodexp.hpc;Scheduler sent command 0
04/24/2018 00:36:52;0100;Server@node2;Req;;Type 21 request received from Scheduler@node2.supernodexp.hpc, sock=16
04/24/2018 00:36:52;0100;Server@node2;Req;;Type 81 request received from Scheduler@node2.supernodexp.hpc, sock=16
04/24/2018 00:36:52;0100;Server@node2;Req;;Type 71 request received from Scheduler@node2.supernodexp.hpc, sock=16
04/24/2018 00:36:52;0100;Server@node2;Req;;Type 58 request received from Scheduler@node2.supernodexp.hpc, sock=16
04/24/2018 00:36:52;0100;Server@node2;Req;;Type 20 request received from Scheduler@node2.supernodexp.hpc, sock=16
04/24/2018 00:36:52;0100;Server@node2;Req;;Type 51 request received from Scheduler@node2.supernodexp.hpc, sock=16
04/24/2018 00:36:52;0100;Server@node2;Req;;Type 23 request received from Scheduler@node2.supernodexp.hpc, sock=16
04/24/2018 00:36:52;0008;Server@node2;Job;12242.node2.supernodexp.hpc;Job Run at request of Scheduler@node2.supernodexp.hpc on exec_vnode (node14:ncpus=8:mem=15728640kb)
04/24/2018 00:36:52;0001;Server@node2;Svr;Server@node2;Success (0) in req_runjob2, return value of svr_startjob is 0
04/24/2018 00:36:52;0100;Server@node2;Req;;Type 23 request received from Scheduler@node2.supernodexp.hpc, sock=16
04/24/2018 00:36:52;0008;Server@node2;Job;12243.node2.supernodexp.hpc;Job Run at request of Scheduler@node2.supernodexp.hpc on exec_vnode (node14:ncpus=8:mem=10485760kb)
04/24/2018 00:36:52;0001;Server@node2;Svr;Server@node2;Success (0) in req_runjob2, return value of svr_startjob is 0
04/24/2018 00:36:52;0100;Server@node2;Req;;Type 23 request received from Scheduler@node2.supernodexp.hpc, sock=16
04/24/2018 00:36:52;0008;Server@node2;Job;12244.node2.supernodexp.hpc;Job Run at request of Scheduler@node2.supernodexp.hpc on exec_vnode (node3:ncpus=4:mem=5242880kb)
04/24/2018 00:36:52;0001;Server@node2;Svr;Server@node2;Success (0) in req_runjob2, return value of svr_startjob is 0
04/24/2018 00:36:52;0100;Server@node2;Req;;Type 11 request received from Scheduler@node2.supernodexp.hpc, sock=16
04/24/2018 00:36:52;0008;Server@node2;Job;12245.node2.supernodexp.hpc;Job Modified at request of Scheduler@node2.supernodexp.hpc
04/24/2018 00:37:00;0080;Server@node2;Job;12234.node2.supernodexp.hpc;Obit received momhop:1 serverhop:1 state:4 substate:42
04/24/2018 00:37:01;0010;Server@node2;Job;12234.node2.supernodexp.hpc;Exit_status=0 resources_used.cpupercent=0 resources_used.cput=00:00:00 resources_used.mem=9652kb resources_used.ncpus=12 resources_used.vmem=724104kb resources_used.walltime=00:05:56
04/24/2018 00:37:01;0100;Server@node2;Job;12234.node2.supernodexp.hpc;dequeuing from workq, state 5
04/24/2018 00:37:01;0040;Server@node2;Svr;node2.supernodexp.hpc;Scheduler sent command 2
04/24/2018 00:37:01;0040;Server@node2;Svr;node2.supernodexp.hpc;Scheduler sent command 0
04/24/2018 00:37:01;0100;Server@node2;Req;;Type 21 request received from Scheduler@node2.supernodexp.hpc, sock=16
04/24/2018 00:37:01;0100;Server@node2;Req;;Type 81 request received from Scheduler@node2.supernodexp.hpc, sock=16
04/24/2018 00:37:01;0100;Server@node2;Req;;Type 71 request received from Scheduler@node2.supernodexp.hpc, sock=16
04/24/2018 00:37:01;0100;Server@node2;Req;;Type 58 request received from Scheduler@node2.supernodexp.hpc, sock=16
04/24/2018 00:37:01;0100;Server@node2;Req;;Type 20 request received from Scheduler@node2.supernodexp.hpc, sock=16
04/24/2018 00:37:01;0100;Server@node2;Req;;Type 51 request received from Scheduler@node2.supernodexp.hpc, sock=16
04/24/2018 00:37:01;0100;Server@node2;Req;;Type 23 request received from Scheduler@node2.supernodexp.hpc, sock=16
04/24/2018 00:37:01;0008;Server@node2;Job;12245.node2.supernodexp.hpc;Job Run at request of Scheduler@node2.supernodexp.hpc on exec_vnode (node13:ncpus=8:mem=20971520kb)
04/24/2018 00:37:01;0001;Server@node2;Svr;Server@node2;Success (0) in req_runjob2, return value of svr_startjob is 0
04/24/2018 00:37:01;0100;Server@node2;Req;;Type 11 request received from Scheduler@node2.supernodexp.hpc, sock=16
04/24/2018 00:37:01;0008;Server@node2;Job;12246.node2.supernodexp.hpc;Job Modified at request of Scheduler@node2.supernodexp.hpc
04/24/2018 00:37:06;0080;Server@node2;Job;12245.node2.supernodexp.hpc;Obit received momhop:1 serverhop:1 state:4 substate:42
04/24/2018 00:37:07;0010;Server@node2;Job;12245.node2.supernodexp.hpc;Exit_status=0 resources_used.cpupercent=0 resources_used.cput=00:00:00 resources_used.mem=0kb resources_used.ncpus=8 resources_used.vmem=0kb resources_used.walltime=00:00:04
04/24/2018 00:37:07;0100;Server@node2;Job;12245.node2.supernodexp.hpc;dequeuing from workq, state 5
04/24/2018 00:37:07;0040;Server@node2;Svr;node2.supernodexp.hpc;Scheduler sent command 2
04/24/2018 00:37:07;0040;Server@node2;Svr;node2.supernodexp.hpc;Scheduler sent command 0
04/24/2018 00:37:07;0100;Server@node2;Req;;Type 21 request received from Scheduler@node2.supernodexp.hpc, sock=16
04/24/2018 00:37:07;0100;Server@node2;Req;;Type 81 request received from Scheduler@node2.supernodexp.hpc, sock=16
04/24/2018 00:37:07;0100;Server@node2;Req;;Type 71 request received from Scheduler@node2.supernodexp.hpc, sock=16
04/24/2018 00:37:07;0100;Server@node2;Req;;Type 58 request received from Scheduler@node2.supernodexp.hpc, sock=16
04/24/2018 00:37:07;0100;Server@node2;Req;;Type 20 request received from Scheduler@node2.supernodexp.hpc, sock=16
04/24/2018 00:37:07;0100;Server@node2;Req;;Type 51 request received from Scheduler@node2.supernodexp.hpc, sock=16
04/24/2018 00:37:07;0100;Server@node2;Req;;Type 11 request received from Scheduler@node2.supernodexp.hpc, sock=16
04/24/2018 00:37:07;0008;Server@node2;Job;12246.node2.supernodexp.hpc;Job Modified at request of Scheduler@node2.supernodexp.hpc
04/24/2018 00:37:13;0080;Server@node2;Job;12244.node2.supernodexp.hpc;Obit received momhop:1 serverhop:1 state:4 substate:42
04/24/2018 00:37:14;0010;Server@node2;Job;12244.node2.supernodexp.hpc;Exit_status=0 resources_used.cpupercent=0 resources_used.cput=00:00:00 resources_used.mem=9092kb resources_used.ncpus=4 resources_used.vmem=103292kb resources_used.walltime=00:00:22
04/24/2018 00:37:14;0100;Server@node2;Job;12244.node2.supernodexp.hpc;dequeuing from workq, state 5
04/24/2018 00:37:14;0040;Server@node2;Svr;node2.supernodexp.hpc;Scheduler sent command 2
04/24/2018 00:37:14;0040;Server@node2;Svr;node2.supernodexp.hpc;Scheduler sent command 0
04/24/2018 00:37:14;0100;Server@node2;Req;;Type 21 request received from Scheduler@node2.supernodexp.hpc, sock=16
04/24/2018 00:37:14;0100;Server@node2;Req;;Type 81 request received from Scheduler@node2.supernodexp.hpc, sock=16
04/24/2018 00:37:14;0100;Server@node2;Req;;Type 71 request received from Scheduler@node2.supernodexp.hpc, sock=16
04/24/2018 00:37:14;0100;Server@node2;Req;;Type 58 request received from Scheduler@node2.supernodexp.hpc, sock=16
04/24/2018 00:37:14;0100;Server@node2;Req;;Type 20 request received from Scheduler@node2.supernodexp.hpc, sock=16
04/24/2018 00:37:14;0100;Server@node2;Req;;Type 51 request received from Scheduler@node2.supernodexp.hpc, sock=16
04/24/2018 00:37:14;0100;Server@node2;Req;;Type 11 request received from Scheduler@node2.supernodexp.hpc, sock=16
04/24/2018 00:37:14;0008;Server@node2;Job;12246.node2.supernodexp.hpc;Job Modified at request of Scheduler@node2.supernodexp.hpc
04/24/2018 00:37:25;0080;Server@node2;Job;12243.node2.supernodexp.hpc;Obit received momhop:1 serverhop:1 state:4 substate:42
04/24/2018 00:37:25;0010;Server@node2;Job;12243.node2.supernodexp.hpc;Exit_status=0 resources_used.cpupercent=0 resources_used.cput=00:00:00 resources_used.mem=9644kb resources_used.ncpus=8 resources_used.vmem=106680kb resources_used.walltime=00:00:33
04/24/2018 00:37:25;0100;Server@node2;Job;12243.node2.supernodexp.hpc;dequeuing from workq, state 5
04/24/2018 00:37:25;0040;Server@node2;Svr;node2.supernodexp.hpc;Scheduler sent command 2
04/24/2018 00:37:25;0040;Server@node2;Svr;node2.supernodexp.hpc;Scheduler sent command 0
04/24/2018 00:37:25;0100;Server@node2;Req;;Type 21 request received from Scheduler@node2.supernodexp.hpc, sock=16
04/24/2018 00:37:25;0100;Server@node2;Req;;Type 81 request received from Scheduler@node2.supernodexp.hpc, sock=16
04/24/2018 00:37:25;0100;Server@node2;Req;;Type 71 request received from Scheduler@node2.supernodexp.hpc, sock=16
04/24/2018 00:37:25;0100;Server@node2;Req;;Type 58 request received from Scheduler@node2.supernodexp.hpc, sock=16
04/24/2018 00:37:26;0100;Server@node2;Req;;Type 20 request received from Scheduler@node2.supernodexp.hpc, sock=16
04/24/2018 00:37:26;0100;Server@node2;Req;;Type 51 request received from Scheduler@node2.supernodexp.hpc, sock=16
04/24/2018 00:37:26;0100;Server@node2;Req;;Type 11 request received from Scheduler@node2.supernodexp.hpc, sock=16
04/24/2018 00:37:26;0008;Server@node2;Job;12246.node2.supernodexp.hpc;Job Modified at request of Scheduler@node2.supernodexp.hpc
04/24/2018 00:37:40;0080;Server@node2;Job;12240.node2.supernodexp.hpc;Obit received momhop:1 serverhop:1 state:4 substate:42
04/24/2018 00:37:41;0010;Server@node2;Job;12240.node2.supernodexp.hpc;Exit_status=0 resources_used.cpupercent=0 resources_used.cput=00:00:00 resources_used.mem=9816kb resources_used.ncpus=8 resources_used.vmem=861332kb resources_used.walltime=00:06:26
04/24/2018 00:37:41;0100;Server@node2;Job;12240.node2.supernodexp.hpc;dequeuing from workq, state 5
04/24/2018 00:37:41;0040;Server@node2;Svr;node2.supernodexp.hpc;Scheduler sent command 2
04/24/2018 00:37:41;0040;Server@node2;Svr;node2.supernodexp.hpc;Scheduler sent command 0
04/24/2018 00:37:41;0100;Server@node2;Req;;Type 21 request received from Scheduler@node2.supernodexp.hpc, sock=16
04/24/2018 00:37:41;0100;Server@node2;Req;;Type 81 request received from Scheduler@node2.supernodexp.hpc, sock=16
04/24/2018 00:37:41;0100;Server@node2;Req;;Type 71 request received from Scheduler@node2.supernodexp.hpc, sock=16
04/24/2018 00:37:41;0100;Server@node2;Req;;Type 58 request received from Scheduler@node2.supernodexp.hpc, sock=16
04/24/2018 00:37:41;0100;Server@node2;Req;;Type 20 request received from Scheduler@node2.supernodexp.hpc, sock=16
04/24/2018 00:37:41;0100;Server@node2;Req;;Type 51 request received from Scheduler@node2.supernodexp.hpc, sock=16
04/24/2018 00:37:41;0100;Server@node2;Req;;Type 11 request received from Scheduler@node2.supernodexp.hpc, sock=16
04/24/2018 00:37:41;0008;Server@node2;Job;12246.node2.supernodexp.hpc;Job Modified at request of Scheduler@node2.supernodexp.hpc
04/24/2018 00:37:43;0080;Server@node2;Job;12236.node2.supernodexp.hpc;Obit received momhop:1 serverhop:1 state:4 substate:42
04/24/2018 00:37:44;0010;Server@node2;Job;12236.node2.supernodexp.hpc;Exit_status=0 resources_used.cpupercent=0 resources_used.cput=00:00:00 resources_used.mem=9640kb resources_used.ncpus=8 resources_used.vmem=173624kb resources_used.walltime=00:06:32
04/24/2018 00:37:44;0100;Server@node2;Job;12236.node2.supernodexp.hpc;dequeuing from workq, state 5
04/24/2018 00:37:44;0040;Server@node2;Svr;node2.supernodexp.hpc;Scheduler sent command 2
04/24/2018 00:37:44;0040;Server@node2;Svr;node2.supernodexp.hpc;Scheduler sent command 0
04/24/2018 00:37:44;0100;Server@node2;Req;;Type 21 request received from Scheduler@node2.supernodexp.hpc, sock=16
04/24/2018 00:37:44;0100;Server@node2;Req;;Type 81 request received from Scheduler@node2.supernodexp.hpc, sock=16
04/24/2018 00:37:44;0100;Server@node2;Req;;Type 71 request received from Scheduler@node2.supernodexp.hpc, sock=16
04/24/2018 00:37:44;0100;Server@node2;Req;;Type 58 request received from Scheduler@node2.supernodexp.hpc, sock=16
04/24/2018 00:37:44;0100;Server@node2;Req;;Type 20 request received from Scheduler@node2.supernodexp.hpc, sock=16
04/24/2018 00:37:44;0100;Server@node2;Req;;Type 51 request received from Scheduler@node2.supernodexp.hpc, sock=16
04/24/2018 00:37:47;0080;Server@node2;Job;12237.node2.supernodexp.hpc;Obit received momhop:1 serverhop:1 state:4 substate:42
04/24/2018 00:37:48;0010;Server@node2;Job;12237.node2.supernodexp.hpc;Exit_status=0 resources_used.cpupercent=0 resources_used.cput=00:00:00 resources_used.mem=9664kb resources_used.ncpus=8 resources_used.vmem=104628kb resources_used.walltime=00:06:37
04/24/2018 00:37:48;0100;Server@node2;Job;12237.node2.supernodexp.hpc;dequeuing from workq, state 5
04/24/2018 00:37:48;0040;Server@node2;Svr;node2.supernodexp.hpc;Scheduler sent command 2
04/24/2018 00:37:48;0040;Server@node2;Svr;node2.supernodexp.hpc;Scheduler sent command 0
04/24/2018 00:37:48;0100;Server@node2;Req;;Type 21 request received from Scheduler@node2.supernodexp.hpc, sock=16
04/24/2018 00:37:48;0100;Server@node2;Req;;Type 81 request received from Scheduler@node2.supernodexp.hpc, sock=16
04/24/2018 00:37:48;0100;Server@node2;Req;;Type 71 request received from Scheduler@node2.supernodexp.hpc, sock=16
04/24/2018 00:37:48;0100;Server@node2;Req;;Type 58 request received from Scheduler@node2.supernodexp.hpc, sock=16
04/24/2018 00:37:48;0100;Server@node2;Req;;Type 20 request received from Scheduler@node2.supernodexp.hpc, sock=16
04/24/2018 00:37:48;0100;Server@node2;Req;;Type 51 request received from Scheduler@node2.supernodexp.hpc, sock=16
04/24/2018 00:40:49;0080;Server@node2;Job;12219.node2.supernodexp.hpc;Obit received momhop:1 serverhop:1 state:4 substate:42
04/24/2018 00:40:50;0010;Server@node2;Job;12219.node2.supernodexp.hpc;Exit_status=2 resources_used.cpupercent=0 resources_used.cput=00:00:00 resources_used.mem=10004kb resources_used.ncpus=32 resources_used.vmem=172216kb resources_used.walltime=00:22:07
04/24/2018 00:40:50;0100;Server@node2;Job;12219.node2.supernodexp.hpc;dequeuing from workq, state 5
04/24/2018 00:40:50;0040;Server@node2;Svr;node2.supernodexp.hpc;Scheduler sent command 2
04/24/2018 00:40:50;0040;Server@node2;Svr;node2.supernodexp.hpc;Scheduler sent command 0
04/24/2018 00:40:50;0100;Server@node2;Req;;Type 21 request received from Scheduler@node2.supernodexp.hpc, sock=16
04/24/2018 00:40:50;0100;Server@node2;Req;;Type 81 request received from Scheduler@node2.supernodexp.hpc, sock=16
04/24/2018 00:40:50;0100;Server@node2;Req;;Type 71 request received from Scheduler@node2.supernodexp.hpc, sock=16
04/24/2018 00:40:50;0100;Server@node2;Req;;Type 58 request received from Scheduler@node2.supernodexp.hpc, sock=16
04/24/2018 00:40:50;0100;Server@node2;Req;;Type 20 request received from Scheduler@node2.supernodexp.hpc, sock=16
04/24/2018 00:40:50;0100;Server@node2;Req;;Type 51 request received from Scheduler@node2.supernodexp.hpc, sock=16
04/24/2018 00:40:50;0100;Server@node2;Req;;Type 23 request received from Scheduler@node2.supernodexp.hpc, sock=16
04/24/2018 00:40:50;0008;Server@node2;Job;12246.node2.supernodexp.hpc;Job Run at request of Scheduler@node2.supernodexp.hpc on exec_vnode (node14:ncpus=32:nmics=2:mem=31457280kb)
04/24/2018 00:40:50;0001;Server@node2;Svr;Server@node2;Success (0) in req_runjob2, return value of svr_startjob is 0
04/24/2018 00:40:50;0100;Server@node2;Req;;Type 11 request received from Scheduler@node2.supernodexp.hpc, sock=16
04/24/2018 00:40:50;0008;Server@node2;Job;12247.node2.supernodexp.hpc;Job Modified at request of Scheduler@node2.supernodexp.hpc
04/24/2018 00:43:01;0080;Server@node2;Job;12241.node2.supernodexp.hpc;Obit received momhop:1 serverhop:1 state:4 substate:42
04/24/2018 00:43:02;0010;Server@node2;Job;12241.node2.supernodexp.hpc;Exit_status=0 resources_used.cpupercent=0 resources_used.cput=00:00:00 resources_used.mem=9340kb resources_used.ncpus=12 resources_used.vmem=172288kb resources_used.walltime=00:06:16
04/24/2018 00:43:02;0100;Server@node2;Job;12241.node2.supernodexp.hpc;dequeuing from workq, state 5
04/24/2018 00:43:02;0040;Server@node2;Svr;node2.supernodexp.hpc;Scheduler sent command 2
04/24/2018 00:43:02;0040;Server@node2;Svr;node2.supernodexp.hpc;Scheduler sent command 0
04/24/2018 00:43:02;0100;Server@node2;Req;;Type 21 request received from Scheduler@node2.supernodexp.hpc, sock=16
04/24/2018 00:43:02;0100;Server@node2;Req;;Type 81 request received from Scheduler@node2.supernodexp.hpc, sock=16
04/24/2018 00:43:02;0100;Server@node2;Req;;Type 71 request received from Scheduler@node2.supernodexp.hpc, sock=16
04/24/2018 00:43:02;0100;Server@node2;Req;;Type 58 request received from Scheduler@node2.supernodexp.hpc, sock=16
04/24/2018 00:43:02;0100;Server@node2;Req;;Type 20 request received from Scheduler@node2.supernodexp.hpc, sock=16
04/24/2018 00:43:02;0100;Server@node2;Req;;Type 51 request received from Scheduler@node2.supernodexp.hpc, sock=16
04/24/2018 00:45:44;0080;Server@node2;Job;12231.node2.supernodexp.hpc;Obit received momhop:1 serverhop:1 state:4 substate:42
04/24/2018 00:45:45;0010;Server@node2;Job;12231.node2.supernodexp.hpc;Exit_status=0 resources_used.cpupercent=0 resources_used.cput=00:00:00 resources_used.mem=10236kb resources_used.ncpus=12 resources_used.vmem=172216kb resources_used.walltime=00:14:56
04/24/2018 00:45:45;0100;Server@node2;Job;12231.node2.supernodexp.hpc;dequeuing from workq, state 5
04/24/2018 00:45:45;0040;Server@node2;Svr;node2.supernodexp.hpc;Scheduler sent command 2
04/24/2018 00:45:45;0040;Server@node2;Svr;node2.supernodexp.hpc;Scheduler sent command 0
04/24/2018 00:45:45;0100;Server@node2;Req;;Type 21 request received from Scheduler@node2.supernodexp.hpc, sock=16
04/24/2018 00:45:45;0100;Server@node2;Req;;Type 81 request received from Scheduler@node2.supernodexp.hpc, sock=16
04/24/2018 00:45:45;0100;Server@node2;Req;;Type 71 request received from Scheduler@node2.supernodexp.hpc, sock=16
04/24/2018 00:45:45;0100;Server@node2;Req;;Type 58 request received from Scheduler@node2.supernodexp.hpc, sock=16
04/24/2018 00:45:45;0100;Server@node2;Req;;Type 20 request received from Scheduler@node2.supernodexp.hpc, sock=16
04/24/2018 00:45:45;0100;Server@node2;Req;;Type 51 request received from Scheduler@node2.supernodexp.hpc, sock=16
04/24/2018 00:45:45;0100;Server@node2;Req;;Type 23 request received from Scheduler@node2.supernodexp.hpc, sock=16
04/24/2018 00:45:45;0008;Server@node2;Job;12247.node2.supernodexp.hpc;Job Run at request of Scheduler@node2.supernodexp.hpc on exec_vnode (node13:nmics=2:ncpus=2:mem=41943040kb)
04/24/2018 00:45:45;0001;Server@node2;Svr;Server@node2;Success (0) in req_runjob2, return value of svr_startjob is 0
04/24/2018 00:45:45;0100;Server@node2;Req;;Type 11 request received from Scheduler@node2.supernodexp.hpc, sock=16
04/24/2018 00:45:45;0008;Server@node2;Job;12248.node2.supernodexp.hpc;Job Modified at request of Scheduler@node2.supernodexp.hpc
04/24/2018 00:46:43;0080;Server@node2;Job;12226.node2.supernodexp.hpc;Obit received momhop:1 serverhop:1 state:4 substate:42
04/24/2018 00:46:44;0010;Server@node2;Job;12226.node2.supernodexp.hpc;Exit_status=2 resources_used.cpupercent=0 resources_used.cput=00:00:00 resources_used.mem=11396kb resources_used.ncpus=32 resources_used.vmem=106752kb resources_used.walltime=00:21:09
04/24/2018 00:46:44;0100;Server@node2;Job;12226.node2.supernodexp.hpc;dequeuing from workq, state 5
04/24/2018 00:46:44;0040;Server@node2;Svr;node2.supernodexp.hpc;Scheduler sent command 2
04/24/2018 00:46:44;0040;Server@node2;Svr;node2.supernodexp.hpc;Scheduler sent command 0
04/24/2018 00:46:44;0100;Server@node2;Req;;Type 21 request received from Scheduler@node2.supernodexp.hpc, sock=16
04/24/2018 00:46:44;0100;Server@node2;Req;;Type 81 request received from Scheduler@node2.supernodexp.hpc, sock=16
04/24/2018 00:46:44;0100;Server@node2;Req;;Type 71 request received from Scheduler@node2.supernodexp.hpc, sock=16
04/24/2018 00:46:44;0100;Server@node2;Req;;Type 58 request received from Scheduler@node2.supernodexp.hpc, sock=16
04/24/2018 00:46:44;0100;Server@node2;Req;;Type 20 request received from Scheduler@node2.supernodexp.hpc, sock=16
04/24/2018 00:46:44;0100;Server@node2;Req;;Type 51 request received from Scheduler@node2.supernodexp.hpc, sock=16
04/24/2018 00:46:44;0100;Server@node2;Req;;Type 23 request received from Scheduler@node2.supernodexp.hpc, sock=16
04/24/2018 00:46:44;0008;Server@node2;Job;12248.node2.supernodexp.hpc;Job Run at request of Scheduler@node2.supernodexp.hpc on exec_vnode (node3:ncpus=32:nmics=2:mem=31457280kb)
04/24/2018 00:46:44;0001;Server@node2;Svr;Server@node2;Success (0) in req_runjob2, return value of svr_startjob is 0
04/24/2018 00:46:44;0100;Server@node2;Req;;Type 11 request received from Scheduler@node2.supernodexp.hpc, sock=16
04/24/2018 00:46:44;0008;Server@node2;Job;12249.node2.supernodexp.hpc;Job Modified at request of Scheduler@node2.supernodexp.hpc
04/24/2018 00:47:34;0080;Server@node2;Job;12247.node2.supernodexp.hpc;Obit received momhop:1 serverhop:1 state:4 substate:42
04/24/2018 00:47:35;0010;Server@node2;Job;12247.node2.supernodexp.hpc;Exit_status=0 resources_used.cpupercent=0 resources_used.cput=00:00:00 resources_used.mem=9400kb resources_used.ncpus=2 resources_used.vmem=104628kb resources_used.walltime=00:01:49
04/24/2018 00:47:35;0100;Server@node2;Job;12247.node2.supernodexp.hpc;dequeuing from workq, state 5
04/24/2018 00:47:35;0040;Server@node2;Svr;node2.supernodexp.hpc;Scheduler sent command 2
04/24/2018 00:47:35;0040;Server@node2;Svr;node2.supernodexp.hpc;Scheduler sent command 0
04/24/2018 00:47:35;0100;Server@node2;Req;;Type 21 request received from Scheduler@node2.supernodexp.hpc, sock=16
04/24/2018 00:47:35;0100;Server@node2;Req;;Type 81 request received from Scheduler@node2.supernodexp.hpc, sock=16
04/24/2018 00:47:35;0100;Server@node2;Req;;Type 71 request received from Scheduler@node2.supernodexp.hpc, sock=16
04/24/2018 00:47:35;0100;Server@node2;Req;;Type 58 request received from Scheduler@node2.supernodexp.hpc, sock=16
04/24/2018 00:47:35;0100;Server@node2;Req;;Type 20 request received from Scheduler@node2.supernodexp.hpc, sock=16
04/24/2018 00:47:35;0100;Server@node2;Req;;Type 51 request received from Scheduler@node2.supernodexp.hpc, sock=16
04/24/2018 00:47:35;0100;Server@node2;Req;;Type 23 request received from Scheduler@node2.supernodexp.hpc, sock=16
04/24/2018 00:47:35;0008;Server@node2;Job;12249.node2.supernodexp.hpc;Job Run at request of Scheduler@node2.supernodexp.hpc on exec_vnode (node13:nmics=2:ncpus=2:mem=2097152kb)
04/24/2018 00:47:35;0001;Server@node2;Svr;Server@node2;Success (0) in req_runjob2, return value of svr_startjob is 0
04/24/2018 00:47:35;0100;Server@node2;Req;;Type 23 request received from Scheduler@node2.supernodexp.hpc, sock=16
04/24/2018 00:47:35;0008;Server@node2;Job;12250.node2.supernodexp.hpc;Job Run at request of Scheduler@node2.supernodexp.hpc on exec_vnode (node13:ncpus=24:mem=5242880kb)
04/24/2018 00:47:35;0001;Server@node2;Svr;Server@node2;Success (0) in req_runjob2, return value of svr_startjob is 0
04/24/2018 00:47:35;0100;Server@node2;Req;;Type 23 request received from Scheduler@node2.supernodexp.hpc, sock=16
04/24/2018 00:47:35;0008;Server@node2;Job;12251.node2.supernodexp.hpc;Job Run at request of Scheduler@node2.supernodexp.hpc on exec_vnode (node3:ncpus=8:mem=15728640kb)
04/24/2018 00:47:35;0001;Server@node2;Svr;Server@node2;Success (0) in req_runjob2, return value of svr_startjob is 0
04/24/2018 00:47:35;0100;Server@node2;Req;;Type 23 request received from Scheduler@node2.supernodexp.hpc, sock=16
04/24/2018 00:47:35;0008;Server@node2;Job;12252.node2.supernodexp.hpc;Job Run at request of Scheduler@node2.supernodexp.hpc on exec_vnode (node3:ncpus=8:mem=10485760kb)
04/24/2018 00:47:35;0001;Server@node2;Svr;Server@node2;Success (0) in req_runjob2, return value of svr_startjob is 0
04/24/2018 00:47:35;0100;Server@node2;Req;;Type 23 request received from Scheduler@node2.supernodexp.hpc, sock=16
04/24/2018 00:47:35;0008;Server@node2;Job;12253.node2.supernodexp.hpc;Job Run at request of Scheduler@node2.supernodexp.hpc on exec_vnode (node14:ncpus=2:mem=2097152kb)
04/24/2018 00:47:35;0001;Server@node2;Svr;Server@node2;Success (0) in req_runjob2, return value of svr_startjob is 0
04/24/2018 00:47:35;0100;Server@node2;Req;;Type 23 request received from Scheduler@node2.supernodexp.hpc, sock=16
04/24/2018 00:47:35;0008;Server@node2;Job;12254.node2.supernodexp.hpc;Job Run at request of Scheduler@node2.supernodexp.hpc on exec_vnode (node14:ncpus=4:mem=5242880kb)
04/24/2018 00:47:35;0001;Server@node2;Svr;Server@node2;Success (0) in req_runjob2, return value of svr_startjob is 0
04/24/2018 00:47:35;0100;Server@node2;Req;;Type 11 request received from Scheduler@node2.supernodexp.hpc, sock=16
04/24/2018 00:47:35;0008;Server@node2;Job;12255.node2.supernodexp.hpc;Job Modified at request of Scheduler@node2.supernodexp.hpc
04/24/2018 00:47:38;0080;Server@node2;Job;12253.node2.supernodexp.hpc;Obit received momhop:1 serverhop:1 state:4 substate:42
04/24/2018 00:47:39;0010;Server@node2;Job;12253.node2.supernodexp.hpc;Exit_status=0 resources_used.cpupercent=0 resources_used.cput=00:00:00 resources_used.mem=0kb resources_used.ncpus=2 resources_used.vmem=0kb resources_used.walltime=00:00:04
04/24/2018 00:47:39;0100;Server@node2;Job;12253.node2.supernodexp.hpc;dequeuing from workq, state 5
04/24/2018 00:47:39;0040;Server@node2;Svr;node2.supernodexp.hpc;Scheduler sent command 2
04/24/2018 00:47:39;0040;Server@node2;Svr;node2.supernodexp.hpc;Scheduler sent command 0
04/24/2018 00:47:39;0100;Server@node2;Req;;Type 21 request received from Scheduler@node2.supernodexp.hpc, sock=16
04/24/2018 00:47:39;0100;Server@node2;Req;;Type 81 request received from Scheduler@node2.supernodexp.hpc, sock=16
04/24/2018 00:47:39;0100;Server@node2;Req;;Type 71 request received from Scheduler@node2.supernodexp.hpc, sock=16
04/24/2018 00:47:39;0100;Server@node2;Req;;Type 58 request received from Scheduler@node2.supernodexp.hpc, sock=16
04/24/2018 00:47:39;0100;Server@node2;Req;;Type 20 request received from Scheduler@node2.supernodexp.hpc, sock=16
04/24/2018 00:47:39;0100;Server@node2;Req;;Type 51 request received from Scheduler@node2.supernodexp.hpc, sock=16
04/24/2018 00:47:39;0080;Server@node2;Job;12249.node2.supernodexp.hpc;Obit received momhop:1 serverhop:1 state:4 substate:42
04/24/2018 00:47:40;0010;Server@node2;Job;12249.node2.supernodexp.hpc;Exit_status=0 resources_used.cpupercent=0 resources_used.cput=00:00:00 resources_used.mem=0kb resources_used.ncpus=2 resources_used.vmem=0kb resources_used.walltime=00:00:05
04/24/2018 00:47:40;0100;Server@node2;Job;12249.node2.supernodexp.hpc;dequeuing from workq, state 5
04/24/2018 00:47:40;0040;Server@node2;Svr;node2.supernodexp.hpc;Scheduler sent command 2
04/24/2018 00:47:40;0040;Server@node2;Svr;node2.supernodexp.hpc;Scheduler sent command 0
04/24/2018 00:47:40;0100;Server@node2;Req;;Type 21 request received from Scheduler@node2.supernodexp.hpc, sock=16
04/24/2018 00:47:40;0100;Server@node2;Req;;Type 81 request received from Scheduler@node2.supernodexp.hpc, sock=16
04/24/2018 00:47:40;0100;Server@node2;Req;;Type 71 request received from Scheduler@node2.supernodexp.hpc, sock=16
04/24/2018 00:47:40;0100;Server@node2;Req;;Type 58 request received from Scheduler@node2.supernodexp.hpc, sock=16
04/24/2018 00:47:40;0100;Server@node2;Req;;Type 20 request received from Scheduler@node2.supernodexp.hpc, sock=16
04/24/2018 00:47:40;0100;Server@node2;Req;;Type 51 request received from Scheduler@node2.supernodexp.hpc, sock=16
04/24/2018 00:47:40;0100;Server@node2;Req;;Type 23 request received from Scheduler@node2.supernodexp.hpc, sock=16
04/24/2018 00:47:40;0008;Server@node2;Job;12255.node2.supernodexp.hpc;Job Run at request of Scheduler@node2.supernodexp.hpc on exec_vnode (node13:ncpus=24:mem=5242880kb)
04/24/2018 00:47:40;0001;Server@node2;Svr;Server@node2;Success (0) in req_runjob2, return value of svr_startjob is 0
04/24/2018 00:47:40;0100;Server@node2;Req;;Type 23 request received from Scheduler@node2.supernodexp.hpc, sock=16
04/24/2018 00:47:40;0008;Server@node2;Job;12256.node2.supernodexp.hpc;Job Run at request of Scheduler@node2.supernodexp.hpc on exec_vnode (node14:ncpus=2:mem=2097152kb)
04/24/2018 00:47:40;0001;Server@node2;Svr;Server@node2;Success (0) in req_runjob2, return value of svr_startjob is 0
04/24/2018 00:47:40;0100;Server@node2;Req;;Type 11 request received from Scheduler@node2.supernodexp.hpc, sock=16
04/24/2018 00:47:40;0008;Server@node2;Job;12257.node2.supernodexp.hpc;Job Modified at request of Scheduler@node2.supernodexp.hpc
04/24/2018 00:47:43;0080;Server@node2;Job;12256.node2.supernodexp.hpc;Obit received momhop:1 serverhop:1 state:4 substate:42
04/24/2018 00:47:44;0010;Server@node2;Job;12256.node2.supernodexp.hpc;Exit_status=0 resources_used.cpupercent=0 resources_used.cput=00:00:00 resources_used.mem=0kb resources_used.ncpus=2 resources_used.vmem=0kb resources_used.walltime=00:00:03
04/24/2018 00:47:44;0100;Server@node2;Job;12256.node2.supernodexp.hpc;dequeuing from workq, state 5
04/24/2018 00:47:44;0040;Server@node2;Svr;node2.supernodexp.hpc;Scheduler sent command 2
04/24/2018 00:47:44;0040;Server@node2;Svr;node2.supernodexp.hpc;Scheduler sent command 0
04/24/2018 00:47:44;0100;Server@node2;Req;;Type 21 request received from Scheduler@node2.supernodexp.hpc, sock=16
04/24/2018 00:47:44;0100;Server@node2;Req;;Type 81 request received from Scheduler@node2.supernodexp.hpc, sock=16
04/24/2018 00:47:44;0100;Server@node2;Req;;Type 71 request received from Scheduler@node2.supernodexp.hpc, sock=16
04/24/2018 00:47:44;0100;Server@node2;Req;;Type 58 request received from Scheduler@node2.supernodexp.hpc, sock=16
04/24/2018 00:47:44;0100;Server@node2;Req;;Type 20 request received from Scheduler@node2.supernodexp.hpc, sock=16
04/24/2018 00:47:44;0100;Server@node2;Req;;Type 51 request received from Scheduler@node2.supernodexp.hpc, sock=16
04/24/2018 00:47:44;0100;Server@node2;Req;;Type 23 request received from Scheduler@node2.supernodexp.hpc, sock=16
04/24/2018 00:47:44;0008;Server@node2;Job;12257.node2.supernodexp.hpc;Job Run at request of Scheduler@node2.supernodexp.hpc on exec_vnode (node14:ncpus=4:mem=5242880kb)
04/24/2018 00:47:44;0001;Server@node2;Svr;Server@node2;Success (0) in req_runjob2, return value of svr_startjob is 0
04/24/2018 00:47:44;0100;Server@node2;Req;;Type 11 request received from Scheduler@node2.supernodexp.hpc, sock=16
04/24/2018 00:47:44;0008;Server@node2;Job;12258.node2.supernodexp.hpc;Job Modified at request of Scheduler@node2.supernodexp.hpc
04/24/2018 00:47:44;0080;Server@node2;Job;12255.node2.supernodexp.hpc;Obit received momhop:1 serverhop:1 state:4 substate:42
04/24/2018 00:47:45;0010;Server@node2;Job;12255.node2.supernodexp.hpc;Exit_status=0 resources_used.cpupercent=0 resources_used.cput=00:00:00 resources_used.mem=0kb resources_used.ncpus=24 resources_used.vmem=0kb resources_used.walltime=00:00:04
04/24/2018 00:47:45;0100;Server@node2;Job;12255.node2.supernodexp.hpc;dequeuing from workq, state 5
04/24/2018 00:47:45;0040;Server@node2;Svr;node2.supernodexp.hpc;Scheduler sent command 2
04/24/2018 00:47:45;0040;Server@node2;Svr;node2.supernodexp.hpc;Scheduler sent command 0
04/24/2018 00:47:45;0100;Server@node2;Req;;Type 21 request received from Scheduler@node2.supernodexp.hpc, sock=16
04/24/2018 00:47:45;0100;Server@node2;Req;;Type 81 request received from Scheduler@node2.supernodexp.hpc, sock=16
04/24/2018 00:47:45;0100;Server@node2;Req;;Type 71 request received from Scheduler@node2.supernodexp.hpc, sock=16
04/24/2018 00:47:45;0100;Server@node2;Req;;Type 58 request received from Scheduler@node2.supernodexp.hpc, sock=16
04/24/2018 00:47:45;0100;Server@node2;Req;;Type 20 request received from Scheduler@node2.supernodexp.hpc, sock=16
04/24/2018 00:47:45;0100;Server@node2;Req;;Type 51 request received from Scheduler@node2.supernodexp.hpc, sock=16
04/24/2018 00:47:45;0100;Server@node2;Req;;Type 23 request received from Scheduler@node2.supernodexp.hpc, sock=16
04/24/2018 00:47:45;0008;Server@node2;Job;12258.node2.supernodexp.hpc;Job Run at request of Scheduler@node2.supernodexp.hpc on exec_vnode (node13:ncpus=24:mem=5242880kb)
04/24/2018 00:47:46;0001;Server@node2;Svr;Server@node2;Success (0) in req_runjob2, return value of svr_startjob is 0
04/24/2018 00:47:46;0100;Server@node2;Req;;Type 11 request received from Scheduler@node2.supernodexp.hpc, sock=16
04/24/2018 00:47:46;0008;Server@node2;Job;12259.node2.supernodexp.hpc;Job Modified at request of Scheduler@node2.supernodexp.hpc
04/24/2018 00:47:50;0080;Server@node2;Job;12258.node2.supernodexp.hpc;Obit received momhop:1 serverhop:1 state:4 substate:42
04/24/2018 00:47:51;0010;Server@node2;Job;12258.node2.supernodexp.hpc;Exit_status=0 resources_used.cpupercent=0 resources_used.cput=00:00:00 resources_used.mem=0kb resources_used.ncpus=24 resources_used.vmem=0kb resources_used.walltime=00:00:05
04/24/2018 00:47:51;0100;Server@node2;Job;12258.node2.supernodexp.hpc;dequeuing from workq, state 5
04/24/2018 00:47:51;0040;Server@node2;Svr;node2.supernodexp.hpc;Scheduler sent command 2
04/24/2018 00:47:51;0040;Server@node2;Svr;node2.supernodexp.hpc;Scheduler sent command 0
04/24/2018 00:47:51;0100;Server@node2;Req;;Type 21 request received from Scheduler@node2.supernodexp.hpc, sock=16
04/24/2018 00:47:51;0100;Server@node2;Req;;Type 81 request received from Scheduler@node2.supernodexp.hpc, sock=16
04/24/2018 00:47:51;0100;Server@node2;Req;;Type 71 request received from Scheduler@node2.supernodexp.hpc, sock=16
04/24/2018 00:47:51;0100;Server@node2;Req;;Type 58 request received from Scheduler@node2.supernodexp.hpc, sock=16
04/24/2018 00:47:51;0100;Server@node2;Req;;Type 20 request received from Scheduler@node2.supernodexp.hpc, sock=16
04/24/2018 00:47:51;0100;Server@node2;Req;;Type 51 request received from Scheduler@node2.supernodexp.hpc, sock=16
04/24/2018 00:47:51;0100;Server@node2;Req;;Type 23 request received from Scheduler@node2.supernodexp.hpc, sock=16
04/24/2018 00:47:51;0008;Server@node2;Job;12259.node2.supernodexp.hpc;Job Run at request of Scheduler@node2.supernodexp.hpc on exec_vnode (node13:ncpus=8:mem=20971520kb)
04/24/2018 00:47:51;0001;Server@node2;Svr;Server@node2;Success (0) in req_runjob2, return value of svr_startjob is 0
04/24/2018 00:47:51;0100;Server@node2;Req;;Type 23 request received from Scheduler@node2.supernodexp.hpc, sock=16
04/24/2018 00:47:51;0008;Server@node2;Job;12260.node2.supernodexp.hpc;Job Run at request of Scheduler@node2.supernodexp.hpc on exec_vnode (node13:ncpus=12:mem=20971520kb)
04/24/2018 00:47:51;0001;Server@node2;Svr;Server@node2;Success (0) in req_runjob2, return value of svr_startjob is 0
04/24/2018 00:47:51;0100;Server@node2;Req;;Type 11 request received from Scheduler@node2.supernodexp.hpc, sock=16
04/24/2018 00:47:51;0008;Server@node2;Job;12261.node2.supernodexp.hpc;Job Modified at request of Scheduler@node2.supernodexp.hpc
04/24/2018 00:47:56;0080;Server@node2;Job;12254.node2.supernodexp.hpc;Obit received momhop:1 serverhop:1 state:4 substate:42
04/24/2018 00:47:56;0080;Server@node2;Job;12259.node2.supernodexp.hpc;Obit received momhop:1 serverhop:1 state:4 substate:42
04/24/2018 00:47:57;0010;Server@node2;Job;12254.node2.supernodexp.hpc;Exit_status=0 resources_used.cpupercent=0 resources_used.cput=00:00:00 resources_used.mem=9400kb resources_used.ncpus=4 resources_used.vmem=171960kb resources_used.walltime=00:00:22
04/24/2018 00:47:57;0100;Server@node2;Job;12254.node2.supernodexp.hpc;dequeuing from workq, state 5
04/24/2018 00:47:57;0040;Server@node2;Svr;node2.supernodexp.hpc;Scheduler sent command 2
04/24/2018 00:47:57;0040;Server@node2;Svr;node2.supernodexp.hpc;Scheduler sent command 0
04/24/2018 00:47:57;0100;Server@node2;Req;;Type 21 request received from Scheduler@node2.supernodexp.hpc, sock=16
04/24/2018 00:47:57;0100;Server@node2;Req;;Type 81 request received from Scheduler@node2.supernodexp.hpc, sock=16
04/24/2018 00:47:57;0100;Server@node2;Req;;Type 71 request received from Scheduler@node2.supernodexp.hpc, sock=16
04/24/2018 00:47:57;0100;Server@node2;Req;;Type 58 request received from Scheduler@node2.supernodexp.hpc, sock=16
04/24/2018 00:47:57;0100;Server@node2;Req;;Type 20 request received from Scheduler@node2.supernodexp.hpc, sock=16
04/24/2018 00:47:57;0100;Server@node2;Req;;Type 51 request received from Scheduler@node2.supernodexp.hpc, sock=16
04/24/2018 00:47:57;0100;Server@node2;Req;;Type 11 request received from Scheduler@node2.supernodexp.hpc, sock=16
04/24/2018 00:47:57;0008;Server@node2;Job;12261.node2.supernodexp.hpc;Job Modified at request of Scheduler@node2.supernodexp.hpc
04/24/2018 00:47:57;0010;Server@node2;Job;12259.node2.supernodexp.hpc;Exit_status=0 resources_used.cpupercent=0 resources_used.cput=00:00:00 resources_used.mem=0kb resources_used.ncpus=8 resources_used.vmem=0kb resources_used.walltime=00:00:05
04/24/2018 00:47:57;0100;Server@node2;Job;12259.node2.supernodexp.hpc;dequeuing from workq, state 5
04/24/2018 00:47:57;0040;Server@node2;Svr;node2.supernodexp.hpc;Scheduler sent command 2
04/24/2018 00:47:57;0040;Server@node2;Svr;node2.supernodexp.hpc;Scheduler sent command 0
04/24/2018 00:47:57;0100;Server@node2;Req;;Type 21 request received from Scheduler@node2.supernodexp.hpc, sock=16
04/24/2018 00:47:57;0100;Server@node2;Req;;Type 81 request received from Scheduler@node2.supernodexp.hpc, sock=16
04/24/2018 00:47:57;0100;Server@node2;Req;;Type 71 request received from Scheduler@node2.supernodexp.hpc, sock=16
04/24/2018 00:47:57;0100;Server@node2;Req;;Type 58 request received from Scheduler@node2.supernodexp.hpc, sock=16
04/24/2018 00:47:57;0100;Server@node2;Req;;Type 20 request received from Scheduler@node2.supernodexp.hpc, sock=16
04/24/2018 00:47:57;0100;Server@node2;Req;;Type 51 request received from Scheduler@node2.supernodexp.hpc, sock=16
04/24/2018 00:47:57;0100;Server@node2;Req;;Type 23 request received from Scheduler@node2.supernodexp.hpc, sock=16
04/24/2018 00:47:57;0008;Server@node2;Job;12261.node2.supernodexp.hpc;Job Run at request of Scheduler@node2.supernodexp.hpc on exec_vnode (node13:ncpus=12:mem=5242880kb)
04/24/2018 00:47:57;0001;Server@node2;Svr;Server@node2;Success (0) in req_runjob2, return value of svr_startjob is 0
04/24/2018 00:47:57;0100;Server@node2;Req;;Type 23 request received from Scheduler@node2.supernodexp.hpc, sock=16
04/24/2018 00:47:57;0008;Server@node2;Job;12262.node2.supernodexp.hpc;Job Run at request of Scheduler@node2.supernodexp.hpc on exec_vnode (node14:ncpus=2:mem=2097152kb)
04/24/2018 00:47:57;0001;Server@node2;Svr;Server@node2;Success (0) in req_runjob2, return value of svr_startjob is 0
04/24/2018 00:47:57;0100;Server@node2;Req;;Type 11 request received from Scheduler@node2.supernodexp.hpc, sock=16
04/24/2018 00:47:57;0008;Server@node2;Job;12263.node2.supernodexp.hpc;Job Modified at request of Scheduler@node2.supernodexp.hpc
04/24/2018 00:48:00;0080;Server@node2;Job;12257.node2.supernodexp.hpc;Obit received momhop:1 serverhop:1 state:4 substate:42
04/24/2018 00:48:00;0080;Server@node2;Job;12262.node2.supernodexp.hpc;Obit received momhop:1 serverhop:1 state:4 substate:42
04/24/2018 00:48:00;0010;Server@node2;Job;12257.node2.supernodexp.hpc;Exit_status=0 resources_used.cpupercent=0 resources_used.cput=00:00:00 resources_used.mem=9628kb resources_used.ncpus=4 resources_used.vmem=171960kb resources_used.walltime=00:00:16
04/24/2018 00:48:00;0100;Server@node2;Job;12257.node2.supernodexp.hpc;dequeuing from workq, state 5
04/24/2018 00:48:00;0040;Server@node2;Svr;node2.supernodexp.hpc;Scheduler sent command 2
04/24/2018 00:48:00;0040;Server@node2;Svr;node2.supernodexp.hpc;Scheduler sent command 0
04/24/2018 00:48:00;0100;Server@node2;Req;;Type 21 request received from Scheduler@node2.supernodexp.hpc, sock=16
04/24/2018 00:48:00;0100;Server@node2;Req;;Type 81 request received from Scheduler@node2.supernodexp.hpc, sock=16
04/24/2018 00:48:00;0100;Server@node2;Req;;Type 71 request received from Scheduler@node2.supernodexp.hpc, sock=16
04/24/2018 00:48:00;0100;Server@node2;Req;;Type 58 request received from Scheduler@node2.supernodexp.hpc, sock=16
04/24/2018 00:48:01;0100;Server@node2;Req;;Type 20 request received from Scheduler@node2.supernodexp.hpc, sock=16
04/24/2018 00:48:01;0100;Server@node2;Req;;Type 51 request received from Scheduler@node2.supernodexp.hpc, sock=16
04/24/2018 00:48:01;0010;Server@node2;Job;12262.node2.supernodexp.hpc;Exit_status=0 resources_used.cpupercent=0 resources_used.cput=00:00:00 resources_used.mem=9652kb resources_used.ncpus=2 resources_used.vmem=169908kb resources_used.walltime=00:00:03
04/24/2018 00:48:01;0100;Server@node2;Job;12262.node2.supernodexp.hpc;dequeuing from workq, state 5
04/24/2018 00:48:01;0040;Server@node2;Svr;node2.supernodexp.hpc;Scheduler sent command 2
04/24/2018 00:48:01;0040;Server@node2;Svr;node2.supernodexp.hpc;Scheduler sent command 0
04/24/2018 00:48:01;0100;Server@node2;Req;;Type 21 request received from Scheduler@node2.supernodexp.hpc, sock=16
04/24/2018 00:48:01;0100;Server@node2;Req;;Type 81 request received from Scheduler@node2.supernodexp.hpc, sock=16
04/24/2018 00:48:01;0100;Server@node2;Req;;Type 71 request received from Scheduler@node2.supernodexp.hpc, sock=16
04/24/2018 00:48:01;0100;Server@node2;Req;;Type 58 request received from Scheduler@node2.supernodexp.hpc, sock=16
04/24/2018 00:48:01;0100;Server@node2;Req;;Type 20 request received from Scheduler@node2.supernodexp.hpc, sock=16
04/24/2018 00:48:01;0100;Server@node2;Req;;Type 51 request received from Scheduler@node2.supernodexp.hpc, sock=16
04/24/2018 00:48:10;0080;Server@node2;Job;12252.node2.supernodexp.hpc;Obit received momhop:1 serverhop:1 state:4 substate:42
04/24/2018 00:48:10;0010;Server@node2;Job;12252.node2.supernodexp.hpc;Exit_status=0 resources_used.cpupercent=0 resources_used.cput=00:00:00 resources_used.mem=8832kb resources_used.ncpus=8 resources_used.vmem=103036kb resources_used.walltime=00:00:37
04/24/2018 00:48:10;0100;Server@node2;Job;12252.node2.supernodexp.hpc;dequeuing from workq, state 5
04/24/2018 00:48:10;0040;Server@node2;Svr;node2.supernodexp.hpc;Scheduler sent command 2
04/24/2018 00:48:10;0040;Server@node2;Svr;node2.supernodexp.hpc;Scheduler sent command 0
04/24/2018 00:48:10;0100;Server@node2;Req;;Type 21 request received from Scheduler@node2.supernodexp.hpc, sock=16
04/24/2018 00:48:10;0100;Server@node2;Req;;Type 81 request received from Scheduler@node2.supernodexp.hpc, sock=16
04/24/2018 00:48:10;0100;Server@node2;Req;;Type 71 request received from Scheduler@node2.supernodexp.hpc, sock=16
04/24/2018 00:48:10;0100;Server@node2;Req;;Type 58 request received from Scheduler@node2.supernodexp.hpc, sock=16
04/24/2018 00:48:11;0100;Server@node2;Req;;Type 20 request received from Scheduler@node2.supernodexp.hpc, sock=16
04/24/2018 00:48:11;0100;Server@node2;Req;;Type 51 request received from Scheduler@node2.supernodexp.hpc, sock=16
04/24/2018 00:49:49;0080;Server@node2;Job;12242.node2.supernodexp.hpc;Obit received momhop:1 serverhop:1 state:4 substate:42
04/24/2018 00:49:50;0010;Server@node2;Job;12242.node2.supernodexp.hpc;Exit_status=0 resources_used.cpupercent=0 resources_used.cput=00:00:00 resources_used.mem=10216kb resources_used.ncpus=8 resources_used.vmem=170164kb resources_used.walltime=00:12:57
04/24/2018 00:49:50;0100;Server@node2;Job;12242.node2.supernodexp.hpc;dequeuing from workq, state 5
04/24/2018 00:49:50;0040;Server@node2;Svr;node2.supernodexp.hpc;Scheduler sent command 2
04/24/2018 00:49:50;0040;Server@node2;Svr;node2.supernodexp.hpc;Scheduler sent command 0
04/24/2018 00:49:50;0100;Server@node2;Req;;Type 21 request received from Scheduler@node2.supernodexp.hpc, sock=16
04/24/2018 00:49:50;0100;Server@node2;Req;;Type 81 request received from Scheduler@node2.supernodexp.hpc, sock=16
04/24/2018 00:49:50;0100;Server@node2;Req;;Type 71 request received from Scheduler@node2.supernodexp.hpc, sock=16
04/24/2018 00:49:50;0100;Server@node2;Req;;Type 58 request received from Scheduler@node2.supernodexp.hpc, sock=16
04/24/2018 00:49:50;0100;Server@node2;Req;;Type 20 request received from Scheduler@node2.supernodexp.hpc, sock=16
04/24/2018 00:49:50;0100;Server@node2;Req;;Type 51 request received from Scheduler@node2.supernodexp.hpc, sock=16
04/24/2018 00:52:57;0080;Server@node2;Job;12250.node2.supernodexp.hpc;Obit received momhop:1 serverhop:1 state:4 substate:42
04/24/2018 00:52:58;0010;Server@node2;Job;12250.node2.supernodexp.hpc;Exit_status=0 resources_used.cpupercent=0 resources_used.cput=00:00:00 resources_used.mem=9624kb resources_used.ncpus=24 resources_used.vmem=172216kb resources_used.walltime=00:05:22
04/24/2018 00:52:58;0100;Server@node2;Job;12250.node2.supernodexp.hpc;dequeuing from workq, state 5
04/24/2018 00:52:58;0040;Server@node2;Svr;node2.supernodexp.hpc;Scheduler sent command 2
04/24/2018 00:52:58;0040;Server@node2;Svr;node2.supernodexp.hpc;Scheduler sent command 0
04/24/2018 00:52:58;0100;Server@node2;Req;;Type 21 request received from Scheduler@node2.supernodexp.hpc, sock=16
04/24/2018 00:52:58;0100;Server@node2;Req;;Type 81 request received from Scheduler@node2.supernodexp.hpc, sock=16
04/24/2018 00:52:58;0100;Server@node2;Req;;Type 71 request received from Scheduler@node2.supernodexp.hpc, sock=16
04/24/2018 00:52:58;0100;Server@node2;Req;;Type 58 request received from Scheduler@node2.supernodexp.hpc, sock=16
04/24/2018 00:52:58;0100;Server@node2;Req;;Type 20 request received from Scheduler@node2.supernodexp.hpc, sock=16
04/24/2018 00:52:58;0100;Server@node2;Req;;Type 51 request received from Scheduler@node2.supernodexp.hpc, sock=16
04/24/2018 00:52:58;0100;Server@node2;Req;;Type 23 request received from Scheduler@node2.supernodexp.hpc, sock=16
04/24/2018 00:52:58;0008;Server@node2;Job;12263.node2.supernodexp.hpc;Job Run at request of Scheduler@node2.supernodexp.hpc on exec_vnode (node13:nmics=2:ncpus=2:mem=2097152kb)
04/24/2018 00:52:58;0001;Server@node2;Svr;Server@node2;Success (0) in req_runjob2, return value of svr_startjob is 0
04/24/2018 00:52:58;0100;Server@node2;Req;;Type 23 request received from Scheduler@node2.supernodexp.hpc, sock=16
04/24/2018 00:52:58;0008;Server@node2;Job;12264.node2.supernodexp.hpc;Job Run at request of Scheduler@node2.supernodexp.hpc on exec_vnode (node3:ncpus=4:mem=5242880kb)
04/24/2018 00:52:58;0001;Server@node2;Svr;Server@node2;Success (0) in req_runjob2, return value of svr_startjob is 0
04/24/2018 00:52:58;0100;Server@node2;Req;;Type 11 request received from Scheduler@node2.supernodexp.hpc, sock=16
04/24/2018 00:52:58;0008;Server@node2;Job;12265.node2.supernodexp.hpc;Job Modified at request of Scheduler@node2.supernodexp.hpc
04/24/2018 00:53:02;0080;Server@node2;Job;12263.node2.supernodexp.hpc;Obit received momhop:1 serverhop:1 state:4 substate:42
04/24/2018 00:53:03;0010;Server@node2;Job;12263.node2.supernodexp.hpc;Exit_status=0 resources_used.cpupercent=0 resources_used.cput=00:00:00 resources_used.mem=0kb resources_used.ncpus=2 resources_used.vmem=0kb resources_used.walltime=00:00:04
04/24/2018 00:53:03;0100;Server@node2;Job;12263.node2.supernodexp.hpc;dequeuing from workq, state 5
04/24/2018 00:53:03;0040;Server@node2;Svr;node2.supernodexp.hpc;Scheduler sent command 2
04/24/2018 00:53:03;0040;Server@node2;Svr;node2.supernodexp.hpc;Scheduler sent command 0
04/24/2018 00:53:03;0100;Server@node2;Req;;Type 21 request received from Scheduler@node2.supernodexp.hpc, sock=16
04/24/2018 00:53:03;0100;Server@node2;Req;;Type 81 request received from Scheduler@node2.supernodexp.hpc, sock=16
04/24/2018 00:53:03;0100;Server@node2;Req;;Type 71 request received from Scheduler@node2.supernodexp.hpc, sock=16
04/24/2018 00:53:03;0100;Server@node2;Req;;Type 58 request received from Scheduler@node2.supernodexp.hpc, sock=16
04/24/2018 00:53:03;0100;Server@node2;Req;;Type 20 request received from Scheduler@node2.supernodexp.hpc, sock=16
04/24/2018 00:53:03;0100;Server@node2;Req;;Type 51 request received from Scheduler@node2.supernodexp.hpc, sock=16
04/24/2018 00:53:03;0100;Server@node2;Req;;Type 11 request received from Scheduler@node2.supernodexp.hpc, sock=16
04/24/2018 00:53:03;0008;Server@node2;Job;12265.node2.supernodexp.hpc;Job Modified at request of Scheduler@node2.supernodexp.hpc
04/24/2018 00:53:20;0080;Server@node2;Job;12264.node2.supernodexp.hpc;Obit received momhop:1 serverhop:1 state:4 substate:42
04/24/2018 00:53:21;0010;Server@node2;Job;12264.node2.supernodexp.hpc;Exit_status=0 resources_used.cpupercent=0 resources_used.cput=00:00:00 resources_used.mem=9084kb resources_used.ncpus=4 resources_used.vmem=104700kb resources_used.walltime=00:00:22
04/24/2018 00:53:21;0100;Server@node2;Job;12264.node2.supernodexp.hpc;dequeuing from workq, state 5
04/24/2018 00:53:21;0040;Server@node2;Svr;node2.supernodexp.hpc;Scheduler sent command 2
04/24/2018 00:53:21;0040;Server@node2;Svr;node2.supernodexp.hpc;Scheduler sent command 0
04/24/2018 00:53:21;0100;Server@node2;Req;;Type 21 request received from Scheduler@node2.supernodexp.hpc, sock=16
04/24/2018 00:53:21;0100;Server@node2;Req;;Type 81 request received from Scheduler@node2.supernodexp.hpc, sock=16
04/24/2018 00:53:21;0100;Server@node2;Req;;Type 71 request received from Scheduler@node2.supernodexp.hpc, sock=16
04/24/2018 00:53:21;0100;Server@node2;Req;;Type 58 request received from Scheduler@node2.supernodexp.hpc, sock=16
04/24/2018 00:53:21;0100;Server@node2;Req;;Type 20 request received from Scheduler@node2.supernodexp.hpc, sock=16
04/24/2018 00:53:21;0100;Server@node2;Req;;Type 51 request received from Scheduler@node2.supernodexp.hpc, sock=16
04/24/2018 00:53:49;0080;Server@node2;Job;12261.node2.supernodexp.hpc;Obit received momhop:1 serverhop:1 state:4 substate:42
04/24/2018 00:53:50;0010;Server@node2;Job;12261.node2.supernodexp.hpc;Exit_status=0 resources_used.cpupercent=0 resources_used.cput=00:00:00 resources_used.mem=9400kb resources_used.ncpus=12 resources_used.vmem=171960kb resources_used.walltime=00:05:52
04/24/2018 00:53:50;0100;Server@node2;Job;12261.node2.supernodexp.hpc;dequeuing from workq, state 5
04/24/2018 00:53:50;0040;Server@node2;Svr;node2.supernodexp.hpc;Scheduler sent command 2
04/24/2018 00:53:50;0040;Server@node2;Svr;node2.supernodexp.hpc;Scheduler sent command 0
04/24/2018 00:53:50;0100;Server@node2;Req;;Type 21 request received from Scheduler@node2.supernodexp.hpc, sock=16
04/24/2018 00:53:50;0100;Server@node2;Req;;Type 81 request received from Scheduler@node2.supernodexp.hpc, sock=16
04/24/2018 00:53:50;0100;Server@node2;Req;;Type 71 request received from Scheduler@node2.supernodexp.hpc, sock=16
04/24/2018 00:53:50;0100;Server@node2;Req;;Type 58 request received from Scheduler@node2.supernodexp.hpc, sock=16
04/24/2018 00:53:50;0100;Server@node2;Req;;Type 20 request received from Scheduler@node2.supernodexp.hpc, sock=16
04/24/2018 00:53:50;0100;Server@node2;Req;;Type 51 request received from Scheduler@node2.supernodexp.hpc, sock=16
04/24/2018 00:53:50;0100;Server@node2;Req;;Type 23 request received from Scheduler@node2.supernodexp.hpc, sock=16
04/24/2018 00:53:50;0008;Server@node2;Job;12265.node2.supernodexp.hpc;Job Run at request of Scheduler@node2.supernodexp.hpc on exec_vnode (node13:ncpus=32:nmics=2:mem=31457280kb)
04/24/2018 00:53:50;0001;Server@node2;Svr;Server@node2;Success (0) in req_runjob2, return value of svr_startjob is 0
04/24/2018 00:53:50;0100;Server@node2;Req;;Type 11 request received from Scheduler@node2.supernodexp.hpc, sock=16
04/24/2018 00:53:50;0008;Server@node2;Job;12266.node2.supernodexp.hpc;Job Modified at request of Scheduler@node2.supernodexp.hpc
04/24/2018 01:01:18;0080;Server@node2;Job;12246.node2.supernodexp.hpc;Obit received momhop:1 serverhop:1 state:4 substate:42
04/24/2018 01:01:19;0080;Server@node2;Job;12251.node2.supernodexp.hpc;Obit received momhop:1 serverhop:1 state:4 substate:42
04/24/2018 01:01:19;0010;Server@node2;Job;12246.node2.supernodexp.hpc;Exit_status=2 resources_used.cpupercent=0 resources_used.cput=00:00:00 resources_used.mem=9960kb resources_used.ncpus=32 resources_used.vmem=41144kb resources_used.walltime=00:20:28
04/24/2018 01:01:19;0100;Server@node2;Job;12246.node2.supernodexp.hpc;dequeuing from workq, state 5
04/24/2018 01:01:19;0040;Server@node2;Svr;node2.supernodexp.hpc;Scheduler sent command 2
04/24/2018 01:01:19;0040;Server@node2;Svr;node2.supernodexp.hpc;Scheduler sent command 0
04/24/2018 01:01:19;0100;Server@node2;Req;;Type 21 request received from Scheduler@node2.supernodexp.hpc, sock=16
04/24/2018 01:01:19;0100;Server@node2;Req;;Type 81 request received from Scheduler@node2.supernodexp.hpc, sock=16
04/24/2018 01:01:19;0100;Server@node2;Req;;Type 71 request received from Scheduler@node2.supernodexp.hpc, sock=16
04/24/2018 01:01:19;0100;Server@node2;Req;;Type 58 request received from Scheduler@node2.supernodexp.hpc, sock=16
04/24/2018 01:01:19;0100;Server@node2;Req;;Type 20 request received from Scheduler@node2.supernodexp.hpc, sock=16
04/24/2018 01:01:19;0100;Server@node2;Req;;Type 51 request received from Scheduler@node2.supernodexp.hpc, sock=16
04/24/2018 01:01:19;0100;Server@node2;Req;;Type 23 request received from Scheduler@node2.supernodexp.hpc, sock=16
04/24/2018 01:01:19;0008;Server@node2;Job;12266.node2.supernodexp.hpc;Job Run at request of Scheduler@node2.supernodexp.hpc on exec_vnode (node14:nmics=2:ncpus=2:mem=41943040kb)
04/24/2018 01:01:19;0001;Server@node2;Svr;Server@node2;Success (0) in req_runjob2, return value of svr_startjob is 0
04/24/2018 01:01:19;0100;Server@node2;Req;;Type 11 request received from Scheduler@node2.supernodexp.hpc, sock=16
04/24/2018 01:01:19;0008;Server@node2;Job;12267.node2.supernodexp.hpc;Job Modified at request of Scheduler@node2.supernodexp.hpc
04/24/2018 01:01:20;0010;Server@node2;Job;12251.node2.supernodexp.hpc;Exit_status=0 resources_used.cpupercent=0 resources_used.cput=00:00:00 resources_used.mem=9096kb resources_used.ncpus=8 resources_used.vmem=103036kb resources_used.walltime=00:13:46
04/24/2018 01:01:20;0100;Server@node2;Job;12251.node2.supernodexp.hpc;dequeuing from workq, state 5
04/24/2018 01:01:20;0040;Server@node2;Svr;node2.supernodexp.hpc;Scheduler sent command 2
04/24/2018 01:01:20;0040;Server@node2;Svr;node2.supernodexp.hpc;Scheduler sent command 0
04/24/2018 01:01:20;0100;Server@node2;Req;;Type 21 request received from Scheduler@node2.supernodexp.hpc, sock=16
04/24/2018 01:01:20;0100;Server@node2;Req;;Type 81 request received from Scheduler@node2.supernodexp.hpc, sock=16
04/24/2018 01:01:20;0100;Server@node2;Req;;Type 71 request received from Scheduler@node2.supernodexp.hpc, sock=16
04/24/2018 01:01:20;0100;Server@node2;Req;;Type 58 request received from Scheduler@node2.supernodexp.hpc, sock=16
04/24/2018 01:01:20;0100;Server@node2;Req;;Type 20 request received from Scheduler@node2.supernodexp.hpc, sock=16
04/24/2018 01:01:20;0100;Server@node2;Req;;Type 51 request received from Scheduler@node2.supernodexp.hpc, sock=16
04/24/2018 01:03:09;0080;Server@node2;Job;12266.node2.supernodexp.hpc;Obit received momhop:1 serverhop:1 state:4 substate:42
04/24/2018 01:03:10;0010;Server@node2;Job;12266.node2.supernodexp.hpc;Exit_status=0 resources_used.cpupercent=0 resources_used.cput=00:00:00 resources_used.mem=9968kb resources_used.ncpus=2 resources_used.vmem=102576kb resources_used.walltime=00:01:50
04/24/2018 01:03:10;0100;Server@node2;Job;12266.node2.supernodexp.hpc;dequeuing from workq, state 5
04/24/2018 01:03:10;0040;Server@node2;Svr;node2.supernodexp.hpc;Scheduler sent command 2
04/24/2018 01:03:10;0040;Server@node2;Svr;node2.supernodexp.hpc;Scheduler sent command 0
04/24/2018 01:03:10;0100;Server@node2;Req;;Type 21 request received from Scheduler@node2.supernodexp.hpc, sock=16
04/24/2018 01:03:10;0100;Server@node2;Req;;Type 81 request received from Scheduler@node2.supernodexp.hpc, sock=16
04/24/2018 01:03:10;0100;Server@node2;Req;;Type 71 request received from Scheduler@node2.supernodexp.hpc, sock=16
04/24/2018 01:03:10;0100;Server@node2;Req;;Type 58 request received from Scheduler@node2.supernodexp.hpc, sock=16
04/24/2018 01:03:10;0100;Server@node2;Req;;Type 20 request received from Scheduler@node2.supernodexp.hpc, sock=16
04/24/2018 01:03:10;0100;Server@node2;Req;;Type 51 request received from Scheduler@node2.supernodexp.hpc, sock=16
04/24/2018 01:03:10;0100;Server@node2;Req;;Type 23 request received from Scheduler@node2.supernodexp.hpc, sock=16
04/24/2018 01:03:10;0008;Server@node2;Job;12267.node2.supernodexp.hpc;Job Run at request of Scheduler@node2.supernodexp.hpc on exec_vnode (node14:nmics=2:ncpus=2:mem=41943040kb)
04/24/2018 01:03:10;0001;Server@node2;Svr;Server@node2;Success (0) in req_runjob2, return value of svr_startjob is 0
04/24/2018 01:03:10;0100;Server@node2;Req;;Type 11 request received from Scheduler@node2.supernodexp.hpc, sock=16
04/24/2018 01:03:10;0008;Server@node2;Job;12268.node2.supernodexp.hpc;Job Modified at request of Scheduler@node2.supernodexp.hpc
04/24/2018 01:05:00;0080;Server@node2;Job;12267.node2.supernodexp.hpc;Obit received momhop:1 serverhop:1 state:4 substate:42
04/24/2018 01:05:01;0010;Server@node2;Job;12267.node2.supernodexp.hpc;Exit_status=0 resources_used.cpupercent=0 resources_used.cput=00:00:00 resources_used.mem=10028kb resources_used.ncpus=2 resources_used.vmem=102576kb resources_used.walltime=00:01:50
04/24/2018 01:05:01;0100;Server@node2;Job;12267.node2.supernodexp.hpc;dequeuing from workq, state 5
04/24/2018 01:05:01;0040;Server@node2;Svr;node2.supernodexp.hpc;Scheduler sent command 2
04/24/2018 01:05:01;0040;Server@node2;Svr;node2.supernodexp.hpc;Scheduler sent command 0
04/24/2018 01:05:01;0100;Server@node2;Req;;Type 21 request received from Scheduler@node2.supernodexp.hpc, sock=16
04/24/2018 01:05:01;0100;Server@node2;Req;;Type 81 request received from Scheduler@node2.supernodexp.hpc, sock=16
04/24/2018 01:05:01;0100;Server@node2;Req;;Type 71 request received from Scheduler@node2.supernodexp.hpc, sock=16
04/24/2018 01:05:01;0100;Server@node2;Req;;Type 58 request received from Scheduler@node2.supernodexp.hpc, sock=16
04/24/2018 01:05:01;0100;Server@node2;Req;;Type 20 request received from Scheduler@node2.supernodexp.hpc, sock=16
04/24/2018 01:05:01;0100;Server@node2;Req;;Type 51 request received from Scheduler@node2.supernodexp.hpc, sock=16
04/24/2018 01:05:01;0100;Server@node2;Req;;Type 23 request received from Scheduler@node2.supernodexp.hpc, sock=16
04/24/2018 01:05:01;0008;Server@node2;Job;12268.node2.supernodexp.hpc;Job Run at request of Scheduler@node2.supernodexp.hpc on exec_vnode (node14:nmics=2:ncpus=2:mem=2097152kb)
04/24/2018 01:05:01;0001;Server@node2;Svr;Server@node2;Success (0) in req_runjob2, return value of svr_startjob is 0
04/24/2018 01:05:01;0100;Server@node2;Req;;Type 23 request received from Scheduler@node2.supernodexp.hpc, sock=16
04/24/2018 01:05:01;0008;Server@node2;Job;12269.node2.supernodexp.hpc;Job Run at request of Scheduler@node2.supernodexp.hpc on exec_vnode (node3:ncpus=12:mem=20971520kb)
04/24/2018 01:05:01;0001;Server@node2;Svr;Server@node2;Success (0) in req_runjob2, return value of svr_startjob is 0
04/24/2018 01:05:01;0100;Server@node2;Req;;Type 23 request received from Scheduler@node2.supernodexp.hpc, sock=16
04/24/2018 01:05:01;0008;Server@node2;Job;12270.node2.supernodexp.hpc;Job Run at request of Scheduler@node2.supernodexp.hpc on exec_vnode (node14:ncpus=24:mem=5242880kb)
04/24/2018 01:05:01;0001;Server@node2;Svr;Server@node2;Success (0) in req_runjob2, return value of svr_startjob is 0
04/24/2018 01:05:01;0100;Server@node2;Req;;Type 23 request received from Scheduler@node2.supernodexp.hpc, sock=16
04/24/2018 01:05:01;0008;Server@node2;Job;12271.node2.supernodexp.hpc;Job Run at request of Scheduler@node2.supernodexp.hpc on exec_vnode (node3:ncpus=4:mem=5242880kb)
04/24/2018 01:05:01;0001;Server@node2;Svr;Server@node2;Success (0) in req_runjob2, return value of svr_startjob is 0
04/24/2018 01:05:01;0100;Server@node2;Req;;Type 11 request received from Scheduler@node2.supernodexp.hpc, sock=16
04/24/2018 01:05:01;0008;Server@node2;Job;12272.node2.supernodexp.hpc;Job Modified at request of Scheduler@node2.supernodexp.hpc
04/24/2018 01:05:05;0080;Server@node2;Job;12268.node2.supernodexp.hpc;Obit received momhop:1 serverhop:1 state:4 substate:42
04/24/2018 01:05:05;0080;Server@node2;Job;12270.node2.supernodexp.hpc;Obit received momhop:1 serverhop:1 state:4 substate:42
04/24/2018 01:05:06;0010;Server@node2;Job;12268.node2.supernodexp.hpc;Exit_status=0 resources_used.cpupercent=0 resources_used.cput=00:00:00 resources_used.mem=0kb resources_used.ncpus=2 resources_used.vmem=0kb resources_used.walltime=00:00:04
04/24/2018 01:05:06;0100;Server@node2;Job;12268.node2.supernodexp.hpc;dequeuing from workq, state 5
04/24/2018 01:05:06;0040;Server@node2;Svr;node2.supernodexp.hpc;Scheduler sent command 2
04/24/2018 01:05:06;0040;Server@node2;Svr;node2.supernodexp.hpc;Scheduler sent command 0
04/24/2018 01:05:06;0100;Server@node2;Req;;Type 21 request received from Scheduler@node2.supernodexp.hpc, sock=16
04/24/2018 01:05:06;0100;Server@node2;Req;;Type 81 request received from Scheduler@node2.supernodexp.hpc, sock=16
04/24/2018 01:05:06;0100;Server@node2;Req;;Type 71 request received from Scheduler@node2.supernodexp.hpc, sock=16
04/24/2018 01:05:06;0100;Server@node2;Req;;Type 58 request received from Scheduler@node2.supernodexp.hpc, sock=16
04/24/2018 01:05:06;0100;Server@node2;Req;;Type 20 request received from Scheduler@node2.supernodexp.hpc, sock=16
04/24/2018 01:05:06;0100;Server@node2;Req;;Type 51 request received from Scheduler@node2.supernodexp.hpc, sock=16
04/24/2018 01:05:06;0010;Server@node2;Job;12270.node2.supernodexp.hpc;Exit_status=0 resources_used.cpupercent=0 resources_used.cput=00:00:00 resources_used.mem=9368kb resources_used.ncpus=24 resources_used.vmem=104372kb resources_used.walltime=00:00:04
04/24/2018 01:05:06;0100;Server@node2;Job;12270.node2.supernodexp.hpc;dequeuing from workq, state 5
04/24/2018 01:05:06;0100;Server@node2;Req;;Type 23 request received from Scheduler@node2.supernodexp.hpc, sock=16
04/24/2018 01:05:06;0008;Server@node2;Job;12272.node2.supernodexp.hpc;Job Run at request of Scheduler@node2.supernodexp.hpc on exec_vnode (node14:nmics=2:ncpus=2:mem=2097152kb)
04/24/2018 01:05:06;0001;Server@node2;Svr;Server@node2;Success (0) in req_runjob2, return value of svr_startjob is 0
04/24/2018 01:05:06;0100;Server@node2;Req;;Type 23 request received from Scheduler@node2.supernodexp.hpc, sock=16
04/24/2018 01:05:06;0008;Server@node2;Job;12273.node2.supernodexp.hpc;Job Run at request of Scheduler@node2.supernodexp.hpc on exec_vnode (node14:ncpus=4:mem=5242880kb)
04/24/2018 01:05:06;0001;Server@node2;Svr;Server@node2;Success (0) in req_runjob2, return value of svr_startjob is 0
04/24/2018 01:05:06;0100;Server@node2;Req;;Type 23 request received from Scheduler@node2.supernodexp.hpc, sock=16
04/24/2018 01:05:06;0008;Server@node2;Job;12274.node2.supernodexp.hpc;Job Run at request of Scheduler@node2.supernodexp.hpc on exec_vnode (node14:ncpus=8:mem=10485760kb)
04/24/2018 01:05:06;0001;Server@node2;Svr;Server@node2;Success (0) in req_runjob2, return value of svr_startjob is 0
04/24/2018 01:05:06;0100;Server@node2;Req;;Type 23 request received from Scheduler@node2.supernodexp.hpc, sock=16
04/24/2018 01:05:06;0008;Server@node2;Job;12275.node2.supernodexp.hpc;Job Run at request of Scheduler@node2.supernodexp.hpc on exec_vnode (node14:ncpus=8:mem=20971520kb)
04/24/2018 01:05:06;0001;Server@node2;Svr;Server@node2;Success (0) in req_runjob2, return value of svr_startjob is 0
04/24/2018 01:05:06;0100;Server@node2;Req;;Type 11 request received from Scheduler@node2.supernodexp.hpc, sock=16
04/24/2018 01:05:06;0008;Server@node2;Job;12276.node2.supernodexp.hpc;Job Modified at request of Scheduler@node2.supernodexp.hpc
04/24/2018 01:05:06;0040;Server@node2;Svr;node2.supernodexp.hpc;Scheduler sent command 2
04/24/2018 01:05:06;0040;Server@node2;Svr;node2.supernodexp.hpc;Scheduler sent command 0
04/24/2018 01:05:06;0100;Server@node2;Req;;Type 21 request received from Scheduler@node2.supernodexp.hpc, sock=16
04/24/2018 01:05:06;0100;Server@node2;Req;;Type 81 request received from Scheduler@node2.supernodexp.hpc, sock=16
04/24/2018 01:05:06;0100;Server@node2;Req;;Type 71 request received from Scheduler@node2.supernodexp.hpc, sock=16
04/24/2018 01:05:06;0100;Server@node2;Req;;Type 58 request received from Scheduler@node2.supernodexp.hpc, sock=16
04/24/2018 01:05:06;0100;Server@node2;Req;;Type 20 request received from Scheduler@node2.supernodexp.hpc, sock=16
04/24/2018 01:05:06;0100;Server@node2;Req;;Type 51 request received from Scheduler@node2.supernodexp.hpc, sock=16
04/24/2018 01:05:06;0100;Server@node2;Req;;Type 23 request received from Scheduler@node2.supernodexp.hpc, sock=16
04/24/2018 01:05:06;0008;Server@node2;Job;12276.node2.supernodexp.hpc;Job Run at request of Scheduler@node2.supernodexp.hpc on exec_vnode (node14:ncpus=8:mem=5242880kb)
04/24/2018 01:05:06;0001;Server@node2;Svr;Server@node2;Success (0) in req_runjob2, return value of svr_startjob is 0
04/24/2018 01:05:06;0100;Server@node2;Req;;Type 23 request received from Scheduler@node2.supernodexp.hpc, sock=16
04/24/2018 01:05:06;0008;Server@node2;Job;12277.node2.supernodexp.hpc;Job Run at request of Scheduler@node2.supernodexp.hpc on exec_vnode (node14:ncpus=12:mem=20971520kb)
04/24/2018 01:05:06;0001;Server@node2;Svr;Server@node2;Success (0) in req_runjob2, return value of svr_startjob is 0
04/24/2018 01:05:06;0100;Server@node2;Req;;Type 11 request received from Scheduler@node2.supernodexp.hpc, sock=16
04/24/2018 01:05:06;0008;Server@node2;Job;12278.node2.supernodexp.hpc;Job Modified at request of Scheduler@node2.supernodexp.hpc
04/24/2018 01:05:13;0080;Server@node2;Job;12272.node2.supernodexp.hpc;Obit received momhop:1 serverhop:1 state:4 substate:42
04/24/2018 01:05:14;0010;Server@node2;Job;12272.node2.supernodexp.hpc;Exit_status=0 resources_used.cpupercent=0 resources_used.cput=00:00:00 resources_used.mem=0kb resources_used.ncpus=2 resources_used.vmem=0kb resources_used.walltime=00:00:07
04/24/2018 01:05:14;0100;Server@node2;Job;12272.node2.supernodexp.hpc;dequeuing from workq, state 5
04/24/2018 01:05:14;0040;Server@node2;Svr;node2.supernodexp.hpc;Scheduler sent command 2
04/24/2018 01:05:14;0040;Server@node2;Svr;node2.supernodexp.hpc;Scheduler sent command 0
04/24/2018 01:05:14;0100;Server@node2;Req;;Type 21 request received from Scheduler@node2.supernodexp.hpc, sock=16
04/24/2018 01:05:14;0100;Server@node2;Req;;Type 81 request received from Scheduler@node2.supernodexp.hpc, sock=16
04/24/2018 01:05:14;0100;Server@node2;Req;;Type 71 request received from Scheduler@node2.supernodexp.hpc, sock=16
04/24/2018 01:05:14;0100;Server@node2;Req;;Type 58 request received from Scheduler@node2.supernodexp.hpc, sock=16
04/24/2018 01:05:14;0100;Server@node2;Req;;Type 20 request received from Scheduler@node2.supernodexp.hpc, sock=16
04/24/2018 01:05:14;0100;Server@node2;Req;;Type 51 request received from Scheduler@node2.supernodexp.hpc, sock=16
04/24/2018 01:05:14;0100;Server@node2;Req;;Type 23 request received from Scheduler@node2.supernodexp.hpc, sock=16
04/24/2018 01:05:15;0008;Server@node2;Job;12278.node2.supernodexp.hpc;Job Run at request of Scheduler@node2.supernodexp.hpc on exec_vnode (node14:ncpus=8:mem=20971520kb)
04/24/2018 01:05:15;0001;Server@node2;Svr;Server@node2;Success (0) in req_runjob2, return value of svr_startjob is 0
04/24/2018 01:05:15;0100;Server@node2;Req;;Type 11 request received from Scheduler@node2.supernodexp.hpc, sock=16
04/24/2018 01:05:15;0008;Server@node2;Job;12279.node2.supernodexp.hpc;Job Modified at request of Scheduler@node2.supernodexp.hpc
04/24/2018 01:05:19;0080;Server@node2;Job;12278.node2.supernodexp.hpc;Obit received momhop:1 serverhop:1 state:4 substate:42
04/24/2018 01:05:20;0010;Server@node2;Job;12278.node2.supernodexp.hpc;Exit_status=0 resources_used.cpupercent=0 resources_used.cput=00:00:00 resources_used.mem=0kb resources_used.ncpus=8 resources_used.vmem=0kb resources_used.walltime=00:00:04
04/24/2018 01:05:20;0100;Server@node2;Job;12278.node2.supernodexp.hpc;dequeuing from workq, state 5
04/24/2018 01:05:20;0080;Server@node2;Job;12271.node2.supernodexp.hpc;Obit received momhop:1 serverhop:1 state:4 substate:42
04/24/2018 01:05:20;0040;Server@node2;Svr;node2.supernodexp.hpc;Scheduler sent command 2
04/24/2018 01:05:20;0040;Server@node2;Svr;node2.supernodexp.hpc;Scheduler sent command 0
04/24/2018 01:05:20;0100;Server@node2;Req;;Type 21 request received from Scheduler@node2.supernodexp.hpc, sock=16
04/24/2018 01:05:20;0100;Server@node2;Req;;Type 81 request received from Scheduler@node2.supernodexp.hpc, sock=16
04/24/2018 01:05:20;0100;Server@node2;Req;;Type 71 request received from Scheduler@node2.supernodexp.hpc, sock=16
04/24/2018 01:05:20;0100;Server@node2;Req;;Type 58 request received from Scheduler@node2.supernodexp.hpc, sock=16
04/24/2018 01:05:20;0100;Server@node2;Req;;Type 20 request received from Scheduler@node2.supernodexp.hpc, sock=16
04/24/2018 01:05:20;0100;Server@node2;Req;;Type 51 request received from Scheduler@node2.supernodexp.hpc, sock=16
04/24/2018 01:05:20;0100;Server@node2;Req;;Type 23 request received from Scheduler@node2.supernodexp.hpc, sock=16
04/24/2018 01:05:20;0008;Server@node2;Job;12279.node2.supernodexp.hpc;Job Run at request of Scheduler@node2.supernodexp.hpc on exec_vnode (node14:ncpus=8:mem=20971520kb)
04/24/2018 01:05:20;0001;Server@node2;Svr;Server@node2;Success (0) in req_runjob2, return value of svr_startjob is 0
04/24/2018 01:05:20;0100;Server@node2;Req;;Type 11 request received from Scheduler@node2.supernodexp.hpc, sock=16
04/24/2018 01:05:20;0008;Server@node2;Job;12280.node2.supernodexp.hpc;Job Modified at request of Scheduler@node2.supernodexp.hpc
04/24/2018 01:05:21;0010;Server@node2;Job;12271.node2.supernodexp.hpc;Exit_status=0 resources_used.cpupercent=0 resources_used.cput=00:00:00 resources_used.mem=9100kb resources_used.ncpus=4 resources_used.vmem=102780kb resources_used.walltime=00:00:20
04/24/2018 01:05:21;0100;Server@node2;Job;12271.node2.supernodexp.hpc;dequeuing from workq, state 5
04/24/2018 01:05:21;0040;Server@node2;Svr;node2.supernodexp.hpc;Scheduler sent command 2
04/24/2018 01:05:21;0040;Server@node2;Svr;node2.supernodexp.hpc;Scheduler sent command 0
04/24/2018 01:05:21;0100;Server@node2;Req;;Type 21 request received from Scheduler@node2.supernodexp.hpc, sock=16
04/24/2018 01:05:21;0100;Server@node2;Req;;Type 81 request received from Scheduler@node2.supernodexp.hpc, sock=16
04/24/2018 01:05:21;0100;Server@node2;Req;;Type 71 request received from Scheduler@node2.supernodexp.hpc, sock=16
04/24/2018 01:05:21;0100;Server@node2;Req;;Type 58 request received from Scheduler@node2.supernodexp.hpc, sock=16
04/24/2018 01:05:21;0100;Server@node2;Req;;Type 20 request received from Scheduler@node2.supernodexp.hpc, sock=16
04/24/2018 01:05:21;0100;Server@node2;Req;;Type 51 request received from Scheduler@node2.supernodexp.hpc, sock=16
04/24/2018 01:05:21;0100;Server@node2;Req;;Type 11 request received from Scheduler@node2.supernodexp.hpc, sock=16
04/24/2018 01:05:21;0008;Server@node2;Job;12280.node2.supernodexp.hpc;Job Modified at request of Scheduler@node2.supernodexp.hpc
04/24/2018 01:05:24;0080;Server@node2;Job;12279.node2.supernodexp.hpc;Obit received momhop:1 serverhop:1 state:4 substate:42
04/24/2018 01:05:25;0010;Server@node2;Job;12279.node2.supernodexp.hpc;Exit_status=0 resources_used.cpupercent=0 resources_used.cput=00:00:00 resources_used.mem=0kb resources_used.ncpus=8 resources_used.vmem=0kb resources_used.walltime=00:00:04
04/24/2018 01:05:25;0100;Server@node2;Job;12279.node2.supernodexp.hpc;dequeuing from workq, state 5
04/24/2018 01:05:25;0040;Server@node2;Svr;node2.supernodexp.hpc;Scheduler sent command 2
04/24/2018 01:05:25;0040;Server@node2;Svr;node2.supernodexp.hpc;Scheduler sent command 0
04/24/2018 01:05:25;0100;Server@node2;Req;;Type 21 request received from Scheduler@node2.supernodexp.hpc, sock=16
04/24/2018 01:05:25;0100;Server@node2;Req;;Type 81 request received from Scheduler@node2.supernodexp.hpc, sock=16
04/24/2018 01:05:25;0100;Server@node2;Req;;Type 71 request received from Scheduler@node2.supernodexp.hpc, sock=16
04/24/2018 01:05:25;0100;Server@node2;Req;;Type 58 request received from Scheduler@node2.supernodexp.hpc, sock=16
04/24/2018 01:05:25;0100;Server@node2;Req;;Type 20 request received from Scheduler@node2.supernodexp.hpc, sock=16
04/24/2018 01:05:25;0100;Server@node2;Req;;Type 51 request received from Scheduler@node2.supernodexp.hpc, sock=16
04/24/2018 01:05:25;0100;Server@node2;Req;;Type 11 request received from Scheduler@node2.supernodexp.hpc, sock=16
04/24/2018 01:05:25;0008;Server@node2;Job;12280.node2.supernodexp.hpc;Job Modified at request of Scheduler@node2.supernodexp.hpc
04/24/2018 01:05:25;0080;Server@node2;Job;12273.node2.supernodexp.hpc;Obit received momhop:1 serverhop:1 state:4 substate:42
04/24/2018 01:05:26;0010;Server@node2;Job;12273.node2.supernodexp.hpc;Exit_status=0 resources_used.cpupercent=0 resources_used.cput=00:00:00 resources_used.mem=9380kb resources_used.ncpus=4 resources_used.vmem=169908kb resources_used.walltime=00:00:19
04/24/2018 01:05:26;0100;Server@node2;Job;12273.node2.supernodexp.hpc;dequeuing from workq, state 5
04/24/2018 01:05:26;0040;Server@node2;Svr;node2.supernodexp.hpc;Scheduler sent command 2
04/24/2018 01:05:26;0040;Server@node2;Svr;node2.supernodexp.hpc;Scheduler sent command 0
04/24/2018 01:05:26;0100;Server@node2;Req;;Type 21 request received from Scheduler@node2.supernodexp.hpc, sock=16
04/24/2018 01:05:26;0100;Server@node2;Req;;Type 81 request received from Scheduler@node2.supernodexp.hpc, sock=16
04/24/2018 01:05:26;0100;Server@node2;Req;;Type 71 request received from Scheduler@node2.supernodexp.hpc, sock=16
04/24/2018 01:05:26;0100;Server@node2;Req;;Type 58 request received from Scheduler@node2.supernodexp.hpc, sock=16
04/24/2018 01:05:26;0100;Server@node2;Req;;Type 20 request received from Scheduler@node2.supernodexp.hpc, sock=16
04/24/2018 01:05:26;0100;Server@node2;Req;;Type 51 request received from Scheduler@node2.supernodexp.hpc, sock=16
04/24/2018 01:05:26;0100;Server@node2;Req;;Type 11 request received from Scheduler@node2.supernodexp.hpc, sock=16
04/24/2018 01:05:26;0008;Server@node2;Job;12280.node2.supernodexp.hpc;Job Modified at request of Scheduler@node2.supernodexp.hpc
04/24/2018 01:05:30;0080;Server@node2;Job;12276.node2.supernodexp.hpc;Obit received momhop:1 serverhop:1 state:4 substate:42
04/24/2018 01:05:31;0010;Server@node2;Job;12276.node2.supernodexp.hpc;Exit_status=0 resources_used.cpupercent=0 resources_used.cput=00:00:00 resources_used.mem=9644kb resources_used.ncpus=8 resources_used.vmem=106036kb resources_used.walltime=00:00:24
04/24/2018 01:05:31;0100;Server@node2;Job;12276.node2.supernodexp.hpc;dequeuing from workq, state 5
04/24/2018 01:05:31;0040;Server@node2;Svr;node2.supernodexp.hpc;Scheduler sent command 2
04/24/2018 01:05:31;0040;Server@node2;Svr;node2.supernodexp.hpc;Scheduler sent command 0
04/24/2018 01:05:31;0100;Server@node2;Req;;Type 21 request received from Scheduler@node2.supernodexp.hpc, sock=16
04/24/2018 01:05:31;0100;Server@node2;Req;;Type 81 request received from Scheduler@node2.supernodexp.hpc, sock=16
04/24/2018 01:05:31;0100;Server@node2;Req;;Type 71 request received from Scheduler@node2.supernodexp.hpc, sock=16
04/24/2018 01:05:31;0100;Server@node2;Req;;Type 58 request received from Scheduler@node2.supernodexp.hpc, sock=16
04/24/2018 01:05:31;0100;Server@node2;Req;;Type 20 request received from Scheduler@node2.supernodexp.hpc, sock=16
04/24/2018 01:05:31;0100;Server@node2;Req;;Type 51 request received from Scheduler@node2.supernodexp.hpc, sock=16
04/24/2018 01:05:31;0100;Server@node2;Req;;Type 11 request received from Scheduler@node2.supernodexp.hpc, sock=16
04/24/2018 01:05:31;0008;Server@node2;Job;12280.node2.supernodexp.hpc;Job Modified at request of Scheduler@node2.supernodexp.hpc
04/24/2018 01:05:39;0080;Server@node2;Job;12274.node2.supernodexp.hpc;Obit received momhop:1 serverhop:1 state:4 substate:42
04/24/2018 01:05:40;0010;Server@node2;Job;12274.node2.supernodexp.hpc;Exit_status=0 resources_used.cpupercent=0 resources_used.cput=00:00:00 resources_used.mem=9636kb resources_used.ncpus=8 resources_used.vmem=450868kb resources_used.walltime=00:00:33
04/24/2018 01:05:40;0100;Server@node2;Job;12274.node2.supernodexp.hpc;dequeuing from workq, state 5
04/24/2018 01:05:40;0040;Server@node2;Svr;node2.supernodexp.hpc;Scheduler sent command 2
04/24/2018 01:05:40;0040;Server@node2;Svr;node2.supernodexp.hpc;Scheduler sent command 0
04/24/2018 01:05:40;0100;Server@node2;Req;;Type 21 request received from Scheduler@node2.supernodexp.hpc, sock=16
04/24/2018 01:05:40;0100;Server@node2;Req;;Type 81 request received from Scheduler@node2.supernodexp.hpc, sock=16
04/24/2018 01:05:40;0100;Server@node2;Req;;Type 71 request received from Scheduler@node2.supernodexp.hpc, sock=16
04/24/2018 01:05:40;0100;Server@node2;Req;;Type 58 request received from Scheduler@node2.supernodexp.hpc, sock=16
04/24/2018 01:05:40;0100;Server@node2;Req;;Type 20 request received from Scheduler@node2.supernodexp.hpc, sock=16
04/24/2018 01:05:40;0100;Server@node2;Req;;Type 51 request received from Scheduler@node2.supernodexp.hpc, sock=16
04/24/2018 01:05:40;0100;Server@node2;Req;;Type 11 request received from Scheduler@node2.supernodexp.hpc, sock=16
04/24/2018 01:05:40;0008;Server@node2;Job;12280.node2.supernodexp.hpc;Job Modified at request of Scheduler@node2.supernodexp.hpc
04/24/2018 01:05:41;0080;Server@node2;Job;12275.node2.supernodexp.hpc;Obit received momhop:1 serverhop:1 state:4 substate:42
04/24/2018 01:05:42;0010;Server@node2;Job;12275.node2.supernodexp.hpc;Exit_status=0 resources_used.cpupercent=0 resources_used.cput=00:00:00 resources_used.mem=9428kb resources_used.ncpus=8 resources_used.vmem=104372kb resources_used.walltime=00:00:35
04/24/2018 01:05:42;0100;Server@node2;Job;12275.node2.supernodexp.hpc;dequeuing from workq, state 5
04/24/2018 01:05:42;0040;Server@node2;Svr;node2.supernodexp.hpc;Scheduler sent command 2
04/24/2018 01:05:42;0040;Server@node2;Svr;node2.supernodexp.hpc;Scheduler sent command 0
04/24/2018 01:05:42;0100;Server@node2;Req;;Type 21 request received from Scheduler@node2.supernodexp.hpc, sock=16
04/24/2018 01:05:42;0100;Server@node2;Req;;Type 81 request received from Scheduler@node2.supernodexp.hpc, sock=16
04/24/2018 01:05:42;0100;Server@node2;Req;;Type 71 request received from Scheduler@node2.supernodexp.hpc, sock=16
04/24/2018 01:05:42;0100;Server@node2;Req;;Type 58 request received from Scheduler@node2.supernodexp.hpc, sock=16
04/24/2018 01:05:42;0100;Server@node2;Req;;Type 20 request received from Scheduler@node2.supernodexp.hpc, sock=16
04/24/2018 01:05:42;0100;Server@node2;Req;;Type 51 request received from Scheduler@node2.supernodexp.hpc, sock=16
04/24/2018 01:05:42;0100;Server@node2;Req;;Type 23 request received from Scheduler@node2.supernodexp.hpc, sock=16
04/24/2018 01:05:42;0008;Server@node2;Job;12280.node2.supernodexp.hpc;Job Run at request of Scheduler@node2.supernodexp.hpc on exec_vnode (node14:ncpus=32:nmics=2:mem=31457280kb)
04/24/2018 01:05:42;0001;Server@node2;Svr;Server@node2;Success (0) in req_runjob2, return value of svr_startjob is 0
04/24/2018 01:05:42;0100;Server@node2;Req;;Type 11 request received from Scheduler@node2.supernodexp.hpc, sock=16
04/24/2018 01:05:42;0008;Server@node2;Job;12281.node2.supernodexp.hpc;Job Modified at request of Scheduler@node2.supernodexp.hpc
04/24/2018 01:08:06;0080;Server@node2;Job;12260.node2.supernodexp.hpc;Obit received momhop:1 serverhop:1 state:4 substate:42
04/24/2018 01:08:07;0010;Server@node2;Job;12260.node2.supernodexp.hpc;Exit_status=0 resources_used.cpupercent=0 resources_used.cput=00:00:00 resources_used.mem=9660kb resources_used.ncpus=12 resources_used.vmem=169908kb resources_used.walltime=00:20:15
04/24/2018 01:08:07;0100;Server@node2;Job;12260.node2.supernodexp.hpc;dequeuing from workq, state 5
04/24/2018 01:08:07;0040;Server@node2;Svr;node2.supernodexp.hpc;Scheduler sent command 2
04/24/2018 01:08:07;0040;Server@node2;Svr;node2.supernodexp.hpc;Scheduler sent command 0
04/24/2018 01:08:07;0100;Server@node2;Req;;Type 21 request received from Scheduler@node2.supernodexp.hpc, sock=16
04/24/2018 01:08:07;0100;Server@node2;Req;;Type 81 request received from Scheduler@node2.supernodexp.hpc, sock=16
04/24/2018 01:08:07;0100;Server@node2;Req;;Type 71 request received from Scheduler@node2.supernodexp.hpc, sock=16
04/24/2018 01:08:07;0100;Server@node2;Req;;Type 58 request received from Scheduler@node2.supernodexp.hpc, sock=16
04/24/2018 01:08:07;0100;Server@node2;Req;;Type 20 request received from Scheduler@node2.supernodexp.hpc, sock=16
04/24/2018 01:08:07;0100;Server@node2;Req;;Type 51 request received from Scheduler@node2.supernodexp.hpc, sock=16
04/24/2018 01:08:07;0100;Server@node2;Req;;Type 23 request received from Scheduler@node2.supernodexp.hpc, sock=16
04/24/2018 01:08:07;0008;Server@node2;Job;12281.node2.supernodexp.hpc;Job Run at request of Scheduler@node2.supernodexp.hpc on exec_vnode (node13:ncpus=8:mem=10485760kb)
04/24/2018 01:08:07;0001;Server@node2;Svr;Server@node2;Success (0) in req_runjob2, return value of svr_startjob is 0
04/24/2018 01:08:07;0100;Server@node2;Req;;Type 11 request received from Scheduler@node2.supernodexp.hpc, sock=16
04/24/2018 01:08:07;0008;Server@node2;Job;12282.node2.supernodexp.hpc;Job Modified at request of Scheduler@node2.supernodexp.hpc
04/24/2018 01:08:35;0080;Server@node2;Job;12281.node2.supernodexp.hpc;Obit received momhop:1 serverhop:1 state:4 substate:42
04/24/2018 01:08:48;0010;Server@node2;Job;12281.node2.supernodexp.hpc;Exit_status=0 resources_used.cpupercent=0 resources_used.cput=00:00:00 resources_used.mem=9652kb resources_used.ncpus=8 resources_used.vmem=104372kb resources_used.walltime=00:00:28
04/24/2018 01:08:48;0100;Server@node2;Job;12281.node2.supernodexp.hpc;dequeuing from workq, state 5
04/24/2018 01:08:48;0040;Server@node2;Svr;node2.supernodexp.hpc;Scheduler sent command 2
04/24/2018 01:08:48;0040;Server@node2;Svr;node2.supernodexp.hpc;Scheduler sent command 0
04/24/2018 01:08:48;0100;Server@node2;Req;;Type 21 request received from Scheduler@node2.supernodexp.hpc, sock=16
04/24/2018 01:08:48;0100;Server@node2;Req;;Type 81 request received from Scheduler@node2.supernodexp.hpc, sock=16
04/24/2018 01:08:48;0100;Server@node2;Req;;Type 71 request received from Scheduler@node2.supernodexp.hpc, sock=16
04/24/2018 01:08:48;0100;Server@node2;Req;;Type 58 request received from Scheduler@node2.supernodexp.hpc, sock=16
04/24/2018 01:08:48;0100;Server@node2;Req;;Type 20 request received from Scheduler@node2.supernodexp.hpc, sock=16
04/24/2018 01:08:48;0100;Server@node2;Req;;Type 51 request received from Scheduler@node2.supernodexp.hpc, sock=16
04/24/2018 01:08:48;0080;Server@node2;Job;12248.node2.supernodexp.hpc;Obit received momhop:1 serverhop:1 state:4 substate:42
04/24/2018 01:08:48;0100;Server@node2;Req;;Type 23 request received from Scheduler@node2.supernodexp.hpc, sock=16
04/24/2018 01:08:48;0008;Server@node2;Job;12282.node2.supernodexp.hpc;Job Run at request of Scheduler@node2.supernodexp.hpc on exec_vnode (node13:ncpus=12:mem=20971520kb)
04/24/2018 01:08:48;0001;Server@node2;Svr;Server@node2;Success (0) in req_runjob2, return value of svr_startjob is 0
04/24/2018 01:08:48;0100;Server@node2;Req;;Type 11 request received from Scheduler@node2.supernodexp.hpc, sock=16
04/24/2018 01:08:48;0008;Server@node2;Job;12283.node2.supernodexp.hpc;Job Modified at request of Scheduler@node2.supernodexp.hpc
04/24/2018 01:08:48;0010;Server@node2;Job;12248.node2.supernodexp.hpc;Exit_status=2 resources_used.cpupercent=0 resources_used.cput=00:00:00 resources_used.mem=9460kb resources_used.ncpus=32 resources_used.vmem=103292kb resources_used.walltime=00:22:04
04/24/2018 01:08:48;0100;Server@node2;Job;12248.node2.supernodexp.hpc;dequeuing from workq, state 5
04/24/2018 01:08:48;0040;Server@node2;Svr;node2.supernodexp.hpc;Scheduler sent command 2
04/24/2018 01:08:48;0040;Server@node2;Svr;node2.supernodexp.hpc;Scheduler sent command 0
04/24/2018 01:08:48;0100;Server@node2;Req;;Type 21 request received from Scheduler@node2.supernodexp.hpc, sock=16
04/24/2018 01:08:48;0100;Server@node2;Req;;Type 81 request received from Scheduler@node2.supernodexp.hpc, sock=16
04/24/2018 01:08:48;0100;Server@node2;Req;;Type 71 request received from Scheduler@node2.supernodexp.hpc, sock=16
04/24/2018 01:08:48;0100;Server@node2;Req;;Type 58 request received from Scheduler@node2.supernodexp.hpc, sock=16
04/24/2018 01:08:49;0100;Server@node2;Req;;Type 20 request received from Scheduler@node2.supernodexp.hpc, sock=16
04/24/2018 01:08:49;0100;Server@node2;Req;;Type 51 request received from Scheduler@node2.supernodexp.hpc, sock=16
04/24/2018 01:08:49;0100;Server@node2;Req;;Type 23 request received from Scheduler@node2.supernodexp.hpc, sock=16
04/24/2018 01:08:49;0008;Server@node2;Job;12283.node2.supernodexp.hpc;Job Run at request of Scheduler@node2.supernodexp.hpc on exec_vnode (node3:ncpus=24:mem=5242880kb)
04/24/2018 01:08:49;0001;Server@node2;Svr;Server@node2;Success (0) in req_runjob2, return value of svr_startjob is 0
04/24/2018 01:08:49;0100;Server@node2;Req;;Type 23 request received from Scheduler@node2.supernodexp.hpc, sock=16
04/24/2018 01:08:49;0008;Server@node2;Job;12284.node2.supernodexp.hpc;Job Run at request of Scheduler@node2.supernodexp.hpc on exec_vnode (node3:nmics=2:ncpus=2:mem=41943040kb)
04/24/2018 01:08:49;0001;Server@node2;Svr;Server@node2;Success (0) in req_runjob2, return value of svr_startjob is 0
04/24/2018 01:08:49;0100;Server@node2;Req;;Type 23 request received from Scheduler@node2.supernodexp.hpc, sock=16
04/24/2018 01:08:49;0008;Server@node2;Job;12285.node2.supernodexp.hpc;Job Run at request of Scheduler@node2.supernodexp.hpc on exec_vnode (node3:ncpus=4:mem=5242880kb)
04/24/2018 01:08:49;0001;Server@node2;Svr;Server@node2;Success (0) in req_runjob2, return value of svr_startjob is 0
04/24/2018 01:08:49;0100;Server@node2;Req;;Type 11 request received from Scheduler@node2.supernodexp.hpc, sock=16
04/24/2018 01:08:49;0008;Server@node2;Job;12286.node2.supernodexp.hpc;Job Modified at request of Scheduler@node2.supernodexp.hpc
04/24/2018 01:08:58;0080;Server@node2;Job;12283.node2.supernodexp.hpc;Obit received momhop:1 serverhop:1 state:4 substate:42
04/24/2018 01:08:59;0010;Server@node2;Job;12283.node2.supernodexp.hpc;Exit_status=0 resources_used.cpupercent=0 resources_used.cput=00:00:00 resources_used.mem=0kb resources_used.ncpus=24 resources_used.vmem=0kb resources_used.walltime=00:00:10
04/24/2018 01:08:59;0100;Server@node2;Job;12283.node2.supernodexp.hpc;dequeuing from workq, state 5
04/24/2018 01:08:59;0040;Server@node2;Svr;node2.supernodexp.hpc;Scheduler sent command 2
04/24/2018 01:08:59;0040;Server@node2;Svr;node2.supernodexp.hpc;Scheduler sent command 0
04/24/2018 01:08:59;0100;Server@node2;Req;;Type 21 request received from Scheduler@node2.supernodexp.hpc, sock=16
04/24/2018 01:08:59;0100;Server@node2;Req;;Type 81 request received from Scheduler@node2.supernodexp.hpc, sock=16
04/24/2018 01:08:59;0100;Server@node2;Req;;Type 71 request received from Scheduler@node2.supernodexp.hpc, sock=16
04/24/2018 01:08:59;0100;Server@node2;Req;;Type 58 request received from Scheduler@node2.supernodexp.hpc, sock=16
04/24/2018 01:08:59;0100;Server@node2;Req;;Type 20 request received from Scheduler@node2.supernodexp.hpc, sock=16
04/24/2018 01:08:59;0100;Server@node2;Req;;Type 51 request received from Scheduler@node2.supernodexp.hpc, sock=16
04/24/2018 01:08:59;0100;Server@node2;Req;;Type 23 request received from Scheduler@node2.supernodexp.hpc, sock=16
04/24/2018 01:08:59;0008;Server@node2;Job;12286.node2.supernodexp.hpc;Job Run at request of Scheduler@node2.supernodexp.hpc on exec_vnode (node3:ncpus=8:mem=20971520kb)
04/24/2018 01:08:59;0001;Server@node2;Svr;Server@node2;Success (0) in req_runjob2, return value of svr_startjob is 0
04/24/2018 01:08:59;0100;Server@node2;Req;;Type 23 request received from Scheduler@node2.supernodexp.hpc, sock=16
04/24/2018 01:08:59;0008;Server@node2;Job;12287.node2.supernodexp.hpc;Job Run at request of Scheduler@node2.supernodexp.hpc on exec_vnode (node3:ncpus=8:mem=20971520kb)
04/24/2018 01:08:59;0001;Server@node2;Svr;Server@node2;Success (0) in req_runjob2, return value of svr_startjob is 0
04/24/2018 01:08:59;0100;Server@node2;Req;;Type 11 request received from Scheduler@node2.supernodexp.hpc, sock=16
04/24/2018 01:08:59;0008;Server@node2;Job;12288.node2.supernodexp.hpc;Job Modified at request of Scheduler@node2.supernodexp.hpc
04/24/2018 01:09:07;0080;Server@node2;Job;12286.node2.supernodexp.hpc;Obit received momhop:1 serverhop:1 state:4 substate:42
04/24/2018 01:09:08;0010;Server@node2;Job;12286.node2.supernodexp.hpc;Exit_status=0 resources_used.cpupercent=0 resources_used.cput=00:00:00 resources_used.mem=0kb resources_used.ncpus=8 resources_used.vmem=0kb resources_used.walltime=00:00:09
04/24/2018 01:09:08;0100;Server@node2;Job;12286.node2.supernodexp.hpc;dequeuing from workq, state 5
04/24/2018 01:09:08;0040;Server@node2;Svr;node2.supernodexp.hpc;Scheduler sent command 2
04/24/2018 01:09:08;0040;Server@node2;Svr;node2.supernodexp.hpc;Scheduler sent command 0
04/24/2018 01:09:08;0100;Server@node2;Req;;Type 21 request received from Scheduler@node2.supernodexp.hpc, sock=16
04/24/2018 01:09:08;0100;Server@node2;Req;;Type 81 request received from Scheduler@node2.supernodexp.hpc, sock=16
04/24/2018 01:09:08;0100;Server@node2;Req;;Type 71 request received from Scheduler@node2.supernodexp.hpc, sock=16
04/24/2018 01:09:08;0100;Server@node2;Req;;Type 58 request received from Scheduler@node2.supernodexp.hpc, sock=16
04/24/2018 01:09:08;0100;Server@node2;Req;;Type 20 request received from Scheduler@node2.supernodexp.hpc, sock=16
04/24/2018 01:09:08;0100;Server@node2;Req;;Type 51 request received from Scheduler@node2.supernodexp.hpc, sock=16
04/24/2018 01:09:08;0080;Server@node2;Job;12285.node2.supernodexp.hpc;Obit received momhop:1 serverhop:1 state:4 substate:42
04/24/2018 01:09:09;0010;Server@node2;Job;12285.node2.supernodexp.hpc;Exit_status=0 resources_used.cpupercent=0 resources_used.cput=00:00:00 resources_used.mem=9080kb resources_used.ncpus=4 resources_used.vmem=172032kb resources_used.walltime=00:00:20
04/24/2018 01:09:09;0100;Server@node2;Job;12285.node2.supernodexp.hpc;dequeuing from workq, state 5
04/24/2018 01:09:09;0040;Server@node2;Svr;node2.supernodexp.hpc;Scheduler sent command 2
04/24/2018 01:09:09;0040;Server@node2;Svr;node2.supernodexp.hpc;Scheduler sent command 0
04/24/2018 01:09:09;0100;Server@node2;Req;;Type 21 request received from Scheduler@node2.supernodexp.hpc, sock=16
04/24/2018 01:09:09;0100;Server@node2;Req;;Type 81 request received from Scheduler@node2.supernodexp.hpc, sock=16
04/24/2018 01:09:09;0100;Server@node2;Req;;Type 71 request received from Scheduler@node2.supernodexp.hpc, sock=16
04/24/2018 01:09:09;0100;Server@node2;Req;;Type 58 request received from Scheduler@node2.supernodexp.hpc, sock=16
04/24/2018 01:09:09;0100;Server@node2;Req;;Type 20 request received from Scheduler@node2.supernodexp.hpc, sock=16
04/24/2018 01:09:09;0100;Server@node2;Req;;Type 51 request received from Scheduler@node2.supernodexp.hpc, sock=16
04/24/2018 01:09:12;0080;Server@node2;Job;12287.node2.supernodexp.hpc;Obit received momhop:1 serverhop:1 state:4 substate:42
04/24/2018 01:09:13;0010;Server@node2;Job;12287.node2.supernodexp.hpc;Exit_status=0 resources_used.cpupercent=0 resources_used.cput=00:00:00 resources_used.mem=9092kb resources_used.ncpus=8 resources_used.vmem=105088kb resources_used.walltime=00:00:14
04/24/2018 01:09:13;0100;Server@node2;Job;12287.node2.supernodexp.hpc;dequeuing from workq, state 5
04/24/2018 01:09:13;0040;Server@node2;Svr;node2.supernodexp.hpc;Scheduler sent command 2
04/24/2018 01:09:13;0040;Server@node2;Svr;node2.supernodexp.hpc;Scheduler sent command 0
04/24/2018 01:09:13;0100;Server@node2;Req;;Type 21 request received from Scheduler@node2.supernodexp.hpc, sock=16
04/24/2018 01:09:13;0100;Server@node2;Req;;Type 81 request received from Scheduler@node2.supernodexp.hpc, sock=16
04/24/2018 01:09:13;0100;Server@node2;Req;;Type 71 request received from Scheduler@node2.supernodexp.hpc, sock=16
04/24/2018 01:09:13;0100;Server@node2;Req;;Type 58 request received from Scheduler@node2.supernodexp.hpc, sock=16
04/24/2018 01:09:13;0100;Server@node2;Req;;Type 20 request received from Scheduler@node2.supernodexp.hpc, sock=16
04/24/2018 01:09:13;0100;Server@node2;Req;;Type 51 request received from Scheduler@node2.supernodexp.hpc, sock=16
04/24/2018 01:10:41;0080;Server@node2;Job;12284.node2.supernodexp.hpc;Obit received momhop:1 serverhop:1 state:4 substate:42
04/24/2018 01:10:42;0010;Server@node2;Job;12284.node2.supernodexp.hpc;Exit_status=0 resources_used.cpupercent=0 resources_used.cput=00:00:00 resources_used.mem=9324kb resources_used.ncpus=2 resources_used.vmem=104444kb resources_used.walltime=00:01:53
04/24/2018 01:10:42;0100;Server@node2;Job;12284.node2.supernodexp.hpc;dequeuing from workq, state 5
04/24/2018 01:10:42;0040;Server@node2;Svr;node2.supernodexp.hpc;Scheduler sent command 2
04/24/2018 01:10:42;0040;Server@node2;Svr;node2.supernodexp.hpc;Scheduler sent command 0
04/24/2018 01:10:42;0100;Server@node2;Req;;Type 21 request received from Scheduler@node2.supernodexp.hpc, sock=16
04/24/2018 01:10:42;0100;Server@node2;Req;;Type 81 request received from Scheduler@node2.supernodexp.hpc, sock=16
04/24/2018 01:10:42;0100;Server@node2;Req;;Type 71 request received from Scheduler@node2.supernodexp.hpc, sock=16
04/24/2018 01:10:42;0100;Server@node2;Req;;Type 58 request received from Scheduler@node2.supernodexp.hpc, sock=16
04/24/2018 01:10:42;0100;Server@node2;Req;;Type 20 request received from Scheduler@node2.supernodexp.hpc, sock=16
04/24/2018 01:10:42;0100;Server@node2;Req;;Type 51 request received from Scheduler@node2.supernodexp.hpc, sock=16
04/24/2018 01:10:42;0100;Server@node2;Req;;Type 23 request received from Scheduler@node2.supernodexp.hpc, sock=16
04/24/2018 01:10:42;0008;Server@node2;Job;12288.node2.supernodexp.hpc;Job Run at request of Scheduler@node2.supernodexp.hpc on exec_vnode (node3:nmics=2:ncpus=12:mem=41943040kb)
04/24/2018 01:10:42;0001;Server@node2;Svr;Server@node2;Success (0) in req_runjob2, return value of svr_startjob is 0
04/24/2018 01:10:42;0100;Server@node2;Req;;Type 23 request received from Scheduler@node2.supernodexp.hpc, sock=16
04/24/2018 01:10:42;0008;Server@node2;Job;12289.node2.supernodexp.hpc;Job Run at request of Scheduler@node2.supernodexp.hpc on exec_vnode (node3:ncpus=2:mem=2097152kb)
04/24/2018 01:10:42;0001;Server@node2;Svr;Server@node2;Success (0) in req_runjob2, return value of svr_startjob is 0
04/24/2018 01:10:42;0100;Server@node2;Req;;Type 23 request received from Scheduler@node2.supernodexp.hpc, sock=16
04/24/2018 01:10:42;0008;Server@node2;Job;12290.node2.supernodexp.hpc;Job Run at request of Scheduler@node2.supernodexp.hpc on exec_vnode (node3:ncpus=8:mem=5242880kb)
04/24/2018 01:10:42;0001;Server@node2;Svr;Server@node2;Success (0) in req_runjob2, return value of svr_startjob is 0
04/24/2018 01:10:42;0100;Server@node2;Req;;Type 23 request received from Scheduler@node2.supernodexp.hpc, sock=16
04/24/2018 01:10:42;0008;Server@node2;Job;12291.node2.supernodexp.hpc;Job Run at request of Scheduler@node2.supernodexp.hpc on exec_vnode (node3:ncpus=12:mem=20971520kb)
04/24/2018 01:10:42;0001;Server@node2;Svr;Server@node2;Success (0) in req_runjob2, return value of svr_startjob is 0
04/24/2018 01:10:42;0100;Server@node2;Req;;Type 11 request received from Scheduler@node2.supernodexp.hpc, sock=16
04/24/2018 01:10:42;0008;Server@node2;Job;12292.node2.supernodexp.hpc;Job Modified at request of Scheduler@node2.supernodexp.hpc
04/24/2018 01:10:51;0080;Server@node2;Job;12289.node2.supernodexp.hpc;Obit received momhop:1 serverhop:1 state:4 substate:42
04/24/2018 01:10:52;0010;Server@node2;Job;12289.node2.supernodexp.hpc;Exit_status=0 resources_used.cpupercent=0 resources_used.cput=00:00:00 resources_used.mem=0kb resources_used.ncpus=2 resources_used.vmem=0kb resources_used.walltime=00:00:09
04/24/2018 01:10:52;0100;Server@node2;Job;12289.node2.supernodexp.hpc;dequeuing from workq, state 5
04/24/2018 01:10:52;0040;Server@node2;Svr;node2.supernodexp.hpc;Scheduler sent command 2
04/24/2018 01:10:52;0040;Server@node2;Svr;node2.supernodexp.hpc;Scheduler sent command 0
04/24/2018 01:10:52;0100;Server@node2;Req;;Type 21 request received from Scheduler@node2.supernodexp.hpc, sock=16
04/24/2018 01:10:52;0100;Server@node2;Req;;Type 81 request received from Scheduler@node2.supernodexp.hpc, sock=16
04/24/2018 01:10:52;0100;Server@node2;Req;;Type 71 request received from Scheduler@node2.supernodexp.hpc, sock=16
04/24/2018 01:10:52;0100;Server@node2;Req;;Type 58 request received from Scheduler@node2.supernodexp.hpc, sock=16
04/24/2018 01:10:52;0100;Server@node2;Req;;Type 20 request received from Scheduler@node2.supernodexp.hpc, sock=16
04/24/2018 01:10:52;0100;Server@node2;Req;;Type 51 request received from Scheduler@node2.supernodexp.hpc, sock=16
04/24/2018 01:10:52;0100;Server@node2;Req;;Type 11 request received from Scheduler@node2.supernodexp.hpc, sock=16
04/24/2018 01:10:52;0008;Server@node2;Job;12292.node2.supernodexp.hpc;Job Modified at request of Scheduler@node2.supernodexp.hpc
04/24/2018 01:11:11;0080;Server@node2;Job;12290.node2.supernodexp.hpc;Obit received momhop:1 serverhop:1 state:4 substate:42
04/24/2018 01:11:12;0010;Server@node2;Job;12290.node2.supernodexp.hpc;Exit_status=0 resources_used.cpupercent=0 resources_used.cput=00:00:00 resources_used.mem=9356kb resources_used.ncpus=8 resources_used.vmem=103036kb resources_used.walltime=00:00:29
04/24/2018 01:11:12;0100;Server@node2;Job;12290.node2.supernodexp.hpc;dequeuing from workq, state 5
04/24/2018 01:11:12;0040;Server@node2;Svr;node2.supernodexp.hpc;Scheduler sent command 2
04/24/2018 01:11:12;0040;Server@node2;Svr;node2.supernodexp.hpc;Scheduler sent command 0
04/24/2018 01:11:12;0100;Server@node2;Req;;Type 21 request received from Scheduler@node2.supernodexp.hpc, sock=16
04/24/2018 01:11:12;0100;Server@node2;Req;;Type 81 request received from Scheduler@node2.supernodexp.hpc, sock=16
04/24/2018 01:11:12;0100;Server@node2;Req;;Type 71 request received from Scheduler@node2.supernodexp.hpc, sock=16
04/24/2018 01:11:12;0100;Server@node2;Req;;Type 58 request received from Scheduler@node2.supernodexp.hpc, sock=16
04/24/2018 01:11:12;0100;Server@node2;Req;;Type 20 request received from Scheduler@node2.supernodexp.hpc, sock=16
04/24/2018 01:11:12;0100;Server@node2;Req;;Type 51 request received from Scheduler@node2.supernodexp.hpc, sock=16
04/24/2018 01:11:12;0100;Server@node2;Req;;Type 11 request received from Scheduler@node2.supernodexp.hpc, sock=16
04/24/2018 01:11:12;0008;Server@node2;Job;12292.node2.supernodexp.hpc;Job Modified at request of Scheduler@node2.supernodexp.hpc
04/24/2018 01:11:25;0080;Server@node2;Job;12277.node2.supernodexp.hpc;Obit received momhop:1 serverhop:1 state:4 substate:42
04/24/2018 01:11:26;0010;Server@node2;Job;12277.node2.supernodexp.hpc;Exit_status=0 resources_used.cpupercent=0 resources_used.cput=00:00:00 resources_used.mem=9648kb resources_used.ncpus=12 resources_used.vmem=104372kb resources_used.walltime=00:06:19
04/24/2018 01:11:26;0100;Server@node2;Job;12277.node2.supernodexp.hpc;dequeuing from workq, state 5
04/24/2018 01:11:26;0040;Server@node2;Svr;node2.supernodexp.hpc;Scheduler sent command 2
04/24/2018 01:11:26;0040;Server@node2;Svr;node2.supernodexp.hpc;Scheduler sent command 0
04/24/2018 01:11:26;0100;Server@node2;Req;;Type 21 request received from Scheduler@node2.supernodexp.hpc, sock=16
04/24/2018 01:11:26;0100;Server@node2;Req;;Type 81 request received from Scheduler@node2.supernodexp.hpc, sock=16
04/24/2018 01:11:26;0100;Server@node2;Req;;Type 71 request received from Scheduler@node2.supernodexp.hpc, sock=16
04/24/2018 01:11:26;0100;Server@node2;Req;;Type 58 request received from Scheduler@node2.supernodexp.hpc, sock=16
04/24/2018 01:11:26;0100;Server@node2;Req;;Type 20 request received from Scheduler@node2.supernodexp.hpc, sock=16
04/24/2018 01:11:26;0100;Server@node2;Req;;Type 51 request received from Scheduler@node2.supernodexp.hpc, sock=16
04/24/2018 01:11:26;0100;Server@node2;Req;;Type 11 request received from Scheduler@node2.supernodexp.hpc, sock=16
04/24/2018 01:11:26;0008;Server@node2;Job;12292.node2.supernodexp.hpc;Job Modified at request of Scheduler@node2.supernodexp.hpc
04/24/2018 01:15:25;0080;Server@node2;Job;12265.node2.supernodexp.hpc;Obit received momhop:1 serverhop:1 state:4 substate:42
04/24/2018 01:15:44;0080;Server@node2;Job;12282.node2.supernodexp.hpc;Obit received momhop:1 serverhop:1 state:4 substate:42
04/24/2018 01:15:50;0010;Server@node2;Job;12265.node2.supernodexp.hpc;Exit_status=2 resources_used.cpupercent=0 resources_used.cput=00:00:00 resources_used.mem=9436kb resources_used.ncpus=32 resources_used.vmem=170164kb resources_used.walltime=00:21:31
04/24/2018 01:15:50;0100;Server@node2;Job;12265.node2.supernodexp.hpc;dequeuing from workq, state 5
04/24/2018 01:15:50;0040;Server@node2;Svr;node2.supernodexp.hpc;Scheduler sent command 2
04/24/2018 01:15:50;0040;Server@node2;Svr;node2.supernodexp.hpc;Scheduler sent command 0
04/24/2018 01:15:50;0100;Server@node2;Req;;Type 21 request received from Scheduler@node2.supernodexp.hpc, sock=16
04/24/2018 01:15:50;0100;Server@node2;Req;;Type 81 request received from Scheduler@node2.supernodexp.hpc, sock=16
04/24/2018 01:15:50;0100;Server@node2;Req;;Type 71 request received from Scheduler@node2.supernodexp.hpc, sock=16
04/24/2018 01:15:50;0100;Server@node2;Req;;Type 58 request received from Scheduler@node2.supernodexp.hpc, sock=16
04/24/2018 01:15:50;0100;Server@node2;Req;;Type 20 request received from Scheduler@node2.supernodexp.hpc, sock=16
04/24/2018 01:15:50;0100;Server@node2;Req;;Type 51 request received from Scheduler@node2.supernodexp.hpc, sock=16
04/24/2018 01:15:50;0100;Server@node2;Req;;Type 23 request received from Scheduler@node2.supernodexp.hpc, sock=16
04/24/2018 01:15:50;0008;Server@node2;Job;12292.node2.supernodexp.hpc;Job Run at request of Scheduler@node2.supernodexp.hpc on exec_vnode (node13:ncpus=24:mem=5242880kb)
04/24/2018 01:15:50;0001;Server@node2;Svr;Server@node2;Success (0) in req_runjob2, return value of svr_startjob is 0
04/24/2018 01:15:50;0100;Server@node2;Req;;Type 23 request received from Scheduler@node2.supernodexp.hpc, sock=16
04/24/2018 01:15:50;0008;Server@node2;Job;12293.node2.supernodexp.hpc;Job Run at request of Scheduler@node2.supernodexp.hpc on exec_vnode (node3:ncpus=12:mem=20971520kb)
04/24/2018 01:15:50;0001;Server@node2;Svr;Server@node2;Success (0) in req_runjob2, return value of svr_startjob is 0
04/24/2018 01:15:50;0100;Server@node2;Req;;Type 23 request received from Scheduler@node2.supernodexp.hpc, sock=16
04/24/2018 01:15:50;0008;Server@node2;Job;12294.node2.supernodexp.hpc;Job Run at request of Scheduler@node2.supernodexp.hpc on exec_vnode (node13:nmics=2:ncpus=2:mem=41943040kb)
04/24/2018 01:15:50;0001;Server@node2;Svr;Server@node2;Success (0) in req_runjob2, return value of svr_startjob is 0
04/24/2018 01:15:50;0100;Server@node2;Req;;Type 23 request received from Scheduler@node2.supernodexp.hpc, sock=16
04/24/2018 01:15:50;0008;Server@node2;Job;12295.node2.supernodexp.hpc;Job Run at request of Scheduler@node2.supernodexp.hpc on exec_vnode (node14:ncpus=8:mem=5242880kb)
04/24/2018 01:15:50;0001;Server@node2;Svr;Server@node2;Success (0) in req_runjob2, return value of svr_startjob is 0
04/24/2018 01:15:50;0100;Server@node2;Req;;Type 23 request received from Scheduler@node2.supernodexp.hpc, sock=16
04/24/2018 01:15:50;0008;Server@node2;Job;12296.node2.supernodexp.hpc;Job Run at request of Scheduler@node2.supernodexp.hpc on exec_vnode (node14:ncpus=4:mem=5242880kb)
04/24/2018 01:15:50;0001;Server@node2;Svr;Server@node2;Success (0) in req_runjob2, return value of svr_startjob is 0
04/24/2018 01:15:50;0100;Server@node2;Req;;Type 23 request received from Scheduler@node2.supernodexp.hpc, sock=16
04/24/2018 01:15:50;0008;Server@node2;Job;12297.node2.supernodexp.hpc;Job Run at request of Scheduler@node2.supernodexp.hpc on exec_vnode (node13:ncpus=8:mem=10485760kb)
04/24/2018 01:15:50;0001;Server@node2;Svr;Server@node2;Success (0) in req_runjob2, return value of svr_startjob is 0
04/24/2018 01:15:50;0100;Server@node2;Req;;Type 11 request received from Scheduler@node2.supernodexp.hpc, sock=16
04/24/2018 01:15:50;0008;Server@node2;Job;12298.node2.supernodexp.hpc;Job Modified at request of Scheduler@node2.supernodexp.hpc
04/24/2018 01:15:51;0010;Server@node2;Job;12282.node2.supernodexp.hpc;Exit_status=0 resources_used.cpupercent=0 resources_used.cput=00:00:00 resources_used.mem=9232kb resources_used.ncpus=12 resources_used.vmem=171572kb resources_used.walltime=00:06:54
04/24/2018 01:15:51;0100;Server@node2;Job;12282.node2.supernodexp.hpc;dequeuing from workq, state 5
04/24/2018 01:15:51;0040;Server@node2;Svr;node2.supernodexp.hpc;Scheduler sent command 2
04/24/2018 01:15:51;0040;Server@node2;Svr;node2.supernodexp.hpc;Scheduler sent command 0
04/24/2018 01:15:51;0100;Server@node2;Req;;Type 21 request received from Scheduler@node2.supernodexp.hpc, sock=16
04/24/2018 01:15:51;0100;Server@node2;Req;;Type 81 request received from Scheduler@node2.supernodexp.hpc, sock=16
04/24/2018 01:15:51;0100;Server@node2;Req;;Type 71 request received from Scheduler@node2.supernodexp.hpc, sock=16
04/24/2018 01:15:51;0100;Server@node2;Req;;Type 58 request received from Scheduler@node2.supernodexp.hpc, sock=16
04/24/2018 01:15:51;0100;Server@node2;Req;;Type 20 request received from Scheduler@node2.supernodexp.hpc, sock=16
04/24/2018 01:15:51;0100;Server@node2;Req;;Type 51 request received from Scheduler@node2.supernodexp.hpc, sock=16
04/24/2018 01:15:51;0100;Server@node2;Req;;Type 23 request received from Scheduler@node2.supernodexp.hpc, sock=16
04/24/2018 01:15:51;0008;Server@node2;Job;12298.node2.supernodexp.hpc;Job Run at request of Scheduler@node2.supernodexp.hpc on exec_vnode (node13:ncpus=12:mem=20971520kb)
04/24/2018 01:15:51;0001;Server@node2;Svr;Server@node2;Success (0) in req_runjob2, return value of svr_startjob is 0
04/24/2018 01:15:51;0100;Server@node2;Req;;Type 23 request received from Scheduler@node2.supernodexp.hpc, sock=16
04/24/2018 01:15:51;0008;Server@node2;Job;12299.node2.supernodexp.hpc;Job Run at request of Scheduler@node2.supernodexp.hpc on exec_vnode (node14:ncpus=4:mem=5242880kb)
04/24/2018 01:15:51;0001;Server@node2;Svr;Server@node2;Success (0) in req_runjob2, return value of svr_startjob is 0
04/24/2018 01:15:51;0100;Server@node2;Req;;Type 23 request received from Scheduler@node2.supernodexp.hpc, sock=16
04/24/2018 01:15:51;0008;Server@node2;Job;12300.node2.supernodexp.hpc;Job Run at request of Scheduler@node2.supernodexp.hpc on exec_vnode (node13:ncpus=2:mem=2097152kb)
04/24/2018 01:15:51;0001;Server@node2;Svr;Server@node2;Success (0) in req_runjob2, return value of svr_startjob is 0
04/24/2018 01:15:51;0100;Server@node2;Req;;Type 11 request received from Scheduler@node2.supernodexp.hpc, sock=16
04/24/2018 01:15:51;0008;Server@node2;Job;12301.node2.supernodexp.hpc;Job Modified at request of Scheduler@node2.supernodexp.hpc
04/24/2018 01:15:54;0080;Server@node2;Job;12300.node2.supernodexp.hpc;Obit received momhop:1 serverhop:1 state:4 substate:42
04/24/2018 01:15:55;0010;Server@node2;Job;12300.node2.supernodexp.hpc;Exit_status=0 resources_used.cpupercent=0 resources_used.cput=00:00:00 resources_used.mem=0kb resources_used.ncpus=2 resources_used.vmem=0kb resources_used.walltime=00:00:03
04/24/2018 01:15:55;0100;Server@node2;Job;12300.node2.supernodexp.hpc;dequeuing from workq, state 5
04/24/2018 01:15:55;0040;Server@node2;Svr;node2.supernodexp.hpc;Scheduler sent command 2
04/24/2018 01:15:55;0040;Server@node2;Svr;node2.supernodexp.hpc;Scheduler sent command 0
04/24/2018 01:15:55;0100;Server@node2;Req;;Type 21 request received from Scheduler@node2.supernodexp.hpc, sock=16
04/24/2018 01:15:55;0100;Server@node2;Req;;Type 81 request received from Scheduler@node2.supernodexp.hpc, sock=16
04/24/2018 01:15:55;0100;Server@node2;Req;;Type 71 request received from Scheduler@node2.supernodexp.hpc, sock=16
04/24/2018 01:15:55;0100;Server@node2;Req;;Type 58 request received from Scheduler@node2.supernodexp.hpc, sock=16
04/24/2018 01:15:55;0100;Server@node2;Req;;Type 20 request received from Scheduler@node2.supernodexp.hpc, sock=16
04/24/2018 01:15:55;0100;Server@node2;Req;;Type 51 request received from Scheduler@node2.supernodexp.hpc, sock=16
04/24/2018 01:15:55;0100;Server@node2;Req;;Type 11 request received from Scheduler@node2.supernodexp.hpc, sock=16
04/24/2018 01:15:55;0008;Server@node2;Job;12301.node2.supernodexp.hpc;Job Modified at request of Scheduler@node2.supernodexp.hpc
04/24/2018 01:16:04;0080;Server@node2;Job;12296.node2.supernodexp.hpc;Obit received momhop:1 serverhop:1 state:4 substate:42
04/24/2018 01:16:04;0080;Server@node2;Job;12299.node2.supernodexp.hpc;Obit received momhop:1 serverhop:1 state:4 substate:42
04/24/2018 01:16:05;0010;Server@node2;Job;12296.node2.supernodexp.hpc;Exit_status=0 resources_used.cpupercent=0 resources_used.cput=00:00:00 resources_used.mem=9612kb resources_used.ncpus=4 resources_used.vmem=172216kb resources_used.walltime=00:00:14
04/24/2018 01:16:05;0100;Server@node2;Job;12296.node2.supernodexp.hpc;dequeuing from workq, state 5
04/24/2018 01:16:05;0040;Server@node2;Svr;node2.supernodexp.hpc;Scheduler sent command 2
04/24/2018 01:16:05;0040;Server@node2;Svr;node2.supernodexp.hpc;Scheduler sent command 0
04/24/2018 01:16:05;0100;Server@node2;Req;;Type 21 request received from Scheduler@node2.supernodexp.hpc, sock=16
04/24/2018 01:16:05;0100;Server@node2;Req;;Type 81 request received from Scheduler@node2.supernodexp.hpc, sock=16
04/24/2018 01:16:05;0100;Server@node2;Req;;Type 71 request received from Scheduler@node2.supernodexp.hpc, sock=16
04/24/2018 01:16:05;0100;Server@node2;Req;;Type 58 request received from Scheduler@node2.supernodexp.hpc, sock=16
04/24/2018 01:16:05;0010;Server@node2;Job;12299.node2.supernodexp.hpc;Exit_status=0 resources_used.cpupercent=0 resources_used.cput=00:00:00 resources_used.mem=9640kb resources_used.ncpus=4 resources_used.vmem=171960kb resources_used.walltime=00:00:14
04/24/2018 01:16:05;0100;Server@node2;Job;12299.node2.supernodexp.hpc;dequeuing from workq, state 5
04/24/2018 01:16:05;0100;Server@node2;Req;;Type 20 request received from Scheduler@node2.supernodexp.hpc, sock=16
04/24/2018 01:16:05;0100;Server@node2;Req;;Type 51 request received from Scheduler@node2.supernodexp.hpc, sock=16
04/24/2018 01:16:05;0100;Server@node2;Req;;Type 23 request received from Scheduler@node2.supernodexp.hpc, sock=16
04/24/2018 01:16:05;0008;Server@node2;Job;12301.node2.supernodexp.hpc;Job Run at request of Scheduler@node2.supernodexp.hpc on exec_vnode (node14:ncpus=8:mem=20971520kb)
04/24/2018 01:16:05;0001;Server@node2;Svr;Server@node2;Success (0) in req_runjob2, return value of svr_startjob is 0
04/24/2018 01:16:05;0100;Server@node2;Req;;Type 11 request received from Scheduler@node2.supernodexp.hpc, sock=16
04/24/2018 01:16:05;0008;Server@node2;Job;12302.node2.supernodexp.hpc;Job Modified at request of Scheduler@node2.supernodexp.hpc
04/24/2018 01:16:05;0040;Server@node2;Svr;node2.supernodexp.hpc;Scheduler sent command 2
04/24/2018 01:16:05;0040;Server@node2;Svr;node2.supernodexp.hpc;Scheduler sent command 0
04/24/2018 01:16:05;0100;Server@node2;Req;;Type 21 request received from Scheduler@node2.supernodexp.hpc, sock=16
04/24/2018 01:16:05;0100;Server@node2;Req;;Type 81 request received from Scheduler@node2.supernodexp.hpc, sock=16
04/24/2018 01:16:05;0100;Server@node2;Req;;Type 71 request received from Scheduler@node2.supernodexp.hpc, sock=16
04/24/2018 01:16:05;0100;Server@node2;Req;;Type 58 request received from Scheduler@node2.supernodexp.hpc, sock=16
04/24/2018 01:16:05;0100;Server@node2;Req;;Type 20 request received from Scheduler@node2.supernodexp.hpc, sock=16
04/24/2018 01:16:05;0100;Server@node2;Req;;Type 51 request received from Scheduler@node2.supernodexp.hpc, sock=16
04/24/2018 01:16:06;0080;Server@node2;Job;12295.node2.supernodexp.hpc;Obit received momhop:1 serverhop:1 state:4 substate:42
04/24/2018 01:16:07;0010;Server@node2;Job;12295.node2.supernodexp.hpc;Exit_status=0 resources_used.cpupercent=0 resources_used.cput=00:00:00 resources_used.mem=9376kb resources_used.ncpus=8 resources_used.vmem=108088kb resources_used.walltime=00:00:16
04/24/2018 01:16:07;0100;Server@node2;Job;12295.node2.supernodexp.hpc;dequeuing from workq, state 5
04/24/2018 01:16:07;0040;Server@node2;Svr;node2.supernodexp.hpc;Scheduler sent command 2
04/24/2018 01:16:07;0040;Server@node2;Svr;node2.supernodexp.hpc;Scheduler sent command 0
04/24/2018 01:16:07;0100;Server@node2;Req;;Type 21 request received from Scheduler@node2.supernodexp.hpc, sock=16
04/24/2018 01:16:07;0100;Server@node2;Req;;Type 81 request received from Scheduler@node2.supernodexp.hpc, sock=16
04/24/2018 01:16:07;0100;Server@node2;Req;;Type 71 request received from Scheduler@node2.supernodexp.hpc, sock=16
04/24/2018 01:16:07;0100;Server@node2;Req;;Type 58 request received from Scheduler@node2.supernodexp.hpc, sock=16
04/24/2018 01:16:07;0100;Server@node2;Req;;Type 20 request received from Scheduler@node2.supernodexp.hpc, sock=16
04/24/2018 01:16:07;0100;Server@node2;Req;;Type 51 request received from Scheduler@node2.supernodexp.hpc, sock=16
04/24/2018 01:16:07;0100;Server@node2;Req;;Type 23 request received from Scheduler@node2.supernodexp.hpc, sock=16
04/24/2018 01:16:07;0008;Server@node2;Job;12302.node2.supernodexp.hpc;Job Run at request of Scheduler@node2.supernodexp.hpc on exec_vnode (node14:ncpus=4:mem=5242880kb)
04/24/2018 01:16:07;0001;Server@node2;Svr;Server@node2;Success (0) in req_runjob2, return value of svr_startjob is 0
04/24/2018 01:16:07;0100;Server@node2;Req;;Type 23 request received from Scheduler@node2.supernodexp.hpc, sock=16
04/24/2018 01:16:07;0008;Server@node2;Job;12303.node2.supernodexp.hpc;Job Run at request of Scheduler@node2.supernodexp.hpc on exec_vnode (node14:ncpus=4:mem=5242880kb)
04/24/2018 01:16:07;0001;Server@node2;Svr;Server@node2;Success (0) in req_runjob2, return value of svr_startjob is 0
04/24/2018 01:16:07;0100;Server@node2;Req;;Type 11 request received from Scheduler@node2.supernodexp.hpc, sock=16
04/24/2018 01:16:07;0008;Server@node2;Job;12304.node2.supernodexp.hpc;Job Modified at request of Scheduler@node2.supernodexp.hpc
04/24/2018 01:16:10;0080;Server@node2;Job;12301.node2.supernodexp.hpc;Obit received momhop:1 serverhop:1 state:4 substate:42
04/24/2018 01:16:10;0010;Server@node2;Job;12301.node2.supernodexp.hpc;Exit_status=0 resources_used.cpupercent=0 resources_used.cput=00:00:00 resources_used.mem=9620kb resources_used.ncpus=8 resources_used.vmem=173624kb resources_used.walltime=00:00:05
04/24/2018 01:16:10;0100;Server@node2;Job;12301.node2.supernodexp.hpc;dequeuing from workq, state 5
04/24/2018 01:16:10;0040;Server@node2;Svr;node2.supernodexp.hpc;Scheduler sent command 2
04/24/2018 01:16:10;0040;Server@node2;Svr;node2.supernodexp.hpc;Scheduler sent command 0
04/24/2018 01:16:10;0100;Server@node2;Req;;Type 21 request received from Scheduler@node2.supernodexp.hpc, sock=16
04/24/2018 01:16:10;0100;Server@node2;Req;;Type 81 request received from Scheduler@node2.supernodexp.hpc, sock=16
04/24/2018 01:16:10;0100;Server@node2;Req;;Type 71 request received from Scheduler@node2.supernodexp.hpc, sock=16
04/24/2018 01:16:10;0100;Server@node2;Req;;Type 58 request received from Scheduler@node2.supernodexp.hpc, sock=16
04/24/2018 01:16:10;0100;Server@node2;Req;;Type 20 request received from Scheduler@node2.supernodexp.hpc, sock=16
04/24/2018 01:16:10;0100;Server@node2;Req;;Type 51 request received from Scheduler@node2.supernodexp.hpc, sock=16
04/24/2018 01:16:14;0080;Server@node2;Job;12297.node2.supernodexp.hpc;Obit received momhop:1 serverhop:1 state:4 substate:42
04/24/2018 01:16:15;0010;Server@node2;Job;12297.node2.supernodexp.hpc;Exit_status=0 resources_used.cpupercent=0 resources_used.cput=00:00:00 resources_used.mem=9624kb resources_used.ncpus=8 resources_used.vmem=451124kb resources_used.walltime=00:00:25
04/24/2018 01:16:15;0100;Server@node2;Job;12297.node2.supernodexp.hpc;dequeuing from workq, state 5
04/24/2018 01:16:15;0040;Server@node2;Svr;node2.supernodexp.hpc;Scheduler sent command 2
04/24/2018 01:16:15;0040;Server@node2;Svr;node2.supernodexp.hpc;Scheduler sent command 0
04/24/2018 01:16:15;0100;Server@node2;Req;;Type 21 request received from Scheduler@node2.supernodexp.hpc, sock=16
04/24/2018 01:16:15;0100;Server@node2;Req;;Type 81 request received from Scheduler@node2.supernodexp.hpc, sock=16
04/24/2018 01:16:15;0100;Server@node2;Req;;Type 71 request received from Scheduler@node2.supernodexp.hpc, sock=16
04/24/2018 01:16:15;0100;Server@node2;Req;;Type 58 request received from Scheduler@node2.supernodexp.hpc, sock=16
04/24/2018 01:16:15;0100;Server@node2;Req;;Type 20 request received from Scheduler@node2.supernodexp.hpc, sock=16
04/24/2018 01:16:15;0100;Server@node2;Req;;Type 51 request received from Scheduler@node2.supernodexp.hpc, sock=16
04/24/2018 01:16:24;0080;Server@node2;Job;12303.node2.supernodexp.hpc;Obit received momhop:1 serverhop:1 state:4 substate:42
04/24/2018 01:16:24;0080;Server@node2;Job;12302.node2.supernodexp.hpc;Obit received momhop:1 serverhop:1 state:4 substate:42
04/24/2018 01:16:25;0010;Server@node2;Job;12303.node2.supernodexp.hpc;Exit_status=0 resources_used.cpupercent=0 resources_used.cput=00:00:00 resources_used.mem=9412kb resources_used.ncpus=4 resources_used.vmem=170164kb resources_used.walltime=00:00:17
04/24/2018 01:16:25;0100;Server@node2;Job;12303.node2.supernodexp.hpc;dequeuing from workq, state 5
04/24/2018 01:16:25;0040;Server@node2;Svr;node2.supernodexp.hpc;Scheduler sent command 2
04/24/2018 01:16:25;0040;Server@node2;Svr;node2.supernodexp.hpc;Scheduler sent command 0
04/24/2018 01:16:25;0100;Server@node2;Req;;Type 21 request received from Scheduler@node2.supernodexp.hpc, sock=16
04/24/2018 01:16:25;0100;Server@node2;Req;;Type 81 request received from Scheduler@node2.supernodexp.hpc, sock=16
04/24/2018 01:16:25;0100;Server@node2;Req;;Type 71 request received from Scheduler@node2.supernodexp.hpc, sock=16
04/24/2018 01:16:25;0100;Server@node2;Req;;Type 58 request received from Scheduler@node2.supernodexp.hpc, sock=16
04/24/2018 01:16:25;0100;Server@node2;Req;;Type 20 request received from Scheduler@node2.supernodexp.hpc, sock=16
04/24/2018 01:16:25;0100;Server@node2;Req;;Type 51 request received from Scheduler@node2.supernodexp.hpc, sock=16
04/24/2018 01:16:25;0010;Server@node2;Job;12302.node2.supernodexp.hpc;Exit_status=0 resources_used.cpupercent=0 resources_used.cput=00:00:00 resources_used.mem=9876kb resources_used.ncpus=4 resources_used.vmem=108796kb resources_used.walltime=00:00:17
04/24/2018 01:16:25;0100;Server@node2;Job;12302.node2.supernodexp.hpc;dequeuing from workq, state 5
04/24/2018 01:16:25;0040;Server@node2;Svr;node2.supernodexp.hpc;Scheduler sent command 2
04/24/2018 01:16:25;0040;Server@node2;Svr;node2.supernodexp.hpc;Scheduler sent command 0
04/24/2018 01:16:25;0100;Server@node2;Req;;Type 21 request received from Scheduler@node2.supernodexp.hpc, sock=16
04/24/2018 01:16:25;0100;Server@node2;Req;;Type 81 request received from Scheduler@node2.supernodexp.hpc, sock=16
04/24/2018 01:16:25;0100;Server@node2;Req;;Type 71 request received from Scheduler@node2.supernodexp.hpc, sock=16
04/24/2018 01:16:25;0100;Server@node2;Req;;Type 58 request received from Scheduler@node2.supernodexp.hpc, sock=16
04/24/2018 01:16:25;0100;Server@node2;Req;;Type 20 request received from Scheduler@node2.supernodexp.hpc, sock=16
04/24/2018 01:16:25;0100;Server@node2;Req;;Type 51 request received from Scheduler@node2.supernodexp.hpc, sock=16
04/24/2018 01:17:13;0080;Server@node2;Job;12291.node2.supernodexp.hpc;Obit received momhop:1 serverhop:1 state:4 substate:42
04/24/2018 01:17:14;0010;Server@node2;Job;12291.node2.supernodexp.hpc;Exit_status=0 resources_used.cpupercent=0 resources_used.cput=00:00:00 resources_used.mem=9100kb resources_used.ncpus=12 resources_used.vmem=170880kb resources_used.walltime=00:06:31
04/24/2018 01:17:14;0100;Server@node2;Job;12291.node2.supernodexp.hpc;dequeuing from workq, state 5
04/24/2018 01:17:14;0040;Server@node2;Svr;node2.supernodexp.hpc;Scheduler sent command 2
04/24/2018 01:17:14;0040;Server@node2;Svr;node2.supernodexp.hpc;Scheduler sent command 0
04/24/2018 01:17:14;0100;Server@node2;Req;;Type 21 request received from Scheduler@node2.supernodexp.hpc, sock=16
04/24/2018 01:17:14;0100;Server@node2;Req;;Type 81 request received from Scheduler@node2.supernodexp.hpc, sock=16
04/24/2018 01:17:14;0100;Server@node2;Req;;Type 71 request received from Scheduler@node2.supernodexp.hpc, sock=16
04/24/2018 01:17:14;0100;Server@node2;Req;;Type 58 request received from Scheduler@node2.supernodexp.hpc, sock=16
04/24/2018 01:17:14;0100;Server@node2;Req;;Type 20 request received from Scheduler@node2.supernodexp.hpc, sock=16
04/24/2018 01:17:14;0100;Server@node2;Req;;Type 51 request received from Scheduler@node2.supernodexp.hpc, sock=16
04/24/2018 01:17:37;0080;Server@node2;Job;12294.node2.supernodexp.hpc;Obit received momhop:1 serverhop:1 state:4 substate:42
04/24/2018 01:17:38;0010;Server@node2;Job;12294.node2.supernodexp.hpc;Exit_status=0 resources_used.cpupercent=0 resources_used.cput=00:00:00 resources_used.mem=9424kb resources_used.ncpus=2 resources_used.vmem=171316kb resources_used.walltime=00:01:47
04/24/2018 01:17:38;0100;Server@node2;Job;12294.node2.supernodexp.hpc;dequeuing from workq, state 5
04/24/2018 01:17:38;0040;Server@node2;Svr;node2.supernodexp.hpc;Scheduler sent command 2
04/24/2018 01:17:38;0040;Server@node2;Svr;node2.supernodexp.hpc;Scheduler sent command 0
04/24/2018 01:17:38;0100;Server@node2;Req;;Type 21 request received from Scheduler@node2.supernodexp.hpc, sock=16
04/24/2018 01:17:38;0100;Server@node2;Req;;Type 81 request received from Scheduler@node2.supernodexp.hpc, sock=16
04/24/2018 01:17:38;0100;Server@node2;Req;;Type 71 request received from Scheduler@node2.supernodexp.hpc, sock=16
04/24/2018 01:17:38;0100;Server@node2;Req;;Type 58 request received from Scheduler@node2.supernodexp.hpc, sock=16
04/24/2018 01:17:38;0100;Server@node2;Req;;Type 20 request received from Scheduler@node2.supernodexp.hpc, sock=16
04/24/2018 01:17:38;0100;Server@node2;Req;;Type 51 request received from Scheduler@node2.supernodexp.hpc, sock=16
04/24/2018 01:17:38;0100;Server@node2;Req;;Type 23 request received from Scheduler@node2.supernodexp.hpc, sock=16
04/24/2018 01:17:38;0008;Server@node2;Job;12304.node2.supernodexp.hpc;Job Run at request of Scheduler@node2.supernodexp.hpc on exec_vnode (node13:nmics=2:ncpus=2:mem=2097152kb)
04/24/2018 01:17:38;0001;Server@node2;Svr;Server@node2;Success (0) in req_runjob2, return value of svr_startjob is 0
04/24/2018 01:17:38;0100;Server@node2;Req;;Type 11 request received from Scheduler@node2.supernodexp.hpc, sock=16
04/24/2018 01:17:38;0008;Server@node2;Job;12305.node2.supernodexp.hpc;Job Modified at request of Scheduler@node2.supernodexp.hpc
04/24/2018 01:17:42;0080;Server@node2;Job;12304.node2.supernodexp.hpc;Obit received momhop:1 serverhop:1 state:4 substate:42
04/24/2018 01:17:43;0010;Server@node2;Job;12304.node2.supernodexp.hpc;Exit_status=0 resources_used.cpupercent=0 resources_used.cput=00:00:00 resources_used.mem=0kb resources_used.ncpus=2 resources_used.vmem=0kb resources_used.walltime=00:00:04
04/24/2018 01:17:43;0100;Server@node2;Job;12304.node2.supernodexp.hpc;dequeuing from workq, state 5
04/24/2018 01:17:43;0040;Server@node2;Svr;node2.supernodexp.hpc;Scheduler sent command 2
04/24/2018 01:17:43;0040;Server@node2;Svr;node2.supernodexp.hpc;Scheduler sent command 0
04/24/2018 01:17:43;0100;Server@node2;Req;;Type 21 request received from Scheduler@node2.supernodexp.hpc, sock=16
04/24/2018 01:17:43;0100;Server@node2;Req;;Type 81 request received from Scheduler@node2.supernodexp.hpc, sock=16
04/24/2018 01:17:43;0100;Server@node2;Req;;Type 71 request received from Scheduler@node2.supernodexp.hpc, sock=16
04/24/2018 01:17:43;0100;Server@node2;Req;;Type 58 request received from Scheduler@node2.supernodexp.hpc, sock=16
04/24/2018 01:17:43;0100;Server@node2;Req;;Type 20 request received from Scheduler@node2.supernodexp.hpc, sock=16
04/24/2018 01:17:43;0100;Server@node2;Req;;Type 51 request received from Scheduler@node2.supernodexp.hpc, sock=16
04/24/2018 01:17:43;0100;Server@node2;Req;;Type 23 request received from Scheduler@node2.supernodexp.hpc, sock=16
04/24/2018 01:17:43;0008;Server@node2;Job;12305.node2.supernodexp.hpc;Job Run at request of Scheduler@node2.supernodexp.hpc on exec_vnode (node13:nmics=2:ncpus=2:mem=41943040kb)
04/24/2018 01:17:43;0001;Server@node2;Svr;Server@node2;Success (0) in req_runjob2, return value of svr_startjob is 0
04/24/2018 01:17:43;0100;Server@node2;Req;;Type 23 request received from Scheduler@node2.supernodexp.hpc, sock=16
04/24/2018 01:17:43;0008;Server@node2;Job;12306.node2.supernodexp.hpc;Job Run at request of Scheduler@node2.supernodexp.hpc on exec_vnode (node3:ncpus=12:mem=5242880kb)
04/24/2018 01:17:43;0001;Server@node2;Svr;Server@node2;Success (0) in req_runjob2, return value of svr_startjob is 0
04/24/2018 01:17:43;0100;Server@node2;Req;;Type 11 request received from Scheduler@node2.supernodexp.hpc, sock=16
04/24/2018 01:17:43;0008;Server@node2;Job;12307.node2.supernodexp.hpc;Job Modified at request of Scheduler@node2.supernodexp.hpc
04/24/2018 01:19:33;0080;Server@node2;Job;12305.node2.supernodexp.hpc;Obit received momhop:1 serverhop:1 state:4 substate:42
04/24/2018 01:19:34;0010;Server@node2;Job;12305.node2.supernodexp.hpc;Exit_status=0 resources_used.cpupercent=0 resources_used.cput=00:00:00 resources_used.mem=9388kb resources_used.ncpus=2 resources_used.vmem=106424kb resources_used.walltime=00:01:51
04/24/2018 01:19:34;0100;Server@node2;Job;12305.node2.supernodexp.hpc;dequeuing from workq, state 5
04/24/2018 01:19:34;0040;Server@node2;Svr;node2.supernodexp.hpc;Scheduler sent command 2
04/24/2018 01:19:34;0040;Server@node2;Svr;node2.supernodexp.hpc;Scheduler sent command 0
04/24/2018 01:19:34;0100;Server@node2;Req;;Type 21 request received from Scheduler@node2.supernodexp.hpc, sock=16
04/24/2018 01:19:34;0100;Server@node2;Req;;Type 81 request received from Scheduler@node2.supernodexp.hpc, sock=16
04/24/2018 01:19:34;0100;Server@node2;Req;;Type 71 request received from Scheduler@node2.supernodexp.hpc, sock=16
04/24/2018 01:19:34;0100;Server@node2;Req;;Type 58 request received from Scheduler@node2.supernodexp.hpc, sock=16
04/24/2018 01:19:34;0100;Server@node2;Req;;Type 20 request received from Scheduler@node2.supernodexp.hpc, sock=16
04/24/2018 01:19:34;0100;Server@node2;Req;;Type 51 request received from Scheduler@node2.supernodexp.hpc, sock=16
04/24/2018 01:19:34;0100;Server@node2;Req;;Type 23 request received from Scheduler@node2.supernodexp.hpc, sock=16
04/24/2018 01:19:34;0008;Server@node2;Job;12307.node2.supernodexp.hpc;Job Run at request of Scheduler@node2.supernodexp.hpc on exec_vnode (node13:nmics=2:ncpus=12:mem=41943040kb)
04/24/2018 01:19:34;0001;Server@node2;Svr;Server@node2;Success (0) in req_runjob2, return value of svr_startjob is 0
04/24/2018 01:19:34;0100;Server@node2;Req;;Type 23 request received from Scheduler@node2.supernodexp.hpc, sock=16
04/24/2018 01:19:34;0008;Server@node2;Job;12308.node2.supernodexp.hpc;Job Run at request of Scheduler@node2.supernodexp.hpc on exec_vnode (node14:ncpus=12:mem=20971520kb)
04/24/2018 01:19:34;0001;Server@node2;Svr;Server@node2;Success (0) in req_runjob2, return value of svr_startjob is 0
04/24/2018 01:19:34;0100;Server@node2;Req;;Type 11 request received from Scheduler@node2.supernodexp.hpc, sock=16
04/24/2018 01:19:34;0008;Server@node2;Job;12309.node2.supernodexp.hpc;Job Modified at request of Scheduler@node2.supernodexp.hpc
04/24/2018 01:21:27;0080;Server@node2;Job;12292.node2.supernodexp.hpc;Obit received momhop:1 serverhop:1 state:4 substate:42
04/24/2018 01:21:28;0010;Server@node2;Job;12292.node2.supernodexp.hpc;Exit_status=0 resources_used.cpupercent=0 resources_used.cput=00:00:00 resources_used.mem=9400kb resources_used.ncpus=24 resources_used.vmem=104628kb resources_used.walltime=00:05:37
04/24/2018 01:21:28;0100;Server@node2;Job;12292.node2.supernodexp.hpc;dequeuing from workq, state 5
04/24/2018 01:21:28;0040;Server@node2;Svr;node2.supernodexp.hpc;Scheduler sent command 2
04/24/2018 01:21:28;0040;Server@node2;Svr;node2.supernodexp.hpc;Scheduler sent command 0
04/24/2018 01:21:28;0100;Server@node2;Req;;Type 21 request received from Scheduler@node2.supernodexp.hpc, sock=16
04/24/2018 01:21:28;0100;Server@node2;Req;;Type 81 request received from Scheduler@node2.supernodexp.hpc, sock=16
04/24/2018 01:21:28;0100;Server@node2;Req;;Type 71 request received from Scheduler@node2.supernodexp.hpc, sock=16
04/24/2018 01:21:28;0100;Server@node2;Req;;Type 58 request received from Scheduler@node2.supernodexp.hpc, sock=16
04/24/2018 01:21:28;0100;Server@node2;Req;;Type 20 request received from Scheduler@node2.supernodexp.hpc, sock=16
04/24/2018 01:21:28;0100;Server@node2;Req;;Type 51 request received from Scheduler@node2.supernodexp.hpc, sock=16
04/24/2018 01:21:28;0100;Server@node2;Req;;Type 23 request received from Scheduler@node2.supernodexp.hpc, sock=16
04/24/2018 01:21:28;0008;Server@node2;Job;12309.node2.supernodexp.hpc;Job Run at request of Scheduler@node2.supernodexp.hpc on exec_vnode (node13:ncpus=8:mem=20971520kb)
04/24/2018 01:21:28;0001;Server@node2;Svr;Server@node2;Success (0) in req_runjob2, return value of svr_startjob is 0
04/24/2018 01:21:28;0100;Server@node2;Req;;Type 23 request received from Scheduler@node2.supernodexp.hpc, sock=16
04/24/2018 01:21:28;0008;Server@node2;Job;12310.node2.supernodexp.hpc;Job Run at request of Scheduler@node2.supernodexp.hpc on exec_vnode (node13:ncpus=8:mem=3145728kb)
04/24/2018 01:21:28;0001;Server@node2;Svr;Server@node2;Success (0) in req_runjob2, return value of svr_startjob is 0
04/24/2018 01:21:28;0100;Server@node2;Req;;Type 23 request received from Scheduler@node2.supernodexp.hpc, sock=16
04/24/2018 01:21:28;0008;Server@node2;Job;12311.node2.supernodexp.hpc;Job Run at request of Scheduler@node2.supernodexp.hpc on exec_vnode (node13:ncpus=8:mem=5242880kb)
04/24/2018 01:21:28;0001;Server@node2;Svr;Server@node2;Success (0) in req_runjob2, return value of svr_startjob is 0
04/24/2018 01:21:28;0100;Server@node2;Req;;Type 11 request received from Scheduler@node2.supernodexp.hpc, sock=16
04/24/2018 01:21:28;0008;Server@node2;Job;12312.node2.supernodexp.hpc;Job Modified at request of Scheduler@node2.supernodexp.hpc
04/24/2018 01:21:49;0080;Server@node2;Job;12311.node2.supernodexp.hpc;Obit received momhop:1 serverhop:1 state:4 substate:42
04/24/2018 01:21:50;0010;Server@node2;Job;12311.node2.supernodexp.hpc;Exit_status=0 resources_used.cpupercent=0 resources_used.cput=00:00:00 resources_used.mem=9636kb resources_used.ncpus=8 resources_used.vmem=172216kb resources_used.walltime=00:00:20
04/24/2018 01:21:50;0100;Server@node2;Job;12311.node2.supernodexp.hpc;dequeuing from workq, state 5
04/24/2018 01:21:50;0040;Server@node2;Svr;node2.supernodexp.hpc;Scheduler sent command 2
04/24/2018 01:21:50;0040;Server@node2;Svr;node2.supernodexp.hpc;Scheduler sent command 0
04/24/2018 01:21:50;0100;Server@node2;Req;;Type 21 request received from Scheduler@node2.supernodexp.hpc, sock=16
04/24/2018 01:21:50;0100;Server@node2;Req;;Type 81 request received from Scheduler@node2.supernodexp.hpc, sock=16
04/24/2018 01:21:50;0100;Server@node2;Req;;Type 71 request received from Scheduler@node2.supernodexp.hpc, sock=16
04/24/2018 01:21:50;0100;Server@node2;Req;;Type 58 request received from Scheduler@node2.supernodexp.hpc, sock=16
04/24/2018 01:21:50;0100;Server@node2;Req;;Type 20 request received from Scheduler@node2.supernodexp.hpc, sock=16
04/24/2018 01:21:50;0100;Server@node2;Req;;Type 51 request received from Scheduler@node2.supernodexp.hpc, sock=16
04/24/2018 01:21:50;0100;Server@node2;Req;;Type 11 request received from Scheduler@node2.supernodexp.hpc, sock=16
04/24/2018 01:21:50;0008;Server@node2;Job;12312.node2.supernodexp.hpc;Job Modified at request of Scheduler@node2.supernodexp.hpc
04/24/2018 01:21:50;0080;Server@node2;Job;12298.node2.supernodexp.hpc;Obit received momhop:1 serverhop:1 state:4 substate:42
04/24/2018 01:21:51;0010;Server@node2;Job;12298.node2.supernodexp.hpc;Exit_status=0 resources_used.cpupercent=0 resources_used.cput=00:00:00 resources_used.mem=9416kb resources_used.ncpus=12 resources_used.vmem=237496kb resources_used.walltime=00:06:00
04/24/2018 01:21:51;0100;Server@node2;Job;12298.node2.supernodexp.hpc;dequeuing from workq, state 5
04/24/2018 01:21:51;0040;Server@node2;Svr;node2.supernodexp.hpc;Scheduler sent command 2
04/24/2018 01:21:51;0040;Server@node2;Svr;node2.supernodexp.hpc;Scheduler sent command 0
04/24/2018 01:21:51;0100;Server@node2;Req;;Type 21 request received from Scheduler@node2.supernodexp.hpc, sock=16
04/24/2018 01:21:51;0100;Server@node2;Req;;Type 81 request received from Scheduler@node2.supernodexp.hpc, sock=16
04/24/2018 01:21:51;0100;Server@node2;Req;;Type 71 request received from Scheduler@node2.supernodexp.hpc, sock=16
04/24/2018 01:21:51;0100;Server@node2;Req;;Type 58 request received from Scheduler@node2.supernodexp.hpc, sock=16
04/24/2018 01:21:51;0100;Server@node2;Req;;Type 20 request received from Scheduler@node2.supernodexp.hpc, sock=16
04/24/2018 01:21:51;0100;Server@node2;Req;;Type 51 request received from Scheduler@node2.supernodexp.hpc, sock=16
04/24/2018 01:21:51;0100;Server@node2;Req;;Type 11 request received from Scheduler@node2.supernodexp.hpc, sock=16
04/24/2018 01:21:51;0008;Server@node2;Job;12312.node2.supernodexp.hpc;Job Modified at request of Scheduler@node2.supernodexp.hpc
04/24/2018 01:21:56;0080;Server@node2;Job;12309.node2.supernodexp.hpc;Obit received momhop:1 serverhop:1 state:4 substate:42
04/24/2018 01:21:57;0010;Server@node2;Job;12309.node2.supernodexp.hpc;Exit_status=0 resources_used.cpupercent=0 resources_used.cput=00:00:00 resources_used.mem=9412kb resources_used.ncpus=8 resources_used.vmem=106680kb resources_used.walltime=00:00:28
04/24/2018 01:21:57;0100;Server@node2;Job;12309.node2.supernodexp.hpc;dequeuing from workq, state 5
04/24/2018 01:21:57;0040;Server@node2;Svr;node2.supernodexp.hpc;Scheduler sent command 2
04/24/2018 01:21:57;0040;Server@node2;Svr;node2.supernodexp.hpc;Scheduler sent command 0
04/24/2018 01:21:57;0100;Server@node2;Req;;Type 21 request received from Scheduler@node2.supernodexp.hpc, sock=16
04/24/2018 01:21:57;0100;Server@node2;Req;;Type 81 request received from Scheduler@node2.supernodexp.hpc, sock=16
04/24/2018 01:21:57;0100;Server@node2;Req;;Type 71 request received from Scheduler@node2.supernodexp.hpc, sock=16
04/24/2018 01:21:57;0100;Server@node2;Req;;Type 58 request received from Scheduler@node2.supernodexp.hpc, sock=16
04/24/2018 01:21:57;0100;Server@node2;Req;;Type 20 request received from Scheduler@node2.supernodexp.hpc, sock=16
04/24/2018 01:21:57;0100;Server@node2;Req;;Type 51 request received from Scheduler@node2.supernodexp.hpc, sock=16
04/24/2018 01:21:57;0100;Server@node2;Req;;Type 23 request received from Scheduler@node2.supernodexp.hpc, sock=16
04/24/2018 01:21:57;0008;Server@node2;Job;12312.node2.supernodexp.hpc;Job Run at request of Scheduler@node2.supernodexp.hpc on exec_vnode (node13:ncpus=24:mem=5242880kb)
04/24/2018 01:21:57;0001;Server@node2;Svr;Server@node2;Success (0) in req_runjob2, return value of svr_startjob is 0
04/24/2018 01:21:57;0100;Server@node2;Req;;Type 11 request received from Scheduler@node2.supernodexp.hpc, sock=16
04/24/2018 01:21:57;0008;Server@node2;Job;12313.node2.supernodexp.hpc;Job Modified at request of Scheduler@node2.supernodexp.hpc
04/24/2018 01:25:08;0080;Server@node2;Job;12306.node2.supernodexp.hpc;Obit received momhop:1 serverhop:1 state:4 substate:42
04/24/2018 01:25:09;0010;Server@node2;Job;12306.node2.supernodexp.hpc;Exit_status=0 resources_used.cpupercent=0 resources_used.cput=00:00:00 resources_used.mem=9340kb resources_used.ncpus=12 resources_used.vmem=106752kb resources_used.walltime=00:07:25
04/24/2018 01:25:09;0100;Server@node2;Job;12306.node2.supernodexp.hpc;dequeuing from workq, state 5
04/24/2018 01:25:09;0040;Server@node2;Svr;node2.supernodexp.hpc;Scheduler sent command 2
04/24/2018 01:25:09;0040;Server@node2;Svr;node2.supernodexp.hpc;Scheduler sent command 0
04/24/2018 01:25:09;0100;Server@node2;Req;;Type 21 request received from Scheduler@node2.supernodexp.hpc, sock=16
04/24/2018 01:25:09;0100;Server@node2;Req;;Type 81 request received from Scheduler@node2.supernodexp.hpc, sock=16
04/24/2018 01:25:09;0100;Server@node2;Req;;Type 71 request received from Scheduler@node2.supernodexp.hpc, sock=16
04/24/2018 01:25:09;0100;Server@node2;Req;;Type 58 request received from Scheduler@node2.supernodexp.hpc, sock=16
04/24/2018 01:25:09;0100;Server@node2;Req;;Type 20 request received from Scheduler@node2.supernodexp.hpc, sock=16
04/24/2018 01:25:09;0100;Server@node2;Req;;Type 51 request received from Scheduler@node2.supernodexp.hpc, sock=16
04/24/2018 01:25:09;0100;Server@node2;Req;;Type 23 request received from Scheduler@node2.supernodexp.hpc, sock=16
04/24/2018 01:25:09;0008;Server@node2;Job;12313.node2.supernodexp.hpc;Job Run at request of Scheduler@node2.supernodexp.hpc on exec_vnode (node3:ncpus=8:mem=5242880kb)
04/24/2018 01:25:09;0001;Server@node2;Svr;Server@node2;Success (0) in req_runjob2, return value of svr_startjob is 0
04/24/2018 01:25:09;0100;Server@node2;Req;;Type 11 request received from Scheduler@node2.supernodexp.hpc, sock=16
04/24/2018 01:25:09;0008;Server@node2;Job;12314.node2.supernodexp.hpc;Job Modified at request of Scheduler@node2.supernodexp.hpc
04/24/2018 01:25:35;0080;Server@node2;Job;12313.node2.supernodexp.hpc;Obit received momhop:1 serverhop:1 state:4 substate:42
04/24/2018 01:25:35;0010;Server@node2;Job;12313.node2.supernodexp.hpc;Exit_status=0 resources_used.cpupercent=0 resources_used.cput=00:00:00 resources_used.mem=9092kb resources_used.ncpus=8 resources_used.vmem=103036kb resources_used.walltime=00:00:25
04/24/2018 01:25:35;0100;Server@node2;Job;12313.node2.supernodexp.hpc;dequeuing from workq, state 5
04/24/2018 01:25:35;0040;Server@node2;Svr;node2.supernodexp.hpc;Scheduler sent command 2
04/24/2018 01:25:35;0040;Server@node2;Svr;node2.supernodexp.hpc;Scheduler sent command 0
04/24/2018 01:25:35;0100;Server@node2;Req;;Type 21 request received from Scheduler@node2.supernodexp.hpc, sock=16
04/24/2018 01:25:35;0100;Server@node2;Req;;Type 81 request received from Scheduler@node2.supernodexp.hpc, sock=16
04/24/2018 01:25:35;0100;Server@node2;Req;;Type 71 request received from Scheduler@node2.supernodexp.hpc, sock=16
04/24/2018 01:25:35;0100;Server@node2;Req;;Type 58 request received from Scheduler@node2.supernodexp.hpc, sock=16
04/24/2018 01:25:35;0100;Server@node2;Req;;Type 20 request received from Scheduler@node2.supernodexp.hpc, sock=16
04/24/2018 01:25:35;0100;Server@node2;Req;;Type 51 request received from Scheduler@node2.supernodexp.hpc, sock=16
04/24/2018 01:25:37;0080;Server@node2;Job;12269.node2.supernodexp.hpc;Obit received momhop:1 serverhop:1 state:4 substate:42
04/24/2018 01:25:38;0010;Server@node2;Job;12269.node2.supernodexp.hpc;Exit_status=0 resources_used.cpupercent=0 resources_used.cput=00:00:00 resources_used.mem=9452kb resources_used.ncpus=12 resources_used.vmem=105344kb resources_used.walltime=00:20:37
04/24/2018 01:25:38;0100;Server@node2;Job;12269.node2.supernodexp.hpc;dequeuing from workq, state 5
04/24/2018 01:25:38;0040;Server@node2;Svr;node2.supernodexp.hpc;Scheduler sent command 2
04/24/2018 01:25:38;0040;Server@node2;Svr;node2.supernodexp.hpc;Scheduler sent command 0
04/24/2018 01:25:38;0100;Server@node2;Req;;Type 21 request received from Scheduler@node2.supernodexp.hpc, sock=16
04/24/2018 01:25:38;0100;Server@node2;Req;;Type 81 request received from Scheduler@node2.supernodexp.hpc, sock=16
04/24/2018 01:25:38;0100;Server@node2;Req;;Type 71 request received from Scheduler@node2.supernodexp.hpc, sock=16
04/24/2018 01:25:38;0100;Server@node2;Req;;Type 58 request received from Scheduler@node2.supernodexp.hpc, sock=16
04/24/2018 01:25:38;0100;Server@node2;Req;;Type 20 request received from Scheduler@node2.supernodexp.hpc, sock=16
04/24/2018 01:25:38;0100;Server@node2;Req;;Type 51 request received from Scheduler@node2.supernodexp.hpc, sock=16
04/24/2018 01:25:48;0080;Server@node2;Job;12288.node2.supernodexp.hpc;Obit received momhop:1 serverhop:1 state:4 substate:42
04/24/2018 01:25:49;0010;Server@node2;Job;12288.node2.supernodexp.hpc;Exit_status=0 resources_used.cpupercent=0 resources_used.cput=00:00:00 resources_used.mem=9104kb resources_used.ncpus=12 resources_used.vmem=170624kb resources_used.walltime=00:15:06
04/24/2018 01:25:49;0100;Server@node2;Job;12288.node2.supernodexp.hpc;dequeuing from workq, state 5
04/24/2018 01:25:49;0040;Server@node2;Svr;node2.supernodexp.hpc;Scheduler sent command 2
04/24/2018 01:25:49;0040;Server@node2;Svr;node2.supernodexp.hpc;Scheduler sent command 0
04/24/2018 01:25:49;0100;Server@node2;Req;;Type 21 request received from Scheduler@node2.supernodexp.hpc, sock=16
04/24/2018 01:25:49;0100;Server@node2;Req;;Type 81 request received from Scheduler@node2.supernodexp.hpc, sock=16
04/24/2018 01:25:49;0100;Server@node2;Req;;Type 71 request received from Scheduler@node2.supernodexp.hpc, sock=16
04/24/2018 01:25:49;0100;Server@node2;Req;;Type 58 request received from Scheduler@node2.supernodexp.hpc, sock=16
04/24/2018 01:25:49;0100;Server@node2;Req;;Type 20 request received from Scheduler@node2.supernodexp.hpc, sock=16
04/24/2018 01:25:49;0100;Server@node2;Req;;Type 51 request received from Scheduler@node2.supernodexp.hpc, sock=16
04/24/2018 01:25:49;0100;Server@node2;Req;;Type 23 request received from Scheduler@node2.supernodexp.hpc, sock=16
04/24/2018 01:25:49;0008;Server@node2;Job;12314.node2.supernodexp.hpc;Job Run at request of Scheduler@node2.supernodexp.hpc on exec_vnode (node3:nmics=2:ncpus=2:mem=41943040kb)
04/24/2018 01:25:49;0001;Server@node2;Svr;Server@node2;Success (0) in req_runjob2, return value of svr_startjob is 0
04/24/2018 01:25:49;0100;Server@node2;Req;;Type 23 request received from Scheduler@node2.supernodexp.hpc, sock=16
04/24/2018 01:25:49;0008;Server@node2;Job;12315.node2.supernodexp.hpc;Job Run at request of Scheduler@node2.supernodexp.hpc on exec_vnode (node3:ncpus=8:mem=15728640kb)
04/24/2018 01:25:49;0001;Server@node2;Svr;Server@node2;Success (0) in req_runjob2, return value of svr_startjob is 0
04/24/2018 01:25:49;0100;Server@node2;Req;;Type 11 request received from Scheduler@node2.supernodexp.hpc, sock=16
04/24/2018 01:25:49;0008;Server@node2;Job;12316.node2.supernodexp.hpc;Job Modified at request of Scheduler@node2.supernodexp.hpc
04/24/2018 01:25:51;0080;Server@node2;Job;12308.node2.supernodexp.hpc;Obit received momhop:1 serverhop:1 state:4 substate:42
04/24/2018 01:25:53;0010;Server@node2;Job;12308.node2.supernodexp.hpc;Exit_status=0 resources_used.cpupercent=0 resources_used.cput=00:00:00 resources_used.mem=9416kb resources_used.ncpus=12 resources_used.vmem=171960kb resources_used.walltime=00:06:17
04/24/2018 01:25:53;0100;Server@node2;Job;12308.node2.supernodexp.hpc;dequeuing from workq, state 5
04/24/2018 01:25:53;0040;Server@node2;Svr;node2.supernodexp.hpc;Scheduler sent command 2
04/24/2018 01:25:53;0040;Server@node2;Svr;node2.supernodexp.hpc;Scheduler sent command 0
04/24/2018 01:25:53;0100;Server@node2;Req;;Type 21 request received from Scheduler@node2.supernodexp.hpc, sock=16
04/24/2018 01:25:53;0100;Server@node2;Req;;Type 81 request received from Scheduler@node2.supernodexp.hpc, sock=16
04/24/2018 01:25:53;0100;Server@node2;Req;;Type 71 request received from Scheduler@node2.supernodexp.hpc, sock=16
04/24/2018 01:25:53;0100;Server@node2;Req;;Type 58 request received from Scheduler@node2.supernodexp.hpc, sock=16
04/24/2018 01:25:53;0100;Server@node2;Req;;Type 20 request received from Scheduler@node2.supernodexp.hpc, sock=16
04/24/2018 01:25:53;0100;Server@node2;Req;;Type 51 request received from Scheduler@node2.supernodexp.hpc, sock=16
04/24/2018 01:25:53;0080;Server@node2;Job;12310.node2.supernodexp.hpc;Obit received momhop:1 serverhop:1 state:4 substate:42
04/24/2018 01:26:06;0010;Server@node2;Job;12310.node2.supernodexp.hpc;Exit_status=0 resources_used.cpupercent=0 resources_used.cput=00:00:00 resources_used.mem=9428kb resources_used.ncpus=8 resources_used.vmem=173624kb resources_used.walltime=00:04:25
04/24/2018 01:26:06;0100;Server@node2;Job;12310.node2.supernodexp.hpc;dequeuing from workq, state 5
04/24/2018 01:26:06;0040;Server@node2;Svr;node2.supernodexp.hpc;Scheduler sent command 2
04/24/2018 01:26:06;0040;Server@node2;Svr;node2.supernodexp.hpc;Scheduler sent command 0
04/24/2018 01:26:06;0100;Server@node2;Req;;Type 21 request received from Scheduler@node2.supernodexp.hpc, sock=16
04/24/2018 01:26:06;0100;Server@node2;Req;;Type 81 request received from Scheduler@node2.supernodexp.hpc, sock=16
04/24/2018 01:26:06;0100;Server@node2;Req;;Type 71 request received from Scheduler@node2.supernodexp.hpc, sock=16
04/24/2018 01:26:06;0100;Server@node2;Req;;Type 58 request received from Scheduler@node2.supernodexp.hpc, sock=16
04/24/2018 01:26:06;0100;Server@node2;Req;;Type 20 request received from Scheduler@node2.supernodexp.hpc, sock=16
04/24/2018 01:26:06;0100;Server@node2;Req;;Type 51 request received from Scheduler@node2.supernodexp.hpc, sock=16
04/24/2018 01:26:07;0080;Server@node2;Job;12280.node2.supernodexp.hpc;Obit received momhop:1 serverhop:1 state:4 substate:42
04/24/2018 01:26:07;0010;Server@node2;Job;12280.node2.supernodexp.hpc;Exit_status=2 resources_used.cpupercent=0 resources_used.cput=00:00:00 resources_used.mem=10840kb resources_used.ncpus=32 resources_used.vmem=945716kb resources_used.walltime=00:20:25
04/24/2018 01:26:07;0100;Server@node2;Job;12280.node2.supernodexp.hpc;dequeuing from workq, state 5
04/24/2018 01:26:07;0040;Server@node2;Svr;node2.supernodexp.hpc;Scheduler sent command 2
04/24/2018 01:26:07;0040;Server@node2;Svr;node2.supernodexp.hpc;Scheduler sent command 0
04/24/2018 01:26:07;0100;Server@node2;Req;;Type 21 request received from Scheduler@node2.supernodexp.hpc, sock=16
04/24/2018 01:26:07;0100;Server@node2;Req;;Type 81 request received from Scheduler@node2.supernodexp.hpc, sock=16
04/24/2018 01:26:07;0100;Server@node2;Req;;Type 71 request received from Scheduler@node2.supernodexp.hpc, sock=16
04/24/2018 01:26:07;0100;Server@node2;Req;;Type 58 request received from Scheduler@node2.supernodexp.hpc, sock=16
04/24/2018 01:26:07;0100;Server@node2;Req;;Type 20 request received from Scheduler@node2.supernodexp.hpc, sock=16
04/24/2018 01:26:07;0100;Server@node2;Req;;Type 51 request received from Scheduler@node2.supernodexp.hpc, sock=16
04/24/2018 01:26:08;0100;Server@node2;Req;;Type 23 request received from Scheduler@node2.supernodexp.hpc, sock=16
04/24/2018 01:26:08;0008;Server@node2;Job;12316.node2.supernodexp.hpc;Job Run at request of Scheduler@node2.supernodexp.hpc on exec_vnode (node14:nmics=2:ncpus=2:mem=41943040kb)
04/24/2018 01:26:08;0001;Server@node2;Svr;Server@node2;Success (0) in req_runjob2, return value of svr_startjob is 0
04/24/2018 01:26:08;0100;Server@node2;Req;;Type 23 request received from Scheduler@node2.supernodexp.hpc, sock=16
04/24/2018 01:26:08;0008;Server@node2;Job;12317.node2.supernodexp.hpc;Job Run at request of Scheduler@node2.supernodexp.hpc on exec_vnode (node3:ncpus=24:mem=5242880kb)
04/24/2018 01:26:08;0001;Server@node2;Svr;Server@node2;Success (0) in req_runjob2, return value of svr_startjob is 0
04/24/2018 01:26:08;0100;Server@node2;Req;;Type 23 request received from Scheduler@node2.supernodexp.hpc, sock=16
04/24/2018 01:26:08;0008;Server@node2;Job;12318.node2.supernodexp.hpc;Job Run at request of Scheduler@node2.supernodexp.hpc on exec_vnode (node14:ncpus=12:mem=20971520kb)
04/24/2018 01:26:08;0001;Server@node2;Svr;Server@node2;Success (0) in req_runjob2, return value of svr_startjob is 0
04/24/2018 01:26:08;0100;Server@node2;Req;;Type 23 request received from Scheduler@node2.supernodexp.hpc, sock=16
04/24/2018 01:26:08;0008;Server@node2;Job;12319.node2.supernodexp.hpc;Job Run at request of Scheduler@node2.supernodexp.hpc on exec_vnode (node14:ncpus=12:mem=20971520kb)
04/24/2018 01:26:08;0001;Server@node2;Svr;Server@node2;Success (0) in req_runjob2, return value of svr_startjob is 0
04/24/2018 01:26:08;0100;Server@node2;Req;;Type 11 request received from Scheduler@node2.supernodexp.hpc, sock=16
04/24/2018 01:26:08;0008;Server@node2;Job;12320.node2.supernodexp.hpc;Job Modified at request of Scheduler@node2.supernodexp.hpc
04/24/2018 01:26:17;0080;Server@node2;Job;12317.node2.supernodexp.hpc;Obit received momhop:1 serverhop:1 state:4 substate:42
04/24/2018 01:26:18;0010;Server@node2;Job;12317.node2.supernodexp.hpc;Exit_status=0 resources_used.cpupercent=0 resources_used.cput=00:00:00 resources_used.mem=0kb resources_used.ncpus=24 resources_used.vmem=0kb resources_used.walltime=00:00:10
04/24/2018 01:26:18;0100;Server@node2;Job;12317.node2.supernodexp.hpc;dequeuing from workq, state 5
04/24/2018 01:26:18;0040;Server@node2;Svr;node2.supernodexp.hpc;Scheduler sent command 2
04/24/2018 01:26:18;0040;Server@node2;Svr;node2.supernodexp.hpc;Scheduler sent command 0
04/24/2018 01:26:18;0100;Server@node2;Req;;Type 21 request received from Scheduler@node2.supernodexp.hpc, sock=16
04/24/2018 01:26:18;0100;Server@node2;Req;;Type 81 request received from Scheduler@node2.supernodexp.hpc, sock=16
04/24/2018 01:26:18;0100;Server@node2;Req;;Type 71 request received from Scheduler@node2.supernodexp.hpc, sock=16
04/24/2018 01:26:18;0100;Server@node2;Req;;Type 58 request received from Scheduler@node2.supernodexp.hpc, sock=16
04/24/2018 01:26:18;0100;Server@node2;Req;;Type 20 request received from Scheduler@node2.supernodexp.hpc, sock=16
04/24/2018 01:26:18;0100;Server@node2;Req;;Type 51 request received from Scheduler@node2.supernodexp.hpc, sock=16
04/24/2018 01:26:51;0080;Server@node2;Job;12312.node2.supernodexp.hpc;Obit received momhop:1 serverhop:1 state:4 substate:42
04/24/2018 01:26:51;0010;Server@node2;Job;12312.node2.supernodexp.hpc;Exit_status=0 resources_used.cpupercent=0 resources_used.cput=00:00:00 resources_used.mem=9624kb resources_used.ncpus=24 resources_used.vmem=658824kb resources_used.walltime=00:04:53
04/24/2018 01:26:51;0100;Server@node2;Job;12312.node2.supernodexp.hpc;dequeuing from workq, state 5
04/24/2018 01:26:51;0040;Server@node2;Svr;node2.supernodexp.hpc;Scheduler sent command 2
04/24/2018 01:26:51;0040;Server@node2;Svr;node2.supernodexp.hpc;Scheduler sent command 0
04/24/2018 01:26:51;0100;Server@node2;Req;;Type 21 request received from Scheduler@node2.supernodexp.hpc, sock=16
04/24/2018 01:26:51;0100;Server@node2;Req;;Type 81 request received from Scheduler@node2.supernodexp.hpc, sock=16
04/24/2018 01:26:51;0100;Server@node2;Req;;Type 71 request received from Scheduler@node2.supernodexp.hpc, sock=16
04/24/2018 01:26:51;0100;Server@node2;Req;;Type 58 request received from Scheduler@node2.supernodexp.hpc, sock=16
04/24/2018 01:26:52;0100;Server@node2;Req;;Type 20 request received from Scheduler@node2.supernodexp.hpc, sock=16
04/24/2018 01:26:52;0100;Server@node2;Req;;Type 51 request received from Scheduler@node2.supernodexp.hpc, sock=16
04/24/2018 01:27:44;0080;Server@node2;Job;12314.node2.supernodexp.hpc;Obit received momhop:1 serverhop:1 state:4 substate:42
04/24/2018 01:27:45;0010;Server@node2;Job;12314.node2.supernodexp.hpc;Exit_status=0 resources_used.cpupercent=0 resources_used.cput=00:00:00 resources_used.mem=9092kb resources_used.ncpus=2 resources_used.vmem=105344kb resources_used.walltime=00:01:55
04/24/2018 01:27:45;0100;Server@node2;Job;12314.node2.supernodexp.hpc;dequeuing from workq, state 5
04/24/2018 01:27:45;0040;Server@node2;Svr;node2.supernodexp.hpc;Scheduler sent command 2
04/24/2018 01:27:45;0040;Server@node2;Svr;node2.supernodexp.hpc;Scheduler sent command 0
04/24/2018 01:27:45;0100;Server@node2;Req;;Type 21 request received from Scheduler@node2.supernodexp.hpc, sock=16
04/24/2018 01:27:45;0100;Server@node2;Req;;Type 81 request received from Scheduler@node2.supernodexp.hpc, sock=16
04/24/2018 01:27:45;0100;Server@node2;Req;;Type 71 request received from Scheduler@node2.supernodexp.hpc, sock=16
04/24/2018 01:27:45;0100;Server@node2;Req;;Type 58 request received from Scheduler@node2.supernodexp.hpc, sock=16
04/24/2018 01:27:45;0100;Server@node2;Req;;Type 20 request received from Scheduler@node2.supernodexp.hpc, sock=16
04/24/2018 01:27:45;0100;Server@node2;Req;;Type 51 request received from Scheduler@node2.supernodexp.hpc, sock=16
04/24/2018 01:27:45;0100;Server@node2;Req;;Type 11 request received from Scheduler@node2.supernodexp.hpc, sock=16
04/24/2018 01:27:45;0008;Server@node2;Job;12320.node2.supernodexp.hpc;Job Modified at request of Scheduler@node2.supernodexp.hpc
04/24/2018 01:28:00;0080;Server@node2;Job;12316.node2.supernodexp.hpc;Obit received momhop:1 serverhop:1 state:4 substate:42
04/24/2018 01:28:01;0010;Server@node2;Job;12316.node2.supernodexp.hpc;Exit_status=0 resources_used.cpupercent=0 resources_used.cput=00:00:00 resources_used.mem=9720kb resources_used.ncpus=2 resources_used.vmem=38836kb resources_used.walltime=00:01:52
04/24/2018 01:28:01;0100;Server@node2;Job;12316.node2.supernodexp.hpc;dequeuing from workq, state 5
04/24/2018 01:28:01;0040;Server@node2;Svr;node2.supernodexp.hpc;Scheduler sent command 2
04/24/2018 01:28:01;0040;Server@node2;Svr;node2.supernodexp.hpc;Scheduler sent command 0
04/24/2018 01:28:01;0100;Server@node2;Req;;Type 21 request received from Scheduler@node2.supernodexp.hpc, sock=16
04/24/2018 01:28:01;0100;Server@node2;Req;;Type 81 request received from Scheduler@node2.supernodexp.hpc, sock=16
04/24/2018 01:28:01;0100;Server@node2;Req;;Type 71 request received from Scheduler@node2.supernodexp.hpc, sock=16
04/24/2018 01:28:01;0100;Server@node2;Req;;Type 58 request received from Scheduler@node2.supernodexp.hpc, sock=16
04/24/2018 01:28:01;0100;Server@node2;Req;;Type 20 request received from Scheduler@node2.supernodexp.hpc, sock=16
04/24/2018 01:28:01;0100;Server@node2;Req;;Type 51 request received from Scheduler@node2.supernodexp.hpc, sock=16
04/24/2018 01:33:00;0080;Server@node2;Job;12293.node2.supernodexp.hpc;Obit received momhop:1 serverhop:1 state:4 substate:42
04/24/2018 01:33:01;0010;Server@node2;Job;12293.node2.supernodexp.hpc;Exit_status=0 resources_used.cpupercent=0 resources_used.cput=00:00:00 resources_used.mem=11404kb resources_used.ncpus=12 resources_used.vmem=106752kb resources_used.walltime=00:17:11
04/24/2018 01:33:01;0100;Server@node2;Job;12293.node2.supernodexp.hpc;dequeuing from workq, state 5
04/24/2018 01:33:01;0040;Server@node2;Svr;node2.supernodexp.hpc;Scheduler sent command 2
04/24/2018 01:33:01;0040;Server@node2;Svr;node2.supernodexp.hpc;Scheduler sent command 0
04/24/2018 01:33:01;0100;Server@node2;Req;;Type 21 request received from Scheduler@node2.supernodexp.hpc, sock=16
04/24/2018 01:33:01;0100;Server@node2;Req;;Type 81 request received from Scheduler@node2.supernodexp.hpc, sock=16
04/24/2018 01:33:01;0100;Server@node2;Req;;Type 71 request received from Scheduler@node2.supernodexp.hpc, sock=16
04/24/2018 01:33:01;0100;Server@node2;Req;;Type 58 request received from Scheduler@node2.supernodexp.hpc, sock=16
04/24/2018 01:33:01;0100;Server@node2;Req;;Type 20 request received from Scheduler@node2.supernodexp.hpc, sock=16
04/24/2018 01:33:01;0100;Server@node2;Req;;Type 51 request received from Scheduler@node2.supernodexp.hpc, sock=16
04/24/2018 01:33:01;0100;Server@node2;Req;;Type 23 request received from Scheduler@node2.supernodexp.hpc, sock=16
04/24/2018 01:33:01;0008;Server@node2;Job;12320.node2.supernodexp.hpc;Job Run at request of Scheduler@node2.supernodexp.hpc on exec_vnode (node3:ncpus=32:nmics=2:mem=31457280kb)
04/24/2018 01:33:01;0001;Server@node2;Svr;Server@node2;Success (0) in req_runjob2, return value of svr_startjob is 0
04/24/2018 01:33:01;0100;Server@node2;Req;;Type 23 request received from Scheduler@node2.supernodexp.hpc, sock=16
04/24/2018 01:33:01;0008;Server@node2;Job;12321.node2.supernodexp.hpc;Job Run at request of Scheduler@node2.supernodexp.hpc on exec_vnode (node3:ncpus=8:mem=10485760kb)
04/24/2018 01:33:01;0001;Server@node2;Svr;Server@node2;Success (0) in req_runjob2, return value of svr_startjob is 0
04/24/2018 01:33:01;0100;Server@node2;Req;;Type 23 request received from Scheduler@node2.supernodexp.hpc, sock=16
04/24/2018 01:33:01;0008;Server@node2;Job;12322.node2.supernodexp.hpc;Job Run at request of Scheduler@node2.supernodexp.hpc on exec_vnode (node14:ncpus=8:mem=3145728kb)
04/24/2018 01:33:01;0001;Server@node2;Svr;Server@node2;Success (0) in req_runjob2, return value of svr_startjob is 0
04/24/2018 01:33:01;0100;Server@node2;Req;;Type 23 request received from Scheduler@node2.supernodexp.hpc, sock=16
04/24/2018 01:33:01;0008;Server@node2;Job;12323.node2.supernodexp.hpc;Job Run at request of Scheduler@node2.supernodexp.hpc on exec_vnode (node14:ncpus=4:mem=5242880kb)
04/24/2018 01:33:01;0001;Server@node2;Svr;Server@node2;Success (0) in req_runjob2, return value of svr_startjob is 0
04/24/2018 01:33:01;0100;Server@node2;Req;;Type 23 request received from Scheduler@node2.supernodexp.hpc, sock=16
04/24/2018 01:33:01;0008;Server@node2;Job;12324.node2.supernodexp.hpc;Job Run at request of Scheduler@node2.supernodexp.hpc on exec_vnode (node14:nmics=2:ncpus=2:mem=41943040kb)
04/24/2018 01:33:01;0001;Server@node2;Svr;Server@node2;Success (0) in req_runjob2, return value of svr_startjob is 0
04/24/2018 01:33:01;0100;Server@node2;Req;;Type 11 request received from Scheduler@node2.supernodexp.hpc, sock=16
04/24/2018 01:33:01;0008;Server@node2;Job;12325.node2.supernodexp.hpc;Job Modified at request of Scheduler@node2.supernodexp.hpc
04/24/2018 01:33:23;0080;Server@node2;Job;12323.node2.supernodexp.hpc;Obit received momhop:1 serverhop:1 state:4 substate:42
04/24/2018 01:33:24;0010;Server@node2;Job;12323.node2.supernodexp.hpc;Exit_status=0 resources_used.cpupercent=0 resources_used.cput=00:00:00 resources_used.mem=9612kb resources_used.ncpus=4 resources_used.vmem=514096kb resources_used.walltime=00:00:23
04/24/2018 01:33:24;0100;Server@node2;Job;12323.node2.supernodexp.hpc;dequeuing from workq, state 5
04/24/2018 01:33:24;0040;Server@node2;Svr;node2.supernodexp.hpc;Scheduler sent command 2
04/24/2018 01:33:24;0040;Server@node2;Svr;node2.supernodexp.hpc;Scheduler sent command 0
04/24/2018 01:33:24;0100;Server@node2;Req;;Type 21 request received from Scheduler@node2.supernodexp.hpc, sock=16
04/24/2018 01:33:24;0100;Server@node2;Req;;Type 81 request received from Scheduler@node2.supernodexp.hpc, sock=16
04/24/2018 01:33:24;0100;Server@node2;Req;;Type 71 request received from Scheduler@node2.supernodexp.hpc, sock=16
04/24/2018 01:33:24;0100;Server@node2;Req;;Type 58 request received from Scheduler@node2.supernodexp.hpc, sock=16
04/24/2018 01:33:24;0100;Server@node2;Req;;Type 20 request received from Scheduler@node2.supernodexp.hpc, sock=16
04/24/2018 01:33:24;0100;Server@node2;Req;;Type 51 request received from Scheduler@node2.supernodexp.hpc, sock=16
04/24/2018 01:33:32;0080;Server@node2;Job;12321.node2.supernodexp.hpc;Obit received momhop:1 serverhop:1 state:4 substate:42
04/24/2018 01:33:33;0010;Server@node2;Job;12321.node2.supernodexp.hpc;Exit_status=0 resources_used.cpupercent=0 resources_used.cput=00:00:00 resources_used.mem=9092kb resources_used.ncpus=8 resources_used.vmem=105344kb resources_used.walltime=00:00:31
04/24/2018 01:33:33;0100;Server@node2;Job;12321.node2.supernodexp.hpc;dequeuing from workq, state 5
04/24/2018 01:33:33;0040;Server@node2;Svr;node2.supernodexp.hpc;Scheduler sent command 2
04/24/2018 01:33:33;0040;Server@node2;Svr;node2.supernodexp.hpc;Scheduler sent command 0
04/24/2018 01:33:33;0100;Server@node2;Req;;Type 21 request received from Scheduler@node2.supernodexp.hpc, sock=16
04/24/2018 01:33:33;0100;Server@node2;Req;;Type 81 request received from Scheduler@node2.supernodexp.hpc, sock=16
04/24/2018 01:33:33;0100;Server@node2;Req;;Type 71 request received from Scheduler@node2.supernodexp.hpc, sock=16
04/24/2018 01:33:33;0100;Server@node2;Req;;Type 58 request received from Scheduler@node2.supernodexp.hpc, sock=16
04/24/2018 01:33:33;0100;Server@node2;Req;;Type 20 request received from Scheduler@node2.supernodexp.hpc, sock=16
04/24/2018 01:33:33;0100;Server@node2;Req;;Type 51 request received from Scheduler@node2.supernodexp.hpc, sock=16
04/24/2018 01:34:29;0080;Server@node2;Job;12307.node2.supernodexp.hpc;Obit received momhop:1 serverhop:1 state:4 substate:42
04/24/2018 01:34:30;0010;Server@node2;Job;12307.node2.supernodexp.hpc;Exit_status=0 resources_used.cpupercent=0 resources_used.cput=00:00:00 resources_used.mem=10036kb resources_used.ncpus=12 resources_used.vmem=172216kb resources_used.walltime=00:14:55
04/24/2018 01:34:30;0100;Server@node2;Job;12307.node2.supernodexp.hpc;dequeuing from workq, state 5
04/24/2018 01:34:30;0040;Server@node2;Svr;node2.supernodexp.hpc;Scheduler sent command 2
04/24/2018 01:34:30;0040;Server@node2;Svr;node2.supernodexp.hpc;Scheduler sent command 0
04/24/2018 01:34:30;0100;Server@node2;Req;;Type 21 request received from Scheduler@node2.supernodexp.hpc, sock=16
04/24/2018 01:34:30;0100;Server@node2;Req;;Type 81 request received from Scheduler@node2.supernodexp.hpc, sock=16
04/24/2018 01:34:30;0100;Server@node2;Req;;Type 71 request received from Scheduler@node2.supernodexp.hpc, sock=16
04/24/2018 01:34:30;0100;Server@node2;Req;;Type 58 request received from Scheduler@node2.supernodexp.hpc, sock=16
04/24/2018 01:34:30;0100;Server@node2;Req;;Type 20 request received from Scheduler@node2.supernodexp.hpc, sock=16
04/24/2018 01:34:30;0100;Server@node2;Req;;Type 51 request received from Scheduler@node2.supernodexp.hpc, sock=16
04/24/2018 01:34:31;0100;Server@node2;Req;;Type 23 request received from Scheduler@node2.supernodexp.hpc, sock=16
04/24/2018 01:34:31;0008;Server@node2;Job;12325.node2.supernodexp.hpc;Job Run at request of Scheduler@node2.supernodexp.hpc on exec_vnode (node13:nmics=2:ncpus=2:mem=41943040kb)
04/24/2018 01:34:31;0001;Server@node2;Svr;Server@node2;Success (0) in req_runjob2, return value of svr_startjob is 0
04/24/2018 01:34:31;0100;Server@node2;Req;;Type 23 request received from Scheduler@node2.supernodexp.hpc, sock=16
04/24/2018 01:34:31;0008;Server@node2;Job;12326.node2.supernodexp.hpc;Job Run at request of Scheduler@node2.supernodexp.hpc on exec_vnode (node3:ncpus=8:mem=20971520kb)
04/24/2018 01:34:31;0001;Server@node2;Svr;Server@node2;Success (0) in req_runjob2, return value of svr_startjob is 0
04/24/2018 01:34:31;0100;Server@node2;Req;;Type 23 request received from Scheduler@node2.supernodexp.hpc, sock=16
04/24/2018 01:34:31;0008;Server@node2;Job;12327.node2.supernodexp.hpc;Job Run at request of Scheduler@node2.supernodexp.hpc on exec_vnode (node14:ncpus=8:mem=10485760kb)
04/24/2018 01:34:31;0001;Server@node2;Svr;Server@node2;Success (0) in req_runjob2, return value of svr_startjob is 0
04/24/2018 01:34:31;0100;Server@node2;Req;;Type 23 request received from Scheduler@node2.supernodexp.hpc, sock=16
04/24/2018 01:34:31;0008;Server@node2;Job;12328.node2.supernodexp.hpc;Job Run at request of Scheduler@node2.supernodexp.hpc on exec_vnode (node13:ncpus=24:mem=5242880kb)
04/24/2018 01:34:31;0001;Server@node2;Svr;Server@node2;Success (0) in req_runjob2, return value of svr_startjob is 0
04/24/2018 01:34:31;0100;Server@node2;Req;;Type 11 request received from Scheduler@node2.supernodexp.hpc, sock=16
04/24/2018 01:34:31;0008;Server@node2;Job;12329.node2.supernodexp.hpc;Job Modified at request of Scheduler@node2.supernodexp.hpc
04/24/2018 01:34:35;0080;Server@node2;Job;12328.node2.supernodexp.hpc;Obit received momhop:1 serverhop:1 state:4 substate:42
04/24/2018 01:34:35;0010;Server@node2;Job;12328.node2.supernodexp.hpc;Exit_status=0 resources_used.cpupercent=0 resources_used.cput=00:00:00 resources_used.mem=0kb resources_used.ncpus=24 resources_used.vmem=0kb resources_used.walltime=00:00:04
04/24/2018 01:34:35;0100;Server@node2;Job;12328.node2.supernodexp.hpc;dequeuing from workq, state 5
04/24/2018 01:34:35;0040;Server@node2;Svr;node2.supernodexp.hpc;Scheduler sent command 2
04/24/2018 01:34:35;0040;Server@node2;Svr;node2.supernodexp.hpc;Scheduler sent command 0
04/24/2018 01:34:35;0100;Server@node2;Req;;Type 21 request received from Scheduler@node2.supernodexp.hpc, sock=16
04/24/2018 01:34:35;0100;Server@node2;Req;;Type 81 request received from Scheduler@node2.supernodexp.hpc, sock=16
04/24/2018 01:34:35;0100;Server@node2;Req;;Type 71 request received from Scheduler@node2.supernodexp.hpc, sock=16
04/24/2018 01:34:35;0100;Server@node2;Req;;Type 58 request received from Scheduler@node2.supernodexp.hpc, sock=16
04/24/2018 01:34:35;0100;Server@node2;Req;;Type 20 request received from Scheduler@node2.supernodexp.hpc, sock=16
04/24/2018 01:34:35;0100;Server@node2;Req;;Type 51 request received from Scheduler@node2.supernodexp.hpc, sock=16
04/24/2018 01:34:59;0080;Server@node2;Job;12324.node2.supernodexp.hpc;Obit received momhop:1 serverhop:1 state:4 substate:42
04/24/2018 01:35:00;0010;Server@node2;Job;12324.node2.supernodexp.hpc;Exit_status=0 resources_used.cpupercent=0 resources_used.cput=00:00:00 resources_used.mem=9616kb resources_used.ncpus=2 resources_used.vmem=172216kb resources_used.walltime=00:01:59
04/24/2018 01:35:00;0100;Server@node2;Job;12324.node2.supernodexp.hpc;dequeuing from workq, state 5
04/24/2018 01:35:00;0040;Server@node2;Svr;node2.supernodexp.hpc;Scheduler sent command 2
04/24/2018 01:35:00;0040;Server@node2;Svr;node2.supernodexp.hpc;Scheduler sent command 0
04/24/2018 01:35:00;0100;Server@node2;Req;;Type 21 request received from Scheduler@node2.supernodexp.hpc, sock=16
04/24/2018 01:35:00;0100;Server@node2;Req;;Type 81 request received from Scheduler@node2.supernodexp.hpc, sock=16
04/24/2018 01:35:00;0100;Server@node2;Req;;Type 71 request received from Scheduler@node2.supernodexp.hpc, sock=16
04/24/2018 01:35:00;0100;Server@node2;Req;;Type 58 request received from Scheduler@node2.supernodexp.hpc, sock=16
04/24/2018 01:35:00;0100;Server@node2;Req;;Type 20 request received from Scheduler@node2.supernodexp.hpc, sock=16
04/24/2018 01:35:00;0100;Server@node2;Req;;Type 51 request received from Scheduler@node2.supernodexp.hpc, sock=16
04/24/2018 01:35:00;0100;Server@node2;Req;;Type 23 request received from Scheduler@node2.supernodexp.hpc, sock=16
04/24/2018 01:35:00;0008;Server@node2;Job;12329.node2.supernodexp.hpc;Job Run at request of Scheduler@node2.supernodexp.hpc on exec_vnode (node14:nmics=2:ncpus=2:mem=41943040kb)
04/24/2018 01:35:00;0001;Server@node2;Svr;Server@node2;Success (0) in req_runjob2, return value of svr_startjob is 0
04/24/2018 01:35:00;0100;Server@node2;Req;;Type 23 request received from Scheduler@node2.supernodexp.hpc, sock=16
04/24/2018 01:35:00;0008;Server@node2;Job;12330.node2.supernodexp.hpc;Job Run at request of Scheduler@node2.supernodexp.hpc on exec_vnode (node13:ncpus=8:mem=10485760kb)
04/24/2018 01:35:00;0001;Server@node2;Svr;Server@node2;Success (0) in req_runjob2, return value of svr_startjob is 0
04/24/2018 01:35:00;0100;Server@node2;Req;;Type 23 request received from Scheduler@node2.supernodexp.hpc, sock=16
04/24/2018 01:35:00;0008;Server@node2;Job;12331.node2.supernodexp.hpc;Job Run at request of Scheduler@node2.supernodexp.hpc on exec_vnode (node13:ncpus=8:mem=5242880kb)
04/24/2018 01:35:00;0001;Server@node2;Svr;Server@node2;Success (0) in req_runjob2, return value of svr_startjob is 0
04/24/2018 01:35:00;0100;Server@node2;Req;;Type 23 request received from Scheduler@node2.supernodexp.hpc, sock=16
04/24/2018 01:35:00;0008;Server@node2;Job;12332.node2.supernodexp.hpc;Job Run at request of Scheduler@node2.supernodexp.hpc on exec_vnode (node14:ncpus=2:mem=2097152kb)
04/24/2018 01:35:00;0001;Server@node2;Svr;Server@node2;Success (0) in req_runjob2, return value of svr_startjob is 0
04/24/2018 01:35:00;0100;Server@node2;Req;;Type 11 request received from Scheduler@node2.supernodexp.hpc, sock=16
04/24/2018 01:35:00;0008;Server@node2;Job;12333.node2.supernodexp.hpc;Job Modified at request of Scheduler@node2.supernodexp.hpc
04/24/2018 01:35:04;0080;Server@node2;Job;12332.node2.supernodexp.hpc;Obit received momhop:1 serverhop:1 state:4 substate:42
04/24/2018 01:35:05;0010;Server@node2;Job;12332.node2.supernodexp.hpc;Exit_status=0 resources_used.cpupercent=0 resources_used.cput=00:00:00 resources_used.mem=0kb resources_used.ncpus=2 resources_used.vmem=0kb resources_used.walltime=00:00:04
04/24/2018 01:35:05;0100;Server@node2;Job;12332.node2.supernodexp.hpc;dequeuing from workq, state 5
04/24/2018 01:35:05;0040;Server@node2;Svr;node2.supernodexp.hpc;Scheduler sent command 2
04/24/2018 01:35:05;0040;Server@node2;Svr;node2.supernodexp.hpc;Scheduler sent command 0
04/24/2018 01:35:05;0100;Server@node2;Req;;Type 21 request received from Scheduler@node2.supernodexp.hpc, sock=16
04/24/2018 01:35:05;0100;Server@node2;Req;;Type 81 request received from Scheduler@node2.supernodexp.hpc, sock=16
04/24/2018 01:35:05;0100;Server@node2;Req;;Type 71 request received from Scheduler@node2.supernodexp.hpc, sock=16
04/24/2018 01:35:05;0100;Server@node2;Req;;Type 58 request received from Scheduler@node2.supernodexp.hpc, sock=16
04/24/2018 01:35:05;0100;Server@node2;Req;;Type 20 request received from Scheduler@node2.supernodexp.hpc, sock=16
04/24/2018 01:35:05;0100;Server@node2;Req;;Type 51 request received from Scheduler@node2.supernodexp.hpc, sock=16
04/24/2018 01:35:08;0080;Server@node2;Job;12326.node2.supernodexp.hpc;Obit received momhop:1 serverhop:1 state:4 substate:42
04/24/2018 01:35:09;0010;Server@node2;Job;12326.node2.supernodexp.hpc;Exit_status=0 resources_used.cpupercent=0 resources_used.cput=00:00:00 resources_used.mem=9096kb resources_used.ncpus=8 resources_used.vmem=105088kb resources_used.walltime=00:00:38
04/24/2018 01:35:09;0100;Server@node2;Job;12326.node2.supernodexp.hpc;dequeuing from workq, state 5
04/24/2018 01:35:09;0040;Server@node2;Svr;node2.supernodexp.hpc;Scheduler sent command 2
04/24/2018 01:35:09;0040;Server@node2;Svr;node2.supernodexp.hpc;Scheduler sent command 0
04/24/2018 01:35:09;0100;Server@node2;Req;;Type 21 request received from Scheduler@node2.supernodexp.hpc, sock=16
04/24/2018 01:35:09;0100;Server@node2;Req;;Type 81 request received from Scheduler@node2.supernodexp.hpc, sock=16
04/24/2018 01:35:09;0100;Server@node2;Req;;Type 71 request received from Scheduler@node2.supernodexp.hpc, sock=16
04/24/2018 01:35:09;0100;Server@node2;Req;;Type 58 request received from Scheduler@node2.supernodexp.hpc, sock=16
04/24/2018 01:35:09;0100;Server@node2;Req;;Type 20 request received from Scheduler@node2.supernodexp.hpc, sock=16
04/24/2018 01:35:09;0100;Server@node2;Req;;Type 51 request received from Scheduler@node2.supernodexp.hpc, sock=16
04/24/2018 01:35:14;0080;Server@node2;Job;12331.node2.supernodexp.hpc;Obit received momhop:1 serverhop:1 state:4 substate:42
04/24/2018 01:35:14;0080;Server@node2;Job;12327.node2.supernodexp.hpc;Obit received momhop:1 serverhop:1 state:4 substate:42
04/24/2018 01:35:15;0010;Server@node2;Job;12327.node2.supernodexp.hpc;Exit_status=0 resources_used.cpupercent=0 resources_used.cput=00:00:00 resources_used.mem=9616kb resources_used.ncpus=8 resources_used.vmem=172216kb resources_used.walltime=00:00:43
04/24/2018 01:35:15;0100;Server@node2;Job;12327.node2.supernodexp.hpc;dequeuing from workq, state 5
04/24/2018 01:35:15;0040;Server@node2;Svr;node2.supernodexp.hpc;Scheduler sent command 2
04/24/2018 01:35:15;0040;Server@node2;Svr;node2.supernodexp.hpc;Scheduler sent command 0
04/24/2018 01:35:15;0100;Server@node2;Req;;Type 21 request received from Scheduler@node2.supernodexp.hpc, sock=16
04/24/2018 01:35:15;0100;Server@node2;Req;;Type 81 request received from Scheduler@node2.supernodexp.hpc, sock=16
04/24/2018 01:35:15;0100;Server@node2;Req;;Type 71 request received from Scheduler@node2.supernodexp.hpc, sock=16
04/24/2018 01:35:15;0100;Server@node2;Req;;Type 58 request received from Scheduler@node2.supernodexp.hpc, sock=16
04/24/2018 01:35:15;0100;Server@node2;Req;;Type 20 request received from Scheduler@node2.supernodexp.hpc, sock=16
04/24/2018 01:35:15;0100;Server@node2;Req;;Type 51 request received from Scheduler@node2.supernodexp.hpc, sock=16
04/24/2018 01:35:15;0010;Server@node2;Job;12331.node2.supernodexp.hpc;Exit_status=0 resources_used.cpupercent=0 resources_used.cput=00:00:00 resources_used.mem=9640kb resources_used.ncpus=8 resources_used.vmem=171960kb resources_used.walltime=00:00:14
04/24/2018 01:35:15;0100;Server@node2;Job;12331.node2.supernodexp.hpc;dequeuing from workq, state 5
04/24/2018 01:35:15;0040;Server@node2;Svr;node2.supernodexp.hpc;Scheduler sent command 2
04/24/2018 01:35:15;0040;Server@node2;Svr;node2.supernodexp.hpc;Scheduler sent command 0
04/24/2018 01:35:15;0100;Server@node2;Req;;Type 21 request received from Scheduler@node2.supernodexp.hpc, sock=16
04/24/2018 01:35:15;0100;Server@node2;Req;;Type 81 request received from Scheduler@node2.supernodexp.hpc, sock=16
04/24/2018 01:35:15;0100;Server@node2;Req;;Type 71 request received from Scheduler@node2.supernodexp.hpc, sock=16
04/24/2018 01:35:15;0100;Server@node2;Req;;Type 58 request received from Scheduler@node2.supernodexp.hpc, sock=16
04/24/2018 01:35:15;0100;Server@node2;Req;;Type 20 request received from Scheduler@node2.supernodexp.hpc, sock=16
04/24/2018 01:35:15;0100;Server@node2;Req;;Type 51 request received from Scheduler@node2.supernodexp.hpc, sock=16
04/24/2018 01:35:24;0080;Server@node2;Job;12330.node2.supernodexp.hpc;Obit received momhop:1 serverhop:1 state:4 substate:42
04/24/2018 01:35:25;0010;Server@node2;Job;12330.node2.supernodexp.hpc;Exit_status=0 resources_used.cpupercent=0 resources_used.cput=00:00:00 resources_used.mem=9404kb resources_used.ncpus=8 resources_used.vmem=172216kb resources_used.walltime=00:00:24
04/24/2018 01:35:25;0100;Server@node2;Job;12330.node2.supernodexp.hpc;dequeuing from workq, state 5
04/24/2018 01:35:25;0040;Server@node2;Svr;node2.supernodexp.hpc;Scheduler sent command 2
04/24/2018 01:35:25;0040;Server@node2;Svr;node2.supernodexp.hpc;Scheduler sent command 0
04/24/2018 01:35:25;0100;Server@node2;Req;;Type 21 request received from Scheduler@node2.supernodexp.hpc, sock=16
04/24/2018 01:35:25;0100;Server@node2;Req;;Type 81 request received from Scheduler@node2.supernodexp.hpc, sock=16
04/24/2018 01:35:25;0100;Server@node2;Req;;Type 71 request received from Scheduler@node2.supernodexp.hpc, sock=16
04/24/2018 01:35:25;0100;Server@node2;Req;;Type 58 request received from Scheduler@node2.supernodexp.hpc, sock=16
04/24/2018 01:35:25;0100;Server@node2;Req;;Type 20 request received from Scheduler@node2.supernodexp.hpc, sock=16
04/24/2018 01:35:25;0100;Server@node2;Req;;Type 51 request received from Scheduler@node2.supernodexp.hpc, sock=16
04/24/2018 01:35:54;0080;Server@node2;Job;12315.node2.supernodexp.hpc;Obit received momhop:1 serverhop:1 state:4 substate:42
04/24/2018 01:35:54;0010;Server@node2;Job;12315.node2.supernodexp.hpc;Exit_status=0 resources_used.cpupercent=0 resources_used.cput=00:00:00 resources_used.mem=9416kb resources_used.ncpus=8 resources_used.vmem=105088kb resources_used.walltime=00:10:04
04/24/2018 01:35:54;0100;Server@node2;Job;12315.node2.supernodexp.hpc;dequeuing from workq, state 5
04/24/2018 01:35:54;0040;Server@node2;Svr;node2.supernodexp.hpc;Scheduler sent command 2
04/24/2018 01:35:54;0040;Server@node2;Svr;node2.supernodexp.hpc;Scheduler sent command 0
04/24/2018 01:35:54;0100;Server@node2;Req;;Type 21 request received from Scheduler@node2.supernodexp.hpc, sock=16
04/24/2018 01:35:54;0100;Server@node2;Req;;Type 81 request received from Scheduler@node2.supernodexp.hpc, sock=16
04/24/2018 01:35:54;0100;Server@node2;Req;;Type 71 request received from Scheduler@node2.supernodexp.hpc, sock=16
04/24/2018 01:35:54;0100;Server@node2;Req;;Type 58 request received from Scheduler@node2.supernodexp.hpc, sock=16
04/24/2018 01:35:54;0100;Server@node2;Req;;Type 20 request received from Scheduler@node2.supernodexp.hpc, sock=16
04/24/2018 01:35:54;0100;Server@node2;Req;;Type 51 request received from Scheduler@node2.supernodexp.hpc, sock=16
04/24/2018 01:36:19;0080;Server@node2;Job;12325.node2.supernodexp.hpc;Obit received momhop:1 serverhop:1 state:4 substate:42
04/24/2018 01:36:19;0010;Server@node2;Job;12325.node2.supernodexp.hpc;Exit_status=0 resources_used.cpupercent=0 resources_used.cput=00:00:00 resources_used.mem=9416kb resources_used.ncpus=2 resources_used.vmem=171960kb resources_used.walltime=00:01:48
04/24/2018 01:36:19;0100;Server@node2;Job;12325.node2.supernodexp.hpc;dequeuing from workq, state 5
04/24/2018 01:36:19;0040;Server@node2;Svr;node2.supernodexp.hpc;Scheduler sent command 2
04/24/2018 01:36:19;0040;Server@node2;Svr;node2.supernodexp.hpc;Scheduler sent command 0
04/24/2018 01:36:19;0100;Server@node2;Req;;Type 21 request received from Scheduler@node2.supernodexp.hpc, sock=16
04/24/2018 01:36:19;0100;Server@node2;Req;;Type 81 request received from Scheduler@node2.supernodexp.hpc, sock=16
04/24/2018 01:36:19;0100;Server@node2;Req;;Type 71 request received from Scheduler@node2.supernodexp.hpc, sock=16
04/24/2018 01:36:19;0100;Server@node2;Req;;Type 58 request received from Scheduler@node2.supernodexp.hpc, sock=16
04/24/2018 01:36:20;0100;Server@node2;Req;;Type 20 request received from Scheduler@node2.supernodexp.hpc, sock=16
04/24/2018 01:36:20;0100;Server@node2;Req;;Type 51 request received from Scheduler@node2.supernodexp.hpc, sock=16
04/24/2018 01:36:20;0100;Server@node2;Req;;Type 23 request received from Scheduler@node2.supernodexp.hpc, sock=16
04/24/2018 01:36:20;0008;Server@node2;Job;12333.node2.supernodexp.hpc;Job Run at request of Scheduler@node2.supernodexp.hpc on exec_vnode (node13:nmics=2:ncpus=12:mem=41943040kb)
04/24/2018 01:36:20;0001;Server@node2;Svr;Server@node2;Success (0) in req_runjob2, return value of svr_startjob is 0
04/24/2018 01:36:20;0100;Server@node2;Req;;Type 23 request received from Scheduler@node2.supernodexp.hpc, sock=16
04/24/2018 01:36:20;0008;Server@node2;Job;12334.node2.supernodexp.hpc;Job Run at request of Scheduler@node2.supernodexp.hpc on exec_vnode (node3:ncpus=8:mem=20971520kb)
04/24/2018 01:36:20;0001;Server@node2;Svr;Server@node2;Success (0) in req_runjob2, return value of svr_startjob is 0
04/24/2018 01:36:20;0100;Server@node2;Req;;Type 23 request received from Scheduler@node2.supernodexp.hpc, sock=16
04/24/2018 01:36:20;0008;Server@node2;Job;12335.node2.supernodexp.hpc;Job Run at request of Scheduler@node2.supernodexp.hpc on exec_vnode (node14:ncpus=12:mem=20971520kb)
04/24/2018 01:36:20;0001;Server@node2;Svr;Server@node2;Success (0) in req_runjob2, return value of svr_startjob is 0
04/24/2018 01:36:20;0100;Server@node2;Req;;Type 23 request received from Scheduler@node2.supernodexp.hpc, sock=16
04/24/2018 01:36:20;0008;Server@node2;Job;12336.node2.supernodexp.hpc;Job Run at request of Scheduler@node2.supernodexp.hpc on exec_vnode (node13:ncpus=12:mem=20971520kb)
04/24/2018 01:36:20;0001;Server@node2;Svr;Server@node2;Success (0) in req_runjob2, return value of svr_startjob is 0
04/24/2018 01:36:20;0100;Server@node2;Req;;Type 23 request received from Scheduler@node2.supernodexp.hpc, sock=16
04/24/2018 01:36:20;0008;Server@node2;Job;12337.node2.supernodexp.hpc;Job Run at request of Scheduler@node2.supernodexp.hpc on exec_vnode (node3:ncpus=8:mem=5242880kb)
04/24/2018 01:36:20;0001;Server@node2;Svr;Server@node2;Success (0) in req_runjob2, return value of svr_startjob is 0
04/24/2018 01:36:20;0100;Server@node2;Req;;Type 23 request received from Scheduler@node2.supernodexp.hpc, sock=16
04/24/2018 01:36:20;0008;Server@node2;Job;12338.node2.supernodexp.hpc;Job Run at request of Scheduler@node2.supernodexp.hpc on exec_vnode (node13:ncpus=8:mem=15728640kb)
04/24/2018 01:36:20;0001;Server@node2;Svr;Server@node2;Success (0) in req_runjob2, return value of svr_startjob is 0
04/24/2018 01:36:20;0100;Server@node2;Req;;Type 23 request received from Scheduler@node2.supernodexp.hpc, sock=16
04/24/2018 01:36:20;0008;Server@node2;Job;12339.node2.supernodexp.hpc;Job Run at request of Scheduler@node2.supernodexp.hpc on exec_vnode (node14:ncpus=2:mem=2097152kb)
04/24/2018 01:36:20;0001;Server@node2;Svr;Server@node2;Success (0) in req_runjob2, return value of svr_startjob is 0
04/24/2018 01:36:20;0100;Server@node2;Req;;Type 11 request received from Scheduler@node2.supernodexp.hpc, sock=16
04/24/2018 01:36:20;0008;Server@node2;Job;12340.node2.supernodexp.hpc;Job Modified at request of Scheduler@node2.supernodexp.hpc
04/24/2018 01:36:24;0080;Server@node2;Job;12339.node2.supernodexp.hpc;Obit received momhop:1 serverhop:1 state:4 substate:42
04/24/2018 01:36:25;0010;Server@node2;Job;12339.node2.supernodexp.hpc;Exit_status=0 resources_used.cpupercent=0 resources_used.cput=00:00:00 resources_used.mem=0kb resources_used.ncpus=2 resources_used.vmem=0kb resources_used.walltime=00:00:04
04/24/2018 01:36:25;0100;Server@node2;Job;12339.node2.supernodexp.hpc;dequeuing from workq, state 5
04/24/2018 01:36:25;0040;Server@node2;Svr;node2.supernodexp.hpc;Scheduler sent command 2
04/24/2018 01:36:25;0040;Server@node2;Svr;node2.supernodexp.hpc;Scheduler sent command 0
04/24/2018 01:36:25;0100;Server@node2;Req;;Type 21 request received from Scheduler@node2.supernodexp.hpc, sock=16
04/24/2018 01:36:25;0100;Server@node2;Req;;Type 81 request received from Scheduler@node2.supernodexp.hpc, sock=16
04/24/2018 01:36:25;0100;Server@node2;Req;;Type 71 request received from Scheduler@node2.supernodexp.hpc, sock=16
04/24/2018 01:36:25;0100;Server@node2;Req;;Type 58 request received from Scheduler@node2.supernodexp.hpc, sock=16
04/24/2018 01:36:25;0100;Server@node2;Req;;Type 20 request received from Scheduler@node2.supernodexp.hpc, sock=16
04/24/2018 01:36:25;0100;Server@node2;Req;;Type 51 request received from Scheduler@node2.supernodexp.hpc, sock=16
04/24/2018 01:36:43;0080;Server@node2;Job;12337.node2.supernodexp.hpc;Obit received momhop:1 serverhop:1 state:4 substate:42
04/24/2018 01:36:44;0010;Server@node2;Job;12337.node2.supernodexp.hpc;Exit_status=0 resources_used.cpupercent=0 resources_used.cput=00:00:00 resources_used.mem=9324kb resources_used.ncpus=8 resources_used.vmem=106496kb resources_used.walltime=00:00:24
04/24/2018 01:36:44;0100;Server@node2;Job;12337.node2.supernodexp.hpc;dequeuing from workq, state 5
04/24/2018 01:36:44;0040;Server@node2;Svr;node2.supernodexp.hpc;Scheduler sent command 2
04/24/2018 01:36:44;0040;Server@node2;Svr;node2.supernodexp.hpc;Scheduler sent command 0
04/24/2018 01:36:44;0100;Server@node2;Req;;Type 21 request received from Scheduler@node2.supernodexp.hpc, sock=16
04/24/2018 01:36:44;0100;Server@node2;Req;;Type 81 request received from Scheduler@node2.supernodexp.hpc, sock=16
04/24/2018 01:36:44;0100;Server@node2;Req;;Type 71 request received from Scheduler@node2.supernodexp.hpc, sock=16
04/24/2018 01:36:44;0100;Server@node2;Req;;Type 58 request received from Scheduler@node2.supernodexp.hpc, sock=16
04/24/2018 01:36:44;0100;Server@node2;Req;;Type 20 request received from Scheduler@node2.supernodexp.hpc, sock=16
04/24/2018 01:36:44;0100;Server@node2;Req;;Type 51 request received from Scheduler@node2.supernodexp.hpc, sock=16
04/24/2018 01:36:54;0080;Server@node2;Job;12334.node2.supernodexp.hpc;Obit received momhop:1 serverhop:1 state:4 substate:42
04/24/2018 01:36:55;0010;Server@node2;Job;12334.node2.supernodexp.hpc;Exit_status=0 resources_used.cpupercent=0 resources_used.cput=00:00:00 resources_used.mem=9096kb resources_used.ncpus=8 resources_used.vmem=103292kb resources_used.walltime=00:00:35
04/24/2018 01:36:55;0100;Server@node2;Job;12334.node2.supernodexp.hpc;dequeuing from workq, state 5
04/24/2018 01:36:55;0040;Server@node2;Svr;node2.supernodexp.hpc;Scheduler sent command 2
04/24/2018 01:36:55;0040;Server@node2;Svr;node2.supernodexp.hpc;Scheduler sent command 0
04/24/2018 01:36:55;0100;Server@node2;Req;;Type 21 request received from Scheduler@node2.supernodexp.hpc, sock=16
04/24/2018 01:36:55;0100;Server@node2;Req;;Type 81 request received from Scheduler@node2.supernodexp.hpc, sock=16
04/24/2018 01:36:55;0100;Server@node2;Req;;Type 71 request received from Scheduler@node2.supernodexp.hpc, sock=16
04/24/2018 01:36:55;0100;Server@node2;Req;;Type 58 request received from Scheduler@node2.supernodexp.hpc, sock=16
04/24/2018 01:36:55;0100;Server@node2;Req;;Type 20 request received from Scheduler@node2.supernodexp.hpc, sock=16
04/24/2018 01:36:55;0100;Server@node2;Req;;Type 51 request received from Scheduler@node2.supernodexp.hpc, sock=16
04/24/2018 01:37:00;0080;Server@node2;Job;12329.node2.supernodexp.hpc;Obit received momhop:1 serverhop:1 state:4 substate:42
04/24/2018 01:37:01;0010;Server@node2;Job;12329.node2.supernodexp.hpc;Exit_status=0 resources_used.cpupercent=0 resources_used.cput=00:00:00 resources_used.mem=9648kb resources_used.ncpus=2 resources_used.vmem=102320kb resources_used.walltime=00:02:00
04/24/2018 01:37:01;0100;Server@node2;Job;12329.node2.supernodexp.hpc;dequeuing from workq, state 5
04/24/2018 01:37:01;0040;Server@node2;Svr;node2.supernodexp.hpc;Scheduler sent command 2
04/24/2018 01:37:01;0040;Server@node2;Svr;node2.supernodexp.hpc;Scheduler sent command 0
04/24/2018 01:37:01;0100;Server@node2;Req;;Type 21 request received from Scheduler@node2.supernodexp.hpc, sock=16
04/24/2018 01:37:01;0100;Server@node2;Req;;Type 81 request received from Scheduler@node2.supernodexp.hpc, sock=16
04/24/2018 01:37:01;0100;Server@node2;Req;;Type 71 request received from Scheduler@node2.supernodexp.hpc, sock=16
04/24/2018 01:37:01;0100;Server@node2;Req;;Type 58 request received from Scheduler@node2.supernodexp.hpc, sock=16
04/24/2018 01:37:01;0100;Server@node2;Req;;Type 20 request received from Scheduler@node2.supernodexp.hpc, sock=16
04/24/2018 01:37:01;0100;Server@node2;Req;;Type 51 request received from Scheduler@node2.supernodexp.hpc, sock=16
04/24/2018 01:37:01;0100;Server@node2;Req;;Type 23 request received from Scheduler@node2.supernodexp.hpc, sock=16
04/24/2018 01:37:01;0008;Server@node2;Job;12340.node2.supernodexp.hpc;Job Run at request of Scheduler@node2.supernodexp.hpc on exec_vnode (node14:nmics=2:ncpus=2:mem=41943040kb)
04/24/2018 01:37:01;0001;Server@node2;Svr;Server@node2;Success (0) in req_runjob2, return value of svr_startjob is 0
04/24/2018 01:37:01;0100;Server@node2;Req;;Type 23 request received from Scheduler@node2.supernodexp.hpc, sock=16
04/24/2018 01:37:01;0008;Server@node2;Job;12341.node2.supernodexp.hpc;Job Run at request of Scheduler@node2.supernodexp.hpc on exec_vnode (node3:ncpus=8:mem=20971520kb)
04/24/2018 01:37:01;0001;Server@node2;Svr;Server@node2;Success (0) in req_runjob2, return value of svr_startjob is 0
04/24/2018 01:37:01;0100;Server@node2;Req;;Type 23 request received from Scheduler@node2.supernodexp.hpc, sock=16
04/24/2018 01:37:01;0008;Server@node2;Job;12342.node2.supernodexp.hpc;Job Run at request of Scheduler@node2.supernodexp.hpc on exec_vnode (node13:ncpus=12:mem=5242880kb)
04/24/2018 01:37:01;0001;Server@node2;Svr;Server@node2;Success (0) in req_runjob2, return value of svr_startjob is 0
04/24/2018 01:37:01;0100;Server@node2;Req;;Type 11 request received from Scheduler@node2.supernodexp.hpc, sock=16
04/24/2018 01:37:01;0008;Server@node2;Job;12343.node2.supernodexp.hpc;Job Modified at request of Scheduler@node2.supernodexp.hpc
04/24/2018 01:37:32;0080;Server@node2;Job;12341.node2.supernodexp.hpc;Obit received momhop:1 serverhop:1 state:4 substate:42
04/24/2018 01:37:33;0010;Server@node2;Job;12341.node2.supernodexp.hpc;Exit_status=0 resources_used.cpupercent=0 resources_used.cput=00:00:00 resources_used.mem=9088kb resources_used.ncpus=8 resources_used.vmem=172032kb resources_used.walltime=00:00:31
04/24/2018 01:37:33;0100;Server@node2;Job;12341.node2.supernodexp.hpc;dequeuing from workq, state 5
04/24/2018 01:37:33;0040;Server@node2;Svr;node2.supernodexp.hpc;Scheduler sent command 2
04/24/2018 01:37:33;0040;Server@node2;Svr;node2.supernodexp.hpc;Scheduler sent command 0
04/24/2018 01:37:33;0100;Server@node2;Req;;Type 21 request received from Scheduler@node2.supernodexp.hpc, sock=16
04/24/2018 01:37:33;0100;Server@node2;Req;;Type 81 request received from Scheduler@node2.supernodexp.hpc, sock=16
04/24/2018 01:37:33;0100;Server@node2;Req;;Type 71 request received from Scheduler@node2.supernodexp.hpc, sock=16
04/24/2018 01:37:33;0100;Server@node2;Req;;Type 58 request received from Scheduler@node2.supernodexp.hpc, sock=16
04/24/2018 01:37:33;0100;Server@node2;Req;;Type 20 request received from Scheduler@node2.supernodexp.hpc, sock=16
04/24/2018 01:37:33;0100;Server@node2;Req;;Type 51 request received from Scheduler@node2.supernodexp.hpc, sock=16
04/24/2018 01:37:34;0100;Server@node2;Req;;Type 23 request received from Scheduler@node2.supernodexp.hpc, sock=16
04/24/2018 01:37:34;0008;Server@node2;Job;12343.node2.supernodexp.hpc;Job Run at request of Scheduler@node2.supernodexp.hpc on exec_vnode (node3:ncpus=12:mem=5242880kb)
04/24/2018 01:37:34;0001;Server@node2;Svr;Server@node2;Success (0) in req_runjob2, return value of svr_startjob is 0
04/24/2018 01:37:34;0100;Server@node2;Req;;Type 11 request received from Scheduler@node2.supernodexp.hpc, sock=16
04/24/2018 01:37:34;0008;Server@node2;Job;12344.node2.supernodexp.hpc;Job Modified at request of Scheduler@node2.supernodexp.hpc
04/24/2018 01:39:00;0080;Server@node2;Job;12340.node2.supernodexp.hpc;Obit received momhop:1 serverhop:1 state:4 substate:42
04/24/2018 01:39:01;0010;Server@node2;Job;12340.node2.supernodexp.hpc;Exit_status=0 resources_used.cpupercent=0 resources_used.cput=00:00:00 resources_used.mem=9424kb resources_used.ncpus=2 resources_used.vmem=171960kb resources_used.walltime=00:01:59
04/24/2018 01:39:01;0100;Server@node2;Job;12340.node2.supernodexp.hpc;dequeuing from workq, state 5
04/24/2018 01:39:01;0040;Server@node2;Svr;node2.supernodexp.hpc;Scheduler sent command 2
04/24/2018 01:39:01;0040;Server@node2;Svr;node2.supernodexp.hpc;Scheduler sent command 0
04/24/2018 01:39:01;0100;Server@node2;Req;;Type 21 request received from Scheduler@node2.supernodexp.hpc, sock=16
04/24/2018 01:39:01;0100;Server@node2;Req;;Type 81 request received from Scheduler@node2.supernodexp.hpc, sock=16
04/24/2018 01:39:01;0100;Server@node2;Req;;Type 71 request received from Scheduler@node2.supernodexp.hpc, sock=16
04/24/2018 01:39:01;0100;Server@node2;Req;;Type 58 request received from Scheduler@node2.supernodexp.hpc, sock=16
04/24/2018 01:39:01;0100;Server@node2;Req;;Type 20 request received from Scheduler@node2.supernodexp.hpc, sock=16
04/24/2018 01:39:01;0100;Server@node2;Req;;Type 51 request received from Scheduler@node2.supernodexp.hpc, sock=16
04/24/2018 01:39:01;0100;Server@node2;Req;;Type 11 request received from Scheduler@node2.supernodexp.hpc, sock=16
04/24/2018 01:39:01;0008;Server@node2;Job;12344.node2.supernodexp.hpc;Job Modified at request of Scheduler@node2.supernodexp.hpc
04/24/2018 01:40:20;0080;Server@node2;Job;12322.node2.supernodexp.hpc;Obit received momhop:1 serverhop:1 state:4 substate:42
04/24/2018 01:40:21;0010;Server@node2;Job;12322.node2.supernodexp.hpc;Exit_status=271 resources_used.cpupercent=0 resources_used.cput=00:00:00 resources_used.mem=9632kb resources_used.ncpus=8 resources_used.vmem=172216kb resources_used.walltime=00:07:20
04/24/2018 01:40:21;0100;Server@node2;Job;12322.node2.supernodexp.hpc;dequeuing from workq, state 5
04/24/2018 01:40:21;0040;Server@node2;Svr;node2.supernodexp.hpc;Scheduler sent command 2
04/24/2018 01:40:21;0040;Server@node2;Svr;node2.supernodexp.hpc;Scheduler sent command 0
04/24/2018 01:40:21;0100;Server@node2;Req;;Type 21 request received from Scheduler@node2.supernodexp.hpc, sock=16
04/24/2018 01:40:21;0100;Server@node2;Req;;Type 81 request received from Scheduler@node2.supernodexp.hpc, sock=16
04/24/2018 01:40:21;0100;Server@node2;Req;;Type 71 request received from Scheduler@node2.supernodexp.hpc, sock=16
04/24/2018 01:40:21;0100;Server@node2;Req;;Type 58 request received from Scheduler@node2.supernodexp.hpc, sock=16
04/24/2018 01:40:21;0100;Server@node2;Req;;Type 20 request received from Scheduler@node2.supernodexp.hpc, sock=16
04/24/2018 01:40:21;0100;Server@node2;Req;;Type 51 request received from Scheduler@node2.supernodexp.hpc, sock=16
04/24/2018 01:40:21;0100;Server@node2;Req;;Type 11 request received from Scheduler@node2.supernodexp.hpc, sock=16
04/24/2018 01:40:21;0008;Server@node2;Job;12344.node2.supernodexp.hpc;Job Modified at request of Scheduler@node2.supernodexp.hpc
04/24/2018 01:43:34;0080;Server@node2;Job;12335.node2.supernodexp.hpc;Obit received momhop:1 serverhop:1 state:4 substate:42
04/24/2018 01:43:35;0010;Server@node2;Job;12335.node2.supernodexp.hpc;Exit_status=271 resources_used.cpupercent=0 resources_used.cput=00:00:00 resources_used.mem=9872kb resources_used.ncpus=12 resources_used.vmem=103728kb resources_used.walltime=00:07:16
04/24/2018 01:43:35;0100;Server@node2;Job;12335.node2.supernodexp.hpc;dequeuing from workq, state 5
04/24/2018 01:43:35;0040;Server@node2;Svr;node2.supernodexp.hpc;Scheduler sent command 2
04/24/2018 01:43:35;0040;Server@node2;Svr;node2.supernodexp.hpc;Scheduler sent command 0
04/24/2018 01:43:35;0100;Server@node2;Req;;Type 21 request received from Scheduler@node2.supernodexp.hpc, sock=16
04/24/2018 01:43:35;0100;Server@node2;Req;;Type 81 request received from Scheduler@node2.supernodexp.hpc, sock=16
04/24/2018 01:43:35;0100;Server@node2;Req;;Type 71 request received from Scheduler@node2.supernodexp.hpc, sock=16
04/24/2018 01:43:35;0100;Server@node2;Req;;Type 58 request received from Scheduler@node2.supernodexp.hpc, sock=16
04/24/2018 01:43:35;0100;Server@node2;Req;;Type 20 request received from Scheduler@node2.supernodexp.hpc, sock=16
04/24/2018 01:43:35;0100;Server@node2;Req;;Type 51 request received from Scheduler@node2.supernodexp.hpc, sock=16
04/24/2018 01:43:36;0100;Server@node2;Req;;Type 23 request received from Scheduler@node2.supernodexp.hpc, sock=16
04/24/2018 01:43:36;0008;Server@node2;Job;12344.node2.supernodexp.hpc;Job Run at request of Scheduler@node2.supernodexp.hpc on exec_vnode (node14:ncpus=24:mem=5242880kb)
04/24/2018 01:43:36;0001;Server@node2;Svr;Server@node2;Success (0) in req_runjob2, return value of svr_startjob is 0
04/24/2018 01:43:36;0100;Server@node2;Req;;Type 11 request received from Scheduler@node2.supernodexp.hpc, sock=16
04/24/2018 01:43:36;0008;Server@node2;Job;12345.node2.supernodexp.hpc;Job Modified at request of Scheduler@node2.supernodexp.hpc
04/24/2018 01:43:43;0080;Server@node2;Job;12344.node2.supernodexp.hpc;Obit received momhop:1 serverhop:1 state:4 substate:42
04/24/2018 01:43:44;0010;Server@node2;Job;12344.node2.supernodexp.hpc;Exit_status=0 resources_used.cpupercent=0 resources_used.cput=00:00:00 resources_used.mem=0kb resources_used.ncpus=24 resources_used.vmem=0kb resources_used.walltime=00:00:08
04/24/2018 01:43:44;0100;Server@node2;Job;12344.node2.supernodexp.hpc;dequeuing from workq, state 5
04/24/2018 01:43:44;0040;Server@node2;Svr;node2.supernodexp.hpc;Scheduler sent command 2
04/24/2018 01:43:44;0040;Server@node2;Svr;node2.supernodexp.hpc;Scheduler sent command 0
04/24/2018 01:43:44;0100;Server@node2;Req;;Type 21 request received from Scheduler@node2.supernodexp.hpc, sock=16
04/24/2018 01:43:44;0100;Server@node2;Req;;Type 81 request received from Scheduler@node2.supernodexp.hpc, sock=16
04/24/2018 01:43:44;0100;Server@node2;Req;;Type 71 request received from Scheduler@node2.supernodexp.hpc, sock=16
04/24/2018 01:43:44;0100;Server@node2;Req;;Type 58 request received from Scheduler@node2.supernodexp.hpc, sock=16
04/24/2018 01:43:44;0100;Server@node2;Req;;Type 20 request received from Scheduler@node2.supernodexp.hpc, sock=16
04/24/2018 01:43:44;0100;Server@node2;Req;;Type 51 request received from Scheduler@node2.supernodexp.hpc, sock=16
04/24/2018 01:43:44;0100;Server@node2;Req;;Type 23 request received from Scheduler@node2.supernodexp.hpc, sock=16
04/24/2018 01:43:44;0008;Server@node2;Job;12345.node2.supernodexp.hpc;Job Run at request of Scheduler@node2.supernodexp.hpc on exec_vnode (node14:ncpus=8:mem=15728640kb)
04/24/2018 01:43:44;0001;Server@node2;Svr;Server@node2;Success (0) in req_runjob2, return value of svr_startjob is 0
04/24/2018 01:43:44;0100;Server@node2;Req;;Type 23 request received from Scheduler@node2.supernodexp.hpc, sock=16
04/24/2018 01:43:44;0008;Server@node2;Job;12346.node2.supernodexp.hpc;Job Run at request of Scheduler@node2.supernodexp.hpc on exec_vnode (node14:nmics=2:ncpus=2:mem=2097152kb)
04/24/2018 01:43:44;0001;Server@node2;Svr;Server@node2;Success (0) in req_runjob2, return value of svr_startjob is 0
04/24/2018 01:43:44;0100;Server@node2;Req;;Type 23 request received from Scheduler@node2.supernodexp.hpc, sock=16
04/24/2018 01:43:44;0008;Server@node2;Job;12347.node2.supernodexp.hpc;Job Run at request of Scheduler@node2.supernodexp.hpc on exec_vnode (node14:ncpus=8:mem=20971520kb)
04/24/2018 01:43:44;0001;Server@node2;Svr;Server@node2;Success (0) in req_runjob2, return value of svr_startjob is 0
04/24/2018 01:43:44;0100;Server@node2;Req;;Type 11 request received from Scheduler@node2.supernodexp.hpc, sock=16
04/24/2018 01:43:44;0008;Server@node2;Job;12348.node2.supernodexp.hpc;Job Modified at request of Scheduler@node2.supernodexp.hpc
04/24/2018 01:43:46;0080;Server@node2;Job;12343.node2.supernodexp.hpc;Obit received momhop:1 serverhop:1 state:4 substate:42
04/24/2018 01:43:47;0010;Server@node2;Job;12343.node2.supernodexp.hpc;Exit_status=0 resources_used.cpupercent=0 resources_used.cput=00:00:00 resources_used.mem=9336kb resources_used.ncpus=12 resources_used.vmem=104444kb resources_used.walltime=00:06:13
04/24/2018 01:43:47;0100;Server@node2;Job;12343.node2.supernodexp.hpc;dequeuing from workq, state 5
04/24/2018 01:43:47;0040;Server@node2;Svr;node2.supernodexp.hpc;Scheduler sent command 2
04/24/2018 01:43:47;0040;Server@node2;Svr;node2.supernodexp.hpc;Scheduler sent command 0
04/24/2018 01:43:47;0100;Server@node2;Req;;Type 21 request received from Scheduler@node2.supernodexp.hpc, sock=16
04/24/2018 01:43:47;0100;Server@node2;Req;;Type 81 request received from Scheduler@node2.supernodexp.hpc, sock=16
04/24/2018 01:43:47;0100;Server@node2;Req;;Type 71 request received from Scheduler@node2.supernodexp.hpc, sock=16
04/24/2018 01:43:47;0100;Server@node2;Req;;Type 58 request received from Scheduler@node2.supernodexp.hpc, sock=16
04/24/2018 01:43:47;0100;Server@node2;Req;;Type 20 request received from Scheduler@node2.supernodexp.hpc, sock=16
04/24/2018 01:43:47;0100;Server@node2;Req;;Type 51 request received from Scheduler@node2.supernodexp.hpc, sock=16
04/24/2018 01:43:49;0080;Server@node2;Job;12346.node2.supernodexp.hpc;Obit received momhop:1 serverhop:1 state:4 substate:42
04/24/2018 01:43:49;0080;Server@node2;Job;12347.node2.supernodexp.hpc;Obit received momhop:1 serverhop:1 state:4 substate:42
04/24/2018 01:43:50;0010;Server@node2;Job;12346.node2.supernodexp.hpc;Exit_status=0 resources_used.cpupercent=0 resources_used.cput=00:00:00 resources_used.mem=0kb resources_used.ncpus=2 resources_used.vmem=0kb resources_used.walltime=00:00:05
04/24/2018 01:43:50;0100;Server@node2;Job;12346.node2.supernodexp.hpc;dequeuing from workq, state 5
04/24/2018 01:43:50;0040;Server@node2;Svr;node2.supernodexp.hpc;Scheduler sent command 2
04/24/2018 01:43:50;0040;Server@node2;Svr;node2.supernodexp.hpc;Scheduler sent command 0
04/24/2018 01:43:50;0100;Server@node2;Req;;Type 21 request received from Scheduler@node2.supernodexp.hpc, sock=16
04/24/2018 01:43:50;0100;Server@node2;Req;;Type 81 request received from Scheduler@node2.supernodexp.hpc, sock=16
04/24/2018 01:43:50;0100;Server@node2;Req;;Type 71 request received from Scheduler@node2.supernodexp.hpc, sock=16
04/24/2018 01:43:50;0100;Server@node2;Req;;Type 58 request received from Scheduler@node2.supernodexp.hpc, sock=16
04/24/2018 01:43:50;0100;Server@node2;Req;;Type 20 request received from Scheduler@node2.supernodexp.hpc, sock=16
04/24/2018 01:43:50;0100;Server@node2;Req;;Type 51 request received from Scheduler@node2.supernodexp.hpc, sock=16
04/24/2018 01:43:50;0010;Server@node2;Job;12347.node2.supernodexp.hpc;Exit_status=0 resources_used.cpupercent=0 resources_used.cput=00:00:00 resources_used.mem=9824kb resources_used.ncpus=8 resources_used.vmem=106036kb resources_used.walltime=00:00:05
04/24/2018 01:43:50;0100;Server@node2;Job;12347.node2.supernodexp.hpc;dequeuing from workq, state 5
04/24/2018 01:43:50;0100;Server@node2;Req;;Type 23 request received from Scheduler@node2.supernodexp.hpc, sock=16
04/24/2018 01:43:50;0008;Server@node2;Job;12348.node2.supernodexp.hpc;Job Run at request of Scheduler@node2.supernodexp.hpc on exec_vnode (node14:nmics=2:ncpus=2:mem=41943040kb)
04/24/2018 01:43:50;0001;Server@node2;Svr;Server@node2;Success (0) in req_runjob2, return value of svr_startjob is 0
04/24/2018 01:43:50;0100;Server@node2;Req;;Type 23 request received from Scheduler@node2.supernodexp.hpc, sock=16
04/24/2018 01:43:50;0008;Server@node2;Job;12349.node2.supernodexp.hpc;Job Run at request of Scheduler@node2.supernodexp.hpc on exec_vnode (node3:ncpus=8:mem=5242880kb)
04/24/2018 01:43:50;0001;Server@node2;Svr;Server@node2;Success (0) in req_runjob2, return value of svr_startjob is 0
04/24/2018 01:43:50;0100;Server@node2;Req;;Type 11 request received from Scheduler@node2.supernodexp.hpc, sock=16
04/24/2018 01:43:50;0008;Server@node2;Job;12350.node2.supernodexp.hpc;Job Modified at request of Scheduler@node2.supernodexp.hpc
04/24/2018 01:43:50;0040;Server@node2;Svr;node2.supernodexp.hpc;Scheduler sent command 2
04/24/2018 01:43:50;0040;Server@node2;Svr;node2.supernodexp.hpc;Scheduler sent command 0
04/24/2018 01:43:50;0100;Server@node2;Req;;Type 21 request received from Scheduler@node2.supernodexp.hpc, sock=16
04/24/2018 01:43:50;0100;Server@node2;Req;;Type 81 request received from Scheduler@node2.supernodexp.hpc, sock=16
04/24/2018 01:43:50;0100;Server@node2;Req;;Type 71 request received from Scheduler@node2.supernodexp.hpc, sock=16
04/24/2018 01:43:50;0100;Server@node2;Req;;Type 58 request received from Scheduler@node2.supernodexp.hpc, sock=16
04/24/2018 01:43:50;0100;Server@node2;Req;;Type 20 request received from Scheduler@node2.supernodexp.hpc, sock=16
04/24/2018 01:43:50;0100;Server@node2;Req;;Type 51 request received from Scheduler@node2.supernodexp.hpc, sock=16
04/24/2018 01:44:10;0080;Server@node2;Job;12349.node2.supernodexp.hpc;Obit received momhop:1 serverhop:1 state:4 substate:42
04/24/2018 01:44:11;0010;Server@node2;Job;12349.node2.supernodexp.hpc;Exit_status=0 resources_used.cpupercent=0 resources_used.cput=00:00:00 resources_used.mem=9348kb resources_used.ncpus=8 resources_used.vmem=106496kb resources_used.walltime=00:00:20
04/24/2018 01:44:11;0100;Server@node2;Job;12349.node2.supernodexp.hpc;dequeuing from workq, state 5
04/24/2018 01:44:11;0040;Server@node2;Svr;node2.supernodexp.hpc;Scheduler sent command 2
04/24/2018 01:44:11;0040;Server@node2;Svr;node2.supernodexp.hpc;Scheduler sent command 0
04/24/2018 01:44:11;0100;Server@node2;Req;;Type 21 request received from Scheduler@node2.supernodexp.hpc, sock=16
04/24/2018 01:44:11;0100;Server@node2;Req;;Type 81 request received from Scheduler@node2.supernodexp.hpc, sock=16
04/24/2018 01:44:11;0100;Server@node2;Req;;Type 71 request received from Scheduler@node2.supernodexp.hpc, sock=16
04/24/2018 01:44:11;0100;Server@node2;Req;;Type 58 request received from Scheduler@node2.supernodexp.hpc, sock=16
04/24/2018 01:44:11;0100;Server@node2;Req;;Type 20 request received from Scheduler@node2.supernodexp.hpc, sock=16
04/24/2018 01:44:11;0100;Server@node2;Req;;Type 51 request received from Scheduler@node2.supernodexp.hpc, sock=16
04/24/2018 01:45:17;0080;Server@node2;Job;12318.node2.supernodexp.hpc;Obit received momhop:1 serverhop:1 state:4 substate:42
04/24/2018 01:45:18;0080;Server@node2;Job;12342.node2.supernodexp.hpc;Obit received momhop:1 serverhop:1 state:4 substate:42
04/24/2018 01:45:18;0010;Server@node2;Job;12318.node2.supernodexp.hpc;Exit_status=0 resources_used.cpupercent=0 resources_used.cput=00:00:00 resources_used.mem=10000kb resources_used.ncpus=12 resources_used.vmem=171316kb resources_used.walltime=00:19:09
04/24/2018 01:45:18;0100;Server@node2;Job;12318.node2.supernodexp.hpc;dequeuing from workq, state 5
04/24/2018 01:45:18;0040;Server@node2;Svr;node2.supernodexp.hpc;Scheduler sent command 2
04/24/2018 01:45:18;0040;Server@node2;Svr;node2.supernodexp.hpc;Scheduler sent command 0
04/24/2018 01:45:18;0100;Server@node2;Req;;Type 21 request received from Scheduler@node2.supernodexp.hpc, sock=16
04/24/2018 01:45:18;0100;Server@node2;Req;;Type 81 request received from Scheduler@node2.supernodexp.hpc, sock=16
04/24/2018 01:45:18;0100;Server@node2;Req;;Type 71 request received from Scheduler@node2.supernodexp.hpc, sock=16
04/24/2018 01:45:18;0100;Server@node2;Req;;Type 58 request received from Scheduler@node2.supernodexp.hpc, sock=16
04/24/2018 01:45:18;0100;Server@node2;Req;;Type 20 request received from Scheduler@node2.supernodexp.hpc, sock=16
04/24/2018 01:45:18;0100;Server@node2;Req;;Type 51 request received from Scheduler@node2.supernodexp.hpc, sock=16
04/24/2018 01:45:18;0010;Server@node2;Job;12342.node2.supernodexp.hpc;Exit_status=0 resources_used.cpupercent=0 resources_used.cput=00:00:00 resources_used.mem=9836kb resources_used.ncpus=12 resources_used.vmem=382288kb resources_used.walltime=00:08:18
04/24/2018 01:45:18;0100;Server@node2;Job;12342.node2.supernodexp.hpc;dequeuing from workq, state 5
04/24/2018 01:45:18;0040;Server@node2;Svr;node2.supernodexp.hpc;Scheduler sent command 2
04/24/2018 01:45:18;0040;Server@node2;Svr;node2.supernodexp.hpc;Scheduler sent command 0
04/24/2018 01:45:18;0100;Server@node2;Req;;Type 21 request received from Scheduler@node2.supernodexp.hpc, sock=16
04/24/2018 01:45:18;0100;Server@node2;Req;;Type 81 request received from Scheduler@node2.supernodexp.hpc, sock=16
04/24/2018 01:45:18;0100;Server@node2;Req;;Type 71 request received from Scheduler@node2.supernodexp.hpc, sock=16
04/24/2018 01:45:18;0100;Server@node2;Req;;Type 58 request received from Scheduler@node2.supernodexp.hpc, sock=16
04/24/2018 01:45:19;0100;Server@node2;Req;;Type 20 request received from Scheduler@node2.supernodexp.hpc, sock=16
04/24/2018 01:45:19;0100;Server@node2;Req;;Type 51 request received from Scheduler@node2.supernodexp.hpc, sock=16
04/24/2018 01:45:45;0080;Server@node2;Job;12319.node2.supernodexp.hpc;Obit received momhop:1 serverhop:1 state:4 substate:42
04/24/2018 01:45:46;0010;Server@node2;Job;12319.node2.supernodexp.hpc;Exit_status=0 resources_used.cpupercent=0 resources_used.cput=00:00:00 resources_used.mem=10016kb resources_used.ncpus=12 resources_used.vmem=172216kb resources_used.walltime=00:19:37
04/24/2018 01:45:46;0100;Server@node2;Job;12319.node2.supernodexp.hpc;dequeuing from workq, state 5
04/24/2018 01:45:46;0040;Server@node2;Svr;node2.supernodexp.hpc;Scheduler sent command 2
04/24/2018 01:45:46;0040;Server@node2;Svr;node2.supernodexp.hpc;Scheduler sent command 0
04/24/2018 01:45:46;0100;Server@node2;Req;;Type 21 request received from Scheduler@node2.supernodexp.hpc, sock=16
04/24/2018 01:45:46;0100;Server@node2;Req;;Type 81 request received from Scheduler@node2.supernodexp.hpc, sock=16
04/24/2018 01:45:46;0100;Server@node2;Req;;Type 71 request received from Scheduler@node2.supernodexp.hpc, sock=16
04/24/2018 01:45:46;0100;Server@node2;Req;;Type 58 request received from Scheduler@node2.supernodexp.hpc, sock=16
04/24/2018 01:45:46;0100;Server@node2;Req;;Type 20 request received from Scheduler@node2.supernodexp.hpc, sock=16
04/24/2018 01:45:46;0100;Server@node2;Req;;Type 51 request received from Scheduler@node2.supernodexp.hpc, sock=16
04/24/2018 01:45:50;0080;Server@node2;Job;12348.node2.supernodexp.hpc;Obit received momhop:1 serverhop:1 state:4 substate:42
04/24/2018 01:45:51;0010;Server@node2;Job;12348.node2.supernodexp.hpc;Exit_status=0 resources_used.cpupercent=0 resources_used.cput=00:00:00 resources_used.mem=9644kb resources_used.ncpus=2 resources_used.vmem=102320kb resources_used.walltime=00:02:00
04/24/2018 01:45:51;0100;Server@node2;Job;12348.node2.supernodexp.hpc;dequeuing from workq, state 5
04/24/2018 01:45:51;0040;Server@node2;Svr;node2.supernodexp.hpc;Scheduler sent command 2
04/24/2018 01:45:51;0040;Server@node2;Svr;node2.supernodexp.hpc;Scheduler sent command 0
04/24/2018 01:45:51;0100;Server@node2;Req;;Type 21 request received from Scheduler@node2.supernodexp.hpc, sock=16
04/24/2018 01:45:51;0100;Server@node2;Req;;Type 81 request received from Scheduler@node2.supernodexp.hpc, sock=16
04/24/2018 01:45:51;0100;Server@node2;Req;;Type 71 request received from Scheduler@node2.supernodexp.hpc, sock=16
04/24/2018 01:45:51;0100;Server@node2;Req;;Type 58 request received from Scheduler@node2.supernodexp.hpc, sock=16
04/24/2018 01:45:51;0100;Server@node2;Req;;Type 20 request received from Scheduler@node2.supernodexp.hpc, sock=16
04/24/2018 01:45:51;0100;Server@node2;Req;;Type 51 request received from Scheduler@node2.supernodexp.hpc, sock=16
04/24/2018 01:45:51;0100;Server@node2;Req;;Type 23 request received from Scheduler@node2.supernodexp.hpc, sock=16
04/24/2018 01:45:51;0008;Server@node2;Job;12350.node2.supernodexp.hpc;Job Run at request of Scheduler@node2.supernodexp.hpc on exec_vnode (node14:nmics=2:ncpus=2:mem=2097152kb)
04/24/2018 01:45:51;0001;Server@node2;Svr;Server@node2;Success (0) in req_runjob2, return value of svr_startjob is 0
04/24/2018 01:45:51;0100;Server@node2;Req;;Type 11 request received from Scheduler@node2.supernodexp.hpc, sock=16
04/24/2018 01:45:51;0008;Server@node2;Job;12351.node2.supernodexp.hpc;Job Modified at request of Scheduler@node2.supernodexp.hpc
04/24/2018 01:45:55;0080;Server@node2;Job;12350.node2.supernodexp.hpc;Obit received momhop:1 serverhop:1 state:4 substate:42
04/24/2018 01:45:56;0010;Server@node2;Job;12350.node2.supernodexp.hpc;Exit_status=0 resources_used.cpupercent=0 resources_used.cput=00:00:00 resources_used.mem=0kb resources_used.ncpus=2 resources_used.vmem=0kb resources_used.walltime=00:00:05
04/24/2018 01:45:56;0100;Server@node2;Job;12350.node2.supernodexp.hpc;dequeuing from workq, state 5
04/24/2018 01:45:56;0040;Server@node2;Svr;node2.supernodexp.hpc;Scheduler sent command 2
04/24/2018 01:45:56;0040;Server@node2;Svr;node2.supernodexp.hpc;Scheduler sent command 0
04/24/2018 01:45:56;0100;Server@node2;Req;;Type 21 request received from Scheduler@node2.supernodexp.hpc, sock=16
04/24/2018 01:45:56;0100;Server@node2;Req;;Type 81 request received from Scheduler@node2.supernodexp.hpc, sock=16
04/24/2018 01:45:56;0100;Server@node2;Req;;Type 71 request received from Scheduler@node2.supernodexp.hpc, sock=16
04/24/2018 01:45:56;0100;Server@node2;Req;;Type 58 request received from Scheduler@node2.supernodexp.hpc, sock=16
04/24/2018 01:45:56;0100;Server@node2;Req;;Type 20 request received from Scheduler@node2.supernodexp.hpc, sock=16
04/24/2018 01:45:56;0100;Server@node2;Req;;Type 51 request received from Scheduler@node2.supernodexp.hpc, sock=16
04/24/2018 01:45:56;0100;Server@node2;Req;;Type 23 request received from Scheduler@node2.supernodexp.hpc, sock=16
04/24/2018 01:45:56;0008;Server@node2;Job;12351.node2.supernodexp.hpc;Job Run at request of Scheduler@node2.supernodexp.hpc on exec_vnode (node14:nmics=2:ncpus=2:mem=41943040kb)
04/24/2018 01:45:56;0001;Server@node2;Svr;Server@node2;Success (0) in req_runjob2, return value of svr_startjob is 0
04/24/2018 01:45:56;0100;Server@node2;Req;;Type 23 request received from Scheduler@node2.supernodexp.hpc, sock=16
04/24/2018 01:45:56;0008;Server@node2;Job;12352.node2.supernodexp.hpc;Job Run at request of Scheduler@node2.supernodexp.hpc on exec_vnode (node3:ncpus=8:mem=3145728kb)
04/24/2018 01:45:56;0001;Server@node2;Svr;Server@node2;Success (0) in req_runjob2, return value of svr_startjob is 0
04/24/2018 01:45:56;0100;Server@node2;Req;;Type 23 request received from Scheduler@node2.supernodexp.hpc, sock=16
04/24/2018 01:45:56;0008;Server@node2;Job;12353.node2.supernodexp.hpc;Job Run at request of Scheduler@node2.supernodexp.hpc on exec_vnode (node3:ncpus=8:mem=20971520kb)
04/24/2018 01:45:56;0001;Server@node2;Svr;Server@node2;Success (0) in req_runjob2, return value of svr_startjob is 0
04/24/2018 01:45:56;0100;Server@node2;Req;;Type 11 request received from Scheduler@node2.supernodexp.hpc, sock=16
04/24/2018 01:45:56;0008;Server@node2;Job;12354.node2.supernodexp.hpc;Job Modified at request of Scheduler@node2.supernodexp.hpc
04/24/2018 01:46:04;0080;Server@node2;Job;12353.node2.supernodexp.hpc;Obit received momhop:1 serverhop:1 state:4 substate:42
04/24/2018 01:46:05;0010;Server@node2;Job;12353.node2.supernodexp.hpc;Exit_status=0 resources_used.cpupercent=0 resources_used.cput=00:00:00 resources_used.mem=0kb resources_used.ncpus=8 resources_used.vmem=0kb resources_used.walltime=00:00:09
04/24/2018 01:46:05;0100;Server@node2;Job;12353.node2.supernodexp.hpc;dequeuing from workq, state 5
04/24/2018 01:46:05;0040;Server@node2;Svr;node2.supernodexp.hpc;Scheduler sent command 2
04/24/2018 01:46:05;0040;Server@node2;Svr;node2.supernodexp.hpc;Scheduler sent command 0
04/24/2018 01:46:05;0100;Server@node2;Req;;Type 21 request received from Scheduler@node2.supernodexp.hpc, sock=16
04/24/2018 01:46:05;0100;Server@node2;Req;;Type 81 request received from Scheduler@node2.supernodexp.hpc, sock=16
04/24/2018 01:46:05;0100;Server@node2;Req;;Type 71 request received from Scheduler@node2.supernodexp.hpc, sock=16
04/24/2018 01:46:05;0100;Server@node2;Req;;Type 58 request received from Scheduler@node2.supernodexp.hpc, sock=16
04/24/2018 01:46:05;0100;Server@node2;Req;;Type 20 request received from Scheduler@node2.supernodexp.hpc, sock=16
04/24/2018 01:46:05;0100;Server@node2;Req;;Type 51 request received from Scheduler@node2.supernodexp.hpc, sock=16
04/24/2018 01:47:40;0080;Server@node2;Job;12351.node2.supernodexp.hpc;Obit received momhop:1 serverhop:1 state:4 substate:42
04/24/2018 01:47:41;0010;Server@node2;Job;12351.node2.supernodexp.hpc;Exit_status=0 resources_used.cpupercent=0 resources_used.cput=00:00:00 resources_used.mem=9420kb resources_used.ncpus=2 resources_used.vmem=102576kb resources_used.walltime=00:01:44
04/24/2018 01:47:41;0100;Server@node2;Job;12351.node2.supernodexp.hpc;dequeuing from workq, state 5
04/24/2018 01:47:41;0040;Server@node2;Svr;node2.supernodexp.hpc;Scheduler sent command 2
04/24/2018 01:47:41;0040;Server@node2;Svr;node2.supernodexp.hpc;Scheduler sent command 0
04/24/2018 01:47:41;0100;Server@node2;Req;;Type 21 request received from Scheduler@node2.supernodexp.hpc, sock=16
04/24/2018 01:47:41;0100;Server@node2;Req;;Type 81 request received from Scheduler@node2.supernodexp.hpc, sock=16
04/24/2018 01:47:41;0100;Server@node2;Req;;Type 71 request received from Scheduler@node2.supernodexp.hpc, sock=16
04/24/2018 01:47:41;0100;Server@node2;Req;;Type 58 request received from Scheduler@node2.supernodexp.hpc, sock=16
04/24/2018 01:47:41;0100;Server@node2;Req;;Type 20 request received from Scheduler@node2.supernodexp.hpc, sock=16
04/24/2018 01:47:41;0100;Server@node2;Req;;Type 51 request received from Scheduler@node2.supernodexp.hpc, sock=16
04/24/2018 01:47:41;0100;Server@node2;Req;;Type 23 request received from Scheduler@node2.supernodexp.hpc, sock=16
04/24/2018 01:47:41;0008;Server@node2;Job;12354.node2.supernodexp.hpc;Job Run at request of Scheduler@node2.supernodexp.hpc on exec_vnode (node14:ncpus=32:nmics=2:mem=31457280kb)
04/24/2018 01:47:41;0001;Server@node2;Svr;Server@node2;Success (0) in req_runjob2, return value of svr_startjob is 0
04/24/2018 01:47:41;0100;Server@node2;Req;;Type 11 request received from Scheduler@node2.supernodexp.hpc, sock=16
04/24/2018 01:47:41;0008;Server@node2;Job;12355.node2.supernodexp.hpc;Job Modified at request of Scheduler@node2.supernodexp.hpc
04/24/2018 01:51:17;0080;Server@node2;Job;12333.node2.supernodexp.hpc;Obit received momhop:1 serverhop:1 state:4 substate:42
04/24/2018 01:51:18;0010;Server@node2;Job;12333.node2.supernodexp.hpc;Exit_status=0 resources_used.cpupercent=0 resources_used.cput=00:00:00 resources_used.mem=9644kb resources_used.ncpus=12 resources_used.vmem=104372kb resources_used.walltime=00:14:57
04/24/2018 01:51:18;0100;Server@node2;Job;12333.node2.supernodexp.hpc;dequeuing from workq, state 5
04/24/2018 01:51:18;0040;Server@node2;Svr;node2.supernodexp.hpc;Scheduler sent command 2
04/24/2018 01:51:18;0040;Server@node2;Svr;node2.supernodexp.hpc;Scheduler sent command 0
04/24/2018 01:51:18;0100;Server@node2;Req;;Type 21 request received from Scheduler@node2.supernodexp.hpc, sock=16
04/24/2018 01:51:18;0100;Server@node2;Req;;Type 81 request received from Scheduler@node2.supernodexp.hpc, sock=16
04/24/2018 01:51:18;0100;Server@node2;Req;;Type 71 request received from Scheduler@node2.supernodexp.hpc, sock=16
04/24/2018 01:51:18;0100;Server@node2;Req;;Type 58 request received from Scheduler@node2.supernodexp.hpc, sock=16
04/24/2018 01:51:18;0100;Server@node2;Req;;Type 20 request received from Scheduler@node2.supernodexp.hpc, sock=16
04/24/2018 01:51:18;0100;Server@node2;Req;;Type 51 request received from Scheduler@node2.supernodexp.hpc, sock=16
04/24/2018 01:51:18;0100;Server@node2;Req;;Type 23 request received from Scheduler@node2.supernodexp.hpc, sock=16
04/24/2018 01:51:18;0008;Server@node2;Job;12355.node2.supernodexp.hpc;Job Run at request of Scheduler@node2.supernodexp.hpc on exec_vnode (node13:ncpus=24:mem=5242880kb)
04/24/2018 01:51:18;0001;Server@node2;Svr;Server@node2;Success (0) in req_runjob2, return value of svr_startjob is 0
04/24/2018 01:51:18;0100;Server@node2;Req;;Type 23 request received from Scheduler@node2.supernodexp.hpc, sock=16
04/24/2018 01:51:18;0008;Server@node2;Job;12356.node2.supernodexp.hpc;Job Run at request of Scheduler@node2.supernodexp.hpc on exec_vnode (node3:ncpus=8:mem=3145728kb)
04/24/2018 01:51:18;0001;Server@node2;Svr;Server@node2;Success (0) in req_runjob2, return value of svr_startjob is 0
04/24/2018 01:51:18;0100;Server@node2;Req;;Type 11 request received from Scheduler@node2.supernodexp.hpc, sock=16
04/24/2018 01:51:18;0008;Server@node2;Job;12357.node2.supernodexp.hpc;Job Modified at request of Scheduler@node2.supernodexp.hpc
04/24/2018 01:52:39;0080;Server@node2;Job;12352.node2.supernodexp.hpc;Obit received momhop:1 serverhop:1 state:4 substate:42
04/24/2018 01:52:40;0010;Server@node2;Job;12352.node2.supernodexp.hpc;Exit_status=271 resources_used.cpupercent=0 resources_used.cput=00:00:00 resources_used.mem=9104kb resources_used.ncpus=8 resources_used.vmem=103292kb resources_used.walltime=00:06:44
04/24/2018 01:52:40;0100;Server@node2;Job;12352.node2.supernodexp.hpc;dequeuing from workq, state 5
04/24/2018 01:52:40;0040;Server@node2;Svr;node2.supernodexp.hpc;Scheduler sent command 2
04/24/2018 01:52:40;0040;Server@node2;Svr;node2.supernodexp.hpc;Scheduler sent command 0
04/24/2018 01:52:40;0100;Server@node2;Req;;Type 21 request received from Scheduler@node2.supernodexp.hpc, sock=16
04/24/2018 01:52:40;0100;Server@node2;Req;;Type 81 request received from Scheduler@node2.supernodexp.hpc, sock=16
04/24/2018 01:52:40;0100;Server@node2;Req;;Type 71 request received from Scheduler@node2.supernodexp.hpc, sock=16
04/24/2018 01:52:40;0100;Server@node2;Req;;Type 58 request received from Scheduler@node2.supernodexp.hpc, sock=16
04/24/2018 01:52:40;0100;Server@node2;Req;;Type 20 request received from Scheduler@node2.supernodexp.hpc, sock=16
04/24/2018 01:52:40;0100;Server@node2;Req;;Type 51 request received from Scheduler@node2.supernodexp.hpc, sock=16
04/24/2018 01:52:40;0100;Server@node2;Req;;Type 11 request received from Scheduler@node2.supernodexp.hpc, sock=16
04/24/2018 01:52:40;0008;Server@node2;Job;12357.node2.supernodexp.hpc;Job Modified at request of Scheduler@node2.supernodexp.hpc
04/24/2018 01:53:18;0080;Server@node2;Job;12338.node2.supernodexp.hpc;Obit received momhop:1 serverhop:1 state:4 substate:42
04/24/2018 01:53:19;0010;Server@node2;Job;12338.node2.supernodexp.hpc;Exit_status=0 resources_used.cpupercent=0 resources_used.cput=00:00:00 resources_used.mem=9648kb resources_used.ncpus=8 resources_used.vmem=104628kb resources_used.walltime=00:16:59
04/24/2018 01:53:19;0100;Server@node2;Job;12338.node2.supernodexp.hpc;dequeuing from workq, state 5
04/24/2018 01:53:19;0040;Server@node2;Svr;node2.supernodexp.hpc;Scheduler sent command 2
04/24/2018 01:53:19;0040;Server@node2;Svr;node2.supernodexp.hpc;Scheduler sent command 0
04/24/2018 01:53:19;0100;Server@node2;Req;;Type 21 request received from Scheduler@node2.supernodexp.hpc, sock=16
04/24/2018 01:53:19;0100;Server@node2;Req;;Type 81 request received from Scheduler@node2.supernodexp.hpc, sock=16
04/24/2018 01:53:19;0100;Server@node2;Req;;Type 71 request received from Scheduler@node2.supernodexp.hpc, sock=16
04/24/2018 01:53:19;0100;Server@node2;Req;;Type 58 request received from Scheduler@node2.supernodexp.hpc, sock=16
04/24/2018 01:53:19;0100;Server@node2;Req;;Type 20 request received from Scheduler@node2.supernodexp.hpc, sock=16
04/24/2018 01:53:19;0100;Server@node2;Req;;Type 51 request received from Scheduler@node2.supernodexp.hpc, sock=16
04/24/2018 01:53:19;0100;Server@node2;Req;;Type 11 request received from Scheduler@node2.supernodexp.hpc, sock=16
04/24/2018 01:53:19;0008;Server@node2;Job;12357.node2.supernodexp.hpc;Job Modified at request of Scheduler@node2.supernodexp.hpc
04/24/2018 01:54:43;0080;Server@node2;Job;12320.node2.supernodexp.hpc;Obit received momhop:1 serverhop:1 state:4 substate:42
04/24/2018 01:54:44;0010;Server@node2;Job;12320.node2.supernodexp.hpc;Exit_status=2 resources_used.cpupercent=0 resources_used.cput=00:00:00 resources_used.mem=9432kb resources_used.ncpus=32 resources_used.vmem=103292kb resources_used.walltime=00:21:42
04/24/2018 01:54:44;0100;Server@node2;Job;12320.node2.supernodexp.hpc;dequeuing from workq, state 5
04/24/2018 01:54:44;0040;Server@node2;Svr;node2.supernodexp.hpc;Scheduler sent command 2
04/24/2018 01:54:44;0040;Server@node2;Svr;node2.supernodexp.hpc;Scheduler sent command 0
04/24/2018 01:54:44;0100;Server@node2;Req;;Type 21 request received from Scheduler@node2.supernodexp.hpc, sock=16
04/24/2018 01:54:44;0100;Server@node2;Req;;Type 81 request received from Scheduler@node2.supernodexp.hpc, sock=16
04/24/2018 01:54:44;0100;Server@node2;Req;;Type 71 request received from Scheduler@node2.supernodexp.hpc, sock=16
04/24/2018 01:54:44;0100;Server@node2;Req;;Type 58 request received from Scheduler@node2.supernodexp.hpc, sock=16
04/24/2018 01:54:44;0100;Server@node2;Req;;Type 20 request received from Scheduler@node2.supernodexp.hpc, sock=16
04/24/2018 01:54:44;0100;Server@node2;Req;;Type 51 request received from Scheduler@node2.supernodexp.hpc, sock=16
04/24/2018 01:54:44;0100;Server@node2;Req;;Type 23 request received from Scheduler@node2.supernodexp.hpc, sock=16
04/24/2018 01:54:44;0008;Server@node2;Job;12357.node2.supernodexp.hpc;Job Run at request of Scheduler@node2.supernodexp.hpc on exec_vnode (node3:ncpus=32:nmics=2:mem=31457280kb)
04/24/2018 01:54:44;0001;Server@node2;Svr;Server@node2;Success (0) in req_runjob2, return value of svr_startjob is 0
04/24/2018 01:54:44;0100;Server@node2;Req;;Type 23 request received from Scheduler@node2.supernodexp.hpc, sock=16
04/24/2018 01:54:44;0008;Server@node2;Job;12358.node2.supernodexp.hpc;Job Run at request of Scheduler@node2.supernodexp.hpc on exec_vnode (node3:ncpus=8:mem=20971520kb)
04/24/2018 01:54:44;0001;Server@node2;Svr;Server@node2;Success (0) in req_runjob2, return value of svr_startjob is 0
04/24/2018 01:54:44;0100;Server@node2;Req;;Type 23 request received from Scheduler@node2.supernodexp.hpc, sock=16
04/24/2018 01:54:44;0008;Server@node2;Job;12359.node2.supernodexp.hpc;Job Run at request of Scheduler@node2.supernodexp.hpc on exec_vnode (node13:ncpus=12:mem=5242880kb)
04/24/2018 01:54:44;0001;Server@node2;Svr;Server@node2;Success (0) in req_runjob2, return value of svr_startjob is 0
04/24/2018 01:54:44;0100;Server@node2;Req;;Type 23 request received from Scheduler@node2.supernodexp.hpc, sock=16
04/24/2018 01:54:44;0008;Server@node2;Job;12360.node2.supernodexp.hpc;Job Run at request of Scheduler@node2.supernodexp.hpc on exec_vnode (node14:ncpus=8:mem=10485760kb)
04/24/2018 01:54:44;0001;Server@node2;Svr;Server@node2;Success (0) in req_runjob2, return value of svr_startjob is 0
04/24/2018 01:54:44;0100;Server@node2;Req;;Type 11 request received from Scheduler@node2.supernodexp.hpc, sock=16
04/24/2018 01:54:44;0008;Server@node2;Job;12361.node2.supernodexp.hpc;Job Modified at request of Scheduler@node2.supernodexp.hpc
04/24/2018 01:55:23;0080;Server@node2;Job;12360.node2.supernodexp.hpc;Obit received momhop:1 serverhop:1 state:4 substate:42
04/24/2018 01:55:24;0010;Server@node2;Job;12360.node2.supernodexp.hpc;Exit_status=0 resources_used.cpupercent=0 resources_used.cput=00:00:00 resources_used.mem=9636kb resources_used.ncpus=8 resources_used.vmem=172216kb resources_used.walltime=00:00:39
04/24/2018 01:55:24;0100;Server@node2;Job;12360.node2.supernodexp.hpc;dequeuing from workq, state 5
04/24/2018 01:55:24;0040;Server@node2;Svr;node2.supernodexp.hpc;Scheduler sent command 2
04/24/2018 01:55:24;0040;Server@node2;Svr;node2.supernodexp.hpc;Scheduler sent command 0
04/24/2018 01:55:24;0100;Server@node2;Req;;Type 21 request received from Scheduler@node2.supernodexp.hpc, sock=16
04/24/2018 01:55:24;0100;Server@node2;Req;;Type 81 request received from Scheduler@node2.supernodexp.hpc, sock=16
04/24/2018 01:55:24;0100;Server@node2;Req;;Type 71 request received from Scheduler@node2.supernodexp.hpc, sock=16
04/24/2018 01:55:24;0100;Server@node2;Req;;Type 58 request received from Scheduler@node2.supernodexp.hpc, sock=16
04/24/2018 01:55:24;0100;Server@node2;Req;;Type 20 request received from Scheduler@node2.supernodexp.hpc, sock=16
04/24/2018 01:55:24;0100;Server@node2;Req;;Type 51 request received from Scheduler@node2.supernodexp.hpc, sock=16
04/24/2018 01:55:24;0100;Server@node2;Req;;Type 11 request received from Scheduler@node2.supernodexp.hpc, sock=16
04/24/2018 01:55:24;0008;Server@node2;Job;12361.node2.supernodexp.hpc;Job Modified at request of Scheduler@node2.supernodexp.hpc
04/24/2018 01:55:33;0080;Server@node2;Job;12358.node2.supernodexp.hpc;Obit received momhop:1 serverhop:1 state:4 substate:42
04/24/2018 01:55:34;0010;Server@node2;Job;12358.node2.supernodexp.hpc;Exit_status=0 resources_used.cpupercent=0 resources_used.cput=00:00:00 resources_used.mem=9096kb resources_used.ncpus=8 resources_used.vmem=103036kb resources_used.walltime=00:00:49
04/24/2018 01:55:34;0100;Server@node2;Job;12358.node2.supernodexp.hpc;dequeuing from workq, state 5
04/24/2018 01:55:34;0040;Server@node2;Svr;node2.supernodexp.hpc;Scheduler sent command 2
04/24/2018 01:55:34;0040;Server@node2;Svr;node2.supernodexp.hpc;Scheduler sent command 0
04/24/2018 01:55:34;0100;Server@node2;Req;;Type 21 request received from Scheduler@node2.supernodexp.hpc, sock=16
04/24/2018 01:55:34;0100;Server@node2;Req;;Type 81 request received from Scheduler@node2.supernodexp.hpc, sock=16
04/24/2018 01:55:34;0100;Server@node2;Req;;Type 71 request received from Scheduler@node2.supernodexp.hpc, sock=16
04/24/2018 01:55:34;0100;Server@node2;Req;;Type 58 request received from Scheduler@node2.supernodexp.hpc, sock=16
04/24/2018 01:55:34;0100;Server@node2;Req;;Type 20 request received from Scheduler@node2.supernodexp.hpc, sock=16
04/24/2018 01:55:34;0100;Server@node2;Req;;Type 51 request received from Scheduler@node2.supernodexp.hpc, sock=16
04/24/2018 01:55:34;0100;Server@node2;Req;;Type 11 request received from Scheduler@node2.supernodexp.hpc, sock=16
04/24/2018 01:55:34;0008;Server@node2;Job;12361.node2.supernodexp.hpc;Job Modified at request of Scheduler@node2.supernodexp.hpc
04/24/2018 01:56:33;0080;Server@node2;Job;12345.node2.supernodexp.hpc;Obit received momhop:1 serverhop:1 state:4 substate:42
04/24/2018 01:56:34;0010;Server@node2;Job;12345.node2.supernodexp.hpc;Exit_status=0 resources_used.cpupercent=0 resources_used.cput=00:00:00 resources_used.mem=10292kb resources_used.ncpus=8 resources_used.vmem=531212kb resources_used.walltime=00:12:49
04/24/2018 01:56:34;0100;Server@node2;Job;12345.node2.supernodexp.hpc;dequeuing from workq, state 5
04/24/2018 01:56:34;0040;Server@node2;Svr;node2.supernodexp.hpc;Scheduler sent command 2
04/24/2018 01:56:34;0040;Server@node2;Svr;node2.supernodexp.hpc;Scheduler sent command 0
04/24/2018 01:56:34;0100;Server@node2;Req;;Type 21 request received from Scheduler@node2.supernodexp.hpc, sock=16
04/24/2018 01:56:34;0100;Server@node2;Req;;Type 81 request received from Scheduler@node2.supernodexp.hpc, sock=16
04/24/2018 01:56:34;0100;Server@node2;Req;;Type 71 request received from Scheduler@node2.supernodexp.hpc, sock=16
04/24/2018 01:56:34;0100;Server@node2;Req;;Type 58 request received from Scheduler@node2.supernodexp.hpc, sock=16
04/24/2018 01:56:34;0100;Server@node2;Req;;Type 20 request received from Scheduler@node2.supernodexp.hpc, sock=16
04/24/2018 01:56:34;0100;Server@node2;Req;;Type 51 request received from Scheduler@node2.supernodexp.hpc, sock=16
04/24/2018 01:56:34;0100;Server@node2;Req;;Type 23 request received from Scheduler@node2.supernodexp.hpc, sock=16
04/24/2018 01:56:34;0008;Server@node2;Job;12361.node2.supernodexp.hpc;Job Run at request of Scheduler@node2.supernodexp.hpc on exec_vnode (node14:ncpus=12:mem=5242880kb)
04/24/2018 01:56:34;0001;Server@node2;Svr;Server@node2;Success (0) in req_runjob2, return value of svr_startjob is 0
04/24/2018 01:56:34;0100;Server@node2;Req;;Type 11 request received from Scheduler@node2.supernodexp.hpc, sock=16
04/24/2018 01:56:34;0008;Server@node2;Job;12362.node2.supernodexp.hpc;Job Modified at request of Scheduler@node2.supernodexp.hpc
04/24/2018 01:56:52;0080;Server@node2;Job;12355.node2.supernodexp.hpc;Obit received momhop:1 serverhop:1 state:4 substate:42
04/24/2018 01:56:53;0010;Server@node2;Job;12355.node2.supernodexp.hpc;Exit_status=0 resources_used.cpupercent=0 resources_used.cput=00:00:00 resources_used.mem=9644kb resources_used.ncpus=24 resources_used.vmem=172216kb resources_used.walltime=00:05:34
04/24/2018 01:56:53;0100;Server@node2;Job;12355.node2.supernodexp.hpc;dequeuing from workq, state 5
04/24/2018 01:56:53;0040;Server@node2;Svr;node2.supernodexp.hpc;Scheduler sent command 2
04/24/2018 01:56:53;0040;Server@node2;Svr;node2.supernodexp.hpc;Scheduler sent command 0
04/24/2018 01:56:53;0100;Server@node2;Req;;Type 21 request received from Scheduler@node2.supernodexp.hpc, sock=16
04/24/2018 01:56:53;0100;Server@node2;Req;;Type 81 request received from Scheduler@node2.supernodexp.hpc, sock=16
04/24/2018 01:56:53;0100;Server@node2;Req;;Type 71 request received from Scheduler@node2.supernodexp.hpc, sock=16
04/24/2018 01:56:53;0100;Server@node2;Req;;Type 58 request received from Scheduler@node2.supernodexp.hpc, sock=16
04/24/2018 01:56:53;0100;Server@node2;Req;;Type 20 request received from Scheduler@node2.supernodexp.hpc, sock=16
04/24/2018 01:56:53;0100;Server@node2;Req;;Type 51 request received from Scheduler@node2.supernodexp.hpc, sock=16
04/24/2018 01:56:53;0100;Server@node2;Req;;Type 11 request received from Scheduler@node2.supernodexp.hpc, sock=16
04/24/2018 01:56:53;0008;Server@node2;Job;12362.node2.supernodexp.hpc;Job Modified at request of Scheduler@node2.supernodexp.hpc
04/24/2018 01:57:07;0080;Server@node2;Job;12336.node2.supernodexp.hpc;Obit received momhop:1 serverhop:1 state:4 substate:42
04/24/2018 01:57:08;0010;Server@node2;Job;12336.node2.supernodexp.hpc;Exit_status=0 resources_used.cpupercent=0 resources_used.cput=00:00:00 resources_used.mem=9628kb resources_used.ncpus=12 resources_used.vmem=104628kb resources_used.walltime=00:20:47
04/24/2018 01:57:08;0100;Server@node2;Job;12336.node2.supernodexp.hpc;dequeuing from workq, state 5
04/24/2018 01:57:08;0040;Server@node2;Svr;node2.supernodexp.hpc;Scheduler sent command 2
04/24/2018 01:57:08;0040;Server@node2;Svr;node2.supernodexp.hpc;Scheduler sent command 0
04/24/2018 01:57:08;0100;Server@node2;Req;;Type 21 request received from Scheduler@node2.supernodexp.hpc, sock=16
04/24/2018 01:57:08;0100;Server@node2;Req;;Type 81 request received from Scheduler@node2.supernodexp.hpc, sock=16
04/24/2018 01:57:08;0100;Server@node2;Req;;Type 71 request received from Scheduler@node2.supernodexp.hpc, sock=16
04/24/2018 01:57:08;0100;Server@node2;Req;;Type 58 request received from Scheduler@node2.supernodexp.hpc, sock=16
04/24/2018 01:57:08;0100;Server@node2;Req;;Type 20 request received from Scheduler@node2.supernodexp.hpc, sock=16
04/24/2018 01:57:08;0100;Server@node2;Req;;Type 51 request received from Scheduler@node2.supernodexp.hpc, sock=16
04/24/2018 01:57:08;0100;Server@node2;Req;;Type 23 request received from Scheduler@node2.supernodexp.hpc, sock=16
04/24/2018 01:57:08;0008;Server@node2;Job;12362.node2.supernodexp.hpc;Job Run at request of Scheduler@node2.supernodexp.hpc on exec_vnode (node13:ncpus=32:nmics=2:mem=31457280kb)
04/24/2018 01:57:08;0001;Server@node2;Svr;Server@node2;Success (0) in req_runjob2, return value of svr_startjob is 0
04/24/2018 01:57:08;0100;Server@node2;Req;;Type 23 request received from Scheduler@node2.supernodexp.hpc, sock=16
04/24/2018 01:57:08;0008;Server@node2;Job;12363.node2.supernodexp.hpc;Job Run at request of Scheduler@node2.supernodexp.hpc on exec_vnode (node3:ncpus=4:mem=5242880kb)
04/24/2018 01:57:08;0001;Server@node2;Svr;Server@node2;Success (0) in req_runjob2, return value of svr_startjob is 0
04/24/2018 01:57:08;0100;Server@node2;Req;;Type 11 request received from Scheduler@node2.supernodexp.hpc, sock=16
04/24/2018 01:57:08;0008;Server@node2;Job;12364.node2.supernodexp.hpc;Job Modified at request of Scheduler@node2.supernodexp.hpc
04/24/2018 01:57:26;0080;Server@node2;Job;12363.node2.supernodexp.hpc;Obit received momhop:1 serverhop:1 state:4 substate:42
04/24/2018 01:57:27;0010;Server@node2;Job;12363.node2.supernodexp.hpc;Exit_status=0 resources_used.cpupercent=0 resources_used.cput=00:00:00 resources_used.mem=9092kb resources_used.ncpus=4 resources_used.vmem=105088kb resources_used.walltime=00:00:19
04/24/2018 01:57:27;0100;Server@node2;Job;12363.node2.supernodexp.hpc;dequeuing from workq, state 5
04/24/2018 01:57:27;0040;Server@node2;Svr;node2.supernodexp.hpc;Scheduler sent command 2
04/24/2018 01:57:27;0040;Server@node2;Svr;node2.supernodexp.hpc;Scheduler sent command 0
04/24/2018 01:57:27;0100;Server@node2;Req;;Type 21 request received from Scheduler@node2.supernodexp.hpc, sock=16
04/24/2018 01:57:27;0100;Server@node2;Req;;Type 81 request received from Scheduler@node2.supernodexp.hpc, sock=16
04/24/2018 01:57:27;0100;Server@node2;Req;;Type 71 request received from Scheduler@node2.supernodexp.hpc, sock=16
04/24/2018 01:57:27;0100;Server@node2;Req;;Type 58 request received from Scheduler@node2.supernodexp.hpc, sock=16
04/24/2018 01:57:27;0100;Server@node2;Req;;Type 20 request received from Scheduler@node2.supernodexp.hpc, sock=16
04/24/2018 01:57:27;0100;Server@node2;Req;;Type 51 request received from Scheduler@node2.supernodexp.hpc, sock=16
04/24/2018 01:57:27;0100;Server@node2;Req;;Type 23 request received from Scheduler@node2.supernodexp.hpc, sock=16
04/24/2018 01:57:27;0008;Server@node2;Job;12364.node2.supernodexp.hpc;Job Run at request of Scheduler@node2.supernodexp.hpc on exec_vnode (node3:ncpus=8:mem=10485760kb)
04/24/2018 01:57:27;0001;Server@node2;Svr;Server@node2;Success (0) in req_runjob2, return value of svr_startjob is 0
04/24/2018 01:57:27;0100;Server@node2;Req;;Type 23 request received from Scheduler@node2.supernodexp.hpc, sock=16
04/24/2018 01:57:27;0008;Server@node2;Job;12365.node2.supernodexp.hpc;Job Run at request of Scheduler@node2.supernodexp.hpc on exec_vnode (node14:ncpus=4:mem=5242880kb)
04/24/2018 01:57:27;0001;Server@node2;Svr;Server@node2;Success (0) in req_runjob2, return value of svr_startjob is 0
04/24/2018 01:57:27;0100;Server@node2;Req;;Type 11 request received from Scheduler@node2.supernodexp.hpc, sock=16
04/24/2018 01:57:27;0008;Server@node2;Job;12366.node2.supernodexp.hpc;Job Modified at request of Scheduler@node2.supernodexp.hpc
04/24/2018 01:57:48;0080;Server@node2;Job;12365.node2.supernodexp.hpc;Obit received momhop:1 serverhop:1 state:4 substate:42
04/24/2018 01:57:49;0010;Server@node2;Job;12365.node2.supernodexp.hpc;Exit_status=0 resources_used.cpupercent=0 resources_used.cput=00:00:00 resources_used.mem=9420kb resources_used.ncpus=4 resources_used.vmem=172216kb resources_used.walltime=00:00:21
04/24/2018 01:57:49;0100;Server@node2;Job;12365.node2.supernodexp.hpc;dequeuing from workq, state 5
04/24/2018 01:57:49;0040;Server@node2;Svr;node2.supernodexp.hpc;Scheduler sent command 2
04/24/2018 01:57:49;0040;Server@node2;Svr;node2.supernodexp.hpc;Scheduler sent command 0
04/24/2018 01:57:49;0100;Server@node2;Req;;Type 21 request received from Scheduler@node2.supernodexp.hpc, sock=16
04/24/2018 01:57:49;0100;Server@node2;Req;;Type 81 request received from Scheduler@node2.supernodexp.hpc, sock=16
04/24/2018 01:57:49;0100;Server@node2;Req;;Type 71 request received from Scheduler@node2.supernodexp.hpc, sock=16
04/24/2018 01:57:49;0100;Server@node2;Req;;Type 58 request received from Scheduler@node2.supernodexp.hpc, sock=16
04/24/2018 01:57:49;0100;Server@node2;Req;;Type 20 request received from Scheduler@node2.supernodexp.hpc, sock=16
04/24/2018 01:57:49;0100;Server@node2;Req;;Type 51 request received from Scheduler@node2.supernodexp.hpc, sock=16
04/24/2018 01:57:49;0100;Server@node2;Req;;Type 11 request received from Scheduler@node2.supernodexp.hpc, sock=16
04/24/2018 01:57:49;0008;Server@node2;Job;12366.node2.supernodexp.hpc;Job Modified at request of Scheduler@node2.supernodexp.hpc
04/24/2018 01:58:01;0080;Server@node2;Job;12356.node2.supernodexp.hpc;Obit received momhop:1 serverhop:1 state:4 substate:42
04/24/2018 01:58:02;0010;Server@node2;Job;12356.node2.supernodexp.hpc;Exit_status=0 resources_used.cpupercent=0 resources_used.cput=00:00:00 resources_used.mem=11400kb resources_used.ncpus=8 resources_used.vmem=172288kb resources_used.walltime=00:06:43
04/24/2018 01:58:02;0100;Server@node2;Job;12356.node2.supernodexp.hpc;dequeuing from workq, state 5
04/24/2018 01:58:02;0040;Server@node2;Svr;node2.supernodexp.hpc;Scheduler sent command 2
04/24/2018 01:58:02;0040;Server@node2;Svr;node2.supernodexp.hpc;Scheduler sent command 0
04/24/2018 01:58:02;0100;Server@node2;Req;;Type 21 request received from Scheduler@node2.supernodexp.hpc, sock=16
04/24/2018 01:58:02;0100;Server@node2;Req;;Type 81 request received from Scheduler@node2.supernodexp.hpc, sock=16
04/24/2018 01:58:02;0100;Server@node2;Req;;Type 71 request received from Scheduler@node2.supernodexp.hpc, sock=16
04/24/2018 01:58:02;0100;Server@node2;Req;;Type 58 request received from Scheduler@node2.supernodexp.hpc, sock=16
04/24/2018 01:58:02;0100;Server@node2;Req;;Type 20 request received from Scheduler@node2.supernodexp.hpc, sock=16
04/24/2018 01:58:02;0100;Server@node2;Req;;Type 51 request received from Scheduler@node2.supernodexp.hpc, sock=16
04/24/2018 01:58:02;0100;Server@node2;Req;;Type 23 request received from Scheduler@node2.supernodexp.hpc, sock=16
04/24/2018 01:58:02;0008;Server@node2;Job;12366.node2.supernodexp.hpc;Job Run at request of Scheduler@node2.supernodexp.hpc on exec_vnode (node3:ncpus=8:mem=5242880kb)
04/24/2018 01:58:02;0001;Server@node2;Svr;Server@node2;Success (0) in req_runjob2, return value of svr_startjob is 0
04/24/2018 01:58:02;0100;Server@node2;Req;;Type 11 request received from Scheduler@node2.supernodexp.hpc, sock=16
04/24/2018 01:58:02;0008;Server@node2;Job;12367.node2.supernodexp.hpc;Job Modified at request of Scheduler@node2.supernodexp.hpc
04/24/2018 01:58:05;0080;Server@node2;Job;12364.node2.supernodexp.hpc;Obit received momhop:1 serverhop:1 state:4 substate:42
04/24/2018 01:58:06;0010;Server@node2;Job;12364.node2.supernodexp.hpc;Exit_status=0 resources_used.cpupercent=0 resources_used.cput=00:00:00 resources_used.mem=9096kb resources_used.ncpus=8 resources_used.vmem=105344kb resources_used.walltime=00:00:38
04/24/2018 01:58:06;0100;Server@node2;Job;12364.node2.supernodexp.hpc;dequeuing from workq, state 5
04/24/2018 01:58:06;0040;Server@node2;Svr;node2.supernodexp.hpc;Scheduler sent command 2
04/24/2018 01:58:06;0040;Server@node2;Svr;node2.supernodexp.hpc;Scheduler sent command 0
04/24/2018 01:58:06;0100;Server@node2;Req;;Type 21 request received from Scheduler@node2.supernodexp.hpc, sock=16
04/24/2018 01:58:06;0100;Server@node2;Req;;Type 81 request received from Scheduler@node2.supernodexp.hpc, sock=16
04/24/2018 01:58:06;0100;Server@node2;Req;;Type 71 request received from Scheduler@node2.supernodexp.hpc, sock=16
04/24/2018 01:58:06;0100;Server@node2;Req;;Type 58 request received from Scheduler@node2.supernodexp.hpc, sock=16
04/24/2018 01:58:06;0100;Server@node2;Req;;Type 20 request received from Scheduler@node2.supernodexp.hpc, sock=16
04/24/2018 01:58:06;0100;Server@node2;Req;;Type 51 request received from Scheduler@node2.supernodexp.hpc, sock=16
04/24/2018 01:58:06;0100;Server@node2;Req;;Type 23 request received from Scheduler@node2.supernodexp.hpc, sock=16
04/24/2018 01:58:06;0008;Server@node2;Job;12367.node2.supernodexp.hpc;Job Run at request of Scheduler@node2.supernodexp.hpc on exec_vnode (node3:ncpus=8:mem=20971520kb)
04/24/2018 01:58:06;0001;Server@node2;Svr;Server@node2;Success (0) in req_runjob2, return value of svr_startjob is 0
04/24/2018 01:58:06;0100;Server@node2;Req;;Type 23 request received from Scheduler@node2.supernodexp.hpc, sock=16
04/24/2018 01:58:06;0008;Server@node2;Job;12368.node2.supernodexp.hpc;Job Run at request of Scheduler@node2.supernodexp.hpc on exec_vnode (node14:ncpus=4:mem=5242880kb)
04/24/2018 01:58:06;0001;Server@node2;Svr;Server@node2;Success (0) in req_runjob2, return value of svr_startjob is 0
04/24/2018 01:58:06;0100;Server@node2;Req;;Type 11 request received from Scheduler@node2.supernodexp.hpc, sock=16
04/24/2018 01:58:06;0008;Server@node2;Job;12369.node2.supernodexp.hpc;Job Modified at request of Scheduler@node2.supernodexp.hpc
04/24/2018 01:58:13;0080;Server@node2;Job;12367.node2.supernodexp.hpc;Obit received momhop:1 serverhop:1 state:4 substate:42
04/24/2018 01:58:14;0010;Server@node2;Job;12367.node2.supernodexp.hpc;Exit_status=0 resources_used.cpupercent=0 resources_used.cput=00:00:00 resources_used.mem=0kb resources_used.ncpus=8 resources_used.vmem=0kb resources_used.walltime=00:00:07
04/24/2018 01:58:14;0100;Server@node2;Job;12367.node2.supernodexp.hpc;dequeuing from workq, state 5
04/24/2018 01:58:14;0040;Server@node2;Svr;node2.supernodexp.hpc;Scheduler sent command 2
04/24/2018 01:58:14;0040;Server@node2;Svr;node2.supernodexp.hpc;Scheduler sent command 0
04/24/2018 01:58:14;0100;Server@node2;Req;;Type 21 request received from Scheduler@node2.supernodexp.hpc, sock=16
04/24/2018 01:58:14;0100;Server@node2;Req;;Type 81 request received from Scheduler@node2.supernodexp.hpc, sock=16
04/24/2018 01:58:14;0100;Server@node2;Req;;Type 71 request received from Scheduler@node2.supernodexp.hpc, sock=16
04/24/2018 01:58:14;0100;Server@node2;Req;;Type 58 request received from Scheduler@node2.supernodexp.hpc, sock=16
04/24/2018 01:58:14;0100;Server@node2;Req;;Type 20 request received from Scheduler@node2.supernodexp.hpc, sock=16
04/24/2018 01:58:14;0100;Server@node2;Req;;Type 51 request received from Scheduler@node2.supernodexp.hpc, sock=16
04/24/2018 01:58:14;0100;Server@node2;Req;;Type 11 request received from Scheduler@node2.supernodexp.hpc, sock=16
04/24/2018 01:58:14;0008;Server@node2;Job;12369.node2.supernodexp.hpc;Job Modified at request of Scheduler@node2.supernodexp.hpc
04/24/2018 01:58:23;0080;Server@node2;Job;12366.node2.supernodexp.hpc;Obit received momhop:1 serverhop:1 state:4 substate:42
04/24/2018 01:58:23;0080;Server@node2;Job;12368.node2.supernodexp.hpc;Obit received momhop:1 serverhop:1 state:4 substate:42
04/24/2018 01:58:24;0010;Server@node2;Job;12366.node2.supernodexp.hpc;Exit_status=0 resources_used.cpupercent=0 resources_used.cput=00:00:00 resources_used.mem=9332kb resources_used.ncpus=8 resources_used.vmem=104700kb resources_used.walltime=00:00:21
04/24/2018 01:58:24;0100;Server@node2;Job;12366.node2.supernodexp.hpc;dequeuing from workq, state 5
04/24/2018 01:58:24;0040;Server@node2;Svr;node2.supernodexp.hpc;Scheduler sent command 2
04/24/2018 01:58:24;0040;Server@node2;Svr;node2.supernodexp.hpc;Scheduler sent command 0
04/24/2018 01:58:24;0100;Server@node2;Req;;Type 21 request received from Scheduler@node2.supernodexp.hpc, sock=16
04/24/2018 01:58:24;0100;Server@node2;Req;;Type 81 request received from Scheduler@node2.supernodexp.hpc, sock=16
04/24/2018 01:58:24;0100;Server@node2;Req;;Type 71 request received from Scheduler@node2.supernodexp.hpc, sock=16
04/24/2018 01:58:24;0100;Server@node2;Req;;Type 58 request received from Scheduler@node2.supernodexp.hpc, sock=16
04/24/2018 01:58:24;0100;Server@node2;Req;;Type 20 request received from Scheduler@node2.supernodexp.hpc, sock=16
04/24/2018 01:58:24;0100;Server@node2;Req;;Type 51 request received from Scheduler@node2.supernodexp.hpc, sock=16
04/24/2018 01:58:24;0010;Server@node2;Job;12368.node2.supernodexp.hpc;Exit_status=0 resources_used.cpupercent=0 resources_used.cput=00:00:00 resources_used.mem=9624kb resources_used.ncpus=4 resources_used.vmem=171960kb resources_used.walltime=00:00:17
04/24/2018 01:58:24;0100;Server@node2;Job;12368.node2.supernodexp.hpc;dequeuing from workq, state 5
04/24/2018 01:58:24;0040;Server@node2;Svr;node2.supernodexp.hpc;Scheduler sent command 2
04/24/2018 01:58:24;0040;Server@node2;Svr;node2.supernodexp.hpc;Scheduler sent command 0
04/24/2018 01:58:24;0100;Server@node2;Req;;Type 21 request received from Scheduler@node2.supernodexp.hpc, sock=16
04/24/2018 01:58:24;0100;Server@node2;Req;;Type 81 request received from Scheduler@node2.supernodexp.hpc, sock=16
04/24/2018 01:58:24;0100;Server@node2;Req;;Type 71 request received from Scheduler@node2.supernodexp.hpc, sock=16
04/24/2018 01:58:24;0100;Server@node2;Req;;Type 58 request received from Scheduler@node2.supernodexp.hpc, sock=16
04/24/2018 01:58:24;0100;Server@node2;Req;;Type 20 request received from Scheduler@node2.supernodexp.hpc, sock=16
04/24/2018 01:58:24;0100;Server@node2;Req;;Type 51 request received from Scheduler@node2.supernodexp.hpc, sock=16
04/24/2018 02:00:43;0080;Server@node2;Job;12359.node2.supernodexp.hpc;Obit received momhop:1 serverhop:1 state:4 substate:42
04/24/2018 02:00:44;0010;Server@node2;Job;12359.node2.supernodexp.hpc;Exit_status=0 resources_used.cpupercent=0 resources_used.cput=00:00:00 resources_used.mem=9408kb resources_used.ncpus=12 resources_used.vmem=169908kb resources_used.walltime=00:05:58
04/24/2018 02:00:44;0100;Server@node2;Job;12359.node2.supernodexp.hpc;dequeuing from workq, state 5
04/24/2018 02:00:44;0040;Server@node2;Svr;node2.supernodexp.hpc;Scheduler sent command 2
04/24/2018 02:00:44;0040;Server@node2;Svr;node2.supernodexp.hpc;Scheduler sent command 0
04/24/2018 02:00:44;0100;Server@node2;Req;;Type 21 request received from Scheduler@node2.supernodexp.hpc, sock=16
04/24/2018 02:00:44;0100;Server@node2;Req;;Type 81 request received from Scheduler@node2.supernodexp.hpc, sock=16
04/24/2018 02:00:44;0100;Server@node2;Req;;Type 71 request received from Scheduler@node2.supernodexp.hpc, sock=16
04/24/2018 02:00:44;0100;Server@node2;Req;;Type 58 request received from Scheduler@node2.supernodexp.hpc, sock=16
04/24/2018 02:00:44;0100;Server@node2;Req;;Type 20 request received from Scheduler@node2.supernodexp.hpc, sock=16
04/24/2018 02:00:44;0100;Server@node2;Req;;Type 51 request received from Scheduler@node2.supernodexp.hpc, sock=16
04/24/2018 02:02:36;0080;Server@node2;Job;12361.node2.supernodexp.hpc;Obit received momhop:1 serverhop:1 state:4 substate:42
04/24/2018 02:02:37;0010;Server@node2;Job;12361.node2.supernodexp.hpc;Exit_status=0 resources_used.cpupercent=0 resources_used.cput=00:00:00 resources_used.mem=9404kb resources_used.ncpus=12 resources_used.vmem=102576kb resources_used.walltime=00:06:02
04/24/2018 02:02:37;0100;Server@node2;Job;12361.node2.supernodexp.hpc;dequeuing from workq, state 5
04/24/2018 02:02:37;0040;Server@node2;Svr;node2.supernodexp.hpc;Scheduler sent command 2
04/24/2018 02:02:37;0040;Server@node2;Svr;node2.supernodexp.hpc;Scheduler sent command 0
04/24/2018 02:02:37;0100;Server@node2;Req;;Type 21 request received from Scheduler@node2.supernodexp.hpc, sock=16
04/24/2018 02:02:37;0100;Server@node2;Req;;Type 81 request received from Scheduler@node2.supernodexp.hpc, sock=16
04/24/2018 02:02:37;0100;Server@node2;Req;;Type 71 request received from Scheduler@node2.supernodexp.hpc, sock=16
04/24/2018 02:02:37;0100;Server@node2;Req;;Type 58 request received from Scheduler@node2.supernodexp.hpc, sock=16
04/24/2018 02:02:37;0100;Server@node2;Req;;Type 20 request received from Scheduler@node2.supernodexp.hpc, sock=16
04/24/2018 02:02:37;0100;Server@node2;Req;;Type 51 request received from Scheduler@node2.supernodexp.hpc, sock=16
04/24/2018 02:08:39;0080;Server@node2;Job;12354.node2.supernodexp.hpc;Obit received momhop:1 serverhop:1 state:4 substate:42
04/24/2018 02:08:40;0010;Server@node2;Job;12354.node2.supernodexp.hpc;Exit_status=2 resources_used.cpupercent=0 resources_used.cput=00:00:00 resources_used.mem=10004kb resources_used.ncpus=32 resources_used.vmem=104628kb resources_used.walltime=00:20:58
04/24/2018 02:08:40;0100;Server@node2;Job;12354.node2.supernodexp.hpc;dequeuing from workq, state 5
04/24/2018 02:08:40;0040;Server@node2;Svr;node2.supernodexp.hpc;Scheduler sent command 2
04/24/2018 02:08:40;0040;Server@node2;Svr;node2.supernodexp.hpc;Scheduler sent command 0
04/24/2018 02:08:40;0100;Server@node2;Req;;Type 21 request received from Scheduler@node2.supernodexp.hpc, sock=16
04/24/2018 02:08:40;0100;Server@node2;Req;;Type 81 request received from Scheduler@node2.supernodexp.hpc, sock=16
04/24/2018 02:08:40;0100;Server@node2;Req;;Type 71 request received from Scheduler@node2.supernodexp.hpc, sock=16
04/24/2018 02:08:40;0100;Server@node2;Req;;Type 58 request received from Scheduler@node2.supernodexp.hpc, sock=16
04/24/2018 02:08:40;0100;Server@node2;Req;;Type 20 request received from Scheduler@node2.supernodexp.hpc, sock=16
04/24/2018 02:08:40;0100;Server@node2;Req;;Type 51 request received from Scheduler@node2.supernodexp.hpc, sock=16
04/24/2018 02:08:40;0100;Server@node2;Req;;Type 23 request received from Scheduler@node2.supernodexp.hpc, sock=16
04/24/2018 02:08:40;0008;Server@node2;Job;12369.node2.supernodexp.hpc;Job Run at request of Scheduler@node2.supernodexp.hpc on exec_vnode (node14:nmics=2:ncpus=12:mem=41943040kb)
04/24/2018 02:08:40;0001;Server@node2;Svr;Server@node2;Success (0) in req_runjob2, return value of svr_startjob is 0
04/24/2018 02:08:40;0100;Server@node2;Req;;Type 23 request received from Scheduler@node2.supernodexp.hpc, sock=16
04/24/2018 02:08:40;0008;Server@node2;Job;12370.node2.supernodexp.hpc;Job Run at request of Scheduler@node2.supernodexp.hpc on exec_vnode (node3:ncpus=8:mem=20971520kb)
04/24/2018 02:08:40;0001;Server@node2;Svr;Server@node2;Success (0) in req_runjob2, return value of svr_startjob is 0
04/24/2018 02:08:40;0100;Server@node2;Req;;Type 23 request received from Scheduler@node2.supernodexp.hpc, sock=16
04/24/2018 02:08:40;0008;Server@node2;Job;12371.node2.supernodexp.hpc;Job Run at request of Scheduler@node2.supernodexp.hpc on exec_vnode (node3:ncpus=8:mem=10485760kb)
04/24/2018 02:08:40;0001;Server@node2;Svr;Server@node2;Success (0) in req_runjob2, return value of svr_startjob is 0
04/24/2018 02:08:40;0100;Server@node2;Req;;Type 23 request received from Scheduler@node2.supernodexp.hpc, sock=16
04/24/2018 02:08:40;0008;Server@node2;Job;12372.node2.supernodexp.hpc;Job Run at request of Scheduler@node2.supernodexp.hpc on exec_vnode (node14:ncpus=2:mem=2097152kb)
04/24/2018 02:08:40;0001;Server@node2;Svr;Server@node2;Success (0) in req_runjob2, return value of svr_startjob is 0
04/24/2018 02:08:40;0100;Server@node2;Req;;Type 23 request received from Scheduler@node2.supernodexp.hpc, sock=16
04/24/2018 02:08:40;0008;Server@node2;Job;12373.node2.supernodexp.hpc;Job Run at request of Scheduler@node2.supernodexp.hpc on exec_vnode (node14:ncpus=12:mem=20971520kb)
04/24/2018 02:08:40;0001;Server@node2;Svr;Server@node2;Success (0) in req_runjob2, return value of svr_startjob is 0
04/24/2018 02:08:40;0100;Server@node2;Req;;Type 23 request received from Scheduler@node2.supernodexp.hpc, sock=16
04/24/2018 02:08:40;0008;Server@node2;Job;12374.node2.supernodexp.hpc;Job Run at request of Scheduler@node2.supernodexp.hpc on exec_vnode (node14:ncpus=8:mem=20971520kb)
04/24/2018 02:08:40;0001;Server@node2;Svr;Server@node2;Success (0) in req_runjob2, return value of svr_startjob is 0
04/24/2018 02:08:40;0100;Server@node2;Req;;Type 23 request received from Scheduler@node2.supernodexp.hpc, sock=16
04/24/2018 02:08:40;0008;Server@node2;Job;12375.node2.supernodexp.hpc;Job Run at request of Scheduler@node2.supernodexp.hpc on exec_vnode (node14:ncpus=8:mem=15728640kb)
04/24/2018 02:08:40;0001;Server@node2;Svr;Server@node2;Success (0) in req_runjob2, return value of svr_startjob is 0
04/24/2018 02:08:40;0100;Server@node2;Req;;Type 23 request received from Scheduler@node2.supernodexp.hpc, sock=16
04/24/2018 02:08:40;0008;Server@node2;Job;12376.node2.supernodexp.hpc;Job Run at request of Scheduler@node2.supernodexp.hpc on exec_vnode (node14:ncpus=2:mem=2097152kb)
04/24/2018 02:08:40;0001;Server@node2;Svr;Server@node2;Success (0) in req_runjob2, return value of svr_startjob is 0
04/24/2018 02:08:40;0100;Server@node2;Req;;Type 23 request received from Scheduler@node2.supernodexp.hpc, sock=16
04/24/2018 02:08:40;0008;Server@node2;Job;12377.node2.supernodexp.hpc;Job Run at request of Scheduler@node2.supernodexp.hpc on exec_vnode (node14:ncpus=4:mem=5242880kb)
04/24/2018 02:08:40;0001;Server@node2;Svr;Server@node2;Success (0) in req_runjob2, return value of svr_startjob is 0
04/24/2018 02:08:40;0100;Server@node2;Req;;Type 11 request received from Scheduler@node2.supernodexp.hpc, sock=16
04/24/2018 02:08:40;0008;Server@node2;Job;12378.node2.supernodexp.hpc;Job Modified at request of Scheduler@node2.supernodexp.hpc
04/24/2018 02:08:46;0080;Server@node2;Job;12376.node2.supernodexp.hpc;Obit received momhop:1 serverhop:1 state:4 substate:42
04/24/2018 02:08:47;0080;Server@node2;Job;12372.node2.supernodexp.hpc;Obit received momhop:1 serverhop:1 state:4 substate:42
04/24/2018 02:08:47;0010;Server@node2;Job;12376.node2.supernodexp.hpc;Exit_status=0 resources_used.cpupercent=0 resources_used.cput=00:00:00 resources_used.mem=0kb resources_used.ncpus=2 resources_used.vmem=0kb resources_used.walltime=00:00:06
04/24/2018 02:08:47;0100;Server@node2;Job;12376.node2.supernodexp.hpc;dequeuing from workq, state 5
04/24/2018 02:08:47;0040;Server@node2;Svr;node2.supernodexp.hpc;Scheduler sent command 2
04/24/2018 02:08:47;0040;Server@node2;Svr;node2.supernodexp.hpc;Scheduler sent command 0
04/24/2018 02:08:47;0100;Server@node2;Req;;Type 21 request received from Scheduler@node2.supernodexp.hpc, sock=16
04/24/2018 02:08:47;0100;Server@node2;Req;;Type 81 request received from Scheduler@node2.supernodexp.hpc, sock=16
04/24/2018 02:08:47;0100;Server@node2;Req;;Type 71 request received from Scheduler@node2.supernodexp.hpc, sock=16
04/24/2018 02:08:47;0100;Server@node2;Req;;Type 58 request received from Scheduler@node2.supernodexp.hpc, sock=16
04/24/2018 02:08:47;0100;Server@node2;Req;;Type 20 request received from Scheduler@node2.supernodexp.hpc, sock=16
04/24/2018 02:08:47;0100;Server@node2;Req;;Type 51 request received from Scheduler@node2.supernodexp.hpc, sock=16
04/24/2018 02:08:48;0010;Server@node2;Job;12372.node2.supernodexp.hpc;Exit_status=0 resources_used.cpupercent=0 resources_used.cput=00:00:00 resources_used.mem=9428kb resources_used.ncpus=2 resources_used.vmem=104628kb resources_used.walltime=00:00:07
04/24/2018 02:08:48;0100;Server@node2;Job;12372.node2.supernodexp.hpc;dequeuing from workq, state 5
04/24/2018 02:08:48;0040;Server@node2;Svr;node2.supernodexp.hpc;Scheduler sent command 2
04/24/2018 02:08:48;0040;Server@node2;Svr;node2.supernodexp.hpc;Scheduler sent command 0
04/24/2018 02:08:48;0100;Server@node2;Req;;Type 21 request received from Scheduler@node2.supernodexp.hpc, sock=16
04/24/2018 02:08:48;0100;Server@node2;Req;;Type 81 request received from Scheduler@node2.supernodexp.hpc, sock=16
04/24/2018 02:08:48;0100;Server@node2;Req;;Type 71 request received from Scheduler@node2.supernodexp.hpc, sock=16
04/24/2018 02:08:48;0100;Server@node2;Req;;Type 58 request received from Scheduler@node2.supernodexp.hpc, sock=16
04/24/2018 02:08:48;0100;Server@node2;Req;;Type 20 request received from Scheduler@node2.supernodexp.hpc, sock=16
04/24/2018 02:08:48;0100;Server@node2;Req;;Type 51 request received from Scheduler@node2.supernodexp.hpc, sock=16
04/24/2018 02:08:48;0080;Server@node2;Job;12374.node2.supernodexp.hpc;Obit received momhop:1 serverhop:1 state:4 substate:42
04/24/2018 02:08:48;0010;Server@node2;Job;12374.node2.supernodexp.hpc;Exit_status=0 resources_used.cpupercent=0 resources_used.cput=00:00:00 resources_used.mem=9884kb resources_used.ncpus=8 resources_used.vmem=248488kb resources_used.walltime=00:00:08
04/24/2018 02:08:48;0100;Server@node2;Job;12374.node2.supernodexp.hpc;dequeuing from workq, state 5
04/24/2018 02:08:49;0040;Server@node2;Svr;node2.supernodexp.hpc;Scheduler sent command 2
04/24/2018 02:08:49;0040;Server@node2;Svr;node2.supernodexp.hpc;Scheduler sent command 0
04/24/2018 02:08:49;0100;Server@node2;Req;;Type 21 request received from Scheduler@node2.supernodexp.hpc, sock=16
04/24/2018 02:08:49;0100;Server@node2;Req;;Type 81 request received from Scheduler@node2.supernodexp.hpc, sock=16
04/24/2018 02:08:49;0100;Server@node2;Req;;Type 71 request received from Scheduler@node2.supernodexp.hpc, sock=16
04/24/2018 02:08:49;0100;Server@node2;Req;;Type 58 request received from Scheduler@node2.supernodexp.hpc, sock=16
04/24/2018 02:08:49;0100;Server@node2;Req;;Type 20 request received from Scheduler@node2.supernodexp.hpc, sock=16
04/24/2018 02:08:49;0100;Server@node2;Req;;Type 51 request received from Scheduler@node2.supernodexp.hpc, sock=16
04/24/2018 02:08:56;0080;Server@node2;Job;12377.node2.supernodexp.hpc;Obit received momhop:1 serverhop:1 state:4 substate:42
04/24/2018 02:08:57;0010;Server@node2;Job;12377.node2.supernodexp.hpc;Exit_status=0 resources_used.cpupercent=0 resources_used.cput=00:00:00 resources_used.mem=9868kb resources_used.ncpus=4 resources_used.vmem=170164kb resources_used.walltime=00:00:16
04/24/2018 02:08:57;0100;Server@node2;Job;12377.node2.supernodexp.hpc;dequeuing from workq, state 5
04/24/2018 02:08:57;0040;Server@node2;Svr;node2.supernodexp.hpc;Scheduler sent command 2
04/24/2018 02:08:57;0040;Server@node2;Svr;node2.supernodexp.hpc;Scheduler sent command 0
04/24/2018 02:08:57;0100;Server@node2;Req;;Type 21 request received from Scheduler@node2.supernodexp.hpc, sock=16
04/24/2018 02:08:57;0100;Server@node2;Req;;Type 81 request received from Scheduler@node2.supernodexp.hpc, sock=16
04/24/2018 02:08:57;0100;Server@node2;Req;;Type 71 request received from Scheduler@node2.supernodexp.hpc, sock=16
04/24/2018 02:08:57;0100;Server@node2;Req;;Type 58 request received from Scheduler@node2.supernodexp.hpc, sock=16
04/24/2018 02:08:57;0100;Server@node2;Req;;Type 20 request received from Scheduler@node2.supernodexp.hpc, sock=16
04/24/2018 02:08:57;0100;Server@node2;Req;;Type 51 request received from Scheduler@node2.supernodexp.hpc, sock=16
04/24/2018 02:09:17;0080;Server@node2;Job;12370.node2.supernodexp.hpc;Obit received momhop:1 serverhop:1 state:4 substate:42
04/24/2018 02:09:18;0080;Server@node2;Job;12371.node2.supernodexp.hpc;Obit received momhop:1 serverhop:1 state:4 substate:42
04/24/2018 02:09:18;0010;Server@node2;Job;12370.node2.supernodexp.hpc;Exit_status=0 resources_used.cpupercent=0 resources_used.cput=00:00:00 resources_used.mem=8828kb resources_used.ncpus=8 resources_used.vmem=170624kb resources_used.walltime=00:00:37
04/24/2018 02:09:18;0100;Server@node2;Job;12370.node2.supernodexp.hpc;dequeuing from workq, state 5
04/24/2018 02:09:18;0040;Server@node2;Svr;node2.supernodexp.hpc;Scheduler sent command 2
04/24/2018 02:09:18;0040;Server@node2;Svr;node2.supernodexp.hpc;Scheduler sent command 0
04/24/2018 02:09:18;0100;Server@node2;Req;;Type 21 request received from Scheduler@node2.supernodexp.hpc, sock=16
04/24/2018 02:09:18;0100;Server@node2;Req;;Type 81 request received from Scheduler@node2.supernodexp.hpc, sock=16
04/24/2018 02:09:18;0100;Server@node2;Req;;Type 71 request received from Scheduler@node2.supernodexp.hpc, sock=16
04/24/2018 02:09:18;0100;Server@node2;Req;;Type 58 request received from Scheduler@node2.supernodexp.hpc, sock=16
04/24/2018 02:09:18;0100;Server@node2;Req;;Type 20 request received from Scheduler@node2.supernodexp.hpc, sock=16
04/24/2018 02:09:18;0100;Server@node2;Req;;Type 51 request received from Scheduler@node2.supernodexp.hpc, sock=16
04/24/2018 02:09:19;0010;Server@node2;Job;12371.node2.supernodexp.hpc;Exit_status=0 resources_used.cpupercent=0 resources_used.cput=00:00:00 resources_used.mem=9332kb resources_used.ncpus=8 resources_used.vmem=104444kb resources_used.walltime=00:00:38
04/24/2018 02:09:19;0100;Server@node2;Job;12371.node2.supernodexp.hpc;dequeuing from workq, state 5
04/24/2018 02:09:19;0040;Server@node2;Svr;node2.supernodexp.hpc;Scheduler sent command 2
04/24/2018 02:09:19;0040;Server@node2;Svr;node2.supernodexp.hpc;Scheduler sent command 0
04/24/2018 02:09:19;0100;Server@node2;Req;;Type 21 request received from Scheduler@node2.supernodexp.hpc, sock=16
04/24/2018 02:09:19;0100;Server@node2;Req;;Type 81 request received from Scheduler@node2.supernodexp.hpc, sock=16
04/24/2018 02:09:19;0100;Server@node2;Req;;Type 71 request received from Scheduler@node2.supernodexp.hpc, sock=16
04/24/2018 02:09:19;0100;Server@node2;Req;;Type 58 request received from Scheduler@node2.supernodexp.hpc, sock=16
04/24/2018 02:09:19;0100;Server@node2;Req;;Type 20 request received from Scheduler@node2.supernodexp.hpc, sock=16
04/24/2018 02:09:19;0100;Server@node2;Req;;Type 51 request received from Scheduler@node2.supernodexp.hpc, sock=16
04/24/2018 02:15:17;0080;Server@node2;Job;12357.node2.supernodexp.hpc;Obit received momhop:1 serverhop:1 state:4 substate:42
04/24/2018 02:15:18;0010;Server@node2;Job;12357.node2.supernodexp.hpc;Exit_status=2 resources_used.cpupercent=0 resources_used.cput=00:00:00 resources_used.mem=9436kb resources_used.ncpus=32 resources_used.vmem=105088kb resources_used.walltime=00:20:33
04/24/2018 02:15:18;0100;Server@node2;Job;12357.node2.supernodexp.hpc;dequeuing from workq, state 5
04/24/2018 02:15:18;0040;Server@node2;Svr;node2.supernodexp.hpc;Scheduler sent command 2
04/24/2018 02:15:18;0040;Server@node2;Svr;node2.supernodexp.hpc;Scheduler sent command 0
04/24/2018 02:15:18;0100;Server@node2;Req;;Type 21 request received from Scheduler@node2.supernodexp.hpc, sock=16
04/24/2018 02:15:18;0100;Server@node2;Req;;Type 81 request received from Scheduler@node2.supernodexp.hpc, sock=16
04/24/2018 02:15:18;0100;Server@node2;Req;;Type 71 request received from Scheduler@node2.supernodexp.hpc, sock=16
04/24/2018 02:15:18;0100;Server@node2;Req;;Type 58 request received from Scheduler@node2.supernodexp.hpc, sock=16
04/24/2018 02:15:18;0100;Server@node2;Req;;Type 20 request received from Scheduler@node2.supernodexp.hpc, sock=16
04/24/2018 02:15:18;0100;Server@node2;Req;;Type 51 request received from Scheduler@node2.supernodexp.hpc, sock=16
04/24/2018 02:15:18;0100;Server@node2;Req;;Type 23 request received from Scheduler@node2.supernodexp.hpc, sock=16
04/24/2018 02:15:18;0008;Server@node2;Job;12378.node2.supernodexp.hpc;Job Run at request of Scheduler@node2.supernodexp.hpc on exec_vnode (node3:nmics=2:ncpus=12:mem=41943040kb)
04/24/2018 02:15:18;0001;Server@node2;Svr;Server@node2;Success (0) in req_runjob2, return value of svr_startjob is 0
04/24/2018 02:15:18;0100;Server@node2;Req;;Type 11 request received from Scheduler@node2.supernodexp.hpc, sock=16
04/24/2018 02:15:18;0008;Server@node2;Job;12379.node2.supernodexp.hpc;Job Modified at request of Scheduler@node2.supernodexp.hpc
04/24/2018 02:16:18;0080;Server@node2;Job;12362.node2.supernodexp.hpc;Obit received momhop:1 serverhop:1 state:4 substate:42
04/24/2018 02:16:19;0010;Server@node2;Job;12362.node2.supernodexp.hpc;Exit_status=2 resources_used.cpupercent=0 resources_used.cput=00:00:00 resources_used.mem=10220kb resources_used.ncpus=32 resources_used.vmem=169908kb resources_used.walltime=00:19:10
04/24/2018 02:16:19;0100;Server@node2;Job;12362.node2.supernodexp.hpc;dequeuing from workq, state 5
04/24/2018 02:16:19;0040;Server@node2;Svr;node2.supernodexp.hpc;Scheduler sent command 2
04/24/2018 02:16:19;0040;Server@node2;Svr;node2.supernodexp.hpc;Scheduler sent command 0
04/24/2018 02:16:19;0100;Server@node2;Req;;Type 21 request received from Scheduler@node2.supernodexp.hpc, sock=16
04/24/2018 02:16:19;0100;Server@node2;Req;;Type 81 request received from Scheduler@node2.supernodexp.hpc, sock=16
04/24/2018 02:16:19;0100;Server@node2;Req;;Type 71 request received from Scheduler@node2.supernodexp.hpc, sock=16
04/24/2018 02:16:19;0100;Server@node2;Req;;Type 58 request received from Scheduler@node2.supernodexp.hpc, sock=16
04/24/2018 02:16:19;0100;Server@node2;Req;;Type 20 request received from Scheduler@node2.supernodexp.hpc, sock=16
04/24/2018 02:16:19;0100;Server@node2;Req;;Type 51 request received from Scheduler@node2.supernodexp.hpc, sock=16
04/24/2018 02:16:19;0100;Server@node2;Req;;Type 23 request received from Scheduler@node2.supernodexp.hpc, sock=16
04/24/2018 02:16:19;0008;Server@node2;Job;12379.node2.supernodexp.hpc;Job Run at request of Scheduler@node2.supernodexp.hpc on exec_vnode (node13:ncpus=32:nmics=2:mem=31457280kb)
04/24/2018 02:16:19;0001;Server@node2;Svr;Server@node2;Success (0) in req_runjob2, return value of svr_startjob is 0
04/24/2018 02:16:19;0100;Server@node2;Req;;Type 23 request received from Scheduler@node2.supernodexp.hpc, sock=16
04/24/2018 02:16:19;0008;Server@node2;Job;12380.node2.supernodexp.hpc;Job Run at request of Scheduler@node2.supernodexp.hpc on exec_vnode (node3:ncpus=8:mem=15728640kb)
04/24/2018 02:16:19;0001;Server@node2;Svr;Server@node2;Success (0) in req_runjob2, return value of svr_startjob is 0
04/24/2018 02:16:19;0100;Server@node2;Req;;Type 11 request received from Scheduler@node2.supernodexp.hpc, sock=16
04/24/2018 02:16:19;0008;Server@node2;Job;12381.node2.supernodexp.hpc;Job Modified at request of Scheduler@node2.supernodexp.hpc
04/24/2018 02:17:33;0080;Server@node2;Job;12375.node2.supernodexp.hpc;Obit received momhop:1 serverhop:1 state:4 substate:42
04/24/2018 02:17:34;0010;Server@node2;Job;12375.node2.supernodexp.hpc;Exit_status=0 resources_used.cpupercent=0 resources_used.cput=00:00:00 resources_used.mem=9636kb resources_used.ncpus=8 resources_used.vmem=237752kb resources_used.walltime=00:08:53
04/24/2018 02:17:34;0100;Server@node2;Job;12375.node2.supernodexp.hpc;dequeuing from workq, state 5
04/24/2018 02:17:34;0040;Server@node2;Svr;node2.supernodexp.hpc;Scheduler sent command 2
04/24/2018 02:17:34;0040;Server@node2;Svr;node2.supernodexp.hpc;Scheduler sent command 0
04/24/2018 02:17:34;0100;Server@node2;Req;;Type 21 request received from Scheduler@node2.supernodexp.hpc, sock=16
04/24/2018 02:17:34;0100;Server@node2;Req;;Type 81 request received from Scheduler@node2.supernodexp.hpc, sock=16
04/24/2018 02:17:34;0100;Server@node2;Req;;Type 71 request received from Scheduler@node2.supernodexp.hpc, sock=16
04/24/2018 02:17:34;0100;Server@node2;Req;;Type 58 request received from Scheduler@node2.supernodexp.hpc, sock=16
04/24/2018 02:17:34;0100;Server@node2;Req;;Type 20 request received from Scheduler@node2.supernodexp.hpc, sock=16
04/24/2018 02:17:34;0100;Server@node2;Req;;Type 51 request received from Scheduler@node2.supernodexp.hpc, sock=16
04/24/2018 02:21:45;0080;Server@node2;Job;12373.node2.supernodexp.hpc;Obit received momhop:1 serverhop:1 state:4 substate:42
04/24/2018 02:21:46;0010;Server@node2;Job;12373.node2.supernodexp.hpc;Exit_status=0 resources_used.cpupercent=0 resources_used.cput=00:00:00 resources_used.mem=9896kb resources_used.ncpus=12 resources_used.vmem=863896kb resources_used.walltime=00:13:05
04/24/2018 02:21:46;0100;Server@node2;Job;12373.node2.supernodexp.hpc;dequeuing from workq, state 5
04/24/2018 02:21:46;0040;Server@node2;Svr;node2.supernodexp.hpc;Scheduler sent command 2
04/24/2018 02:21:46;0040;Server@node2;Svr;node2.supernodexp.hpc;Scheduler sent command 0
04/24/2018 02:21:46;0100;Server@node2;Req;;Type 21 request received from Scheduler@node2.supernodexp.hpc, sock=16
04/24/2018 02:21:46;0100;Server@node2;Req;;Type 81 request received from Scheduler@node2.supernodexp.hpc, sock=16
04/24/2018 02:21:46;0100;Server@node2;Req;;Type 71 request received from Scheduler@node2.supernodexp.hpc, sock=16
04/24/2018 02:21:46;0100;Server@node2;Req;;Type 58 request received from Scheduler@node2.supernodexp.hpc, sock=16
04/24/2018 02:21:46;0100;Server@node2;Req;;Type 20 request received from Scheduler@node2.supernodexp.hpc, sock=16
04/24/2018 02:21:46;0100;Server@node2;Req;;Type 51 request received from Scheduler@node2.supernodexp.hpc, sock=16
04/24/2018 02:23:38;0080;Server@node2;Job;12369.node2.supernodexp.hpc;Obit received momhop:1 serverhop:1 state:4 substate:42
04/24/2018 02:23:39;0010;Server@node2;Job;12369.node2.supernodexp.hpc;Exit_status=0 resources_used.cpupercent=0 resources_used.cput=00:00:00 resources_used.mem=12268kb resources_used.ncpus=12 resources_used.vmem=104628kb resources_used.walltime=00:14:58
04/24/2018 02:23:39;0100;Server@node2;Job;12369.node2.supernodexp.hpc;dequeuing from workq, state 5
04/24/2018 02:23:39;0040;Server@node2;Svr;node2.supernodexp.hpc;Scheduler sent command 2
04/24/2018 02:23:39;0040;Server@node2;Svr;node2.supernodexp.hpc;Scheduler sent command 0
04/24/2018 02:23:39;0100;Server@node2;Req;;Type 21 request received from Scheduler@node2.supernodexp.hpc, sock=16
04/24/2018 02:23:39;0100;Server@node2;Req;;Type 81 request received from Scheduler@node2.supernodexp.hpc, sock=16
04/24/2018 02:23:39;0100;Server@node2;Req;;Type 71 request received from Scheduler@node2.supernodexp.hpc, sock=16
04/24/2018 02:23:39;0100;Server@node2;Req;;Type 58 request received from Scheduler@node2.supernodexp.hpc, sock=16
04/24/2018 02:23:39;0100;Server@node2;Req;;Type 20 request received from Scheduler@node2.supernodexp.hpc, sock=16
04/24/2018 02:23:39;0100;Server@node2;Req;;Type 51 request received from Scheduler@node2.supernodexp.hpc, sock=16
04/24/2018 02:23:39;0100;Server@node2;Req;;Type 23 request received from Scheduler@node2.supernodexp.hpc, sock=16
04/24/2018 02:23:39;0008;Server@node2;Job;12381.node2.supernodexp.hpc;Job Run at request of Scheduler@node2.supernodexp.hpc on exec_vnode (node14:nmics=2:ncpus=12:mem=41943040kb)
04/24/2018 02:23:39;0001;Server@node2;Svr;Server@node2;Success (0) in req_runjob2, return value of svr_startjob is 0
04/24/2018 02:23:39;0100;Server@node2;Req;;Type 23 request received from Scheduler@node2.supernodexp.hpc, sock=16
04/24/2018 02:23:39;0008;Server@node2;Job;12382.node2.supernodexp.hpc;Job Run at request of Scheduler@node2.supernodexp.hpc on exec_vnode (node3:ncpus=8:mem=10485760kb)
04/24/2018 02:23:39;0001;Server@node2;Svr;Server@node2;Success (0) in req_runjob2, return value of svr_startjob is 0
04/24/2018 02:23:39;0100;Server@node2;Req;;Type 23 request received from Scheduler@node2.supernodexp.hpc, sock=16
04/24/2018 02:23:39;0008;Server@node2;Job;12383.node2.supernodexp.hpc;Job Run at request of Scheduler@node2.supernodexp.hpc on exec_vnode (node3:ncpus=2:mem=2097152kb)
04/24/2018 02:23:39;0001;Server@node2;Svr;Server@node2;Success (0) in req_runjob2, return value of svr_startjob is 0
04/24/2018 02:23:39;0100;Server@node2;Req;;Type 23 request received from Scheduler@node2.supernodexp.hpc, sock=16
04/24/2018 02:23:39;0008;Server@node2;Job;12384.node2.supernodexp.hpc;Job Run at request of Scheduler@node2.supernodexp.hpc on exec_vnode (node3:ncpus=2:mem=2097152kb)
04/24/2018 02:23:39;0001;Server@node2;Svr;Server@node2;Success (0) in req_runjob2, return value of svr_startjob is 0
04/24/2018 02:23:39;0100;Server@node2;Req;;Type 23 request received from Scheduler@node2.supernodexp.hpc, sock=16
04/24/2018 02:23:39;0008;Server@node2;Job;12385.node2.supernodexp.hpc;Job Run at request of Scheduler@node2.supernodexp.hpc on exec_vnode (node3:ncpus=8:mem=3145728kb)
04/24/2018 02:23:39;0001;Server@node2;Svr;Server@node2;Success (0) in req_runjob2, return value of svr_startjob is 0
04/24/2018 02:23:39;0100;Server@node2;Req;;Type 23 request received from Scheduler@node2.supernodexp.hpc, sock=16
04/24/2018 02:23:39;0008;Server@node2;Job;12386.node2.supernodexp.hpc;Job Run at request of Scheduler@node2.supernodexp.hpc on exec_vnode (node3:ncpus=8:mem=20971520kb)
04/24/2018 02:23:39;0001;Server@node2;Svr;Server@node2;Success (0) in req_runjob2, return value of svr_startjob is 0
04/24/2018 02:23:39;0100;Server@node2;Req;;Type 23 request received from Scheduler@node2.supernodexp.hpc, sock=16
04/24/2018 02:23:39;0008;Server@node2;Job;12387.node2.supernodexp.hpc;Job Run at request of Scheduler@node2.supernodexp.hpc on exec_vnode (node14:ncpus=12:mem=5242880kb)
04/24/2018 02:23:39;0001;Server@node2;Svr;Server@node2;Success (0) in req_runjob2, return value of svr_startjob is 0
04/24/2018 02:23:39;0100;Server@node2;Req;;Type 23 request received from Scheduler@node2.supernodexp.hpc, sock=16
04/24/2018 02:23:39;0008;Server@node2;Job;12388.node2.supernodexp.hpc;Job Run at request of Scheduler@node2.supernodexp.hpc on exec_vnode (node14:ncpus=12:mem=5242880kb)
04/24/2018 02:23:39;0001;Server@node2;Svr;Server@node2;Success (0) in req_runjob2, return value of svr_startjob is 0
04/24/2018 02:23:39;0100;Server@node2;Req;;Type 23 request received from Scheduler@node2.supernodexp.hpc, sock=16
04/24/2018 02:23:39;0008;Server@node2;Job;12389.node2.supernodexp.hpc;Job Run at request of Scheduler@node2.supernodexp.hpc on exec_vnode (node14:ncpus=12:mem=20971520kb)
04/24/2018 02:23:39;0001;Server@node2;Svr;Server@node2;Success (0) in req_runjob2, return value of svr_startjob is 0
04/24/2018 02:23:39;0100;Server@node2;Req;;Type 23 request received from Scheduler@node2.supernodexp.hpc, sock=16
04/24/2018 02:23:39;0008;Server@node2;Job;12390.node2.supernodexp.hpc;Job Run at request of Scheduler@node2.supernodexp.hpc on exec_vnode (node13:ncpus=12:mem=20971520kb)
04/24/2018 02:23:39;0001;Server@node2;Svr;Server@node2;Success (0) in req_runjob2, return value of svr_startjob is 0
04/24/2018 02:23:39;0100;Server@node2;Req;;Type 11 request received from Scheduler@node2.supernodexp.hpc, sock=16
04/24/2018 02:23:39;0008;Server@node2;Job;12391.node2.supernodexp.hpc;Job Modified at request of Scheduler@node2.supernodexp.hpc
04/24/2018 02:23:46;0080;Server@node2;Job;12383.node2.supernodexp.hpc;Obit received momhop:1 serverhop:1 state:4 substate:42
04/24/2018 02:23:47;0010;Server@node2;Job;12383.node2.supernodexp.hpc;Exit_status=0 resources_used.cpupercent=0 resources_used.cput=00:00:00 resources_used.mem=0kb resources_used.ncpus=2 resources_used.vmem=0kb resources_used.walltime=00:00:08
04/24/2018 02:23:47;0100;Server@node2;Job;12383.node2.supernodexp.hpc;dequeuing from workq, state 5
04/24/2018 02:23:47;0040;Server@node2;Svr;node2.supernodexp.hpc;Scheduler sent command 2
04/24/2018 02:23:47;0040;Server@node2;Svr;node2.supernodexp.hpc;Scheduler sent command 0
04/24/2018 02:23:47;0100;Server@node2;Req;;Type 21 request received from Scheduler@node2.supernodexp.hpc, sock=16
04/24/2018 02:23:47;0100;Server@node2;Req;;Type 81 request received from Scheduler@node2.supernodexp.hpc, sock=16
04/24/2018 02:23:47;0100;Server@node2;Req;;Type 71 request received from Scheduler@node2.supernodexp.hpc, sock=16
04/24/2018 02:23:47;0100;Server@node2;Req;;Type 58 request received from Scheduler@node2.supernodexp.hpc, sock=16
04/24/2018 02:23:47;0100;Server@node2;Req;;Type 20 request received from Scheduler@node2.supernodexp.hpc, sock=16
04/24/2018 02:23:47;0100;Server@node2;Req;;Type 51 request received from Scheduler@node2.supernodexp.hpc, sock=16
04/24/2018 02:23:47;0100;Server@node2;Req;;Type 11 request received from Scheduler@node2.supernodexp.hpc, sock=16
04/24/2018 02:23:47;0008;Server@node2;Job;12391.node2.supernodexp.hpc;Job Modified at request of Scheduler@node2.supernodexp.hpc
04/24/2018 02:23:59;0080;Server@node2;Job;12384.node2.supernodexp.hpc;Obit received momhop:1 serverhop:1 state:4 substate:42
04/24/2018 02:24:00;0010;Server@node2;Job;12384.node2.supernodexp.hpc;Exit_status=0 resources_used.cpupercent=0 resources_used.cput=00:00:00 resources_used.mem=9096kb resources_used.ncpus=2 resources_used.vmem=105088kb resources_used.walltime=00:00:21
04/24/2018 02:24:00;0100;Server@node2;Job;12384.node2.supernodexp.hpc;dequeuing from workq, state 5
04/24/2018 02:24:00;0040;Server@node2;Svr;node2.supernodexp.hpc;Scheduler sent command 2
04/24/2018 02:24:00;0040;Server@node2;Svr;node2.supernodexp.hpc;Scheduler sent command 0
04/24/2018 02:24:00;0100;Server@node2;Req;;Type 21 request received from Scheduler@node2.supernodexp.hpc, sock=16
04/24/2018 02:24:00;0100;Server@node2;Req;;Type 81 request received from Scheduler@node2.supernodexp.hpc, sock=16
04/24/2018 02:24:00;0100;Server@node2;Req;;Type 71 request received from Scheduler@node2.supernodexp.hpc, sock=16
04/24/2018 02:24:00;0100;Server@node2;Req;;Type 58 request received from Scheduler@node2.supernodexp.hpc, sock=16
04/24/2018 02:24:00;0100;Server@node2;Req;;Type 20 request received from Scheduler@node2.supernodexp.hpc, sock=16
04/24/2018 02:24:00;0100;Server@node2;Req;;Type 51 request received from Scheduler@node2.supernodexp.hpc, sock=16
04/24/2018 02:24:00;0100;Server@node2;Req;;Type 11 request received from Scheduler@node2.supernodexp.hpc, sock=16
04/24/2018 02:24:00;0008;Server@node2;Job;12391.node2.supernodexp.hpc;Job Modified at request of Scheduler@node2.supernodexp.hpc
04/24/2018 02:24:13;0080;Server@node2;Job;12382.node2.supernodexp.hpc;Obit received momhop:1 serverhop:1 state:4 substate:42
04/24/2018 02:24:13;0010;Server@node2;Job;12382.node2.supernodexp.hpc;Exit_status=0 resources_used.cpupercent=0 resources_used.cput=00:00:00 resources_used.mem=9088kb resources_used.ncpus=8 resources_used.vmem=105344kb resources_used.walltime=00:00:34
04/24/2018 02:24:13;0100;Server@node2;Job;12382.node2.supernodexp.hpc;dequeuing from workq, state 5
04/24/2018 02:24:13;0040;Server@node2;Svr;node2.supernodexp.hpc;Scheduler sent command 2
04/24/2018 02:24:13;0040;Server@node2;Svr;node2.supernodexp.hpc;Scheduler sent command 0
04/24/2018 02:24:13;0100;Server@node2;Req;;Type 21 request received from Scheduler@node2.supernodexp.hpc, sock=16
04/24/2018 02:24:13;0100;Server@node2;Req;;Type 81 request received from Scheduler@node2.supernodexp.hpc, sock=16
04/24/2018 02:24:13;0100;Server@node2;Req;;Type 71 request received from Scheduler@node2.supernodexp.hpc, sock=16
04/24/2018 02:24:13;0100;Server@node2;Req;;Type 58 request received from Scheduler@node2.supernodexp.hpc, sock=16
04/24/2018 02:24:13;0100;Server@node2;Req;;Type 20 request received from Scheduler@node2.supernodexp.hpc, sock=16
04/24/2018 02:24:13;0100;Server@node2;Req;;Type 51 request received from Scheduler@node2.supernodexp.hpc, sock=16
04/24/2018 02:24:14;0100;Server@node2;Req;;Type 23 request received from Scheduler@node2.supernodexp.hpc, sock=16
04/24/2018 02:24:14;0008;Server@node2;Job;12391.node2.supernodexp.hpc;Job Run at request of Scheduler@node2.supernodexp.hpc on exec_vnode (node3:ncpus=12:mem=5242880kb)
04/24/2018 02:24:14;0001;Server@node2;Svr;Server@node2;Success (0) in req_runjob2, return value of svr_startjob is 0
04/24/2018 02:24:14;0100;Server@node2;Req;;Type 11 request received from Scheduler@node2.supernodexp.hpc, sock=16
04/24/2018 02:24:14;0008;Server@node2;Job;12392.node2.supernodexp.hpc;Job Modified at request of Scheduler@node2.supernodexp.hpc
04/24/2018 02:24:25;0080;Server@node2;Job;12386.node2.supernodexp.hpc;Obit received momhop:1 serverhop:1 state:4 substate:42
04/24/2018 02:24:26;0010;Server@node2;Job;12386.node2.supernodexp.hpc;Exit_status=0 resources_used.cpupercent=0 resources_used.cput=00:00:00 resources_used.mem=9080kb resources_used.ncpus=8 resources_used.vmem=172288kb resources_used.walltime=00:00:47
04/24/2018 02:24:26;0100;Server@node2;Job;12386.node2.supernodexp.hpc;dequeuing from workq, state 5
04/24/2018 02:24:26;0040;Server@node2;Svr;node2.supernodexp.hpc;Scheduler sent command 2
04/24/2018 02:24:26;0040;Server@node2;Svr;node2.supernodexp.hpc;Scheduler sent command 0
04/24/2018 02:24:26;0100;Server@node2;Req;;Type 21 request received from Scheduler@node2.supernodexp.hpc, sock=16
04/24/2018 02:24:26;0100;Server@node2;Req;;Type 81 request received from Scheduler@node2.supernodexp.hpc, sock=16
04/24/2018 02:24:26;0100;Server@node2;Req;;Type 71 request received from Scheduler@node2.supernodexp.hpc, sock=16
04/24/2018 02:24:26;0100;Server@node2;Req;;Type 58 request received from Scheduler@node2.supernodexp.hpc, sock=16
04/24/2018 02:24:26;0100;Server@node2;Req;;Type 20 request received from Scheduler@node2.supernodexp.hpc, sock=16
04/24/2018 02:24:26;0100;Server@node2;Req;;Type 51 request received from Scheduler@node2.supernodexp.hpc, sock=16
04/24/2018 02:24:26;0100;Server@node2;Req;;Type 23 request received from Scheduler@node2.supernodexp.hpc, sock=16
04/24/2018 02:24:26;0008;Server@node2;Job;12392.node2.supernodexp.hpc;Job Run at request of Scheduler@node2.supernodexp.hpc on exec_vnode (node3:ncpus=8:mem=20971520kb)
04/24/2018 02:24:26;0001;Server@node2;Svr;Server@node2;Success (0) in req_runjob2, return value of svr_startjob is 0
04/24/2018 02:24:26;0100;Server@node2;Req;;Type 23 request received from Scheduler@node2.supernodexp.hpc, sock=16
04/24/2018 02:24:26;0008;Server@node2;Job;12393.node2.supernodexp.hpc;Job Run at request of Scheduler@node2.supernodexp.hpc on exec_vnode (node13:ncpus=2:mem=2097152kb)
04/24/2018 02:24:26;0001;Server@node2;Svr;Server@node2;Success (0) in req_runjob2, return value of svr_startjob is 0
04/24/2018 02:24:26;0100;Server@node2;Req;;Type 11 request received from Scheduler@node2.supernodexp.hpc, sock=16
04/24/2018 02:24:26;0008;Server@node2;Job;12394.node2.supernodexp.hpc;Job Modified at request of Scheduler@node2.supernodexp.hpc
04/24/2018 02:24:29;0080;Server@node2;Job;12393.node2.supernodexp.hpc;Obit received momhop:1 serverhop:1 state:4 substate:42
04/24/2018 02:24:29;0010;Server@node2;Job;12393.node2.supernodexp.hpc;Exit_status=0 resources_used.cpupercent=0 resources_used.cput=00:00:00 resources_used.mem=0kb resources_used.ncpus=2 resources_used.vmem=0kb resources_used.walltime=00:00:03
04/24/2018 02:24:29;0100;Server@node2;Job;12393.node2.supernodexp.hpc;dequeuing from workq, state 5
04/24/2018 02:24:29;0040;Server@node2;Svr;node2.supernodexp.hpc;Scheduler sent command 2
04/24/2018 02:24:29;0040;Server@node2;Svr;node2.supernodexp.hpc;Scheduler sent command 0
04/24/2018 02:24:29;0100;Server@node2;Req;;Type 21 request received from Scheduler@node2.supernodexp.hpc, sock=16
04/24/2018 02:24:29;0100;Server@node2;Req;;Type 81 request received from Scheduler@node2.supernodexp.hpc, sock=16
04/24/2018 02:24:29;0100;Server@node2;Req;;Type 71 request received from Scheduler@node2.supernodexp.hpc, sock=16
04/24/2018 02:24:29;0100;Server@node2;Req;;Type 58 request received from Scheduler@node2.supernodexp.hpc, sock=16
04/24/2018 02:24:29;0100;Server@node2;Req;;Type 20 request received from Scheduler@node2.supernodexp.hpc, sock=16
04/24/2018 02:24:29;0100;Server@node2;Req;;Type 51 request received from Scheduler@node2.supernodexp.hpc, sock=16
04/24/2018 02:24:30;0100;Server@node2;Req;;Type 11 request received from Scheduler@node2.supernodexp.hpc, sock=16
04/24/2018 02:24:30;0008;Server@node2;Job;12394.node2.supernodexp.hpc;Job Modified at request of Scheduler@node2.supernodexp.hpc
04/24/2018 02:24:33;0080;Server@node2;Job;12392.node2.supernodexp.hpc;Obit received momhop:1 serverhop:1 state:4 substate:42
04/24/2018 02:24:34;0010;Server@node2;Job;12392.node2.supernodexp.hpc;Exit_status=0 resources_used.cpupercent=0 resources_used.cput=00:00:00 resources_used.mem=0kb resources_used.ncpus=8 resources_used.vmem=0kb resources_used.walltime=00:00:07
04/24/2018 02:24:34;0100;Server@node2;Job;12392.node2.supernodexp.hpc;dequeuing from workq, state 5
04/24/2018 02:24:34;0040;Server@node2;Svr;node2.supernodexp.hpc;Scheduler sent command 2
04/24/2018 02:24:34;0040;Server@node2;Svr;node2.supernodexp.hpc;Scheduler sent command 0
04/24/2018 02:24:34;0100;Server@node2;Req;;Type 21 request received from Scheduler@node2.supernodexp.hpc, sock=16
04/24/2018 02:24:34;0100;Server@node2;Req;;Type 81 request received from Scheduler@node2.supernodexp.hpc, sock=16
04/24/2018 02:24:34;0100;Server@node2;Req;;Type 71 request received from Scheduler@node2.supernodexp.hpc, sock=16
04/24/2018 02:24:34;0100;Server@node2;Req;;Type 58 request received from Scheduler@node2.supernodexp.hpc, sock=16
04/24/2018 02:24:34;0100;Server@node2;Req;;Type 20 request received from Scheduler@node2.supernodexp.hpc, sock=16
04/24/2018 02:24:34;0100;Server@node2;Req;;Type 51 request received from Scheduler@node2.supernodexp.hpc, sock=16
04/24/2018 02:24:34;0100;Server@node2;Req;;Type 23 request received from Scheduler@node2.supernodexp.hpc, sock=16
04/24/2018 02:24:34;0008;Server@node2;Job;12394.node2.supernodexp.hpc;Job Run at request of Scheduler@node2.supernodexp.hpc on exec_vnode (node3:ncpus=8:mem=15728640kb)
04/24/2018 02:24:34;0001;Server@node2;Svr;Server@node2;Success (0) in req_runjob2, return value of svr_startjob is 0
04/24/2018 02:24:34;0100;Server@node2;Req;;Type 11 request received from Scheduler@node2.supernodexp.hpc, sock=16
04/24/2018 02:24:34;0008;Server@node2;Job;12395.node2.supernodexp.hpc;Job Modified at request of Scheduler@node2.supernodexp.hpc
04/24/2018 02:26:46;0080;Server@node2;Job;12380.node2.supernodexp.hpc;Obit received momhop:1 serverhop:1 state:4 substate:42
04/24/2018 02:26:47;0010;Server@node2;Job;12380.node2.supernodexp.hpc;Exit_status=0 resources_used.cpupercent=0 resources_used.cput=00:00:00 resources_used.mem=9156kb resources_used.ncpus=8 resources_used.vmem=37500kb resources_used.walltime=00:10:27
04/24/2018 02:26:47;0100;Server@node2;Job;12380.node2.supernodexp.hpc;dequeuing from workq, state 5
04/24/2018 02:26:47;0040;Server@node2;Svr;node2.supernodexp.hpc;Scheduler sent command 2
04/24/2018 02:26:47;0040;Server@node2;Svr;node2.supernodexp.hpc;Scheduler sent command 0
04/24/2018 02:26:47;0100;Server@node2;Req;;Type 21 request received from Scheduler@node2.supernodexp.hpc, sock=16
04/24/2018 02:26:47;0100;Server@node2;Req;;Type 81 request received from Scheduler@node2.supernodexp.hpc, sock=16
04/24/2018 02:26:47;0100;Server@node2;Req;;Type 71 request received from Scheduler@node2.supernodexp.hpc, sock=16
04/24/2018 02:26:47;0100;Server@node2;Req;;Type 58 request received from Scheduler@node2.supernodexp.hpc, sock=16
04/24/2018 02:26:47;0100;Server@node2;Req;;Type 20 request received from Scheduler@node2.supernodexp.hpc, sock=16
04/24/2018 02:26:47;0100;Server@node2;Req;;Type 51 request received from Scheduler@node2.supernodexp.hpc, sock=16
04/24/2018 02:26:47;0100;Server@node2;Req;;Type 23 request received from Scheduler@node2.supernodexp.hpc, sock=16
04/24/2018 02:26:47;0008;Server@node2;Job;12395.node2.supernodexp.hpc;Job Run at request of Scheduler@node2.supernodexp.hpc on exec_vnode (node3:ncpus=8:mem=15728640kb)
04/24/2018 02:26:47;0001;Server@node2;Svr;Server@node2;Success (0) in req_runjob2, return value of svr_startjob is 0
04/24/2018 02:26:47;0100;Server@node2;Req;;Type 11 request received from Scheduler@node2.supernodexp.hpc, sock=16
04/24/2018 02:26:47;0008;Server@node2;Job;12396.node2.supernodexp.hpc;Job Modified at request of Scheduler@node2.supernodexp.hpc
04/24/2018 02:29:08;0080;Server@node2;Job;12390.node2.supernodexp.hpc;Obit received momhop:1 serverhop:1 state:4 substate:42
04/24/2018 02:29:09;0010;Server@node2;Job;12390.node2.supernodexp.hpc;Exit_status=0 resources_used.cpupercent=0 resources_used.cput=00:00:00 resources_used.mem=9628kb resources_used.ncpus=12 resources_used.vmem=104628kb resources_used.walltime=00:05:30
04/24/2018 02:29:09;0100;Server@node2;Job;12390.node2.supernodexp.hpc;dequeuing from workq, state 5
04/24/2018 02:29:09;0040;Server@node2;Svr;node2.supernodexp.hpc;Scheduler sent command 2
04/24/2018 02:29:09;0040;Server@node2;Svr;node2.supernodexp.hpc;Scheduler sent command 0
04/24/2018 02:29:09;0100;Server@node2;Req;;Type 21 request received from Scheduler@node2.supernodexp.hpc, sock=16
04/24/2018 02:29:09;0100;Server@node2;Req;;Type 81 request received from Scheduler@node2.supernodexp.hpc, sock=16
04/24/2018 02:29:09;0100;Server@node2;Req;;Type 71 request received from Scheduler@node2.supernodexp.hpc, sock=16
04/24/2018 02:29:09;0100;Server@node2;Req;;Type 58 request received from Scheduler@node2.supernodexp.hpc, sock=16
04/24/2018 02:29:10;0100;Server@node2;Req;;Type 20 request received from Scheduler@node2.supernodexp.hpc, sock=16
04/24/2018 02:29:10;0100;Server@node2;Req;;Type 51 request received from Scheduler@node2.supernodexp.hpc, sock=16
04/24/2018 02:29:10;0100;Server@node2;Req;;Type 23 request received from Scheduler@node2.supernodexp.hpc, sock=16
04/24/2018 02:29:10;0008;Server@node2;Job;12396.node2.supernodexp.hpc;Job Run at request of Scheduler@node2.supernodexp.hpc on exec_vnode (node13:ncpus=8:mem=20971520kb)
04/24/2018 02:29:10;0001;Server@node2;Svr;Server@node2;Success (0) in req_runjob2, return value of svr_startjob is 0
04/24/2018 02:29:10;0100;Server@node2;Req;;Type 23 request received from Scheduler@node2.supernodexp.hpc, sock=16
04/24/2018 02:29:10;0008;Server@node2;Job;12397.node2.supernodexp.hpc;Job Run at request of Scheduler@node2.supernodexp.hpc on exec_vnode (node13:ncpus=8:mem=5242880kb)
04/24/2018 02:29:10;0001;Server@node2;Svr;Server@node2;Success (0) in req_runjob2, return value of svr_startjob is 0
04/24/2018 02:29:10;0100;Server@node2;Req;;Type 11 request received from Scheduler@node2.supernodexp.hpc, sock=16
04/24/2018 02:29:10;0008;Server@node2;Job;12398.node2.supernodexp.hpc;Job Modified at request of Scheduler@node2.supernodexp.hpc
04/24/2018 02:29:14;0080;Server@node2;Job;12396.node2.supernodexp.hpc;Obit received momhop:1 serverhop:1 state:4 substate:42
04/24/2018 02:29:15;0010;Server@node2;Job;12396.node2.supernodexp.hpc;Exit_status=0 resources_used.cpupercent=0 resources_used.cput=00:00:00 resources_used.mem=0kb resources_used.ncpus=8 resources_used.vmem=0kb resources_used.walltime=00:00:05
04/24/2018 02:29:15;0100;Server@node2;Job;12396.node2.supernodexp.hpc;dequeuing from workq, state 5
04/24/2018 02:29:15;0040;Server@node2;Svr;node2.supernodexp.hpc;Scheduler sent command 2
04/24/2018 02:29:15;0040;Server@node2;Svr;node2.supernodexp.hpc;Scheduler sent command 0
04/24/2018 02:29:15;0100;Server@node2;Req;;Type 21 request received from Scheduler@node2.supernodexp.hpc, sock=16
04/24/2018 02:29:15;0100;Server@node2;Req;;Type 81 request received from Scheduler@node2.supernodexp.hpc, sock=16
04/24/2018 02:29:15;0100;Server@node2;Req;;Type 71 request received from Scheduler@node2.supernodexp.hpc, sock=16
04/24/2018 02:29:15;0100;Server@node2;Req;;Type 58 request received from Scheduler@node2.supernodexp.hpc, sock=16
04/24/2018 02:29:15;0100;Server@node2;Req;;Type 20 request received from Scheduler@node2.supernodexp.hpc, sock=16
04/24/2018 02:29:15;0100;Server@node2;Req;;Type 51 request received from Scheduler@node2.supernodexp.hpc, sock=16
04/24/2018 02:29:15;0100;Server@node2;Req;;Type 11 request received from Scheduler@node2.supernodexp.hpc, sock=16
04/24/2018 02:29:15;0008;Server@node2;Job;12398.node2.supernodexp.hpc;Job Modified at request of Scheduler@node2.supernodexp.hpc
04/24/2018 02:29:25;0080;Server@node2;Job;12397.node2.supernodexp.hpc;Obit received momhop:1 serverhop:1 state:4 substate:42
04/24/2018 02:29:26;0010;Server@node2;Job;12397.node2.supernodexp.hpc;Exit_status=0 resources_used.cpupercent=0 resources_used.cput=00:00:00 resources_used.mem=9412kb resources_used.ncpus=8 resources_used.vmem=171960kb resources_used.walltime=00:00:15
04/24/2018 02:29:26;0100;Server@node2;Job;12397.node2.supernodexp.hpc;dequeuing from workq, state 5
04/24/2018 02:29:26;0040;Server@node2;Svr;node2.supernodexp.hpc;Scheduler sent command 2
04/24/2018 02:29:26;0040;Server@node2;Svr;node2.supernodexp.hpc;Scheduler sent command 0
04/24/2018 02:29:26;0100;Server@node2;Req;;Type 21 request received from Scheduler@node2.supernodexp.hpc, sock=16
04/24/2018 02:29:26;0100;Server@node2;Req;;Type 81 request received from Scheduler@node2.supernodexp.hpc, sock=16
04/24/2018 02:29:26;0100;Server@node2;Req;;Type 71 request received from Scheduler@node2.supernodexp.hpc, sock=16
04/24/2018 02:29:26;0100;Server@node2;Req;;Type 58 request received from Scheduler@node2.supernodexp.hpc, sock=16
04/24/2018 02:29:26;0100;Server@node2;Req;;Type 20 request received from Scheduler@node2.supernodexp.hpc, sock=16
