05/04/2018 00:00:00;0002;Server@node2;Svr;Log;Log opened
05/04/2018 00:00:00;0002;Server@node2;Svr;Server@node2;pbs_version=14.0.1
05/04/2018 00:00:00;0002;Server@node2;Svr;Server@node2;pbs_build=mach=N/A:security=N/A:configure_args=N/A
05/04/2018 00:00:00;0002;Server@node2;Svr;Server@node2;hostname=node2.supernodexp.hpc;pbs_leaf_name=N/A;pbs_mom_node_name=N/A
05/04/2018 00:00:00;0002;Server@node2;Svr;Server@node2;ipv4 interface lo: localhost localhost.localdomain localhost4 localhost4.localdomain4 
05/04/2018 00:00:00;0002;Server@node2;Svr;Server@node2;ipv4 interface br0: node2.supernodexp.hpc node2 supernodexp-cn02 
05/04/2018 00:00:00;0002;Server@node2;Svr;Server@node2;ipv4 interface ib0: node2.supernodexp.hpc 
05/04/2018 00:00:00;0002;Server@node2;Svr;Server@node2;ipv4 interface virbr0: node2.supernodexp.hpc 
05/04/2018 00:00:00;0002;Server@node2;Svr;Server@node2;ipv4 interface docker0: node2.supernodexp.hpc 
05/04/2018 00:00:00;0002;Server@node2;Svr;Server@node2;ipv6 interface lo: localhost localhost.localdomain localhost6 localhost6.localdomain6 
05/04/2018 00:00:00;0002;Server@node2;Svr;Server@node2;ipv6 interface eno49: node2.supernodexp.hpc 
05/04/2018 00:00:00;0002;Server@node2;Svr;Server@node2;ipv6 interface br0: node2.supernodexp.hpc 
05/04/2018 00:00:00;0002;Server@node2;Svr;Server@node2;ipv6 interface ib0: node2.supernodexp.hpc 
05/04/2018 00:00:00;0002;Server@node2;Svr;Server@node2;ipv6 interface veth1pl8819: node2.supernodexp.hpc 
05/04/2018 00:00:00;0002;Server@node2;Svr;Act;Account file /var/spool/pbs/server_priv/accounting/20180504 opened
05/04/2018 00:01:46;0080;Server@node2;Job;14440.node2.supernodexp.hpc;Obit received momhop:1 serverhop:1 state:4 substate:42
05/04/2018 00:01:47;0010;Server@node2;Job;14440.node2.supernodexp.hpc;Exit_status=2 resources_used.cpupercent=0 resources_used.cput=00:00:00 resources_used.mem=9180kb resources_used.ncpus=32 resources_used.vmem=103036kb resources_used.walltime=00:20:07
05/04/2018 00:01:47;0100;Server@node2;Job;14440.node2.supernodexp.hpc;dequeuing from workq, state 5
05/04/2018 00:01:47;0040;Server@node2;Svr;node2.supernodexp.hpc;Scheduler sent command 2
05/04/2018 00:01:47;0040;Server@node2;Svr;node2.supernodexp.hpc;Scheduler sent command 0
05/04/2018 00:01:47;0100;Server@node2;Req;;Type 21 request received from Scheduler@node2.supernodexp.hpc, sock=16
05/04/2018 00:01:47;0100;Server@node2;Req;;Type 81 request received from Scheduler@node2.supernodexp.hpc, sock=16
05/04/2018 00:01:47;0100;Server@node2;Req;;Type 71 request received from Scheduler@node2.supernodexp.hpc, sock=16
05/04/2018 00:01:47;0100;Server@node2;Req;;Type 58 request received from Scheduler@node2.supernodexp.hpc, sock=16
05/04/2018 00:01:47;0100;Server@node2;Req;;Type 20 request received from Scheduler@node2.supernodexp.hpc, sock=16
05/04/2018 00:01:47;0100;Server@node2;Req;;Type 51 request received from Scheduler@node2.supernodexp.hpc, sock=16
05/04/2018 00:01:47;0100;Server@node2;Req;;Type 23 request received from Scheduler@node2.supernodexp.hpc, sock=16
05/04/2018 00:01:47;0008;Server@node2;Job;14482.node2.supernodexp.hpc;Job Run at request of Scheduler@node2.supernodexp.hpc on exec_vnode (node3:ncpus=32:nmics=2:mem=31457280kb)
05/04/2018 00:01:47;0001;Server@node2;Svr;Server@node2;Success (0) in req_runjob2, return value of svr_startjob is 0
05/04/2018 00:01:47;0100;Server@node2;Req;;Type 11 request received from Scheduler@node2.supernodexp.hpc, sock=16
05/04/2018 00:01:47;0008;Server@node2;Job;14483.node2.supernodexp.hpc;Job Modified at request of Scheduler@node2.supernodexp.hpc
05/04/2018 00:11:47;0040;Server@node2;Svr;node2.supernodexp.hpc;Scheduler sent command 3
05/04/2018 00:11:47;0040;Server@node2;Svr;node2.supernodexp.hpc;Scheduler sent command 0
05/04/2018 00:11:47;0100;Server@node2;Req;;Type 21 request received from Scheduler@node2.supernodexp.hpc, sock=16
05/04/2018 00:11:47;0100;Server@node2;Req;;Type 81 request received from Scheduler@node2.supernodexp.hpc, sock=16
05/04/2018 00:11:47;0100;Server@node2;Req;;Type 71 request received from Scheduler@node2.supernodexp.hpc, sock=16
05/04/2018 00:11:47;0100;Server@node2;Req;;Type 58 request received from Scheduler@node2.supernodexp.hpc, sock=16
05/04/2018 00:11:47;0100;Server@node2;Req;;Type 20 request received from Scheduler@node2.supernodexp.hpc, sock=16
05/04/2018 00:11:47;0100;Server@node2;Req;;Type 51 request received from Scheduler@node2.supernodexp.hpc, sock=16
05/04/2018 00:15:19;0080;Server@node2;Job;14441.node2.supernodexp.hpc;Obit received momhop:1 serverhop:1 state:4 substate:42
05/04/2018 00:15:20;0010;Server@node2;Job;14441.node2.supernodexp.hpc;Exit_status=2 resources_used.cpupercent=0 resources_used.cput=00:00:00 resources_used.mem=10020kb resources_used.ncpus=32 resources_used.vmem=172216kb resources_used.walltime=00:19:02
05/04/2018 00:15:20;0100;Server@node2;Job;14441.node2.supernodexp.hpc;dequeuing from workq, state 5
05/04/2018 00:15:20;0040;Server@node2;Svr;node2.supernodexp.hpc;Scheduler sent command 2
05/04/2018 00:15:20;0040;Server@node2;Svr;node2.supernodexp.hpc;Scheduler sent command 0
05/04/2018 00:15:20;0100;Server@node2;Req;;Type 21 request received from Scheduler@node2.supernodexp.hpc, sock=16
05/04/2018 00:15:20;0100;Server@node2;Req;;Type 81 request received from Scheduler@node2.supernodexp.hpc, sock=16
05/04/2018 00:15:20;0100;Server@node2;Req;;Type 71 request received from Scheduler@node2.supernodexp.hpc, sock=16
05/04/2018 00:15:20;0100;Server@node2;Req;;Type 58 request received from Scheduler@node2.supernodexp.hpc, sock=16
05/04/2018 00:15:20;0100;Server@node2;Req;;Type 20 request received from Scheduler@node2.supernodexp.hpc, sock=16
05/04/2018 00:15:20;0100;Server@node2;Req;;Type 51 request received from Scheduler@node2.supernodexp.hpc, sock=16
05/04/2018 00:15:20;0100;Server@node2;Req;;Type 23 request received from Scheduler@node2.supernodexp.hpc, sock=16
05/04/2018 00:15:20;0008;Server@node2;Job;14483.node2.supernodexp.hpc;Job Run at request of Scheduler@node2.supernodexp.hpc on exec_vnode (node14:ncpus=32:nmics=2:mem=31457280kb)
05/04/2018 00:15:20;0001;Server@node2;Svr;Server@node2;Success (0) in req_runjob2, return value of svr_startjob is 0
05/04/2018 00:15:20;0100;Server@node2;Req;;Type 11 request received from Scheduler@node2.supernodexp.hpc, sock=16
05/04/2018 00:15:20;0008;Server@node2;Job;14497.node2.supernodexp.hpc;Job Modified at request of Scheduler@node2.supernodexp.hpc
05/04/2018 00:16:06;0080;Server@node2;Job;14460.node2.supernodexp.hpc;Obit received momhop:1 serverhop:1 state:4 substate:42
05/04/2018 00:16:07;0010;Server@node2;Job;14460.node2.supernodexp.hpc;Exit_status=2 resources_used.cpupercent=0 resources_used.cput=00:00:00 resources_used.mem=9996kb resources_used.ncpus=32 resources_used.vmem=171960kb resources_used.walltime=00:18:56
05/04/2018 00:16:07;0100;Server@node2;Job;14460.node2.supernodexp.hpc;dequeuing from workq, state 5
05/04/2018 00:16:07;0040;Server@node2;Svr;node2.supernodexp.hpc;Scheduler sent command 2
05/04/2018 00:16:07;0040;Server@node2;Svr;node2.supernodexp.hpc;Scheduler sent command 0
05/04/2018 00:16:07;0100;Server@node2;Req;;Type 21 request received from Scheduler@node2.supernodexp.hpc, sock=16
05/04/2018 00:16:07;0100;Server@node2;Req;;Type 81 request received from Scheduler@node2.supernodexp.hpc, sock=16
05/04/2018 00:16:07;0100;Server@node2;Req;;Type 71 request received from Scheduler@node2.supernodexp.hpc, sock=16
05/04/2018 00:16:07;0100;Server@node2;Req;;Type 58 request received from Scheduler@node2.supernodexp.hpc, sock=16
05/04/2018 00:16:07;0100;Server@node2;Req;;Type 20 request received from Scheduler@node2.supernodexp.hpc, sock=16
05/04/2018 00:16:07;0100;Server@node2;Req;;Type 51 request received from Scheduler@node2.supernodexp.hpc, sock=16
05/04/2018 00:16:07;0100;Server@node2;Req;;Type 23 request received from Scheduler@node2.supernodexp.hpc, sock=16
05/04/2018 00:16:07;0008;Server@node2;Job;14497.node2.supernodexp.hpc;Job Run at request of Scheduler@node2.supernodexp.hpc on exec_vnode (node13:ncpus=32:nmics=2:mem=31457280kb)
05/04/2018 00:16:07;0001;Server@node2;Svr;Server@node2;Success (0) in req_runjob2, return value of svr_startjob is 0
05/04/2018 00:16:07;0100;Server@node2;Req;;Type 11 request received from Scheduler@node2.supernodexp.hpc, sock=16
05/04/2018 00:16:07;0008;Server@node2;Job;14506.node2.supernodexp.hpc;Job Modified at request of Scheduler@node2.supernodexp.hpc
05/04/2018 00:22:02;0080;Server@node2;Job;14482.node2.supernodexp.hpc;Obit received momhop:1 serverhop:1 state:4 substate:42
05/04/2018 00:22:03;0010;Server@node2;Job;14482.node2.supernodexp.hpc;Exit_status=2 resources_used.cpupercent=0 resources_used.cput=00:00:00 resources_used.mem=9452kb resources_used.ncpus=32 resources_used.vmem=103292kb resources_used.walltime=00:20:15
05/04/2018 00:22:03;0100;Server@node2;Job;14482.node2.supernodexp.hpc;dequeuing from workq, state 5
05/04/2018 00:22:03;0040;Server@node2;Svr;node2.supernodexp.hpc;Scheduler sent command 2
05/04/2018 00:22:03;0040;Server@node2;Svr;node2.supernodexp.hpc;Scheduler sent command 0
05/04/2018 00:22:03;0100;Server@node2;Req;;Type 21 request received from Scheduler@node2.supernodexp.hpc, sock=16
05/04/2018 00:22:03;0100;Server@node2;Req;;Type 81 request received from Scheduler@node2.supernodexp.hpc, sock=16
05/04/2018 00:22:03;0100;Server@node2;Req;;Type 71 request received from Scheduler@node2.supernodexp.hpc, sock=16
05/04/2018 00:22:03;0100;Server@node2;Req;;Type 58 request received from Scheduler@node2.supernodexp.hpc, sock=16
05/04/2018 00:22:03;0100;Server@node2;Req;;Type 20 request received from Scheduler@node2.supernodexp.hpc, sock=16
05/04/2018 00:22:03;0100;Server@node2;Req;;Type 51 request received from Scheduler@node2.supernodexp.hpc, sock=16
05/04/2018 00:22:03;0100;Server@node2;Req;;Type 23 request received from Scheduler@node2.supernodexp.hpc, sock=16
05/04/2018 00:22:03;0008;Server@node2;Job;14506.node2.supernodexp.hpc;Job Run at request of Scheduler@node2.supernodexp.hpc on exec_vnode (node3:ncpus=32:nmics=2:mem=31457280kb)
05/04/2018 00:22:03;0001;Server@node2;Svr;Server@node2;Success (0) in req_runjob2, return value of svr_startjob is 0
05/04/2018 00:22:03;0100;Server@node2;Req;;Type 11 request received from Scheduler@node2.supernodexp.hpc, sock=16
05/04/2018 00:22:03;0008;Server@node2;Job;14511.node2.supernodexp.hpc;Job Modified at request of Scheduler@node2.supernodexp.hpc
05/04/2018 00:32:03;0040;Server@node2;Svr;node2.supernodexp.hpc;Scheduler sent command 3
05/04/2018 00:32:03;0040;Server@node2;Svr;node2.supernodexp.hpc;Scheduler sent command 0
05/04/2018 00:32:03;0100;Server@node2;Req;;Type 21 request received from Scheduler@node2.supernodexp.hpc, sock=16
05/04/2018 00:32:03;0100;Server@node2;Req;;Type 81 request received from Scheduler@node2.supernodexp.hpc, sock=16
05/04/2018 00:32:03;0100;Server@node2;Req;;Type 71 request received from Scheduler@node2.supernodexp.hpc, sock=16
05/04/2018 00:32:03;0100;Server@node2;Req;;Type 58 request received from Scheduler@node2.supernodexp.hpc, sock=16
05/04/2018 00:32:03;0100;Server@node2;Req;;Type 20 request received from Scheduler@node2.supernodexp.hpc, sock=16
05/04/2018 00:32:03;0100;Server@node2;Req;;Type 51 request received from Scheduler@node2.supernodexp.hpc, sock=16
05/04/2018 00:34:07;0080;Server@node2;Job;14483.node2.supernodexp.hpc;Obit received momhop:1 serverhop:1 state:4 substate:42
05/04/2018 00:34:08;0010;Server@node2;Job;14483.node2.supernodexp.hpc;Exit_status=2 resources_used.cpupercent=0 resources_used.cput=00:00:00 resources_used.mem=11916kb resources_used.ncpus=32 resources_used.vmem=1013176kb resources_used.walltime=00:18:47
05/04/2018 00:34:08;0100;Server@node2;Job;14483.node2.supernodexp.hpc;dequeuing from workq, state 5
05/04/2018 00:34:08;0040;Server@node2;Svr;node2.supernodexp.hpc;Scheduler sent command 2
05/04/2018 00:34:08;0040;Server@node2;Svr;node2.supernodexp.hpc;Scheduler sent command 0
05/04/2018 00:34:08;0100;Server@node2;Req;;Type 21 request received from Scheduler@node2.supernodexp.hpc, sock=16
05/04/2018 00:34:08;0100;Server@node2;Req;;Type 81 request received from Scheduler@node2.supernodexp.hpc, sock=16
05/04/2018 00:34:08;0100;Server@node2;Req;;Type 71 request received from Scheduler@node2.supernodexp.hpc, sock=16
05/04/2018 00:34:08;0100;Server@node2;Req;;Type 58 request received from Scheduler@node2.supernodexp.hpc, sock=16
05/04/2018 00:34:08;0100;Server@node2;Req;;Type 20 request received from Scheduler@node2.supernodexp.hpc, sock=16
05/04/2018 00:34:08;0100;Server@node2;Req;;Type 51 request received from Scheduler@node2.supernodexp.hpc, sock=16
05/04/2018 00:34:08;0100;Server@node2;Req;;Type 23 request received from Scheduler@node2.supernodexp.hpc, sock=16
05/04/2018 00:34:08;0008;Server@node2;Job;14511.node2.supernodexp.hpc;Job Run at request of Scheduler@node2.supernodexp.hpc on exec_vnode (node14:ncpus=32:nmics=2:mem=31457280kb)
05/04/2018 00:34:08;0001;Server@node2;Svr;Server@node2;Success (0) in req_runjob2, return value of svr_startjob is 0
05/04/2018 00:34:08;0100;Server@node2;Req;;Type 11 request received from Scheduler@node2.supernodexp.hpc, sock=16
05/04/2018 00:34:08;0008;Server@node2;Job;14540.node2.supernodexp.hpc;Job Modified at request of Scheduler@node2.supernodexp.hpc
05/04/2018 00:34:54;0080;Server@node2;Job;14497.node2.supernodexp.hpc;Obit received momhop:1 serverhop:1 state:4 substate:42
05/04/2018 00:34:55;0010;Server@node2;Job;14497.node2.supernodexp.hpc;Exit_status=2 resources_used.cpupercent=0 resources_used.cput=00:00:00 resources_used.mem=10220kb resources_used.ncpus=32 resources_used.vmem=104628kb resources_used.walltime=00:18:48
05/04/2018 00:34:55;0100;Server@node2;Job;14497.node2.supernodexp.hpc;dequeuing from workq, state 5
05/04/2018 00:34:55;0040;Server@node2;Svr;node2.supernodexp.hpc;Scheduler sent command 2
05/04/2018 00:34:55;0040;Server@node2;Svr;node2.supernodexp.hpc;Scheduler sent command 0
05/04/2018 00:34:55;0100;Server@node2;Req;;Type 21 request received from Scheduler@node2.supernodexp.hpc, sock=16
05/04/2018 00:34:55;0100;Server@node2;Req;;Type 81 request received from Scheduler@node2.supernodexp.hpc, sock=16
05/04/2018 00:34:55;0100;Server@node2;Req;;Type 71 request received from Scheduler@node2.supernodexp.hpc, sock=16
05/04/2018 00:34:55;0100;Server@node2;Req;;Type 58 request received from Scheduler@node2.supernodexp.hpc, sock=16
05/04/2018 00:34:55;0100;Server@node2;Req;;Type 20 request received from Scheduler@node2.supernodexp.hpc, sock=16
05/04/2018 00:34:55;0100;Server@node2;Req;;Type 51 request received from Scheduler@node2.supernodexp.hpc, sock=16
05/04/2018 00:34:55;0100;Server@node2;Req;;Type 23 request received from Scheduler@node2.supernodexp.hpc, sock=16
05/04/2018 00:34:55;0008;Server@node2;Job;14540.node2.supernodexp.hpc;Job Run at request of Scheduler@node2.supernodexp.hpc on exec_vnode (node13:ncpus=32:nmics=2:mem=31457280kb)
05/04/2018 00:34:55;0001;Server@node2;Svr;Server@node2;Success (0) in req_runjob2, return value of svr_startjob is 0
05/04/2018 00:34:55;0100;Server@node2;Req;;Type 11 request received from Scheduler@node2.supernodexp.hpc, sock=16
05/04/2018 00:34:55;0008;Server@node2;Job;14555.node2.supernodexp.hpc;Job Modified at request of Scheduler@node2.supernodexp.hpc
05/04/2018 00:42:27;0080;Server@node2;Job;14506.node2.supernodexp.hpc;Obit received momhop:1 serverhop:1 state:4 substate:42
05/04/2018 00:42:28;0010;Server@node2;Job;14506.node2.supernodexp.hpc;Exit_status=2 resources_used.cpupercent=0 resources_used.cput=00:00:00 resources_used.mem=9428kb resources_used.ncpus=32 resources_used.vmem=170880kb resources_used.walltime=00:20:24
05/04/2018 00:42:28;0100;Server@node2;Job;14506.node2.supernodexp.hpc;dequeuing from workq, state 5
05/04/2018 00:42:28;0040;Server@node2;Svr;node2.supernodexp.hpc;Scheduler sent command 2
05/04/2018 00:42:28;0040;Server@node2;Svr;node2.supernodexp.hpc;Scheduler sent command 0
05/04/2018 00:42:28;0100;Server@node2;Req;;Type 21 request received from Scheduler@node2.supernodexp.hpc, sock=16
05/04/2018 00:42:28;0100;Server@node2;Req;;Type 81 request received from Scheduler@node2.supernodexp.hpc, sock=16
05/04/2018 00:42:28;0100;Server@node2;Req;;Type 71 request received from Scheduler@node2.supernodexp.hpc, sock=16
05/04/2018 00:42:28;0100;Server@node2;Req;;Type 58 request received from Scheduler@node2.supernodexp.hpc, sock=16
05/04/2018 00:42:28;0100;Server@node2;Req;;Type 20 request received from Scheduler@node2.supernodexp.hpc, sock=16
05/04/2018 00:42:28;0100;Server@node2;Req;;Type 51 request received from Scheduler@node2.supernodexp.hpc, sock=16
05/04/2018 00:42:28;0100;Server@node2;Req;;Type 23 request received from Scheduler@node2.supernodexp.hpc, sock=16
05/04/2018 00:42:28;0008;Server@node2;Job;14555.node2.supernodexp.hpc;Job Run at request of Scheduler@node2.supernodexp.hpc on exec_vnode (node3:ncpus=32:nmics=2:mem=31457280kb)
05/04/2018 00:42:28;0001;Server@node2;Svr;Server@node2;Success (0) in req_runjob2, return value of svr_startjob is 0
05/04/2018 00:42:28;0100;Server@node2;Req;;Type 11 request received from Scheduler@node2.supernodexp.hpc, sock=16
05/04/2018 00:42:28;0008;Server@node2;Job;14614.node2.supernodexp.hpc;Job Modified at request of Scheduler@node2.supernodexp.hpc
05/04/2018 00:52:28;0040;Server@node2;Svr;node2.supernodexp.hpc;Scheduler sent command 3
05/04/2018 00:52:28;0040;Server@node2;Svr;node2.supernodexp.hpc;Scheduler sent command 0
05/04/2018 00:52:28;0100;Server@node2;Req;;Type 21 request received from Scheduler@node2.supernodexp.hpc, sock=16
05/04/2018 00:52:28;0100;Server@node2;Req;;Type 81 request received from Scheduler@node2.supernodexp.hpc, sock=16
05/04/2018 00:52:28;0100;Server@node2;Req;;Type 71 request received from Scheduler@node2.supernodexp.hpc, sock=16
05/04/2018 00:52:28;0100;Server@node2;Req;;Type 58 request received from Scheduler@node2.supernodexp.hpc, sock=16
05/04/2018 00:52:28;0100;Server@node2;Req;;Type 20 request received from Scheduler@node2.supernodexp.hpc, sock=16
05/04/2018 00:52:28;0100;Server@node2;Req;;Type 51 request received from Scheduler@node2.supernodexp.hpc, sock=16
05/04/2018 00:52:49;0080;Server@node2;Job;14511.node2.supernodexp.hpc;Obit received momhop:1 serverhop:1 state:4 substate:42
05/04/2018 00:52:50;0010;Server@node2;Job;14511.node2.supernodexp.hpc;Exit_status=2 resources_used.cpupercent=0 resources_used.cput=00:00:00 resources_used.mem=10000kb resources_used.ncpus=32 resources_used.vmem=169908kb resources_used.walltime=00:18:41
05/04/2018 00:52:50;0100;Server@node2;Job;14511.node2.supernodexp.hpc;dequeuing from workq, state 5
05/04/2018 00:52:50;0040;Server@node2;Svr;node2.supernodexp.hpc;Scheduler sent command 2
05/04/2018 00:52:50;0040;Server@node2;Svr;node2.supernodexp.hpc;Scheduler sent command 0
05/04/2018 00:52:50;0100;Server@node2;Req;;Type 21 request received from Scheduler@node2.supernodexp.hpc, sock=16
05/04/2018 00:52:50;0100;Server@node2;Req;;Type 81 request received from Scheduler@node2.supernodexp.hpc, sock=16
05/04/2018 00:52:50;0100;Server@node2;Req;;Type 71 request received from Scheduler@node2.supernodexp.hpc, sock=16
05/04/2018 00:52:50;0100;Server@node2;Req;;Type 58 request received from Scheduler@node2.supernodexp.hpc, sock=16
05/04/2018 00:52:50;0100;Server@node2;Req;;Type 20 request received from Scheduler@node2.supernodexp.hpc, sock=16
05/04/2018 00:52:50;0100;Server@node2;Req;;Type 51 request received from Scheduler@node2.supernodexp.hpc, sock=16
05/04/2018 00:52:50;0100;Server@node2;Req;;Type 23 request received from Scheduler@node2.supernodexp.hpc, sock=16
05/04/2018 00:52:50;0008;Server@node2;Job;14614.node2.supernodexp.hpc;Job Run at request of Scheduler@node2.supernodexp.hpc on exec_vnode (node14:ncpus=32:nmics=2:mem=31457280kb)
05/04/2018 00:52:50;0001;Server@node2;Svr;Server@node2;Success (0) in req_runjob2, return value of svr_startjob is 0
05/04/2018 00:52:50;0100;Server@node2;Req;;Type 11 request received from Scheduler@node2.supernodexp.hpc, sock=16
05/04/2018 00:52:50;0008;Server@node2;Job;14619.node2.supernodexp.hpc;Job Modified at request of Scheduler@node2.supernodexp.hpc
05/04/2018 00:53:41;0080;Server@node2;Job;14540.node2.supernodexp.hpc;Obit received momhop:1 serverhop:1 state:4 substate:42
05/04/2018 00:53:42;0010;Server@node2;Job;14540.node2.supernodexp.hpc;Exit_status=2 resources_used.cpupercent=0 resources_used.cput=00:00:00 resources_used.mem=10240kb resources_used.ncpus=32 resources_used.vmem=170164kb resources_used.walltime=00:18:46
05/04/2018 00:53:42;0100;Server@node2;Job;14540.node2.supernodexp.hpc;dequeuing from workq, state 5
05/04/2018 00:53:42;0040;Server@node2;Svr;node2.supernodexp.hpc;Scheduler sent command 2
05/04/2018 00:53:42;0040;Server@node2;Svr;node2.supernodexp.hpc;Scheduler sent command 0
05/04/2018 00:53:42;0100;Server@node2;Req;;Type 21 request received from Scheduler@node2.supernodexp.hpc, sock=16
05/04/2018 00:53:42;0100;Server@node2;Req;;Type 81 request received from Scheduler@node2.supernodexp.hpc, sock=16
05/04/2018 00:53:42;0100;Server@node2;Req;;Type 71 request received from Scheduler@node2.supernodexp.hpc, sock=16
05/04/2018 00:53:42;0100;Server@node2;Req;;Type 58 request received from Scheduler@node2.supernodexp.hpc, sock=16
05/04/2018 00:53:42;0100;Server@node2;Req;;Type 20 request received from Scheduler@node2.supernodexp.hpc, sock=16
05/04/2018 00:53:42;0100;Server@node2;Req;;Type 51 request received from Scheduler@node2.supernodexp.hpc, sock=16
05/04/2018 00:53:42;0100;Server@node2;Req;;Type 23 request received from Scheduler@node2.supernodexp.hpc, sock=16
05/04/2018 00:53:42;0008;Server@node2;Job;14619.node2.supernodexp.hpc;Job Run at request of Scheduler@node2.supernodexp.hpc on exec_vnode (node13:ncpus=32:nmics=2:mem=31457280kb)
05/04/2018 00:53:42;0001;Server@node2;Svr;Server@node2;Success (0) in req_runjob2, return value of svr_startjob is 0
05/04/2018 00:53:42;0100;Server@node2;Req;;Type 11 request received from Scheduler@node2.supernodexp.hpc, sock=16
05/04/2018 00:53:42;0008;Server@node2;Job;14638.node2.supernodexp.hpc;Job Modified at request of Scheduler@node2.supernodexp.hpc
05/04/2018 01:02:43;0080;Server@node2;Job;14555.node2.supernodexp.hpc;Obit received momhop:1 serverhop:1 state:4 substate:42
05/04/2018 01:02:43;0010;Server@node2;Job;14555.node2.supernodexp.hpc;Exit_status=2 resources_used.cpupercent=0 resources_used.cput=00:00:00 resources_used.mem=9432kb resources_used.ncpus=32 resources_used.vmem=105344kb resources_used.walltime=00:20:15
05/04/2018 01:02:43;0100;Server@node2;Job;14555.node2.supernodexp.hpc;dequeuing from workq, state 5
05/04/2018 01:02:43;0040;Server@node2;Svr;node2.supernodexp.hpc;Scheduler sent command 2
05/04/2018 01:02:43;0040;Server@node2;Svr;node2.supernodexp.hpc;Scheduler sent command 0
05/04/2018 01:02:43;0100;Server@node2;Req;;Type 21 request received from Scheduler@node2.supernodexp.hpc, sock=16
05/04/2018 01:02:43;0100;Server@node2;Req;;Type 81 request received from Scheduler@node2.supernodexp.hpc, sock=16
05/04/2018 01:02:43;0100;Server@node2;Req;;Type 71 request received from Scheduler@node2.supernodexp.hpc, sock=16
05/04/2018 01:02:43;0100;Server@node2;Req;;Type 58 request received from Scheduler@node2.supernodexp.hpc, sock=16
05/04/2018 01:02:43;0100;Server@node2;Req;;Type 20 request received from Scheduler@node2.supernodexp.hpc, sock=16
05/04/2018 01:02:43;0100;Server@node2;Req;;Type 51 request received from Scheduler@node2.supernodexp.hpc, sock=16
05/04/2018 01:02:43;0100;Server@node2;Req;;Type 23 request received from Scheduler@node2.supernodexp.hpc, sock=16
05/04/2018 01:02:43;0008;Server@node2;Job;14638.node2.supernodexp.hpc;Job Run at request of Scheduler@node2.supernodexp.hpc on exec_vnode (node3:ncpus=32:nmics=2:mem=31457280kb)
05/04/2018 01:02:43;0001;Server@node2;Svr;Server@node2;Success (0) in req_runjob2, return value of svr_startjob is 0
05/04/2018 01:02:43;0100;Server@node2;Req;;Type 11 request received from Scheduler@node2.supernodexp.hpc, sock=16
05/04/2018 01:02:43;0008;Server@node2;Job;14655.node2.supernodexp.hpc;Job Modified at request of Scheduler@node2.supernodexp.hpc
05/04/2018 01:11:34;0080;Server@node2;Job;14614.node2.supernodexp.hpc;Obit received momhop:1 serverhop:1 state:4 substate:42
05/04/2018 01:11:34;0010;Server@node2;Job;14614.node2.supernodexp.hpc;Exit_status=2 resources_used.cpupercent=0 resources_used.cput=00:00:00 resources_used.mem=10260kb resources_used.ncpus=32 resources_used.vmem=102576kb resources_used.walltime=00:18:44
05/04/2018 01:11:34;0100;Server@node2;Job;14614.node2.supernodexp.hpc;dequeuing from workq, state 5
05/04/2018 01:11:34;0040;Server@node2;Svr;node2.supernodexp.hpc;Scheduler sent command 2
05/04/2018 01:11:34;0040;Server@node2;Svr;node2.supernodexp.hpc;Scheduler sent command 0
05/04/2018 01:11:34;0100;Server@node2;Req;;Type 21 request received from Scheduler@node2.supernodexp.hpc, sock=16
05/04/2018 01:11:34;0100;Server@node2;Req;;Type 81 request received from Scheduler@node2.supernodexp.hpc, sock=16
05/04/2018 01:11:34;0100;Server@node2;Req;;Type 71 request received from Scheduler@node2.supernodexp.hpc, sock=16
05/04/2018 01:11:34;0100;Server@node2;Req;;Type 58 request received from Scheduler@node2.supernodexp.hpc, sock=16
05/04/2018 01:11:35;0100;Server@node2;Req;;Type 20 request received from Scheduler@node2.supernodexp.hpc, sock=16
05/04/2018 01:11:35;0100;Server@node2;Req;;Type 51 request received from Scheduler@node2.supernodexp.hpc, sock=16
05/04/2018 01:11:35;0100;Server@node2;Req;;Type 23 request received from Scheduler@node2.supernodexp.hpc, sock=16
05/04/2018 01:11:35;0008;Server@node2;Job;14655.node2.supernodexp.hpc;Job Run at request of Scheduler@node2.supernodexp.hpc on exec_vnode (node14:ncpus=32:nmics=2:mem=31457280kb)
05/04/2018 01:11:35;0001;Server@node2;Svr;Server@node2;Success (0) in req_runjob2, return value of svr_startjob is 0
05/04/2018 01:11:35;0100;Server@node2;Req;;Type 11 request received from Scheduler@node2.supernodexp.hpc, sock=16
05/04/2018 01:11:35;0008;Server@node2;Job;14679.node2.supernodexp.hpc;Job Modified at request of Scheduler@node2.supernodexp.hpc
05/04/2018 01:12:36;0080;Server@node2;Job;14619.node2.supernodexp.hpc;Obit received momhop:1 serverhop:1 state:4 substate:42
05/04/2018 01:12:37;0010;Server@node2;Job;14619.node2.supernodexp.hpc;Exit_status=2 resources_used.cpupercent=0 resources_used.cput=00:00:00 resources_used.mem=10012kb resources_used.ncpus=32 resources_used.vmem=171960kb resources_used.walltime=00:18:53
05/04/2018 01:12:37;0100;Server@node2;Job;14619.node2.supernodexp.hpc;dequeuing from workq, state 5
05/04/2018 01:12:37;0040;Server@node2;Svr;node2.supernodexp.hpc;Scheduler sent command 2
05/04/2018 01:12:37;0040;Server@node2;Svr;node2.supernodexp.hpc;Scheduler sent command 0
05/04/2018 01:12:37;0100;Server@node2;Req;;Type 21 request received from Scheduler@node2.supernodexp.hpc, sock=16
05/04/2018 01:12:37;0100;Server@node2;Req;;Type 81 request received from Scheduler@node2.supernodexp.hpc, sock=16
05/04/2018 01:12:37;0100;Server@node2;Req;;Type 71 request received from Scheduler@node2.supernodexp.hpc, sock=16
05/04/2018 01:12:37;0100;Server@node2;Req;;Type 58 request received from Scheduler@node2.supernodexp.hpc, sock=16
05/04/2018 01:12:37;0100;Server@node2;Req;;Type 20 request received from Scheduler@node2.supernodexp.hpc, sock=16
05/04/2018 01:12:37;0100;Server@node2;Req;;Type 51 request received from Scheduler@node2.supernodexp.hpc, sock=16
05/04/2018 01:12:37;0100;Server@node2;Req;;Type 23 request received from Scheduler@node2.supernodexp.hpc, sock=16
05/04/2018 01:12:37;0008;Server@node2;Job;14679.node2.supernodexp.hpc;Job Run at request of Scheduler@node2.supernodexp.hpc on exec_vnode (node13:ncpus=32:nmics=2:mem=31457280kb)
05/04/2018 01:12:37;0001;Server@node2;Svr;Server@node2;Success (0) in req_runjob2, return value of svr_startjob is 0
05/04/2018 01:12:37;0100;Server@node2;Req;;Type 11 request received from Scheduler@node2.supernodexp.hpc, sock=16
05/04/2018 01:12:37;0008;Server@node2;Job;14733.node2.supernodexp.hpc;Job Modified at request of Scheduler@node2.supernodexp.hpc
05/04/2018 01:22:37;0040;Server@node2;Svr;node2.supernodexp.hpc;Scheduler sent command 3
05/04/2018 01:22:37;0040;Server@node2;Svr;node2.supernodexp.hpc;Scheduler sent command 0
05/04/2018 01:22:37;0100;Server@node2;Req;;Type 21 request received from Scheduler@node2.supernodexp.hpc, sock=16
05/04/2018 01:22:37;0100;Server@node2;Req;;Type 81 request received from Scheduler@node2.supernodexp.hpc, sock=16
05/04/2018 01:22:37;0100;Server@node2;Req;;Type 71 request received from Scheduler@node2.supernodexp.hpc, sock=16
05/04/2018 01:22:37;0100;Server@node2;Req;;Type 58 request received from Scheduler@node2.supernodexp.hpc, sock=16
05/04/2018 01:22:37;0100;Server@node2;Req;;Type 20 request received from Scheduler@node2.supernodexp.hpc, sock=16
05/04/2018 01:22:37;0100;Server@node2;Req;;Type 51 request received from Scheduler@node2.supernodexp.hpc, sock=16
05/04/2018 01:22:57;0080;Server@node2;Job;14638.node2.supernodexp.hpc;Obit received momhop:1 serverhop:1 state:4 substate:42
05/04/2018 01:22:57;0010;Server@node2;Job;14638.node2.supernodexp.hpc;Exit_status=2 resources_used.cpupercent=0 resources_used.cput=00:00:00 resources_used.mem=9580kb resources_used.ncpus=32 resources_used.vmem=171940kb resources_used.walltime=00:20:13
05/04/2018 01:22:57;0100;Server@node2;Job;14638.node2.supernodexp.hpc;dequeuing from workq, state 5
05/04/2018 01:22:57;0040;Server@node2;Svr;node2.supernodexp.hpc;Scheduler sent command 2
05/04/2018 01:22:57;0040;Server@node2;Svr;node2.supernodexp.hpc;Scheduler sent command 0
05/04/2018 01:22:57;0100;Server@node2;Req;;Type 21 request received from Scheduler@node2.supernodexp.hpc, sock=16
05/04/2018 01:22:57;0100;Server@node2;Req;;Type 81 request received from Scheduler@node2.supernodexp.hpc, sock=16
05/04/2018 01:22:57;0100;Server@node2;Req;;Type 71 request received from Scheduler@node2.supernodexp.hpc, sock=16
05/04/2018 01:22:57;0100;Server@node2;Req;;Type 58 request received from Scheduler@node2.supernodexp.hpc, sock=16
05/04/2018 01:22:57;0100;Server@node2;Req;;Type 20 request received from Scheduler@node2.supernodexp.hpc, sock=16
05/04/2018 01:22:57;0100;Server@node2;Req;;Type 51 request received from Scheduler@node2.supernodexp.hpc, sock=16
05/04/2018 01:22:57;0100;Server@node2;Req;;Type 23 request received from Scheduler@node2.supernodexp.hpc, sock=16
05/04/2018 01:22:57;0008;Server@node2;Job;14733.node2.supernodexp.hpc;Job Run at request of Scheduler@node2.supernodexp.hpc on exec_vnode (node3:ncpus=32:nmics=2:mem=31457280kb)
05/04/2018 01:22:57;0001;Server@node2;Svr;Server@node2;Success (0) in req_runjob2, return value of svr_startjob is 0
05/04/2018 01:22:57;0100;Server@node2;Req;;Type 11 request received from Scheduler@node2.supernodexp.hpc, sock=16
05/04/2018 01:22:57;0008;Server@node2;Job;14749.node2.supernodexp.hpc;Job Modified at request of Scheduler@node2.supernodexp.hpc
05/04/2018 01:30:27;0080;Server@node2;Job;14655.node2.supernodexp.hpc;Obit received momhop:1 serverhop:1 state:4 substate:42
05/04/2018 01:30:28;0010;Server@node2;Job;14655.node2.supernodexp.hpc;Exit_status=2 resources_used.cpupercent=0 resources_used.cput=00:00:00 resources_used.mem=9628kb resources_used.ncpus=32 resources_used.vmem=1141428kb resources_used.walltime=00:18:52
05/04/2018 01:30:28;0100;Server@node2;Job;14655.node2.supernodexp.hpc;dequeuing from workq, state 5
05/04/2018 01:30:28;0040;Server@node2;Svr;node2.supernodexp.hpc;Scheduler sent command 2
05/04/2018 01:30:28;0040;Server@node2;Svr;node2.supernodexp.hpc;Scheduler sent command 0
05/04/2018 01:30:28;0100;Server@node2;Req;;Type 21 request received from Scheduler@node2.supernodexp.hpc, sock=16
05/04/2018 01:30:28;0100;Server@node2;Req;;Type 81 request received from Scheduler@node2.supernodexp.hpc, sock=16
05/04/2018 01:30:28;0100;Server@node2;Req;;Type 71 request received from Scheduler@node2.supernodexp.hpc, sock=16
05/04/2018 01:30:28;0100;Server@node2;Req;;Type 58 request received from Scheduler@node2.supernodexp.hpc, sock=16
05/04/2018 01:30:28;0100;Server@node2;Req;;Type 20 request received from Scheduler@node2.supernodexp.hpc, sock=16
05/04/2018 01:30:28;0100;Server@node2;Req;;Type 51 request received from Scheduler@node2.supernodexp.hpc, sock=16
05/04/2018 01:30:28;0100;Server@node2;Req;;Type 23 request received from Scheduler@node2.supernodexp.hpc, sock=16
05/04/2018 01:30:28;0008;Server@node2;Job;14749.node2.supernodexp.hpc;Job Run at request of Scheduler@node2.supernodexp.hpc on exec_vnode (node14:ncpus=32:nmics=2:mem=31457280kb)
05/04/2018 01:30:28;0001;Server@node2;Svr;Server@node2;Success (0) in req_runjob2, return value of svr_startjob is 0
05/04/2018 01:30:28;0100;Server@node2;Req;;Type 11 request received from Scheduler@node2.supernodexp.hpc, sock=16
05/04/2018 01:30:28;0008;Server@node2;Job;14775.node2.supernodexp.hpc;Job Modified at request of Scheduler@node2.supernodexp.hpc
05/04/2018 01:31:25;0080;Server@node2;Job;14679.node2.supernodexp.hpc;Obit received momhop:1 serverhop:1 state:4 substate:42
05/04/2018 01:31:26;0010;Server@node2;Job;14679.node2.supernodexp.hpc;Exit_status=2 resources_used.cpupercent=0 resources_used.cput=00:00:00 resources_used.mem=9800kb resources_used.ncpus=32 resources_used.vmem=170164kb resources_used.walltime=00:18:49
05/04/2018 01:31:26;0100;Server@node2;Job;14679.node2.supernodexp.hpc;dequeuing from workq, state 5
05/04/2018 01:31:26;0040;Server@node2;Svr;node2.supernodexp.hpc;Scheduler sent command 2
05/04/2018 01:31:26;0040;Server@node2;Svr;node2.supernodexp.hpc;Scheduler sent command 0
05/04/2018 01:31:26;0100;Server@node2;Req;;Type 21 request received from Scheduler@node2.supernodexp.hpc, sock=16
05/04/2018 01:31:26;0100;Server@node2;Req;;Type 81 request received from Scheduler@node2.supernodexp.hpc, sock=16
05/04/2018 01:31:26;0100;Server@node2;Req;;Type 71 request received from Scheduler@node2.supernodexp.hpc, sock=16
05/04/2018 01:31:26;0100;Server@node2;Req;;Type 58 request received from Scheduler@node2.supernodexp.hpc, sock=16
05/04/2018 01:31:26;0100;Server@node2;Req;;Type 20 request received from Scheduler@node2.supernodexp.hpc, sock=16
05/04/2018 01:31:26;0100;Server@node2;Req;;Type 51 request received from Scheduler@node2.supernodexp.hpc, sock=16
05/04/2018 01:31:26;0100;Server@node2;Req;;Type 23 request received from Scheduler@node2.supernodexp.hpc, sock=16
05/04/2018 01:31:26;0008;Server@node2;Job;14775.node2.supernodexp.hpc;Job Run at request of Scheduler@node2.supernodexp.hpc on exec_vnode (node13:ncpus=32:nmics=2:mem=31457280kb)
05/04/2018 01:31:26;0001;Server@node2;Svr;Server@node2;Success (0) in req_runjob2, return value of svr_startjob is 0
05/04/2018 01:31:26;0100;Server@node2;Req;;Type 11 request received from Scheduler@node2.supernodexp.hpc, sock=16
05/04/2018 01:31:26;0008;Server@node2;Job;14786.node2.supernodexp.hpc;Job Modified at request of Scheduler@node2.supernodexp.hpc
05/04/2018 01:41:26;0040;Server@node2;Svr;node2.supernodexp.hpc;Scheduler sent command 3
05/04/2018 01:41:26;0040;Server@node2;Svr;node2.supernodexp.hpc;Scheduler sent command 0
05/04/2018 01:41:26;0100;Server@node2;Req;;Type 21 request received from Scheduler@node2.supernodexp.hpc, sock=16
05/04/2018 01:41:26;0100;Server@node2;Req;;Type 81 request received from Scheduler@node2.supernodexp.hpc, sock=16
05/04/2018 01:41:26;0100;Server@node2;Req;;Type 71 request received from Scheduler@node2.supernodexp.hpc, sock=16
05/04/2018 01:41:26;0100;Server@node2;Req;;Type 58 request received from Scheduler@node2.supernodexp.hpc, sock=16
05/04/2018 01:41:26;0100;Server@node2;Req;;Type 20 request received from Scheduler@node2.supernodexp.hpc, sock=16
05/04/2018 01:41:26;0100;Server@node2;Req;;Type 51 request received from Scheduler@node2.supernodexp.hpc, sock=16
05/04/2018 01:43:08;0080;Server@node2;Job;14733.node2.supernodexp.hpc;Obit received momhop:1 serverhop:1 state:4 substate:42
05/04/2018 01:43:09;0010;Server@node2;Job;14733.node2.supernodexp.hpc;Exit_status=2 resources_used.cpupercent=0 resources_used.cput=00:00:00 resources_used.mem=9436kb resources_used.ncpus=32 resources_used.vmem=104700kb resources_used.walltime=00:20:11
05/04/2018 01:43:09;0100;Server@node2;Job;14733.node2.supernodexp.hpc;dequeuing from workq, state 5
05/04/2018 01:43:09;0040;Server@node2;Svr;node2.supernodexp.hpc;Scheduler sent command 2
05/04/2018 01:43:09;0040;Server@node2;Svr;node2.supernodexp.hpc;Scheduler sent command 0
05/04/2018 01:43:09;0100;Server@node2;Req;;Type 21 request received from Scheduler@node2.supernodexp.hpc, sock=16
05/04/2018 01:43:09;0100;Server@node2;Req;;Type 81 request received from Scheduler@node2.supernodexp.hpc, sock=16
05/04/2018 01:43:09;0100;Server@node2;Req;;Type 71 request received from Scheduler@node2.supernodexp.hpc, sock=16
05/04/2018 01:43:09;0100;Server@node2;Req;;Type 58 request received from Scheduler@node2.supernodexp.hpc, sock=16
05/04/2018 01:43:09;0100;Server@node2;Req;;Type 20 request received from Scheduler@node2.supernodexp.hpc, sock=16
05/04/2018 01:43:09;0100;Server@node2;Req;;Type 51 request received from Scheduler@node2.supernodexp.hpc, sock=16
05/04/2018 01:43:09;0100;Server@node2;Req;;Type 23 request received from Scheduler@node2.supernodexp.hpc, sock=16
05/04/2018 01:43:09;0008;Server@node2;Job;14786.node2.supernodexp.hpc;Job Run at request of Scheduler@node2.supernodexp.hpc on exec_vnode (node3:ncpus=32:nmics=2:mem=31457280kb)
05/04/2018 01:43:09;0001;Server@node2;Svr;Server@node2;Success (0) in req_runjob2, return value of svr_startjob is 0
05/04/2018 01:43:09;0100;Server@node2;Req;;Type 11 request received from Scheduler@node2.supernodexp.hpc, sock=16
05/04/2018 01:43:09;0008;Server@node2;Job;14822.node2.supernodexp.hpc;Job Modified at request of Scheduler@node2.supernodexp.hpc
05/04/2018 01:49:24;0080;Server@node2;Job;14749.node2.supernodexp.hpc;Obit received momhop:1 serverhop:1 state:4 substate:42
05/04/2018 01:49:25;0010;Server@node2;Job;14749.node2.supernodexp.hpc;Exit_status=2 resources_used.cpupercent=0 resources_used.cput=00:00:00 resources_used.mem=9960kb resources_used.ncpus=32 resources_used.vmem=104628kb resources_used.walltime=00:18:56
05/04/2018 01:49:25;0100;Server@node2;Job;14749.node2.supernodexp.hpc;dequeuing from workq, state 5
05/04/2018 01:49:25;0040;Server@node2;Svr;node2.supernodexp.hpc;Scheduler sent command 2
05/04/2018 01:49:25;0040;Server@node2;Svr;node2.supernodexp.hpc;Scheduler sent command 0
05/04/2018 01:49:25;0100;Server@node2;Req;;Type 21 request received from Scheduler@node2.supernodexp.hpc, sock=16
05/04/2018 01:49:25;0100;Server@node2;Req;;Type 81 request received from Scheduler@node2.supernodexp.hpc, sock=16
05/04/2018 01:49:25;0100;Server@node2;Req;;Type 71 request received from Scheduler@node2.supernodexp.hpc, sock=16
05/04/2018 01:49:25;0100;Server@node2;Req;;Type 58 request received from Scheduler@node2.supernodexp.hpc, sock=16
05/04/2018 01:49:25;0100;Server@node2;Req;;Type 20 request received from Scheduler@node2.supernodexp.hpc, sock=16
05/04/2018 01:49:25;0100;Server@node2;Req;;Type 51 request received from Scheduler@node2.supernodexp.hpc, sock=16
05/04/2018 01:49:25;0100;Server@node2;Req;;Type 23 request received from Scheduler@node2.supernodexp.hpc, sock=16
05/04/2018 01:49:25;0008;Server@node2;Job;14822.node2.supernodexp.hpc;Job Run at request of Scheduler@node2.supernodexp.hpc on exec_vnode (node14:ncpus=32:nmics=2:mem=31457280kb)
05/04/2018 01:49:25;0001;Server@node2;Svr;Server@node2;Success (0) in req_runjob2, return value of svr_startjob is 0
05/04/2018 01:49:25;0100;Server@node2;Req;;Type 11 request received from Scheduler@node2.supernodexp.hpc, sock=16
05/04/2018 01:49:25;0008;Server@node2;Job;14857.node2.supernodexp.hpc;Job Modified at request of Scheduler@node2.supernodexp.hpc
05/04/2018 01:50:11;0080;Server@node2;Job;14775.node2.supernodexp.hpc;Obit received momhop:1 serverhop:1 state:4 substate:42
05/04/2018 01:50:12;0010;Server@node2;Job;14775.node2.supernodexp.hpc;Exit_status=2 resources_used.cpupercent=0 resources_used.cput=00:00:00 resources_used.mem=9840kb resources_used.ncpus=32 resources_used.vmem=877232kb resources_used.walltime=00:18:45
05/04/2018 01:50:12;0100;Server@node2;Job;14775.node2.supernodexp.hpc;dequeuing from workq, state 5
05/04/2018 01:50:12;0040;Server@node2;Svr;node2.supernodexp.hpc;Scheduler sent command 2
05/04/2018 01:50:12;0040;Server@node2;Svr;node2.supernodexp.hpc;Scheduler sent command 0
05/04/2018 01:50:12;0100;Server@node2;Req;;Type 21 request received from Scheduler@node2.supernodexp.hpc, sock=16
05/04/2018 01:50:12;0100;Server@node2;Req;;Type 81 request received from Scheduler@node2.supernodexp.hpc, sock=16
05/04/2018 01:50:12;0100;Server@node2;Req;;Type 71 request received from Scheduler@node2.supernodexp.hpc, sock=16
05/04/2018 01:50:12;0100;Server@node2;Req;;Type 58 request received from Scheduler@node2.supernodexp.hpc, sock=16
05/04/2018 01:50:12;0100;Server@node2;Req;;Type 20 request received from Scheduler@node2.supernodexp.hpc, sock=16
05/04/2018 01:50:12;0100;Server@node2;Req;;Type 51 request received from Scheduler@node2.supernodexp.hpc, sock=16
05/04/2018 01:50:12;0100;Server@node2;Req;;Type 23 request received from Scheduler@node2.supernodexp.hpc, sock=16
05/04/2018 01:50:12;0008;Server@node2;Job;14857.node2.supernodexp.hpc;Job Run at request of Scheduler@node2.supernodexp.hpc on exec_vnode (node13:ncpus=32:nmics=2:mem=31457280kb)
05/04/2018 01:50:12;0001;Server@node2;Svr;Server@node2;Success (0) in req_runjob2, return value of svr_startjob is 0
05/04/2018 01:50:12;0100;Server@node2;Req;;Type 11 request received from Scheduler@node2.supernodexp.hpc, sock=16
05/04/2018 01:50:12;0008;Server@node2;Job;14861.node2.supernodexp.hpc;Job Modified at request of Scheduler@node2.supernodexp.hpc
05/04/2018 02:00:12;0040;Server@node2;Svr;node2.supernodexp.hpc;Scheduler sent command 3
05/04/2018 02:00:12;0040;Server@node2;Svr;node2.supernodexp.hpc;Scheduler sent command 0
05/04/2018 02:00:12;0100;Server@node2;Req;;Type 21 request received from Scheduler@node2.supernodexp.hpc, sock=16
05/04/2018 02:00:12;0100;Server@node2;Req;;Type 81 request received from Scheduler@node2.supernodexp.hpc, sock=16
05/04/2018 02:00:12;0100;Server@node2;Req;;Type 71 request received from Scheduler@node2.supernodexp.hpc, sock=16
05/04/2018 02:00:12;0100;Server@node2;Req;;Type 58 request received from Scheduler@node2.supernodexp.hpc, sock=16
05/04/2018 02:00:12;0100;Server@node2;Req;;Type 20 request received from Scheduler@node2.supernodexp.hpc, sock=16
05/04/2018 02:00:12;0100;Server@node2;Req;;Type 51 request received from Scheduler@node2.supernodexp.hpc, sock=16
05/04/2018 02:03:21;0080;Server@node2;Job;14786.node2.supernodexp.hpc;Obit received momhop:1 serverhop:1 state:4 substate:42
05/04/2018 02:03:22;0010;Server@node2;Job;14786.node2.supernodexp.hpc;Exit_status=2 resources_used.cpupercent=0 resources_used.cput=00:00:00 resources_used.mem=9428kb resources_used.ncpus=32 resources_used.vmem=103036kb resources_used.walltime=00:20:12
05/04/2018 02:03:22;0100;Server@node2;Job;14786.node2.supernodexp.hpc;dequeuing from workq, state 5
05/04/2018 02:03:22;0040;Server@node2;Svr;node2.supernodexp.hpc;Scheduler sent command 2
05/04/2018 02:03:22;0040;Server@node2;Svr;node2.supernodexp.hpc;Scheduler sent command 0
05/04/2018 02:03:22;0100;Server@node2;Req;;Type 21 request received from Scheduler@node2.supernodexp.hpc, sock=16
05/04/2018 02:03:22;0100;Server@node2;Req;;Type 81 request received from Scheduler@node2.supernodexp.hpc, sock=16
05/04/2018 02:03:22;0100;Server@node2;Req;;Type 71 request received from Scheduler@node2.supernodexp.hpc, sock=16
05/04/2018 02:03:22;0100;Server@node2;Req;;Type 58 request received from Scheduler@node2.supernodexp.hpc, sock=16
05/04/2018 02:03:22;0100;Server@node2;Req;;Type 20 request received from Scheduler@node2.supernodexp.hpc, sock=16
05/04/2018 02:03:22;0100;Server@node2;Req;;Type 51 request received from Scheduler@node2.supernodexp.hpc, sock=16
05/04/2018 02:03:22;0100;Server@node2;Req;;Type 23 request received from Scheduler@node2.supernodexp.hpc, sock=16
05/04/2018 02:03:22;0008;Server@node2;Job;14861.node2.supernodexp.hpc;Job Run at request of Scheduler@node2.supernodexp.hpc on exec_vnode (node3:ncpus=32:nmics=2:mem=31457280kb)
05/04/2018 02:03:22;0001;Server@node2;Svr;Server@node2;Success (0) in req_runjob2, return value of svr_startjob is 0
05/04/2018 02:03:22;0100;Server@node2;Req;;Type 11 request received from Scheduler@node2.supernodexp.hpc, sock=16
05/04/2018 02:03:22;0008;Server@node2;Job;14871.node2.supernodexp.hpc;Job Modified at request of Scheduler@node2.supernodexp.hpc
05/04/2018 02:08:19;0080;Server@node2;Job;14822.node2.supernodexp.hpc;Obit received momhop:1 serverhop:1 state:4 substate:42
05/04/2018 02:08:20;0010;Server@node2;Job;14822.node2.supernodexp.hpc;Exit_status=2 resources_used.cpupercent=0 resources_used.cput=00:00:00 resources_used.mem=10020kb resources_used.ncpus=32 resources_used.vmem=170164kb resources_used.walltime=00:18:54
05/04/2018 02:08:20;0100;Server@node2;Job;14822.node2.supernodexp.hpc;dequeuing from workq, state 5
05/04/2018 02:08:20;0040;Server@node2;Svr;node2.supernodexp.hpc;Scheduler sent command 2
05/04/2018 02:08:20;0040;Server@node2;Svr;node2.supernodexp.hpc;Scheduler sent command 0
05/04/2018 02:08:20;0100;Server@node2;Req;;Type 21 request received from Scheduler@node2.supernodexp.hpc, sock=16
05/04/2018 02:08:20;0100;Server@node2;Req;;Type 81 request received from Scheduler@node2.supernodexp.hpc, sock=16
05/04/2018 02:08:20;0100;Server@node2;Req;;Type 71 request received from Scheduler@node2.supernodexp.hpc, sock=16
05/04/2018 02:08:20;0100;Server@node2;Req;;Type 58 request received from Scheduler@node2.supernodexp.hpc, sock=16
05/04/2018 02:08:20;0100;Server@node2;Req;;Type 20 request received from Scheduler@node2.supernodexp.hpc, sock=16
05/04/2018 02:08:20;0100;Server@node2;Req;;Type 51 request received from Scheduler@node2.supernodexp.hpc, sock=16
05/04/2018 02:08:20;0100;Server@node2;Req;;Type 23 request received from Scheduler@node2.supernodexp.hpc, sock=16
05/04/2018 02:08:20;0008;Server@node2;Job;14871.node2.supernodexp.hpc;Job Run at request of Scheduler@node2.supernodexp.hpc on exec_vnode (node14:ncpus=32:nmics=2:mem=31457280kb)
05/04/2018 02:08:20;0001;Server@node2;Svr;Server@node2;Success (0) in req_runjob2, return value of svr_startjob is 0
05/04/2018 02:08:20;0100;Server@node2;Req;;Type 11 request received from Scheduler@node2.supernodexp.hpc, sock=16
05/04/2018 02:08:20;0008;Server@node2;Job;14873.node2.supernodexp.hpc;Job Modified at request of Scheduler@node2.supernodexp.hpc
05/04/2018 02:09:06;0080;Server@node2;Job;14857.node2.supernodexp.hpc;Obit received momhop:1 serverhop:1 state:4 substate:42
05/04/2018 02:09:07;0010;Server@node2;Job;14857.node2.supernodexp.hpc;Exit_status=2 resources_used.cpupercent=0 resources_used.cput=00:00:00 resources_used.mem=12268kb resources_used.ncpus=32 resources_used.vmem=104628kb resources_used.walltime=00:18:54
05/04/2018 02:09:07;0100;Server@node2;Job;14857.node2.supernodexp.hpc;dequeuing from workq, state 5
05/04/2018 02:09:07;0040;Server@node2;Svr;node2.supernodexp.hpc;Scheduler sent command 2
05/04/2018 02:09:07;0040;Server@node2;Svr;node2.supernodexp.hpc;Scheduler sent command 0
05/04/2018 02:09:07;0100;Server@node2;Req;;Type 21 request received from Scheduler@node2.supernodexp.hpc, sock=16
05/04/2018 02:09:07;0100;Server@node2;Req;;Type 81 request received from Scheduler@node2.supernodexp.hpc, sock=16
05/04/2018 02:09:07;0100;Server@node2;Req;;Type 71 request received from Scheduler@node2.supernodexp.hpc, sock=16
05/04/2018 02:09:07;0100;Server@node2;Req;;Type 58 request received from Scheduler@node2.supernodexp.hpc, sock=16
05/04/2018 02:09:07;0100;Server@node2;Req;;Type 20 request received from Scheduler@node2.supernodexp.hpc, sock=16
05/04/2018 02:09:07;0100;Server@node2;Req;;Type 51 request received from Scheduler@node2.supernodexp.hpc, sock=16
05/04/2018 02:09:07;0100;Server@node2;Req;;Type 23 request received from Scheduler@node2.supernodexp.hpc, sock=16
05/04/2018 02:09:07;0008;Server@node2;Job;14873.node2.supernodexp.hpc;Job Run at request of Scheduler@node2.supernodexp.hpc on exec_vnode (node13:ncpus=32:nmics=2:mem=31457280kb)
05/04/2018 02:09:07;0001;Server@node2;Svr;Server@node2;Success (0) in req_runjob2, return value of svr_startjob is 0
05/04/2018 02:09:07;0100;Server@node2;Req;;Type 11 request received from Scheduler@node2.supernodexp.hpc, sock=16
05/04/2018 02:09:07;0008;Server@node2;Job;14877.node2.supernodexp.hpc;Job Modified at request of Scheduler@node2.supernodexp.hpc
05/04/2018 02:19:07;0040;Server@node2;Svr;node2.supernodexp.hpc;Scheduler sent command 3
05/04/2018 02:19:07;0040;Server@node2;Svr;node2.supernodexp.hpc;Scheduler sent command 0
05/04/2018 02:19:07;0100;Server@node2;Req;;Type 21 request received from Scheduler@node2.supernodexp.hpc, sock=16
05/04/2018 02:19:07;0100;Server@node2;Req;;Type 81 request received from Scheduler@node2.supernodexp.hpc, sock=16
05/04/2018 02:19:07;0100;Server@node2;Req;;Type 71 request received from Scheduler@node2.supernodexp.hpc, sock=16
05/04/2018 02:19:07;0100;Server@node2;Req;;Type 58 request received from Scheduler@node2.supernodexp.hpc, sock=16
05/04/2018 02:19:07;0100;Server@node2;Req;;Type 20 request received from Scheduler@node2.supernodexp.hpc, sock=16
05/04/2018 02:19:07;0100;Server@node2;Req;;Type 51 request received from Scheduler@node2.supernodexp.hpc, sock=16
05/04/2018 02:23:31;0080;Server@node2;Job;14861.node2.supernodexp.hpc;Obit received momhop:1 serverhop:1 state:4 substate:42
05/04/2018 02:23:32;0010;Server@node2;Job;14861.node2.supernodexp.hpc;Exit_status=2 resources_used.cpupercent=0 resources_used.cput=00:00:00 resources_used.mem=9600kb resources_used.ncpus=32 resources_used.vmem=104700kb resources_used.walltime=00:20:09
05/04/2018 02:23:32;0100;Server@node2;Job;14861.node2.supernodexp.hpc;dequeuing from workq, state 5
05/04/2018 02:23:32;0040;Server@node2;Svr;node2.supernodexp.hpc;Scheduler sent command 2
05/04/2018 02:23:32;0040;Server@node2;Svr;node2.supernodexp.hpc;Scheduler sent command 0
05/04/2018 02:23:32;0100;Server@node2;Req;;Type 21 request received from Scheduler@node2.supernodexp.hpc, sock=16
05/04/2018 02:23:32;0100;Server@node2;Req;;Type 81 request received from Scheduler@node2.supernodexp.hpc, sock=16
05/04/2018 02:23:32;0100;Server@node2;Req;;Type 71 request received from Scheduler@node2.supernodexp.hpc, sock=16
05/04/2018 02:23:32;0100;Server@node2;Req;;Type 58 request received from Scheduler@node2.supernodexp.hpc, sock=16
05/04/2018 02:23:32;0100;Server@node2;Req;;Type 20 request received from Scheduler@node2.supernodexp.hpc, sock=16
05/04/2018 02:23:32;0100;Server@node2;Req;;Type 51 request received from Scheduler@node2.supernodexp.hpc, sock=16
05/04/2018 02:23:32;0100;Server@node2;Req;;Type 23 request received from Scheduler@node2.supernodexp.hpc, sock=16
05/04/2018 02:23:32;0008;Server@node2;Job;14877.node2.supernodexp.hpc;Job Run at request of Scheduler@node2.supernodexp.hpc on exec_vnode (node3:ncpus=32:nmics=2:mem=31457280kb)
05/04/2018 02:23:32;0001;Server@node2;Svr;Server@node2;Success (0) in req_runjob2, return value of svr_startjob is 0
05/04/2018 02:23:32;0100;Server@node2;Req;;Type 11 request received from Scheduler@node2.supernodexp.hpc, sock=16
05/04/2018 02:23:32;0008;Server@node2;Job;14951.node2.supernodexp.hpc;Job Modified at request of Scheduler@node2.supernodexp.hpc
05/04/2018 02:27:04;0080;Server@node2;Job;14871.node2.supernodexp.hpc;Obit received momhop:1 serverhop:1 state:4 substate:42
05/04/2018 02:27:05;0010;Server@node2;Job;14871.node2.supernodexp.hpc;Exit_status=2 resources_used.cpupercent=0 resources_used.cput=00:00:00 resources_used.mem=10108kb resources_used.ncpus=32 resources_used.vmem=172216kb resources_used.walltime=00:18:44
05/04/2018 02:27:05;0100;Server@node2;Job;14871.node2.supernodexp.hpc;dequeuing from workq, state 5
05/04/2018 02:27:05;0040;Server@node2;Svr;node2.supernodexp.hpc;Scheduler sent command 2
05/04/2018 02:27:05;0040;Server@node2;Svr;node2.supernodexp.hpc;Scheduler sent command 0
05/04/2018 02:27:05;0100;Server@node2;Req;;Type 21 request received from Scheduler@node2.supernodexp.hpc, sock=16
05/04/2018 02:27:05;0100;Server@node2;Req;;Type 81 request received from Scheduler@node2.supernodexp.hpc, sock=16
05/04/2018 02:27:05;0100;Server@node2;Req;;Type 71 request received from Scheduler@node2.supernodexp.hpc, sock=16
05/04/2018 02:27:05;0100;Server@node2;Req;;Type 58 request received from Scheduler@node2.supernodexp.hpc, sock=16
05/04/2018 02:27:05;0100;Server@node2;Req;;Type 20 request received from Scheduler@node2.supernodexp.hpc, sock=16
05/04/2018 02:27:05;0100;Server@node2;Req;;Type 51 request received from Scheduler@node2.supernodexp.hpc, sock=16
05/04/2018 02:27:05;0100;Server@node2;Req;;Type 23 request received from Scheduler@node2.supernodexp.hpc, sock=16
05/04/2018 02:27:05;0008;Server@node2;Job;14951.node2.supernodexp.hpc;Job Run at request of Scheduler@node2.supernodexp.hpc on exec_vnode (node14:ncpus=32:nmics=2:mem=31457280kb)
05/04/2018 02:27:05;0001;Server@node2;Svr;Server@node2;Success (0) in req_runjob2, return value of svr_startjob is 0
05/04/2018 02:27:05;0100;Server@node2;Req;;Type 11 request received from Scheduler@node2.supernodexp.hpc, sock=16
05/04/2018 02:27:05;0008;Server@node2;Job;14956.node2.supernodexp.hpc;Job Modified at request of Scheduler@node2.supernodexp.hpc
05/04/2018 02:27:55;0080;Server@node2;Job;14873.node2.supernodexp.hpc;Obit received momhop:1 serverhop:1 state:4 substate:42
05/04/2018 02:27:56;0010;Server@node2;Job;14873.node2.supernodexp.hpc;Exit_status=2 resources_used.cpupercent=0 resources_used.cput=00:00:00 resources_used.mem=10016kb resources_used.ncpus=32 resources_used.vmem=171960kb resources_used.walltime=00:18:47
05/04/2018 02:27:56;0100;Server@node2;Job;14873.node2.supernodexp.hpc;dequeuing from workq, state 5
05/04/2018 02:27:56;0040;Server@node2;Svr;node2.supernodexp.hpc;Scheduler sent command 2
05/04/2018 02:27:56;0040;Server@node2;Svr;node2.supernodexp.hpc;Scheduler sent command 0
05/04/2018 02:27:56;0100;Server@node2;Req;;Type 21 request received from Scheduler@node2.supernodexp.hpc, sock=16
05/04/2018 02:27:56;0100;Server@node2;Req;;Type 81 request received from Scheduler@node2.supernodexp.hpc, sock=16
05/04/2018 02:27:56;0100;Server@node2;Req;;Type 71 request received from Scheduler@node2.supernodexp.hpc, sock=16
05/04/2018 02:27:56;0100;Server@node2;Req;;Type 58 request received from Scheduler@node2.supernodexp.hpc, sock=16
05/04/2018 02:27:56;0100;Server@node2;Req;;Type 20 request received from Scheduler@node2.supernodexp.hpc, sock=16
05/04/2018 02:27:56;0100;Server@node2;Req;;Type 51 request received from Scheduler@node2.supernodexp.hpc, sock=16
05/04/2018 02:27:56;0100;Server@node2;Req;;Type 23 request received from Scheduler@node2.supernodexp.hpc, sock=16
05/04/2018 02:27:56;0008;Server@node2;Job;14956.node2.supernodexp.hpc;Job Run at request of Scheduler@node2.supernodexp.hpc on exec_vnode (node13:ncpus=32:nmics=2:mem=31457280kb)
05/04/2018 02:27:56;0001;Server@node2;Svr;Server@node2;Success (0) in req_runjob2, return value of svr_startjob is 0
05/04/2018 02:27:56;0100;Server@node2;Req;;Type 11 request received from Scheduler@node2.supernodexp.hpc, sock=16
05/04/2018 02:27:56;0008;Server@node2;Job;14958.node2.supernodexp.hpc;Job Modified at request of Scheduler@node2.supernodexp.hpc
05/04/2018 02:37:56;0040;Server@node2;Svr;node2.supernodexp.hpc;Scheduler sent command 3
05/04/2018 02:37:56;0040;Server@node2;Svr;node2.supernodexp.hpc;Scheduler sent command 0
05/04/2018 02:37:56;0100;Server@node2;Req;;Type 21 request received from Scheduler@node2.supernodexp.hpc, sock=16
05/04/2018 02:37:56;0100;Server@node2;Req;;Type 81 request received from Scheduler@node2.supernodexp.hpc, sock=16
05/04/2018 02:37:56;0100;Server@node2;Req;;Type 71 request received from Scheduler@node2.supernodexp.hpc, sock=16
05/04/2018 02:37:56;0100;Server@node2;Req;;Type 58 request received from Scheduler@node2.supernodexp.hpc, sock=16
05/04/2018 02:37:56;0100;Server@node2;Req;;Type 20 request received from Scheduler@node2.supernodexp.hpc, sock=16
05/04/2018 02:37:56;0100;Server@node2;Req;;Type 51 request received from Scheduler@node2.supernodexp.hpc, sock=16
05/04/2018 02:43:49;0080;Server@node2;Job;14877.node2.supernodexp.hpc;Obit received momhop:1 serverhop:1 state:4 substate:42
05/04/2018 02:43:50;0010;Server@node2;Job;14877.node2.supernodexp.hpc;Exit_status=2 resources_used.cpupercent=0 resources_used.cput=00:00:00 resources_used.mem=9444kb resources_used.ncpus=32 resources_used.vmem=105344kb resources_used.walltime=00:20:17
05/04/2018 02:43:50;0100;Server@node2;Job;14877.node2.supernodexp.hpc;dequeuing from workq, state 5
05/04/2018 02:43:50;0040;Server@node2;Svr;node2.supernodexp.hpc;Scheduler sent command 2
05/04/2018 02:43:50;0040;Server@node2;Svr;node2.supernodexp.hpc;Scheduler sent command 0
05/04/2018 02:43:50;0100;Server@node2;Req;;Type 21 request received from Scheduler@node2.supernodexp.hpc, sock=16
05/04/2018 02:43:50;0100;Server@node2;Req;;Type 81 request received from Scheduler@node2.supernodexp.hpc, sock=16
05/04/2018 02:43:50;0100;Server@node2;Req;;Type 71 request received from Scheduler@node2.supernodexp.hpc, sock=16
05/04/2018 02:43:50;0100;Server@node2;Req;;Type 58 request received from Scheduler@node2.supernodexp.hpc, sock=16
05/04/2018 02:43:50;0100;Server@node2;Req;;Type 20 request received from Scheduler@node2.supernodexp.hpc, sock=16
05/04/2018 02:43:50;0100;Server@node2;Req;;Type 51 request received from Scheduler@node2.supernodexp.hpc, sock=16
05/04/2018 02:43:50;0100;Server@node2;Req;;Type 23 request received from Scheduler@node2.supernodexp.hpc, sock=16
05/04/2018 02:43:50;0008;Server@node2;Job;14958.node2.supernodexp.hpc;Job Run at request of Scheduler@node2.supernodexp.hpc on exec_vnode (node3:ncpus=32:nmics=2:mem=31457280kb)
05/04/2018 02:43:50;0001;Server@node2;Svr;Server@node2;Success (0) in req_runjob2, return value of svr_startjob is 0
05/04/2018 02:43:50;0100;Server@node2;Req;;Type 11 request received from Scheduler@node2.supernodexp.hpc, sock=16
05/04/2018 02:43:50;0008;Server@node2;Job;14967.node2.supernodexp.hpc;Job Modified at request of Scheduler@node2.supernodexp.hpc
05/04/2018 02:45:59;0080;Server@node2;Job;14951.node2.supernodexp.hpc;Obit received momhop:1 serverhop:1 state:4 substate:42
05/04/2018 02:46:00;0010;Server@node2;Job;14951.node2.supernodexp.hpc;Exit_status=2 resources_used.cpupercent=0 resources_used.cput=00:00:00 resources_used.mem=10036kb resources_used.ncpus=32 resources_used.vmem=104628kb resources_used.walltime=00:18:54
05/04/2018 02:46:00;0100;Server@node2;Job;14951.node2.supernodexp.hpc;dequeuing from workq, state 5
05/04/2018 02:46:00;0040;Server@node2;Svr;node2.supernodexp.hpc;Scheduler sent command 2
05/04/2018 02:46:00;0040;Server@node2;Svr;node2.supernodexp.hpc;Scheduler sent command 0
05/04/2018 02:46:00;0100;Server@node2;Req;;Type 21 request received from Scheduler@node2.supernodexp.hpc, sock=16
05/04/2018 02:46:00;0100;Server@node2;Req;;Type 81 request received from Scheduler@node2.supernodexp.hpc, sock=16
05/04/2018 02:46:00;0100;Server@node2;Req;;Type 71 request received from Scheduler@node2.supernodexp.hpc, sock=16
05/04/2018 02:46:00;0100;Server@node2;Req;;Type 58 request received from Scheduler@node2.supernodexp.hpc, sock=16
05/04/2018 02:46:00;0100;Server@node2;Req;;Type 20 request received from Scheduler@node2.supernodexp.hpc, sock=16
05/04/2018 02:46:00;0100;Server@node2;Req;;Type 51 request received from Scheduler@node2.supernodexp.hpc, sock=16
05/04/2018 02:46:00;0100;Server@node2;Req;;Type 23 request received from Scheduler@node2.supernodexp.hpc, sock=16
05/04/2018 02:46:00;0008;Server@node2;Job;14967.node2.supernodexp.hpc;Job Run at request of Scheduler@node2.supernodexp.hpc on exec_vnode (node14:ncpus=32:nmics=2:mem=31457280kb)
05/04/2018 02:46:00;0001;Server@node2;Svr;Server@node2;Success (0) in req_runjob2, return value of svr_startjob is 0
05/04/2018 02:46:00;0100;Server@node2;Req;;Type 11 request received from Scheduler@node2.supernodexp.hpc, sock=16
05/04/2018 02:46:00;0008;Server@node2;Job;14990.node2.supernodexp.hpc;Job Modified at request of Scheduler@node2.supernodexp.hpc
05/04/2018 02:46:42;0080;Server@node2;Job;14956.node2.supernodexp.hpc;Obit received momhop:1 serverhop:1 state:4 substate:42
05/04/2018 02:46:42;0010;Server@node2;Job;14956.node2.supernodexp.hpc;Exit_status=2 resources_used.cpupercent=0 resources_used.cput=00:00:00 resources_used.mem=10016kb resources_used.ncpus=32 resources_used.vmem=102320kb resources_used.walltime=00:18:46
05/04/2018 02:46:42;0100;Server@node2;Job;14956.node2.supernodexp.hpc;dequeuing from workq, state 5
05/04/2018 02:46:42;0040;Server@node2;Svr;node2.supernodexp.hpc;Scheduler sent command 2
05/04/2018 02:46:42;0040;Server@node2;Svr;node2.supernodexp.hpc;Scheduler sent command 0
05/04/2018 02:46:42;0100;Server@node2;Req;;Type 21 request received from Scheduler@node2.supernodexp.hpc, sock=16
05/04/2018 02:46:42;0100;Server@node2;Req;;Type 81 request received from Scheduler@node2.supernodexp.hpc, sock=16
05/04/2018 02:46:42;0100;Server@node2;Req;;Type 71 request received from Scheduler@node2.supernodexp.hpc, sock=16
05/04/2018 02:46:42;0100;Server@node2;Req;;Type 58 request received from Scheduler@node2.supernodexp.hpc, sock=16
05/04/2018 02:46:42;0100;Server@node2;Req;;Type 20 request received from Scheduler@node2.supernodexp.hpc, sock=16
05/04/2018 02:46:42;0100;Server@node2;Req;;Type 51 request received from Scheduler@node2.supernodexp.hpc, sock=16
05/04/2018 02:46:43;0100;Server@node2;Req;;Type 23 request received from Scheduler@node2.supernodexp.hpc, sock=16
05/04/2018 02:46:43;0008;Server@node2;Job;14990.node2.supernodexp.hpc;Job Run at request of Scheduler@node2.supernodexp.hpc on exec_vnode (node13:ncpus=32:nmics=2:mem=31457280kb)
05/04/2018 02:46:43;0001;Server@node2;Svr;Server@node2;Success (0) in req_runjob2, return value of svr_startjob is 0
05/04/2018 02:46:43;0100;Server@node2;Req;;Type 11 request received from Scheduler@node2.supernodexp.hpc, sock=16
05/04/2018 02:46:43;0008;Server@node2;Job;15016.node2.supernodexp.hpc;Job Modified at request of Scheduler@node2.supernodexp.hpc
05/04/2018 02:56:42;0040;Server@node2;Svr;node2.supernodexp.hpc;Scheduler sent command 3
05/04/2018 02:56:42;0040;Server@node2;Svr;node2.supernodexp.hpc;Scheduler sent command 0
05/04/2018 02:56:42;0100;Server@node2;Req;;Type 21 request received from Scheduler@node2.supernodexp.hpc, sock=16
05/04/2018 02:56:42;0100;Server@node2;Req;;Type 81 request received from Scheduler@node2.supernodexp.hpc, sock=16
05/04/2018 02:56:42;0100;Server@node2;Req;;Type 71 request received from Scheduler@node2.supernodexp.hpc, sock=16
05/04/2018 02:56:42;0100;Server@node2;Req;;Type 58 request received from Scheduler@node2.supernodexp.hpc, sock=16
05/04/2018 02:56:42;0100;Server@node2;Req;;Type 20 request received from Scheduler@node2.supernodexp.hpc, sock=16
05/04/2018 02:56:42;0100;Server@node2;Req;;Type 51 request received from Scheduler@node2.supernodexp.hpc, sock=16
05/04/2018 03:04:04;0080;Server@node2;Job;14958.node2.supernodexp.hpc;Obit received momhop:1 serverhop:1 state:4 substate:42
05/04/2018 03:04:04;0010;Server@node2;Job;14958.node2.supernodexp.hpc;Exit_status=2 resources_used.cpupercent=0 resources_used.cput=00:00:00 resources_used.mem=9444kb resources_used.ncpus=32 resources_used.vmem=105088kb resources_used.walltime=00:20:14
05/04/2018 03:04:04;0100;Server@node2;Job;14958.node2.supernodexp.hpc;dequeuing from workq, state 5
05/04/2018 03:04:04;0040;Server@node2;Svr;node2.supernodexp.hpc;Scheduler sent command 2
05/04/2018 03:04:04;0040;Server@node2;Svr;node2.supernodexp.hpc;Scheduler sent command 0
05/04/2018 03:04:04;0100;Server@node2;Req;;Type 21 request received from Scheduler@node2.supernodexp.hpc, sock=16
05/04/2018 03:04:04;0100;Server@node2;Req;;Type 81 request received from Scheduler@node2.supernodexp.hpc, sock=16
05/04/2018 03:04:04;0100;Server@node2;Req;;Type 71 request received from Scheduler@node2.supernodexp.hpc, sock=16
05/04/2018 03:04:04;0100;Server@node2;Req;;Type 58 request received from Scheduler@node2.supernodexp.hpc, sock=16
05/04/2018 03:04:04;0100;Server@node2;Req;;Type 20 request received from Scheduler@node2.supernodexp.hpc, sock=16
05/04/2018 03:04:04;0100;Server@node2;Req;;Type 51 request received from Scheduler@node2.supernodexp.hpc, sock=16
05/04/2018 03:04:04;0100;Server@node2;Req;;Type 23 request received from Scheduler@node2.supernodexp.hpc, sock=16
05/04/2018 03:04:04;0008;Server@node2;Job;15016.node2.supernodexp.hpc;Job Run at request of Scheduler@node2.supernodexp.hpc on exec_vnode (node3:ncpus=32:nmics=2:mem=31457280kb)
05/04/2018 03:04:04;0001;Server@node2;Svr;Server@node2;Success (0) in req_runjob2, return value of svr_startjob is 0
05/04/2018 03:04:04;0100;Server@node2;Req;;Type 11 request received from Scheduler@node2.supernodexp.hpc, sock=16
05/04/2018 03:04:04;0008;Server@node2;Job;15049.node2.supernodexp.hpc;Job Modified at request of Scheduler@node2.supernodexp.hpc
05/04/2018 03:04:43;0080;Server@node2;Job;14967.node2.supernodexp.hpc;Obit received momhop:1 serverhop:1 state:4 substate:42
05/04/2018 03:04:43;0010;Server@node2;Job;14967.node2.supernodexp.hpc;Exit_status=2 resources_used.cpupercent=0 resources_used.cput=00:00:00 resources_used.mem=10232kb resources_used.ncpus=32 resources_used.vmem=104372kb resources_used.walltime=00:18:43
05/04/2018 03:04:43;0100;Server@node2;Job;14967.node2.supernodexp.hpc;dequeuing from workq, state 5
05/04/2018 03:04:43;0040;Server@node2;Svr;node2.supernodexp.hpc;Scheduler sent command 2
05/04/2018 03:04:43;0040;Server@node2;Svr;node2.supernodexp.hpc;Scheduler sent command 0
05/04/2018 03:04:43;0100;Server@node2;Req;;Type 21 request received from Scheduler@node2.supernodexp.hpc, sock=16
05/04/2018 03:04:43;0100;Server@node2;Req;;Type 81 request received from Scheduler@node2.supernodexp.hpc, sock=16
05/04/2018 03:04:43;0100;Server@node2;Req;;Type 71 request received from Scheduler@node2.supernodexp.hpc, sock=16
05/04/2018 03:04:43;0100;Server@node2;Req;;Type 58 request received from Scheduler@node2.supernodexp.hpc, sock=16
05/04/2018 03:04:43;0100;Server@node2;Req;;Type 20 request received from Scheduler@node2.supernodexp.hpc, sock=16
05/04/2018 03:04:43;0100;Server@node2;Req;;Type 51 request received from Scheduler@node2.supernodexp.hpc, sock=16
05/04/2018 03:04:44;0100;Server@node2;Req;;Type 23 request received from Scheduler@node2.supernodexp.hpc, sock=16
05/04/2018 03:04:44;0008;Server@node2;Job;15049.node2.supernodexp.hpc;Job Run at request of Scheduler@node2.supernodexp.hpc on exec_vnode (node14:ncpus=32:nmics=2:mem=31457280kb)
05/04/2018 03:04:44;0001;Server@node2;Svr;Server@node2;Success (0) in req_runjob2, return value of svr_startjob is 0
05/04/2018 03:04:44;0100;Server@node2;Req;;Type 11 request received from Scheduler@node2.supernodexp.hpc, sock=16
05/04/2018 03:04:44;0008;Server@node2;Job;15050.node2.supernodexp.hpc;Job Modified at request of Scheduler@node2.supernodexp.hpc
05/04/2018 03:05:29;0080;Server@node2;Job;14990.node2.supernodexp.hpc;Obit received momhop:1 serverhop:1 state:4 substate:42
05/04/2018 03:05:30;0010;Server@node2;Job;14990.node2.supernodexp.hpc;Exit_status=2 resources_used.cpupercent=0 resources_used.cput=00:00:00 resources_used.mem=10036kb resources_used.ncpus=32 resources_used.vmem=237496kb resources_used.walltime=00:18:47
05/04/2018 03:05:30;0100;Server@node2;Job;14990.node2.supernodexp.hpc;dequeuing from workq, state 5
05/04/2018 03:05:30;0040;Server@node2;Svr;node2.supernodexp.hpc;Scheduler sent command 2
05/04/2018 03:05:30;0040;Server@node2;Svr;node2.supernodexp.hpc;Scheduler sent command 0
05/04/2018 03:05:30;0100;Server@node2;Req;;Type 21 request received from Scheduler@node2.supernodexp.hpc, sock=16
05/04/2018 03:05:30;0100;Server@node2;Req;;Type 81 request received from Scheduler@node2.supernodexp.hpc, sock=16
05/04/2018 03:05:30;0100;Server@node2;Req;;Type 71 request received from Scheduler@node2.supernodexp.hpc, sock=16
05/04/2018 03:05:30;0100;Server@node2;Req;;Type 58 request received from Scheduler@node2.supernodexp.hpc, sock=16
05/04/2018 03:05:30;0100;Server@node2;Req;;Type 20 request received from Scheduler@node2.supernodexp.hpc, sock=16
05/04/2018 03:05:30;0100;Server@node2;Req;;Type 51 request received from Scheduler@node2.supernodexp.hpc, sock=16
05/04/2018 03:05:30;0100;Server@node2;Req;;Type 23 request received from Scheduler@node2.supernodexp.hpc, sock=16
05/04/2018 03:05:30;0008;Server@node2;Job;15050.node2.supernodexp.hpc;Job Run at request of Scheduler@node2.supernodexp.hpc on exec_vnode (node13:ncpus=32:nmics=2:mem=31457280kb)
05/04/2018 03:05:30;0001;Server@node2;Svr;Server@node2;Success (0) in req_runjob2, return value of svr_startjob is 0
05/04/2018 03:05:30;0100;Server@node2;Req;;Type 11 request received from Scheduler@node2.supernodexp.hpc, sock=16
05/04/2018 03:05:30;0008;Server@node2;Job;15068.node2.supernodexp.hpc;Job Modified at request of Scheduler@node2.supernodexp.hpc
05/04/2018 03:15:30;0040;Server@node2;Svr;node2.supernodexp.hpc;Scheduler sent command 3
05/04/2018 03:15:30;0040;Server@node2;Svr;node2.supernodexp.hpc;Scheduler sent command 0
05/04/2018 03:15:30;0100;Server@node2;Req;;Type 21 request received from Scheduler@node2.supernodexp.hpc, sock=16
05/04/2018 03:15:30;0100;Server@node2;Req;;Type 81 request received from Scheduler@node2.supernodexp.hpc, sock=16
05/04/2018 03:15:30;0100;Server@node2;Req;;Type 71 request received from Scheduler@node2.supernodexp.hpc, sock=16
05/04/2018 03:15:30;0100;Server@node2;Req;;Type 58 request received from Scheduler@node2.supernodexp.hpc, sock=16
05/04/2018 03:15:30;0100;Server@node2;Req;;Type 20 request received from Scheduler@node2.supernodexp.hpc, sock=16
05/04/2018 03:15:30;0100;Server@node2;Req;;Type 51 request received from Scheduler@node2.supernodexp.hpc, sock=16
05/04/2018 03:23:23;0080;Server@node2;Job;15049.node2.supernodexp.hpc;Obit received momhop:1 serverhop:1 state:4 substate:42
05/04/2018 03:23:24;0010;Server@node2;Job;15049.node2.supernodexp.hpc;Exit_status=2 resources_used.cpupercent=0 resources_used.cput=00:00:00 resources_used.mem=10020kb resources_used.ncpus=32 resources_used.vmem=104628kb resources_used.walltime=00:18:39
05/04/2018 03:23:24;0100;Server@node2;Job;15049.node2.supernodexp.hpc;dequeuing from workq, state 5
05/04/2018 03:23:24;0040;Server@node2;Svr;node2.supernodexp.hpc;Scheduler sent command 2
05/04/2018 03:23:24;0040;Server@node2;Svr;node2.supernodexp.hpc;Scheduler sent command 0
05/04/2018 03:23:24;0100;Server@node2;Req;;Type 21 request received from Scheduler@node2.supernodexp.hpc, sock=16
05/04/2018 03:23:24;0100;Server@node2;Req;;Type 81 request received from Scheduler@node2.supernodexp.hpc, sock=16
05/04/2018 03:23:24;0100;Server@node2;Req;;Type 71 request received from Scheduler@node2.supernodexp.hpc, sock=16
05/04/2018 03:23:24;0100;Server@node2;Req;;Type 58 request received from Scheduler@node2.supernodexp.hpc, sock=16
05/04/2018 03:23:24;0100;Server@node2;Req;;Type 20 request received from Scheduler@node2.supernodexp.hpc, sock=16
05/04/2018 03:23:24;0100;Server@node2;Req;;Type 51 request received from Scheduler@node2.supernodexp.hpc, sock=16
05/04/2018 03:23:24;0100;Server@node2;Req;;Type 23 request received from Scheduler@node2.supernodexp.hpc, sock=16
05/04/2018 03:23:24;0008;Server@node2;Job;15068.node2.supernodexp.hpc;Job Run at request of Scheduler@node2.supernodexp.hpc on exec_vnode (node14:ncpus=32:nmics=2:mem=31457280kb)
05/04/2018 03:23:24;0001;Server@node2;Svr;Server@node2;Success (0) in req_runjob2, return value of svr_startjob is 0
05/04/2018 03:23:24;0100;Server@node2;Req;;Type 11 request received from Scheduler@node2.supernodexp.hpc, sock=16
05/04/2018 03:23:24;0008;Server@node2;Job;15083.node2.supernodexp.hpc;Job Modified at request of Scheduler@node2.supernodexp.hpc
05/04/2018 03:24:16;0080;Server@node2;Job;15050.node2.supernodexp.hpc;Obit received momhop:1 serverhop:1 state:4 substate:42
05/04/2018 03:24:17;0010;Server@node2;Job;15050.node2.supernodexp.hpc;Exit_status=2 resources_used.cpupercent=0 resources_used.cput=00:00:00 resources_used.mem=10000kb resources_used.ncpus=32 resources_used.vmem=171316kb resources_used.walltime=00:18:46
05/04/2018 03:24:17;0100;Server@node2;Job;15050.node2.supernodexp.hpc;dequeuing from workq, state 5
05/04/2018 03:24:17;0040;Server@node2;Svr;node2.supernodexp.hpc;Scheduler sent command 2
05/04/2018 03:24:17;0040;Server@node2;Svr;node2.supernodexp.hpc;Scheduler sent command 0
05/04/2018 03:24:17;0100;Server@node2;Req;;Type 21 request received from Scheduler@node2.supernodexp.hpc, sock=16
05/04/2018 03:24:17;0100;Server@node2;Req;;Type 81 request received from Scheduler@node2.supernodexp.hpc, sock=16
05/04/2018 03:24:17;0100;Server@node2;Req;;Type 71 request received from Scheduler@node2.supernodexp.hpc, sock=16
05/04/2018 03:24:17;0100;Server@node2;Req;;Type 58 request received from Scheduler@node2.supernodexp.hpc, sock=16
05/04/2018 03:24:17;0100;Server@node2;Req;;Type 20 request received from Scheduler@node2.supernodexp.hpc, sock=16
05/04/2018 03:24:17;0100;Server@node2;Req;;Type 51 request received from Scheduler@node2.supernodexp.hpc, sock=16
05/04/2018 03:24:17;0100;Server@node2;Req;;Type 23 request received from Scheduler@node2.supernodexp.hpc, sock=16
05/04/2018 03:24:17;0008;Server@node2;Job;15083.node2.supernodexp.hpc;Job Run at request of Scheduler@node2.supernodexp.hpc on exec_vnode (node13:ncpus=32:nmics=2:mem=31457280kb)
05/04/2018 03:24:17;0001;Server@node2;Svr;Server@node2;Success (0) in req_runjob2, return value of svr_startjob is 0
05/04/2018 03:24:17;0100;Server@node2;Req;;Type 11 request received from Scheduler@node2.supernodexp.hpc, sock=16
05/04/2018 03:24:17;0008;Server@node2;Job;15092.node2.supernodexp.hpc;Job Modified at request of Scheduler@node2.supernodexp.hpc
05/04/2018 03:24:28;0080;Server@node2;Job;15016.node2.supernodexp.hpc;Obit received momhop:1 serverhop:1 state:4 substate:42
05/04/2018 03:24:29;0010;Server@node2;Job;15016.node2.supernodexp.hpc;Exit_status=2 resources_used.cpupercent=0 resources_used.cput=00:00:00 resources_used.mem=9448kb resources_used.ncpus=32 resources_used.vmem=103292kb resources_used.walltime=00:20:24
05/04/2018 03:24:29;0100;Server@node2;Job;15016.node2.supernodexp.hpc;dequeuing from workq, state 5
05/04/2018 03:24:29;0040;Server@node2;Svr;node2.supernodexp.hpc;Scheduler sent command 2
05/04/2018 03:24:29;0040;Server@node2;Svr;node2.supernodexp.hpc;Scheduler sent command 0
05/04/2018 03:24:29;0100;Server@node2;Req;;Type 21 request received from Scheduler@node2.supernodexp.hpc, sock=16
05/04/2018 03:24:29;0100;Server@node2;Req;;Type 81 request received from Scheduler@node2.supernodexp.hpc, sock=16
05/04/2018 03:24:29;0100;Server@node2;Req;;Type 71 request received from Scheduler@node2.supernodexp.hpc, sock=16
05/04/2018 03:24:29;0100;Server@node2;Req;;Type 58 request received from Scheduler@node2.supernodexp.hpc, sock=16
05/04/2018 03:24:29;0100;Server@node2;Req;;Type 20 request received from Scheduler@node2.supernodexp.hpc, sock=16
05/04/2018 03:24:29;0100;Server@node2;Req;;Type 51 request received from Scheduler@node2.supernodexp.hpc, sock=16
05/04/2018 03:24:29;0100;Server@node2;Req;;Type 23 request received from Scheduler@node2.supernodexp.hpc, sock=16
05/04/2018 03:24:29;0008;Server@node2;Job;15092.node2.supernodexp.hpc;Job Run at request of Scheduler@node2.supernodexp.hpc on exec_vnode (node3:ncpus=32:nmics=2:mem=31457280kb)
05/04/2018 03:24:29;0001;Server@node2;Svr;Server@node2;Success (0) in req_runjob2, return value of svr_startjob is 0
05/04/2018 03:24:29;0100;Server@node2;Req;;Type 11 request received from Scheduler@node2.supernodexp.hpc, sock=16
05/04/2018 03:24:29;0008;Server@node2;Job;15142.node2.supernodexp.hpc;Job Modified at request of Scheduler@node2.supernodexp.hpc
05/04/2018 03:34:29;0040;Server@node2;Svr;node2.supernodexp.hpc;Scheduler sent command 3
05/04/2018 03:34:29;0040;Server@node2;Svr;node2.supernodexp.hpc;Scheduler sent command 0
05/04/2018 03:34:29;0100;Server@node2;Req;;Type 21 request received from Scheduler@node2.supernodexp.hpc, sock=16
05/04/2018 03:34:29;0100;Server@node2;Req;;Type 81 request received from Scheduler@node2.supernodexp.hpc, sock=16
05/04/2018 03:34:29;0100;Server@node2;Req;;Type 71 request received from Scheduler@node2.supernodexp.hpc, sock=16
05/04/2018 03:34:29;0100;Server@node2;Req;;Type 58 request received from Scheduler@node2.supernodexp.hpc, sock=16
05/04/2018 03:34:29;0100;Server@node2;Req;;Type 20 request received from Scheduler@node2.supernodexp.hpc, sock=16
05/04/2018 03:34:29;0100;Server@node2;Req;;Type 51 request received from Scheduler@node2.supernodexp.hpc, sock=16
05/04/2018 03:42:08;0080;Server@node2;Job;15068.node2.supernodexp.hpc;Obit received momhop:1 serverhop:1 state:4 substate:42
05/04/2018 03:42:09;0010;Server@node2;Job;15068.node2.supernodexp.hpc;Exit_status=2 resources_used.cpupercent=0 resources_used.cput=00:00:00 resources_used.mem=9996kb resources_used.ncpus=32 resources_used.vmem=169908kb resources_used.walltime=00:18:44
05/04/2018 03:42:09;0100;Server@node2;Job;15068.node2.supernodexp.hpc;dequeuing from workq, state 5
05/04/2018 03:42:09;0040;Server@node2;Svr;node2.supernodexp.hpc;Scheduler sent command 2
05/04/2018 03:42:09;0040;Server@node2;Svr;node2.supernodexp.hpc;Scheduler sent command 0
05/04/2018 03:42:09;0100;Server@node2;Req;;Type 21 request received from Scheduler@node2.supernodexp.hpc, sock=16
05/04/2018 03:42:09;0100;Server@node2;Req;;Type 81 request received from Scheduler@node2.supernodexp.hpc, sock=16
05/04/2018 03:42:09;0100;Server@node2;Req;;Type 71 request received from Scheduler@node2.supernodexp.hpc, sock=16
05/04/2018 03:42:09;0100;Server@node2;Req;;Type 58 request received from Scheduler@node2.supernodexp.hpc, sock=16
05/04/2018 03:42:09;0100;Server@node2;Req;;Type 20 request received from Scheduler@node2.supernodexp.hpc, sock=16
05/04/2018 03:42:09;0100;Server@node2;Req;;Type 51 request received from Scheduler@node2.supernodexp.hpc, sock=16
05/04/2018 03:42:09;0100;Server@node2;Req;;Type 23 request received from Scheduler@node2.supernodexp.hpc, sock=16
05/04/2018 03:42:09;0008;Server@node2;Job;15142.node2.supernodexp.hpc;Job Run at request of Scheduler@node2.supernodexp.hpc on exec_vnode (node14:ncpus=32:nmics=2:mem=31457280kb)
05/04/2018 03:42:09;0001;Server@node2;Svr;Server@node2;Success (0) in req_runjob2, return value of svr_startjob is 0
05/04/2018 03:42:09;0100;Server@node2;Req;;Type 11 request received from Scheduler@node2.supernodexp.hpc, sock=16
05/04/2018 03:42:09;0008;Server@node2;Job;15144.node2.supernodexp.hpc;Job Modified at request of Scheduler@node2.supernodexp.hpc
05/04/2018 03:43:04;0080;Server@node2;Job;15083.node2.supernodexp.hpc;Obit received momhop:1 serverhop:1 state:4 substate:42
05/04/2018 03:43:05;0010;Server@node2;Job;15083.node2.supernodexp.hpc;Exit_status=2 resources_used.cpupercent=0 resources_used.cput=00:00:00 resources_used.mem=11820kb resources_used.ncpus=32 resources_used.vmem=748212kb resources_used.walltime=00:18:48
05/04/2018 03:43:05;0100;Server@node2;Job;15083.node2.supernodexp.hpc;dequeuing from workq, state 5
05/04/2018 03:43:05;0040;Server@node2;Svr;node2.supernodexp.hpc;Scheduler sent command 2
05/04/2018 03:43:05;0040;Server@node2;Svr;node2.supernodexp.hpc;Scheduler sent command 0
05/04/2018 03:43:05;0100;Server@node2;Req;;Type 21 request received from Scheduler@node2.supernodexp.hpc, sock=16
05/04/2018 03:43:05;0100;Server@node2;Req;;Type 81 request received from Scheduler@node2.supernodexp.hpc, sock=16
05/04/2018 03:43:05;0100;Server@node2;Req;;Type 71 request received from Scheduler@node2.supernodexp.hpc, sock=16
05/04/2018 03:43:05;0100;Server@node2;Req;;Type 58 request received from Scheduler@node2.supernodexp.hpc, sock=16
05/04/2018 03:43:05;0100;Server@node2;Req;;Type 20 request received from Scheduler@node2.supernodexp.hpc, sock=16
05/04/2018 03:43:05;0100;Server@node2;Req;;Type 51 request received from Scheduler@node2.supernodexp.hpc, sock=16
05/04/2018 03:43:05;0100;Server@node2;Req;;Type 23 request received from Scheduler@node2.supernodexp.hpc, sock=16
05/04/2018 03:43:05;0008;Server@node2;Job;15144.node2.supernodexp.hpc;Job Run at request of Scheduler@node2.supernodexp.hpc on exec_vnode (node13:ncpus=32:nmics=2:mem=31457280kb)
05/04/2018 03:43:05;0001;Server@node2;Svr;Server@node2;Success (0) in req_runjob2, return value of svr_startjob is 0
05/04/2018 03:43:05;0100;Server@node2;Req;;Type 11 request received from Scheduler@node2.supernodexp.hpc, sock=16
05/04/2018 03:43:05;0008;Server@node2;Job;15211.node2.supernodexp.hpc;Job Modified at request of Scheduler@node2.supernodexp.hpc
05/04/2018 03:44:36;0080;Server@node2;Job;15092.node2.supernodexp.hpc;Obit received momhop:1 serverhop:1 state:4 substate:42
05/04/2018 03:44:37;0010;Server@node2;Job;15092.node2.supernodexp.hpc;Exit_status=2 resources_used.cpupercent=0 resources_used.cput=00:00:00 resources_used.mem=9440kb resources_used.ncpus=32 resources_used.vmem=103036kb resources_used.walltime=00:20:07
05/04/2018 03:44:37;0100;Server@node2;Job;15092.node2.supernodexp.hpc;dequeuing from workq, state 5
05/04/2018 03:44:37;0040;Server@node2;Svr;node2.supernodexp.hpc;Scheduler sent command 2
05/04/2018 03:44:37;0040;Server@node2;Svr;node2.supernodexp.hpc;Scheduler sent command 0
05/04/2018 03:44:37;0100;Server@node2;Req;;Type 21 request received from Scheduler@node2.supernodexp.hpc, sock=16
05/04/2018 03:44:37;0100;Server@node2;Req;;Type 81 request received from Scheduler@node2.supernodexp.hpc, sock=16
05/04/2018 03:44:37;0100;Server@node2;Req;;Type 71 request received from Scheduler@node2.supernodexp.hpc, sock=16
05/04/2018 03:44:37;0100;Server@node2;Req;;Type 58 request received from Scheduler@node2.supernodexp.hpc, sock=16
05/04/2018 03:44:37;0100;Server@node2;Req;;Type 20 request received from Scheduler@node2.supernodexp.hpc, sock=16
05/04/2018 03:44:37;0100;Server@node2;Req;;Type 51 request received from Scheduler@node2.supernodexp.hpc, sock=16
05/04/2018 03:44:37;0100;Server@node2;Req;;Type 23 request received from Scheduler@node2.supernodexp.hpc, sock=16
05/04/2018 03:44:37;0008;Server@node2;Job;15211.node2.supernodexp.hpc;Job Run at request of Scheduler@node2.supernodexp.hpc on exec_vnode (node3:ncpus=32:nmics=2:mem=31457280kb)
05/04/2018 03:44:37;0001;Server@node2;Svr;Server@node2;Success (0) in req_runjob2, return value of svr_startjob is 0
05/04/2018 03:44:37;0100;Server@node2;Req;;Type 11 request received from Scheduler@node2.supernodexp.hpc, sock=16
05/04/2018 03:44:37;0008;Server@node2;Job;15256.node2.supernodexp.hpc;Job Modified at request of Scheduler@node2.supernodexp.hpc
05/04/2018 03:54:37;0040;Server@node2;Svr;node2.supernodexp.hpc;Scheduler sent command 3
05/04/2018 03:54:37;0040;Server@node2;Svr;node2.supernodexp.hpc;Scheduler sent command 0
05/04/2018 03:54:37;0100;Server@node2;Req;;Type 21 request received from Scheduler@node2.supernodexp.hpc, sock=16
05/04/2018 03:54:37;0100;Server@node2;Req;;Type 81 request received from Scheduler@node2.supernodexp.hpc, sock=16
05/04/2018 03:54:37;0100;Server@node2;Req;;Type 71 request received from Scheduler@node2.supernodexp.hpc, sock=16
05/04/2018 03:54:37;0100;Server@node2;Req;;Type 58 request received from Scheduler@node2.supernodexp.hpc, sock=16
05/04/2018 03:54:37;0100;Server@node2;Req;;Type 20 request received from Scheduler@node2.supernodexp.hpc, sock=16
05/04/2018 03:54:37;0100;Server@node2;Req;;Type 51 request received from Scheduler@node2.supernodexp.hpc, sock=16
05/04/2018 04:01:10;0080;Server@node2;Job;15142.node2.supernodexp.hpc;Obit received momhop:1 serverhop:1 state:4 substate:42
05/04/2018 04:01:11;0010;Server@node2;Job;15142.node2.supernodexp.hpc;Exit_status=2 resources_used.cpupercent=0 resources_used.cput=00:00:00 resources_used.mem=10300kb resources_used.ncpus=32 resources_used.vmem=106036kb resources_used.walltime=00:19:01
05/04/2018 04:01:11;0100;Server@node2;Job;15142.node2.supernodexp.hpc;dequeuing from workq, state 5
05/04/2018 04:01:11;0040;Server@node2;Svr;node2.supernodexp.hpc;Scheduler sent command 2
05/04/2018 04:01:11;0040;Server@node2;Svr;node2.supernodexp.hpc;Scheduler sent command 0
05/04/2018 04:01:11;0100;Server@node2;Req;;Type 21 request received from Scheduler@node2.supernodexp.hpc, sock=16
05/04/2018 04:01:11;0100;Server@node2;Req;;Type 81 request received from Scheduler@node2.supernodexp.hpc, sock=16
05/04/2018 04:01:11;0100;Server@node2;Req;;Type 71 request received from Scheduler@node2.supernodexp.hpc, sock=16
05/04/2018 04:01:11;0100;Server@node2;Req;;Type 58 request received from Scheduler@node2.supernodexp.hpc, sock=16
05/04/2018 04:01:11;0100;Server@node2;Req;;Type 20 request received from Scheduler@node2.supernodexp.hpc, sock=16
05/04/2018 04:01:11;0100;Server@node2;Req;;Type 51 request received from Scheduler@node2.supernodexp.hpc, sock=16
05/04/2018 04:01:11;0100;Server@node2;Req;;Type 23 request received from Scheduler@node2.supernodexp.hpc, sock=16
05/04/2018 04:01:11;0008;Server@node2;Job;15256.node2.supernodexp.hpc;Job Run at request of Scheduler@node2.supernodexp.hpc on exec_vnode (node14:ncpus=32:nmics=2:mem=31457280kb)
05/04/2018 04:01:11;0001;Server@node2;Svr;Server@node2;Success (0) in req_runjob2, return value of svr_startjob is 0
05/04/2018 04:01:11;0100;Server@node2;Req;;Type 11 request received from Scheduler@node2.supernodexp.hpc, sock=16
05/04/2018 04:01:11;0008;Server@node2;Job;15263.node2.supernodexp.hpc;Job Modified at request of Scheduler@node2.supernodexp.hpc
05/04/2018 04:01:53;0080;Server@node2;Job;15144.node2.supernodexp.hpc;Obit received momhop:1 serverhop:1 state:4 substate:42
05/04/2018 04:01:54;0010;Server@node2;Job;15144.node2.supernodexp.hpc;Exit_status=2 resources_used.cpupercent=0 resources_used.cput=00:00:00 resources_used.mem=10012kb resources_used.ncpus=32 resources_used.vmem=171960kb resources_used.walltime=00:18:47
05/04/2018 04:01:54;0100;Server@node2;Job;15144.node2.supernodexp.hpc;dequeuing from workq, state 5
05/04/2018 04:01:54;0040;Server@node2;Svr;node2.supernodexp.hpc;Scheduler sent command 2
05/04/2018 04:01:54;0040;Server@node2;Svr;node2.supernodexp.hpc;Scheduler sent command 0
05/04/2018 04:01:54;0100;Server@node2;Req;;Type 21 request received from Scheduler@node2.supernodexp.hpc, sock=16
05/04/2018 04:01:54;0100;Server@node2;Req;;Type 81 request received from Scheduler@node2.supernodexp.hpc, sock=16
05/04/2018 04:01:54;0100;Server@node2;Req;;Type 71 request received from Scheduler@node2.supernodexp.hpc, sock=16
05/04/2018 04:01:54;0100;Server@node2;Req;;Type 58 request received from Scheduler@node2.supernodexp.hpc, sock=16
05/04/2018 04:01:54;0100;Server@node2;Req;;Type 20 request received from Scheduler@node2.supernodexp.hpc, sock=16
05/04/2018 04:01:54;0100;Server@node2;Req;;Type 51 request received from Scheduler@node2.supernodexp.hpc, sock=16
05/04/2018 04:01:54;0100;Server@node2;Req;;Type 23 request received from Scheduler@node2.supernodexp.hpc, sock=16
05/04/2018 04:01:54;0008;Server@node2;Job;15263.node2.supernodexp.hpc;Job Run at request of Scheduler@node2.supernodexp.hpc on exec_vnode (node13:ncpus=32:nmics=2:mem=31457280kb)
05/04/2018 04:01:54;0001;Server@node2;Svr;Server@node2;Success (0) in req_runjob2, return value of svr_startjob is 0
05/04/2018 04:01:54;0100;Server@node2;Req;;Type 11 request received from Scheduler@node2.supernodexp.hpc, sock=16
05/04/2018 04:01:54;0008;Server@node2;Job;15283.node2.supernodexp.hpc;Job Modified at request of Scheduler@node2.supernodexp.hpc
05/04/2018 04:04:49;0080;Server@node2;Job;15211.node2.supernodexp.hpc;Obit received momhop:1 serverhop:1 state:4 substate:42
05/04/2018 04:04:50;0010;Server@node2;Job;15211.node2.supernodexp.hpc;Exit_status=2 resources_used.cpupercent=0 resources_used.cput=00:00:00 resources_used.mem=9580kb resources_used.ncpus=32 resources_used.vmem=106404kb resources_used.walltime=00:20:12
05/04/2018 04:04:50;0100;Server@node2;Job;15211.node2.supernodexp.hpc;dequeuing from workq, state 5
05/04/2018 04:04:50;0040;Server@node2;Svr;node2.supernodexp.hpc;Scheduler sent command 2
05/04/2018 04:04:50;0040;Server@node2;Svr;node2.supernodexp.hpc;Scheduler sent command 0
05/04/2018 04:04:50;0100;Server@node2;Req;;Type 21 request received from Scheduler@node2.supernodexp.hpc, sock=16
05/04/2018 04:04:50;0100;Server@node2;Req;;Type 81 request received from Scheduler@node2.supernodexp.hpc, sock=16
05/04/2018 04:04:50;0100;Server@node2;Req;;Type 71 request received from Scheduler@node2.supernodexp.hpc, sock=16
05/04/2018 04:04:50;0100;Server@node2;Req;;Type 58 request received from Scheduler@node2.supernodexp.hpc, sock=16
05/04/2018 04:04:50;0100;Server@node2;Req;;Type 20 request received from Scheduler@node2.supernodexp.hpc, sock=16
05/04/2018 04:04:50;0100;Server@node2;Req;;Type 51 request received from Scheduler@node2.supernodexp.hpc, sock=16
05/04/2018 04:04:50;0100;Server@node2;Req;;Type 23 request received from Scheduler@node2.supernodexp.hpc, sock=16
05/04/2018 04:04:50;0008;Server@node2;Job;15283.node2.supernodexp.hpc;Job Run at request of Scheduler@node2.supernodexp.hpc on exec_vnode (node3:ncpus=32:nmics=2:mem=31457280kb)
05/04/2018 04:04:50;0001;Server@node2;Svr;Server@node2;Success (0) in req_runjob2, return value of svr_startjob is 0
05/04/2018 04:04:50;0100;Server@node2;Req;;Type 11 request received from Scheduler@node2.supernodexp.hpc, sock=16
05/04/2018 04:04:50;0008;Server@node2;Job;15285.node2.supernodexp.hpc;Job Modified at request of Scheduler@node2.supernodexp.hpc
05/04/2018 04:14:50;0040;Server@node2;Svr;node2.supernodexp.hpc;Scheduler sent command 3
05/04/2018 04:14:50;0040;Server@node2;Svr;node2.supernodexp.hpc;Scheduler sent command 0
05/04/2018 04:14:50;0100;Server@node2;Req;;Type 21 request received from Scheduler@node2.supernodexp.hpc, sock=16
05/04/2018 04:14:50;0100;Server@node2;Req;;Type 81 request received from Scheduler@node2.supernodexp.hpc, sock=16
05/04/2018 04:14:50;0100;Server@node2;Req;;Type 71 request received from Scheduler@node2.supernodexp.hpc, sock=16
05/04/2018 04:14:50;0100;Server@node2;Req;;Type 58 request received from Scheduler@node2.supernodexp.hpc, sock=16
05/04/2018 04:14:50;0100;Server@node2;Req;;Type 20 request received from Scheduler@node2.supernodexp.hpc, sock=16
05/04/2018 04:14:50;0100;Server@node2;Req;;Type 51 request received from Scheduler@node2.supernodexp.hpc, sock=16
05/04/2018 04:20:03;0080;Server@node2;Job;15256.node2.supernodexp.hpc;Obit received momhop:1 serverhop:1 state:4 substate:42
05/04/2018 04:20:04;0010;Server@node2;Job;15256.node2.supernodexp.hpc;Exit_status=2 resources_used.cpupercent=0 resources_used.cput=00:00:00 resources_used.mem=10100kb resources_used.ncpus=32 resources_used.vmem=104628kb resources_used.walltime=00:18:52
05/04/2018 04:20:04;0100;Server@node2;Job;15256.node2.supernodexp.hpc;dequeuing from workq, state 5
05/04/2018 04:20:04;0040;Server@node2;Svr;node2.supernodexp.hpc;Scheduler sent command 2
05/04/2018 04:20:04;0040;Server@node2;Svr;node2.supernodexp.hpc;Scheduler sent command 0
05/04/2018 04:20:04;0100;Server@node2;Req;;Type 21 request received from Scheduler@node2.supernodexp.hpc, sock=16
05/04/2018 04:20:04;0100;Server@node2;Req;;Type 81 request received from Scheduler@node2.supernodexp.hpc, sock=16
05/04/2018 04:20:04;0100;Server@node2;Req;;Type 71 request received from Scheduler@node2.supernodexp.hpc, sock=16
05/04/2018 04:20:04;0100;Server@node2;Req;;Type 58 request received from Scheduler@node2.supernodexp.hpc, sock=16
05/04/2018 04:20:04;0100;Server@node2;Req;;Type 20 request received from Scheduler@node2.supernodexp.hpc, sock=16
05/04/2018 04:20:04;0100;Server@node2;Req;;Type 51 request received from Scheduler@node2.supernodexp.hpc, sock=16
05/04/2018 04:20:04;0100;Server@node2;Req;;Type 23 request received from Scheduler@node2.supernodexp.hpc, sock=16
05/04/2018 04:20:04;0008;Server@node2;Job;15285.node2.supernodexp.hpc;Job Run at request of Scheduler@node2.supernodexp.hpc on exec_vnode (node14:ncpus=32:nmics=2:mem=31457280kb)
05/04/2018 04:20:04;0001;Server@node2;Svr;Server@node2;Success (0) in req_runjob2, return value of svr_startjob is 0
05/04/2018 04:20:04;0100;Server@node2;Req;;Type 11 request received from Scheduler@node2.supernodexp.hpc, sock=16
05/04/2018 04:20:04;0008;Server@node2;Job;15302.node2.supernodexp.hpc;Job Modified at request of Scheduler@node2.supernodexp.hpc
05/04/2018 04:20:41;0080;Server@node2;Job;15263.node2.supernodexp.hpc;Obit received momhop:1 serverhop:1 state:4 substate:42
05/04/2018 04:20:42;0010;Server@node2;Job;15263.node2.supernodexp.hpc;Exit_status=2 resources_used.cpupercent=0 resources_used.cput=00:00:00 resources_used.mem=9604kb resources_used.ncpus=32 resources_used.vmem=172216kb resources_used.walltime=00:18:47
05/04/2018 04:20:42;0100;Server@node2;Job;15263.node2.supernodexp.hpc;dequeuing from workq, state 5
05/04/2018 04:20:42;0040;Server@node2;Svr;node2.supernodexp.hpc;Scheduler sent command 2
05/04/2018 04:20:42;0040;Server@node2;Svr;node2.supernodexp.hpc;Scheduler sent command 0
05/04/2018 04:20:42;0100;Server@node2;Req;;Type 21 request received from Scheduler@node2.supernodexp.hpc, sock=16
05/04/2018 04:20:42;0100;Server@node2;Req;;Type 81 request received from Scheduler@node2.supernodexp.hpc, sock=16
05/04/2018 04:20:42;0100;Server@node2;Req;;Type 71 request received from Scheduler@node2.supernodexp.hpc, sock=16
05/04/2018 04:20:42;0100;Server@node2;Req;;Type 58 request received from Scheduler@node2.supernodexp.hpc, sock=16
05/04/2018 04:20:42;0100;Server@node2;Req;;Type 20 request received from Scheduler@node2.supernodexp.hpc, sock=16
05/04/2018 04:20:42;0100;Server@node2;Req;;Type 51 request received from Scheduler@node2.supernodexp.hpc, sock=16
05/04/2018 04:20:42;0100;Server@node2;Req;;Type 23 request received from Scheduler@node2.supernodexp.hpc, sock=16
05/04/2018 04:20:42;0008;Server@node2;Job;15302.node2.supernodexp.hpc;Job Run at request of Scheduler@node2.supernodexp.hpc on exec_vnode (node13:ncpus=32:nmics=2:mem=31457280kb)
05/04/2018 04:20:42;0001;Server@node2;Svr;Server@node2;Success (0) in req_runjob2, return value of svr_startjob is 0
05/04/2018 04:20:42;0100;Server@node2;Req;;Type 11 request received from Scheduler@node2.supernodexp.hpc, sock=16
05/04/2018 04:20:42;0008;Server@node2;Job;15317.node2.supernodexp.hpc;Job Modified at request of Scheduler@node2.supernodexp.hpc
05/04/2018 04:25:08;0080;Server@node2;Job;15283.node2.supernodexp.hpc;Obit received momhop:1 serverhop:1 state:4 substate:42
05/04/2018 04:25:09;0010;Server@node2;Job;15283.node2.supernodexp.hpc;Exit_status=2 resources_used.cpupercent=0 resources_used.cput=00:00:00 resources_used.mem=9448kb resources_used.ncpus=32 resources_used.vmem=103292kb resources_used.walltime=00:20:18
05/04/2018 04:25:09;0100;Server@node2;Job;15283.node2.supernodexp.hpc;dequeuing from workq, state 5
05/04/2018 04:25:09;0040;Server@node2;Svr;node2.supernodexp.hpc;Scheduler sent command 2
05/04/2018 04:25:09;0040;Server@node2;Svr;node2.supernodexp.hpc;Scheduler sent command 0
05/04/2018 04:25:09;0100;Server@node2;Req;;Type 21 request received from Scheduler@node2.supernodexp.hpc, sock=16
05/04/2018 04:25:09;0100;Server@node2;Req;;Type 81 request received from Scheduler@node2.supernodexp.hpc, sock=16
05/04/2018 04:25:09;0100;Server@node2;Req;;Type 71 request received from Scheduler@node2.supernodexp.hpc, sock=16
05/04/2018 04:25:09;0100;Server@node2;Req;;Type 58 request received from Scheduler@node2.supernodexp.hpc, sock=16
05/04/2018 04:25:09;0100;Server@node2;Req;;Type 20 request received from Scheduler@node2.supernodexp.hpc, sock=16
05/04/2018 04:25:09;0100;Server@node2;Req;;Type 51 request received from Scheduler@node2.supernodexp.hpc, sock=16
05/04/2018 04:25:09;0100;Server@node2;Req;;Type 23 request received from Scheduler@node2.supernodexp.hpc, sock=16
05/04/2018 04:25:09;0008;Server@node2;Job;15317.node2.supernodexp.hpc;Job Run at request of Scheduler@node2.supernodexp.hpc on exec_vnode (node3:ncpus=32:nmics=2:mem=31457280kb)
05/04/2018 04:25:09;0001;Server@node2;Svr;Server@node2;Success (0) in req_runjob2, return value of svr_startjob is 0
05/04/2018 04:25:09;0100;Server@node2;Req;;Type 11 request received from Scheduler@node2.supernodexp.hpc, sock=16
05/04/2018 04:25:09;0008;Server@node2;Job;15357.node2.supernodexp.hpc;Job Modified at request of Scheduler@node2.supernodexp.hpc
05/04/2018 04:35:09;0040;Server@node2;Svr;node2.supernodexp.hpc;Scheduler sent command 3
05/04/2018 04:35:09;0040;Server@node2;Svr;node2.supernodexp.hpc;Scheduler sent command 0
05/04/2018 04:35:09;0100;Server@node2;Req;;Type 21 request received from Scheduler@node2.supernodexp.hpc, sock=16
05/04/2018 04:35:09;0100;Server@node2;Req;;Type 81 request received from Scheduler@node2.supernodexp.hpc, sock=16
05/04/2018 04:35:09;0100;Server@node2;Req;;Type 71 request received from Scheduler@node2.supernodexp.hpc, sock=16
05/04/2018 04:35:09;0100;Server@node2;Req;;Type 58 request received from Scheduler@node2.supernodexp.hpc, sock=16
05/04/2018 04:35:09;0100;Server@node2;Req;;Type 20 request received from Scheduler@node2.supernodexp.hpc, sock=16
05/04/2018 04:35:09;0100;Server@node2;Req;;Type 51 request received from Scheduler@node2.supernodexp.hpc, sock=16
05/04/2018 04:38:52;0080;Server@node2;Job;15285.node2.supernodexp.hpc;Obit received momhop:1 serverhop:1 state:4 substate:42
05/04/2018 04:38:53;0010;Server@node2;Job;15285.node2.supernodexp.hpc;Exit_status=2 resources_used.cpupercent=0 resources_used.cput=00:00:00 resources_used.mem=10252kb resources_used.ncpus=32 resources_used.vmem=106036kb resources_used.walltime=00:18:48
05/04/2018 04:38:53;0100;Server@node2;Job;15285.node2.supernodexp.hpc;dequeuing from workq, state 5
05/04/2018 04:38:53;0040;Server@node2;Svr;node2.supernodexp.hpc;Scheduler sent command 2
05/04/2018 04:38:53;0040;Server@node2;Svr;node2.supernodexp.hpc;Scheduler sent command 0
05/04/2018 04:38:53;0100;Server@node2;Req;;Type 21 request received from Scheduler@node2.supernodexp.hpc, sock=16
05/04/2018 04:38:53;0100;Server@node2;Req;;Type 81 request received from Scheduler@node2.supernodexp.hpc, sock=16
05/04/2018 04:38:53;0100;Server@node2;Req;;Type 71 request received from Scheduler@node2.supernodexp.hpc, sock=16
05/04/2018 04:38:53;0100;Server@node2;Req;;Type 58 request received from Scheduler@node2.supernodexp.hpc, sock=16
05/04/2018 04:38:53;0100;Server@node2;Req;;Type 20 request received from Scheduler@node2.supernodexp.hpc, sock=16
05/04/2018 04:38:53;0100;Server@node2;Req;;Type 51 request received from Scheduler@node2.supernodexp.hpc, sock=16
05/04/2018 04:38:53;0100;Server@node2;Req;;Type 23 request received from Scheduler@node2.supernodexp.hpc, sock=16
05/04/2018 04:38:53;0008;Server@node2;Job;15357.node2.supernodexp.hpc;Job Run at request of Scheduler@node2.supernodexp.hpc on exec_vnode (node14:ncpus=32:nmics=2:mem=31457280kb)
05/04/2018 04:38:53;0001;Server@node2;Svr;Server@node2;Success (0) in req_runjob2, return value of svr_startjob is 0
05/04/2018 04:38:53;0100;Server@node2;Req;;Type 11 request received from Scheduler@node2.supernodexp.hpc, sock=16
05/04/2018 04:38:53;0008;Server@node2;Job;15391.node2.supernodexp.hpc;Job Modified at request of Scheduler@node2.supernodexp.hpc
05/04/2018 04:39:29;0080;Server@node2;Job;15302.node2.supernodexp.hpc;Obit received momhop:1 serverhop:1 state:4 substate:42
05/04/2018 04:39:29;0010;Server@node2;Job;15302.node2.supernodexp.hpc;Exit_status=2 resources_used.cpupercent=0 resources_used.cput=00:00:00 resources_used.mem=9636kb resources_used.ncpus=32 resources_used.vmem=171960kb resources_used.walltime=00:18:47
05/04/2018 04:39:29;0100;Server@node2;Job;15302.node2.supernodexp.hpc;dequeuing from workq, state 5
05/04/2018 04:39:29;0040;Server@node2;Svr;node2.supernodexp.hpc;Scheduler sent command 2
05/04/2018 04:39:29;0040;Server@node2;Svr;node2.supernodexp.hpc;Scheduler sent command 0
05/04/2018 04:39:29;0100;Server@node2;Req;;Type 21 request received from Scheduler@node2.supernodexp.hpc, sock=16
05/04/2018 04:39:29;0100;Server@node2;Req;;Type 81 request received from Scheduler@node2.supernodexp.hpc, sock=16
05/04/2018 04:39:29;0100;Server@node2;Req;;Type 71 request received from Scheduler@node2.supernodexp.hpc, sock=16
05/04/2018 04:39:29;0100;Server@node2;Req;;Type 58 request received from Scheduler@node2.supernodexp.hpc, sock=16
05/04/2018 04:39:30;0100;Server@node2;Req;;Type 20 request received from Scheduler@node2.supernodexp.hpc, sock=16
05/04/2018 04:39:30;0100;Server@node2;Req;;Type 51 request received from Scheduler@node2.supernodexp.hpc, sock=16
05/04/2018 04:39:30;0100;Server@node2;Req;;Type 23 request received from Scheduler@node2.supernodexp.hpc, sock=16
05/04/2018 04:39:30;0008;Server@node2;Job;15391.node2.supernodexp.hpc;Job Run at request of Scheduler@node2.supernodexp.hpc on exec_vnode (node13:ncpus=32:nmics=2:mem=31457280kb)
05/04/2018 04:39:30;0001;Server@node2;Svr;Server@node2;Success (0) in req_runjob2, return value of svr_startjob is 0
05/04/2018 04:39:30;0100;Server@node2;Req;;Type 11 request received from Scheduler@node2.supernodexp.hpc, sock=16
05/04/2018 04:39:30;0008;Server@node2;Job;15394.node2.supernodexp.hpc;Job Modified at request of Scheduler@node2.supernodexp.hpc
05/04/2018 04:45:31;0080;Server@node2;Job;15317.node2.supernodexp.hpc;Obit received momhop:1 serverhop:1 state:4 substate:42
05/04/2018 04:45:32;0010;Server@node2;Job;15317.node2.supernodexp.hpc;Exit_status=2 resources_used.cpupercent=0 resources_used.cput=00:00:00 resources_used.mem=9700kb resources_used.ncpus=32 resources_used.vmem=170880kb resources_used.walltime=00:20:22
05/04/2018 04:45:32;0100;Server@node2;Job;15317.node2.supernodexp.hpc;dequeuing from workq, state 5
05/04/2018 04:45:32;0040;Server@node2;Svr;node2.supernodexp.hpc;Scheduler sent command 2
05/04/2018 04:45:32;0040;Server@node2;Svr;node2.supernodexp.hpc;Scheduler sent command 0
05/04/2018 04:45:32;0100;Server@node2;Req;;Type 21 request received from Scheduler@node2.supernodexp.hpc, sock=16
05/04/2018 04:45:32;0100;Server@node2;Req;;Type 81 request received from Scheduler@node2.supernodexp.hpc, sock=16
05/04/2018 04:45:32;0100;Server@node2;Req;;Type 71 request received from Scheduler@node2.supernodexp.hpc, sock=16
05/04/2018 04:45:32;0100;Server@node2;Req;;Type 58 request received from Scheduler@node2.supernodexp.hpc, sock=16
05/04/2018 04:45:32;0100;Server@node2;Req;;Type 20 request received from Scheduler@node2.supernodexp.hpc, sock=16
05/04/2018 04:45:32;0100;Server@node2;Req;;Type 51 request received from Scheduler@node2.supernodexp.hpc, sock=16
05/04/2018 04:45:32;0100;Server@node2;Req;;Type 23 request received from Scheduler@node2.supernodexp.hpc, sock=16
05/04/2018 04:45:32;0008;Server@node2;Job;15394.node2.supernodexp.hpc;Job Run at request of Scheduler@node2.supernodexp.hpc on exec_vnode (node3:ncpus=32:nmics=2:mem=31457280kb)
05/04/2018 04:45:32;0001;Server@node2;Svr;Server@node2;Success (0) in req_runjob2, return value of svr_startjob is 0
05/04/2018 04:45:32;0100;Server@node2;Req;;Type 11 request received from Scheduler@node2.supernodexp.hpc, sock=16
05/04/2018 04:45:32;0008;Server@node2;Job;15399.node2.supernodexp.hpc;Job Modified at request of Scheduler@node2.supernodexp.hpc
05/04/2018 04:55:32;0040;Server@node2;Svr;node2.supernodexp.hpc;Scheduler sent command 3
05/04/2018 04:55:32;0040;Server@node2;Svr;node2.supernodexp.hpc;Scheduler sent command 0
05/04/2018 04:55:32;0100;Server@node2;Req;;Type 21 request received from Scheduler@node2.supernodexp.hpc, sock=16
05/04/2018 04:55:32;0100;Server@node2;Req;;Type 81 request received from Scheduler@node2.supernodexp.hpc, sock=16
05/04/2018 04:55:32;0100;Server@node2;Req;;Type 71 request received from Scheduler@node2.supernodexp.hpc, sock=16
05/04/2018 04:55:32;0100;Server@node2;Req;;Type 58 request received from Scheduler@node2.supernodexp.hpc, sock=16
05/04/2018 04:55:32;0100;Server@node2;Req;;Type 20 request received from Scheduler@node2.supernodexp.hpc, sock=16
05/04/2018 04:55:32;0100;Server@node2;Req;;Type 51 request received from Scheduler@node2.supernodexp.hpc, sock=16
05/04/2018 04:57:38;0080;Server@node2;Job;15357.node2.supernodexp.hpc;Obit received momhop:1 serverhop:1 state:4 substate:42
05/04/2018 04:57:39;0010;Server@node2;Job;15357.node2.supernodexp.hpc;Exit_status=2 resources_used.cpupercent=0 resources_used.cput=00:00:00 resources_used.mem=9884kb resources_used.ncpus=32 resources_used.vmem=880692kb resources_used.walltime=00:18:45
05/04/2018 04:57:39;0100;Server@node2;Job;15357.node2.supernodexp.hpc;dequeuing from workq, state 5
05/04/2018 04:57:39;0040;Server@node2;Svr;node2.supernodexp.hpc;Scheduler sent command 2
05/04/2018 04:57:39;0040;Server@node2;Svr;node2.supernodexp.hpc;Scheduler sent command 0
05/04/2018 04:57:39;0100;Server@node2;Req;;Type 21 request received from Scheduler@node2.supernodexp.hpc, sock=16
05/04/2018 04:57:39;0100;Server@node2;Req;;Type 81 request received from Scheduler@node2.supernodexp.hpc, sock=16
05/04/2018 04:57:39;0100;Server@node2;Req;;Type 71 request received from Scheduler@node2.supernodexp.hpc, sock=16
05/04/2018 04:57:39;0100;Server@node2;Req;;Type 58 request received from Scheduler@node2.supernodexp.hpc, sock=16
05/04/2018 04:57:39;0100;Server@node2;Req;;Type 20 request received from Scheduler@node2.supernodexp.hpc, sock=16
05/04/2018 04:57:39;0100;Server@node2;Req;;Type 51 request received from Scheduler@node2.supernodexp.hpc, sock=16
05/04/2018 04:57:39;0100;Server@node2;Req;;Type 23 request received from Scheduler@node2.supernodexp.hpc, sock=16
05/04/2018 04:57:39;0008;Server@node2;Job;15399.node2.supernodexp.hpc;Job Run at request of Scheduler@node2.supernodexp.hpc on exec_vnode (node14:ncpus=32:nmics=2:mem=31457280kb)
05/04/2018 04:57:39;0001;Server@node2;Svr;Server@node2;Success (0) in req_runjob2, return value of svr_startjob is 0
05/04/2018 04:57:39;0100;Server@node2;Req;;Type 11 request received from Scheduler@node2.supernodexp.hpc, sock=16
05/04/2018 04:57:39;0008;Server@node2;Job;15416.node2.supernodexp.hpc;Job Modified at request of Scheduler@node2.supernodexp.hpc
05/04/2018 04:58:30;0080;Server@node2;Job;15391.node2.supernodexp.hpc;Obit received momhop:1 serverhop:1 state:4 substate:42
05/04/2018 04:58:30;0010;Server@node2;Job;15391.node2.supernodexp.hpc;Exit_status=2 resources_used.cpupercent=0 resources_used.cput=00:00:00 resources_used.mem=10236kb resources_used.ncpus=32 resources_used.vmem=108088kb resources_used.walltime=00:19:00
05/04/2018 04:58:30;0100;Server@node2;Job;15391.node2.supernodexp.hpc;dequeuing from workq, state 5
05/04/2018 04:58:30;0040;Server@node2;Svr;node2.supernodexp.hpc;Scheduler sent command 2
05/04/2018 04:58:30;0040;Server@node2;Svr;node2.supernodexp.hpc;Scheduler sent command 0
05/04/2018 04:58:30;0100;Server@node2;Req;;Type 21 request received from Scheduler@node2.supernodexp.hpc, sock=16
05/04/2018 04:58:30;0100;Server@node2;Req;;Type 81 request received from Scheduler@node2.supernodexp.hpc, sock=16
05/04/2018 04:58:30;0100;Server@node2;Req;;Type 71 request received from Scheduler@node2.supernodexp.hpc, sock=16
05/04/2018 04:58:30;0100;Server@node2;Req;;Type 58 request received from Scheduler@node2.supernodexp.hpc, sock=16
05/04/2018 04:58:31;0100;Server@node2;Req;;Type 20 request received from Scheduler@node2.supernodexp.hpc, sock=16
05/04/2018 04:58:31;0100;Server@node2;Req;;Type 51 request received from Scheduler@node2.supernodexp.hpc, sock=16
05/04/2018 04:58:31;0100;Server@node2;Req;;Type 23 request received from Scheduler@node2.supernodexp.hpc, sock=16
05/04/2018 04:58:31;0008;Server@node2;Job;15416.node2.supernodexp.hpc;Job Run at request of Scheduler@node2.supernodexp.hpc on exec_vnode (node13:ncpus=32:nmics=2:mem=31457280kb)
05/04/2018 04:58:31;0001;Server@node2;Svr;Server@node2;Success (0) in req_runjob2, return value of svr_startjob is 0
05/04/2018 04:58:31;0100;Server@node2;Req;;Type 11 request received from Scheduler@node2.supernodexp.hpc, sock=16
05/04/2018 04:58:31;0008;Server@node2;Job;15473.node2.supernodexp.hpc;Job Modified at request of Scheduler@node2.supernodexp.hpc
05/04/2018 05:05:44;0080;Server@node2;Job;15394.node2.supernodexp.hpc;Obit received momhop:1 serverhop:1 state:4 substate:42
05/04/2018 05:05:45;0010;Server@node2;Job;15394.node2.supernodexp.hpc;Exit_status=2 resources_used.cpupercent=0 resources_used.cput=00:00:00 resources_used.mem=9432kb resources_used.ncpus=32 resources_used.vmem=105088kb resources_used.walltime=00:20:12
05/04/2018 05:05:45;0100;Server@node2;Job;15394.node2.supernodexp.hpc;dequeuing from workq, state 5
05/04/2018 05:05:45;0040;Server@node2;Svr;node2.supernodexp.hpc;Scheduler sent command 2
05/04/2018 05:05:45;0040;Server@node2;Svr;node2.supernodexp.hpc;Scheduler sent command 0
05/04/2018 05:05:45;0100;Server@node2;Req;;Type 21 request received from Scheduler@node2.supernodexp.hpc, sock=16
05/04/2018 05:05:45;0100;Server@node2;Req;;Type 81 request received from Scheduler@node2.supernodexp.hpc, sock=16
05/04/2018 05:05:45;0100;Server@node2;Req;;Type 71 request received from Scheduler@node2.supernodexp.hpc, sock=16
05/04/2018 05:05:45;0100;Server@node2;Req;;Type 58 request received from Scheduler@node2.supernodexp.hpc, sock=16
05/04/2018 05:05:45;0100;Server@node2;Req;;Type 20 request received from Scheduler@node2.supernodexp.hpc, sock=16
05/04/2018 05:05:45;0100;Server@node2;Req;;Type 51 request received from Scheduler@node2.supernodexp.hpc, sock=16
05/04/2018 05:05:45;0100;Server@node2;Req;;Type 23 request received from Scheduler@node2.supernodexp.hpc, sock=16
05/04/2018 05:05:45;0008;Server@node2;Job;15473.node2.supernodexp.hpc;Job Run at request of Scheduler@node2.supernodexp.hpc on exec_vnode (node3:ncpus=32:nmics=2:mem=31457280kb)
05/04/2018 05:05:45;0001;Server@node2;Svr;Server@node2;Success (0) in req_runjob2, return value of svr_startjob is 0
05/04/2018 05:05:45;0100;Server@node2;Req;;Type 11 request received from Scheduler@node2.supernodexp.hpc, sock=16
05/04/2018 05:05:45;0008;Server@node2;Job;15499.node2.supernodexp.hpc;Job Modified at request of Scheduler@node2.supernodexp.hpc
05/04/2018 05:15:45;0040;Server@node2;Svr;node2.supernodexp.hpc;Scheduler sent command 3
05/04/2018 05:15:45;0040;Server@node2;Svr;node2.supernodexp.hpc;Scheduler sent command 0
05/04/2018 05:15:45;0100;Server@node2;Req;;Type 21 request received from Scheduler@node2.supernodexp.hpc, sock=16
05/04/2018 05:15:45;0100;Server@node2;Req;;Type 81 request received from Scheduler@node2.supernodexp.hpc, sock=16
05/04/2018 05:15:45;0100;Server@node2;Req;;Type 71 request received from Scheduler@node2.supernodexp.hpc, sock=16
05/04/2018 05:15:45;0100;Server@node2;Req;;Type 58 request received from Scheduler@node2.supernodexp.hpc, sock=16
05/04/2018 05:15:45;0100;Server@node2;Req;;Type 20 request received from Scheduler@node2.supernodexp.hpc, sock=16
05/04/2018 05:15:45;0100;Server@node2;Req;;Type 51 request received from Scheduler@node2.supernodexp.hpc, sock=16
05/04/2018 05:16:30;0080;Server@node2;Job;15399.node2.supernodexp.hpc;Obit received momhop:1 serverhop:1 state:4 substate:42
05/04/2018 05:16:31;0010;Server@node2;Job;15399.node2.supernodexp.hpc;Exit_status=2 resources_used.cpupercent=0 resources_used.cput=00:00:00 resources_used.mem=10048kb resources_used.ncpus=32 resources_used.vmem=170164kb resources_used.walltime=00:18:51
05/04/2018 05:16:31;0100;Server@node2;Job;15399.node2.supernodexp.hpc;dequeuing from workq, state 5
05/04/2018 05:16:31;0040;Server@node2;Svr;node2.supernodexp.hpc;Scheduler sent command 2
05/04/2018 05:16:31;0040;Server@node2;Svr;node2.supernodexp.hpc;Scheduler sent command 0
05/04/2018 05:16:31;0100;Server@node2;Req;;Type 21 request received from Scheduler@node2.supernodexp.hpc, sock=16
05/04/2018 05:16:31;0100;Server@node2;Req;;Type 81 request received from Scheduler@node2.supernodexp.hpc, sock=16
05/04/2018 05:16:31;0100;Server@node2;Req;;Type 71 request received from Scheduler@node2.supernodexp.hpc, sock=16
05/04/2018 05:16:31;0100;Server@node2;Req;;Type 58 request received from Scheduler@node2.supernodexp.hpc, sock=16
05/04/2018 05:16:31;0100;Server@node2;Req;;Type 20 request received from Scheduler@node2.supernodexp.hpc, sock=16
05/04/2018 05:16:31;0100;Server@node2;Req;;Type 51 request received from Scheduler@node2.supernodexp.hpc, sock=16
05/04/2018 05:16:31;0100;Server@node2;Req;;Type 23 request received from Scheduler@node2.supernodexp.hpc, sock=16
05/04/2018 05:16:31;0008;Server@node2;Job;15499.node2.supernodexp.hpc;Job Run at request of Scheduler@node2.supernodexp.hpc on exec_vnode (node14:ncpus=32:nmics=2:mem=31457280kb)
05/04/2018 05:16:31;0001;Server@node2;Svr;Server@node2;Success (0) in req_runjob2, return value of svr_startjob is 0
05/04/2018 05:16:31;0100;Server@node2;Req;;Type 11 request received from Scheduler@node2.supernodexp.hpc, sock=16
05/04/2018 05:16:31;0008;Server@node2;Job;15529.node2.supernodexp.hpc;Job Modified at request of Scheduler@node2.supernodexp.hpc
05/04/2018 05:17:25;0080;Server@node2;Job;15416.node2.supernodexp.hpc;Obit received momhop:1 serverhop:1 state:4 substate:42
05/04/2018 05:17:26;0010;Server@node2;Job;15416.node2.supernodexp.hpc;Exit_status=2 resources_used.cpupercent=0 resources_used.cput=00:00:00 resources_used.mem=10100kb resources_used.ncpus=32 resources_used.vmem=948280kb resources_used.walltime=00:18:55
05/04/2018 05:17:26;0100;Server@node2;Job;15416.node2.supernodexp.hpc;dequeuing from workq, state 5
05/04/2018 05:17:26;0040;Server@node2;Svr;node2.supernodexp.hpc;Scheduler sent command 2
05/04/2018 05:17:26;0040;Server@node2;Svr;node2.supernodexp.hpc;Scheduler sent command 0
05/04/2018 05:17:26;0100;Server@node2;Req;;Type 21 request received from Scheduler@node2.supernodexp.hpc, sock=16
05/04/2018 05:17:26;0100;Server@node2;Req;;Type 81 request received from Scheduler@node2.supernodexp.hpc, sock=16
05/04/2018 05:17:26;0100;Server@node2;Req;;Type 71 request received from Scheduler@node2.supernodexp.hpc, sock=16
05/04/2018 05:17:26;0100;Server@node2;Req;;Type 58 request received from Scheduler@node2.supernodexp.hpc, sock=16
05/04/2018 05:17:26;0100;Server@node2;Req;;Type 20 request received from Scheduler@node2.supernodexp.hpc, sock=16
05/04/2018 05:17:26;0100;Server@node2;Req;;Type 51 request received from Scheduler@node2.supernodexp.hpc, sock=16
05/04/2018 05:17:26;0100;Server@node2;Req;;Type 23 request received from Scheduler@node2.supernodexp.hpc, sock=16
05/04/2018 05:17:26;0008;Server@node2;Job;15529.node2.supernodexp.hpc;Job Run at request of Scheduler@node2.supernodexp.hpc on exec_vnode (node13:ncpus=32:nmics=2:mem=31457280kb)
05/04/2018 05:17:26;0001;Server@node2;Svr;Server@node2;Success (0) in req_runjob2, return value of svr_startjob is 0
05/04/2018 05:17:26;0100;Server@node2;Req;;Type 11 request received from Scheduler@node2.supernodexp.hpc, sock=16
05/04/2018 05:17:26;0008;Server@node2;Job;15540.node2.supernodexp.hpc;Job Modified at request of Scheduler@node2.supernodexp.hpc
05/04/2018 05:26:01;0080;Server@node2;Job;15473.node2.supernodexp.hpc;Obit received momhop:1 serverhop:1 state:4 substate:42
05/04/2018 05:26:01;0010;Server@node2;Job;15473.node2.supernodexp.hpc;Exit_status=2 resources_used.cpupercent=0 resources_used.cput=00:00:00 resources_used.mem=9436kb resources_used.ncpus=32 resources_used.vmem=105088kb resources_used.walltime=00:20:16
05/04/2018 05:26:01;0100;Server@node2;Job;15473.node2.supernodexp.hpc;dequeuing from workq, state 5
05/04/2018 05:26:01;0040;Server@node2;Svr;node2.supernodexp.hpc;Scheduler sent command 2
05/04/2018 05:26:01;0040;Server@node2;Svr;node2.supernodexp.hpc;Scheduler sent command 0
05/04/2018 05:26:01;0100;Server@node2;Req;;Type 21 request received from Scheduler@node2.supernodexp.hpc, sock=16
05/04/2018 05:26:01;0100;Server@node2;Req;;Type 81 request received from Scheduler@node2.supernodexp.hpc, sock=16
05/04/2018 05:26:01;0100;Server@node2;Req;;Type 71 request received from Scheduler@node2.supernodexp.hpc, sock=16
05/04/2018 05:26:01;0100;Server@node2;Req;;Type 58 request received from Scheduler@node2.supernodexp.hpc, sock=16
05/04/2018 05:26:01;0100;Server@node2;Req;;Type 20 request received from Scheduler@node2.supernodexp.hpc, sock=16
05/04/2018 05:26:01;0100;Server@node2;Req;;Type 51 request received from Scheduler@node2.supernodexp.hpc, sock=16
05/04/2018 05:26:01;0100;Server@node2;Req;;Type 23 request received from Scheduler@node2.supernodexp.hpc, sock=16
05/04/2018 05:26:01;0008;Server@node2;Job;15540.node2.supernodexp.hpc;Job Run at request of Scheduler@node2.supernodexp.hpc on exec_vnode (node3:ncpus=32:nmics=2:mem=31457280kb)
05/04/2018 05:26:01;0001;Server@node2;Svr;Server@node2;Success (0) in req_runjob2, return value of svr_startjob is 0
05/04/2018 05:26:01;0100;Server@node2;Req;;Type 11 request received from Scheduler@node2.supernodexp.hpc, sock=16
05/04/2018 05:26:01;0008;Server@node2;Job;15548.node2.supernodexp.hpc;Job Modified at request of Scheduler@node2.supernodexp.hpc
05/04/2018 05:35:19;0080;Server@node2;Job;15499.node2.supernodexp.hpc;Obit received momhop:1 serverhop:1 state:4 substate:42
05/04/2018 05:35:19;0010;Server@node2;Job;15499.node2.supernodexp.hpc;Exit_status=2 resources_used.cpupercent=0 resources_used.cput=00:00:00 resources_used.mem=10040kb resources_used.ncpus=32 resources_used.vmem=104628kb resources_used.walltime=00:18:48
05/04/2018 05:35:19;0100;Server@node2;Job;15499.node2.supernodexp.hpc;dequeuing from workq, state 5
05/04/2018 05:35:19;0040;Server@node2;Svr;node2.supernodexp.hpc;Scheduler sent command 2
05/04/2018 05:35:19;0040;Server@node2;Svr;node2.supernodexp.hpc;Scheduler sent command 0
05/04/2018 05:35:19;0100;Server@node2;Req;;Type 21 request received from Scheduler@node2.supernodexp.hpc, sock=16
05/04/2018 05:35:19;0100;Server@node2;Req;;Type 81 request received from Scheduler@node2.supernodexp.hpc, sock=16
05/04/2018 05:35:19;0100;Server@node2;Req;;Type 71 request received from Scheduler@node2.supernodexp.hpc, sock=16
05/04/2018 05:35:19;0100;Server@node2;Req;;Type 58 request received from Scheduler@node2.supernodexp.hpc, sock=16
05/04/2018 05:35:19;0100;Server@node2;Req;;Type 20 request received from Scheduler@node2.supernodexp.hpc, sock=16
05/04/2018 05:35:19;0100;Server@node2;Req;;Type 51 request received from Scheduler@node2.supernodexp.hpc, sock=16
05/04/2018 05:35:19;0100;Server@node2;Req;;Type 23 request received from Scheduler@node2.supernodexp.hpc, sock=16
05/04/2018 05:35:19;0008;Server@node2;Job;15548.node2.supernodexp.hpc;Job Run at request of Scheduler@node2.supernodexp.hpc on exec_vnode (node14:ncpus=32:nmics=2:mem=31457280kb)
05/04/2018 05:35:19;0001;Server@node2;Svr;Server@node2;Success (0) in req_runjob2, return value of svr_startjob is 0
05/04/2018 05:35:19;0100;Server@node2;Req;;Type 11 request received from Scheduler@node2.supernodexp.hpc, sock=16
05/04/2018 05:35:19;0008;Server@node2;Job;15565.node2.supernodexp.hpc;Job Modified at request of Scheduler@node2.supernodexp.hpc
05/04/2018 05:36:13;0080;Server@node2;Job;15529.node2.supernodexp.hpc;Obit received momhop:1 serverhop:1 state:4 substate:42
05/04/2018 05:36:14;0010;Server@node2;Job;15529.node2.supernodexp.hpc;Exit_status=2 resources_used.cpupercent=0 resources_used.cput=00:00:00 resources_used.mem=9976kb resources_used.ncpus=32 resources_used.vmem=104628kb resources_used.walltime=00:18:46
05/04/2018 05:36:14;0100;Server@node2;Job;15529.node2.supernodexp.hpc;dequeuing from workq, state 5
05/04/2018 05:36:14;0040;Server@node2;Svr;node2.supernodexp.hpc;Scheduler sent command 2
05/04/2018 05:36:14;0040;Server@node2;Svr;node2.supernodexp.hpc;Scheduler sent command 0
05/04/2018 05:36:14;0100;Server@node2;Req;;Type 21 request received from Scheduler@node2.supernodexp.hpc, sock=16
05/04/2018 05:36:14;0100;Server@node2;Req;;Type 81 request received from Scheduler@node2.supernodexp.hpc, sock=16
05/04/2018 05:36:14;0100;Server@node2;Req;;Type 71 request received from Scheduler@node2.supernodexp.hpc, sock=16
05/04/2018 05:36:14;0100;Server@node2;Req;;Type 58 request received from Scheduler@node2.supernodexp.hpc, sock=16
05/04/2018 05:36:14;0100;Server@node2;Req;;Type 20 request received from Scheduler@node2.supernodexp.hpc, sock=16
05/04/2018 05:36:14;0100;Server@node2;Req;;Type 51 request received from Scheduler@node2.supernodexp.hpc, sock=16
05/04/2018 05:36:14;0100;Server@node2;Req;;Type 23 request received from Scheduler@node2.supernodexp.hpc, sock=16
05/04/2018 05:36:14;0008;Server@node2;Job;15565.node2.supernodexp.hpc;Job Run at request of Scheduler@node2.supernodexp.hpc on exec_vnode (node13:ncpus=32:nmics=2:mem=31457280kb)
05/04/2018 05:36:14;0001;Server@node2;Svr;Server@node2;Success (0) in req_runjob2, return value of svr_startjob is 0
05/04/2018 05:36:14;0100;Server@node2;Req;;Type 11 request received from Scheduler@node2.supernodexp.hpc, sock=16
05/04/2018 05:36:14;0008;Server@node2;Job;15572.node2.supernodexp.hpc;Job Modified at request of Scheduler@node2.supernodexp.hpc
05/04/2018 05:46:14;0040;Server@node2;Svr;node2.supernodexp.hpc;Scheduler sent command 3
05/04/2018 05:46:14;0040;Server@node2;Svr;node2.supernodexp.hpc;Scheduler sent command 0
05/04/2018 05:46:14;0100;Server@node2;Req;;Type 21 request received from Scheduler@node2.supernodexp.hpc, sock=16
05/04/2018 05:46:14;0100;Server@node2;Req;;Type 81 request received from Scheduler@node2.supernodexp.hpc, sock=16
05/04/2018 05:46:14;0100;Server@node2;Req;;Type 71 request received from Scheduler@node2.supernodexp.hpc, sock=16
05/04/2018 05:46:14;0100;Server@node2;Req;;Type 58 request received from Scheduler@node2.supernodexp.hpc, sock=16
05/04/2018 05:46:14;0100;Server@node2;Req;;Type 20 request received from Scheduler@node2.supernodexp.hpc, sock=16
05/04/2018 05:46:14;0100;Server@node2;Req;;Type 51 request received from Scheduler@node2.supernodexp.hpc, sock=16
05/04/2018 05:46:16;0080;Server@node2;Job;15540.node2.supernodexp.hpc;Obit received momhop:1 serverhop:1 state:4 substate:42
05/04/2018 05:46:17;0010;Server@node2;Job;15540.node2.supernodexp.hpc;Exit_status=2 resources_used.cpupercent=0 resources_used.cput=00:00:00 resources_used.mem=11476kb resources_used.ncpus=32 resources_used.vmem=106752kb resources_used.walltime=00:20:15
05/04/2018 05:46:17;0100;Server@node2;Job;15540.node2.supernodexp.hpc;dequeuing from workq, state 5
05/04/2018 05:46:17;0040;Server@node2;Svr;node2.supernodexp.hpc;Scheduler sent command 2
05/04/2018 05:46:17;0040;Server@node2;Svr;node2.supernodexp.hpc;Scheduler sent command 0
05/04/2018 05:46:17;0100;Server@node2;Req;;Type 21 request received from Scheduler@node2.supernodexp.hpc, sock=16
05/04/2018 05:46:17;0100;Server@node2;Req;;Type 81 request received from Scheduler@node2.supernodexp.hpc, sock=16
05/04/2018 05:46:17;0100;Server@node2;Req;;Type 71 request received from Scheduler@node2.supernodexp.hpc, sock=16
05/04/2018 05:46:17;0100;Server@node2;Req;;Type 58 request received from Scheduler@node2.supernodexp.hpc, sock=16
05/04/2018 05:46:17;0100;Server@node2;Req;;Type 20 request received from Scheduler@node2.supernodexp.hpc, sock=16
05/04/2018 05:46:17;0100;Server@node2;Req;;Type 51 request received from Scheduler@node2.supernodexp.hpc, sock=16
05/04/2018 05:46:17;0100;Server@node2;Req;;Type 23 request received from Scheduler@node2.supernodexp.hpc, sock=16
05/04/2018 05:46:17;0008;Server@node2;Job;15572.node2.supernodexp.hpc;Job Run at request of Scheduler@node2.supernodexp.hpc on exec_vnode (node3:ncpus=32:nmics=2:mem=31457280kb)
05/04/2018 05:46:17;0001;Server@node2;Svr;Server@node2;Success (0) in req_runjob2, return value of svr_startjob is 0
05/04/2018 05:46:17;0100;Server@node2;Req;;Type 11 request received from Scheduler@node2.supernodexp.hpc, sock=16
05/04/2018 05:46:17;0008;Server@node2;Job;15574.node2.supernodexp.hpc;Job Modified at request of Scheduler@node2.supernodexp.hpc
05/04/2018 05:53:58;0080;Server@node2;Job;15548.node2.supernodexp.hpc;Obit received momhop:1 serverhop:1 state:4 substate:42
05/04/2018 05:53:58;0010;Server@node2;Job;15548.node2.supernodexp.hpc;Exit_status=2 resources_used.cpupercent=0 resources_used.cput=00:00:00 resources_used.mem=10024kb resources_used.ncpus=32 resources_used.vmem=170164kb resources_used.walltime=00:18:39
05/04/2018 05:53:58;0100;Server@node2;Job;15548.node2.supernodexp.hpc;dequeuing from workq, state 5
05/04/2018 05:53:58;0040;Server@node2;Svr;node2.supernodexp.hpc;Scheduler sent command 2
05/04/2018 05:53:58;0040;Server@node2;Svr;node2.supernodexp.hpc;Scheduler sent command 0
05/04/2018 05:53:58;0100;Server@node2;Req;;Type 21 request received from Scheduler@node2.supernodexp.hpc, sock=16
05/04/2018 05:53:58;0100;Server@node2;Req;;Type 81 request received from Scheduler@node2.supernodexp.hpc, sock=16
05/04/2018 05:53:58;0100;Server@node2;Req;;Type 71 request received from Scheduler@node2.supernodexp.hpc, sock=16
05/04/2018 05:53:58;0100;Server@node2;Req;;Type 58 request received from Scheduler@node2.supernodexp.hpc, sock=16
05/04/2018 05:53:59;0100;Server@node2;Req;;Type 20 request received from Scheduler@node2.supernodexp.hpc, sock=16
05/04/2018 05:53:59;0100;Server@node2;Req;;Type 51 request received from Scheduler@node2.supernodexp.hpc, sock=16
05/04/2018 05:53:59;0100;Server@node2;Req;;Type 23 request received from Scheduler@node2.supernodexp.hpc, sock=16
05/04/2018 05:53:59;0008;Server@node2;Job;15574.node2.supernodexp.hpc;Job Run at request of Scheduler@node2.supernodexp.hpc on exec_vnode (node14:ncpus=32:nmics=2:mem=31457280kb)
05/04/2018 05:53:59;0001;Server@node2;Svr;Server@node2;Success (0) in req_runjob2, return value of svr_startjob is 0
05/04/2018 05:53:59;0100;Server@node2;Req;;Type 11 request received from Scheduler@node2.supernodexp.hpc, sock=16
05/04/2018 05:53:59;0008;Server@node2;Job;15588.node2.supernodexp.hpc;Job Modified at request of Scheduler@node2.supernodexp.hpc
05/04/2018 05:55:16;0080;Server@node2;Job;15565.node2.supernodexp.hpc;Obit received momhop:1 serverhop:1 state:4 substate:42
05/04/2018 05:55:19;0010;Server@node2;Job;15565.node2.supernodexp.hpc;Exit_status=2 resources_used.cpupercent=0 resources_used.cput=00:00:00 resources_used.mem=9664kb resources_used.ncpus=32 resources_used.vmem=173624kb resources_used.walltime=00:19:02
05/04/2018 05:55:19;0100;Server@node2;Job;15565.node2.supernodexp.hpc;dequeuing from workq, state 5
05/04/2018 05:55:19;0040;Server@node2;Svr;node2.supernodexp.hpc;Scheduler sent command 2
05/04/2018 05:55:19;0040;Server@node2;Svr;node2.supernodexp.hpc;Scheduler sent command 0
05/04/2018 05:55:19;0100;Server@node2;Req;;Type 21 request received from Scheduler@node2.supernodexp.hpc, sock=16
05/04/2018 05:55:19;0100;Server@node2;Req;;Type 81 request received from Scheduler@node2.supernodexp.hpc, sock=16
05/04/2018 05:55:19;0100;Server@node2;Req;;Type 71 request received from Scheduler@node2.supernodexp.hpc, sock=16
05/04/2018 05:55:19;0100;Server@node2;Req;;Type 58 request received from Scheduler@node2.supernodexp.hpc, sock=16
05/04/2018 05:55:19;0100;Server@node2;Req;;Type 20 request received from Scheduler@node2.supernodexp.hpc, sock=16
05/04/2018 05:55:19;0100;Server@node2;Req;;Type 51 request received from Scheduler@node2.supernodexp.hpc, sock=16
05/04/2018 05:55:19;0100;Server@node2;Req;;Type 23 request received from Scheduler@node2.supernodexp.hpc, sock=16
05/04/2018 05:55:19;0008;Server@node2;Job;15588.node2.supernodexp.hpc;Job Run at request of Scheduler@node2.supernodexp.hpc on exec_vnode (node13:ncpus=32:nmics=2:mem=31457280kb)
05/04/2018 05:55:19;0001;Server@node2;Svr;Server@node2;Success (0) in req_runjob2, return value of svr_startjob is 0
05/04/2018 05:55:19;0100;Server@node2;Req;;Type 11 request received from Scheduler@node2.supernodexp.hpc, sock=16
05/04/2018 05:55:19;0008;Server@node2;Job;15601.node2.supernodexp.hpc;Job Modified at request of Scheduler@node2.supernodexp.hpc
05/04/2018 06:05:19;0040;Server@node2;Svr;node2.supernodexp.hpc;Scheduler sent command 3
05/04/2018 06:05:19;0040;Server@node2;Svr;node2.supernodexp.hpc;Scheduler sent command 0
05/04/2018 06:05:19;0100;Server@node2;Req;;Type 21 request received from Scheduler@node2.supernodexp.hpc, sock=16
05/04/2018 06:05:19;0100;Server@node2;Req;;Type 81 request received from Scheduler@node2.supernodexp.hpc, sock=16
05/04/2018 06:05:19;0100;Server@node2;Req;;Type 71 request received from Scheduler@node2.supernodexp.hpc, sock=16
05/04/2018 06:05:19;0100;Server@node2;Req;;Type 58 request received from Scheduler@node2.supernodexp.hpc, sock=16
05/04/2018 06:05:19;0100;Server@node2;Req;;Type 20 request received from Scheduler@node2.supernodexp.hpc, sock=16
05/04/2018 06:05:19;0100;Server@node2;Req;;Type 51 request received from Scheduler@node2.supernodexp.hpc, sock=16
05/04/2018 06:06:29;0080;Server@node2;Job;15572.node2.supernodexp.hpc;Obit received momhop:1 serverhop:1 state:4 substate:42
05/04/2018 06:06:29;0010;Server@node2;Job;15572.node2.supernodexp.hpc;Exit_status=2 resources_used.cpupercent=0 resources_used.cput=00:00:00 resources_used.mem=9456kb resources_used.ncpus=32 resources_used.vmem=106752kb resources_used.walltime=00:20:12
05/04/2018 06:06:29;0100;Server@node2;Job;15572.node2.supernodexp.hpc;dequeuing from workq, state 5
05/04/2018 06:06:29;0040;Server@node2;Svr;node2.supernodexp.hpc;Scheduler sent command 2
05/04/2018 06:06:29;0040;Server@node2;Svr;node2.supernodexp.hpc;Scheduler sent command 0
05/04/2018 06:06:29;0100;Server@node2;Req;;Type 21 request received from Scheduler@node2.supernodexp.hpc, sock=16
05/04/2018 06:06:29;0100;Server@node2;Req;;Type 81 request received from Scheduler@node2.supernodexp.hpc, sock=16
05/04/2018 06:06:29;0100;Server@node2;Req;;Type 71 request received from Scheduler@node2.supernodexp.hpc, sock=16
05/04/2018 06:06:29;0100;Server@node2;Req;;Type 58 request received from Scheduler@node2.supernodexp.hpc, sock=16
05/04/2018 06:06:29;0100;Server@node2;Req;;Type 20 request received from Scheduler@node2.supernodexp.hpc, sock=16
05/04/2018 06:06:29;0100;Server@node2;Req;;Type 51 request received from Scheduler@node2.supernodexp.hpc, sock=16
05/04/2018 06:06:30;0100;Server@node2;Req;;Type 23 request received from Scheduler@node2.supernodexp.hpc, sock=16
05/04/2018 06:06:30;0008;Server@node2;Job;15601.node2.supernodexp.hpc;Job Run at request of Scheduler@node2.supernodexp.hpc on exec_vnode (node3:ncpus=32:nmics=2:mem=31457280kb)
05/04/2018 06:06:30;0001;Server@node2;Svr;Server@node2;Success (0) in req_runjob2, return value of svr_startjob is 0
05/04/2018 06:06:30;0100;Server@node2;Req;;Type 11 request received from Scheduler@node2.supernodexp.hpc, sock=16
05/04/2018 06:06:30;0008;Server@node2;Job;15612.node2.supernodexp.hpc;Job Modified at request of Scheduler@node2.supernodexp.hpc
05/04/2018 06:12:50;0080;Server@node2;Job;15574.node2.supernodexp.hpc;Obit received momhop:1 serverhop:1 state:4 substate:42
05/04/2018 06:12:51;0010;Server@node2;Job;15574.node2.supernodexp.hpc;Exit_status=2 resources_used.cpupercent=0 resources_used.cput=00:00:00 resources_used.mem=10252kb resources_used.ncpus=32 resources_used.vmem=170164kb resources_used.walltime=00:18:51
05/04/2018 06:12:51;0100;Server@node2;Job;15574.node2.supernodexp.hpc;dequeuing from workq, state 5
05/04/2018 06:12:51;0040;Server@node2;Svr;node2.supernodexp.hpc;Scheduler sent command 2
05/04/2018 06:12:51;0040;Server@node2;Svr;node2.supernodexp.hpc;Scheduler sent command 0
05/04/2018 06:12:51;0100;Server@node2;Req;;Type 21 request received from Scheduler@node2.supernodexp.hpc, sock=16
05/04/2018 06:12:51;0100;Server@node2;Req;;Type 81 request received from Scheduler@node2.supernodexp.hpc, sock=16
05/04/2018 06:12:51;0100;Server@node2;Req;;Type 71 request received from Scheduler@node2.supernodexp.hpc, sock=16
05/04/2018 06:12:51;0100;Server@node2;Req;;Type 58 request received from Scheduler@node2.supernodexp.hpc, sock=16
05/04/2018 06:12:51;0100;Server@node2;Req;;Type 20 request received from Scheduler@node2.supernodexp.hpc, sock=16
05/04/2018 06:12:51;0100;Server@node2;Req;;Type 51 request received from Scheduler@node2.supernodexp.hpc, sock=16
05/04/2018 06:12:51;0100;Server@node2;Req;;Type 23 request received from Scheduler@node2.supernodexp.hpc, sock=16
05/04/2018 06:12:51;0008;Server@node2;Job;15612.node2.supernodexp.hpc;Job Run at request of Scheduler@node2.supernodexp.hpc on exec_vnode (node14:ncpus=32:nmics=2:mem=31457280kb)
05/04/2018 06:12:51;0001;Server@node2;Svr;Server@node2;Success (0) in req_runjob2, return value of svr_startjob is 0
05/04/2018 06:12:51;0100;Server@node2;Req;;Type 11 request received from Scheduler@node2.supernodexp.hpc, sock=16
05/04/2018 06:12:51;0008;Server@node2;Job;15626.node2.supernodexp.hpc;Job Modified at request of Scheduler@node2.supernodexp.hpc
05/04/2018 06:14:18;0080;Server@node2;Job;15588.node2.supernodexp.hpc;Obit received momhop:1 serverhop:1 state:4 substate:42
05/04/2018 06:14:19;0010;Server@node2;Job;15588.node2.supernodexp.hpc;Exit_status=2 resources_used.cpupercent=0 resources_used.cput=00:00:00 resources_used.mem=9648kb resources_used.ncpus=32 resources_used.vmem=171960kb resources_used.walltime=00:19:00
05/04/2018 06:14:19;0100;Server@node2;Job;15588.node2.supernodexp.hpc;dequeuing from workq, state 5
05/04/2018 06:14:19;0040;Server@node2;Svr;node2.supernodexp.hpc;Scheduler sent command 2
05/04/2018 06:14:19;0040;Server@node2;Svr;node2.supernodexp.hpc;Scheduler sent command 0
05/04/2018 06:14:19;0100;Server@node2;Req;;Type 21 request received from Scheduler@node2.supernodexp.hpc, sock=16
05/04/2018 06:14:19;0100;Server@node2;Req;;Type 81 request received from Scheduler@node2.supernodexp.hpc, sock=16
05/04/2018 06:14:19;0100;Server@node2;Req;;Type 71 request received from Scheduler@node2.supernodexp.hpc, sock=16
05/04/2018 06:14:19;0100;Server@node2;Req;;Type 58 request received from Scheduler@node2.supernodexp.hpc, sock=16
05/04/2018 06:14:19;0100;Server@node2;Req;;Type 20 request received from Scheduler@node2.supernodexp.hpc, sock=16
05/04/2018 06:14:19;0100;Server@node2;Req;;Type 51 request received from Scheduler@node2.supernodexp.hpc, sock=16
05/04/2018 06:14:19;0100;Server@node2;Req;;Type 23 request received from Scheduler@node2.supernodexp.hpc, sock=16
05/04/2018 06:14:19;0008;Server@node2;Job;15626.node2.supernodexp.hpc;Job Run at request of Scheduler@node2.supernodexp.hpc on exec_vnode (node13:ncpus=32:nmics=2:mem=31457280kb)
05/04/2018 06:14:19;0001;Server@node2;Svr;Server@node2;Success (0) in req_runjob2, return value of svr_startjob is 0
05/04/2018 06:14:19;0100;Server@node2;Req;;Type 11 request received from Scheduler@node2.supernodexp.hpc, sock=16
05/04/2018 06:14:19;0008;Server@node2;Job;15645.node2.supernodexp.hpc;Job Modified at request of Scheduler@node2.supernodexp.hpc
05/04/2018 06:24:19;0040;Server@node2;Svr;node2.supernodexp.hpc;Scheduler sent command 3
05/04/2018 06:24:19;0040;Server@node2;Svr;node2.supernodexp.hpc;Scheduler sent command 0
05/04/2018 06:24:19;0100;Server@node2;Req;;Type 21 request received from Scheduler@node2.supernodexp.hpc, sock=16
05/04/2018 06:24:19;0100;Server@node2;Req;;Type 81 request received from Scheduler@node2.supernodexp.hpc, sock=16
05/04/2018 06:24:19;0100;Server@node2;Req;;Type 71 request received from Scheduler@node2.supernodexp.hpc, sock=16
05/04/2018 06:24:19;0100;Server@node2;Req;;Type 58 request received from Scheduler@node2.supernodexp.hpc, sock=16
05/04/2018 06:24:19;0100;Server@node2;Req;;Type 20 request received from Scheduler@node2.supernodexp.hpc, sock=16
05/04/2018 06:24:19;0100;Server@node2;Req;;Type 51 request received from Scheduler@node2.supernodexp.hpc, sock=16
05/04/2018 06:26:38;0080;Server@node2;Job;15601.node2.supernodexp.hpc;Obit received momhop:1 serverhop:1 state:4 substate:42
05/04/2018 06:26:39;0010;Server@node2;Job;15601.node2.supernodexp.hpc;Exit_status=2 resources_used.cpupercent=0 resources_used.cput=00:00:00 resources_used.mem=9432kb resources_used.ncpus=32 resources_used.vmem=103036kb resources_used.walltime=00:20:09
05/04/2018 06:26:39;0100;Server@node2;Job;15601.node2.supernodexp.hpc;dequeuing from workq, state 5
05/04/2018 06:26:39;0040;Server@node2;Svr;node2.supernodexp.hpc;Scheduler sent command 2
05/04/2018 06:26:39;0040;Server@node2;Svr;node2.supernodexp.hpc;Scheduler sent command 0
05/04/2018 06:26:39;0100;Server@node2;Req;;Type 21 request received from Scheduler@node2.supernodexp.hpc, sock=16
05/04/2018 06:26:39;0100;Server@node2;Req;;Type 81 request received from Scheduler@node2.supernodexp.hpc, sock=16
05/04/2018 06:26:39;0100;Server@node2;Req;;Type 71 request received from Scheduler@node2.supernodexp.hpc, sock=16
05/04/2018 06:26:39;0100;Server@node2;Req;;Type 58 request received from Scheduler@node2.supernodexp.hpc, sock=16
05/04/2018 06:26:39;0100;Server@node2;Req;;Type 20 request received from Scheduler@node2.supernodexp.hpc, sock=16
05/04/2018 06:26:39;0100;Server@node2;Req;;Type 51 request received from Scheduler@node2.supernodexp.hpc, sock=16
05/04/2018 06:26:39;0100;Server@node2;Req;;Type 23 request received from Scheduler@node2.supernodexp.hpc, sock=16
05/04/2018 06:26:39;0008;Server@node2;Job;15645.node2.supernodexp.hpc;Job Run at request of Scheduler@node2.supernodexp.hpc on exec_vnode (node3:ncpus=32:nmics=2:mem=31457280kb)
05/04/2018 06:26:39;0001;Server@node2;Svr;Server@node2;Success (0) in req_runjob2, return value of svr_startjob is 0
05/04/2018 06:26:39;0100;Server@node2;Req;;Type 11 request received from Scheduler@node2.supernodexp.hpc, sock=16
05/04/2018 06:26:39;0008;Server@node2;Job;15657.node2.supernodexp.hpc;Job Modified at request of Scheduler@node2.supernodexp.hpc
05/04/2018 06:31:39;0080;Server@node2;Job;15612.node2.supernodexp.hpc;Obit received momhop:1 serverhop:1 state:4 substate:42
05/04/2018 06:31:40;0010;Server@node2;Job;15612.node2.supernodexp.hpc;Exit_status=2 resources_used.cpupercent=0 resources_used.cput=00:00:00 resources_used.mem=10008kb resources_used.ncpus=32 resources_used.vmem=102576kb resources_used.walltime=00:18:49
05/04/2018 06:31:40;0100;Server@node2;Job;15612.node2.supernodexp.hpc;dequeuing from workq, state 5
05/04/2018 06:31:40;0040;Server@node2;Svr;node2.supernodexp.hpc;Scheduler sent command 2
05/04/2018 06:31:40;0040;Server@node2;Svr;node2.supernodexp.hpc;Scheduler sent command 0
05/04/2018 06:31:40;0100;Server@node2;Req;;Type 21 request received from Scheduler@node2.supernodexp.hpc, sock=16
05/04/2018 06:31:40;0100;Server@node2;Req;;Type 81 request received from Scheduler@node2.supernodexp.hpc, sock=16
05/04/2018 06:31:40;0100;Server@node2;Req;;Type 71 request received from Scheduler@node2.supernodexp.hpc, sock=16
05/04/2018 06:31:40;0100;Server@node2;Req;;Type 58 request received from Scheduler@node2.supernodexp.hpc, sock=16
05/04/2018 06:31:40;0100;Server@node2;Req;;Type 20 request received from Scheduler@node2.supernodexp.hpc, sock=16
05/04/2018 06:31:40;0100;Server@node2;Req;;Type 51 request received from Scheduler@node2.supernodexp.hpc, sock=16
05/04/2018 06:31:40;0100;Server@node2;Req;;Type 23 request received from Scheduler@node2.supernodexp.hpc, sock=16
05/04/2018 06:31:40;0008;Server@node2;Job;15657.node2.supernodexp.hpc;Job Run at request of Scheduler@node2.supernodexp.hpc on exec_vnode (node14:ncpus=32:nmics=2:mem=31457280kb)
05/04/2018 06:31:40;0001;Server@node2;Svr;Server@node2;Success (0) in req_runjob2, return value of svr_startjob is 0
05/04/2018 06:31:40;0100;Server@node2;Req;;Type 11 request received from Scheduler@node2.supernodexp.hpc, sock=16
05/04/2018 06:31:40;0008;Server@node2;Job;15669.node2.supernodexp.hpc;Job Modified at request of Scheduler@node2.supernodexp.hpc
05/04/2018 06:33:14;0080;Server@node2;Job;15626.node2.supernodexp.hpc;Obit received momhop:1 serverhop:1 state:4 substate:42
05/04/2018 06:33:15;0010;Server@node2;Job;15626.node2.supernodexp.hpc;Exit_status=2 resources_used.cpupercent=0 resources_used.cput=00:00:00 resources_used.mem=10020kb resources_used.ncpus=32 resources_used.vmem=172216kb resources_used.walltime=00:18:55
05/04/2018 06:33:15;0100;Server@node2;Job;15626.node2.supernodexp.hpc;dequeuing from workq, state 5
05/04/2018 06:33:15;0040;Server@node2;Svr;node2.supernodexp.hpc;Scheduler sent command 2
05/04/2018 06:33:15;0040;Server@node2;Svr;node2.supernodexp.hpc;Scheduler sent command 0
05/04/2018 06:33:15;0100;Server@node2;Req;;Type 21 request received from Scheduler@node2.supernodexp.hpc, sock=16
05/04/2018 06:33:15;0100;Server@node2;Req;;Type 81 request received from Scheduler@node2.supernodexp.hpc, sock=16
05/04/2018 06:33:15;0100;Server@node2;Req;;Type 71 request received from Scheduler@node2.supernodexp.hpc, sock=16
05/04/2018 06:33:15;0100;Server@node2;Req;;Type 58 request received from Scheduler@node2.supernodexp.hpc, sock=16
05/04/2018 06:33:15;0100;Server@node2;Req;;Type 20 request received from Scheduler@node2.supernodexp.hpc, sock=16
05/04/2018 06:33:15;0100;Server@node2;Req;;Type 51 request received from Scheduler@node2.supernodexp.hpc, sock=16
05/04/2018 06:33:15;0100;Server@node2;Req;;Type 23 request received from Scheduler@node2.supernodexp.hpc, sock=16
05/04/2018 06:33:15;0008;Server@node2;Job;15669.node2.supernodexp.hpc;Job Run at request of Scheduler@node2.supernodexp.hpc on exec_vnode (node13:ncpus=32:nmics=2:mem=31457280kb)
05/04/2018 06:33:15;0001;Server@node2;Svr;Server@node2;Success (0) in req_runjob2, return value of svr_startjob is 0
05/04/2018 06:33:15;0100;Server@node2;Req;;Type 11 request received from Scheduler@node2.supernodexp.hpc, sock=16
05/04/2018 06:33:15;0008;Server@node2;Job;15672.node2.supernodexp.hpc;Job Modified at request of Scheduler@node2.supernodexp.hpc
05/04/2018 06:43:15;0040;Server@node2;Svr;node2.supernodexp.hpc;Scheduler sent command 3
05/04/2018 06:43:15;0040;Server@node2;Svr;node2.supernodexp.hpc;Scheduler sent command 0
05/04/2018 06:43:15;0100;Server@node2;Req;;Type 21 request received from Scheduler@node2.supernodexp.hpc, sock=16
05/04/2018 06:43:15;0100;Server@node2;Req;;Type 81 request received from Scheduler@node2.supernodexp.hpc, sock=16
05/04/2018 06:43:15;0100;Server@node2;Req;;Type 71 request received from Scheduler@node2.supernodexp.hpc, sock=16
05/04/2018 06:43:15;0100;Server@node2;Req;;Type 58 request received from Scheduler@node2.supernodexp.hpc, sock=16
05/04/2018 06:43:15;0100;Server@node2;Req;;Type 20 request received from Scheduler@node2.supernodexp.hpc, sock=16
05/04/2018 06:43:15;0100;Server@node2;Req;;Type 51 request received from Scheduler@node2.supernodexp.hpc, sock=16
05/04/2018 06:46:58;0080;Server@node2;Job;15645.node2.supernodexp.hpc;Obit received momhop:1 serverhop:1 state:4 substate:42
05/04/2018 06:46:59;0010;Server@node2;Job;15645.node2.supernodexp.hpc;Exit_status=2 resources_used.cpupercent=0 resources_used.cput=00:00:00 resources_used.mem=9200kb resources_used.ncpus=32 resources_used.vmem=103036kb resources_used.walltime=00:20:19
05/04/2018 06:46:59;0100;Server@node2;Job;15645.node2.supernodexp.hpc;dequeuing from workq, state 5
05/04/2018 06:46:59;0040;Server@node2;Svr;node2.supernodexp.hpc;Scheduler sent command 2
05/04/2018 06:46:59;0040;Server@node2;Svr;node2.supernodexp.hpc;Scheduler sent command 0
05/04/2018 06:46:59;0100;Server@node2;Req;;Type 21 request received from Scheduler@node2.supernodexp.hpc, sock=16
05/04/2018 06:46:59;0100;Server@node2;Req;;Type 81 request received from Scheduler@node2.supernodexp.hpc, sock=16
05/04/2018 06:46:59;0100;Server@node2;Req;;Type 71 request received from Scheduler@node2.supernodexp.hpc, sock=16
05/04/2018 06:46:59;0100;Server@node2;Req;;Type 58 request received from Scheduler@node2.supernodexp.hpc, sock=16
05/04/2018 06:46:59;0100;Server@node2;Req;;Type 20 request received from Scheduler@node2.supernodexp.hpc, sock=16
05/04/2018 06:46:59;0100;Server@node2;Req;;Type 51 request received from Scheduler@node2.supernodexp.hpc, sock=16
05/04/2018 06:46:59;0100;Server@node2;Req;;Type 23 request received from Scheduler@node2.supernodexp.hpc, sock=16
05/04/2018 06:46:59;0008;Server@node2;Job;15672.node2.supernodexp.hpc;Job Run at request of Scheduler@node2.supernodexp.hpc on exec_vnode (node3:ncpus=32:nmics=2:mem=31457280kb)
05/04/2018 06:46:59;0001;Server@node2;Svr;Server@node2;Success (0) in req_runjob2, return value of svr_startjob is 0
05/04/2018 06:46:59;0100;Server@node2;Req;;Type 11 request received from Scheduler@node2.supernodexp.hpc, sock=16
05/04/2018 06:46:59;0008;Server@node2;Job;15701.node2.supernodexp.hpc;Job Modified at request of Scheduler@node2.supernodexp.hpc
05/04/2018 06:50:40;0080;Server@node2;Job;15657.node2.supernodexp.hpc;Obit received momhop:1 serverhop:1 state:4 substate:42
05/04/2018 06:50:41;0010;Server@node2;Job;15657.node2.supernodexp.hpc;Exit_status=2 resources_used.cpupercent=0 resources_used.cput=00:00:00 resources_used.mem=10212kb resources_used.ncpus=32 resources_used.vmem=104372kb resources_used.walltime=00:19:00
05/04/2018 06:50:41;0100;Server@node2;Job;15657.node2.supernodexp.hpc;dequeuing from workq, state 5
05/04/2018 06:50:41;0040;Server@node2;Svr;node2.supernodexp.hpc;Scheduler sent command 2
05/04/2018 06:50:41;0040;Server@node2;Svr;node2.supernodexp.hpc;Scheduler sent command 0
05/04/2018 06:50:41;0100;Server@node2;Req;;Type 21 request received from Scheduler@node2.supernodexp.hpc, sock=16
05/04/2018 06:50:41;0100;Server@node2;Req;;Type 81 request received from Scheduler@node2.supernodexp.hpc, sock=16
05/04/2018 06:50:41;0100;Server@node2;Req;;Type 71 request received from Scheduler@node2.supernodexp.hpc, sock=16
05/04/2018 06:50:41;0100;Server@node2;Req;;Type 58 request received from Scheduler@node2.supernodexp.hpc, sock=16
05/04/2018 06:50:41;0100;Server@node2;Req;;Type 20 request received from Scheduler@node2.supernodexp.hpc, sock=16
05/04/2018 06:50:41;0100;Server@node2;Req;;Type 51 request received from Scheduler@node2.supernodexp.hpc, sock=16
05/04/2018 06:50:41;0100;Server@node2;Req;;Type 23 request received from Scheduler@node2.supernodexp.hpc, sock=16
05/04/2018 06:50:41;0008;Server@node2;Job;15701.node2.supernodexp.hpc;Job Run at request of Scheduler@node2.supernodexp.hpc on exec_vnode (node14:ncpus=32:nmics=2:mem=31457280kb)
05/04/2018 06:50:41;0001;Server@node2;Svr;Server@node2;Success (0) in req_runjob2, return value of svr_startjob is 0
05/04/2018 06:50:41;0100;Server@node2;Req;;Type 11 request received from Scheduler@node2.supernodexp.hpc, sock=16
05/04/2018 06:50:41;0008;Server@node2;Job;15708.node2.supernodexp.hpc;Job Modified at request of Scheduler@node2.supernodexp.hpc
05/04/2018 06:52:08;0080;Server@node2;Job;15669.node2.supernodexp.hpc;Obit received momhop:1 serverhop:1 state:4 substate:42
05/04/2018 06:52:09;0010;Server@node2;Job;15669.node2.supernodexp.hpc;Exit_status=2 resources_used.cpupercent=0 resources_used.cput=00:00:00 resources_used.mem=10240kb resources_used.ncpus=32 resources_used.vmem=104372kb resources_used.walltime=00:18:52
05/04/2018 06:52:09;0100;Server@node2;Job;15669.node2.supernodexp.hpc;dequeuing from workq, state 5
05/04/2018 06:52:09;0040;Server@node2;Svr;node2.supernodexp.hpc;Scheduler sent command 2
05/04/2018 06:52:09;0040;Server@node2;Svr;node2.supernodexp.hpc;Scheduler sent command 0
05/04/2018 06:52:09;0100;Server@node2;Req;;Type 21 request received from Scheduler@node2.supernodexp.hpc, sock=16
05/04/2018 06:52:09;0100;Server@node2;Req;;Type 81 request received from Scheduler@node2.supernodexp.hpc, sock=16
05/04/2018 06:52:09;0100;Server@node2;Req;;Type 71 request received from Scheduler@node2.supernodexp.hpc, sock=16
05/04/2018 06:52:09;0100;Server@node2;Req;;Type 58 request received from Scheduler@node2.supernodexp.hpc, sock=16
05/04/2018 06:52:09;0100;Server@node2;Req;;Type 20 request received from Scheduler@node2.supernodexp.hpc, sock=16
05/04/2018 06:52:09;0100;Server@node2;Req;;Type 51 request received from Scheduler@node2.supernodexp.hpc, sock=16
05/04/2018 06:52:09;0100;Server@node2;Req;;Type 23 request received from Scheduler@node2.supernodexp.hpc, sock=16
05/04/2018 06:52:09;0008;Server@node2;Job;15708.node2.supernodexp.hpc;Job Run at request of Scheduler@node2.supernodexp.hpc on exec_vnode (node13:ncpus=32:nmics=2:mem=31457280kb)
05/04/2018 06:52:09;0001;Server@node2;Svr;Server@node2;Success (0) in req_runjob2, return value of svr_startjob is 0
05/04/2018 06:52:09;0100;Server@node2;Req;;Type 11 request received from Scheduler@node2.supernodexp.hpc, sock=16
05/04/2018 06:52:09;0008;Server@node2;Job;15720.node2.supernodexp.hpc;Job Modified at request of Scheduler@node2.supernodexp.hpc
05/04/2018 07:02:09;0040;Server@node2;Svr;node2.supernodexp.hpc;Scheduler sent command 3
05/04/2018 07:02:09;0040;Server@node2;Svr;node2.supernodexp.hpc;Scheduler sent command 0
05/04/2018 07:02:09;0100;Server@node2;Req;;Type 21 request received from Scheduler@node2.supernodexp.hpc, sock=16
05/04/2018 07:02:09;0100;Server@node2;Req;;Type 81 request received from Scheduler@node2.supernodexp.hpc, sock=16
05/04/2018 07:02:09;0100;Server@node2;Req;;Type 71 request received from Scheduler@node2.supernodexp.hpc, sock=16
05/04/2018 07:02:09;0100;Server@node2;Req;;Type 58 request received from Scheduler@node2.supernodexp.hpc, sock=16
05/04/2018 07:02:09;0100;Server@node2;Req;;Type 20 request received from Scheduler@node2.supernodexp.hpc, sock=16
05/04/2018 07:02:09;0100;Server@node2;Req;;Type 51 request received from Scheduler@node2.supernodexp.hpc, sock=16
05/04/2018 07:07:21;0080;Server@node2;Job;15672.node2.supernodexp.hpc;Obit received momhop:1 serverhop:1 state:4 substate:42
05/04/2018 07:07:22;0010;Server@node2;Job;15672.node2.supernodexp.hpc;Exit_status=2 resources_used.cpupercent=0 resources_used.cput=00:00:00 resources_used.mem=9464kb resources_used.ncpus=32 resources_used.vmem=105344kb resources_used.walltime=00:20:22
05/04/2018 07:07:22;0100;Server@node2;Job;15672.node2.supernodexp.hpc;dequeuing from workq, state 5
05/04/2018 07:07:22;0040;Server@node2;Svr;node2.supernodexp.hpc;Scheduler sent command 2
05/04/2018 07:07:22;0040;Server@node2;Svr;node2.supernodexp.hpc;Scheduler sent command 0
05/04/2018 07:07:22;0100;Server@node2;Req;;Type 21 request received from Scheduler@node2.supernodexp.hpc, sock=16
05/04/2018 07:07:22;0100;Server@node2;Req;;Type 81 request received from Scheduler@node2.supernodexp.hpc, sock=16
05/04/2018 07:07:22;0100;Server@node2;Req;;Type 71 request received from Scheduler@node2.supernodexp.hpc, sock=16
05/04/2018 07:07:22;0100;Server@node2;Req;;Type 58 request received from Scheduler@node2.supernodexp.hpc, sock=16
05/04/2018 07:07:22;0100;Server@node2;Req;;Type 20 request received from Scheduler@node2.supernodexp.hpc, sock=16
05/04/2018 07:07:22;0100;Server@node2;Req;;Type 51 request received from Scheduler@node2.supernodexp.hpc, sock=16
05/04/2018 07:07:22;0100;Server@node2;Req;;Type 23 request received from Scheduler@node2.supernodexp.hpc, sock=16
05/04/2018 07:07:22;0008;Server@node2;Job;15720.node2.supernodexp.hpc;Job Run at request of Scheduler@node2.supernodexp.hpc on exec_vnode (node3:ncpus=32:nmics=2:mem=31457280kb)
05/04/2018 07:07:22;0001;Server@node2;Svr;Server@node2;Success (0) in req_runjob2, return value of svr_startjob is 0
05/04/2018 07:07:22;0100;Server@node2;Req;;Type 11 request received from Scheduler@node2.supernodexp.hpc, sock=16
05/04/2018 07:07:22;0008;Server@node2;Job;15728.node2.supernodexp.hpc;Job Modified at request of Scheduler@node2.supernodexp.hpc
05/04/2018 07:09:33;0080;Server@node2;Job;15701.node2.supernodexp.hpc;Obit received momhop:1 serverhop:1 state:4 substate:42
05/04/2018 07:09:34;0010;Server@node2;Job;15701.node2.supernodexp.hpc;Exit_status=2 resources_used.cpupercent=0 resources_used.cput=00:00:00 resources_used.mem=9992kb resources_used.ncpus=32 resources_used.vmem=169908kb resources_used.walltime=00:18:52
05/04/2018 07:09:34;0100;Server@node2;Job;15701.node2.supernodexp.hpc;dequeuing from workq, state 5
05/04/2018 07:09:34;0040;Server@node2;Svr;node2.supernodexp.hpc;Scheduler sent command 2
05/04/2018 07:09:34;0040;Server@node2;Svr;node2.supernodexp.hpc;Scheduler sent command 0
05/04/2018 07:09:34;0100;Server@node2;Req;;Type 21 request received from Scheduler@node2.supernodexp.hpc, sock=16
05/04/2018 07:09:34;0100;Server@node2;Req;;Type 81 request received from Scheduler@node2.supernodexp.hpc, sock=16
05/04/2018 07:09:34;0100;Server@node2;Req;;Type 71 request received from Scheduler@node2.supernodexp.hpc, sock=16
05/04/2018 07:09:34;0100;Server@node2;Req;;Type 58 request received from Scheduler@node2.supernodexp.hpc, sock=16
05/04/2018 07:09:34;0100;Server@node2;Req;;Type 20 request received from Scheduler@node2.supernodexp.hpc, sock=16
05/04/2018 07:09:34;0100;Server@node2;Req;;Type 51 request received from Scheduler@node2.supernodexp.hpc, sock=16
05/04/2018 07:09:34;0100;Server@node2;Req;;Type 23 request received from Scheduler@node2.supernodexp.hpc, sock=16
05/04/2018 07:09:34;0008;Server@node2;Job;15728.node2.supernodexp.hpc;Job Run at request of Scheduler@node2.supernodexp.hpc on exec_vnode (node14:ncpus=32:nmics=2:mem=31457280kb)
05/04/2018 07:09:34;0001;Server@node2;Svr;Server@node2;Success (0) in req_runjob2, return value of svr_startjob is 0
05/04/2018 07:09:34;0100;Server@node2;Req;;Type 11 request received from Scheduler@node2.supernodexp.hpc, sock=16
05/04/2018 07:09:34;0008;Server@node2;Job;15733.node2.supernodexp.hpc;Job Modified at request of Scheduler@node2.supernodexp.hpc
05/04/2018 07:11:04;0080;Server@node2;Job;15708.node2.supernodexp.hpc;Obit received momhop:1 serverhop:1 state:4 substate:42
05/04/2018 07:11:04;0010;Server@node2;Job;15708.node2.supernodexp.hpc;Exit_status=2 resources_used.cpupercent=0 resources_used.cput=00:00:00 resources_used.mem=10264kb resources_used.ncpus=32 resources_used.vmem=172216kb resources_used.walltime=00:18:55
05/04/2018 07:11:04;0100;Server@node2;Job;15708.node2.supernodexp.hpc;dequeuing from workq, state 5
05/04/2018 07:11:04;0040;Server@node2;Svr;node2.supernodexp.hpc;Scheduler sent command 2
05/04/2018 07:11:04;0040;Server@node2;Svr;node2.supernodexp.hpc;Scheduler sent command 0
05/04/2018 07:11:04;0100;Server@node2;Req;;Type 21 request received from Scheduler@node2.supernodexp.hpc, sock=16
05/04/2018 07:11:04;0100;Server@node2;Req;;Type 81 request received from Scheduler@node2.supernodexp.hpc, sock=16
05/04/2018 07:11:04;0100;Server@node2;Req;;Type 71 request received from Scheduler@node2.supernodexp.hpc, sock=16
05/04/2018 07:11:04;0100;Server@node2;Req;;Type 58 request received from Scheduler@node2.supernodexp.hpc, sock=16
05/04/2018 07:11:04;0100;Server@node2;Req;;Type 20 request received from Scheduler@node2.supernodexp.hpc, sock=16
05/04/2018 07:11:04;0100;Server@node2;Req;;Type 51 request received from Scheduler@node2.supernodexp.hpc, sock=16
05/04/2018 07:11:04;0100;Server@node2;Req;;Type 23 request received from Scheduler@node2.supernodexp.hpc, sock=16
05/04/2018 07:11:04;0008;Server@node2;Job;15733.node2.supernodexp.hpc;Job Run at request of Scheduler@node2.supernodexp.hpc on exec_vnode (node13:ncpus=32:nmics=2:mem=31457280kb)
05/04/2018 07:11:04;0001;Server@node2;Svr;Server@node2;Success (0) in req_runjob2, return value of svr_startjob is 0
05/04/2018 07:11:04;0100;Server@node2;Req;;Type 11 request received from Scheduler@node2.supernodexp.hpc, sock=16
05/04/2018 07:11:04;0008;Server@node2;Job;15750.node2.supernodexp.hpc;Job Modified at request of Scheduler@node2.supernodexp.hpc
05/04/2018 07:21:04;0040;Server@node2;Svr;node2.supernodexp.hpc;Scheduler sent command 3
05/04/2018 07:21:04;0040;Server@node2;Svr;node2.supernodexp.hpc;Scheduler sent command 0
05/04/2018 07:21:04;0100;Server@node2;Req;;Type 21 request received from Scheduler@node2.supernodexp.hpc, sock=16
05/04/2018 07:21:04;0100;Server@node2;Req;;Type 81 request received from Scheduler@node2.supernodexp.hpc, sock=16
05/04/2018 07:21:04;0100;Server@node2;Req;;Type 71 request received from Scheduler@node2.supernodexp.hpc, sock=16
05/04/2018 07:21:04;0100;Server@node2;Req;;Type 58 request received from Scheduler@node2.supernodexp.hpc, sock=16
05/04/2018 07:21:04;0100;Server@node2;Req;;Type 20 request received from Scheduler@node2.supernodexp.hpc, sock=16
05/04/2018 07:21:04;0100;Server@node2;Req;;Type 51 request received from Scheduler@node2.supernodexp.hpc, sock=16
05/04/2018 07:27:42;0080;Server@node2;Job;15720.node2.supernodexp.hpc;Obit received momhop:1 serverhop:1 state:4 substate:42
05/04/2018 07:27:43;0010;Server@node2;Job;15720.node2.supernodexp.hpc;Exit_status=2 resources_used.cpupercent=0 resources_used.cput=00:00:00 resources_used.mem=9456kb resources_used.ncpus=32 resources_used.vmem=170880kb resources_used.walltime=00:20:20
05/04/2018 07:27:43;0100;Server@node2;Job;15720.node2.supernodexp.hpc;dequeuing from workq, state 5
05/04/2018 07:27:43;0040;Server@node2;Svr;node2.supernodexp.hpc;Scheduler sent command 2
05/04/2018 07:27:43;0040;Server@node2;Svr;node2.supernodexp.hpc;Scheduler sent command 0
05/04/2018 07:27:43;0100;Server@node2;Req;;Type 21 request received from Scheduler@node2.supernodexp.hpc, sock=16
05/04/2018 07:27:43;0100;Server@node2;Req;;Type 81 request received from Scheduler@node2.supernodexp.hpc, sock=16
05/04/2018 07:27:43;0100;Server@node2;Req;;Type 71 request received from Scheduler@node2.supernodexp.hpc, sock=16
05/04/2018 07:27:43;0100;Server@node2;Req;;Type 58 request received from Scheduler@node2.supernodexp.hpc, sock=16
05/04/2018 07:27:43;0100;Server@node2;Req;;Type 20 request received from Scheduler@node2.supernodexp.hpc, sock=16
05/04/2018 07:27:43;0100;Server@node2;Req;;Type 51 request received from Scheduler@node2.supernodexp.hpc, sock=16
05/04/2018 07:27:43;0100;Server@node2;Req;;Type 23 request received from Scheduler@node2.supernodexp.hpc, sock=16
05/04/2018 07:27:43;0008;Server@node2;Job;15750.node2.supernodexp.hpc;Job Run at request of Scheduler@node2.supernodexp.hpc on exec_vnode (node3:ncpus=32:nmics=2:mem=31457280kb)
05/04/2018 07:27:43;0001;Server@node2;Svr;Server@node2;Success (0) in req_runjob2, return value of svr_startjob is 0
05/04/2018 07:27:43;0100;Server@node2;Req;;Type 11 request received from Scheduler@node2.supernodexp.hpc, sock=16
05/04/2018 07:27:43;0008;Server@node2;Job;15757.node2.supernodexp.hpc;Job Modified at request of Scheduler@node2.supernodexp.hpc
05/04/2018 07:28:34;0080;Server@node2;Job;15728.node2.supernodexp.hpc;Obit received momhop:1 serverhop:1 state:4 substate:42
05/04/2018 07:28:35;0010;Server@node2;Job;15728.node2.supernodexp.hpc;Exit_status=2 resources_used.cpupercent=0 resources_used.cput=00:00:00 resources_used.mem=10248kb resources_used.ncpus=32 resources_used.vmem=170164kb resources_used.walltime=00:19:00
05/04/2018 07:28:35;0100;Server@node2;Job;15728.node2.supernodexp.hpc;dequeuing from workq, state 5
05/04/2018 07:28:35;0040;Server@node2;Svr;node2.supernodexp.hpc;Scheduler sent command 2
05/04/2018 07:28:35;0040;Server@node2;Svr;node2.supernodexp.hpc;Scheduler sent command 0
05/04/2018 07:28:35;0100;Server@node2;Req;;Type 21 request received from Scheduler@node2.supernodexp.hpc, sock=16
05/04/2018 07:28:35;0100;Server@node2;Req;;Type 81 request received from Scheduler@node2.supernodexp.hpc, sock=16
05/04/2018 07:28:35;0100;Server@node2;Req;;Type 71 request received from Scheduler@node2.supernodexp.hpc, sock=16
05/04/2018 07:28:35;0100;Server@node2;Req;;Type 58 request received from Scheduler@node2.supernodexp.hpc, sock=16
05/04/2018 07:28:35;0100;Server@node2;Req;;Type 20 request received from Scheduler@node2.supernodexp.hpc, sock=16
05/04/2018 07:28:35;0100;Server@node2;Req;;Type 51 request received from Scheduler@node2.supernodexp.hpc, sock=16
05/04/2018 07:28:35;0100;Server@node2;Req;;Type 23 request received from Scheduler@node2.supernodexp.hpc, sock=16
05/04/2018 07:28:35;0008;Server@node2;Job;15757.node2.supernodexp.hpc;Job Run at request of Scheduler@node2.supernodexp.hpc on exec_vnode (node14:ncpus=32:nmics=2:mem=31457280kb)
05/04/2018 07:28:35;0001;Server@node2;Svr;Server@node2;Success (0) in req_runjob2, return value of svr_startjob is 0
05/04/2018 07:28:35;0100;Server@node2;Req;;Type 11 request received from Scheduler@node2.supernodexp.hpc, sock=16
05/04/2018 07:28:35;0008;Server@node2;Job;15857.node2.supernodexp.hpc;Job Modified at request of Scheduler@node2.supernodexp.hpc
05/04/2018 07:29:49;0080;Server@node2;Job;15733.node2.supernodexp.hpc;Obit received momhop:1 serverhop:1 state:4 substate:42
05/04/2018 07:29:50;0010;Server@node2;Job;15733.node2.supernodexp.hpc;Exit_status=2 resources_used.cpupercent=0 resources_used.cput=00:00:00 resources_used.mem=9664kb resources_used.ncpus=32 resources_used.vmem=1143480kb resources_used.walltime=00:18:45
05/04/2018 07:29:50;0100;Server@node2;Job;15733.node2.supernodexp.hpc;dequeuing from workq, state 5
05/04/2018 07:29:50;0040;Server@node2;Svr;node2.supernodexp.hpc;Scheduler sent command 2
05/04/2018 07:29:50;0040;Server@node2;Svr;node2.supernodexp.hpc;Scheduler sent command 0
05/04/2018 07:29:50;0100;Server@node2;Req;;Type 21 request received from Scheduler@node2.supernodexp.hpc, sock=16
05/04/2018 07:29:50;0100;Server@node2;Req;;Type 81 request received from Scheduler@node2.supernodexp.hpc, sock=16
05/04/2018 07:29:50;0100;Server@node2;Req;;Type 71 request received from Scheduler@node2.supernodexp.hpc, sock=16
05/04/2018 07:29:50;0100;Server@node2;Req;;Type 58 request received from Scheduler@node2.supernodexp.hpc, sock=16
05/04/2018 07:29:50;0100;Server@node2;Req;;Type 20 request received from Scheduler@node2.supernodexp.hpc, sock=16
05/04/2018 07:29:50;0100;Server@node2;Req;;Type 51 request received from Scheduler@node2.supernodexp.hpc, sock=16
05/04/2018 07:29:50;0100;Server@node2;Req;;Type 23 request received from Scheduler@node2.supernodexp.hpc, sock=16
05/04/2018 07:29:50;0008;Server@node2;Job;15857.node2.supernodexp.hpc;Job Run at request of Scheduler@node2.supernodexp.hpc on exec_vnode (node13:ncpus=32:nmics=2:mem=31457280kb)
05/04/2018 07:29:50;0001;Server@node2;Svr;Server@node2;Success (0) in req_runjob2, return value of svr_startjob is 0
05/04/2018 07:29:50;0100;Server@node2;Req;;Type 11 request received from Scheduler@node2.supernodexp.hpc, sock=16
05/04/2018 07:29:50;0008;Server@node2;Job;15872.node2.supernodexp.hpc;Job Modified at request of Scheduler@node2.supernodexp.hpc
05/04/2018 07:39:50;0040;Server@node2;Svr;node2.supernodexp.hpc;Scheduler sent command 3
05/04/2018 07:39:50;0040;Server@node2;Svr;node2.supernodexp.hpc;Scheduler sent command 0
05/04/2018 07:39:50;0100;Server@node2;Req;;Type 21 request received from Scheduler@node2.supernodexp.hpc, sock=16
05/04/2018 07:39:50;0100;Server@node2;Req;;Type 81 request received from Scheduler@node2.supernodexp.hpc, sock=16
05/04/2018 07:39:50;0100;Server@node2;Req;;Type 71 request received from Scheduler@node2.supernodexp.hpc, sock=16
05/04/2018 07:39:50;0100;Server@node2;Req;;Type 58 request received from Scheduler@node2.supernodexp.hpc, sock=16
05/04/2018 07:39:50;0100;Server@node2;Req;;Type 20 request received from Scheduler@node2.supernodexp.hpc, sock=16
05/04/2018 07:39:50;0100;Server@node2;Req;;Type 51 request received from Scheduler@node2.supernodexp.hpc, sock=16
05/04/2018 07:47:23;0080;Server@node2;Job;15757.node2.supernodexp.hpc;Obit received momhop:1 serverhop:1 state:4 substate:42
05/04/2018 07:47:24;0010;Server@node2;Job;15757.node2.supernodexp.hpc;Exit_status=2 resources_used.cpupercent=0 resources_used.cput=00:00:00 resources_used.mem=10248kb resources_used.ncpus=32 resources_used.vmem=104372kb resources_used.walltime=00:18:48
05/04/2018 07:47:24;0100;Server@node2;Job;15757.node2.supernodexp.hpc;dequeuing from workq, state 5
05/04/2018 07:47:24;0040;Server@node2;Svr;node2.supernodexp.hpc;Scheduler sent command 2
05/04/2018 07:47:24;0040;Server@node2;Svr;node2.supernodexp.hpc;Scheduler sent command 0
05/04/2018 07:47:24;0100;Server@node2;Req;;Type 21 request received from Scheduler@node2.supernodexp.hpc, sock=16
05/04/2018 07:47:24;0100;Server@node2;Req;;Type 81 request received from Scheduler@node2.supernodexp.hpc, sock=16
05/04/2018 07:47:24;0100;Server@node2;Req;;Type 71 request received from Scheduler@node2.supernodexp.hpc, sock=16
05/04/2018 07:47:24;0100;Server@node2;Req;;Type 58 request received from Scheduler@node2.supernodexp.hpc, sock=16
05/04/2018 07:47:24;0100;Server@node2;Req;;Type 20 request received from Scheduler@node2.supernodexp.hpc, sock=16
05/04/2018 07:47:24;0100;Server@node2;Req;;Type 51 request received from Scheduler@node2.supernodexp.hpc, sock=16
05/04/2018 07:47:24;0100;Server@node2;Req;;Type 23 request received from Scheduler@node2.supernodexp.hpc, sock=16
05/04/2018 07:47:24;0008;Server@node2;Job;15872.node2.supernodexp.hpc;Job Run at request of Scheduler@node2.supernodexp.hpc on exec_vnode (node14:ncpus=32:nmics=2:mem=31457280kb)
05/04/2018 07:47:24;0001;Server@node2;Svr;Server@node2;Success (0) in req_runjob2, return value of svr_startjob is 0
05/04/2018 07:47:24;0100;Server@node2;Req;;Type 11 request received from Scheduler@node2.supernodexp.hpc, sock=16
05/04/2018 07:47:24;0008;Server@node2;Job;15904.node2.supernodexp.hpc;Job Modified at request of Scheduler@node2.supernodexp.hpc
05/04/2018 07:48:00;0080;Server@node2;Job;15750.node2.supernodexp.hpc;Obit received momhop:1 serverhop:1 state:4 substate:42
05/04/2018 07:48:01;0010;Server@node2;Job;15750.node2.supernodexp.hpc;Exit_status=2 resources_used.cpupercent=0 resources_used.cput=00:00:00 resources_used.mem=9432kb resources_used.ncpus=32 resources_used.vmem=170624kb resources_used.walltime=00:20:17
05/04/2018 07:48:01;0100;Server@node2;Job;15750.node2.supernodexp.hpc;dequeuing from workq, state 5
05/04/2018 07:48:01;0040;Server@node2;Svr;node2.supernodexp.hpc;Scheduler sent command 2
05/04/2018 07:48:01;0040;Server@node2;Svr;node2.supernodexp.hpc;Scheduler sent command 0
05/04/2018 07:48:01;0100;Server@node2;Req;;Type 21 request received from Scheduler@node2.supernodexp.hpc, sock=16
05/04/2018 07:48:01;0100;Server@node2;Req;;Type 81 request received from Scheduler@node2.supernodexp.hpc, sock=16
05/04/2018 07:48:01;0100;Server@node2;Req;;Type 71 request received from Scheduler@node2.supernodexp.hpc, sock=16
05/04/2018 07:48:01;0100;Server@node2;Req;;Type 58 request received from Scheduler@node2.supernodexp.hpc, sock=16
05/04/2018 07:48:01;0100;Server@node2;Req;;Type 20 request received from Scheduler@node2.supernodexp.hpc, sock=16
05/04/2018 07:48:01;0100;Server@node2;Req;;Type 51 request received from Scheduler@node2.supernodexp.hpc, sock=16
05/04/2018 07:48:01;0100;Server@node2;Req;;Type 23 request received from Scheduler@node2.supernodexp.hpc, sock=16
05/04/2018 07:48:01;0008;Server@node2;Job;15904.node2.supernodexp.hpc;Job Run at request of Scheduler@node2.supernodexp.hpc on exec_vnode (node3:ncpus=32:nmics=2:mem=31457280kb)
05/04/2018 07:48:01;0001;Server@node2;Svr;Server@node2;Success (0) in req_runjob2, return value of svr_startjob is 0
05/04/2018 07:48:01;0100;Server@node2;Req;;Type 11 request received from Scheduler@node2.supernodexp.hpc, sock=16
05/04/2018 07:48:01;0008;Server@node2;Job;15906.node2.supernodexp.hpc;Job Modified at request of Scheduler@node2.supernodexp.hpc
05/04/2018 07:48:46;0080;Server@node2;Job;15857.node2.supernodexp.hpc;Obit received momhop:1 serverhop:1 state:4 substate:42
05/04/2018 07:48:47;0010;Server@node2;Job;15857.node2.supernodexp.hpc;Exit_status=2 resources_used.cpupercent=0 resources_used.cput=00:00:00 resources_used.mem=9392kb resources_used.ncpus=32 resources_used.vmem=172216kb resources_used.walltime=00:18:56
05/04/2018 07:48:47;0100;Server@node2;Job;15857.node2.supernodexp.hpc;dequeuing from workq, state 5
05/04/2018 07:48:47;0040;Server@node2;Svr;node2.supernodexp.hpc;Scheduler sent command 2
05/04/2018 07:48:47;0040;Server@node2;Svr;node2.supernodexp.hpc;Scheduler sent command 0
05/04/2018 07:48:47;0100;Server@node2;Req;;Type 21 request received from Scheduler@node2.supernodexp.hpc, sock=16
05/04/2018 07:48:47;0100;Server@node2;Req;;Type 81 request received from Scheduler@node2.supernodexp.hpc, sock=16
05/04/2018 07:48:47;0100;Server@node2;Req;;Type 71 request received from Scheduler@node2.supernodexp.hpc, sock=16
05/04/2018 07:48:47;0100;Server@node2;Req;;Type 58 request received from Scheduler@node2.supernodexp.hpc, sock=16
05/04/2018 07:48:47;0100;Server@node2;Req;;Type 20 request received from Scheduler@node2.supernodexp.hpc, sock=16
05/04/2018 07:48:47;0100;Server@node2;Req;;Type 51 request received from Scheduler@node2.supernodexp.hpc, sock=16
05/04/2018 07:48:47;0100;Server@node2;Req;;Type 23 request received from Scheduler@node2.supernodexp.hpc, sock=16
05/04/2018 07:48:47;0008;Server@node2;Job;15906.node2.supernodexp.hpc;Job Run at request of Scheduler@node2.supernodexp.hpc on exec_vnode (node13:ncpus=32:nmics=2:mem=31457280kb)
05/04/2018 07:48:47;0001;Server@node2;Svr;Server@node2;Success (0) in req_runjob2, return value of svr_startjob is 0
05/04/2018 07:48:47;0100;Server@node2;Req;;Type 11 request received from Scheduler@node2.supernodexp.hpc, sock=16
05/04/2018 07:48:47;0008;Server@node2;Job;15952.node2.supernodexp.hpc;Job Modified at request of Scheduler@node2.supernodexp.hpc
05/04/2018 07:58:47;0040;Server@node2;Svr;node2.supernodexp.hpc;Scheduler sent command 3
05/04/2018 07:58:47;0040;Server@node2;Svr;node2.supernodexp.hpc;Scheduler sent command 0
05/04/2018 07:58:47;0100;Server@node2;Req;;Type 21 request received from Scheduler@node2.supernodexp.hpc, sock=16
05/04/2018 07:58:47;0100;Server@node2;Req;;Type 81 request received from Scheduler@node2.supernodexp.hpc, sock=16
05/04/2018 07:58:47;0100;Server@node2;Req;;Type 71 request received from Scheduler@node2.supernodexp.hpc, sock=16
05/04/2018 07:58:47;0100;Server@node2;Req;;Type 58 request received from Scheduler@node2.supernodexp.hpc, sock=16
05/04/2018 07:58:47;0100;Server@node2;Req;;Type 20 request received from Scheduler@node2.supernodexp.hpc, sock=16
05/04/2018 07:58:47;0100;Server@node2;Req;;Type 51 request received from Scheduler@node2.supernodexp.hpc, sock=16
05/04/2018 08:06:16;0080;Server@node2;Job;15872.node2.supernodexp.hpc;Obit received momhop:1 serverhop:1 state:4 substate:42
05/04/2018 08:06:17;0010;Server@node2;Job;15872.node2.supernodexp.hpc;Exit_status=2 resources_used.cpupercent=0 resources_used.cput=00:00:00 resources_used.mem=10244kb resources_used.ncpus=32 resources_used.vmem=104372kb resources_used.walltime=00:18:52
05/04/2018 08:06:17;0100;Server@node2;Job;15872.node2.supernodexp.hpc;dequeuing from workq, state 5
05/04/2018 08:06:17;0040;Server@node2;Svr;node2.supernodexp.hpc;Scheduler sent command 2
05/04/2018 08:06:17;0040;Server@node2;Svr;node2.supernodexp.hpc;Scheduler sent command 0
05/04/2018 08:06:17;0100;Server@node2;Req;;Type 21 request received from Scheduler@node2.supernodexp.hpc, sock=16
05/04/2018 08:06:17;0100;Server@node2;Req;;Type 81 request received from Scheduler@node2.supernodexp.hpc, sock=16
05/04/2018 08:06:17;0100;Server@node2;Req;;Type 71 request received from Scheduler@node2.supernodexp.hpc, sock=16
05/04/2018 08:06:17;0100;Server@node2;Req;;Type 58 request received from Scheduler@node2.supernodexp.hpc, sock=16
05/04/2018 08:06:17;0100;Server@node2;Req;;Type 20 request received from Scheduler@node2.supernodexp.hpc, sock=16
05/04/2018 08:06:17;0100;Server@node2;Req;;Type 51 request received from Scheduler@node2.supernodexp.hpc, sock=16
05/04/2018 08:06:17;0100;Server@node2;Req;;Type 23 request received from Scheduler@node2.supernodexp.hpc, sock=16
05/04/2018 08:06:17;0008;Server@node2;Job;15952.node2.supernodexp.hpc;Job Run at request of Scheduler@node2.supernodexp.hpc on exec_vnode (node14:ncpus=32:nmics=2:mem=31457280kb)
05/04/2018 08:06:17;0001;Server@node2;Svr;Server@node2;Success (0) in req_runjob2, return value of svr_startjob is 0
05/04/2018 08:06:17;0100;Server@node2;Req;;Type 11 request received from Scheduler@node2.supernodexp.hpc, sock=16
05/04/2018 08:06:17;0008;Server@node2;Job;15960.node2.supernodexp.hpc;Job Modified at request of Scheduler@node2.supernodexp.hpc
05/04/2018 08:07:37;0080;Server@node2;Job;15906.node2.supernodexp.hpc;Obit received momhop:1 serverhop:1 state:4 substate:42
05/04/2018 08:07:38;0010;Server@node2;Job;15906.node2.supernodexp.hpc;Exit_status=2 resources_used.cpupercent=0 resources_used.cput=00:00:00 resources_used.mem=10020kb resources_used.ncpus=32 resources_used.vmem=172216kb resources_used.walltime=00:18:49
05/04/2018 08:07:38;0100;Server@node2;Job;15906.node2.supernodexp.hpc;dequeuing from workq, state 5
05/04/2018 08:07:38;0040;Server@node2;Svr;node2.supernodexp.hpc;Scheduler sent command 2
05/04/2018 08:07:38;0040;Server@node2;Svr;node2.supernodexp.hpc;Scheduler sent command 0
05/04/2018 08:07:38;0100;Server@node2;Req;;Type 21 request received from Scheduler@node2.supernodexp.hpc, sock=16
05/04/2018 08:07:38;0100;Server@node2;Req;;Type 81 request received from Scheduler@node2.supernodexp.hpc, sock=16
05/04/2018 08:07:38;0100;Server@node2;Req;;Type 71 request received from Scheduler@node2.supernodexp.hpc, sock=16
05/04/2018 08:07:38;0100;Server@node2;Req;;Type 58 request received from Scheduler@node2.supernodexp.hpc, sock=16
05/04/2018 08:07:38;0100;Server@node2;Req;;Type 20 request received from Scheduler@node2.supernodexp.hpc, sock=16
05/04/2018 08:07:38;0100;Server@node2;Req;;Type 51 request received from Scheduler@node2.supernodexp.hpc, sock=16
05/04/2018 08:07:38;0100;Server@node2;Req;;Type 23 request received from Scheduler@node2.supernodexp.hpc, sock=16
05/04/2018 08:07:38;0008;Server@node2;Job;15960.node2.supernodexp.hpc;Job Run at request of Scheduler@node2.supernodexp.hpc on exec_vnode (node13:ncpus=32:nmics=2:mem=31457280kb)
05/04/2018 08:07:38;0001;Server@node2;Svr;Server@node2;Success (0) in req_runjob2, return value of svr_startjob is 0
05/04/2018 08:07:38;0100;Server@node2;Req;;Type 11 request received from Scheduler@node2.supernodexp.hpc, sock=16
05/04/2018 08:07:38;0008;Server@node2;Job;15965.node2.supernodexp.hpc;Job Modified at request of Scheduler@node2.supernodexp.hpc
05/04/2018 08:08:15;0080;Server@node2;Job;15904.node2.supernodexp.hpc;Obit received momhop:1 serverhop:1 state:4 substate:42
05/04/2018 08:08:15;0010;Server@node2;Job;15904.node2.supernodexp.hpc;Exit_status=2 resources_used.cpupercent=0 resources_used.cput=00:00:00 resources_used.mem=9452kb resources_used.ncpus=32 resources_used.vmem=103292kb resources_used.walltime=00:20:14
05/04/2018 08:08:15;0100;Server@node2;Job;15904.node2.supernodexp.hpc;dequeuing from workq, state 5
05/04/2018 08:08:15;0040;Server@node2;Svr;node2.supernodexp.hpc;Scheduler sent command 2
05/04/2018 08:08:15;0040;Server@node2;Svr;node2.supernodexp.hpc;Scheduler sent command 0
05/04/2018 08:08:15;0100;Server@node2;Req;;Type 21 request received from Scheduler@node2.supernodexp.hpc, sock=16
05/04/2018 08:08:15;0100;Server@node2;Req;;Type 81 request received from Scheduler@node2.supernodexp.hpc, sock=16
05/04/2018 08:08:15;0100;Server@node2;Req;;Type 71 request received from Scheduler@node2.supernodexp.hpc, sock=16
05/04/2018 08:08:15;0100;Server@node2;Req;;Type 58 request received from Scheduler@node2.supernodexp.hpc, sock=16
05/04/2018 08:08:16;0100;Server@node2;Req;;Type 20 request received from Scheduler@node2.supernodexp.hpc, sock=16
05/04/2018 08:08:16;0100;Server@node2;Req;;Type 51 request received from Scheduler@node2.supernodexp.hpc, sock=16
05/04/2018 08:08:16;0100;Server@node2;Req;;Type 23 request received from Scheduler@node2.supernodexp.hpc, sock=16
05/04/2018 08:08:16;0008;Server@node2;Job;15965.node2.supernodexp.hpc;Job Run at request of Scheduler@node2.supernodexp.hpc on exec_vnode (node3:ncpus=32:nmics=2:mem=31457280kb)
05/04/2018 08:08:16;0001;Server@node2;Svr;Server@node2;Success (0) in req_runjob2, return value of svr_startjob is 0
05/04/2018 08:08:16;0100;Server@node2;Req;;Type 11 request received from Scheduler@node2.supernodexp.hpc, sock=16
05/04/2018 08:08:16;0008;Server@node2;Job;15979.node2.supernodexp.hpc;Job Modified at request of Scheduler@node2.supernodexp.hpc
05/04/2018 08:18:15;0040;Server@node2;Svr;node2.supernodexp.hpc;Scheduler sent command 3
05/04/2018 08:18:15;0040;Server@node2;Svr;node2.supernodexp.hpc;Scheduler sent command 0
05/04/2018 08:18:15;0100;Server@node2;Req;;Type 21 request received from Scheduler@node2.supernodexp.hpc, sock=16
05/04/2018 08:18:15;0100;Server@node2;Req;;Type 81 request received from Scheduler@node2.supernodexp.hpc, sock=16
05/04/2018 08:18:15;0100;Server@node2;Req;;Type 71 request received from Scheduler@node2.supernodexp.hpc, sock=16
05/04/2018 08:18:15;0100;Server@node2;Req;;Type 58 request received from Scheduler@node2.supernodexp.hpc, sock=16
05/04/2018 08:18:15;0100;Server@node2;Req;;Type 20 request received from Scheduler@node2.supernodexp.hpc, sock=16
05/04/2018 08:18:15;0100;Server@node2;Req;;Type 51 request received from Scheduler@node2.supernodexp.hpc, sock=16
05/04/2018 08:25:18;0080;Server@node2;Job;15952.node2.supernodexp.hpc;Obit received momhop:1 serverhop:1 state:4 substate:42
05/04/2018 08:25:19;0010;Server@node2;Job;15952.node2.supernodexp.hpc;Exit_status=2 resources_used.cpupercent=0 resources_used.cput=00:00:00 resources_used.mem=10232kb resources_used.ncpus=32 resources_used.vmem=104628kb resources_used.walltime=00:19:01
05/04/2018 08:25:19;0100;Server@node2;Job;15952.node2.supernodexp.hpc;dequeuing from workq, state 5
05/04/2018 08:25:19;0040;Server@node2;Svr;node2.supernodexp.hpc;Scheduler sent command 2
05/04/2018 08:25:19;0040;Server@node2;Svr;node2.supernodexp.hpc;Scheduler sent command 0
05/04/2018 08:25:19;0100;Server@node2;Req;;Type 21 request received from Scheduler@node2.supernodexp.hpc, sock=16
05/04/2018 08:25:19;0100;Server@node2;Req;;Type 81 request received from Scheduler@node2.supernodexp.hpc, sock=16
05/04/2018 08:25:19;0100;Server@node2;Req;;Type 71 request received from Scheduler@node2.supernodexp.hpc, sock=16
05/04/2018 08:25:19;0100;Server@node2;Req;;Type 58 request received from Scheduler@node2.supernodexp.hpc, sock=16
05/04/2018 08:25:19;0100;Server@node2;Req;;Type 20 request received from Scheduler@node2.supernodexp.hpc, sock=16
05/04/2018 08:25:19;0100;Server@node2;Req;;Type 51 request received from Scheduler@node2.supernodexp.hpc, sock=16
05/04/2018 08:25:19;0100;Server@node2;Req;;Type 23 request received from Scheduler@node2.supernodexp.hpc, sock=16
05/04/2018 08:25:19;0008;Server@node2;Job;15979.node2.supernodexp.hpc;Job Run at request of Scheduler@node2.supernodexp.hpc on exec_vnode (node14:ncpus=32:nmics=2:mem=31457280kb)
05/04/2018 08:25:19;0001;Server@node2;Svr;Server@node2;Success (0) in req_runjob2, return value of svr_startjob is 0
05/04/2018 08:25:19;0100;Server@node2;Req;;Type 11 request received from Scheduler@node2.supernodexp.hpc, sock=16
05/04/2018 08:25:19;0008;Server@node2;Job;15981.node2.supernodexp.hpc;Job Modified at request of Scheduler@node2.supernodexp.hpc
05/04/2018 08:26:15;0080;Server@node2;Job;15960.node2.supernodexp.hpc;Obit received momhop:1 serverhop:1 state:4 substate:42
05/04/2018 08:26:16;0010;Server@node2;Job;15960.node2.supernodexp.hpc;Exit_status=2 resources_used.cpupercent=0 resources_used.cput=00:00:00 resources_used.mem=9880kb resources_used.ncpus=32 resources_used.vmem=749364kb resources_used.walltime=00:18:37
05/04/2018 08:26:16;0100;Server@node2;Job;15960.node2.supernodexp.hpc;dequeuing from workq, state 5
05/04/2018 08:26:16;0040;Server@node2;Svr;node2.supernodexp.hpc;Scheduler sent command 2
05/04/2018 08:26:16;0040;Server@node2;Svr;node2.supernodexp.hpc;Scheduler sent command 0
05/04/2018 08:26:16;0100;Server@node2;Req;;Type 21 request received from Scheduler@node2.supernodexp.hpc, sock=16
05/04/2018 08:26:16;0100;Server@node2;Req;;Type 81 request received from Scheduler@node2.supernodexp.hpc, sock=16
05/04/2018 08:26:16;0100;Server@node2;Req;;Type 71 request received from Scheduler@node2.supernodexp.hpc, sock=16
05/04/2018 08:26:16;0100;Server@node2;Req;;Type 58 request received from Scheduler@node2.supernodexp.hpc, sock=16
05/04/2018 08:26:16;0100;Server@node2;Req;;Type 20 request received from Scheduler@node2.supernodexp.hpc, sock=16
05/04/2018 08:26:16;0100;Server@node2;Req;;Type 51 request received from Scheduler@node2.supernodexp.hpc, sock=16
05/04/2018 08:26:16;0100;Server@node2;Req;;Type 23 request received from Scheduler@node2.supernodexp.hpc, sock=16
05/04/2018 08:26:16;0008;Server@node2;Job;15981.node2.supernodexp.hpc;Job Run at request of Scheduler@node2.supernodexp.hpc on exec_vnode (node13:ncpus=32:nmics=2:mem=31457280kb)
05/04/2018 08:26:16;0001;Server@node2;Svr;Server@node2;Success (0) in req_runjob2, return value of svr_startjob is 0
05/04/2018 08:26:16;0100;Server@node2;Req;;Type 11 request received from Scheduler@node2.supernodexp.hpc, sock=16
05/04/2018 08:26:16;0008;Server@node2;Job;15986.node2.supernodexp.hpc;Job Modified at request of Scheduler@node2.supernodexp.hpc
05/04/2018 08:28:31;0080;Server@node2;Job;15965.node2.supernodexp.hpc;Obit received momhop:1 serverhop:1 state:4 substate:42
05/04/2018 08:28:32;0010;Server@node2;Job;15965.node2.supernodexp.hpc;Exit_status=2 resources_used.cpupercent=0 resources_used.cput=00:00:00 resources_used.mem=9444kb resources_used.ncpus=32 resources_used.vmem=103292kb resources_used.walltime=00:20:15
05/04/2018 08:28:32;0100;Server@node2;Job;15965.node2.supernodexp.hpc;dequeuing from workq, state 5
05/04/2018 08:28:32;0040;Server@node2;Svr;node2.supernodexp.hpc;Scheduler sent command 2
05/04/2018 08:28:32;0040;Server@node2;Svr;node2.supernodexp.hpc;Scheduler sent command 0
05/04/2018 08:28:32;0100;Server@node2;Req;;Type 21 request received from Scheduler@node2.supernodexp.hpc, sock=16
05/04/2018 08:28:32;0100;Server@node2;Req;;Type 81 request received from Scheduler@node2.supernodexp.hpc, sock=16
05/04/2018 08:28:32;0100;Server@node2;Req;;Type 71 request received from Scheduler@node2.supernodexp.hpc, sock=16
05/04/2018 08:28:32;0100;Server@node2;Req;;Type 58 request received from Scheduler@node2.supernodexp.hpc, sock=16
05/04/2018 08:28:32;0100;Server@node2;Req;;Type 20 request received from Scheduler@node2.supernodexp.hpc, sock=16
05/04/2018 08:28:32;0100;Server@node2;Req;;Type 51 request received from Scheduler@node2.supernodexp.hpc, sock=16
05/04/2018 08:28:32;0100;Server@node2;Req;;Type 23 request received from Scheduler@node2.supernodexp.hpc, sock=16
05/04/2018 08:28:32;0008;Server@node2;Job;15986.node2.supernodexp.hpc;Job Run at request of Scheduler@node2.supernodexp.hpc on exec_vnode (node3:ncpus=32:nmics=2:mem=31457280kb)
05/04/2018 08:28:32;0001;Server@node2;Svr;Server@node2;Success (0) in req_runjob2, return value of svr_startjob is 0
05/04/2018 08:28:32;0100;Server@node2;Req;;Type 11 request received from Scheduler@node2.supernodexp.hpc, sock=16
05/04/2018 08:28:32;0008;Server@node2;Job;16001.node2.supernodexp.hpc;Job Modified at request of Scheduler@node2.supernodexp.hpc
05/04/2018 08:38:32;0040;Server@node2;Svr;node2.supernodexp.hpc;Scheduler sent command 3
05/04/2018 08:38:32;0040;Server@node2;Svr;node2.supernodexp.hpc;Scheduler sent command 0
05/04/2018 08:38:32;0100;Server@node2;Req;;Type 21 request received from Scheduler@node2.supernodexp.hpc, sock=16
05/04/2018 08:38:32;0100;Server@node2;Req;;Type 81 request received from Scheduler@node2.supernodexp.hpc, sock=16
05/04/2018 08:38:32;0100;Server@node2;Req;;Type 71 request received from Scheduler@node2.supernodexp.hpc, sock=16
05/04/2018 08:38:32;0100;Server@node2;Req;;Type 58 request received from Scheduler@node2.supernodexp.hpc, sock=16
05/04/2018 08:38:32;0100;Server@node2;Req;;Type 20 request received from Scheduler@node2.supernodexp.hpc, sock=16
05/04/2018 08:38:32;0100;Server@node2;Req;;Type 51 request received from Scheduler@node2.supernodexp.hpc, sock=16
05/04/2018 08:44:11;0080;Server@node2;Job;15979.node2.supernodexp.hpc;Obit received momhop:1 serverhop:1 state:4 substate:42
05/04/2018 08:44:11;0010;Server@node2;Job;15979.node2.supernodexp.hpc;Exit_status=2 resources_used.cpupercent=0 resources_used.cput=00:00:00 resources_used.mem=10244kb resources_used.ncpus=32 resources_used.vmem=105780kb resources_used.walltime=00:18:52
05/04/2018 08:44:11;0100;Server@node2;Job;15979.node2.supernodexp.hpc;dequeuing from workq, state 5
05/04/2018 08:44:11;0040;Server@node2;Svr;node2.supernodexp.hpc;Scheduler sent command 2
05/04/2018 08:44:11;0040;Server@node2;Svr;node2.supernodexp.hpc;Scheduler sent command 0
05/04/2018 08:44:11;0100;Server@node2;Req;;Type 21 request received from Scheduler@node2.supernodexp.hpc, sock=16
05/04/2018 08:44:11;0100;Server@node2;Req;;Type 81 request received from Scheduler@node2.supernodexp.hpc, sock=16
05/04/2018 08:44:11;0100;Server@node2;Req;;Type 71 request received from Scheduler@node2.supernodexp.hpc, sock=16
05/04/2018 08:44:11;0100;Server@node2;Req;;Type 58 request received from Scheduler@node2.supernodexp.hpc, sock=16
05/04/2018 08:44:11;0100;Server@node2;Req;;Type 20 request received from Scheduler@node2.supernodexp.hpc, sock=16
05/04/2018 08:44:11;0100;Server@node2;Req;;Type 51 request received from Scheduler@node2.supernodexp.hpc, sock=16
05/04/2018 08:44:12;0100;Server@node2;Req;;Type 23 request received from Scheduler@node2.supernodexp.hpc, sock=16
05/04/2018 08:44:12;0008;Server@node2;Job;16001.node2.supernodexp.hpc;Job Run at request of Scheduler@node2.supernodexp.hpc on exec_vnode (node14:ncpus=32:nmics=2:mem=31457280kb)
05/04/2018 08:44:12;0001;Server@node2;Svr;Server@node2;Success (0) in req_runjob2, return value of svr_startjob is 0
05/04/2018 08:44:12;0100;Server@node2;Req;;Type 11 request received from Scheduler@node2.supernodexp.hpc, sock=16
05/04/2018 08:44:12;0008;Server@node2;Job;16003.node2.supernodexp.hpc;Job Modified at request of Scheduler@node2.supernodexp.hpc
05/04/2018 08:45:06;0080;Server@node2;Job;15981.node2.supernodexp.hpc;Obit received momhop:1 serverhop:1 state:4 substate:42
05/04/2018 08:45:07;0010;Server@node2;Job;15981.node2.supernodexp.hpc;Exit_status=2 resources_used.cpupercent=0 resources_used.cput=00:00:00 resources_used.mem=9848kb resources_used.ncpus=32 resources_used.vmem=1010356kb resources_used.walltime=00:18:50
05/04/2018 08:45:07;0100;Server@node2;Job;15981.node2.supernodexp.hpc;dequeuing from workq, state 5
05/04/2018 08:45:07;0040;Server@node2;Svr;node2.supernodexp.hpc;Scheduler sent command 2
05/04/2018 08:45:07;0040;Server@node2;Svr;node2.supernodexp.hpc;Scheduler sent command 0
05/04/2018 08:45:07;0100;Server@node2;Req;;Type 21 request received from Scheduler@node2.supernodexp.hpc, sock=16
05/04/2018 08:45:07;0100;Server@node2;Req;;Type 81 request received from Scheduler@node2.supernodexp.hpc, sock=16
05/04/2018 08:45:07;0100;Server@node2;Req;;Type 71 request received from Scheduler@node2.supernodexp.hpc, sock=16
05/04/2018 08:45:07;0100;Server@node2;Req;;Type 58 request received from Scheduler@node2.supernodexp.hpc, sock=16
05/04/2018 08:45:07;0100;Server@node2;Req;;Type 20 request received from Scheduler@node2.supernodexp.hpc, sock=16
05/04/2018 08:45:07;0100;Server@node2;Req;;Type 51 request received from Scheduler@node2.supernodexp.hpc, sock=16
05/04/2018 08:45:07;0100;Server@node2;Req;;Type 23 request received from Scheduler@node2.supernodexp.hpc, sock=16
05/04/2018 08:45:07;0008;Server@node2;Job;16003.node2.supernodexp.hpc;Job Run at request of Scheduler@node2.supernodexp.hpc on exec_vnode (node13:ncpus=32:nmics=2:mem=31457280kb)
05/04/2018 08:45:07;0001;Server@node2;Svr;Server@node2;Success (0) in req_runjob2, return value of svr_startjob is 0
05/04/2018 08:45:07;0100;Server@node2;Req;;Type 11 request received from Scheduler@node2.supernodexp.hpc, sock=16
05/04/2018 08:45:07;0008;Server@node2;Job;16015.node2.supernodexp.hpc;Job Modified at request of Scheduler@node2.supernodexp.hpc
05/04/2018 08:48:56;0080;Server@node2;Job;15986.node2.supernodexp.hpc;Obit received momhop:1 serverhop:1 state:4 substate:42
05/04/2018 08:48:57;0010;Server@node2;Job;15986.node2.supernodexp.hpc;Exit_status=2 resources_used.cpupercent=0 resources_used.cput=00:00:00 resources_used.mem=9436kb resources_used.ncpus=32 resources_used.vmem=170880kb resources_used.walltime=00:20:24
05/04/2018 08:48:57;0100;Server@node2;Job;15986.node2.supernodexp.hpc;dequeuing from workq, state 5
05/04/2018 08:48:57;0040;Server@node2;Svr;node2.supernodexp.hpc;Scheduler sent command 2
05/04/2018 08:48:57;0040;Server@node2;Svr;node2.supernodexp.hpc;Scheduler sent command 0
05/04/2018 08:48:57;0100;Server@node2;Req;;Type 21 request received from Scheduler@node2.supernodexp.hpc, sock=16
05/04/2018 08:48:57;0100;Server@node2;Req;;Type 81 request received from Scheduler@node2.supernodexp.hpc, sock=16
05/04/2018 08:48:57;0100;Server@node2;Req;;Type 71 request received from Scheduler@node2.supernodexp.hpc, sock=16
05/04/2018 08:48:57;0100;Server@node2;Req;;Type 58 request received from Scheduler@node2.supernodexp.hpc, sock=16
05/04/2018 08:48:57;0100;Server@node2;Req;;Type 20 request received from Scheduler@node2.supernodexp.hpc, sock=16
05/04/2018 08:48:57;0100;Server@node2;Req;;Type 51 request received from Scheduler@node2.supernodexp.hpc, sock=16
05/04/2018 08:48:57;0100;Server@node2;Req;;Type 23 request received from Scheduler@node2.supernodexp.hpc, sock=16
05/04/2018 08:48:57;0008;Server@node2;Job;16015.node2.supernodexp.hpc;Job Run at request of Scheduler@node2.supernodexp.hpc on exec_vnode (node3:ncpus=32:nmics=2:mem=31457280kb)
05/04/2018 08:48:57;0001;Server@node2;Svr;Server@node2;Success (0) in req_runjob2, return value of svr_startjob is 0
05/04/2018 08:48:57;0100;Server@node2;Req;;Type 11 request received from Scheduler@node2.supernodexp.hpc, sock=16
05/04/2018 08:48:57;0008;Server@node2;Job;16031.node2.supernodexp.hpc;Job Modified at request of Scheduler@node2.supernodexp.hpc
05/04/2018 08:58:57;0040;Server@node2;Svr;node2.supernodexp.hpc;Scheduler sent command 3
05/04/2018 08:58:57;0040;Server@node2;Svr;node2.supernodexp.hpc;Scheduler sent command 0
05/04/2018 08:58:57;0100;Server@node2;Req;;Type 21 request received from Scheduler@node2.supernodexp.hpc, sock=16
05/04/2018 08:58:57;0100;Server@node2;Req;;Type 81 request received from Scheduler@node2.supernodexp.hpc, sock=16
05/04/2018 08:58:57;0100;Server@node2;Req;;Type 71 request received from Scheduler@node2.supernodexp.hpc, sock=16
05/04/2018 08:58:57;0100;Server@node2;Req;;Type 58 request received from Scheduler@node2.supernodexp.hpc, sock=16
05/04/2018 08:58:57;0100;Server@node2;Req;;Type 20 request received from Scheduler@node2.supernodexp.hpc, sock=16
05/04/2018 08:58:57;0100;Server@node2;Req;;Type 51 request received from Scheduler@node2.supernodexp.hpc, sock=16
05/04/2018 09:03:01;0080;Server@node2;Job;16001.node2.supernodexp.hpc;Obit received momhop:1 serverhop:1 state:4 substate:42
05/04/2018 09:03:02;0010;Server@node2;Job;16001.node2.supernodexp.hpc;Exit_status=2 resources_used.cpupercent=0 resources_used.cput=00:00:00 resources_used.mem=10016kb resources_used.ncpus=32 resources_used.vmem=170164kb resources_used.walltime=00:18:49
05/04/2018 09:03:02;0100;Server@node2;Job;16001.node2.supernodexp.hpc;dequeuing from workq, state 5
05/04/2018 09:03:02;0040;Server@node2;Svr;node2.supernodexp.hpc;Scheduler sent command 2
05/04/2018 09:03:02;0040;Server@node2;Svr;node2.supernodexp.hpc;Scheduler sent command 0
05/04/2018 09:03:02;0100;Server@node2;Req;;Type 21 request received from Scheduler@node2.supernodexp.hpc, sock=16
05/04/2018 09:03:02;0100;Server@node2;Req;;Type 81 request received from Scheduler@node2.supernodexp.hpc, sock=16
05/04/2018 09:03:02;0100;Server@node2;Req;;Type 71 request received from Scheduler@node2.supernodexp.hpc, sock=16
05/04/2018 09:03:02;0100;Server@node2;Req;;Type 58 request received from Scheduler@node2.supernodexp.hpc, sock=16
05/04/2018 09:03:02;0100;Server@node2;Req;;Type 20 request received from Scheduler@node2.supernodexp.hpc, sock=16
05/04/2018 09:03:02;0100;Server@node2;Req;;Type 51 request received from Scheduler@node2.supernodexp.hpc, sock=16
05/04/2018 09:03:02;0100;Server@node2;Req;;Type 23 request received from Scheduler@node2.supernodexp.hpc, sock=16
05/04/2018 09:03:02;0008;Server@node2;Job;16031.node2.supernodexp.hpc;Job Run at request of Scheduler@node2.supernodexp.hpc on exec_vnode (node14:ncpus=32:nmics=2:mem=31457280kb)
05/04/2018 09:03:02;0001;Server@node2;Svr;Server@node2;Success (0) in req_runjob2, return value of svr_startjob is 0
05/04/2018 09:03:02;0100;Server@node2;Req;;Type 11 request received from Scheduler@node2.supernodexp.hpc, sock=16
05/04/2018 09:03:02;0008;Server@node2;Job;16071.node2.supernodexp.hpc;Job Modified at request of Scheduler@node2.supernodexp.hpc
05/04/2018 09:04:04;0080;Server@node2;Job;16003.node2.supernodexp.hpc;Obit received momhop:1 serverhop:1 state:4 substate:42
05/04/2018 09:04:05;0010;Server@node2;Job;16003.node2.supernodexp.hpc;Exit_status=2 resources_used.cpupercent=0 resources_used.cput=00:00:00 resources_used.mem=10028kb resources_used.ncpus=32 resources_used.vmem=104628kb resources_used.walltime=00:18:56
05/04/2018 09:04:05;0100;Server@node2;Job;16003.node2.supernodexp.hpc;dequeuing from workq, state 5
05/04/2018 09:04:05;0040;Server@node2;Svr;node2.supernodexp.hpc;Scheduler sent command 2
05/04/2018 09:04:05;0040;Server@node2;Svr;node2.supernodexp.hpc;Scheduler sent command 0
05/04/2018 09:04:05;0100;Server@node2;Req;;Type 21 request received from Scheduler@node2.supernodexp.hpc, sock=16
05/04/2018 09:04:05;0100;Server@node2;Req;;Type 81 request received from Scheduler@node2.supernodexp.hpc, sock=16
05/04/2018 09:04:05;0100;Server@node2;Req;;Type 71 request received from Scheduler@node2.supernodexp.hpc, sock=16
05/04/2018 09:04:05;0100;Server@node2;Req;;Type 58 request received from Scheduler@node2.supernodexp.hpc, sock=16
05/04/2018 09:04:05;0100;Server@node2;Req;;Type 20 request received from Scheduler@node2.supernodexp.hpc, sock=16
05/04/2018 09:04:05;0100;Server@node2;Req;;Type 51 request received from Scheduler@node2.supernodexp.hpc, sock=16
05/04/2018 09:04:05;0100;Server@node2;Req;;Type 23 request received from Scheduler@node2.supernodexp.hpc, sock=16
05/04/2018 09:04:05;0008;Server@node2;Job;16071.node2.supernodexp.hpc;Job Run at request of Scheduler@node2.supernodexp.hpc on exec_vnode (node13:ncpus=32:nmics=2:mem=31457280kb)
05/04/2018 09:04:05;0001;Server@node2;Svr;Server@node2;Success (0) in req_runjob2, return value of svr_startjob is 0
05/04/2018 09:04:05;0100;Server@node2;Req;;Type 11 request received from Scheduler@node2.supernodexp.hpc, sock=16
05/04/2018 09:04:05;0008;Server@node2;Job;16081.node2.supernodexp.hpc;Job Modified at request of Scheduler@node2.supernodexp.hpc
05/04/2018 09:09:18;0080;Server@node2;Job;16015.node2.supernodexp.hpc;Obit received momhop:1 serverhop:1 state:4 substate:42
05/04/2018 09:09:18;0010;Server@node2;Job;16015.node2.supernodexp.hpc;Exit_status=2 resources_used.cpupercent=0 resources_used.cput=00:00:00 resources_used.mem=9440kb resources_used.ncpus=32 resources_used.vmem=170880kb resources_used.walltime=00:20:21
05/04/2018 09:09:18;0100;Server@node2;Job;16015.node2.supernodexp.hpc;dequeuing from workq, state 5
05/04/2018 09:09:18;0040;Server@node2;Svr;node2.supernodexp.hpc;Scheduler sent command 2
05/04/2018 09:09:18;0040;Server@node2;Svr;node2.supernodexp.hpc;Scheduler sent command 0
05/04/2018 09:09:18;0100;Server@node2;Req;;Type 21 request received from Scheduler@node2.supernodexp.hpc, sock=16
05/04/2018 09:09:18;0100;Server@node2;Req;;Type 81 request received from Scheduler@node2.supernodexp.hpc, sock=16
05/04/2018 09:09:18;0100;Server@node2;Req;;Type 71 request received from Scheduler@node2.supernodexp.hpc, sock=16
05/04/2018 09:09:18;0100;Server@node2;Req;;Type 58 request received from Scheduler@node2.supernodexp.hpc, sock=16
05/04/2018 09:09:18;0100;Server@node2;Req;;Type 20 request received from Scheduler@node2.supernodexp.hpc, sock=16
05/04/2018 09:09:18;0100;Server@node2;Req;;Type 51 request received from Scheduler@node2.supernodexp.hpc, sock=16
05/04/2018 09:09:19;0100;Server@node2;Req;;Type 23 request received from Scheduler@node2.supernodexp.hpc, sock=16
05/04/2018 09:09:19;0008;Server@node2;Job;16081.node2.supernodexp.hpc;Job Run at request of Scheduler@node2.supernodexp.hpc on exec_vnode (node3:ncpus=32:nmics=2:mem=31457280kb)
05/04/2018 09:09:19;0001;Server@node2;Svr;Server@node2;Success (0) in req_runjob2, return value of svr_startjob is 0
05/04/2018 09:09:19;0100;Server@node2;Req;;Type 11 request received from Scheduler@node2.supernodexp.hpc, sock=16
05/04/2018 09:09:19;0008;Server@node2;Job;16151.node2.supernodexp.hpc;Job Modified at request of Scheduler@node2.supernodexp.hpc
05/04/2018 09:19:18;0040;Server@node2;Svr;node2.supernodexp.hpc;Scheduler sent command 3
05/04/2018 09:19:18;0040;Server@node2;Svr;node2.supernodexp.hpc;Scheduler sent command 0
05/04/2018 09:19:18;0100;Server@node2;Req;;Type 21 request received from Scheduler@node2.supernodexp.hpc, sock=16
05/04/2018 09:19:18;0100;Server@node2;Req;;Type 81 request received from Scheduler@node2.supernodexp.hpc, sock=16
05/04/2018 09:19:18;0100;Server@node2;Req;;Type 71 request received from Scheduler@node2.supernodexp.hpc, sock=16
05/04/2018 09:19:18;0100;Server@node2;Req;;Type 58 request received from Scheduler@node2.supernodexp.hpc, sock=16
05/04/2018 09:19:18;0100;Server@node2;Req;;Type 20 request received from Scheduler@node2.supernodexp.hpc, sock=16
05/04/2018 09:19:18;0100;Server@node2;Req;;Type 51 request received from Scheduler@node2.supernodexp.hpc, sock=16
05/04/2018 09:22:05;0080;Server@node2;Job;16031.node2.supernodexp.hpc;Obit received momhop:1 serverhop:1 state:4 substate:42
05/04/2018 09:22:05;0010;Server@node2;Job;16031.node2.supernodexp.hpc;Exit_status=2 resources_used.cpupercent=0 resources_used.cput=00:00:00 resources_used.mem=10016kb resources_used.ncpus=32 resources_used.vmem=102576kb resources_used.walltime=00:19:03
05/04/2018 09:22:05;0100;Server@node2;Job;16031.node2.supernodexp.hpc;dequeuing from workq, state 5
05/04/2018 09:22:05;0040;Server@node2;Svr;node2.supernodexp.hpc;Scheduler sent command 2
05/04/2018 09:22:05;0040;Server@node2;Svr;node2.supernodexp.hpc;Scheduler sent command 0
05/04/2018 09:22:05;0100;Server@node2;Req;;Type 21 request received from Scheduler@node2.supernodexp.hpc, sock=16
05/04/2018 09:22:05;0100;Server@node2;Req;;Type 81 request received from Scheduler@node2.supernodexp.hpc, sock=16
05/04/2018 09:22:05;0100;Server@node2;Req;;Type 71 request received from Scheduler@node2.supernodexp.hpc, sock=16
05/04/2018 09:22:05;0100;Server@node2;Req;;Type 58 request received from Scheduler@node2.supernodexp.hpc, sock=16
05/04/2018 09:22:05;0100;Server@node2;Req;;Type 20 request received from Scheduler@node2.supernodexp.hpc, sock=16
05/04/2018 09:22:05;0100;Server@node2;Req;;Type 51 request received from Scheduler@node2.supernodexp.hpc, sock=16
05/04/2018 09:22:05;0100;Server@node2;Req;;Type 23 request received from Scheduler@node2.supernodexp.hpc, sock=16
05/04/2018 09:22:05;0008;Server@node2;Job;16151.node2.supernodexp.hpc;Job Run at request of Scheduler@node2.supernodexp.hpc on exec_vnode (node14:ncpus=32:nmics=2:mem=31457280kb)
05/04/2018 09:22:05;0001;Server@node2;Svr;Server@node2;Success (0) in req_runjob2, return value of svr_startjob is 0
05/04/2018 09:22:05;0100;Server@node2;Req;;Type 11 request received from Scheduler@node2.supernodexp.hpc, sock=16
05/04/2018 09:22:05;0008;Server@node2;Job;16168.node2.supernodexp.hpc;Job Modified at request of Scheduler@node2.supernodexp.hpc
05/04/2018 09:22:45;0080;Server@node2;Job;16071.node2.supernodexp.hpc;Obit received momhop:1 serverhop:1 state:4 substate:42
05/04/2018 09:22:46;0010;Server@node2;Job;16071.node2.supernodexp.hpc;Exit_status=2 resources_used.cpupercent=0 resources_used.cput=00:00:00 resources_used.mem=9664kb resources_used.ncpus=32 resources_used.vmem=819260kb resources_used.walltime=00:18:40
05/04/2018 09:22:46;0100;Server@node2;Job;16071.node2.supernodexp.hpc;dequeuing from workq, state 5
05/04/2018 09:22:46;0040;Server@node2;Svr;node2.supernodexp.hpc;Scheduler sent command 2
05/04/2018 09:22:46;0040;Server@node2;Svr;node2.supernodexp.hpc;Scheduler sent command 0
05/04/2018 09:22:46;0100;Server@node2;Req;;Type 21 request received from Scheduler@node2.supernodexp.hpc, sock=16
05/04/2018 09:22:46;0100;Server@node2;Req;;Type 81 request received from Scheduler@node2.supernodexp.hpc, sock=16
05/04/2018 09:22:46;0100;Server@node2;Req;;Type 71 request received from Scheduler@node2.supernodexp.hpc, sock=16
05/04/2018 09:22:46;0100;Server@node2;Req;;Type 58 request received from Scheduler@node2.supernodexp.hpc, sock=16
05/04/2018 09:22:46;0100;Server@node2;Req;;Type 20 request received from Scheduler@node2.supernodexp.hpc, sock=16
05/04/2018 09:22:46;0100;Server@node2;Req;;Type 51 request received from Scheduler@node2.supernodexp.hpc, sock=16
05/04/2018 09:22:46;0100;Server@node2;Req;;Type 23 request received from Scheduler@node2.supernodexp.hpc, sock=16
05/04/2018 09:22:46;0008;Server@node2;Job;16168.node2.supernodexp.hpc;Job Run at request of Scheduler@node2.supernodexp.hpc on exec_vnode (node13:ncpus=32:nmics=2:mem=31457280kb)
05/04/2018 09:22:46;0001;Server@node2;Svr;Server@node2;Success (0) in req_runjob2, return value of svr_startjob is 0
05/04/2018 09:22:46;0100;Server@node2;Req;;Type 11 request received from Scheduler@node2.supernodexp.hpc, sock=16
05/04/2018 09:22:46;0008;Server@node2;Job;16180.node2.supernodexp.hpc;Job Modified at request of Scheduler@node2.supernodexp.hpc
05/04/2018 09:29:37;0080;Server@node2;Job;16081.node2.supernodexp.hpc;Obit received momhop:1 serverhop:1 state:4 substate:42
05/04/2018 09:29:38;0010;Server@node2;Job;16081.node2.supernodexp.hpc;Exit_status=2 resources_used.cpupercent=0 resources_used.cput=00:00:00 resources_used.mem=9440kb resources_used.ncpus=32 resources_used.vmem=105088kb resources_used.walltime=00:20:19
05/04/2018 09:29:38;0100;Server@node2;Job;16081.node2.supernodexp.hpc;dequeuing from workq, state 5
05/04/2018 09:29:38;0040;Server@node2;Svr;node2.supernodexp.hpc;Scheduler sent command 2
05/04/2018 09:29:38;0040;Server@node2;Svr;node2.supernodexp.hpc;Scheduler sent command 0
05/04/2018 09:29:38;0100;Server@node2;Req;;Type 21 request received from Scheduler@node2.supernodexp.hpc, sock=16
05/04/2018 09:29:38;0100;Server@node2;Req;;Type 81 request received from Scheduler@node2.supernodexp.hpc, sock=16
05/04/2018 09:29:38;0100;Server@node2;Req;;Type 71 request received from Scheduler@node2.supernodexp.hpc, sock=16
05/04/2018 09:29:38;0100;Server@node2;Req;;Type 58 request received from Scheduler@node2.supernodexp.hpc, sock=16
05/04/2018 09:29:38;0100;Server@node2;Req;;Type 20 request received from Scheduler@node2.supernodexp.hpc, sock=16
05/04/2018 09:29:38;0100;Server@node2;Req;;Type 51 request received from Scheduler@node2.supernodexp.hpc, sock=16
05/04/2018 09:29:38;0100;Server@node2;Req;;Type 23 request received from Scheduler@node2.supernodexp.hpc, sock=16
05/04/2018 09:29:38;0008;Server@node2;Job;16180.node2.supernodexp.hpc;Job Run at request of Scheduler@node2.supernodexp.hpc on exec_vnode (node3:ncpus=32:nmics=2:mem=31457280kb)
05/04/2018 09:29:38;0001;Server@node2;Svr;Server@node2;Success (0) in req_runjob2, return value of svr_startjob is 0
05/04/2018 09:29:38;0100;Server@node2;Req;;Type 11 request received from Scheduler@node2.supernodexp.hpc, sock=16
05/04/2018 09:29:38;0008;Server@node2;Job;16205.node2.supernodexp.hpc;Job Modified at request of Scheduler@node2.supernodexp.hpc
05/04/2018 09:39:38;0040;Server@node2;Svr;node2.supernodexp.hpc;Scheduler sent command 3
05/04/2018 09:39:38;0040;Server@node2;Svr;node2.supernodexp.hpc;Scheduler sent command 0
05/04/2018 09:39:38;0100;Server@node2;Req;;Type 21 request received from Scheduler@node2.supernodexp.hpc, sock=16
05/04/2018 09:39:38;0100;Server@node2;Req;;Type 81 request received from Scheduler@node2.supernodexp.hpc, sock=16
05/04/2018 09:39:38;0100;Server@node2;Req;;Type 71 request received from Scheduler@node2.supernodexp.hpc, sock=16
05/04/2018 09:39:38;0100;Server@node2;Req;;Type 58 request received from Scheduler@node2.supernodexp.hpc, sock=16
05/04/2018 09:39:38;0100;Server@node2;Req;;Type 20 request received from Scheduler@node2.supernodexp.hpc, sock=16
05/04/2018 09:39:38;0100;Server@node2;Req;;Type 51 request received from Scheduler@node2.supernodexp.hpc, sock=16
05/04/2018 09:41:01;0080;Server@node2;Job;16151.node2.supernodexp.hpc;Obit received momhop:1 serverhop:1 state:4 substate:42
05/04/2018 09:41:02;0010;Server@node2;Job;16151.node2.supernodexp.hpc;Exit_status=2 resources_used.cpupercent=0 resources_used.cput=00:00:00 resources_used.mem=10016kb resources_used.ncpus=32 resources_used.vmem=106036kb resources_used.walltime=00:18:56
05/04/2018 09:41:02;0100;Server@node2;Job;16151.node2.supernodexp.hpc;dequeuing from workq, state 5
05/04/2018 09:41:02;0040;Server@node2;Svr;node2.supernodexp.hpc;Scheduler sent command 2
05/04/2018 09:41:02;0040;Server@node2;Svr;node2.supernodexp.hpc;Scheduler sent command 0
05/04/2018 09:41:02;0100;Server@node2;Req;;Type 21 request received from Scheduler@node2.supernodexp.hpc, sock=16
05/04/2018 09:41:02;0100;Server@node2;Req;;Type 81 request received from Scheduler@node2.supernodexp.hpc, sock=16
05/04/2018 09:41:02;0100;Server@node2;Req;;Type 71 request received from Scheduler@node2.supernodexp.hpc, sock=16
05/04/2018 09:41:02;0100;Server@node2;Req;;Type 58 request received from Scheduler@node2.supernodexp.hpc, sock=16
05/04/2018 09:41:02;0100;Server@node2;Req;;Type 20 request received from Scheduler@node2.supernodexp.hpc, sock=16
05/04/2018 09:41:02;0100;Server@node2;Req;;Type 51 request received from Scheduler@node2.supernodexp.hpc, sock=16
05/04/2018 09:41:02;0100;Server@node2;Req;;Type 23 request received from Scheduler@node2.supernodexp.hpc, sock=16
05/04/2018 09:41:02;0008;Server@node2;Job;16205.node2.supernodexp.hpc;Job Run at request of Scheduler@node2.supernodexp.hpc on exec_vnode (node14:ncpus=32:nmics=2:mem=31457280kb)
05/04/2018 09:41:02;0001;Server@node2;Svr;Server@node2;Success (0) in req_runjob2, return value of svr_startjob is 0
05/04/2018 09:41:02;0100;Server@node2;Req;;Type 11 request received from Scheduler@node2.supernodexp.hpc, sock=16
05/04/2018 09:41:02;0008;Server@node2;Job;16214.node2.supernodexp.hpc;Job Modified at request of Scheduler@node2.supernodexp.hpc
05/04/2018 09:41:44;0080;Server@node2;Job;16168.node2.supernodexp.hpc;Obit received momhop:1 serverhop:1 state:4 substate:42
05/04/2018 09:41:45;0010;Server@node2;Job;16168.node2.supernodexp.hpc;Exit_status=2 resources_used.cpupercent=0 resources_used.cput=00:00:00 resources_used.mem=9664kb resources_used.ncpus=32 resources_used.vmem=946872kb resources_used.walltime=00:18:58
05/04/2018 09:41:45;0100;Server@node2;Job;16168.node2.supernodexp.hpc;dequeuing from workq, state 5
05/04/2018 09:41:45;0040;Server@node2;Svr;node2.supernodexp.hpc;Scheduler sent command 2
05/04/2018 09:41:45;0040;Server@node2;Svr;node2.supernodexp.hpc;Scheduler sent command 0
05/04/2018 09:41:45;0100;Server@node2;Req;;Type 21 request received from Scheduler@node2.supernodexp.hpc, sock=16
05/04/2018 09:41:45;0100;Server@node2;Req;;Type 81 request received from Scheduler@node2.supernodexp.hpc, sock=16
05/04/2018 09:41:45;0100;Server@node2;Req;;Type 71 request received from Scheduler@node2.supernodexp.hpc, sock=16
05/04/2018 09:41:45;0100;Server@node2;Req;;Type 58 request received from Scheduler@node2.supernodexp.hpc, sock=16
05/04/2018 09:41:45;0100;Server@node2;Req;;Type 20 request received from Scheduler@node2.supernodexp.hpc, sock=16
05/04/2018 09:41:45;0100;Server@node2;Req;;Type 51 request received from Scheduler@node2.supernodexp.hpc, sock=16
05/04/2018 09:41:45;0100;Server@node2;Req;;Type 23 request received from Scheduler@node2.supernodexp.hpc, sock=16
05/04/2018 09:41:45;0008;Server@node2;Job;16214.node2.supernodexp.hpc;Job Run at request of Scheduler@node2.supernodexp.hpc on exec_vnode (node13:ncpus=32:nmics=2:mem=31457280kb)
05/04/2018 09:41:45;0001;Server@node2;Svr;Server@node2;Success (0) in req_runjob2, return value of svr_startjob is 0
05/04/2018 09:41:45;0100;Server@node2;Req;;Type 11 request received from Scheduler@node2.supernodexp.hpc, sock=16
05/04/2018 09:41:45;0008;Server@node2;Job;16215.node2.supernodexp.hpc;Job Modified at request of Scheduler@node2.supernodexp.hpc
05/04/2018 09:49:46;0080;Server@node2;Job;16180.node2.supernodexp.hpc;Obit received momhop:1 serverhop:1 state:4 substate:42
05/04/2018 09:49:47;0010;Server@node2;Job;16180.node2.supernodexp.hpc;Exit_status=2 resources_used.cpupercent=0 resources_used.cput=00:00:00 resources_used.mem=11456kb resources_used.ncpus=32 resources_used.vmem=170880kb resources_used.walltime=00:20:08
05/04/2018 09:49:47;0100;Server@node2;Job;16180.node2.supernodexp.hpc;dequeuing from workq, state 5
05/04/2018 09:49:47;0040;Server@node2;Svr;node2.supernodexp.hpc;Scheduler sent command 2
05/04/2018 09:49:47;0040;Server@node2;Svr;node2.supernodexp.hpc;Scheduler sent command 0
05/04/2018 09:49:47;0100;Server@node2;Req;;Type 21 request received from Scheduler@node2.supernodexp.hpc, sock=16
05/04/2018 09:49:47;0100;Server@node2;Req;;Type 81 request received from Scheduler@node2.supernodexp.hpc, sock=16
05/04/2018 09:49:47;0100;Server@node2;Req;;Type 71 request received from Scheduler@node2.supernodexp.hpc, sock=16
05/04/2018 09:49:47;0100;Server@node2;Req;;Type 58 request received from Scheduler@node2.supernodexp.hpc, sock=16
05/04/2018 09:49:47;0100;Server@node2;Req;;Type 20 request received from Scheduler@node2.supernodexp.hpc, sock=16
05/04/2018 09:49:47;0100;Server@node2;Req;;Type 51 request received from Scheduler@node2.supernodexp.hpc, sock=16
05/04/2018 09:49:47;0100;Server@node2;Req;;Type 23 request received from Scheduler@node2.supernodexp.hpc, sock=16
05/04/2018 09:49:47;0008;Server@node2;Job;16215.node2.supernodexp.hpc;Job Run at request of Scheduler@node2.supernodexp.hpc on exec_vnode (node3:ncpus=32:nmics=2:mem=31457280kb)
05/04/2018 09:49:47;0001;Server@node2;Svr;Server@node2;Success (0) in req_runjob2, return value of svr_startjob is 0
05/04/2018 09:49:47;0100;Server@node2;Req;;Type 11 request received from Scheduler@node2.supernodexp.hpc, sock=16
05/04/2018 09:49:47;0008;Server@node2;Job;16232.node2.supernodexp.hpc;Job Modified at request of Scheduler@node2.supernodexp.hpc
05/04/2018 09:59:42;0080;Server@node2;Job;16205.node2.supernodexp.hpc;Obit received momhop:1 serverhop:1 state:4 substate:42
05/04/2018 09:59:43;0010;Server@node2;Job;16205.node2.supernodexp.hpc;Exit_status=2 resources_used.cpupercent=0 resources_used.cput=00:00:00 resources_used.mem=9644kb resources_used.ncpus=32 resources_used.vmem=945076kb resources_used.walltime=00:18:40
05/04/2018 09:59:43;0100;Server@node2;Job;16205.node2.supernodexp.hpc;dequeuing from workq, state 5
05/04/2018 09:59:43;0040;Server@node2;Svr;node2.supernodexp.hpc;Scheduler sent command 2
05/04/2018 09:59:43;0040;Server@node2;Svr;node2.supernodexp.hpc;Scheduler sent command 0
05/04/2018 09:59:43;0100;Server@node2;Req;;Type 21 request received from Scheduler@node2.supernodexp.hpc, sock=16
05/04/2018 09:59:43;0100;Server@node2;Req;;Type 81 request received from Scheduler@node2.supernodexp.hpc, sock=16
05/04/2018 09:59:43;0100;Server@node2;Req;;Type 71 request received from Scheduler@node2.supernodexp.hpc, sock=16
05/04/2018 09:59:43;0100;Server@node2;Req;;Type 58 request received from Scheduler@node2.supernodexp.hpc, sock=16
05/04/2018 09:59:43;0100;Server@node2;Req;;Type 20 request received from Scheduler@node2.supernodexp.hpc, sock=16
05/04/2018 09:59:43;0100;Server@node2;Req;;Type 51 request received from Scheduler@node2.supernodexp.hpc, sock=16
05/04/2018 09:59:43;0100;Server@node2;Req;;Type 23 request received from Scheduler@node2.supernodexp.hpc, sock=16
05/04/2018 09:59:43;0008;Server@node2;Job;16232.node2.supernodexp.hpc;Job Run at request of Scheduler@node2.supernodexp.hpc on exec_vnode (node14:ncpus=32:nmics=2:mem=31457280kb)
05/04/2018 09:59:43;0001;Server@node2;Svr;Server@node2;Success (0) in req_runjob2, return value of svr_startjob is 0
05/04/2018 09:59:43;0100;Server@node2;Req;;Type 11 request received from Scheduler@node2.supernodexp.hpc, sock=16
05/04/2018 09:59:43;0008;Server@node2;Job;16243.node2.supernodexp.hpc;Job Modified at request of Scheduler@node2.supernodexp.hpc
05/04/2018 10:00:23;0080;Server@node2;Job;16214.node2.supernodexp.hpc;Obit received momhop:1 serverhop:1 state:4 substate:42
05/04/2018 10:00:24;0010;Server@node2;Job;16214.node2.supernodexp.hpc;Exit_status=2 resources_used.cpupercent=0 resources_used.cput=00:00:00 resources_used.mem=10024kb resources_used.ncpus=32 resources_used.vmem=169908kb resources_used.walltime=00:18:37
05/04/2018 10:00:24;0100;Server@node2;Job;16214.node2.supernodexp.hpc;dequeuing from workq, state 5
05/04/2018 10:00:24;0040;Server@node2;Svr;node2.supernodexp.hpc;Scheduler sent command 2
05/04/2018 10:00:24;0040;Server@node2;Svr;node2.supernodexp.hpc;Scheduler sent command 0
05/04/2018 10:00:24;0100;Server@node2;Req;;Type 21 request received from Scheduler@node2.supernodexp.hpc, sock=16
05/04/2018 10:00:24;0100;Server@node2;Req;;Type 81 request received from Scheduler@node2.supernodexp.hpc, sock=16
05/04/2018 10:00:24;0100;Server@node2;Req;;Type 71 request received from Scheduler@node2.supernodexp.hpc, sock=16
05/04/2018 10:00:24;0100;Server@node2;Req;;Type 58 request received from Scheduler@node2.supernodexp.hpc, sock=16
05/04/2018 10:00:24;0100;Server@node2;Req;;Type 20 request received from Scheduler@node2.supernodexp.hpc, sock=16
05/04/2018 10:00:24;0100;Server@node2;Req;;Type 51 request received from Scheduler@node2.supernodexp.hpc, sock=16
05/04/2018 10:00:24;0100;Server@node2;Req;;Type 23 request received from Scheduler@node2.supernodexp.hpc, sock=16
05/04/2018 10:00:24;0008;Server@node2;Job;16243.node2.supernodexp.hpc;Job Run at request of Scheduler@node2.supernodexp.hpc on exec_vnode (node13:ncpus=32:nmics=2:mem=31457280kb)
05/04/2018 10:00:24;0001;Server@node2;Svr;Server@node2;Success (0) in req_runjob2, return value of svr_startjob is 0
05/04/2018 10:00:24;0100;Server@node2;Req;;Type 11 request received from Scheduler@node2.supernodexp.hpc, sock=16
05/04/2018 10:00:24;0008;Server@node2;Job;16250.node2.supernodexp.hpc;Job Modified at request of Scheduler@node2.supernodexp.hpc
05/04/2018 10:09:58;0080;Server@node2;Job;16215.node2.supernodexp.hpc;Obit received momhop:1 serverhop:1 state:4 substate:42
05/04/2018 10:09:59;0010;Server@node2;Job;16215.node2.supernodexp.hpc;Exit_status=2 resources_used.cpupercent=0 resources_used.cput=00:00:00 resources_used.mem=9420kb resources_used.ncpus=32 resources_used.vmem=103292kb resources_used.walltime=00:20:11
05/04/2018 10:09:59;0100;Server@node2;Job;16215.node2.supernodexp.hpc;dequeuing from workq, state 5
05/04/2018 10:09:59;0040;Server@node2;Svr;node2.supernodexp.hpc;Scheduler sent command 2
05/04/2018 10:09:59;0040;Server@node2;Svr;node2.supernodexp.hpc;Scheduler sent command 0
05/04/2018 10:09:59;0100;Server@node2;Req;;Type 21 request received from Scheduler@node2.supernodexp.hpc, sock=16
05/04/2018 10:09:59;0100;Server@node2;Req;;Type 81 request received from Scheduler@node2.supernodexp.hpc, sock=16
05/04/2018 10:09:59;0100;Server@node2;Req;;Type 71 request received from Scheduler@node2.supernodexp.hpc, sock=16
05/04/2018 10:09:59;0100;Server@node2;Req;;Type 58 request received from Scheduler@node2.supernodexp.hpc, sock=16
05/04/2018 10:09:59;0100;Server@node2;Req;;Type 20 request received from Scheduler@node2.supernodexp.hpc, sock=16
05/04/2018 10:09:59;0100;Server@node2;Req;;Type 51 request received from Scheduler@node2.supernodexp.hpc, sock=16
05/04/2018 10:09:59;0100;Server@node2;Req;;Type 23 request received from Scheduler@node2.supernodexp.hpc, sock=16
05/04/2018 10:09:59;0008;Server@node2;Job;16250.node2.supernodexp.hpc;Job Run at request of Scheduler@node2.supernodexp.hpc on exec_vnode (node3:ncpus=32:nmics=2:mem=31457280kb)
05/04/2018 10:09:59;0001;Server@node2;Svr;Server@node2;Success (0) in req_runjob2, return value of svr_startjob is 0
05/04/2018 10:09:59;0100;Server@node2;Req;;Type 23 request received from Scheduler@node2.supernodexp.hpc, sock=16
05/04/2018 10:09:59;0008;Server@node2;Job;14319.node2.supernodexp.hpc;Job Run at request of Scheduler@node2.supernodexp.hpc on exec_vnode (node3:ncpus=12:mem=20971520kb)
05/04/2018 10:09:59;0001;Server@node2;Svr;Server@node2;Success (0) in req_runjob2, return value of svr_startjob is 0
05/04/2018 10:09:59;0100;Server@node2;Req;;Type 23 request received from Scheduler@node2.supernodexp.hpc, sock=16
05/04/2018 10:09:59;0008;Server@node2;Job;14347.node2.supernodexp.hpc;Job Run at request of Scheduler@node2.supernodexp.hpc on exec_vnode (node14:ncpus=12:mem=20971520kb)
05/04/2018 10:09:59;0001;Server@node2;Svr;Server@node2;Success (0) in req_runjob2, return value of svr_startjob is 0
05/04/2018 10:09:59;0100;Server@node2;Req;;Type 23 request received from Scheduler@node2.supernodexp.hpc, sock=16
05/04/2018 10:09:59;0008;Server@node2;Job;14363.node2.supernodexp.hpc;Job Run at request of Scheduler@node2.supernodexp.hpc on exec_vnode (node13:ncpus=12:mem=20971520kb)
05/04/2018 10:09:59;0001;Server@node2;Svr;Server@node2;Success (0) in req_runjob2, return value of svr_startjob is 0
05/04/2018 10:09:59;0100;Server@node2;Req;;Type 11 request received from Scheduler@node2.supernodexp.hpc, sock=16
05/04/2018 10:09:59;0008;Server@node2;Job;14376.node2.supernodexp.hpc;Job Modified at request of Scheduler@node2.supernodexp.hpc
05/04/2018 10:19:59;0040;Server@node2;Svr;node2.supernodexp.hpc;Scheduler sent command 3
05/04/2018 10:19:59;0040;Server@node2;Svr;node2.supernodexp.hpc;Scheduler sent command 0
05/04/2018 10:19:59;0100;Server@node2;Req;;Type 21 request received from Scheduler@node2.supernodexp.hpc, sock=16
05/04/2018 10:19:59;0100;Server@node2;Req;;Type 81 request received from Scheduler@node2.supernodexp.hpc, sock=16
05/04/2018 10:19:59;0100;Server@node2;Req;;Type 71 request received from Scheduler@node2.supernodexp.hpc, sock=16
05/04/2018 10:19:59;0100;Server@node2;Req;;Type 58 request received from Scheduler@node2.supernodexp.hpc, sock=16
05/04/2018 10:19:59;0100;Server@node2;Req;;Type 20 request received from Scheduler@node2.supernodexp.hpc, sock=16
05/04/2018 10:19:59;0100;Server@node2;Req;;Type 51 request received from Scheduler@node2.supernodexp.hpc, sock=16
05/04/2018 10:20:12;0080;Server@node2;Job;16232.node2.supernodexp.hpc;Obit received momhop:1 serverhop:1 state:4 substate:42
05/04/2018 10:20:13;0010;Server@node2;Job;16232.node2.supernodexp.hpc;Exit_status=2 resources_used.cpupercent=0 resources_used.cput=00:00:00 resources_used.mem=10248kb resources_used.ncpus=32 resources_used.vmem=104372kb resources_used.walltime=00:20:29
05/04/2018 10:20:13;0100;Server@node2;Job;16232.node2.supernodexp.hpc;dequeuing from workq, state 5
05/04/2018 10:20:13;0040;Server@node2;Svr;node2.supernodexp.hpc;Scheduler sent command 2
05/04/2018 10:20:13;0040;Server@node2;Svr;node2.supernodexp.hpc;Scheduler sent command 0
05/04/2018 10:20:13;0100;Server@node2;Req;;Type 21 request received from Scheduler@node2.supernodexp.hpc, sock=16
05/04/2018 10:20:13;0100;Server@node2;Req;;Type 81 request received from Scheduler@node2.supernodexp.hpc, sock=16
05/04/2018 10:20:13;0100;Server@node2;Req;;Type 71 request received from Scheduler@node2.supernodexp.hpc, sock=16
05/04/2018 10:20:13;0100;Server@node2;Req;;Type 58 request received from Scheduler@node2.supernodexp.hpc, sock=16
05/04/2018 10:20:13;0100;Server@node2;Req;;Type 20 request received from Scheduler@node2.supernodexp.hpc, sock=16
05/04/2018 10:20:13;0100;Server@node2;Req;;Type 51 request received from Scheduler@node2.supernodexp.hpc, sock=16
05/04/2018 10:20:13;0100;Server@node2;Req;;Type 23 request received from Scheduler@node2.supernodexp.hpc, sock=16
05/04/2018 10:20:13;0008;Server@node2;Job;14376.node2.supernodexp.hpc;Job Run at request of Scheduler@node2.supernodexp.hpc on exec_vnode (node14:ncpus=12:mem=20971520kb)
05/04/2018 10:20:13;0001;Server@node2;Svr;Server@node2;Success (0) in req_runjob2, return value of svr_startjob is 0
05/04/2018 10:20:13;0100;Server@node2;Req;;Type 23 request received from Scheduler@node2.supernodexp.hpc, sock=16
05/04/2018 10:20:13;0008;Server@node2;Job;14383.node2.supernodexp.hpc;Job Run at request of Scheduler@node2.supernodexp.hpc on exec_vnode (node14:ncpus=12:mem=20971520kb)
05/04/2018 10:20:13;0001;Server@node2;Svr;Server@node2;Success (0) in req_runjob2, return value of svr_startjob is 0
05/04/2018 10:20:13;0100;Server@node2;Req;;Type 23 request received from Scheduler@node2.supernodexp.hpc, sock=16
05/04/2018 10:20:13;0008;Server@node2;Job;14420.node2.supernodexp.hpc;Job Run at request of Scheduler@node2.supernodexp.hpc on exec_vnode (node14:ncpus=12:mem=20971520kb)
05/04/2018 10:20:13;0001;Server@node2;Svr;Server@node2;Success (0) in req_runjob2, return value of svr_startjob is 0
05/04/2018 10:20:13;0100;Server@node2;Req;;Type 11 request received from Scheduler@node2.supernodexp.hpc, sock=16
05/04/2018 10:20:13;0008;Server@node2;Job;14435.node2.supernodexp.hpc;Job Modified at request of Scheduler@node2.supernodexp.hpc
05/04/2018 10:21:15;0080;Server@node2;Job;16243.node2.supernodexp.hpc;Obit received momhop:1 serverhop:1 state:4 substate:42
05/04/2018 10:21:16;0010;Server@node2;Job;16243.node2.supernodexp.hpc;Exit_status=2 resources_used.cpupercent=0 resources_used.cput=00:00:00 resources_used.mem=9416kb resources_used.ncpus=32 resources_used.vmem=172216kb resources_used.walltime=00:20:51
05/04/2018 10:21:16;0100;Server@node2;Job;16243.node2.supernodexp.hpc;dequeuing from workq, state 5
05/04/2018 10:21:16;0040;Server@node2;Svr;node2.supernodexp.hpc;Scheduler sent command 2
05/04/2018 10:21:16;0040;Server@node2;Svr;node2.supernodexp.hpc;Scheduler sent command 0
05/04/2018 10:21:16;0100;Server@node2;Req;;Type 21 request received from Scheduler@node2.supernodexp.hpc, sock=16
05/04/2018 10:21:16;0100;Server@node2;Req;;Type 81 request received from Scheduler@node2.supernodexp.hpc, sock=16
05/04/2018 10:21:16;0100;Server@node2;Req;;Type 71 request received from Scheduler@node2.supernodexp.hpc, sock=16
05/04/2018 10:21:16;0100;Server@node2;Req;;Type 58 request received from Scheduler@node2.supernodexp.hpc, sock=16
05/04/2018 10:21:16;0100;Server@node2;Req;;Type 20 request received from Scheduler@node2.supernodexp.hpc, sock=16
05/04/2018 10:21:16;0100;Server@node2;Req;;Type 51 request received from Scheduler@node2.supernodexp.hpc, sock=16
05/04/2018 10:21:16;0100;Server@node2;Req;;Type 23 request received from Scheduler@node2.supernodexp.hpc, sock=16
05/04/2018 10:21:16;0008;Server@node2;Job;14435.node2.supernodexp.hpc;Job Run at request of Scheduler@node2.supernodexp.hpc on exec_vnode (node13:ncpus=12:mem=20971520kb)
05/04/2018 10:21:16;0001;Server@node2;Svr;Server@node2;Success (0) in req_runjob2, return value of svr_startjob is 0
05/04/2018 10:21:16;0100;Server@node2;Req;;Type 23 request received from Scheduler@node2.supernodexp.hpc, sock=16
05/04/2018 10:21:16;0008;Server@node2;Job;14436.node2.supernodexp.hpc;Job Run at request of Scheduler@node2.supernodexp.hpc on exec_vnode (node13:ncpus=12:mem=20971520kb)
05/04/2018 10:21:16;0001;Server@node2;Svr;Server@node2;Success (0) in req_runjob2, return value of svr_startjob is 0
05/04/2018 10:21:16;0100;Server@node2;Req;;Type 23 request received from Scheduler@node2.supernodexp.hpc, sock=16
05/04/2018 10:21:16;0008;Server@node2;Job;14445.node2.supernodexp.hpc;Job Run at request of Scheduler@node2.supernodexp.hpc on exec_vnode (node13:ncpus=12:mem=20971520kb)
05/04/2018 10:21:16;0001;Server@node2;Svr;Server@node2;Success (0) in req_runjob2, return value of svr_startjob is 0
05/04/2018 10:21:16;0100;Server@node2;Req;;Type 11 request received from Scheduler@node2.supernodexp.hpc, sock=16
05/04/2018 10:21:16;0008;Server@node2;Job;14463.node2.supernodexp.hpc;Job Modified at request of Scheduler@node2.supernodexp.hpc
05/04/2018 10:29:04;0080;Server@node2;Job;14319.node2.supernodexp.hpc;Obit received momhop:1 serverhop:1 state:4 substate:42
05/04/2018 10:29:05;0010;Server@node2;Job;14319.node2.supernodexp.hpc;Exit_status=0 resources_used.cpupercent=0 resources_used.cput=00:00:00 resources_used.mem=9396kb resources_used.ncpus=12 resources_used.vmem=37756kb resources_used.walltime=00:19:05
05/04/2018 10:29:05;0100;Server@node2;Job;14319.node2.supernodexp.hpc;dequeuing from workq, state 5
05/04/2018 10:29:05;0040;Server@node2;Svr;node2.supernodexp.hpc;Scheduler sent command 2
05/04/2018 10:29:05;0040;Server@node2;Svr;node2.supernodexp.hpc;Scheduler sent command 0
05/04/2018 10:29:05;0100;Server@node2;Req;;Type 21 request received from Scheduler@node2.supernodexp.hpc, sock=16
05/04/2018 10:29:05;0100;Server@node2;Req;;Type 81 request received from Scheduler@node2.supernodexp.hpc, sock=16
05/04/2018 10:29:05;0100;Server@node2;Req;;Type 71 request received from Scheduler@node2.supernodexp.hpc, sock=16
05/04/2018 10:29:05;0100;Server@node2;Req;;Type 58 request received from Scheduler@node2.supernodexp.hpc, sock=16
05/04/2018 10:29:05;0100;Server@node2;Req;;Type 20 request received from Scheduler@node2.supernodexp.hpc, sock=16
05/04/2018 10:29:05;0100;Server@node2;Req;;Type 51 request received from Scheduler@node2.supernodexp.hpc, sock=16
05/04/2018 10:29:05;0100;Server@node2;Req;;Type 23 request received from Scheduler@node2.supernodexp.hpc, sock=16
05/04/2018 10:29:05;0008;Server@node2;Job;14463.node2.supernodexp.hpc;Job Run at request of Scheduler@node2.supernodexp.hpc on exec_vnode (node3:ncpus=12:mem=20971520kb)
05/04/2018 10:29:05;0001;Server@node2;Svr;Server@node2;Success (0) in req_runjob2, return value of svr_startjob is 0
05/04/2018 10:29:05;0100;Server@node2;Req;;Type 11 request received from Scheduler@node2.supernodexp.hpc, sock=16
05/04/2018 10:29:05;0008;Server@node2;Job;14477.node2.supernodexp.hpc;Job Modified at request of Scheduler@node2.supernodexp.hpc
05/04/2018 10:32:22;0080;Server@node2;Job;16250.node2.supernodexp.hpc;Obit received momhop:1 serverhop:1 state:4 substate:42
05/04/2018 10:32:23;0010;Server@node2;Job;16250.node2.supernodexp.hpc;Exit_status=2 resources_used.cpupercent=0 resources_used.cput=00:00:00 resources_used.mem=9428kb resources_used.ncpus=32 resources_used.vmem=105088kb resources_used.walltime=00:22:23
05/04/2018 10:32:23;0100;Server@node2;Job;16250.node2.supernodexp.hpc;dequeuing from workq, state 5
05/04/2018 10:32:23;0040;Server@node2;Svr;node2.supernodexp.hpc;Scheduler sent command 2
05/04/2018 10:32:23;0040;Server@node2;Svr;node2.supernodexp.hpc;Scheduler sent command 0
05/04/2018 10:32:23;0100;Server@node2;Req;;Type 21 request received from Scheduler@node2.supernodexp.hpc, sock=16
05/04/2018 10:32:23;0100;Server@node2;Req;;Type 81 request received from Scheduler@node2.supernodexp.hpc, sock=16
05/04/2018 10:32:23;0100;Server@node2;Req;;Type 71 request received from Scheduler@node2.supernodexp.hpc, sock=16
05/04/2018 10:32:23;0100;Server@node2;Req;;Type 58 request received from Scheduler@node2.supernodexp.hpc, sock=16
05/04/2018 10:32:23;0100;Server@node2;Req;;Type 20 request received from Scheduler@node2.supernodexp.hpc, sock=16
05/04/2018 10:32:23;0100;Server@node2;Req;;Type 51 request received from Scheduler@node2.supernodexp.hpc, sock=16
05/04/2018 10:32:23;0100;Server@node2;Req;;Type 23 request received from Scheduler@node2.supernodexp.hpc, sock=16
05/04/2018 10:32:23;0008;Server@node2;Job;14477.node2.supernodexp.hpc;Job Run at request of Scheduler@node2.supernodexp.hpc on exec_vnode (node3:ncpus=12:mem=20971520kb)
05/04/2018 10:32:23;0001;Server@node2;Svr;Server@node2;Success (0) in req_runjob2, return value of svr_startjob is 0
05/04/2018 10:32:23;0100;Server@node2;Req;;Type 23 request received from Scheduler@node2.supernodexp.hpc, sock=16
05/04/2018 10:32:23;0008;Server@node2;Job;14569.node2.supernodexp.hpc;Job Run at request of Scheduler@node2.supernodexp.hpc on exec_vnode (node3:ncpus=12:mem=20971520kb)
05/04/2018 10:32:23;0001;Server@node2;Svr;Server@node2;Success (0) in req_runjob2, return value of svr_startjob is 0
05/04/2018 10:32:23;0100;Server@node2;Req;;Type 23 request received from Scheduler@node2.supernodexp.hpc, sock=16
05/04/2018 10:32:23;0008;Server@node2;Job;14572.node2.supernodexp.hpc;Job Run at request of Scheduler@node2.supernodexp.hpc on exec_vnode (node3:ncpus=12:mem=20971520kb)
05/04/2018 10:32:23;0001;Server@node2;Svr;Server@node2;Success (0) in req_runjob2, return value of svr_startjob is 0
05/04/2018 10:32:23;0100;Server@node2;Req;;Type 11 request received from Scheduler@node2.supernodexp.hpc, sock=16
05/04/2018 10:32:23;0008;Server@node2;Job;14609.node2.supernodexp.hpc;Job Modified at request of Scheduler@node2.supernodexp.hpc
05/04/2018 10:33:12;0080;Server@node2;Job;14363.node2.supernodexp.hpc;Obit received momhop:1 serverhop:1 state:4 substate:42
05/04/2018 10:33:13;0010;Server@node2;Job;14363.node2.supernodexp.hpc;Exit_status=0 resources_used.cpupercent=0 resources_used.cput=00:00:00 resources_used.mem=9612kb resources_used.ncpus=12 resources_used.vmem=808876kb resources_used.walltime=00:23:15
05/04/2018 10:33:13;0100;Server@node2;Job;14363.node2.supernodexp.hpc;dequeuing from workq, state 5
05/04/2018 10:33:13;0040;Server@node2;Svr;node2.supernodexp.hpc;Scheduler sent command 2
05/04/2018 10:33:13;0040;Server@node2;Svr;node2.supernodexp.hpc;Scheduler sent command 0
05/04/2018 10:33:13;0100;Server@node2;Req;;Type 21 request received from Scheduler@node2.supernodexp.hpc, sock=16
05/04/2018 10:33:13;0100;Server@node2;Req;;Type 81 request received from Scheduler@node2.supernodexp.hpc, sock=16
05/04/2018 10:33:13;0100;Server@node2;Req;;Type 71 request received from Scheduler@node2.supernodexp.hpc, sock=16
05/04/2018 10:33:13;0100;Server@node2;Req;;Type 58 request received from Scheduler@node2.supernodexp.hpc, sock=16
05/04/2018 10:33:13;0100;Server@node2;Req;;Type 20 request received from Scheduler@node2.supernodexp.hpc, sock=16
05/04/2018 10:33:13;0100;Server@node2;Req;;Type 51 request received from Scheduler@node2.supernodexp.hpc, sock=16
05/04/2018 10:33:13;0100;Server@node2;Req;;Type 23 request received from Scheduler@node2.supernodexp.hpc, sock=16
05/04/2018 10:33:13;0008;Server@node2;Job;14609.node2.supernodexp.hpc;Job Run at request of Scheduler@node2.supernodexp.hpc on exec_vnode (node13:ncpus=12:mem=20971520kb)
05/04/2018 10:33:13;0001;Server@node2;Svr;Server@node2;Success (0) in req_runjob2, return value of svr_startjob is 0
05/04/2018 10:33:13;0100;Server@node2;Req;;Type 11 request received from Scheduler@node2.supernodexp.hpc, sock=16
05/04/2018 10:33:13;0008;Server@node2;Job;14617.node2.supernodexp.hpc;Job Modified at request of Scheduler@node2.supernodexp.hpc
05/04/2018 10:34:45;0080;Server@node2;Job;14347.node2.supernodexp.hpc;Obit received momhop:1 serverhop:1 state:4 substate:42
05/04/2018 10:34:46;0010;Server@node2;Job;14347.node2.supernodexp.hpc;Exit_status=0 resources_used.cpupercent=0 resources_used.cput=00:00:00 resources_used.mem=10224kb resources_used.ncpus=12 resources_used.vmem=172216kb resources_used.walltime=00:24:47
05/04/2018 10:34:46;0100;Server@node2;Job;14347.node2.supernodexp.hpc;dequeuing from workq, state 5
05/04/2018 10:34:46;0040;Server@node2;Svr;node2.supernodexp.hpc;Scheduler sent command 2
05/04/2018 10:34:46;0040;Server@node2;Svr;node2.supernodexp.hpc;Scheduler sent command 0
05/04/2018 10:34:46;0100;Server@node2;Req;;Type 21 request received from Scheduler@node2.supernodexp.hpc, sock=16
05/04/2018 10:34:46;0100;Server@node2;Req;;Type 81 request received from Scheduler@node2.supernodexp.hpc, sock=16
05/04/2018 10:34:46;0100;Server@node2;Req;;Type 71 request received from Scheduler@node2.supernodexp.hpc, sock=16
05/04/2018 10:34:46;0100;Server@node2;Req;;Type 58 request received from Scheduler@node2.supernodexp.hpc, sock=16
05/04/2018 10:34:46;0100;Server@node2;Req;;Type 20 request received from Scheduler@node2.supernodexp.hpc, sock=16
05/04/2018 10:34:46;0100;Server@node2;Req;;Type 51 request received from Scheduler@node2.supernodexp.hpc, sock=16
05/04/2018 10:34:46;0100;Server@node2;Req;;Type 23 request received from Scheduler@node2.supernodexp.hpc, sock=16
05/04/2018 10:34:46;0008;Server@node2;Job;14617.node2.supernodexp.hpc;Job Run at request of Scheduler@node2.supernodexp.hpc on exec_vnode (node14:ncpus=12:mem=20971520kb)
05/04/2018 10:34:46;0001;Server@node2;Svr;Server@node2;Success (0) in req_runjob2, return value of svr_startjob is 0
05/04/2018 10:34:46;0100;Server@node2;Req;;Type 11 request received from Scheduler@node2.supernodexp.hpc, sock=16
05/04/2018 10:34:46;0008;Server@node2;Job;14635.node2.supernodexp.hpc;Job Modified at request of Scheduler@node2.supernodexp.hpc
05/04/2018 10:44:46;0040;Server@node2;Svr;node2.supernodexp.hpc;Scheduler sent command 3
05/04/2018 10:44:46;0040;Server@node2;Svr;node2.supernodexp.hpc;Scheduler sent command 0
05/04/2018 10:44:46;0100;Server@node2;Req;;Type 21 request received from Scheduler@node2.supernodexp.hpc, sock=16
05/04/2018 10:44:46;0100;Server@node2;Req;;Type 81 request received from Scheduler@node2.supernodexp.hpc, sock=16
05/04/2018 10:44:46;0100;Server@node2;Req;;Type 71 request received from Scheduler@node2.supernodexp.hpc, sock=16
05/04/2018 10:44:46;0100;Server@node2;Req;;Type 58 request received from Scheduler@node2.supernodexp.hpc, sock=16
05/04/2018 10:44:46;0100;Server@node2;Req;;Type 20 request received from Scheduler@node2.supernodexp.hpc, sock=16
05/04/2018 10:44:46;0100;Server@node2;Req;;Type 51 request received from Scheduler@node2.supernodexp.hpc, sock=16
05/04/2018 10:49:18;0080;Server@node2;Job;14383.node2.supernodexp.hpc;Obit received momhop:1 serverhop:1 state:4 substate:42
05/04/2018 10:49:19;0010;Server@node2;Job;14383.node2.supernodexp.hpc;Exit_status=0 resources_used.cpupercent=0 resources_used.cput=00:00:00 resources_used.mem=9648kb resources_used.ncpus=12 resources_used.vmem=237752kb resources_used.walltime=00:29:05
05/04/2018 10:49:19;0100;Server@node2;Job;14383.node2.supernodexp.hpc;dequeuing from workq, state 5
05/04/2018 10:49:19;0040;Server@node2;Svr;node2.supernodexp.hpc;Scheduler sent command 2
05/04/2018 10:49:19;0040;Server@node2;Svr;node2.supernodexp.hpc;Scheduler sent command 0
05/04/2018 10:49:19;0100;Server@node2;Req;;Type 21 request received from Scheduler@node2.supernodexp.hpc, sock=16
05/04/2018 10:49:19;0100;Server@node2;Req;;Type 81 request received from Scheduler@node2.supernodexp.hpc, sock=16
05/04/2018 10:49:19;0100;Server@node2;Req;;Type 71 request received from Scheduler@node2.supernodexp.hpc, sock=16
05/04/2018 10:49:19;0100;Server@node2;Req;;Type 58 request received from Scheduler@node2.supernodexp.hpc, sock=16
05/04/2018 10:49:19;0100;Server@node2;Req;;Type 20 request received from Scheduler@node2.supernodexp.hpc, sock=16
05/04/2018 10:49:19;0100;Server@node2;Req;;Type 51 request received from Scheduler@node2.supernodexp.hpc, sock=16
05/04/2018 10:49:19;0100;Server@node2;Req;;Type 23 request received from Scheduler@node2.supernodexp.hpc, sock=16
05/04/2018 10:49:19;0008;Server@node2;Job;14635.node2.supernodexp.hpc;Job Run at request of Scheduler@node2.supernodexp.hpc on exec_vnode (node14:ncpus=12:mem=20971520kb)
05/04/2018 10:49:19;0001;Server@node2;Svr;Server@node2;Success (0) in req_runjob2, return value of svr_startjob is 0
05/04/2018 10:49:19;0100;Server@node2;Req;;Type 11 request received from Scheduler@node2.supernodexp.hpc, sock=16
05/04/2018 10:49:19;0008;Server@node2;Job;14659.node2.supernodexp.hpc;Job Modified at request of Scheduler@node2.supernodexp.hpc
05/04/2018 10:49:23;0080;Server@node2;Job;14376.node2.supernodexp.hpc;Obit received momhop:1 serverhop:1 state:4 substate:42
05/04/2018 10:49:24;0010;Server@node2;Job;14376.node2.supernodexp.hpc;Exit_status=0 resources_used.cpupercent=0 resources_used.cput=00:00:00 resources_used.mem=10000kb resources_used.ncpus=12 resources_used.vmem=173368kb resources_used.walltime=00:29:10
05/04/2018 10:49:24;0100;Server@node2;Job;14376.node2.supernodexp.hpc;dequeuing from workq, state 5
05/04/2018 10:49:24;0040;Server@node2;Svr;node2.supernodexp.hpc;Scheduler sent command 2
05/04/2018 10:49:24;0040;Server@node2;Svr;node2.supernodexp.hpc;Scheduler sent command 0
05/04/2018 10:49:24;0100;Server@node2;Req;;Type 21 request received from Scheduler@node2.supernodexp.hpc, sock=16
05/04/2018 10:49:24;0100;Server@node2;Req;;Type 81 request received from Scheduler@node2.supernodexp.hpc, sock=16
05/04/2018 10:49:24;0100;Server@node2;Req;;Type 71 request received from Scheduler@node2.supernodexp.hpc, sock=16
05/04/2018 10:49:24;0100;Server@node2;Req;;Type 58 request received from Scheduler@node2.supernodexp.hpc, sock=16
05/04/2018 10:49:24;0100;Server@node2;Req;;Type 20 request received from Scheduler@node2.supernodexp.hpc, sock=16
05/04/2018 10:49:24;0100;Server@node2;Req;;Type 51 request received from Scheduler@node2.supernodexp.hpc, sock=16
05/04/2018 10:49:24;0100;Server@node2;Req;;Type 23 request received from Scheduler@node2.supernodexp.hpc, sock=16
05/04/2018 10:49:24;0008;Server@node2;Job;14659.node2.supernodexp.hpc;Job Run at request of Scheduler@node2.supernodexp.hpc on exec_vnode (node14:ncpus=12:mem=20971520kb)
05/04/2018 10:49:24;0001;Server@node2;Svr;Server@node2;Success (0) in req_runjob2, return value of svr_startjob is 0
05/04/2018 10:49:24;0100;Server@node2;Req;;Type 11 request received from Scheduler@node2.supernodexp.hpc, sock=16
05/04/2018 10:49:24;0008;Server@node2;Job;14682.node2.supernodexp.hpc;Job Modified at request of Scheduler@node2.supernodexp.hpc
05/04/2018 10:49:37;0080;Server@node2;Job;14420.node2.supernodexp.hpc;Obit received momhop:1 serverhop:1 state:4 substate:42
05/04/2018 10:49:39;0010;Server@node2;Job;14420.node2.supernodexp.hpc;Exit_status=271 resources_used.cpupercent=0 resources_used.cput=00:00:00 resources_used.mem=9424kb resources_used.ncpus=12 resources_used.vmem=171960kb resources_used.walltime=00:29:24
05/04/2018 10:49:39;0100;Server@node2;Job;14420.node2.supernodexp.hpc;dequeuing from workq, state 5
05/04/2018 10:49:39;0040;Server@node2;Svr;node2.supernodexp.hpc;Scheduler sent command 2
05/04/2018 10:49:39;0040;Server@node2;Svr;node2.supernodexp.hpc;Scheduler sent command 0
05/04/2018 10:49:39;0100;Server@node2;Req;;Type 21 request received from Scheduler@node2.supernodexp.hpc, sock=16
05/04/2018 10:49:39;0100;Server@node2;Req;;Type 81 request received from Scheduler@node2.supernodexp.hpc, sock=16
05/04/2018 10:49:39;0100;Server@node2;Req;;Type 71 request received from Scheduler@node2.supernodexp.hpc, sock=16
05/04/2018 10:49:39;0100;Server@node2;Req;;Type 58 request received from Scheduler@node2.supernodexp.hpc, sock=16
05/04/2018 10:49:39;0100;Server@node2;Req;;Type 20 request received from Scheduler@node2.supernodexp.hpc, sock=16
05/04/2018 10:49:39;0100;Server@node2;Req;;Type 51 request received from Scheduler@node2.supernodexp.hpc, sock=16
05/04/2018 10:49:39;0100;Server@node2;Req;;Type 23 request received from Scheduler@node2.supernodexp.hpc, sock=16
05/04/2018 10:49:39;0008;Server@node2;Job;14682.node2.supernodexp.hpc;Job Run at request of Scheduler@node2.supernodexp.hpc on exec_vnode (node14:ncpus=12:mem=20971520kb)
05/04/2018 10:49:39;0001;Server@node2;Svr;Server@node2;Success (0) in req_runjob2, return value of svr_startjob is 0
05/04/2018 10:49:39;0100;Server@node2;Req;;Type 11 request received from Scheduler@node2.supernodexp.hpc, sock=16
05/04/2018 10:49:39;0008;Server@node2;Job;14687.node2.supernodexp.hpc;Job Modified at request of Scheduler@node2.supernodexp.hpc
05/04/2018 10:49:49;0080;Server@node2;Job;14435.node2.supernodexp.hpc;Obit received momhop:1 serverhop:1 state:4 substate:42
05/04/2018 10:49:49;0080;Server@node2;Job;14436.node2.supernodexp.hpc;Obit received momhop:1 serverhop:1 state:4 substate:42
05/04/2018 10:49:49;0080;Server@node2;Job;14445.node2.supernodexp.hpc;Obit received momhop:1 serverhop:1 state:4 substate:42
05/04/2018 10:49:50;0010;Server@node2;Job;14445.node2.supernodexp.hpc;Exit_status=271 resources_used.cpupercent=0 resources_used.cput=00:00:00 resources_used.mem=9416kb resources_used.ncpus=12 resources_used.vmem=171960kb resources_used.walltime=00:28:32
05/04/2018 10:49:50;0100;Server@node2;Job;14445.node2.supernodexp.hpc;dequeuing from workq, state 5
05/04/2018 10:49:50;0040;Server@node2;Svr;node2.supernodexp.hpc;Scheduler sent command 2
05/04/2018 10:49:50;0040;Server@node2;Svr;node2.supernodexp.hpc;Scheduler sent command 0
05/04/2018 10:49:50;0100;Server@node2;Req;;Type 21 request received from Scheduler@node2.supernodexp.hpc, sock=16
05/04/2018 10:49:50;0100;Server@node2;Req;;Type 81 request received from Scheduler@node2.supernodexp.hpc, sock=16
05/04/2018 10:49:50;0100;Server@node2;Req;;Type 71 request received from Scheduler@node2.supernodexp.hpc, sock=16
05/04/2018 10:49:50;0100;Server@node2;Req;;Type 58 request received from Scheduler@node2.supernodexp.hpc, sock=16
05/04/2018 10:49:50;0100;Server@node2;Req;;Type 20 request received from Scheduler@node2.supernodexp.hpc, sock=16
05/04/2018 10:49:50;0100;Server@node2;Req;;Type 51 request received from Scheduler@node2.supernodexp.hpc, sock=16
05/04/2018 10:49:50;0100;Server@node2;Req;;Type 23 request received from Scheduler@node2.supernodexp.hpc, sock=16
05/04/2018 10:49:50;0008;Server@node2;Job;14687.node2.supernodexp.hpc;Job Run at request of Scheduler@node2.supernodexp.hpc on exec_vnode (node13:ncpus=12:mem=20971520kb)
05/04/2018 10:49:50;0001;Server@node2;Svr;Server@node2;Success (0) in req_runjob2, return value of svr_startjob is 0
05/04/2018 10:49:50;0100;Server@node2;Req;;Type 11 request received from Scheduler@node2.supernodexp.hpc, sock=16
05/04/2018 10:49:50;0008;Server@node2;Job;14693.node2.supernodexp.hpc;Job Modified at request of Scheduler@node2.supernodexp.hpc
05/04/2018 10:49:51;0010;Server@node2;Job;14435.node2.supernodexp.hpc;Exit_status=271 resources_used.cpupercent=0 resources_used.cput=00:00:00 resources_used.mem=10016kb resources_used.ncpus=12 resources_used.vmem=171960kb resources_used.walltime=00:28:32
05/04/2018 10:49:51;0100;Server@node2;Job;14435.node2.supernodexp.hpc;dequeuing from workq, state 5
05/04/2018 10:49:51;0040;Server@node2;Svr;node2.supernodexp.hpc;Scheduler sent command 2
05/04/2018 10:49:51;0040;Server@node2;Svr;node2.supernodexp.hpc;Scheduler sent command 0
05/04/2018 10:49:51;0100;Server@node2;Req;;Type 21 request received from Scheduler@node2.supernodexp.hpc, sock=16
05/04/2018 10:49:51;0100;Server@node2;Req;;Type 81 request received from Scheduler@node2.supernodexp.hpc, sock=16
05/04/2018 10:49:51;0100;Server@node2;Req;;Type 71 request received from Scheduler@node2.supernodexp.hpc, sock=16
05/04/2018 10:49:51;0100;Server@node2;Req;;Type 58 request received from Scheduler@node2.supernodexp.hpc, sock=16
05/04/2018 10:49:51;0010;Server@node2;Job;14436.node2.supernodexp.hpc;Exit_status=271 resources_used.cpupercent=0 resources_used.cput=00:00:00 resources_used.mem=10208kb resources_used.ncpus=12 resources_used.vmem=170164kb resources_used.walltime=00:28:32
05/04/2018 10:49:51;0100;Server@node2;Job;14436.node2.supernodexp.hpc;dequeuing from workq, state 5
05/04/2018 10:49:51;0100;Server@node2;Req;;Type 20 request received from Scheduler@node2.supernodexp.hpc, sock=16
05/04/2018 10:49:51;0100;Server@node2;Req;;Type 51 request received from Scheduler@node2.supernodexp.hpc, sock=16
05/04/2018 10:49:51;0100;Server@node2;Req;;Type 23 request received from Scheduler@node2.supernodexp.hpc, sock=16
05/04/2018 10:49:51;0008;Server@node2;Job;14693.node2.supernodexp.hpc;Job Run at request of Scheduler@node2.supernodexp.hpc on exec_vnode (node13:ncpus=12:mem=20971520kb)
05/04/2018 10:49:51;0001;Server@node2;Svr;Server@node2;Success (0) in req_runjob2, return value of svr_startjob is 0
05/04/2018 10:49:51;0100;Server@node2;Req;;Type 23 request received from Scheduler@node2.supernodexp.hpc, sock=16
05/04/2018 10:49:51;0008;Server@node2;Job;14696.node2.supernodexp.hpc;Job Run at request of Scheduler@node2.supernodexp.hpc on exec_vnode (node13:ncpus=12:mem=20971520kb)
05/04/2018 10:49:51;0001;Server@node2;Svr;Server@node2;Success (0) in req_runjob2, return value of svr_startjob is 0
05/04/2018 10:49:51;0100;Server@node2;Req;;Type 11 request received from Scheduler@node2.supernodexp.hpc, sock=16
05/04/2018 10:49:51;0008;Server@node2;Job;14746.node2.supernodexp.hpc;Job Modified at request of Scheduler@node2.supernodexp.hpc
05/04/2018 10:49:51;0040;Server@node2;Svr;node2.supernodexp.hpc;Scheduler sent command 2
05/04/2018 10:49:51;0040;Server@node2;Svr;node2.supernodexp.hpc;Scheduler sent command 0
05/04/2018 10:49:51;0100;Server@node2;Req;;Type 21 request received from Scheduler@node2.supernodexp.hpc, sock=16
05/04/2018 10:49:51;0100;Server@node2;Req;;Type 81 request received from Scheduler@node2.supernodexp.hpc, sock=16
05/04/2018 10:49:51;0100;Server@node2;Req;;Type 71 request received from Scheduler@node2.supernodexp.hpc, sock=16
05/04/2018 10:49:51;0100;Server@node2;Req;;Type 58 request received from Scheduler@node2.supernodexp.hpc, sock=16
05/04/2018 10:49:51;0100;Server@node2;Req;;Type 20 request received from Scheduler@node2.supernodexp.hpc, sock=16
05/04/2018 10:49:51;0100;Server@node2;Req;;Type 51 request received from Scheduler@node2.supernodexp.hpc, sock=16
05/04/2018 10:54:43;0080;Server@node2;Job;14463.node2.supernodexp.hpc;Obit received momhop:1 serverhop:1 state:4 substate:42
05/04/2018 10:54:44;0010;Server@node2;Job;14463.node2.supernodexp.hpc;Exit_status=0 resources_used.cpupercent=0 resources_used.cput=00:00:00 resources_used.mem=11216kb resources_used.ncpus=12 resources_used.vmem=104444kb resources_used.walltime=00:25:38
05/04/2018 10:54:44;0100;Server@node2;Job;14463.node2.supernodexp.hpc;dequeuing from workq, state 5
05/04/2018 10:54:44;0040;Server@node2;Svr;node2.supernodexp.hpc;Scheduler sent command 2
05/04/2018 10:54:44;0040;Server@node2;Svr;node2.supernodexp.hpc;Scheduler sent command 0
05/04/2018 10:54:44;0100;Server@node2;Req;;Type 21 request received from Scheduler@node2.supernodexp.hpc, sock=16
05/04/2018 10:54:44;0100;Server@node2;Req;;Type 81 request received from Scheduler@node2.supernodexp.hpc, sock=16
05/04/2018 10:54:44;0100;Server@node2;Req;;Type 71 request received from Scheduler@node2.supernodexp.hpc, sock=16
05/04/2018 10:54:44;0100;Server@node2;Req;;Type 58 request received from Scheduler@node2.supernodexp.hpc, sock=16
05/04/2018 10:54:44;0100;Server@node2;Req;;Type 20 request received from Scheduler@node2.supernodexp.hpc, sock=16
05/04/2018 10:54:44;0100;Server@node2;Req;;Type 51 request received from Scheduler@node2.supernodexp.hpc, sock=16
05/04/2018 10:54:44;0100;Server@node2;Req;;Type 23 request received from Scheduler@node2.supernodexp.hpc, sock=16
05/04/2018 10:54:44;0008;Server@node2;Job;14746.node2.supernodexp.hpc;Job Run at request of Scheduler@node2.supernodexp.hpc on exec_vnode (node3:ncpus=12:mem=20971520kb)
05/04/2018 10:54:44;0001;Server@node2;Svr;Server@node2;Success (0) in req_runjob2, return value of svr_startjob is 0
05/04/2018 10:54:44;0100;Server@node2;Req;;Type 11 request received from Scheduler@node2.supernodexp.hpc, sock=16
05/04/2018 10:54:44;0008;Server@node2;Job;14763.node2.supernodexp.hpc;Job Modified at request of Scheduler@node2.supernodexp.hpc
05/04/2018 10:59:54;0080;Server@node2;Job;14569.node2.supernodexp.hpc;Obit received momhop:1 serverhop:1 state:4 substate:42
05/04/2018 10:59:55;0010;Server@node2;Job;14569.node2.supernodexp.hpc;Exit_status=0 resources_used.cpupercent=0 resources_used.cput=00:00:00 resources_used.mem=9428kb resources_used.ncpus=12 resources_used.vmem=105344kb resources_used.walltime=00:27:31
05/04/2018 10:59:55;0100;Server@node2;Job;14569.node2.supernodexp.hpc;dequeuing from workq, state 5
05/04/2018 10:59:55;0040;Server@node2;Svr;node2.supernodexp.hpc;Scheduler sent command 2
05/04/2018 10:59:55;0040;Server@node2;Svr;node2.supernodexp.hpc;Scheduler sent command 0
05/04/2018 10:59:55;0100;Server@node2;Req;;Type 21 request received from Scheduler@node2.supernodexp.hpc, sock=16
05/04/2018 10:59:55;0100;Server@node2;Req;;Type 81 request received from Scheduler@node2.supernodexp.hpc, sock=16
05/04/2018 10:59:55;0100;Server@node2;Req;;Type 71 request received from Scheduler@node2.supernodexp.hpc, sock=16
05/04/2018 10:59:55;0100;Server@node2;Req;;Type 58 request received from Scheduler@node2.supernodexp.hpc, sock=16
05/04/2018 10:59:55;0100;Server@node2;Req;;Type 20 request received from Scheduler@node2.supernodexp.hpc, sock=16
05/04/2018 10:59:55;0100;Server@node2;Req;;Type 51 request received from Scheduler@node2.supernodexp.hpc, sock=16
05/04/2018 10:59:55;0100;Server@node2;Req;;Type 23 request received from Scheduler@node2.supernodexp.hpc, sock=16
05/04/2018 10:59:55;0008;Server@node2;Job;14763.node2.supernodexp.hpc;Job Run at request of Scheduler@node2.supernodexp.hpc on exec_vnode (node3:ncpus=12:mem=20971520kb)
05/04/2018 10:59:55;0001;Server@node2;Svr;Server@node2;Success (0) in req_runjob2, return value of svr_startjob is 0
05/04/2018 10:59:55;0100;Server@node2;Req;;Type 11 request received from Scheduler@node2.supernodexp.hpc, sock=16
05/04/2018 10:59:55;0008;Server@node2;Job;14791.node2.supernodexp.hpc;Job Modified at request of Scheduler@node2.supernodexp.hpc
05/04/2018 11:00:11;0080;Server@node2;Job;14477.node2.supernodexp.hpc;Obit received momhop:1 serverhop:1 state:4 substate:42
05/04/2018 11:00:11;0080;Server@node2;Job;14572.node2.supernodexp.hpc;Obit received momhop:1 serverhop:1 state:4 substate:42
05/04/2018 11:00:12;0010;Server@node2;Job;14572.node2.supernodexp.hpc;Exit_status=271 resources_used.cpupercent=0 resources_used.cput=00:00:00 resources_used.mem=9104kb resources_used.ncpus=12 resources_used.vmem=105344kb resources_used.walltime=00:27:48
05/04/2018 11:00:12;0100;Server@node2;Job;14572.node2.supernodexp.hpc;dequeuing from workq, state 5
05/04/2018 11:00:12;0040;Server@node2;Svr;node2.supernodexp.hpc;Scheduler sent command 2
05/04/2018 11:00:12;0040;Server@node2;Svr;node2.supernodexp.hpc;Scheduler sent command 0
05/04/2018 11:00:12;0100;Server@node2;Req;;Type 21 request received from Scheduler@node2.supernodexp.hpc, sock=16
05/04/2018 11:00:12;0100;Server@node2;Req;;Type 81 request received from Scheduler@node2.supernodexp.hpc, sock=16
05/04/2018 11:00:12;0100;Server@node2;Req;;Type 71 request received from Scheduler@node2.supernodexp.hpc, sock=16
05/04/2018 11:00:12;0100;Server@node2;Req;;Type 58 request received from Scheduler@node2.supernodexp.hpc, sock=16
05/04/2018 11:00:12;0100;Server@node2;Req;;Type 20 request received from Scheduler@node2.supernodexp.hpc, sock=16
05/04/2018 11:00:12;0100;Server@node2;Req;;Type 51 request received from Scheduler@node2.supernodexp.hpc, sock=16
05/04/2018 11:00:12;0100;Server@node2;Req;;Type 23 request received from Scheduler@node2.supernodexp.hpc, sock=16
05/04/2018 11:00:12;0008;Server@node2;Job;14791.node2.supernodexp.hpc;Job Run at request of Scheduler@node2.supernodexp.hpc on exec_vnode (node3:ncpus=12:mem=20971520kb)
05/04/2018 11:00:12;0001;Server@node2;Svr;Server@node2;Success (0) in req_runjob2, return value of svr_startjob is 0
05/04/2018 11:00:12;0100;Server@node2;Req;;Type 11 request received from Scheduler@node2.supernodexp.hpc, sock=16
05/04/2018 11:00:12;0008;Server@node2;Job;14820.node2.supernodexp.hpc;Job Modified at request of Scheduler@node2.supernodexp.hpc
05/04/2018 11:00:13;0010;Server@node2;Job;14477.node2.supernodexp.hpc;Exit_status=271 resources_used.cpupercent=0 resources_used.cput=00:00:00 resources_used.mem=9352kb resources_used.ncpus=12 resources_used.vmem=104444kb resources_used.walltime=00:27:48
05/04/2018 11:00:13;0100;Server@node2;Job;14477.node2.supernodexp.hpc;dequeuing from workq, state 5
05/04/2018 11:00:13;0040;Server@node2;Svr;node2.supernodexp.hpc;Scheduler sent command 2
05/04/2018 11:00:13;0040;Server@node2;Svr;node2.supernodexp.hpc;Scheduler sent command 0
05/04/2018 11:00:13;0100;Server@node2;Req;;Type 21 request received from Scheduler@node2.supernodexp.hpc, sock=16
05/04/2018 11:00:13;0100;Server@node2;Req;;Type 81 request received from Scheduler@node2.supernodexp.hpc, sock=16
05/04/2018 11:00:13;0100;Server@node2;Req;;Type 71 request received from Scheduler@node2.supernodexp.hpc, sock=16
05/04/2018 11:00:13;0100;Server@node2;Req;;Type 58 request received from Scheduler@node2.supernodexp.hpc, sock=16
05/04/2018 11:00:13;0100;Server@node2;Req;;Type 20 request received from Scheduler@node2.supernodexp.hpc, sock=16
05/04/2018 11:00:13;0100;Server@node2;Req;;Type 51 request received from Scheduler@node2.supernodexp.hpc, sock=16
05/04/2018 11:00:13;0100;Server@node2;Req;;Type 23 request received from Scheduler@node2.supernodexp.hpc, sock=16
05/04/2018 11:00:13;0008;Server@node2;Job;14820.node2.supernodexp.hpc;Job Run at request of Scheduler@node2.supernodexp.hpc on exec_vnode (node3:ncpus=12:mem=20971520kb)
05/04/2018 11:00:13;0001;Server@node2;Svr;Server@node2;Success (0) in req_runjob2, return value of svr_startjob is 0
05/04/2018 11:00:13;0100;Server@node2;Req;;Type 11 request received from Scheduler@node2.supernodexp.hpc, sock=16
05/04/2018 11:00:13;0008;Server@node2;Job;14824.node2.supernodexp.hpc;Job Modified at request of Scheduler@node2.supernodexp.hpc
05/04/2018 11:01:22;0080;Server@node2;Job;14609.node2.supernodexp.hpc;Obit received momhop:1 serverhop:1 state:4 substate:42
05/04/2018 11:01:24;0010;Server@node2;Job;14609.node2.supernodexp.hpc;Exit_status=271 resources_used.cpupercent=0 resources_used.cput=00:00:00 resources_used.mem=10228kb resources_used.ncpus=12 resources_used.vmem=172216kb resources_used.walltime=00:28:09
05/04/2018 11:01:24;0100;Server@node2;Job;14609.node2.supernodexp.hpc;dequeuing from workq, state 5
05/04/2018 11:01:24;0040;Server@node2;Svr;node2.supernodexp.hpc;Scheduler sent command 2
05/04/2018 11:01:24;0040;Server@node2;Svr;node2.supernodexp.hpc;Scheduler sent command 0
05/04/2018 11:01:24;0100;Server@node2;Req;;Type 21 request received from Scheduler@node2.supernodexp.hpc, sock=16
05/04/2018 11:01:24;0100;Server@node2;Req;;Type 81 request received from Scheduler@node2.supernodexp.hpc, sock=16
05/04/2018 11:01:24;0100;Server@node2;Req;;Type 71 request received from Scheduler@node2.supernodexp.hpc, sock=16
05/04/2018 11:01:24;0100;Server@node2;Req;;Type 58 request received from Scheduler@node2.supernodexp.hpc, sock=16
05/04/2018 11:01:24;0100;Server@node2;Req;;Type 20 request received from Scheduler@node2.supernodexp.hpc, sock=16
05/04/2018 11:01:24;0100;Server@node2;Req;;Type 51 request received from Scheduler@node2.supernodexp.hpc, sock=16
05/04/2018 11:01:24;0100;Server@node2;Req;;Type 23 request received from Scheduler@node2.supernodexp.hpc, sock=16
05/04/2018 11:01:24;0008;Server@node2;Job;14824.node2.supernodexp.hpc;Job Run at request of Scheduler@node2.supernodexp.hpc on exec_vnode (node13:ncpus=12:mem=20971520kb)
05/04/2018 11:01:24;0001;Server@node2;Svr;Server@node2;Success (0) in req_runjob2, return value of svr_startjob is 0
05/04/2018 11:01:24;0100;Server@node2;Req;;Type 11 request received from Scheduler@node2.supernodexp.hpc, sock=16
05/04/2018 11:01:24;0008;Server@node2;Job;14826.node2.supernodexp.hpc;Job Modified at request of Scheduler@node2.supernodexp.hpc
05/04/2018 11:02:42;0080;Server@node2;Job;14617.node2.supernodexp.hpc;Obit received momhop:1 serverhop:1 state:4 substate:42
05/04/2018 11:02:44;0010;Server@node2;Job;14617.node2.supernodexp.hpc;Exit_status=271 resources_used.cpupercent=0 resources_used.cput=00:00:00 resources_used.mem=10228kb resources_used.ncpus=12 resources_used.vmem=171960kb resources_used.walltime=00:27:56
05/04/2018 11:02:44;0100;Server@node2;Job;14617.node2.supernodexp.hpc;dequeuing from workq, state 5
05/04/2018 11:02:44;0040;Server@node2;Svr;node2.supernodexp.hpc;Scheduler sent command 2
05/04/2018 11:02:44;0040;Server@node2;Svr;node2.supernodexp.hpc;Scheduler sent command 0
05/04/2018 11:02:44;0100;Server@node2;Req;;Type 21 request received from Scheduler@node2.supernodexp.hpc, sock=16
05/04/2018 11:02:44;0100;Server@node2;Req;;Type 81 request received from Scheduler@node2.supernodexp.hpc, sock=16
05/04/2018 11:02:44;0100;Server@node2;Req;;Type 71 request received from Scheduler@node2.supernodexp.hpc, sock=16
05/04/2018 11:02:44;0100;Server@node2;Req;;Type 58 request received from Scheduler@node2.supernodexp.hpc, sock=16
05/04/2018 11:02:44;0100;Server@node2;Req;;Type 20 request received from Scheduler@node2.supernodexp.hpc, sock=16
05/04/2018 11:02:44;0100;Server@node2;Req;;Type 51 request received from Scheduler@node2.supernodexp.hpc, sock=16
05/04/2018 11:02:44;0100;Server@node2;Req;;Type 23 request received from Scheduler@node2.supernodexp.hpc, sock=16
05/04/2018 11:02:44;0008;Server@node2;Job;14826.node2.supernodexp.hpc;Job Run at request of Scheduler@node2.supernodexp.hpc on exec_vnode (node14:ncpus=12:mem=20971520kb)
05/04/2018 11:02:44;0001;Server@node2;Svr;Server@node2;Success (0) in req_runjob2, return value of svr_startjob is 0
05/04/2018 11:02:44;0100;Server@node2;Req;;Type 11 request received from Scheduler@node2.supernodexp.hpc, sock=16
05/04/2018 11:02:44;0008;Server@node2;Job;14830.node2.supernodexp.hpc;Job Modified at request of Scheduler@node2.supernodexp.hpc
05/04/2018 11:12:44;0040;Server@node2;Svr;node2.supernodexp.hpc;Scheduler sent command 3
05/04/2018 11:12:44;0040;Server@node2;Svr;node2.supernodexp.hpc;Scheduler sent command 0
05/04/2018 11:12:44;0100;Server@node2;Req;;Type 21 request received from Scheduler@node2.supernodexp.hpc, sock=16
05/04/2018 11:12:44;0100;Server@node2;Req;;Type 81 request received from Scheduler@node2.supernodexp.hpc, sock=16
05/04/2018 11:12:44;0100;Server@node2;Req;;Type 71 request received from Scheduler@node2.supernodexp.hpc, sock=16
05/04/2018 11:12:44;0100;Server@node2;Req;;Type 58 request received from Scheduler@node2.supernodexp.hpc, sock=16
05/04/2018 11:12:44;0100;Server@node2;Req;;Type 20 request received from Scheduler@node2.supernodexp.hpc, sock=16
05/04/2018 11:12:44;0100;Server@node2;Req;;Type 51 request received from Scheduler@node2.supernodexp.hpc, sock=16
05/04/2018 11:14:38;0100;Server@node2;Req;;Type 0 request received from baovo@node2.supernodexp.hpc, sock=16
05/04/2018 11:14:38;0100;Server@node2;Req;;Type 49 request received from baovo@node2.supernodexp.hpc, sock=19
05/04/2018 11:14:38;0100;Server@node2;Req;;Type 21 request received from baovo@node2.supernodexp.hpc, sock=16
05/04/2018 11:14:38;0100;Server@node2;Req;;Type 19 request received from baovo@node2.supernodexp.hpc, sock=16
05/04/2018 11:17:30;0080;Server@node2;Job;14635.node2.supernodexp.hpc;Obit received momhop:1 serverhop:1 state:4 substate:42
05/04/2018 11:17:30;0080;Server@node2;Job;14659.node2.supernodexp.hpc;Obit received momhop:1 serverhop:1 state:4 substate:42
05/04/2018 11:17:30;0080;Server@node2;Job;14682.node2.supernodexp.hpc;Obit received momhop:1 serverhop:1 state:4 substate:42
05/04/2018 11:17:33;0010;Server@node2;Job;14635.node2.supernodexp.hpc;Exit_status=271 resources_used.cpupercent=0 resources_used.cput=00:00:00 resources_used.mem=10212kb resources_used.ncpus=12 resources_used.vmem=106680kb resources_used.walltime=00:28:11
05/04/2018 11:17:33;0100;Server@node2;Job;14635.node2.supernodexp.hpc;dequeuing from workq, state 5
05/04/2018 11:17:33;0040;Server@node2;Svr;node2.supernodexp.hpc;Scheduler sent command 2
05/04/2018 11:17:33;0040;Server@node2;Svr;node2.supernodexp.hpc;Scheduler sent command 0
05/04/2018 11:17:33;0100;Server@node2;Req;;Type 21 request received from Scheduler@node2.supernodexp.hpc, sock=16
05/04/2018 11:17:33;0100;Server@node2;Req;;Type 81 request received from Scheduler@node2.supernodexp.hpc, sock=16
05/04/2018 11:17:33;0100;Server@node2;Req;;Type 71 request received from Scheduler@node2.supernodexp.hpc, sock=16
05/04/2018 11:17:33;0100;Server@node2;Req;;Type 58 request received from Scheduler@node2.supernodexp.hpc, sock=16
05/04/2018 11:17:33;0010;Server@node2;Job;14659.node2.supernodexp.hpc;Exit_status=271 resources_used.cpupercent=0 resources_used.cput=00:00:00 resources_used.mem=9604kb resources_used.ncpus=12 resources_used.vmem=172216kb resources_used.walltime=00:28:06
05/04/2018 11:17:33;0100;Server@node2;Job;14659.node2.supernodexp.hpc;dequeuing from workq, state 5
05/04/2018 11:17:33;0100;Server@node2;Req;;Type 20 request received from Scheduler@node2.supernodexp.hpc, sock=16
05/04/2018 11:17:33;0100;Server@node2;Req;;Type 51 request received from Scheduler@node2.supernodexp.hpc, sock=16
05/04/2018 11:17:33;0010;Server@node2;Job;14682.node2.supernodexp.hpc;Exit_status=271 resources_used.cpupercent=0 resources_used.cput=00:00:00 resources_used.mem=9876kb resources_used.ncpus=12 resources_used.vmem=679568kb resources_used.walltime=00:27:51
05/04/2018 11:17:33;0100;Server@node2;Job;14682.node2.supernodexp.hpc;dequeuing from workq, state 5
05/04/2018 11:17:33;0100;Server@node2;Req;;Type 23 request received from Scheduler@node2.supernodexp.hpc, sock=16
05/04/2018 11:17:33;0008;Server@node2;Job;14830.node2.supernodexp.hpc;Job Run at request of Scheduler@node2.supernodexp.hpc on exec_vnode (node14:ncpus=12:mem=20971520kb)
05/04/2018 11:17:33;0001;Server@node2;Svr;Server@node2;Success (0) in req_runjob2, return value of svr_startjob is 0
05/04/2018 11:17:33;0100;Server@node2;Req;;Type 23 request received from Scheduler@node2.supernodexp.hpc, sock=16
05/04/2018 11:17:33;0008;Server@node2;Job;14841.node2.supernodexp.hpc;Job Run at request of Scheduler@node2.supernodexp.hpc on exec_vnode (node14:ncpus=12:mem=20971520kb)
05/04/2018 11:17:33;0001;Server@node2;Svr;Server@node2;Success (0) in req_runjob2, return value of svr_startjob is 0
05/04/2018 11:17:33;0100;Server@node2;Req;;Type 11 request received from Scheduler@node2.supernodexp.hpc, sock=16
05/04/2018 11:17:33;0008;Server@node2;Job;14846.node2.supernodexp.hpc;Job Modified at request of Scheduler@node2.supernodexp.hpc
05/04/2018 11:17:33;0040;Server@node2;Svr;node2.supernodexp.hpc;Scheduler sent command 2
05/04/2018 11:17:33;0040;Server@node2;Svr;node2.supernodexp.hpc;Scheduler sent command 0
05/04/2018 11:17:33;0100;Server@node2;Req;;Type 21 request received from Scheduler@node2.supernodexp.hpc, sock=16
05/04/2018 11:17:33;0100;Server@node2;Req;;Type 81 request received from Scheduler@node2.supernodexp.hpc, sock=16
05/04/2018 11:17:33;0100;Server@node2;Req;;Type 71 request received from Scheduler@node2.supernodexp.hpc, sock=16
05/04/2018 11:17:33;0100;Server@node2;Req;;Type 58 request received from Scheduler@node2.supernodexp.hpc, sock=16
05/04/2018 11:17:33;0100;Server@node2;Req;;Type 20 request received from Scheduler@node2.supernodexp.hpc, sock=16
05/04/2018 11:17:33;0100;Server@node2;Req;;Type 51 request received from Scheduler@node2.supernodexp.hpc, sock=16
05/04/2018 11:17:33;0100;Server@node2;Req;;Type 23 request received from Scheduler@node2.supernodexp.hpc, sock=16
05/04/2018 11:17:33;0008;Server@node2;Job;14846.node2.supernodexp.hpc;Job Run at request of Scheduler@node2.supernodexp.hpc on exec_vnode (node14:ncpus=12:mem=20971520kb)
05/04/2018 11:17:33;0001;Server@node2;Svr;Server@node2;Success (0) in req_runjob2, return value of svr_startjob is 0
05/04/2018 11:17:33;0100;Server@node2;Req;;Type 11 request received from Scheduler@node2.supernodexp.hpc, sock=16
05/04/2018 11:17:33;0008;Server@node2;Job;14856.node2.supernodexp.hpc;Job Modified at request of Scheduler@node2.supernodexp.hpc
05/04/2018 11:17:58;0080;Server@node2;Job;14687.node2.supernodexp.hpc;Obit received momhop:1 serverhop:1 state:4 substate:42
05/04/2018 11:17:58;0080;Server@node2;Job;14693.node2.supernodexp.hpc;Obit received momhop:1 serverhop:1 state:4 substate:42
05/04/2018 11:17:58;0080;Server@node2;Job;14696.node2.supernodexp.hpc;Obit received momhop:1 serverhop:1 state:4 substate:42
05/04/2018 11:18:00;0010;Server@node2;Job;14696.node2.supernodexp.hpc;Exit_status=271 resources_used.cpupercent=0 resources_used.cput=00:00:00 resources_used.mem=10248kb resources_used.ncpus=12 resources_used.vmem=171960kb resources_used.walltime=00:28:07
05/04/2018 11:18:00;0100;Server@node2;Job;14696.node2.supernodexp.hpc;dequeuing from workq, state 5
05/04/2018 11:18:00;0040;Server@node2;Svr;node2.supernodexp.hpc;Scheduler sent command 2
05/04/2018 11:18:00;0040;Server@node2;Svr;node2.supernodexp.hpc;Scheduler sent command 0
05/04/2018 11:18:00;0100;Server@node2;Req;;Type 21 request received from Scheduler@node2.supernodexp.hpc, sock=16
05/04/2018 11:18:00;0100;Server@node2;Req;;Type 81 request received from Scheduler@node2.supernodexp.hpc, sock=16
05/04/2018 11:18:00;0100;Server@node2;Req;;Type 71 request received from Scheduler@node2.supernodexp.hpc, sock=16
05/04/2018 11:18:00;0100;Server@node2;Req;;Type 58 request received from Scheduler@node2.supernodexp.hpc, sock=16
05/04/2018 11:18:00;0100;Server@node2;Req;;Type 20 request received from Scheduler@node2.supernodexp.hpc, sock=16
05/04/2018 11:18:00;0100;Server@node2;Req;;Type 51 request received from Scheduler@node2.supernodexp.hpc, sock=16
05/04/2018 11:18:00;0100;Server@node2;Req;;Type 23 request received from Scheduler@node2.supernodexp.hpc, sock=16
05/04/2018 11:18:00;0008;Server@node2;Job;14856.node2.supernodexp.hpc;Job Run at request of Scheduler@node2.supernodexp.hpc on exec_vnode (node13:ncpus=12:mem=20971520kb)
05/04/2018 11:18:00;0001;Server@node2;Svr;Server@node2;Success (0) in req_runjob2, return value of svr_startjob is 0
05/04/2018 11:18:00;0100;Server@node2;Req;;Type 11 request received from Scheduler@node2.supernodexp.hpc, sock=16
05/04/2018 11:18:00;0008;Server@node2;Job;14858.node2.supernodexp.hpc;Job Modified at request of Scheduler@node2.supernodexp.hpc
05/04/2018 11:18:01;0010;Server@node2;Job;14687.node2.supernodexp.hpc;Exit_status=271 resources_used.cpupercent=0 resources_used.cput=00:00:00 resources_used.mem=10000kb resources_used.ncpus=12 resources_used.vmem=171960kb resources_used.walltime=00:28:07
05/04/2018 11:18:01;0100;Server@node2;Job;14687.node2.supernodexp.hpc;dequeuing from workq, state 5
05/04/2018 11:18:01;0040;Server@node2;Svr;node2.supernodexp.hpc;Scheduler sent command 2
05/04/2018 11:18:01;0040;Server@node2;Svr;node2.supernodexp.hpc;Scheduler sent command 0
05/04/2018 11:18:01;0100;Server@node2;Req;;Type 21 request received from Scheduler@node2.supernodexp.hpc, sock=16
05/04/2018 11:18:01;0100;Server@node2;Req;;Type 81 request received from Scheduler@node2.supernodexp.hpc, sock=16
05/04/2018 11:18:01;0100;Server@node2;Req;;Type 71 request received from Scheduler@node2.supernodexp.hpc, sock=16
05/04/2018 11:18:01;0100;Server@node2;Req;;Type 58 request received from Scheduler@node2.supernodexp.hpc, sock=16
05/04/2018 11:18:01;0100;Server@node2;Req;;Type 20 request received from Scheduler@node2.supernodexp.hpc, sock=16
05/04/2018 11:18:01;0100;Server@node2;Req;;Type 51 request received from Scheduler@node2.supernodexp.hpc, sock=16
05/04/2018 11:18:01;0010;Server@node2;Job;14693.node2.supernodexp.hpc;Exit_status=271 resources_used.cpupercent=0 resources_used.cput=00:00:00 resources_used.mem=10216kb resources_used.ncpus=12 resources_used.vmem=170164kb resources_used.walltime=00:28:07
05/04/2018 11:18:01;0100;Server@node2;Job;14693.node2.supernodexp.hpc;dequeuing from workq, state 5
05/04/2018 11:18:01;0100;Server@node2;Req;;Type 23 request received from Scheduler@node2.supernodexp.hpc, sock=16
05/04/2018 11:18:01;0008;Server@node2;Job;14858.node2.supernodexp.hpc;Job Run at request of Scheduler@node2.supernodexp.hpc on exec_vnode (node13:ncpus=12:mem=20971520kb)
05/04/2018 11:18:01;0001;Server@node2;Svr;Server@node2;Success (0) in req_runjob2, return value of svr_startjob is 0
05/04/2018 11:18:01;0100;Server@node2;Req;;Type 11 request received from Scheduler@node2.supernodexp.hpc, sock=16
05/04/2018 11:18:01;0008;Server@node2;Job;14881.node2.supernodexp.hpc;Job Modified at request of Scheduler@node2.supernodexp.hpc
05/04/2018 11:18:01;0040;Server@node2;Svr;node2.supernodexp.hpc;Scheduler sent command 2
05/04/2018 11:18:01;0040;Server@node2;Svr;node2.supernodexp.hpc;Scheduler sent command 0
05/04/2018 11:18:01;0100;Server@node2;Req;;Type 21 request received from Scheduler@node2.supernodexp.hpc, sock=16
05/04/2018 11:18:01;0100;Server@node2;Req;;Type 81 request received from Scheduler@node2.supernodexp.hpc, sock=16
05/04/2018 11:18:01;0100;Server@node2;Req;;Type 71 request received from Scheduler@node2.supernodexp.hpc, sock=16
05/04/2018 11:18:01;0100;Server@node2;Req;;Type 58 request received from Scheduler@node2.supernodexp.hpc, sock=16
05/04/2018 11:18:01;0100;Server@node2;Req;;Type 20 request received from Scheduler@node2.supernodexp.hpc, sock=16
05/04/2018 11:18:01;0100;Server@node2;Req;;Type 51 request received from Scheduler@node2.supernodexp.hpc, sock=16
05/04/2018 11:18:01;0100;Server@node2;Req;;Type 23 request received from Scheduler@node2.supernodexp.hpc, sock=16
05/04/2018 11:18:01;0008;Server@node2;Job;14881.node2.supernodexp.hpc;Job Run at request of Scheduler@node2.supernodexp.hpc on exec_vnode (node13:ncpus=12:mem=20971520kb)
05/04/2018 11:18:01;0001;Server@node2;Svr;Server@node2;Success (0) in req_runjob2, return value of svr_startjob is 0
05/04/2018 11:18:01;0100;Server@node2;Req;;Type 11 request received from Scheduler@node2.supernodexp.hpc, sock=16
05/04/2018 11:18:01;0008;Server@node2;Job;14916.node2.supernodexp.hpc;Job Modified at request of Scheduler@node2.supernodexp.hpc
05/04/2018 11:22:10;0080;Server@node2;Job;14746.node2.supernodexp.hpc;Obit received momhop:1 serverhop:1 state:4 substate:42
05/04/2018 11:22:11;0010;Server@node2;Job;14746.node2.supernodexp.hpc;Exit_status=0 resources_used.cpupercent=0 resources_used.cput=00:00:00 resources_used.mem=11436kb resources_used.ncpus=12 resources_used.vmem=106752kb resources_used.walltime=00:27:26
05/04/2018 11:22:11;0100;Server@node2;Job;14746.node2.supernodexp.hpc;dequeuing from workq, state 5
05/04/2018 11:22:11;0040;Server@node2;Svr;node2.supernodexp.hpc;Scheduler sent command 2
05/04/2018 11:22:11;0040;Server@node2;Svr;node2.supernodexp.hpc;Scheduler sent command 0
05/04/2018 11:22:11;0100;Server@node2;Req;;Type 21 request received from Scheduler@node2.supernodexp.hpc, sock=16
05/04/2018 11:22:11;0100;Server@node2;Req;;Type 81 request received from Scheduler@node2.supernodexp.hpc, sock=16
05/04/2018 11:22:11;0100;Server@node2;Req;;Type 71 request received from Scheduler@node2.supernodexp.hpc, sock=16
05/04/2018 11:22:11;0100;Server@node2;Req;;Type 58 request received from Scheduler@node2.supernodexp.hpc, sock=16
05/04/2018 11:22:11;0100;Server@node2;Req;;Type 20 request received from Scheduler@node2.supernodexp.hpc, sock=16
05/04/2018 11:22:11;0100;Server@node2;Req;;Type 51 request received from Scheduler@node2.supernodexp.hpc, sock=16
05/04/2018 11:22:11;0100;Server@node2;Req;;Type 23 request received from Scheduler@node2.supernodexp.hpc, sock=16
05/04/2018 11:22:11;0008;Server@node2;Job;14916.node2.supernodexp.hpc;Job Run at request of Scheduler@node2.supernodexp.hpc on exec_vnode (node3:ncpus=12:mem=20971520kb)
05/04/2018 11:22:11;0001;Server@node2;Svr;Server@node2;Success (0) in req_runjob2, return value of svr_startjob is 0
05/04/2018 11:22:11;0100;Server@node2;Req;;Type 11 request received from Scheduler@node2.supernodexp.hpc, sock=16
05/04/2018 11:22:11;0008;Server@node2;Job;14932.node2.supernodexp.hpc;Job Modified at request of Scheduler@node2.supernodexp.hpc
05/04/2018 11:27:26;0080;Server@node2;Job;14820.node2.supernodexp.hpc;Obit received momhop:1 serverhop:1 state:4 substate:42
05/04/2018 11:27:27;0010;Server@node2;Job;14820.node2.supernodexp.hpc;Exit_status=0 resources_used.cpupercent=0 resources_used.cput=00:00:00 resources_used.mem=9104kb resources_used.ncpus=12 resources_used.vmem=105344kb resources_used.walltime=00:27:13
05/04/2018 11:27:27;0100;Server@node2;Job;14820.node2.supernodexp.hpc;dequeuing from workq, state 5
05/04/2018 11:27:27;0040;Server@node2;Svr;node2.supernodexp.hpc;Scheduler sent command 2
05/04/2018 11:27:27;0040;Server@node2;Svr;node2.supernodexp.hpc;Scheduler sent command 0
05/04/2018 11:27:27;0100;Server@node2;Req;;Type 21 request received from Scheduler@node2.supernodexp.hpc, sock=16
05/04/2018 11:27:27;0100;Server@node2;Req;;Type 81 request received from Scheduler@node2.supernodexp.hpc, sock=16
05/04/2018 11:27:27;0100;Server@node2;Req;;Type 71 request received from Scheduler@node2.supernodexp.hpc, sock=16
05/04/2018 11:27:27;0100;Server@node2;Req;;Type 58 request received from Scheduler@node2.supernodexp.hpc, sock=16
05/04/2018 11:27:27;0100;Server@node2;Req;;Type 20 request received from Scheduler@node2.supernodexp.hpc, sock=16
05/04/2018 11:27:27;0100;Server@node2;Req;;Type 51 request received from Scheduler@node2.supernodexp.hpc, sock=16
05/04/2018 11:27:27;0100;Server@node2;Req;;Type 23 request received from Scheduler@node2.supernodexp.hpc, sock=16
05/04/2018 11:27:27;0008;Server@node2;Job;14932.node2.supernodexp.hpc;Job Run at request of Scheduler@node2.supernodexp.hpc on exec_vnode (node3:ncpus=12:mem=20971520kb)
05/04/2018 11:27:27;0001;Server@node2;Svr;Server@node2;Success (0) in req_runjob2, return value of svr_startjob is 0
05/04/2018 11:27:27;0100;Server@node2;Req;;Type 11 request received from Scheduler@node2.supernodexp.hpc, sock=16
05/04/2018 11:27:27;0008;Server@node2;Job;14934.node2.supernodexp.hpc;Job Modified at request of Scheduler@node2.supernodexp.hpc
05/04/2018 11:27:30;0080;Server@node2;Job;14763.node2.supernodexp.hpc;Obit received momhop:1 serverhop:1 state:4 substate:42
05/04/2018 11:27:31;0010;Server@node2;Job;14763.node2.supernodexp.hpc;Exit_status=0 resources_used.cpupercent=0 resources_used.cput=00:00:00 resources_used.mem=9696kb resources_used.ncpus=12 resources_used.vmem=103036kb resources_used.walltime=00:27:35
05/04/2018 11:27:31;0100;Server@node2;Job;14763.node2.supernodexp.hpc;dequeuing from workq, state 5
05/04/2018 11:27:31;0040;Server@node2;Svr;node2.supernodexp.hpc;Scheduler sent command 2
05/04/2018 11:27:31;0040;Server@node2;Svr;node2.supernodexp.hpc;Scheduler sent command 0
05/04/2018 11:27:31;0100;Server@node2;Req;;Type 21 request received from Scheduler@node2.supernodexp.hpc, sock=16
05/04/2018 11:27:31;0100;Server@node2;Req;;Type 81 request received from Scheduler@node2.supernodexp.hpc, sock=16
05/04/2018 11:27:31;0100;Server@node2;Req;;Type 71 request received from Scheduler@node2.supernodexp.hpc, sock=16
05/04/2018 11:27:31;0100;Server@node2;Req;;Type 58 request received from Scheduler@node2.supernodexp.hpc, sock=16
05/04/2018 11:27:31;0100;Server@node2;Req;;Type 20 request received from Scheduler@node2.supernodexp.hpc, sock=16
05/04/2018 11:27:31;0100;Server@node2;Req;;Type 51 request received from Scheduler@node2.supernodexp.hpc, sock=16
05/04/2018 11:27:31;0100;Server@node2;Req;;Type 23 request received from Scheduler@node2.supernodexp.hpc, sock=16
05/04/2018 11:27:31;0008;Server@node2;Job;14934.node2.supernodexp.hpc;Job Run at request of Scheduler@node2.supernodexp.hpc on exec_vnode (node3:ncpus=12:mem=20971520kb)
05/04/2018 11:27:31;0001;Server@node2;Svr;Server@node2;Success (0) in req_runjob2, return value of svr_startjob is 0
05/04/2018 11:27:31;0100;Server@node2;Req;;Type 11 request received from Scheduler@node2.supernodexp.hpc, sock=16
05/04/2018 11:27:31;0008;Server@node2;Job;14935.node2.supernodexp.hpc;Job Modified at request of Scheduler@node2.supernodexp.hpc
05/04/2018 11:27:53;0080;Server@node2;Job;14791.node2.supernodexp.hpc;Obit received momhop:1 serverhop:1 state:4 substate:42
05/04/2018 11:27:54;0010;Server@node2;Job;14791.node2.supernodexp.hpc;Exit_status=0 resources_used.cpupercent=0 resources_used.cput=00:00:00 resources_used.mem=9348kb resources_used.ncpus=12 resources_used.vmem=173348kb resources_used.walltime=00:27:41
05/04/2018 11:27:54;0100;Server@node2;Job;14791.node2.supernodexp.hpc;dequeuing from workq, state 5
05/04/2018 11:27:54;0040;Server@node2;Svr;node2.supernodexp.hpc;Scheduler sent command 2
05/04/2018 11:27:54;0040;Server@node2;Svr;node2.supernodexp.hpc;Scheduler sent command 0
05/04/2018 11:27:54;0100;Server@node2;Req;;Type 21 request received from Scheduler@node2.supernodexp.hpc, sock=16
05/04/2018 11:27:54;0100;Server@node2;Req;;Type 81 request received from Scheduler@node2.supernodexp.hpc, sock=16
05/04/2018 11:27:54;0100;Server@node2;Req;;Type 71 request received from Scheduler@node2.supernodexp.hpc, sock=16
05/04/2018 11:27:54;0100;Server@node2;Req;;Type 58 request received from Scheduler@node2.supernodexp.hpc, sock=16
05/04/2018 11:27:54;0100;Server@node2;Req;;Type 20 request received from Scheduler@node2.supernodexp.hpc, sock=16
05/04/2018 11:27:54;0100;Server@node2;Req;;Type 51 request received from Scheduler@node2.supernodexp.hpc, sock=16
05/04/2018 11:27:54;0100;Server@node2;Req;;Type 23 request received from Scheduler@node2.supernodexp.hpc, sock=16
05/04/2018 11:27:54;0008;Server@node2;Job;14935.node2.supernodexp.hpc;Job Run at request of Scheduler@node2.supernodexp.hpc on exec_vnode (node3:ncpus=12:mem=20971520kb)
05/04/2018 11:27:54;0001;Server@node2;Svr;Server@node2;Success (0) in req_runjob2, return value of svr_startjob is 0
05/04/2018 11:27:54;0100;Server@node2;Req;;Type 11 request received from Scheduler@node2.supernodexp.hpc, sock=16
05/04/2018 11:27:54;0008;Server@node2;Job;14939.node2.supernodexp.hpc;Job Modified at request of Scheduler@node2.supernodexp.hpc
05/04/2018 11:29:36;0080;Server@node2;Job;14824.node2.supernodexp.hpc;Obit received momhop:1 serverhop:1 state:4 substate:42
05/04/2018 11:29:38;0010;Server@node2;Job;14824.node2.supernodexp.hpc;Exit_status=271 resources_used.cpupercent=0 resources_used.cput=00:00:00 resources_used.mem=10016kb resources_used.ncpus=12 resources_used.vmem=171960kb resources_used.walltime=00:28:11
05/04/2018 11:29:38;0100;Server@node2;Job;14824.node2.supernodexp.hpc;dequeuing from workq, state 5
05/04/2018 11:29:38;0040;Server@node2;Svr;node2.supernodexp.hpc;Scheduler sent command 2
05/04/2018 11:29:38;0040;Server@node2;Svr;node2.supernodexp.hpc;Scheduler sent command 0
05/04/2018 11:29:38;0100;Server@node2;Req;;Type 21 request received from Scheduler@node2.supernodexp.hpc, sock=16
05/04/2018 11:29:38;0100;Server@node2;Req;;Type 81 request received from Scheduler@node2.supernodexp.hpc, sock=16
05/04/2018 11:29:38;0100;Server@node2;Req;;Type 71 request received from Scheduler@node2.supernodexp.hpc, sock=16
05/04/2018 11:29:38;0100;Server@node2;Req;;Type 58 request received from Scheduler@node2.supernodexp.hpc, sock=16
05/04/2018 11:29:38;0100;Server@node2;Req;;Type 20 request received from Scheduler@node2.supernodexp.hpc, sock=16
05/04/2018 11:29:38;0100;Server@node2;Req;;Type 51 request received from Scheduler@node2.supernodexp.hpc, sock=16
05/04/2018 11:29:38;0100;Server@node2;Req;;Type 23 request received from Scheduler@node2.supernodexp.hpc, sock=16
05/04/2018 11:29:38;0008;Server@node2;Job;14939.node2.supernodexp.hpc;Job Run at request of Scheduler@node2.supernodexp.hpc on exec_vnode (node13:ncpus=12:mem=20971520kb)
05/04/2018 11:29:38;0001;Server@node2;Svr;Server@node2;Success (0) in req_runjob2, return value of svr_startjob is 0
05/04/2018 11:29:38;0100;Server@node2;Req;;Type 11 request received from Scheduler@node2.supernodexp.hpc, sock=16
05/04/2018 11:29:38;0008;Server@node2;Job;15008.node2.supernodexp.hpc;Job Modified at request of Scheduler@node2.supernodexp.hpc
05/04/2018 11:30:38;0080;Server@node2;Job;14826.node2.supernodexp.hpc;Obit received momhop:1 serverhop:1 state:4 substate:42
05/04/2018 11:30:40;0010;Server@node2;Job;14826.node2.supernodexp.hpc;Exit_status=271 resources_used.cpupercent=0 resources_used.cput=00:00:00 resources_used.mem=10568kb resources_used.ncpus=12 resources_used.vmem=1006480kb resources_used.walltime=00:27:54
05/04/2018 11:30:40;0100;Server@node2;Job;14826.node2.supernodexp.hpc;dequeuing from workq, state 5
05/04/2018 11:30:40;0040;Server@node2;Svr;node2.supernodexp.hpc;Scheduler sent command 2
05/04/2018 11:30:40;0040;Server@node2;Svr;node2.supernodexp.hpc;Scheduler sent command 0
05/04/2018 11:30:40;0100;Server@node2;Req;;Type 21 request received from Scheduler@node2.supernodexp.hpc, sock=16
05/04/2018 11:30:40;0100;Server@node2;Req;;Type 81 request received from Scheduler@node2.supernodexp.hpc, sock=16
05/04/2018 11:30:40;0100;Server@node2;Req;;Type 71 request received from Scheduler@node2.supernodexp.hpc, sock=16
05/04/2018 11:30:40;0100;Server@node2;Req;;Type 58 request received from Scheduler@node2.supernodexp.hpc, sock=16
05/04/2018 11:30:40;0100;Server@node2;Req;;Type 20 request received from Scheduler@node2.supernodexp.hpc, sock=16
05/04/2018 11:30:40;0100;Server@node2;Req;;Type 51 request received from Scheduler@node2.supernodexp.hpc, sock=16
05/04/2018 11:30:40;0100;Server@node2;Req;;Type 23 request received from Scheduler@node2.supernodexp.hpc, sock=16
05/04/2018 11:30:40;0008;Server@node2;Job;15008.node2.supernodexp.hpc;Job Run at request of Scheduler@node2.supernodexp.hpc on exec_vnode (node14:ncpus=12:mem=20971520kb)
05/04/2018 11:30:40;0001;Server@node2;Svr;Server@node2;Success (0) in req_runjob2, return value of svr_startjob is 0
05/04/2018 11:30:40;0100;Server@node2;Req;;Type 11 request received from Scheduler@node2.supernodexp.hpc, sock=16
05/04/2018 11:30:40;0008;Server@node2;Job;15022.node2.supernodexp.hpc;Job Modified at request of Scheduler@node2.supernodexp.hpc
05/04/2018 11:40:40;0040;Server@node2;Svr;node2.supernodexp.hpc;Scheduler sent command 3
05/04/2018 11:40:40;0040;Server@node2;Svr;node2.supernodexp.hpc;Scheduler sent command 0
05/04/2018 11:40:40;0100;Server@node2;Req;;Type 21 request received from Scheduler@node2.supernodexp.hpc, sock=16
05/04/2018 11:40:40;0100;Server@node2;Req;;Type 81 request received from Scheduler@node2.supernodexp.hpc, sock=16
05/04/2018 11:40:40;0100;Server@node2;Req;;Type 71 request received from Scheduler@node2.supernodexp.hpc, sock=16
05/04/2018 11:40:40;0100;Server@node2;Req;;Type 58 request received from Scheduler@node2.supernodexp.hpc, sock=16
05/04/2018 11:40:40;0100;Server@node2;Req;;Type 20 request received from Scheduler@node2.supernodexp.hpc, sock=16
05/04/2018 11:40:40;0100;Server@node2;Req;;Type 51 request received from Scheduler@node2.supernodexp.hpc, sock=16
05/04/2018 11:45:27;0080;Server@node2;Job;14830.node2.supernodexp.hpc;Obit received momhop:1 serverhop:1 state:4 substate:42
05/04/2018 11:45:27;0080;Server@node2;Job;14841.node2.supernodexp.hpc;Obit received momhop:1 serverhop:1 state:4 substate:42
05/04/2018 11:45:27;0080;Server@node2;Job;14846.node2.supernodexp.hpc;Obit received momhop:1 serverhop:1 state:4 substate:42
05/04/2018 11:45:30;0010;Server@node2;Job;14830.node2.supernodexp.hpc;Exit_status=271 resources_used.cpupercent=0 resources_used.cput=00:00:00 resources_used.mem=9640kb resources_used.ncpus=12 resources_used.vmem=173368kb resources_used.walltime=00:27:54
05/04/2018 11:45:30;0100;Server@node2;Job;14830.node2.supernodexp.hpc;dequeuing from workq, state 5
05/04/2018 11:45:30;0040;Server@node2;Svr;node2.supernodexp.hpc;Scheduler sent command 2
05/04/2018 11:45:30;0040;Server@node2;Svr;node2.supernodexp.hpc;Scheduler sent command 0
05/04/2018 11:45:30;0100;Server@node2;Req;;Type 21 request received from Scheduler@node2.supernodexp.hpc, sock=16
05/04/2018 11:45:30;0100;Server@node2;Req;;Type 81 request received from Scheduler@node2.supernodexp.hpc, sock=16
05/04/2018 11:45:30;0100;Server@node2;Req;;Type 71 request received from Scheduler@node2.supernodexp.hpc, sock=16
05/04/2018 11:45:30;0100;Server@node2;Req;;Type 58 request received from Scheduler@node2.supernodexp.hpc, sock=16
05/04/2018 11:45:30;0100;Server@node2;Req;;Type 20 request received from Scheduler@node2.supernodexp.hpc, sock=16
05/04/2018 11:45:30;0100;Server@node2;Req;;Type 51 request received from Scheduler@node2.supernodexp.hpc, sock=16
05/04/2018 11:45:30;0100;Server@node2;Req;;Type 23 request received from Scheduler@node2.supernodexp.hpc, sock=16
05/04/2018 11:45:30;0008;Server@node2;Job;15022.node2.supernodexp.hpc;Job Run at request of Scheduler@node2.supernodexp.hpc on exec_vnode (node14:ncpus=12:mem=20971520kb)
05/04/2018 11:45:30;0001;Server@node2;Svr;Server@node2;Success (0) in req_runjob2, return value of svr_startjob is 0
05/04/2018 11:45:30;0100;Server@node2;Req;;Type 11 request received from Scheduler@node2.supernodexp.hpc, sock=16
05/04/2018 11:45:30;0008;Server@node2;Job;15026.node2.supernodexp.hpc;Job Modified at request of Scheduler@node2.supernodexp.hpc
05/04/2018 11:45:30;0010;Server@node2;Job;14841.node2.supernodexp.hpc;Exit_status=271 resources_used.cpupercent=0 resources_used.cput=00:00:00 resources_used.mem=10232kb resources_used.ncpus=12 resources_used.vmem=172216kb resources_used.walltime=00:27:54
05/04/2018 11:45:30;0100;Server@node2;Job;14841.node2.supernodexp.hpc;dequeuing from workq, state 5
05/04/2018 11:45:30;0040;Server@node2;Svr;node2.supernodexp.hpc;Scheduler sent command 2
05/04/2018 11:45:30;0040;Server@node2;Svr;node2.supernodexp.hpc;Scheduler sent command 0
05/04/2018 11:45:30;0100;Server@node2;Req;;Type 21 request received from Scheduler@node2.supernodexp.hpc, sock=16
05/04/2018 11:45:30;0100;Server@node2;Req;;Type 81 request received from Scheduler@node2.supernodexp.hpc, sock=16
05/04/2018 11:45:30;0100;Server@node2;Req;;Type 71 request received from Scheduler@node2.supernodexp.hpc, sock=16
05/04/2018 11:45:30;0100;Server@node2;Req;;Type 58 request received from Scheduler@node2.supernodexp.hpc, sock=16
05/04/2018 11:45:30;0010;Server@node2;Job;14846.node2.supernodexp.hpc;Exit_status=271 resources_used.cpupercent=0 resources_used.cput=00:00:00 resources_used.mem=10208kb resources_used.ncpus=12 resources_used.vmem=102576kb resources_used.walltime=00:27:54
05/04/2018 11:45:30;0100;Server@node2;Job;14846.node2.supernodexp.hpc;dequeuing from workq, state 5
05/04/2018 11:45:30;0100;Server@node2;Req;;Type 20 request received from Scheduler@node2.supernodexp.hpc, sock=16
05/04/2018 11:45:30;0100;Server@node2;Req;;Type 51 request received from Scheduler@node2.supernodexp.hpc, sock=16
05/04/2018 11:45:30;0100;Server@node2;Req;;Type 23 request received from Scheduler@node2.supernodexp.hpc, sock=16
05/04/2018 11:45:30;0008;Server@node2;Job;15026.node2.supernodexp.hpc;Job Run at request of Scheduler@node2.supernodexp.hpc on exec_vnode (node14:ncpus=12:mem=20971520kb)
05/04/2018 11:45:30;0001;Server@node2;Svr;Server@node2;Success (0) in req_runjob2, return value of svr_startjob is 0
05/04/2018 11:45:30;0100;Server@node2;Req;;Type 23 request received from Scheduler@node2.supernodexp.hpc, sock=16
05/04/2018 11:45:30;0008;Server@node2;Job;15030.node2.supernodexp.hpc;Job Run at request of Scheduler@node2.supernodexp.hpc on exec_vnode (node14:ncpus=12:mem=20971520kb)
05/04/2018 11:45:30;0001;Server@node2;Svr;Server@node2;Success (0) in req_runjob2, return value of svr_startjob is 0
05/04/2018 11:45:30;0100;Server@node2;Req;;Type 11 request received from Scheduler@node2.supernodexp.hpc, sock=16
05/04/2018 11:45:30;0008;Server@node2;Job;15033.node2.supernodexp.hpc;Job Modified at request of Scheduler@node2.supernodexp.hpc
05/04/2018 11:45:30;0040;Server@node2;Svr;node2.supernodexp.hpc;Scheduler sent command 2
05/04/2018 11:45:30;0040;Server@node2;Svr;node2.supernodexp.hpc;Scheduler sent command 0
05/04/2018 11:45:30;0100;Server@node2;Req;;Type 21 request received from Scheduler@node2.supernodexp.hpc, sock=16
05/04/2018 11:45:30;0100;Server@node2;Req;;Type 81 request received from Scheduler@node2.supernodexp.hpc, sock=16
05/04/2018 11:45:30;0100;Server@node2;Req;;Type 71 request received from Scheduler@node2.supernodexp.hpc, sock=16
05/04/2018 11:45:30;0100;Server@node2;Req;;Type 58 request received from Scheduler@node2.supernodexp.hpc, sock=16
05/04/2018 11:45:30;0100;Server@node2;Req;;Type 20 request received from Scheduler@node2.supernodexp.hpc, sock=16
05/04/2018 11:45:30;0100;Server@node2;Req;;Type 51 request received from Scheduler@node2.supernodexp.hpc, sock=16
05/04/2018 11:46:11;0080;Server@node2;Job;14856.node2.supernodexp.hpc;Obit received momhop:1 serverhop:1 state:4 substate:42
05/04/2018 11:46:11;0080;Server@node2;Job;14858.node2.supernodexp.hpc;Obit received momhop:1 serverhop:1 state:4 substate:42
05/04/2018 11:46:12;0080;Server@node2;Job;14881.node2.supernodexp.hpc;Obit received momhop:1 serverhop:1 state:4 substate:42
05/04/2018 11:46:15;0010;Server@node2;Job;14856.node2.supernodexp.hpc;Exit_status=271 resources_used.cpupercent=0 resources_used.cput=00:00:00 resources_used.mem=9992kb resources_used.ncpus=12 resources_used.vmem=171960kb resources_used.walltime=00:28:11
05/04/2018 11:46:15;0100;Server@node2;Job;14856.node2.supernodexp.hpc;dequeuing from workq, state 5
05/04/2018 11:46:15;0040;Server@node2;Svr;node2.supernodexp.hpc;Scheduler sent command 2
05/04/2018 11:46:15;0040;Server@node2;Svr;node2.supernodexp.hpc;Scheduler sent command 0
05/04/2018 11:46:15;0100;Server@node2;Req;;Type 21 request received from Scheduler@node2.supernodexp.hpc, sock=16
05/04/2018 11:46:15;0100;Server@node2;Req;;Type 81 request received from Scheduler@node2.supernodexp.hpc, sock=16
05/04/2018 11:46:15;0100;Server@node2;Req;;Type 71 request received from Scheduler@node2.supernodexp.hpc, sock=16
05/04/2018 11:46:15;0100;Server@node2;Req;;Type 58 request received from Scheduler@node2.supernodexp.hpc, sock=16
05/04/2018 11:46:15;0100;Server@node2;Req;;Type 20 request received from Scheduler@node2.supernodexp.hpc, sock=16
05/04/2018 11:46:15;0100;Server@node2;Req;;Type 51 request received from Scheduler@node2.supernodexp.hpc, sock=16
05/04/2018 11:46:15;0100;Server@node2;Req;;Type 23 request received from Scheduler@node2.supernodexp.hpc, sock=16
05/04/2018 11:46:15;0008;Server@node2;Job;15033.node2.supernodexp.hpc;Job Run at request of Scheduler@node2.supernodexp.hpc on exec_vnode (node13:ncpus=12:mem=20971520kb)
05/04/2018 11:46:15;0001;Server@node2;Svr;Server@node2;Success (0) in req_runjob2, return value of svr_startjob is 0
05/04/2018 11:46:15;0100;Server@node2;Req;;Type 11 request received from Scheduler@node2.supernodexp.hpc, sock=16
05/04/2018 11:46:15;0008;Server@node2;Job;15044.node2.supernodexp.hpc;Job Modified at request of Scheduler@node2.supernodexp.hpc
05/04/2018 11:46:15;0010;Server@node2;Job;14858.node2.supernodexp.hpc;Exit_status=271 resources_used.cpupercent=0 resources_used.cput=00:00:00 resources_used.mem=9972kb resources_used.ncpus=12 resources_used.vmem=106036kb resources_used.walltime=00:28:11
05/04/2018 11:46:15;0100;Server@node2;Job;14858.node2.supernodexp.hpc;dequeuing from workq, state 5
05/04/2018 11:46:15;0040;Server@node2;Svr;node2.supernodexp.hpc;Scheduler sent command 2
05/04/2018 11:46:15;0040;Server@node2;Svr;node2.supernodexp.hpc;Scheduler sent command 0
05/04/2018 11:46:15;0100;Server@node2;Req;;Type 21 request received from Scheduler@node2.supernodexp.hpc, sock=16
05/04/2018 11:46:15;0100;Server@node2;Req;;Type 81 request received from Scheduler@node2.supernodexp.hpc, sock=16
05/04/2018 11:46:15;0100;Server@node2;Req;;Type 71 request received from Scheduler@node2.supernodexp.hpc, sock=16
05/04/2018 11:46:15;0100;Server@node2;Req;;Type 58 request received from Scheduler@node2.supernodexp.hpc, sock=16
05/04/2018 11:46:15;0100;Server@node2;Req;;Type 20 request received from Scheduler@node2.supernodexp.hpc, sock=16
05/04/2018 11:46:15;0010;Server@node2;Job;14881.node2.supernodexp.hpc;Exit_status=271 resources_used.cpupercent=0 resources_used.cput=00:00:00 resources_used.mem=10004kb resources_used.ncpus=12 resources_used.vmem=173368kb resources_used.walltime=00:28:11
05/04/2018 11:46:15;0100;Server@node2;Job;14881.node2.supernodexp.hpc;dequeuing from workq, state 5
05/04/2018 11:46:15;0100;Server@node2;Req;;Type 51 request received from Scheduler@node2.supernodexp.hpc, sock=16
05/04/2018 11:46:15;0100;Server@node2;Req;;Type 23 request received from Scheduler@node2.supernodexp.hpc, sock=16
05/04/2018 11:46:15;0008;Server@node2;Job;15044.node2.supernodexp.hpc;Job Run at request of Scheduler@node2.supernodexp.hpc on exec_vnode (node13:ncpus=12:mem=20971520kb)
05/04/2018 11:46:15;0001;Server@node2;Svr;Server@node2;Success (0) in req_runjob2, return value of svr_startjob is 0
05/04/2018 11:46:15;0100;Server@node2;Req;;Type 23 request received from Scheduler@node2.supernodexp.hpc, sock=16
05/04/2018 11:46:15;0008;Server@node2;Job;15047.node2.supernodexp.hpc;Job Run at request of Scheduler@node2.supernodexp.hpc on exec_vnode (node13:ncpus=12:mem=20971520kb)
05/04/2018 11:46:15;0001;Server@node2;Svr;Server@node2;Success (0) in req_runjob2, return value of svr_startjob is 0
05/04/2018 11:46:15;0100;Server@node2;Req;;Type 11 request received from Scheduler@node2.supernodexp.hpc, sock=16
05/04/2018 11:46:15;0008;Server@node2;Job;15109.node2.supernodexp.hpc;Job Modified at request of Scheduler@node2.supernodexp.hpc
05/04/2018 11:46:15;0040;Server@node2;Svr;node2.supernodexp.hpc;Scheduler sent command 2
05/04/2018 11:46:15;0040;Server@node2;Svr;node2.supernodexp.hpc;Scheduler sent command 0
05/04/2018 11:46:15;0100;Server@node2;Req;;Type 21 request received from Scheduler@node2.supernodexp.hpc, sock=16
05/04/2018 11:46:15;0100;Server@node2;Req;;Type 81 request received from Scheduler@node2.supernodexp.hpc, sock=16
05/04/2018 11:46:15;0100;Server@node2;Req;;Type 71 request received from Scheduler@node2.supernodexp.hpc, sock=16
05/04/2018 11:46:15;0100;Server@node2;Req;;Type 58 request received from Scheduler@node2.supernodexp.hpc, sock=16
05/04/2018 11:46:15;0100;Server@node2;Req;;Type 20 request received from Scheduler@node2.supernodexp.hpc, sock=16
05/04/2018 11:46:15;0100;Server@node2;Req;;Type 51 request received from Scheduler@node2.supernodexp.hpc, sock=16
05/04/2018 11:49:58;0080;Server@node2;Job;14916.node2.supernodexp.hpc;Obit received momhop:1 serverhop:1 state:4 substate:42
05/04/2018 11:49:59;0010;Server@node2;Job;14916.node2.supernodexp.hpc;Exit_status=0 resources_used.cpupercent=0 resources_used.cput=00:00:00 resources_used.mem=9596kb resources_used.ncpus=12 resources_used.vmem=106752kb resources_used.walltime=00:27:47
05/04/2018 11:49:59;0100;Server@node2;Job;14916.node2.supernodexp.hpc;dequeuing from workq, state 5
05/04/2018 11:49:59;0040;Server@node2;Svr;node2.supernodexp.hpc;Scheduler sent command 2
05/04/2018 11:49:59;0040;Server@node2;Svr;node2.supernodexp.hpc;Scheduler sent command 0
05/04/2018 11:49:59;0100;Server@node2;Req;;Type 21 request received from Scheduler@node2.supernodexp.hpc, sock=16
05/04/2018 11:49:59;0100;Server@node2;Req;;Type 81 request received from Scheduler@node2.supernodexp.hpc, sock=16
05/04/2018 11:49:59;0100;Server@node2;Req;;Type 71 request received from Scheduler@node2.supernodexp.hpc, sock=16
05/04/2018 11:49:59;0100;Server@node2;Req;;Type 58 request received from Scheduler@node2.supernodexp.hpc, sock=16
05/04/2018 11:49:59;0100;Server@node2;Req;;Type 20 request received from Scheduler@node2.supernodexp.hpc, sock=16
05/04/2018 11:49:59;0100;Server@node2;Req;;Type 51 request received from Scheduler@node2.supernodexp.hpc, sock=16
05/04/2018 11:49:59;0100;Server@node2;Req;;Type 23 request received from Scheduler@node2.supernodexp.hpc, sock=16
05/04/2018 11:49:59;0008;Server@node2;Job;15109.node2.supernodexp.hpc;Job Run at request of Scheduler@node2.supernodexp.hpc on exec_vnode (node3:ncpus=12:mem=20971520kb)
05/04/2018 11:49:59;0001;Server@node2;Svr;Server@node2;Success (0) in req_runjob2, return value of svr_startjob is 0
05/04/2018 11:49:59;0100;Server@node2;Req;;Type 11 request received from Scheduler@node2.supernodexp.hpc, sock=16
05/04/2018 11:49:59;0008;Server@node2;Job;15126.node2.supernodexp.hpc;Job Modified at request of Scheduler@node2.supernodexp.hpc
05/04/2018 11:55:01;0080;Server@node2;Job;14934.node2.supernodexp.hpc;Obit received momhop:1 serverhop:1 state:4 substate:42
05/04/2018 11:55:02;0010;Server@node2;Job;14934.node2.supernodexp.hpc;Exit_status=0 resources_used.cpupercent=0 resources_used.cput=00:00:00 resources_used.mem=9092kb resources_used.ncpus=12 resources_used.vmem=106752kb resources_used.walltime=00:27:30
05/04/2018 11:55:02;0100;Server@node2;Job;14934.node2.supernodexp.hpc;dequeuing from workq, state 5
05/04/2018 11:55:02;0040;Server@node2;Svr;node2.supernodexp.hpc;Scheduler sent command 2
05/04/2018 11:55:02;0040;Server@node2;Svr;node2.supernodexp.hpc;Scheduler sent command 0
05/04/2018 11:55:02;0100;Server@node2;Req;;Type 21 request received from Scheduler@node2.supernodexp.hpc, sock=16
05/04/2018 11:55:02;0100;Server@node2;Req;;Type 81 request received from Scheduler@node2.supernodexp.hpc, sock=16
05/04/2018 11:55:02;0100;Server@node2;Req;;Type 71 request received from Scheduler@node2.supernodexp.hpc, sock=16
05/04/2018 11:55:02;0100;Server@node2;Req;;Type 58 request received from Scheduler@node2.supernodexp.hpc, sock=16
05/04/2018 11:55:02;0100;Server@node2;Req;;Type 20 request received from Scheduler@node2.supernodexp.hpc, sock=16
05/04/2018 11:55:02;0100;Server@node2;Req;;Type 51 request received from Scheduler@node2.supernodexp.hpc, sock=16
05/04/2018 11:55:02;0100;Server@node2;Req;;Type 23 request received from Scheduler@node2.supernodexp.hpc, sock=16
05/04/2018 11:55:02;0008;Server@node2;Job;15126.node2.supernodexp.hpc;Job Run at request of Scheduler@node2.supernodexp.hpc on exec_vnode (node3:ncpus=12:mem=20971520kb)
05/04/2018 11:55:02;0001;Server@node2;Svr;Server@node2;Success (0) in req_runjob2, return value of svr_startjob is 0
05/04/2018 11:55:02;0100;Server@node2;Req;;Type 11 request received from Scheduler@node2.supernodexp.hpc, sock=16
05/04/2018 11:55:02;0008;Server@node2;Job;15161.node2.supernodexp.hpc;Job Modified at request of Scheduler@node2.supernodexp.hpc
05/04/2018 11:55:05;0080;Server@node2;Job;14932.node2.supernodexp.hpc;Obit received momhop:1 serverhop:1 state:4 substate:42
05/04/2018 11:55:06;0010;Server@node2;Job;14932.node2.supernodexp.hpc;Exit_status=0 resources_used.cpupercent=0 resources_used.cput=00:00:00 resources_used.mem=9704kb resources_used.ncpus=12 resources_used.vmem=170624kb resources_used.walltime=00:27:38
05/04/2018 11:55:06;0100;Server@node2;Job;14932.node2.supernodexp.hpc;dequeuing from workq, state 5
05/04/2018 11:55:06;0040;Server@node2;Svr;node2.supernodexp.hpc;Scheduler sent command 2
05/04/2018 11:55:06;0040;Server@node2;Svr;node2.supernodexp.hpc;Scheduler sent command 0
05/04/2018 11:55:06;0100;Server@node2;Req;;Type 21 request received from Scheduler@node2.supernodexp.hpc, sock=16
05/04/2018 11:55:06;0100;Server@node2;Req;;Type 81 request received from Scheduler@node2.supernodexp.hpc, sock=16
05/04/2018 11:55:06;0100;Server@node2;Req;;Type 71 request received from Scheduler@node2.supernodexp.hpc, sock=16
05/04/2018 11:55:06;0100;Server@node2;Req;;Type 58 request received from Scheduler@node2.supernodexp.hpc, sock=16
05/04/2018 11:55:06;0100;Server@node2;Req;;Type 20 request received from Scheduler@node2.supernodexp.hpc, sock=16
05/04/2018 11:55:06;0100;Server@node2;Req;;Type 51 request received from Scheduler@node2.supernodexp.hpc, sock=16
05/04/2018 11:55:06;0100;Server@node2;Req;;Type 23 request received from Scheduler@node2.supernodexp.hpc, sock=16
05/04/2018 11:55:06;0008;Server@node2;Job;15161.node2.supernodexp.hpc;Job Run at request of Scheduler@node2.supernodexp.hpc on exec_vnode (node3:ncpus=12:mem=20971520kb)
05/04/2018 11:55:06;0001;Server@node2;Svr;Server@node2;Success (0) in req_runjob2, return value of svr_startjob is 0
05/04/2018 11:55:06;0100;Server@node2;Req;;Type 11 request received from Scheduler@node2.supernodexp.hpc, sock=16
05/04/2018 11:55:06;0008;Server@node2;Job;15183.node2.supernodexp.hpc;Job Modified at request of Scheduler@node2.supernodexp.hpc
05/04/2018 11:55:39;0080;Server@node2;Job;14935.node2.supernodexp.hpc;Obit received momhop:1 serverhop:1 state:4 substate:42
05/04/2018 11:55:40;0010;Server@node2;Job;14935.node2.supernodexp.hpc;Exit_status=271 resources_used.cpupercent=0 resources_used.cput=00:00:00 resources_used.mem=9612kb resources_used.ncpus=12 resources_used.vmem=104444kb resources_used.walltime=00:27:45
05/04/2018 11:55:40;0100;Server@node2;Job;14935.node2.supernodexp.hpc;dequeuing from workq, state 5
05/04/2018 11:55:40;0040;Server@node2;Svr;node2.supernodexp.hpc;Scheduler sent command 2
05/04/2018 11:55:40;0040;Server@node2;Svr;node2.supernodexp.hpc;Scheduler sent command 0
05/04/2018 11:55:40;0100;Server@node2;Req;;Type 21 request received from Scheduler@node2.supernodexp.hpc, sock=16
05/04/2018 11:55:40;0100;Server@node2;Req;;Type 81 request received from Scheduler@node2.supernodexp.hpc, sock=16
05/04/2018 11:55:40;0100;Server@node2;Req;;Type 71 request received from Scheduler@node2.supernodexp.hpc, sock=16
05/04/2018 11:55:40;0100;Server@node2;Req;;Type 58 request received from Scheduler@node2.supernodexp.hpc, sock=16
05/04/2018 11:55:40;0100;Server@node2;Req;;Type 20 request received from Scheduler@node2.supernodexp.hpc, sock=16
05/04/2018 11:55:40;0100;Server@node2;Req;;Type 51 request received from Scheduler@node2.supernodexp.hpc, sock=16
05/04/2018 11:55:40;0100;Server@node2;Req;;Type 23 request received from Scheduler@node2.supernodexp.hpc, sock=16
05/04/2018 11:55:40;0008;Server@node2;Job;15183.node2.supernodexp.hpc;Job Run at request of Scheduler@node2.supernodexp.hpc on exec_vnode (node3:ncpus=12:mem=20971520kb)
05/04/2018 11:55:40;0001;Server@node2;Svr;Server@node2;Success (0) in req_runjob2, return value of svr_startjob is 0
05/04/2018 11:55:40;0100;Server@node2;Req;;Type 11 request received from Scheduler@node2.supernodexp.hpc, sock=16
05/04/2018 11:55:40;0008;Server@node2;Job;15195.node2.supernodexp.hpc;Job Modified at request of Scheduler@node2.supernodexp.hpc
05/04/2018 11:57:47;0080;Server@node2;Job;14939.node2.supernodexp.hpc;Obit received momhop:1 serverhop:1 state:4 substate:42
05/04/2018 11:57:49;0010;Server@node2;Job;14939.node2.supernodexp.hpc;Exit_status=271 resources_used.cpupercent=0 resources_used.cput=00:00:00 resources_used.mem=10084kb resources_used.ncpus=12 resources_used.vmem=940300kb resources_used.walltime=00:28:09
05/04/2018 11:57:49;0100;Server@node2;Job;14939.node2.supernodexp.hpc;dequeuing from workq, state 5
05/04/2018 11:57:49;0040;Server@node2;Svr;node2.supernodexp.hpc;Scheduler sent command 2
05/04/2018 11:57:49;0040;Server@node2;Svr;node2.supernodexp.hpc;Scheduler sent command 0
05/04/2018 11:57:49;0100;Server@node2;Req;;Type 21 request received from Scheduler@node2.supernodexp.hpc, sock=16
05/04/2018 11:57:49;0100;Server@node2;Req;;Type 81 request received from Scheduler@node2.supernodexp.hpc, sock=16
05/04/2018 11:57:49;0100;Server@node2;Req;;Type 71 request received from Scheduler@node2.supernodexp.hpc, sock=16
05/04/2018 11:57:49;0100;Server@node2;Req;;Type 58 request received from Scheduler@node2.supernodexp.hpc, sock=16
05/04/2018 11:57:49;0100;Server@node2;Req;;Type 20 request received from Scheduler@node2.supernodexp.hpc, sock=16
05/04/2018 11:57:49;0100;Server@node2;Req;;Type 51 request received from Scheduler@node2.supernodexp.hpc, sock=16
05/04/2018 11:57:49;0100;Server@node2;Req;;Type 23 request received from Scheduler@node2.supernodexp.hpc, sock=16
05/04/2018 11:57:49;0008;Server@node2;Job;15195.node2.supernodexp.hpc;Job Run at request of Scheduler@node2.supernodexp.hpc on exec_vnode (node13:ncpus=12:mem=20971520kb)
05/04/2018 11:57:49;0001;Server@node2;Svr;Server@node2;Success (0) in req_runjob2, return value of svr_startjob is 0
05/04/2018 11:57:49;0100;Server@node2;Req;;Type 11 request received from Scheduler@node2.supernodexp.hpc, sock=16
05/04/2018 11:57:49;0008;Server@node2;Job;15218.node2.supernodexp.hpc;Job Modified at request of Scheduler@node2.supernodexp.hpc
05/04/2018 11:58:37;0080;Server@node2;Job;15008.node2.supernodexp.hpc;Obit received momhop:1 serverhop:1 state:4 substate:42
05/04/2018 11:58:38;0010;Server@node2;Job;15008.node2.supernodexp.hpc;Exit_status=271 resources_used.cpupercent=0 resources_used.cput=00:00:00 resources_used.mem=10264kb resources_used.ncpus=12 resources_used.vmem=172216kb resources_used.walltime=00:27:57
05/04/2018 11:58:38;0100;Server@node2;Job;15008.node2.supernodexp.hpc;dequeuing from workq, state 5
05/04/2018 11:58:38;0040;Server@node2;Svr;node2.supernodexp.hpc;Scheduler sent command 2
05/04/2018 11:58:38;0040;Server@node2;Svr;node2.supernodexp.hpc;Scheduler sent command 0
05/04/2018 11:58:38;0100;Server@node2;Req;;Type 21 request received from Scheduler@node2.supernodexp.hpc, sock=16
05/04/2018 11:58:38;0100;Server@node2;Req;;Type 81 request received from Scheduler@node2.supernodexp.hpc, sock=16
05/04/2018 11:58:38;0100;Server@node2;Req;;Type 71 request received from Scheduler@node2.supernodexp.hpc, sock=16
05/04/2018 11:58:38;0100;Server@node2;Req;;Type 58 request received from Scheduler@node2.supernodexp.hpc, sock=16
05/04/2018 11:58:39;0100;Server@node2;Req;;Type 20 request received from Scheduler@node2.supernodexp.hpc, sock=16
05/04/2018 11:58:39;0100;Server@node2;Req;;Type 51 request received from Scheduler@node2.supernodexp.hpc, sock=16
05/04/2018 11:58:39;0100;Server@node2;Req;;Type 23 request received from Scheduler@node2.supernodexp.hpc, sock=16
05/04/2018 11:58:39;0008;Server@node2;Job;15218.node2.supernodexp.hpc;Job Run at request of Scheduler@node2.supernodexp.hpc on exec_vnode (node14:ncpus=12:mem=20971520kb)
05/04/2018 11:58:39;0001;Server@node2;Svr;Server@node2;Success (0) in req_runjob2, return value of svr_startjob is 0
05/04/2018 11:58:39;0100;Server@node2;Req;;Type 11 request received from Scheduler@node2.supernodexp.hpc, sock=16
05/04/2018 11:58:39;0008;Server@node2;Job;15251.node2.supernodexp.hpc;Job Modified at request of Scheduler@node2.supernodexp.hpc
05/04/2018 12:08:38;0040;Server@node2;Svr;node2.supernodexp.hpc;Scheduler sent command 3
05/04/2018 12:08:38;0040;Server@node2;Svr;node2.supernodexp.hpc;Scheduler sent command 0
05/04/2018 12:08:38;0100;Server@node2;Req;;Type 21 request received from Scheduler@node2.supernodexp.hpc, sock=16
05/04/2018 12:08:38;0100;Server@node2;Req;;Type 81 request received from Scheduler@node2.supernodexp.hpc, sock=16
05/04/2018 12:08:38;0100;Server@node2;Req;;Type 71 request received from Scheduler@node2.supernodexp.hpc, sock=16
05/04/2018 12:08:38;0100;Server@node2;Req;;Type 58 request received from Scheduler@node2.supernodexp.hpc, sock=16
05/04/2018 12:08:38;0100;Server@node2;Req;;Type 20 request received from Scheduler@node2.supernodexp.hpc, sock=16
05/04/2018 12:08:38;0100;Server@node2;Req;;Type 51 request received from Scheduler@node2.supernodexp.hpc, sock=16
05/04/2018 12:13:22;0080;Server@node2;Job;15022.node2.supernodexp.hpc;Obit received momhop:1 serverhop:1 state:4 substate:42
05/04/2018 12:13:23;0080;Server@node2;Job;15026.node2.supernodexp.hpc;Obit received momhop:1 serverhop:1 state:4 substate:42
05/04/2018 12:13:23;0080;Server@node2;Job;15030.node2.supernodexp.hpc;Obit received momhop:1 serverhop:1 state:4 substate:42
05/04/2018 12:13:25;0010;Server@node2;Job;15022.node2.supernodexp.hpc;Exit_status=271 resources_used.cpupercent=0 resources_used.cput=00:00:00 resources_used.mem=10196kb resources_used.ncpus=12 resources_used.vmem=104628kb resources_used.walltime=00:27:53
05/04/2018 12:13:25;0100;Server@node2;Job;15022.node2.supernodexp.hpc;dequeuing from workq, state 5
05/04/2018 12:13:25;0040;Server@node2;Svr;node2.supernodexp.hpc;Scheduler sent command 2
05/04/2018 12:13:25;0040;Server@node2;Svr;node2.supernodexp.hpc;Scheduler sent command 0
05/04/2018 12:13:25;0100;Server@node2;Req;;Type 21 request received from Scheduler@node2.supernodexp.hpc, sock=16
05/04/2018 12:13:25;0100;Server@node2;Req;;Type 81 request received from Scheduler@node2.supernodexp.hpc, sock=16
05/04/2018 12:13:25;0100;Server@node2;Req;;Type 71 request received from Scheduler@node2.supernodexp.hpc, sock=16
05/04/2018 12:13:25;0100;Server@node2;Req;;Type 58 request received from Scheduler@node2.supernodexp.hpc, sock=16
05/04/2018 12:13:25;0100;Server@node2;Req;;Type 20 request received from Scheduler@node2.supernodexp.hpc, sock=16
05/04/2018 12:13:25;0100;Server@node2;Req;;Type 51 request received from Scheduler@node2.supernodexp.hpc, sock=16
05/04/2018 12:13:25;0010;Server@node2;Job;15026.node2.supernodexp.hpc;Exit_status=271 resources_used.cpupercent=0 resources_used.cput=00:00:00 resources_used.mem=11912kb resources_used.ncpus=12 resources_used.vmem=743852kb resources_used.walltime=00:27:52
05/04/2018 12:13:25;0100;Server@node2;Job;15026.node2.supernodexp.hpc;dequeuing from workq, state 5
05/04/2018 12:13:25;0100;Server@node2;Req;;Type 23 request received from Scheduler@node2.supernodexp.hpc, sock=16
05/04/2018 12:13:25;0008;Server@node2;Job;15251.node2.supernodexp.hpc;Job Run at request of Scheduler@node2.supernodexp.hpc on exec_vnode (node14:ncpus=12:mem=20971520kb)
05/04/2018 12:13:25;0001;Server@node2;Svr;Server@node2;Success (0) in req_runjob2, return value of svr_startjob is 0
05/04/2018 12:13:25;0100;Server@node2;Req;;Type 11 request received from Scheduler@node2.supernodexp.hpc, sock=16
05/04/2018 12:13:25;0008;Server@node2;Job;15297.node2.supernodexp.hpc;Job Modified at request of Scheduler@node2.supernodexp.hpc
05/04/2018 12:13:25;0040;Server@node2;Svr;node2.supernodexp.hpc;Scheduler sent command 2
05/04/2018 12:13:25;0040;Server@node2;Svr;node2.supernodexp.hpc;Scheduler sent command 0
05/04/2018 12:13:25;0100;Server@node2;Req;;Type 21 request received from Scheduler@node2.supernodexp.hpc, sock=16
05/04/2018 12:13:25;0100;Server@node2;Req;;Type 81 request received from Scheduler@node2.supernodexp.hpc, sock=16
05/04/2018 12:13:25;0100;Server@node2;Req;;Type 71 request received from Scheduler@node2.supernodexp.hpc, sock=16
05/04/2018 12:13:25;0100;Server@node2;Req;;Type 58 request received from Scheduler@node2.supernodexp.hpc, sock=16
05/04/2018 12:13:25;0100;Server@node2;Req;;Type 20 request received from Scheduler@node2.supernodexp.hpc, sock=16
05/04/2018 12:13:25;0100;Server@node2;Req;;Type 51 request received from Scheduler@node2.supernodexp.hpc, sock=16
05/04/2018 12:13:25;0010;Server@node2;Job;15030.node2.supernodexp.hpc;Exit_status=271 resources_used.cpupercent=0 resources_used.cput=00:00:00 resources_used.mem=9856kb resources_used.ncpus=12 resources_used.vmem=173624kb resources_used.walltime=00:27:52
05/04/2018 12:13:25;0100;Server@node2;Job;15030.node2.supernodexp.hpc;dequeuing from workq, state 5
05/04/2018 12:13:25;0100;Server@node2;Req;;Type 23 request received from Scheduler@node2.supernodexp.hpc, sock=16
05/04/2018 12:13:25;0008;Server@node2;Job;15297.node2.supernodexp.hpc;Job Run at request of Scheduler@node2.supernodexp.hpc on exec_vnode (node14:ncpus=12:mem=20971520kb)
05/04/2018 12:13:25;0001;Server@node2;Svr;Server@node2;Success (0) in req_runjob2, return value of svr_startjob is 0
05/04/2018 12:13:25;0100;Server@node2;Req;;Type 11 request received from Scheduler@node2.supernodexp.hpc, sock=16
05/04/2018 12:13:25;0008;Server@node2;Job;15306.node2.supernodexp.hpc;Job Modified at request of Scheduler@node2.supernodexp.hpc
05/04/2018 12:13:25;0040;Server@node2;Svr;node2.supernodexp.hpc;Scheduler sent command 2
05/04/2018 12:13:25;0040;Server@node2;Svr;node2.supernodexp.hpc;Scheduler sent command 0
05/04/2018 12:13:25;0100;Server@node2;Req;;Type 21 request received from Scheduler@node2.supernodexp.hpc, sock=16
05/04/2018 12:13:25;0100;Server@node2;Req;;Type 81 request received from Scheduler@node2.supernodexp.hpc, sock=16
05/04/2018 12:13:25;0100;Server@node2;Req;;Type 71 request received from Scheduler@node2.supernodexp.hpc, sock=16
05/04/2018 12:13:25;0100;Server@node2;Req;;Type 58 request received from Scheduler@node2.supernodexp.hpc, sock=16
05/04/2018 12:13:25;0100;Server@node2;Req;;Type 20 request received from Scheduler@node2.supernodexp.hpc, sock=16
05/04/2018 12:13:25;0100;Server@node2;Req;;Type 51 request received from Scheduler@node2.supernodexp.hpc, sock=16
05/04/2018 12:13:25;0100;Server@node2;Req;;Type 23 request received from Scheduler@node2.supernodexp.hpc, sock=16
05/04/2018 12:13:25;0008;Server@node2;Job;15306.node2.supernodexp.hpc;Job Run at request of Scheduler@node2.supernodexp.hpc on exec_vnode (node14:ncpus=12:mem=20971520kb)
05/04/2018 12:13:25;0001;Server@node2;Svr;Server@node2;Success (0) in req_runjob2, return value of svr_startjob is 0
05/04/2018 12:13:25;0100;Server@node2;Req;;Type 11 request received from Scheduler@node2.supernodexp.hpc, sock=16
05/04/2018 12:13:25;0008;Server@node2;Job;15330.node2.supernodexp.hpc;Job Modified at request of Scheduler@node2.supernodexp.hpc
05/04/2018 12:14:21;0080;Server@node2;Job;15033.node2.supernodexp.hpc;Obit received momhop:1 serverhop:1 state:4 substate:42
05/04/2018 12:14:22;0080;Server@node2;Job;15044.node2.supernodexp.hpc;Obit received momhop:1 serverhop:1 state:4 substate:42
05/04/2018 12:14:22;0080;Server@node2;Job;15047.node2.supernodexp.hpc;Obit received momhop:1 serverhop:1 state:4 substate:42
05/04/2018 12:14:25;0010;Server@node2;Job;15044.node2.supernodexp.hpc;Exit_status=271 resources_used.cpupercent=0 resources_used.cput=00:00:00 resources_used.mem=10228kb resources_used.ncpus=12 resources_used.vmem=172216kb resources_used.walltime=00:28:07
05/04/2018 12:14:25;0100;Server@node2;Job;15044.node2.supernodexp.hpc;dequeuing from workq, state 5
05/04/2018 12:14:25;0040;Server@node2;Svr;node2.supernodexp.hpc;Scheduler sent command 2
05/04/2018 12:14:25;0040;Server@node2;Svr;node2.supernodexp.hpc;Scheduler sent command 0
05/04/2018 12:14:25;0100;Server@node2;Req;;Type 21 request received from Scheduler@node2.supernodexp.hpc, sock=16
05/04/2018 12:14:25;0100;Server@node2;Req;;Type 81 request received from Scheduler@node2.supernodexp.hpc, sock=16
05/04/2018 12:14:25;0100;Server@node2;Req;;Type 71 request received from Scheduler@node2.supernodexp.hpc, sock=16
05/04/2018 12:14:25;0100;Server@node2;Req;;Type 58 request received from Scheduler@node2.supernodexp.hpc, sock=16
05/04/2018 12:14:25;0100;Server@node2;Req;;Type 20 request received from Scheduler@node2.supernodexp.hpc, sock=16
05/04/2018 12:14:25;0100;Server@node2;Req;;Type 51 request received from Scheduler@node2.supernodexp.hpc, sock=16
05/04/2018 12:14:25;0010;Server@node2;Job;15047.node2.supernodexp.hpc;Exit_status=271 resources_used.cpupercent=0 resources_used.cput=00:00:00 resources_used.mem=9620kb resources_used.ncpus=12 resources_used.vmem=1082048kb resources_used.walltime=00:28:07
05/04/2018 12:14:25;0100;Server@node2;Job;15047.node2.supernodexp.hpc;dequeuing from workq, state 5
05/04/2018 12:14:25;0100;Server@node2;Req;;Type 23 request received from Scheduler@node2.supernodexp.hpc, sock=16
05/04/2018 12:14:25;0008;Server@node2;Job;15330.node2.supernodexp.hpc;Job Run at request of Scheduler@node2.supernodexp.hpc on exec_vnode (node13:ncpus=12:mem=20971520kb)
05/04/2018 12:14:25;0001;Server@node2;Svr;Server@node2;Success (0) in req_runjob2, return value of svr_startjob is 0
05/04/2018 12:14:25;0100;Server@node2;Req;;Type 11 request received from Scheduler@node2.supernodexp.hpc, sock=16
05/04/2018 12:14:25;0008;Server@node2;Job;15355.node2.supernodexp.hpc;Job Modified at request of Scheduler@node2.supernodexp.hpc
05/04/2018 12:14:25;0040;Server@node2;Svr;node2.supernodexp.hpc;Scheduler sent command 2
05/04/2018 12:14:25;0040;Server@node2;Svr;node2.supernodexp.hpc;Scheduler sent command 0
05/04/2018 12:14:25;0100;Server@node2;Req;;Type 21 request received from Scheduler@node2.supernodexp.hpc, sock=16
05/04/2018 12:14:25;0100;Server@node2;Req;;Type 81 request received from Scheduler@node2.supernodexp.hpc, sock=16
05/04/2018 12:14:25;0100;Server@node2;Req;;Type 71 request received from Scheduler@node2.supernodexp.hpc, sock=16
05/04/2018 12:14:25;0100;Server@node2;Req;;Type 58 request received from Scheduler@node2.supernodexp.hpc, sock=16
05/04/2018 12:14:25;0010;Server@node2;Job;15033.node2.supernodexp.hpc;Exit_status=271 resources_used.cpupercent=0 resources_used.cput=00:00:00 resources_used.mem=10248kb resources_used.ncpus=12 resources_used.vmem=237752kb resources_used.walltime=00:28:07
05/04/2018 12:14:25;0100;Server@node2;Job;15033.node2.supernodexp.hpc;dequeuing from workq, state 5
05/04/2018 12:14:25;0100;Server@node2;Req;;Type 20 request received from Scheduler@node2.supernodexp.hpc, sock=16
05/04/2018 12:14:25;0100;Server@node2;Req;;Type 51 request received from Scheduler@node2.supernodexp.hpc, sock=16
05/04/2018 12:14:25;0100;Server@node2;Req;;Type 23 request received from Scheduler@node2.supernodexp.hpc, sock=16
05/04/2018 12:14:25;0008;Server@node2;Job;15355.node2.supernodexp.hpc;Job Run at request of Scheduler@node2.supernodexp.hpc on exec_vnode (node13:ncpus=12:mem=20971520kb)
05/04/2018 12:14:25;0001;Server@node2;Svr;Server@node2;Success (0) in req_runjob2, return value of svr_startjob is 0
05/04/2018 12:14:25;0100;Server@node2;Req;;Type 23 request received from Scheduler@node2.supernodexp.hpc, sock=16
05/04/2018 12:14:25;0008;Server@node2;Job;15356.node2.supernodexp.hpc;Job Run at request of Scheduler@node2.supernodexp.hpc on exec_vnode (node13:ncpus=12:mem=20971520kb)
05/04/2018 12:14:25;0001;Server@node2;Svr;Server@node2;Success (0) in req_runjob2, return value of svr_startjob is 0
05/04/2018 12:14:25;0100;Server@node2;Req;;Type 11 request received from Scheduler@node2.supernodexp.hpc, sock=16
05/04/2018 12:14:25;0008;Server@node2;Job;15373.node2.supernodexp.hpc;Job Modified at request of Scheduler@node2.supernodexp.hpc
05/04/2018 12:14:25;0040;Server@node2;Svr;node2.supernodexp.hpc;Scheduler sent command 2
05/04/2018 12:14:25;0040;Server@node2;Svr;node2.supernodexp.hpc;Scheduler sent command 0
05/04/2018 12:14:25;0100;Server@node2;Req;;Type 21 request received from Scheduler@node2.supernodexp.hpc, sock=16
05/04/2018 12:14:25;0100;Server@node2;Req;;Type 81 request received from Scheduler@node2.supernodexp.hpc, sock=16
05/04/2018 12:14:25;0100;Server@node2;Req;;Type 71 request received from Scheduler@node2.supernodexp.hpc, sock=16
05/04/2018 12:14:25;0100;Server@node2;Req;;Type 58 request received from Scheduler@node2.supernodexp.hpc, sock=16
05/04/2018 12:14:25;0100;Server@node2;Req;;Type 20 request received from Scheduler@node2.supernodexp.hpc, sock=16
05/04/2018 12:14:25;0100;Server@node2;Req;;Type 51 request received from Scheduler@node2.supernodexp.hpc, sock=16
05/04/2018 12:18:05;0080;Server@node2;Job;15109.node2.supernodexp.hpc;Obit received momhop:1 serverhop:1 state:4 substate:42
05/04/2018 12:18:07;0010;Server@node2;Job;15109.node2.supernodexp.hpc;Exit_status=271 resources_used.cpupercent=0 resources_used.cput=00:00:00 resources_used.mem=9636kb resources_used.ncpus=12 resources_used.vmem=106752kb resources_used.walltime=00:28:06
05/04/2018 12:18:07;0100;Server@node2;Job;15109.node2.supernodexp.hpc;dequeuing from workq, state 5
05/04/2018 12:18:07;0040;Server@node2;Svr;node2.supernodexp.hpc;Scheduler sent command 2
05/04/2018 12:18:07;0040;Server@node2;Svr;node2.supernodexp.hpc;Scheduler sent command 0
05/04/2018 12:18:07;0100;Server@node2;Req;;Type 21 request received from Scheduler@node2.supernodexp.hpc, sock=16
05/04/2018 12:18:07;0100;Server@node2;Req;;Type 81 request received from Scheduler@node2.supernodexp.hpc, sock=16
05/04/2018 12:18:07;0100;Server@node2;Req;;Type 71 request received from Scheduler@node2.supernodexp.hpc, sock=16
05/04/2018 12:18:07;0100;Server@node2;Req;;Type 58 request received from Scheduler@node2.supernodexp.hpc, sock=16
05/04/2018 12:18:07;0100;Server@node2;Req;;Type 20 request received from Scheduler@node2.supernodexp.hpc, sock=16
05/04/2018 12:18:07;0100;Server@node2;Req;;Type 51 request received from Scheduler@node2.supernodexp.hpc, sock=16
05/04/2018 12:18:07;0100;Server@node2;Req;;Type 23 request received from Scheduler@node2.supernodexp.hpc, sock=16
05/04/2018 12:18:07;0008;Server@node2;Job;15373.node2.supernodexp.hpc;Job Run at request of Scheduler@node2.supernodexp.hpc on exec_vnode (node3:ncpus=12:mem=20971520kb)
05/04/2018 12:18:07;0001;Server@node2;Svr;Server@node2;Success (0) in req_runjob2, return value of svr_startjob is 0
05/04/2018 12:18:07;0100;Server@node2;Req;;Type 11 request received from Scheduler@node2.supernodexp.hpc, sock=16
05/04/2018 12:18:07;0008;Server@node2;Job;15410.node2.supernodexp.hpc;Job Modified at request of Scheduler@node2.supernodexp.hpc
05/04/2018 12:23:04;0080;Server@node2;Job;15161.node2.supernodexp.hpc;Obit received momhop:1 serverhop:1 state:4 substate:42
05/04/2018 12:23:05;0010;Server@node2;Job;15161.node2.supernodexp.hpc;Exit_status=0 resources_used.cpupercent=0 resources_used.cput=00:00:00 resources_used.mem=9108kb resources_used.ncpus=12 resources_used.vmem=105088kb resources_used.walltime=00:27:58
05/04/2018 12:23:05;0100;Server@node2;Job;15161.node2.supernodexp.hpc;dequeuing from workq, state 5
05/04/2018 12:23:05;0040;Server@node2;Svr;node2.supernodexp.hpc;Scheduler sent command 2
05/04/2018 12:23:05;0040;Server@node2;Svr;node2.supernodexp.hpc;Scheduler sent command 0
05/04/2018 12:23:05;0100;Server@node2;Req;;Type 21 request received from Scheduler@node2.supernodexp.hpc, sock=16
05/04/2018 12:23:05;0100;Server@node2;Req;;Type 81 request received from Scheduler@node2.supernodexp.hpc, sock=16
05/04/2018 12:23:05;0100;Server@node2;Req;;Type 71 request received from Scheduler@node2.supernodexp.hpc, sock=16
05/04/2018 12:23:05;0100;Server@node2;Req;;Type 58 request received from Scheduler@node2.supernodexp.hpc, sock=16
05/04/2018 12:23:05;0100;Server@node2;Req;;Type 20 request received from Scheduler@node2.supernodexp.hpc, sock=16
05/04/2018 12:23:05;0100;Server@node2;Req;;Type 51 request received from Scheduler@node2.supernodexp.hpc, sock=16
05/04/2018 12:23:05;0100;Server@node2;Req;;Type 23 request received from Scheduler@node2.supernodexp.hpc, sock=16
05/04/2018 12:23:05;0008;Server@node2;Job;15410.node2.supernodexp.hpc;Job Run at request of Scheduler@node2.supernodexp.hpc on exec_vnode (node3:ncpus=12:mem=20971520kb)
05/04/2018 12:23:05;0001;Server@node2;Svr;Server@node2;Success (0) in req_runjob2, return value of svr_startjob is 0
05/04/2018 12:23:05;0100;Server@node2;Req;;Type 11 request received from Scheduler@node2.supernodexp.hpc, sock=16
05/04/2018 12:23:05;0008;Server@node2;Job;15426.node2.supernodexp.hpc;Job Modified at request of Scheduler@node2.supernodexp.hpc
05/04/2018 12:23:21;0080;Server@node2;Job;15126.node2.supernodexp.hpc;Obit received momhop:1 serverhop:1 state:4 substate:42
05/04/2018 12:23:22;0010;Server@node2;Job;15126.node2.supernodexp.hpc;Exit_status=271 resources_used.cpupercent=0 resources_used.cput=00:00:00 resources_used.mem=9432kb resources_used.ncpus=12 resources_used.vmem=105088kb resources_used.walltime=00:28:19
05/04/2018 12:23:22;0100;Server@node2;Job;15126.node2.supernodexp.hpc;dequeuing from workq, state 5
05/04/2018 12:23:22;0040;Server@node2;Svr;node2.supernodexp.hpc;Scheduler sent command 2
05/04/2018 12:23:22;0040;Server@node2;Svr;node2.supernodexp.hpc;Scheduler sent command 0
05/04/2018 12:23:22;0100;Server@node2;Req;;Type 21 request received from Scheduler@node2.supernodexp.hpc, sock=16
05/04/2018 12:23:22;0100;Server@node2;Req;;Type 81 request received from Scheduler@node2.supernodexp.hpc, sock=16
05/04/2018 12:23:22;0100;Server@node2;Req;;Type 71 request received from Scheduler@node2.supernodexp.hpc, sock=16
05/04/2018 12:23:22;0100;Server@node2;Req;;Type 58 request received from Scheduler@node2.supernodexp.hpc, sock=16
05/04/2018 12:23:22;0100;Server@node2;Req;;Type 20 request received from Scheduler@node2.supernodexp.hpc, sock=16
05/04/2018 12:23:22;0100;Server@node2;Req;;Type 51 request received from Scheduler@node2.supernodexp.hpc, sock=16
05/04/2018 12:23:22;0100;Server@node2;Req;;Type 23 request received from Scheduler@node2.supernodexp.hpc, sock=16
05/04/2018 12:23:22;0008;Server@node2;Job;15426.node2.supernodexp.hpc;Job Run at request of Scheduler@node2.supernodexp.hpc on exec_vnode (node3:ncpus=12:mem=20971520kb)
05/04/2018 12:23:22;0001;Server@node2;Svr;Server@node2;Success (0) in req_runjob2, return value of svr_startjob is 0
05/04/2018 12:23:22;0100;Server@node2;Req;;Type 11 request received from Scheduler@node2.supernodexp.hpc, sock=16
05/04/2018 12:23:22;0008;Server@node2;Job;15468.node2.supernodexp.hpc;Job Modified at request of Scheduler@node2.supernodexp.hpc
05/04/2018 12:23:29;0080;Server@node2;Job;15183.node2.supernodexp.hpc;Obit received momhop:1 serverhop:1 state:4 substate:42
05/04/2018 12:23:30;0010;Server@node2;Job;15183.node2.supernodexp.hpc;Exit_status=0 resources_used.cpupercent=0 resources_used.cput=00:00:00 resources_used.mem=9092kb resources_used.ncpus=12 resources_used.vmem=104444kb resources_used.walltime=00:27:48
05/04/2018 12:23:30;0100;Server@node2;Job;15183.node2.supernodexp.hpc;dequeuing from workq, state 5
05/04/2018 12:23:30;0040;Server@node2;Svr;node2.supernodexp.hpc;Scheduler sent command 2
05/04/2018 12:23:30;0040;Server@node2;Svr;node2.supernodexp.hpc;Scheduler sent command 0
05/04/2018 12:23:30;0100;Server@node2;Req;;Type 21 request received from Scheduler@node2.supernodexp.hpc, sock=16
05/04/2018 12:23:30;0100;Server@node2;Req;;Type 81 request received from Scheduler@node2.supernodexp.hpc, sock=16
05/04/2018 12:23:30;0100;Server@node2;Req;;Type 71 request received from Scheduler@node2.supernodexp.hpc, sock=16
05/04/2018 12:23:30;0100;Server@node2;Req;;Type 58 request received from Scheduler@node2.supernodexp.hpc, sock=16
05/04/2018 12:23:30;0100;Server@node2;Req;;Type 20 request received from Scheduler@node2.supernodexp.hpc, sock=16
05/04/2018 12:23:30;0100;Server@node2;Req;;Type 51 request received from Scheduler@node2.supernodexp.hpc, sock=16
05/04/2018 12:23:30;0100;Server@node2;Req;;Type 23 request received from Scheduler@node2.supernodexp.hpc, sock=16
05/04/2018 12:23:30;0008;Server@node2;Job;15468.node2.supernodexp.hpc;Job Run at request of Scheduler@node2.supernodexp.hpc on exec_vnode (node3:ncpus=12:mem=20971520kb)
05/04/2018 12:23:30;0001;Server@node2;Svr;Server@node2;Success (0) in req_runjob2, return value of svr_startjob is 0
05/04/2018 12:23:30;0100;Server@node2;Req;;Type 11 request received from Scheduler@node2.supernodexp.hpc, sock=16
05/04/2018 12:23:30;0008;Server@node2;Job;15469.node2.supernodexp.hpc;Job Modified at request of Scheduler@node2.supernodexp.hpc
05/04/2018 12:25:59;0080;Server@node2;Job;15195.node2.supernodexp.hpc;Obit received momhop:1 serverhop:1 state:4 substate:42
05/04/2018 12:26:01;0010;Server@node2;Job;15195.node2.supernodexp.hpc;Exit_status=271 resources_used.cpupercent=0 resources_used.cput=00:00:00 resources_used.mem=10232kb resources_used.ncpus=12 resources_used.vmem=108088kb resources_used.walltime=00:28:09
05/04/2018 12:26:01;0100;Server@node2;Job;15195.node2.supernodexp.hpc;dequeuing from workq, state 5
05/04/2018 12:26:01;0040;Server@node2;Svr;node2.supernodexp.hpc;Scheduler sent command 2
05/04/2018 12:26:01;0040;Server@node2;Svr;node2.supernodexp.hpc;Scheduler sent command 0
05/04/2018 12:26:01;0100;Server@node2;Req;;Type 21 request received from Scheduler@node2.supernodexp.hpc, sock=16
05/04/2018 12:26:01;0100;Server@node2;Req;;Type 81 request received from Scheduler@node2.supernodexp.hpc, sock=16
05/04/2018 12:26:01;0100;Server@node2;Req;;Type 71 request received from Scheduler@node2.supernodexp.hpc, sock=16
05/04/2018 12:26:01;0100;Server@node2;Req;;Type 58 request received from Scheduler@node2.supernodexp.hpc, sock=16
05/04/2018 12:26:01;0100;Server@node2;Req;;Type 20 request received from Scheduler@node2.supernodexp.hpc, sock=16
05/04/2018 12:26:01;0100;Server@node2;Req;;Type 51 request received from Scheduler@node2.supernodexp.hpc, sock=16
05/04/2018 12:26:01;0100;Server@node2;Req;;Type 23 request received from Scheduler@node2.supernodexp.hpc, sock=16
05/04/2018 12:26:01;0008;Server@node2;Job;15469.node2.supernodexp.hpc;Job Run at request of Scheduler@node2.supernodexp.hpc on exec_vnode (node13:ncpus=12:mem=20971520kb)
05/04/2018 12:26:01;0001;Server@node2;Svr;Server@node2;Success (0) in req_runjob2, return value of svr_startjob is 0
05/04/2018 12:26:01;0100;Server@node2;Req;;Type 11 request received from Scheduler@node2.supernodexp.hpc, sock=16
05/04/2018 12:26:01;0008;Server@node2;Job;15510.node2.supernodexp.hpc;Job Modified at request of Scheduler@node2.supernodexp.hpc
05/04/2018 12:26:32;0080;Server@node2;Job;15218.node2.supernodexp.hpc;Obit received momhop:1 serverhop:1 state:4 substate:42
05/04/2018 12:26:34;0010;Server@node2;Job;15218.node2.supernodexp.hpc;Exit_status=271 resources_used.cpupercent=0 resources_used.cput=00:00:00 resources_used.mem=9996kb resources_used.ncpus=12 resources_used.vmem=173368kb resources_used.walltime=00:27:54
05/04/2018 12:26:34;0100;Server@node2;Job;15218.node2.supernodexp.hpc;dequeuing from workq, state 5
05/04/2018 12:26:34;0040;Server@node2;Svr;node2.supernodexp.hpc;Scheduler sent command 2
05/04/2018 12:26:34;0040;Server@node2;Svr;node2.supernodexp.hpc;Scheduler sent command 0
05/04/2018 12:26:34;0100;Server@node2;Req;;Type 21 request received from Scheduler@node2.supernodexp.hpc, sock=16
05/04/2018 12:26:34;0100;Server@node2;Req;;Type 81 request received from Scheduler@node2.supernodexp.hpc, sock=16
05/04/2018 12:26:34;0100;Server@node2;Req;;Type 71 request received from Scheduler@node2.supernodexp.hpc, sock=16
05/04/2018 12:26:34;0100;Server@node2;Req;;Type 58 request received from Scheduler@node2.supernodexp.hpc, sock=16
05/04/2018 12:26:34;0100;Server@node2;Req;;Type 20 request received from Scheduler@node2.supernodexp.hpc, sock=16
05/04/2018 12:26:34;0100;Server@node2;Req;;Type 51 request received from Scheduler@node2.supernodexp.hpc, sock=16
05/04/2018 12:26:34;0100;Server@node2;Req;;Type 23 request received from Scheduler@node2.supernodexp.hpc, sock=16
05/04/2018 12:26:34;0008;Server@node2;Job;15510.node2.supernodexp.hpc;Job Run at request of Scheduler@node2.supernodexp.hpc on exec_vnode (node14:ncpus=12:mem=20971520kb)
05/04/2018 12:26:34;0001;Server@node2;Svr;Server@node2;Success (0) in req_runjob2, return value of svr_startjob is 0
05/04/2018 12:26:34;0100;Server@node2;Req;;Type 11 request received from Scheduler@node2.supernodexp.hpc, sock=16
05/04/2018 12:26:34;0008;Server@node2;Job;15521.node2.supernodexp.hpc;Job Modified at request of Scheduler@node2.supernodexp.hpc
05/04/2018 12:36:34;0040;Server@node2;Svr;node2.supernodexp.hpc;Scheduler sent command 3
05/04/2018 12:36:34;0040;Server@node2;Svr;node2.supernodexp.hpc;Scheduler sent command 0
05/04/2018 12:36:34;0100;Server@node2;Req;;Type 21 request received from Scheduler@node2.supernodexp.hpc, sock=16
05/04/2018 12:36:34;0100;Server@node2;Req;;Type 81 request received from Scheduler@node2.supernodexp.hpc, sock=16
05/04/2018 12:36:34;0100;Server@node2;Req;;Type 71 request received from Scheduler@node2.supernodexp.hpc, sock=16
05/04/2018 12:36:34;0100;Server@node2;Req;;Type 58 request received from Scheduler@node2.supernodexp.hpc, sock=16
05/04/2018 12:36:34;0100;Server@node2;Req;;Type 20 request received from Scheduler@node2.supernodexp.hpc, sock=16
05/04/2018 12:36:34;0100;Server@node2;Req;;Type 51 request received from Scheduler@node2.supernodexp.hpc, sock=16
05/04/2018 12:41:19;0080;Server@node2;Job;15251.node2.supernodexp.hpc;Obit received momhop:1 serverhop:1 state:4 substate:42
05/04/2018 12:41:19;0080;Server@node2;Job;15297.node2.supernodexp.hpc;Obit received momhop:1 serverhop:1 state:4 substate:42
05/04/2018 12:41:19;0080;Server@node2;Job;15306.node2.supernodexp.hpc;Obit received momhop:1 serverhop:1 state:4 substate:42
05/04/2018 12:41:21;0010;Server@node2;Job;15306.node2.supernodexp.hpc;Exit_status=271 resources_used.cpupercent=0 resources_used.cput=00:00:00 resources_used.mem=10252kb resources_used.ncpus=12 resources_used.vmem=173624kb resources_used.walltime=00:27:54
05/04/2018 12:41:21;0100;Server@node2;Job;15306.node2.supernodexp.hpc;dequeuing from workq, state 5
05/04/2018 12:41:21;0040;Server@node2;Svr;node2.supernodexp.hpc;Scheduler sent command 2
05/04/2018 12:41:21;0040;Server@node2;Svr;node2.supernodexp.hpc;Scheduler sent command 0
05/04/2018 12:41:21;0100;Server@node2;Req;;Type 21 request received from Scheduler@node2.supernodexp.hpc, sock=16
05/04/2018 12:41:21;0100;Server@node2;Req;;Type 81 request received from Scheduler@node2.supernodexp.hpc, sock=16
05/04/2018 12:41:21;0100;Server@node2;Req;;Type 71 request received from Scheduler@node2.supernodexp.hpc, sock=16
05/04/2018 12:41:21;0100;Server@node2;Req;;Type 58 request received from Scheduler@node2.supernodexp.hpc, sock=16
05/04/2018 12:41:21;0100;Server@node2;Req;;Type 20 request received from Scheduler@node2.supernodexp.hpc, sock=16
05/04/2018 12:41:21;0100;Server@node2;Req;;Type 51 request received from Scheduler@node2.supernodexp.hpc, sock=16
05/04/2018 12:41:21;0010;Server@node2;Job;15251.node2.supernodexp.hpc;Exit_status=271 resources_used.cpupercent=0 resources_used.cput=00:00:00 resources_used.mem=9984kb resources_used.ncpus=12 resources_used.vmem=171572kb resources_used.walltime=00:27:55
05/04/2018 12:41:21;0100;Server@node2;Job;15251.node2.supernodexp.hpc;dequeuing from workq, state 5
05/04/2018 12:41:21;0100;Server@node2;Req;;Type 23 request received from Scheduler@node2.supernodexp.hpc, sock=16
05/04/2018 12:41:21;0008;Server@node2;Job;15521.node2.supernodexp.hpc;Job Run at request of Scheduler@node2.supernodexp.hpc on exec_vnode (node14:ncpus=12:mem=20971520kb)
05/04/2018 12:41:21;0001;Server@node2;Svr;Server@node2;Success (0) in req_runjob2, return value of svr_startjob is 0
05/04/2018 12:41:21;0010;Server@node2;Job;15297.node2.supernodexp.hpc;Exit_status=271 resources_used.cpupercent=0 resources_used.cput=00:00:00 resources_used.mem=9992kb resources_used.ncpus=12 resources_used.vmem=172216kb resources_used.walltime=00:27:54
05/04/2018 12:41:21;0100;Server@node2;Job;15297.node2.supernodexp.hpc;dequeuing from workq, state 5
05/04/2018 12:41:21;0100;Server@node2;Req;;Type 11 request received from Scheduler@node2.supernodexp.hpc, sock=16
05/04/2018 12:41:21;0008;Server@node2;Job;15524.node2.supernodexp.hpc;Job Modified at request of Scheduler@node2.supernodexp.hpc
05/04/2018 12:41:21;0040;Server@node2;Svr;node2.supernodexp.hpc;Scheduler sent command 2
05/04/2018 12:41:21;0040;Server@node2;Svr;node2.supernodexp.hpc;Scheduler sent command 0
05/04/2018 12:41:21;0100;Server@node2;Req;;Type 21 request received from Scheduler@node2.supernodexp.hpc, sock=16
05/04/2018 12:41:21;0100;Server@node2;Req;;Type 81 request received from Scheduler@node2.supernodexp.hpc, sock=16
05/04/2018 12:41:21;0100;Server@node2;Req;;Type 71 request received from Scheduler@node2.supernodexp.hpc, sock=16
05/04/2018 12:41:21;0100;Server@node2;Req;;Type 58 request received from Scheduler@node2.supernodexp.hpc, sock=16
05/04/2018 12:41:21;0100;Server@node2;Req;;Type 20 request received from Scheduler@node2.supernodexp.hpc, sock=16
05/04/2018 12:41:21;0100;Server@node2;Req;;Type 51 request received from Scheduler@node2.supernodexp.hpc, sock=16
05/04/2018 12:41:21;0100;Server@node2;Req;;Type 23 request received from Scheduler@node2.supernodexp.hpc, sock=16
05/04/2018 12:41:21;0008;Server@node2;Job;15524.node2.supernodexp.hpc;Job Run at request of Scheduler@node2.supernodexp.hpc on exec_vnode (node14:ncpus=12:mem=20971520kb)
05/04/2018 12:41:21;0001;Server@node2;Svr;Server@node2;Success (0) in req_runjob2, return value of svr_startjob is 0
05/04/2018 12:41:21;0100;Server@node2;Req;;Type 23 request received from Scheduler@node2.supernodexp.hpc, sock=16
05/04/2018 12:41:21;0008;Server@node2;Job;15534.node2.supernodexp.hpc;Job Run at request of Scheduler@node2.supernodexp.hpc on exec_vnode (node14:ncpus=12:mem=20971520kb)
05/04/2018 12:41:21;0001;Server@node2;Svr;Server@node2;Success (0) in req_runjob2, return value of svr_startjob is 0
05/04/2018 12:41:21;0100;Server@node2;Req;;Type 11 request received from Scheduler@node2.supernodexp.hpc, sock=16
05/04/2018 12:41:21;0008;Server@node2;Job;15555.node2.supernodexp.hpc;Job Modified at request of Scheduler@node2.supernodexp.hpc
05/04/2018 12:42:36;0080;Server@node2;Job;15330.node2.supernodexp.hpc;Obit received momhop:1 serverhop:1 state:4 substate:42
05/04/2018 12:42:36;0080;Server@node2;Job;15355.node2.supernodexp.hpc;Obit received momhop:1 serverhop:1 state:4 substate:42
05/04/2018 12:42:36;0080;Server@node2;Job;15356.node2.supernodexp.hpc;Obit received momhop:1 serverhop:1 state:4 substate:42
05/04/2018 12:42:39;0010;Server@node2;Job;15330.node2.supernodexp.hpc;Exit_status=271 resources_used.cpupercent=0 resources_used.cput=00:00:00 resources_used.mem=9912kb resources_used.ncpus=12 resources_used.vmem=1153352kb resources_used.walltime=00:28:11
05/04/2018 12:42:39;0100;Server@node2;Job;15330.node2.supernodexp.hpc;dequeuing from workq, state 5
05/04/2018 12:42:39;0040;Server@node2;Svr;node2.supernodexp.hpc;Scheduler sent command 2
05/04/2018 12:42:39;0040;Server@node2;Svr;node2.supernodexp.hpc;Scheduler sent command 0
05/04/2018 12:42:39;0100;Server@node2;Req;;Type 21 request received from Scheduler@node2.supernodexp.hpc, sock=16
05/04/2018 12:42:39;0100;Server@node2;Req;;Type 81 request received from Scheduler@node2.supernodexp.hpc, sock=16
05/04/2018 12:42:39;0100;Server@node2;Req;;Type 71 request received from Scheduler@node2.supernodexp.hpc, sock=16
05/04/2018 12:42:39;0100;Server@node2;Req;;Type 58 request received from Scheduler@node2.supernodexp.hpc, sock=16
05/04/2018 12:42:39;0100;Server@node2;Req;;Type 20 request received from Scheduler@node2.supernodexp.hpc, sock=16
05/04/2018 12:42:39;0100;Server@node2;Req;;Type 51 request received from Scheduler@node2.supernodexp.hpc, sock=16
05/04/2018 12:42:39;0100;Server@node2;Req;;Type 23 request received from Scheduler@node2.supernodexp.hpc, sock=16
05/04/2018 12:42:39;0008;Server@node2;Job;15555.node2.supernodexp.hpc;Job Run at request of Scheduler@node2.supernodexp.hpc on exec_vnode (node13:ncpus=12:mem=20971520kb)
05/04/2018 12:42:39;0001;Server@node2;Svr;Server@node2;Success (0) in req_runjob2, return value of svr_startjob is 0
05/04/2018 12:42:39;0100;Server@node2;Req;;Type 11 request received from Scheduler@node2.supernodexp.hpc, sock=16
05/04/2018 12:42:39;0008;Server@node2;Job;15556.node2.supernodexp.hpc;Job Modified at request of Scheduler@node2.supernodexp.hpc
05/04/2018 12:42:39;0010;Server@node2;Job;15355.node2.supernodexp.hpc;Exit_status=271 resources_used.cpupercent=0 resources_used.cput=00:00:00 resources_used.mem=10280kb resources_used.ncpus=12 resources_used.vmem=171316kb resources_used.walltime=00:28:11
05/04/2018 12:42:39;0100;Server@node2;Job;15355.node2.supernodexp.hpc;dequeuing from workq, state 5
05/04/2018 12:42:39;0040;Server@node2;Svr;node2.supernodexp.hpc;Scheduler sent command 2
05/04/2018 12:42:39;0040;Server@node2;Svr;node2.supernodexp.hpc;Scheduler sent command 0
05/04/2018 12:42:39;0100;Server@node2;Req;;Type 21 request received from Scheduler@node2.supernodexp.hpc, sock=16
05/04/2018 12:42:39;0100;Server@node2;Req;;Type 81 request received from Scheduler@node2.supernodexp.hpc, sock=16
05/04/2018 12:42:39;0100;Server@node2;Req;;Type 71 request received from Scheduler@node2.supernodexp.hpc, sock=16
05/04/2018 12:42:39;0100;Server@node2;Req;;Type 58 request received from Scheduler@node2.supernodexp.hpc, sock=16
05/04/2018 12:42:39;0100;Server@node2;Req;;Type 20 request received from Scheduler@node2.supernodexp.hpc, sock=16
05/04/2018 12:42:39;0100;Server@node2;Req;;Type 51 request received from Scheduler@node2.supernodexp.hpc, sock=16
05/04/2018 12:42:39;0010;Server@node2;Job;15356.node2.supernodexp.hpc;Exit_status=271 resources_used.cpupercent=0 resources_used.cput=00:00:00 resources_used.mem=9592kb resources_used.ncpus=12 resources_used.vmem=949436kb resources_used.walltime=00:28:11
05/04/2018 12:42:39;0100;Server@node2;Job;15356.node2.supernodexp.hpc;dequeuing from workq, state 5
05/04/2018 12:42:39;0100;Server@node2;Req;;Type 23 request received from Scheduler@node2.supernodexp.hpc, sock=16
05/04/2018 12:42:39;0008;Server@node2;Job;15556.node2.supernodexp.hpc;Job Run at request of Scheduler@node2.supernodexp.hpc on exec_vnode (node13:ncpus=12:mem=20971520kb)
05/04/2018 12:42:39;0001;Server@node2;Svr;Server@node2;Success (0) in req_runjob2, return value of svr_startjob is 0
05/04/2018 12:42:39;0100;Server@node2;Req;;Type 11 request received from Scheduler@node2.supernodexp.hpc, sock=16
05/04/2018 12:42:39;0008;Server@node2;Job;15562.node2.supernodexp.hpc;Job Modified at request of Scheduler@node2.supernodexp.hpc
05/04/2018 12:42:39;0040;Server@node2;Svr;node2.supernodexp.hpc;Scheduler sent command 2
05/04/2018 12:42:39;0040;Server@node2;Svr;node2.supernodexp.hpc;Scheduler sent command 0
05/04/2018 12:42:39;0100;Server@node2;Req;;Type 21 request received from Scheduler@node2.supernodexp.hpc, sock=16
05/04/2018 12:42:39;0100;Server@node2;Req;;Type 81 request received from Scheduler@node2.supernodexp.hpc, sock=16
05/04/2018 12:42:39;0100;Server@node2;Req;;Type 71 request received from Scheduler@node2.supernodexp.hpc, sock=16
05/04/2018 12:42:39;0100;Server@node2;Req;;Type 58 request received from Scheduler@node2.supernodexp.hpc, sock=16
05/04/2018 12:42:39;0100;Server@node2;Req;;Type 20 request received from Scheduler@node2.supernodexp.hpc, sock=16
05/04/2018 12:42:39;0100;Server@node2;Req;;Type 51 request received from Scheduler@node2.supernodexp.hpc, sock=16
05/04/2018 12:42:39;0100;Server@node2;Req;;Type 23 request received from Scheduler@node2.supernodexp.hpc, sock=16
05/04/2018 12:42:39;0008;Server@node2;Job;15562.node2.supernodexp.hpc;Job Run at request of Scheduler@node2.supernodexp.hpc on exec_vnode (node13:ncpus=12:mem=20971520kb)
05/04/2018 12:42:39;0001;Server@node2;Svr;Server@node2;Success (0) in req_runjob2, return value of svr_startjob is 0
05/04/2018 12:42:39;0100;Server@node2;Req;;Type 11 request received from Scheduler@node2.supernodexp.hpc, sock=16
05/04/2018 12:42:39;0008;Server@node2;Job;15581.node2.supernodexp.hpc;Job Modified at request of Scheduler@node2.supernodexp.hpc
05/04/2018 12:45:48;0080;Server@node2;Job;15373.node2.supernodexp.hpc;Obit received momhop:1 serverhop:1 state:4 substate:42
05/04/2018 12:45:49;0010;Server@node2;Job;15373.node2.supernodexp.hpc;Exit_status=0 resources_used.cpupercent=0 resources_used.cput=00:00:00 resources_used.mem=9596kb resources_used.ncpus=12 resources_used.vmem=106496kb resources_used.walltime=00:27:41
05/04/2018 12:45:49;0100;Server@node2;Job;15373.node2.supernodexp.hpc;dequeuing from workq, state 5
05/04/2018 12:45:49;0040;Server@node2;Svr;node2.supernodexp.hpc;Scheduler sent command 2
05/04/2018 12:45:49;0040;Server@node2;Svr;node2.supernodexp.hpc;Scheduler sent command 0
05/04/2018 12:45:49;0100;Server@node2;Req;;Type 21 request received from Scheduler@node2.supernodexp.hpc, sock=16
05/04/2018 12:45:49;0100;Server@node2;Req;;Type 81 request received from Scheduler@node2.supernodexp.hpc, sock=16
05/04/2018 12:45:49;0100;Server@node2;Req;;Type 71 request received from Scheduler@node2.supernodexp.hpc, sock=16
05/04/2018 12:45:49;0100;Server@node2;Req;;Type 58 request received from Scheduler@node2.supernodexp.hpc, sock=16
05/04/2018 12:45:49;0100;Server@node2;Req;;Type 20 request received from Scheduler@node2.supernodexp.hpc, sock=16
05/04/2018 12:45:49;0100;Server@node2;Req;;Type 51 request received from Scheduler@node2.supernodexp.hpc, sock=16
05/04/2018 12:45:49;0100;Server@node2;Req;;Type 23 request received from Scheduler@node2.supernodexp.hpc, sock=16
05/04/2018 12:45:49;0008;Server@node2;Job;15581.node2.supernodexp.hpc;Job Run at request of Scheduler@node2.supernodexp.hpc on exec_vnode (node3:ncpus=12:mem=20971520kb)
05/04/2018 12:45:49;0001;Server@node2;Svr;Server@node2;Success (0) in req_runjob2, return value of svr_startjob is 0
05/04/2018 12:45:49;0100;Server@node2;Req;;Type 11 request received from Scheduler@node2.supernodexp.hpc, sock=16
05/04/2018 12:45:49;0008;Server@node2;Job;15583.node2.supernodexp.hpc;Job Modified at request of Scheduler@node2.supernodexp.hpc
05/04/2018 12:50:41;0080;Server@node2;Job;15410.node2.supernodexp.hpc;Obit received momhop:1 serverhop:1 state:4 substate:42
05/04/2018 12:50:42;0010;Server@node2;Job;15410.node2.supernodexp.hpc;Exit_status=0 resources_used.cpupercent=0 resources_used.cput=00:00:00 resources_used.mem=9356kb resources_used.ncpus=12 resources_used.vmem=172288kb resources_used.walltime=00:27:36
05/04/2018 12:50:42;0100;Server@node2;Job;15410.node2.supernodexp.hpc;dequeuing from workq, state 5
05/04/2018 12:50:42;0040;Server@node2;Svr;node2.supernodexp.hpc;Scheduler sent command 2
05/04/2018 12:50:42;0040;Server@node2;Svr;node2.supernodexp.hpc;Scheduler sent command 0
05/04/2018 12:50:42;0100;Server@node2;Req;;Type 21 request received from Scheduler@node2.supernodexp.hpc, sock=16
05/04/2018 12:50:42;0100;Server@node2;Req;;Type 81 request received from Scheduler@node2.supernodexp.hpc, sock=16
05/04/2018 12:50:42;0100;Server@node2;Req;;Type 71 request received from Scheduler@node2.supernodexp.hpc, sock=16
05/04/2018 12:50:42;0100;Server@node2;Req;;Type 58 request received from Scheduler@node2.supernodexp.hpc, sock=16
05/04/2018 12:50:42;0100;Server@node2;Req;;Type 20 request received from Scheduler@node2.supernodexp.hpc, sock=16
05/04/2018 12:50:42;0100;Server@node2;Req;;Type 51 request received from Scheduler@node2.supernodexp.hpc, sock=16
05/04/2018 12:50:42;0100;Server@node2;Req;;Type 23 request received from Scheduler@node2.supernodexp.hpc, sock=16
05/04/2018 12:50:42;0008;Server@node2;Job;15583.node2.supernodexp.hpc;Job Run at request of Scheduler@node2.supernodexp.hpc on exec_vnode (node3:ncpus=12:mem=20971520kb)
05/04/2018 12:50:42;0001;Server@node2;Svr;Server@node2;Success (0) in req_runjob2, return value of svr_startjob is 0
05/04/2018 12:50:42;0100;Server@node2;Req;;Type 11 request received from Scheduler@node2.supernodexp.hpc, sock=16
05/04/2018 12:50:42;0008;Server@node2;Job;15585.node2.supernodexp.hpc;Job Modified at request of Scheduler@node2.supernodexp.hpc
05/04/2018 12:50:47;0080;Server@node2;Job;15468.node2.supernodexp.hpc;Obit received momhop:1 serverhop:1 state:4 substate:42
05/04/2018 12:50:48;0010;Server@node2;Job;15468.node2.supernodexp.hpc;Exit_status=0 resources_used.cpupercent=0 resources_used.cput=00:00:00 resources_used.mem=9340kb resources_used.ncpus=12 resources_used.vmem=104444kb resources_used.walltime=00:27:17
05/04/2018 12:50:48;0100;Server@node2;Job;15468.node2.supernodexp.hpc;dequeuing from workq, state 5
05/04/2018 12:50:48;0040;Server@node2;Svr;node2.supernodexp.hpc;Scheduler sent command 2
05/04/2018 12:50:48;0040;Server@node2;Svr;node2.supernodexp.hpc;Scheduler sent command 0
05/04/2018 12:50:48;0100;Server@node2;Req;;Type 21 request received from Scheduler@node2.supernodexp.hpc, sock=16
05/04/2018 12:50:48;0100;Server@node2;Req;;Type 81 request received from Scheduler@node2.supernodexp.hpc, sock=16
05/04/2018 12:50:48;0100;Server@node2;Req;;Type 71 request received from Scheduler@node2.supernodexp.hpc, sock=16
05/04/2018 12:50:48;0100;Server@node2;Req;;Type 58 request received from Scheduler@node2.supernodexp.hpc, sock=16
05/04/2018 12:50:48;0100;Server@node2;Req;;Type 20 request received from Scheduler@node2.supernodexp.hpc, sock=16
05/04/2018 12:50:48;0100;Server@node2;Req;;Type 51 request received from Scheduler@node2.supernodexp.hpc, sock=16
05/04/2018 12:50:48;0100;Server@node2;Req;;Type 23 request received from Scheduler@node2.supernodexp.hpc, sock=16
05/04/2018 12:50:48;0008;Server@node2;Job;15585.node2.supernodexp.hpc;Job Run at request of Scheduler@node2.supernodexp.hpc on exec_vnode (node3:ncpus=12:mem=20971520kb)
05/04/2018 12:50:48;0001;Server@node2;Svr;Server@node2;Success (0) in req_runjob2, return value of svr_startjob is 0
05/04/2018 12:50:48;0100;Server@node2;Req;;Type 11 request received from Scheduler@node2.supernodexp.hpc, sock=16
05/04/2018 12:50:48;0008;Server@node2;Job;15587.node2.supernodexp.hpc;Job Modified at request of Scheduler@node2.supernodexp.hpc
05/04/2018 12:50:55;0080;Server@node2;Job;15426.node2.supernodexp.hpc;Obit received momhop:1 serverhop:1 state:4 substate:42
05/04/2018 12:50:56;0010;Server@node2;Job;15426.node2.supernodexp.hpc;Exit_status=0 resources_used.cpupercent=0 resources_used.cput=00:00:00 resources_used.mem=9096kb resources_used.ncpus=12 resources_used.vmem=105088kb resources_used.walltime=00:27:33
05/04/2018 12:50:56;0100;Server@node2;Job;15426.node2.supernodexp.hpc;dequeuing from workq, state 5
05/04/2018 12:50:56;0040;Server@node2;Svr;node2.supernodexp.hpc;Scheduler sent command 2
05/04/2018 12:50:56;0040;Server@node2;Svr;node2.supernodexp.hpc;Scheduler sent command 0
05/04/2018 12:50:56;0100;Server@node2;Req;;Type 21 request received from Scheduler@node2.supernodexp.hpc, sock=16
05/04/2018 12:50:56;0100;Server@node2;Req;;Type 81 request received from Scheduler@node2.supernodexp.hpc, sock=16
05/04/2018 12:50:56;0100;Server@node2;Req;;Type 71 request received from Scheduler@node2.supernodexp.hpc, sock=16
05/04/2018 12:50:56;0100;Server@node2;Req;;Type 58 request received from Scheduler@node2.supernodexp.hpc, sock=16
05/04/2018 12:50:56;0100;Server@node2;Req;;Type 20 request received from Scheduler@node2.supernodexp.hpc, sock=16
05/04/2018 12:50:56;0100;Server@node2;Req;;Type 51 request received from Scheduler@node2.supernodexp.hpc, sock=16
05/04/2018 12:50:56;0100;Server@node2;Req;;Type 23 request received from Scheduler@node2.supernodexp.hpc, sock=16
05/04/2018 12:50:56;0008;Server@node2;Job;15587.node2.supernodexp.hpc;Job Run at request of Scheduler@node2.supernodexp.hpc on exec_vnode (node3:ncpus=12:mem=20971520kb)
05/04/2018 12:50:56;0001;Server@node2;Svr;Server@node2;Success (0) in req_runjob2, return value of svr_startjob is 0
05/04/2018 12:50:56;0100;Server@node2;Req;;Type 11 request received from Scheduler@node2.supernodexp.hpc, sock=16
05/04/2018 12:50:56;0008;Server@node2;Job;15589.node2.supernodexp.hpc;Job Modified at request of Scheduler@node2.supernodexp.hpc
05/04/2018 12:54:11;0080;Server@node2;Job;15469.node2.supernodexp.hpc;Obit received momhop:1 serverhop:1 state:4 substate:42
05/04/2018 12:54:12;0010;Server@node2;Job;15469.node2.supernodexp.hpc;Exit_status=271 resources_used.cpupercent=0 resources_used.cput=00:00:00 resources_used.mem=10204kb resources_used.ncpus=12 resources_used.vmem=104628kb resources_used.walltime=00:28:10
05/04/2018 12:54:12;0100;Server@node2;Job;15469.node2.supernodexp.hpc;dequeuing from workq, state 5
05/04/2018 12:54:12;0040;Server@node2;Svr;node2.supernodexp.hpc;Scheduler sent command 2
05/04/2018 12:54:12;0040;Server@node2;Svr;node2.supernodexp.hpc;Scheduler sent command 0
05/04/2018 12:54:12;0100;Server@node2;Req;;Type 21 request received from Scheduler@node2.supernodexp.hpc, sock=16
05/04/2018 12:54:12;0100;Server@node2;Req;;Type 81 request received from Scheduler@node2.supernodexp.hpc, sock=16
05/04/2018 12:54:12;0100;Server@node2;Req;;Type 71 request received from Scheduler@node2.supernodexp.hpc, sock=16
05/04/2018 12:54:12;0100;Server@node2;Req;;Type 58 request received from Scheduler@node2.supernodexp.hpc, sock=16
05/04/2018 12:54:12;0100;Server@node2;Req;;Type 20 request received from Scheduler@node2.supernodexp.hpc, sock=16
05/04/2018 12:54:12;0100;Server@node2;Req;;Type 51 request received from Scheduler@node2.supernodexp.hpc, sock=16
05/04/2018 12:54:12;0100;Server@node2;Req;;Type 23 request received from Scheduler@node2.supernodexp.hpc, sock=16
05/04/2018 12:54:12;0008;Server@node2;Job;15589.node2.supernodexp.hpc;Job Run at request of Scheduler@node2.supernodexp.hpc on exec_vnode (node13:ncpus=12:mem=20971520kb)
05/04/2018 12:54:12;0001;Server@node2;Svr;Server@node2;Success (0) in req_runjob2, return value of svr_startjob is 0
05/04/2018 12:54:12;0100;Server@node2;Req;;Type 11 request received from Scheduler@node2.supernodexp.hpc, sock=16
05/04/2018 12:54:12;0008;Server@node2;Job;15591.node2.supernodexp.hpc;Job Modified at request of Scheduler@node2.supernodexp.hpc
05/04/2018 12:54:28;0080;Server@node2;Job;15510.node2.supernodexp.hpc;Obit received momhop:1 serverhop:1 state:4 substate:42
05/04/2018 12:54:30;0010;Server@node2;Job;15510.node2.supernodexp.hpc;Exit_status=271 resources_used.cpupercent=0 resources_used.cput=00:00:00 resources_used.mem=10244kb resources_used.ncpus=12 resources_used.vmem=172216kb resources_used.walltime=00:27:54
05/04/2018 12:54:30;0100;Server@node2;Job;15510.node2.supernodexp.hpc;dequeuing from workq, state 5
05/04/2018 12:54:30;0040;Server@node2;Svr;node2.supernodexp.hpc;Scheduler sent command 2
05/04/2018 12:54:30;0040;Server@node2;Svr;node2.supernodexp.hpc;Scheduler sent command 0
05/04/2018 12:54:30;0100;Server@node2;Req;;Type 21 request received from Scheduler@node2.supernodexp.hpc, sock=16
05/04/2018 12:54:30;0100;Server@node2;Req;;Type 81 request received from Scheduler@node2.supernodexp.hpc, sock=16
05/04/2018 12:54:30;0100;Server@node2;Req;;Type 71 request received from Scheduler@node2.supernodexp.hpc, sock=16
05/04/2018 12:54:30;0100;Server@node2;Req;;Type 58 request received from Scheduler@node2.supernodexp.hpc, sock=16
05/04/2018 12:54:30;0100;Server@node2;Req;;Type 20 request received from Scheduler@node2.supernodexp.hpc, sock=16
05/04/2018 12:54:30;0100;Server@node2;Req;;Type 51 request received from Scheduler@node2.supernodexp.hpc, sock=16
05/04/2018 12:54:30;0100;Server@node2;Req;;Type 23 request received from Scheduler@node2.supernodexp.hpc, sock=16
05/04/2018 12:54:30;0008;Server@node2;Job;15591.node2.supernodexp.hpc;Job Run at request of Scheduler@node2.supernodexp.hpc on exec_vnode (node14:ncpus=12:mem=20971520kb)
05/04/2018 12:54:30;0001;Server@node2;Svr;Server@node2;Success (0) in req_runjob2, return value of svr_startjob is 0
05/04/2018 12:54:30;0100;Server@node2;Req;;Type 11 request received from Scheduler@node2.supernodexp.hpc, sock=16
05/04/2018 12:54:30;0008;Server@node2;Job;15598.node2.supernodexp.hpc;Job Modified at request of Scheduler@node2.supernodexp.hpc
05/04/2018 13:04:30;0040;Server@node2;Svr;node2.supernodexp.hpc;Scheduler sent command 3
05/04/2018 13:04:30;0040;Server@node2;Svr;node2.supernodexp.hpc;Scheduler sent command 0
05/04/2018 13:04:30;0100;Server@node2;Req;;Type 21 request received from Scheduler@node2.supernodexp.hpc, sock=16
05/04/2018 13:04:30;0100;Server@node2;Req;;Type 81 request received from Scheduler@node2.supernodexp.hpc, sock=16
05/04/2018 13:04:30;0100;Server@node2;Req;;Type 71 request received from Scheduler@node2.supernodexp.hpc, sock=16
05/04/2018 13:04:30;0100;Server@node2;Req;;Type 58 request received from Scheduler@node2.supernodexp.hpc, sock=16
05/04/2018 13:04:30;0100;Server@node2;Req;;Type 20 request received from Scheduler@node2.supernodexp.hpc, sock=16
05/04/2018 13:04:30;0100;Server@node2;Req;;Type 51 request received from Scheduler@node2.supernodexp.hpc, sock=16
05/04/2018 13:09:14;0080;Server@node2;Job;15521.node2.supernodexp.hpc;Obit received momhop:1 serverhop:1 state:4 substate:42
05/04/2018 13:09:14;0080;Server@node2;Job;15524.node2.supernodexp.hpc;Obit received momhop:1 serverhop:1 state:4 substate:42
05/04/2018 13:09:14;0080;Server@node2;Job;15534.node2.supernodexp.hpc;Obit received momhop:1 serverhop:1 state:4 substate:42
05/04/2018 13:09:17;0010;Server@node2;Job;15521.node2.supernodexp.hpc;Exit_status=271 resources_used.cpupercent=0 resources_used.cput=00:00:00 resources_used.mem=10208kb resources_used.ncpus=12 resources_used.vmem=106036kb resources_used.walltime=00:27:53
05/04/2018 13:09:17;0100;Server@node2;Job;15521.node2.supernodexp.hpc;dequeuing from workq, state 5
05/04/2018 13:09:17;0040;Server@node2;Svr;node2.supernodexp.hpc;Scheduler sent command 2
05/04/2018 13:09:17;0040;Server@node2;Svr;node2.supernodexp.hpc;Scheduler sent command 0
05/04/2018 13:09:17;0100;Server@node2;Req;;Type 21 request received from Scheduler@node2.supernodexp.hpc, sock=16
05/04/2018 13:09:17;0100;Server@node2;Req;;Type 81 request received from Scheduler@node2.supernodexp.hpc, sock=16
05/04/2018 13:09:17;0100;Server@node2;Req;;Type 71 request received from Scheduler@node2.supernodexp.hpc, sock=16
05/04/2018 13:09:17;0100;Server@node2;Req;;Type 58 request received from Scheduler@node2.supernodexp.hpc, sock=16
05/04/2018 13:09:17;0010;Server@node2;Job;15524.node2.supernodexp.hpc;Exit_status=271 resources_used.cpupercent=0 resources_used.cput=00:00:00 resources_used.mem=9404kb resources_used.ncpus=12 resources_used.vmem=171960kb resources_used.walltime=00:27:53
05/04/2018 13:09:17;0100;Server@node2;Job;15524.node2.supernodexp.hpc;dequeuing from workq, state 5
05/04/2018 13:09:17;0100;Server@node2;Req;;Type 20 request received from Scheduler@node2.supernodexp.hpc, sock=16
05/04/2018 13:09:17;0100;Server@node2;Req;;Type 51 request received from Scheduler@node2.supernodexp.hpc, sock=16
05/04/2018 13:09:17;0100;Server@node2;Req;;Type 23 request received from Scheduler@node2.supernodexp.hpc, sock=16
05/04/2018 13:09:17;0008;Server@node2;Job;15598.node2.supernodexp.hpc;Job Run at request of Scheduler@node2.supernodexp.hpc on exec_vnode (node14:ncpus=12:mem=20971520kb)
05/04/2018 13:09:17;0001;Server@node2;Svr;Server@node2;Success (0) in req_runjob2, return value of svr_startjob is 0
05/04/2018 13:09:17;0100;Server@node2;Req;;Type 23 request received from Scheduler@node2.supernodexp.hpc, sock=16
05/04/2018 13:09:17;0008;Server@node2;Job;15599.node2.supernodexp.hpc;Job Run at request of Scheduler@node2.supernodexp.hpc on exec_vnode (node14:ncpus=12:mem=20971520kb)
05/04/2018 13:09:17;0001;Server@node2;Svr;Server@node2;Success (0) in req_runjob2, return value of svr_startjob is 0
05/04/2018 13:09:17;0010;Server@node2;Job;15534.node2.supernodexp.hpc;Exit_status=271 resources_used.cpupercent=0 resources_used.cput=00:00:00 resources_used.mem=9632kb resources_used.ncpus=12 resources_used.vmem=172216kb resources_used.walltime=00:27:53
05/04/2018 13:09:17;0100;Server@node2;Job;15534.node2.supernodexp.hpc;dequeuing from workq, state 5
05/04/2018 13:09:17;0100;Server@node2;Req;;Type 11 request received from Scheduler@node2.supernodexp.hpc, sock=16
05/04/2018 13:09:17;0008;Server@node2;Job;15625.node2.supernodexp.hpc;Job Modified at request of Scheduler@node2.supernodexp.hpc
05/04/2018 13:09:17;0040;Server@node2;Svr;node2.supernodexp.hpc;Scheduler sent command 2
05/04/2018 13:09:17;0040;Server@node2;Svr;node2.supernodexp.hpc;Scheduler sent command 0
05/04/2018 13:09:17;0100;Server@node2;Req;;Type 21 request received from Scheduler@node2.supernodexp.hpc, sock=16
05/04/2018 13:09:17;0100;Server@node2;Req;;Type 81 request received from Scheduler@node2.supernodexp.hpc, sock=16
05/04/2018 13:09:17;0100;Server@node2;Req;;Type 71 request received from Scheduler@node2.supernodexp.hpc, sock=16
05/04/2018 13:09:17;0100;Server@node2;Req;;Type 58 request received from Scheduler@node2.supernodexp.hpc, sock=16
05/04/2018 13:09:17;0100;Server@node2;Req;;Type 20 request received from Scheduler@node2.supernodexp.hpc, sock=16
05/04/2018 13:09:17;0100;Server@node2;Req;;Type 51 request received from Scheduler@node2.supernodexp.hpc, sock=16
05/04/2018 13:09:17;0100;Server@node2;Req;;Type 23 request received from Scheduler@node2.supernodexp.hpc, sock=16
05/04/2018 13:09:17;0008;Server@node2;Job;15625.node2.supernodexp.hpc;Job Run at request of Scheduler@node2.supernodexp.hpc on exec_vnode (node14:ncpus=12:mem=20971520kb)
05/04/2018 13:09:17;0001;Server@node2;Svr;Server@node2;Success (0) in req_runjob2, return value of svr_startjob is 0
05/04/2018 13:09:17;0100;Server@node2;Req;;Type 11 request received from Scheduler@node2.supernodexp.hpc, sock=16
05/04/2018 13:09:17;0008;Server@node2;Job;15633.node2.supernodexp.hpc;Job Modified at request of Scheduler@node2.supernodexp.hpc
05/04/2018 13:10:47;0080;Server@node2;Job;15555.node2.supernodexp.hpc;Obit received momhop:1 serverhop:1 state:4 substate:42
05/04/2018 13:10:47;0080;Server@node2;Job;15556.node2.supernodexp.hpc;Obit received momhop:1 serverhop:1 state:4 substate:42
05/04/2018 13:10:47;0080;Server@node2;Job;15562.node2.supernodexp.hpc;Obit received momhop:1 serverhop:1 state:4 substate:42
05/04/2018 13:10:49;0010;Server@node2;Job;15555.node2.supernodexp.hpc;Exit_status=271 resources_used.cpupercent=0 resources_used.cput=00:00:00 resources_used.mem=10212kb resources_used.ncpus=12 resources_used.vmem=104372kb resources_used.walltime=00:28:08
05/04/2018 13:10:49;0100;Server@node2;Job;15555.node2.supernodexp.hpc;dequeuing from workq, state 5
05/04/2018 13:10:49;0040;Server@node2;Svr;node2.supernodexp.hpc;Scheduler sent command 2
05/04/2018 13:10:49;0040;Server@node2;Svr;node2.supernodexp.hpc;Scheduler sent command 0
05/04/2018 13:10:49;0100;Server@node2;Req;;Type 21 request received from Scheduler@node2.supernodexp.hpc, sock=16
05/04/2018 13:10:49;0100;Server@node2;Req;;Type 81 request received from Scheduler@node2.supernodexp.hpc, sock=16
05/04/2018 13:10:49;0100;Server@node2;Req;;Type 71 request received from Scheduler@node2.supernodexp.hpc, sock=16
05/04/2018 13:10:49;0100;Server@node2;Req;;Type 58 request received from Scheduler@node2.supernodexp.hpc, sock=16
05/04/2018 13:10:49;0100;Server@node2;Req;;Type 20 request received from Scheduler@node2.supernodexp.hpc, sock=16
05/04/2018 13:10:49;0100;Server@node2;Req;;Type 51 request received from Scheduler@node2.supernodexp.hpc, sock=16
05/04/2018 13:10:49;0100;Server@node2;Req;;Type 23 request received from Scheduler@node2.supernodexp.hpc, sock=16
05/04/2018 13:10:49;0008;Server@node2;Job;15633.node2.supernodexp.hpc;Job Run at request of Scheduler@node2.supernodexp.hpc on exec_vnode (node13:ncpus=12:mem=20971520kb)
05/04/2018 13:10:50;0001;Server@node2;Svr;Server@node2;Success (0) in req_runjob2, return value of svr_startjob is 0
05/04/2018 13:10:50;0100;Server@node2;Req;;Type 11 request received from Scheduler@node2.supernodexp.hpc, sock=16
05/04/2018 13:10:50;0008;Server@node2;Job;15634.node2.supernodexp.hpc;Job Modified at request of Scheduler@node2.supernodexp.hpc
05/04/2018 13:10:50;0010;Server@node2;Job;15556.node2.supernodexp.hpc;Exit_status=271 resources_used.cpupercent=0 resources_used.cput=00:00:00 resources_used.mem=9624kb resources_used.ncpus=12 resources_used.vmem=1020616kb resources_used.walltime=00:28:08
05/04/2018 13:10:50;0100;Server@node2;Job;15556.node2.supernodexp.hpc;dequeuing from workq, state 5
05/04/2018 13:10:50;0040;Server@node2;Svr;node2.supernodexp.hpc;Scheduler sent command 2
05/04/2018 13:10:50;0040;Server@node2;Svr;node2.supernodexp.hpc;Scheduler sent command 0
05/04/2018 13:10:50;0100;Server@node2;Req;;Type 21 request received from Scheduler@node2.supernodexp.hpc, sock=16
05/04/2018 13:10:50;0100;Server@node2;Req;;Type 81 request received from Scheduler@node2.supernodexp.hpc, sock=16
05/04/2018 13:10:50;0100;Server@node2;Req;;Type 71 request received from Scheduler@node2.supernodexp.hpc, sock=16
05/04/2018 13:10:50;0100;Server@node2;Req;;Type 58 request received from Scheduler@node2.supernodexp.hpc, sock=16
05/04/2018 13:10:50;0100;Server@node2;Req;;Type 20 request received from Scheduler@node2.supernodexp.hpc, sock=16
05/04/2018 13:10:50;0100;Server@node2;Req;;Type 51 request received from Scheduler@node2.supernodexp.hpc, sock=16
05/04/2018 13:10:50;0010;Server@node2;Job;15562.node2.supernodexp.hpc;Exit_status=271 resources_used.cpupercent=0 resources_used.cput=00:00:00 resources_used.mem=9668kb resources_used.ncpus=12 resources_used.vmem=173368kb resources_used.walltime=00:28:08
05/04/2018 13:10:50;0100;Server@node2;Job;15562.node2.supernodexp.hpc;dequeuing from workq, state 5
05/04/2018 13:10:50;0100;Server@node2;Req;;Type 23 request received from Scheduler@node2.supernodexp.hpc, sock=16
05/04/2018 13:10:50;0008;Server@node2;Job;15634.node2.supernodexp.hpc;Job Run at request of Scheduler@node2.supernodexp.hpc on exec_vnode (node13:ncpus=12:mem=20971520kb)
05/04/2018 13:10:50;0001;Server@node2;Svr;Server@node2;Success (0) in req_runjob2, return value of svr_startjob is 0
05/04/2018 13:10:50;0100;Server@node2;Req;;Type 11 request received from Scheduler@node2.supernodexp.hpc, sock=16
05/04/2018 13:10:50;0008;Server@node2;Job;15656.node2.supernodexp.hpc;Job Modified at request of Scheduler@node2.supernodexp.hpc
05/04/2018 13:10:50;0040;Server@node2;Svr;node2.supernodexp.hpc;Scheduler sent command 2
05/04/2018 13:10:50;0040;Server@node2;Svr;node2.supernodexp.hpc;Scheduler sent command 0
05/04/2018 13:10:50;0100;Server@node2;Req;;Type 21 request received from Scheduler@node2.supernodexp.hpc, sock=16
05/04/2018 13:10:50;0100;Server@node2;Req;;Type 81 request received from Scheduler@node2.supernodexp.hpc, sock=16
05/04/2018 13:10:50;0100;Server@node2;Req;;Type 71 request received from Scheduler@node2.supernodexp.hpc, sock=16
05/04/2018 13:10:50;0100;Server@node2;Req;;Type 58 request received from Scheduler@node2.supernodexp.hpc, sock=16
05/04/2018 13:10:50;0100;Server@node2;Req;;Type 20 request received from Scheduler@node2.supernodexp.hpc, sock=16
05/04/2018 13:10:50;0100;Server@node2;Req;;Type 51 request received from Scheduler@node2.supernodexp.hpc, sock=16
05/04/2018 13:10:50;0100;Server@node2;Req;;Type 23 request received from Scheduler@node2.supernodexp.hpc, sock=16
05/04/2018 13:10:50;0008;Server@node2;Job;15656.node2.supernodexp.hpc;Job Run at request of Scheduler@node2.supernodexp.hpc on exec_vnode (node13:ncpus=12:mem=20971520kb)
05/04/2018 13:10:50;0001;Server@node2;Svr;Server@node2;Success (0) in req_runjob2, return value of svr_startjob is 0
05/04/2018 13:10:50;0100;Server@node2;Req;;Type 11 request received from Scheduler@node2.supernodexp.hpc, sock=16
05/04/2018 13:10:50;0008;Server@node2;Job;15686.node2.supernodexp.hpc;Job Modified at request of Scheduler@node2.supernodexp.hpc
05/04/2018 13:13:43;0080;Server@node2;Job;15581.node2.supernodexp.hpc;Obit received momhop:1 serverhop:1 state:4 substate:42
05/04/2018 13:13:44;0010;Server@node2;Job;15581.node2.supernodexp.hpc;Exit_status=0 resources_used.cpupercent=0 resources_used.cput=00:00:00 resources_used.mem=9436kb resources_used.ncpus=12 resources_used.vmem=170624kb resources_used.walltime=00:27:54
05/04/2018 13:13:44;0100;Server@node2;Job;15581.node2.supernodexp.hpc;dequeuing from workq, state 5
05/04/2018 13:13:44;0040;Server@node2;Svr;node2.supernodexp.hpc;Scheduler sent command 2
05/04/2018 13:13:44;0040;Server@node2;Svr;node2.supernodexp.hpc;Scheduler sent command 0
05/04/2018 13:13:44;0100;Server@node2;Req;;Type 21 request received from Scheduler@node2.supernodexp.hpc, sock=16
05/04/2018 13:13:44;0100;Server@node2;Req;;Type 81 request received from Scheduler@node2.supernodexp.hpc, sock=16
05/04/2018 13:13:44;0100;Server@node2;Req;;Type 71 request received from Scheduler@node2.supernodexp.hpc, sock=16
05/04/2018 13:13:44;0100;Server@node2;Req;;Type 58 request received from Scheduler@node2.supernodexp.hpc, sock=16
05/04/2018 13:13:44;0100;Server@node2;Req;;Type 20 request received from Scheduler@node2.supernodexp.hpc, sock=16
05/04/2018 13:13:44;0100;Server@node2;Req;;Type 51 request received from Scheduler@node2.supernodexp.hpc, sock=16
05/04/2018 13:13:44;0100;Server@node2;Req;;Type 23 request received from Scheduler@node2.supernodexp.hpc, sock=16
05/04/2018 13:13:44;0008;Server@node2;Job;15686.node2.supernodexp.hpc;Job Run at request of Scheduler@node2.supernodexp.hpc on exec_vnode (node3:ncpus=12:mem=20971520kb)
05/04/2018 13:13:44;0001;Server@node2;Svr;Server@node2;Success (0) in req_runjob2, return value of svr_startjob is 0
05/04/2018 13:13:44;0100;Server@node2;Req;;Type 11 request received from Scheduler@node2.supernodexp.hpc, sock=16
05/04/2018 13:13:44;0008;Server@node2;Job;15689.node2.supernodexp.hpc;Job Modified at request of Scheduler@node2.supernodexp.hpc
05/04/2018 13:18:20;0080;Server@node2;Job;15587.node2.supernodexp.hpc;Obit received momhop:1 serverhop:1 state:4 substate:42
05/04/2018 13:18:21;0010;Server@node2;Job;15587.node2.supernodexp.hpc;Exit_status=0 resources_used.cpupercent=0 resources_used.cput=00:00:00 resources_used.mem=9344kb resources_used.ncpus=12 resources_used.vmem=104700kb resources_used.walltime=00:27:24
05/04/2018 13:18:21;0100;Server@node2;Job;15587.node2.supernodexp.hpc;dequeuing from workq, state 5
05/04/2018 13:18:21;0040;Server@node2;Svr;node2.supernodexp.hpc;Scheduler sent command 2
05/04/2018 13:18:21;0040;Server@node2;Svr;node2.supernodexp.hpc;Scheduler sent command 0
05/04/2018 13:18:21;0100;Server@node2;Req;;Type 21 request received from Scheduler@node2.supernodexp.hpc, sock=16
05/04/2018 13:18:21;0100;Server@node2;Req;;Type 81 request received from Scheduler@node2.supernodexp.hpc, sock=16
05/04/2018 13:18:21;0100;Server@node2;Req;;Type 71 request received from Scheduler@node2.supernodexp.hpc, sock=16
05/04/2018 13:18:21;0100;Server@node2;Req;;Type 58 request received from Scheduler@node2.supernodexp.hpc, sock=16
05/04/2018 13:18:21;0100;Server@node2;Req;;Type 20 request received from Scheduler@node2.supernodexp.hpc, sock=16
05/04/2018 13:18:21;0100;Server@node2;Req;;Type 51 request received from Scheduler@node2.supernodexp.hpc, sock=16
05/04/2018 13:18:21;0100;Server@node2;Req;;Type 23 request received from Scheduler@node2.supernodexp.hpc, sock=16
05/04/2018 13:18:21;0008;Server@node2;Job;15689.node2.supernodexp.hpc;Job Run at request of Scheduler@node2.supernodexp.hpc on exec_vnode (node3:ncpus=12:mem=20971520kb)
05/04/2018 13:18:21;0001;Server@node2;Svr;Server@node2;Success (0) in req_runjob2, return value of svr_startjob is 0
05/04/2018 13:18:21;0100;Server@node2;Req;;Type 11 request received from Scheduler@node2.supernodexp.hpc, sock=16
05/04/2018 13:18:21;0008;Server@node2;Job;15713.node2.supernodexp.hpc;Job Modified at request of Scheduler@node2.supernodexp.hpc
05/04/2018 13:18:30;0080;Server@node2;Job;15583.node2.supernodexp.hpc;Obit received momhop:1 serverhop:1 state:4 substate:42
05/04/2018 13:18:31;0010;Server@node2;Job;15583.node2.supernodexp.hpc;Exit_status=0 resources_used.cpupercent=0 resources_used.cput=00:00:00 resources_used.mem=9428kb resources_used.ncpus=12 resources_used.vmem=170624kb resources_used.walltime=00:27:48
05/04/2018 13:18:31;0100;Server@node2;Job;15583.node2.supernodexp.hpc;dequeuing from workq, state 5
05/04/2018 13:18:31;0040;Server@node2;Svr;node2.supernodexp.hpc;Scheduler sent command 2
05/04/2018 13:18:31;0040;Server@node2;Svr;node2.supernodexp.hpc;Scheduler sent command 0
05/04/2018 13:18:31;0100;Server@node2;Req;;Type 21 request received from Scheduler@node2.supernodexp.hpc, sock=16
05/04/2018 13:18:31;0100;Server@node2;Req;;Type 81 request received from Scheduler@node2.supernodexp.hpc, sock=16
05/04/2018 13:18:31;0100;Server@node2;Req;;Type 71 request received from Scheduler@node2.supernodexp.hpc, sock=16
05/04/2018 13:18:31;0100;Server@node2;Req;;Type 58 request received from Scheduler@node2.supernodexp.hpc, sock=16
05/04/2018 13:18:31;0100;Server@node2;Req;;Type 20 request received from Scheduler@node2.supernodexp.hpc, sock=16
05/04/2018 13:18:31;0100;Server@node2;Req;;Type 51 request received from Scheduler@node2.supernodexp.hpc, sock=16
05/04/2018 13:18:31;0100;Server@node2;Req;;Type 23 request received from Scheduler@node2.supernodexp.hpc, sock=16
05/04/2018 13:18:31;0008;Server@node2;Job;15713.node2.supernodexp.hpc;Job Run at request of Scheduler@node2.supernodexp.hpc on exec_vnode (node3:ncpus=12:mem=20971520kb)
05/04/2018 13:18:31;0001;Server@node2;Svr;Server@node2;Success (0) in req_runjob2, return value of svr_startjob is 0
05/04/2018 13:18:31;0100;Server@node2;Req;;Type 11 request received from Scheduler@node2.supernodexp.hpc, sock=16
05/04/2018 13:18:31;0008;Server@node2;Job;15726.node2.supernodexp.hpc;Job Modified at request of Scheduler@node2.supernodexp.hpc
05/04/2018 13:18:35;0080;Server@node2;Job;15585.node2.supernodexp.hpc;Obit received momhop:1 serverhop:1 state:4 substate:42
05/04/2018 13:18:36;0010;Server@node2;Job;15585.node2.supernodexp.hpc;Exit_status=271 resources_used.cpupercent=0 resources_used.cput=00:00:00 resources_used.mem=9108kb resources_used.ncpus=12 resources_used.vmem=105088kb resources_used.walltime=00:27:47
05/04/2018 13:18:36;0100;Server@node2;Job;15585.node2.supernodexp.hpc;dequeuing from workq, state 5
05/04/2018 13:18:36;0040;Server@node2;Svr;node2.supernodexp.hpc;Scheduler sent command 2
05/04/2018 13:18:36;0040;Server@node2;Svr;node2.supernodexp.hpc;Scheduler sent command 0
05/04/2018 13:18:36;0100;Server@node2;Req;;Type 21 request received from Scheduler@node2.supernodexp.hpc, sock=16
05/04/2018 13:18:36;0100;Server@node2;Req;;Type 81 request received from Scheduler@node2.supernodexp.hpc, sock=16
05/04/2018 13:18:36;0100;Server@node2;Req;;Type 71 request received from Scheduler@node2.supernodexp.hpc, sock=16
05/04/2018 13:18:36;0100;Server@node2;Req;;Type 58 request received from Scheduler@node2.supernodexp.hpc, sock=16
05/04/2018 13:18:36;0100;Server@node2;Req;;Type 20 request received from Scheduler@node2.supernodexp.hpc, sock=16
05/04/2018 13:18:36;0100;Server@node2;Req;;Type 51 request received from Scheduler@node2.supernodexp.hpc, sock=16
05/04/2018 13:18:36;0100;Server@node2;Req;;Type 23 request received from Scheduler@node2.supernodexp.hpc, sock=16
05/04/2018 13:18:36;0008;Server@node2;Job;15726.node2.supernodexp.hpc;Job Run at request of Scheduler@node2.supernodexp.hpc on exec_vnode (node3:ncpus=12:mem=20971520kb)
05/04/2018 13:18:36;0001;Server@node2;Svr;Server@node2;Success (0) in req_runjob2, return value of svr_startjob is 0
05/04/2018 13:18:36;0100;Server@node2;Req;;Type 11 request received from Scheduler@node2.supernodexp.hpc, sock=16
05/04/2018 13:18:36;0008;Server@node2;Job;15738.node2.supernodexp.hpc;Job Modified at request of Scheduler@node2.supernodexp.hpc
05/04/2018 13:22:23;0080;Server@node2;Job;15589.node2.supernodexp.hpc;Obit received momhop:1 serverhop:1 state:4 substate:42
05/04/2018 13:22:24;0080;Server@node2;Job;15591.node2.supernodexp.hpc;Obit received momhop:1 serverhop:1 state:4 substate:42
05/04/2018 13:22:25;0010;Server@node2;Job;15589.node2.supernodexp.hpc;Exit_status=271 resources_used.cpupercent=0 resources_used.cput=00:00:00 resources_used.mem=12056kb resources_used.ncpus=12 resources_used.vmem=106424kb resources_used.walltime=00:28:10
05/04/2018 13:22:25;0100;Server@node2;Job;15589.node2.supernodexp.hpc;dequeuing from workq, state 5
05/04/2018 13:22:25;0040;Server@node2;Svr;node2.supernodexp.hpc;Scheduler sent command 2
05/04/2018 13:22:25;0040;Server@node2;Svr;node2.supernodexp.hpc;Scheduler sent command 0
05/04/2018 13:22:25;0100;Server@node2;Req;;Type 21 request received from Scheduler@node2.supernodexp.hpc, sock=16
05/04/2018 13:22:25;0100;Server@node2;Req;;Type 81 request received from Scheduler@node2.supernodexp.hpc, sock=16
05/04/2018 13:22:25;0100;Server@node2;Req;;Type 71 request received from Scheduler@node2.supernodexp.hpc, sock=16
05/04/2018 13:22:25;0100;Server@node2;Req;;Type 58 request received from Scheduler@node2.supernodexp.hpc, sock=16
05/04/2018 13:22:25;0100;Server@node2;Req;;Type 20 request received from Scheduler@node2.supernodexp.hpc, sock=16
05/04/2018 13:22:25;0100;Server@node2;Req;;Type 51 request received from Scheduler@node2.supernodexp.hpc, sock=16
05/04/2018 13:22:25;0100;Server@node2;Req;;Type 23 request received from Scheduler@node2.supernodexp.hpc, sock=16
05/04/2018 13:22:25;0008;Server@node2;Job;15738.node2.supernodexp.hpc;Job Run at request of Scheduler@node2.supernodexp.hpc on exec_vnode (node13:ncpus=12:mem=20971520kb)
05/04/2018 13:22:25;0001;Server@node2;Svr;Server@node2;Success (0) in req_runjob2, return value of svr_startjob is 0
05/04/2018 13:22:25;0100;Server@node2;Req;;Type 11 request received from Scheduler@node2.supernodexp.hpc, sock=16
05/04/2018 13:22:25;0008;Server@node2;Job;15740.node2.supernodexp.hpc;Job Modified at request of Scheduler@node2.supernodexp.hpc
05/04/2018 13:22:26;0010;Server@node2;Job;15591.node2.supernodexp.hpc;Exit_status=271 resources_used.cpupercent=0 resources_used.cput=00:00:00 resources_used.mem=10248kb resources_used.ncpus=12 resources_used.vmem=102064kb resources_used.walltime=00:27:54
05/04/2018 13:22:26;0100;Server@node2;Job;15591.node2.supernodexp.hpc;dequeuing from workq, state 5
05/04/2018 13:22:26;0040;Server@node2;Svr;node2.supernodexp.hpc;Scheduler sent command 2
05/04/2018 13:22:26;0040;Server@node2;Svr;node2.supernodexp.hpc;Scheduler sent command 0
05/04/2018 13:22:26;0100;Server@node2;Req;;Type 21 request received from Scheduler@node2.supernodexp.hpc, sock=16
05/04/2018 13:22:26;0100;Server@node2;Req;;Type 81 request received from Scheduler@node2.supernodexp.hpc, sock=16
05/04/2018 13:22:26;0100;Server@node2;Req;;Type 71 request received from Scheduler@node2.supernodexp.hpc, sock=16
05/04/2018 13:22:26;0100;Server@node2;Req;;Type 58 request received from Scheduler@node2.supernodexp.hpc, sock=16
05/04/2018 13:22:26;0100;Server@node2;Req;;Type 20 request received from Scheduler@node2.supernodexp.hpc, sock=16
05/04/2018 13:22:26;0100;Server@node2;Req;;Type 51 request received from Scheduler@node2.supernodexp.hpc, sock=16
05/04/2018 13:22:26;0100;Server@node2;Req;;Type 23 request received from Scheduler@node2.supernodexp.hpc, sock=16
05/04/2018 13:22:26;0008;Server@node2;Job;15740.node2.supernodexp.hpc;Job Run at request of Scheduler@node2.supernodexp.hpc on exec_vnode (node14:ncpus=12:mem=20971520kb)
05/04/2018 13:22:26;0001;Server@node2;Svr;Server@node2;Success (0) in req_runjob2, return value of svr_startjob is 0
05/04/2018 13:22:26;0100;Server@node2;Req;;Type 11 request received from Scheduler@node2.supernodexp.hpc, sock=16
05/04/2018 13:22:26;0008;Server@node2;Job;15777.node2.supernodexp.hpc;Job Modified at request of Scheduler@node2.supernodexp.hpc
05/04/2018 13:32:26;0040;Server@node2;Svr;node2.supernodexp.hpc;Scheduler sent command 3
05/04/2018 13:32:26;0040;Server@node2;Svr;node2.supernodexp.hpc;Scheduler sent command 0
05/04/2018 13:32:26;0100;Server@node2;Req;;Type 21 request received from Scheduler@node2.supernodexp.hpc, sock=16
05/04/2018 13:32:26;0100;Server@node2;Req;;Type 81 request received from Scheduler@node2.supernodexp.hpc, sock=16
05/04/2018 13:32:26;0100;Server@node2;Req;;Type 71 request received from Scheduler@node2.supernodexp.hpc, sock=16
05/04/2018 13:32:26;0100;Server@node2;Req;;Type 58 request received from Scheduler@node2.supernodexp.hpc, sock=16
05/04/2018 13:32:26;0100;Server@node2;Req;;Type 20 request received from Scheduler@node2.supernodexp.hpc, sock=16
05/04/2018 13:32:26;0100;Server@node2;Req;;Type 51 request received from Scheduler@node2.supernodexp.hpc, sock=16
05/04/2018 13:37:11;0080;Server@node2;Job;15598.node2.supernodexp.hpc;Obit received momhop:1 serverhop:1 state:4 substate:42
05/04/2018 13:37:11;0080;Server@node2;Job;15599.node2.supernodexp.hpc;Obit received momhop:1 serverhop:1 state:4 substate:42
05/04/2018 13:37:11;0080;Server@node2;Job;15625.node2.supernodexp.hpc;Obit received momhop:1 serverhop:1 state:4 substate:42
05/04/2018 13:37:13;0010;Server@node2;Job;15599.node2.supernodexp.hpc;Exit_status=271 resources_used.cpupercent=0 resources_used.cput=00:00:00 resources_used.mem=9432kb resources_used.ncpus=12 resources_used.vmem=106680kb resources_used.walltime=00:27:54
05/04/2018 13:37:13;0100;Server@node2;Job;15599.node2.supernodexp.hpc;dequeuing from workq, state 5
05/04/2018 13:37:13;0040;Server@node2;Svr;node2.supernodexp.hpc;Scheduler sent command 2
05/04/2018 13:37:13;0040;Server@node2;Svr;node2.supernodexp.hpc;Scheduler sent command 0
05/04/2018 13:37:13;0100;Server@node2;Req;;Type 21 request received from Scheduler@node2.supernodexp.hpc, sock=16
05/04/2018 13:37:13;0100;Server@node2;Req;;Type 81 request received from Scheduler@node2.supernodexp.hpc, sock=16
05/04/2018 13:37:13;0100;Server@node2;Req;;Type 71 request received from Scheduler@node2.supernodexp.hpc, sock=16
05/04/2018 13:37:13;0100;Server@node2;Req;;Type 58 request received from Scheduler@node2.supernodexp.hpc, sock=16
05/04/2018 13:37:13;0100;Server@node2;Req;;Type 20 request received from Scheduler@node2.supernodexp.hpc, sock=16
05/04/2018 13:37:13;0100;Server@node2;Req;;Type 51 request received from Scheduler@node2.supernodexp.hpc, sock=16
05/04/2018 13:37:13;0100;Server@node2;Req;;Type 23 request received from Scheduler@node2.supernodexp.hpc, sock=16
05/04/2018 13:37:13;0008;Server@node2;Job;15777.node2.supernodexp.hpc;Job Run at request of Scheduler@node2.supernodexp.hpc on exec_vnode (node14:ncpus=12:mem=20971520kb)
05/04/2018 13:37:13;0001;Server@node2;Svr;Server@node2;Success (0) in req_runjob2, return value of svr_startjob is 0
05/04/2018 13:37:13;0100;Server@node2;Req;;Type 11 request received from Scheduler@node2.supernodexp.hpc, sock=16
05/04/2018 13:37:13;0008;Server@node2;Job;15812.node2.supernodexp.hpc;Job Modified at request of Scheduler@node2.supernodexp.hpc
05/04/2018 13:37:13;0010;Server@node2;Job;15598.node2.supernodexp.hpc;Exit_status=271 resources_used.cpupercent=0 resources_used.cput=00:00:00 resources_used.mem=10272kb resources_used.ncpus=12 resources_used.vmem=173368kb resources_used.walltime=00:27:54
05/04/2018 13:37:13;0100;Server@node2;Job;15598.node2.supernodexp.hpc;dequeuing from workq, state 5
05/04/2018 13:37:13;0040;Server@node2;Svr;node2.supernodexp.hpc;Scheduler sent command 2
05/04/2018 13:37:13;0040;Server@node2;Svr;node2.supernodexp.hpc;Scheduler sent command 0
05/04/2018 13:37:13;0100;Server@node2;Req;;Type 21 request received from Scheduler@node2.supernodexp.hpc, sock=16
05/04/2018 13:37:13;0100;Server@node2;Req;;Type 81 request received from Scheduler@node2.supernodexp.hpc, sock=16
05/04/2018 13:37:13;0100;Server@node2;Req;;Type 71 request received from Scheduler@node2.supernodexp.hpc, sock=16
05/04/2018 13:37:13;0100;Server@node2;Req;;Type 58 request received from Scheduler@node2.supernodexp.hpc, sock=16
05/04/2018 13:37:13;0100;Server@node2;Req;;Type 20 request received from Scheduler@node2.supernodexp.hpc, sock=16
05/04/2018 13:37:13;0100;Server@node2;Req;;Type 51 request received from Scheduler@node2.supernodexp.hpc, sock=16
05/04/2018 13:37:13;0010;Server@node2;Job;15625.node2.supernodexp.hpc;Exit_status=271 resources_used.cpupercent=0 resources_used.cput=00:00:00 resources_used.mem=9392kb resources_used.ncpus=12 resources_used.vmem=172216kb resources_used.walltime=00:27:54
05/04/2018 13:37:13;0100;Server@node2;Job;15625.node2.supernodexp.hpc;dequeuing from workq, state 5
05/04/2018 13:37:13;0100;Server@node2;Req;;Type 23 request received from Scheduler@node2.supernodexp.hpc, sock=16
05/04/2018 13:37:13;0008;Server@node2;Job;15812.node2.supernodexp.hpc;Job Run at request of Scheduler@node2.supernodexp.hpc on exec_vnode (node14:ncpus=12:mem=20971520kb)
05/04/2018 13:37:13;0001;Server@node2;Svr;Server@node2;Success (0) in req_runjob2, return value of svr_startjob is 0
05/04/2018 13:37:13;0100;Server@node2;Req;;Type 11 request received from Scheduler@node2.supernodexp.hpc, sock=16
05/04/2018 13:37:13;0008;Server@node2;Job;15836.node2.supernodexp.hpc;Job Modified at request of Scheduler@node2.supernodexp.hpc
05/04/2018 13:37:13;0040;Server@node2;Svr;node2.supernodexp.hpc;Scheduler sent command 2
05/04/2018 13:37:13;0040;Server@node2;Svr;node2.supernodexp.hpc;Scheduler sent command 0
05/04/2018 13:37:13;0100;Server@node2;Req;;Type 21 request received from Scheduler@node2.supernodexp.hpc, sock=16
05/04/2018 13:37:13;0100;Server@node2;Req;;Type 81 request received from Scheduler@node2.supernodexp.hpc, sock=16
05/04/2018 13:37:13;0100;Server@node2;Req;;Type 71 request received from Scheduler@node2.supernodexp.hpc, sock=16
05/04/2018 13:37:13;0100;Server@node2;Req;;Type 58 request received from Scheduler@node2.supernodexp.hpc, sock=16
05/04/2018 13:37:13;0100;Server@node2;Req;;Type 20 request received from Scheduler@node2.supernodexp.hpc, sock=16
05/04/2018 13:37:13;0100;Server@node2;Req;;Type 51 request received from Scheduler@node2.supernodexp.hpc, sock=16
05/04/2018 13:37:13;0100;Server@node2;Req;;Type 23 request received from Scheduler@node2.supernodexp.hpc, sock=16
05/04/2018 13:37:13;0008;Server@node2;Job;15836.node2.supernodexp.hpc;Job Run at request of Scheduler@node2.supernodexp.hpc on exec_vnode (node14:ncpus=12:mem=20971520kb)
05/04/2018 13:37:13;0001;Server@node2;Svr;Server@node2;Success (0) in req_runjob2, return value of svr_startjob is 0
05/04/2018 13:37:13;0100;Server@node2;Req;;Type 11 request received from Scheduler@node2.supernodexp.hpc, sock=16
05/04/2018 13:37:13;0008;Server@node2;Job;15858.node2.supernodexp.hpc;Job Modified at request of Scheduler@node2.supernodexp.hpc
05/04/2018 13:38:55;0080;Server@node2;Job;15633.node2.supernodexp.hpc;Obit received momhop:1 serverhop:1 state:4 substate:42
05/04/2018 13:38:55;0080;Server@node2;Job;15634.node2.supernodexp.hpc;Obit received momhop:1 serverhop:1 state:4 substate:42
05/04/2018 13:38:55;0080;Server@node2;Job;15656.node2.supernodexp.hpc;Obit received momhop:1 serverhop:1 state:4 substate:42
05/04/2018 13:38:59;0010;Server@node2;Job;15633.node2.supernodexp.hpc;Exit_status=271 resources_used.cpupercent=0 resources_used.cput=00:00:00 resources_used.mem=10496kb resources_used.ncpus=12 resources_used.vmem=1213632kb resources_used.walltime=00:28:06
05/04/2018 13:38:59;0100;Server@node2;Job;15633.node2.supernodexp.hpc;dequeuing from workq, state 5
05/04/2018 13:38:59;0040;Server@node2;Svr;node2.supernodexp.hpc;Scheduler sent command 2
05/04/2018 13:38:59;0040;Server@node2;Svr;node2.supernodexp.hpc;Scheduler sent command 0
05/04/2018 13:38:59;0100;Server@node2;Req;;Type 21 request received from Scheduler@node2.supernodexp.hpc, sock=16
05/04/2018 13:38:59;0100;Server@node2;Req;;Type 81 request received from Scheduler@node2.supernodexp.hpc, sock=16
05/04/2018 13:38:59;0100;Server@node2;Req;;Type 71 request received from Scheduler@node2.supernodexp.hpc, sock=16
05/04/2018 13:38:59;0100;Server@node2;Req;;Type 58 request received from Scheduler@node2.supernodexp.hpc, sock=16
05/04/2018 13:38:59;0100;Server@node2;Req;;Type 20 request received from Scheduler@node2.supernodexp.hpc, sock=16
05/04/2018 13:38:59;0100;Server@node2;Req;;Type 51 request received from Scheduler@node2.supernodexp.hpc, sock=16
05/04/2018 13:38:59;0100;Server@node2;Req;;Type 23 request received from Scheduler@node2.supernodexp.hpc, sock=16
05/04/2018 13:38:59;0008;Server@node2;Job;15858.node2.supernodexp.hpc;Job Run at request of Scheduler@node2.supernodexp.hpc on exec_vnode (node13:ncpus=12:mem=20971520kb)
05/04/2018 13:38:59;0001;Server@node2;Svr;Server@node2;Success (0) in req_runjob2, return value of svr_startjob is 0
05/04/2018 13:38:59;0100;Server@node2;Req;;Type 11 request received from Scheduler@node2.supernodexp.hpc, sock=16
05/04/2018 13:38:59;0008;Server@node2;Job;15882.node2.supernodexp.hpc;Job Modified at request of Scheduler@node2.supernodexp.hpc
05/04/2018 13:38:59;0010;Server@node2;Job;15634.node2.supernodexp.hpc;Exit_status=271 resources_used.cpupercent=0 resources_used.cput=00:00:00 resources_used.mem=9412kb resources_used.ncpus=12 resources_used.vmem=104628kb resources_used.walltime=00:28:06
05/04/2018 13:38:59;0100;Server@node2;Job;15634.node2.supernodexp.hpc;dequeuing from workq, state 5
05/04/2018 13:38:59;0040;Server@node2;Svr;node2.supernodexp.hpc;Scheduler sent command 2
05/04/2018 13:38:59;0040;Server@node2;Svr;node2.supernodexp.hpc;Scheduler sent command 0
05/04/2018 13:38:59;0100;Server@node2;Req;;Type 21 request received from Scheduler@node2.supernodexp.hpc, sock=16
05/04/2018 13:38:59;0100;Server@node2;Req;;Type 81 request received from Scheduler@node2.supernodexp.hpc, sock=16
05/04/2018 13:38:59;0100;Server@node2;Req;;Type 71 request received from Scheduler@node2.supernodexp.hpc, sock=16
05/04/2018 13:38:59;0100;Server@node2;Req;;Type 58 request received from Scheduler@node2.supernodexp.hpc, sock=16
05/04/2018 13:38:59;0100;Server@node2;Req;;Type 20 request received from Scheduler@node2.supernodexp.hpc, sock=16
05/04/2018 13:38:59;0100;Server@node2;Req;;Type 51 request received from Scheduler@node2.supernodexp.hpc, sock=16
05/04/2018 13:38:59;0010;Server@node2;Job;15656.node2.supernodexp.hpc;Exit_status=271 resources_used.cpupercent=0 resources_used.cput=00:00:00 resources_used.mem=9628kb resources_used.ncpus=12 resources_used.vmem=949436kb resources_used.walltime=00:28:06
05/04/2018 13:38:59;0100;Server@node2;Job;15656.node2.supernodexp.hpc;dequeuing from workq, state 5
05/04/2018 13:38:59;0100;Server@node2;Req;;Type 23 request received from Scheduler@node2.supernodexp.hpc, sock=16
05/04/2018 13:38:59;0008;Server@node2;Job;15882.node2.supernodexp.hpc;Job Run at request of Scheduler@node2.supernodexp.hpc on exec_vnode (node13:ncpus=12:mem=20971520kb)
05/04/2018 13:38:59;0001;Server@node2;Svr;Server@node2;Success (0) in req_runjob2, return value of svr_startjob is 0
05/04/2018 13:38:59;0100;Server@node2;Req;;Type 11 request received from Scheduler@node2.supernodexp.hpc, sock=16
05/04/2018 13:38:59;0008;Server@node2;Job;15888.node2.supernodexp.hpc;Job Modified at request of Scheduler@node2.supernodexp.hpc
05/04/2018 13:38:59;0040;Server@node2;Svr;node2.supernodexp.hpc;Scheduler sent command 2
05/04/2018 13:38:59;0040;Server@node2;Svr;node2.supernodexp.hpc;Scheduler sent command 0
05/04/2018 13:38:59;0100;Server@node2;Req;;Type 21 request received from Scheduler@node2.supernodexp.hpc, sock=16
05/04/2018 13:38:59;0100;Server@node2;Req;;Type 81 request received from Scheduler@node2.supernodexp.hpc, sock=16
05/04/2018 13:38:59;0100;Server@node2;Req;;Type 71 request received from Scheduler@node2.supernodexp.hpc, sock=16
05/04/2018 13:38:59;0100;Server@node2;Req;;Type 58 request received from Scheduler@node2.supernodexp.hpc, sock=16
05/04/2018 13:38:59;0100;Server@node2;Req;;Type 20 request received from Scheduler@node2.supernodexp.hpc, sock=16
05/04/2018 13:38:59;0100;Server@node2;Req;;Type 51 request received from Scheduler@node2.supernodexp.hpc, sock=16
05/04/2018 13:38:59;0100;Server@node2;Req;;Type 23 request received from Scheduler@node2.supernodexp.hpc, sock=16
05/04/2018 13:38:59;0008;Server@node2;Job;15888.node2.supernodexp.hpc;Job Run at request of Scheduler@node2.supernodexp.hpc on exec_vnode (node13:ncpus=12:mem=20971520kb)
05/04/2018 13:38:59;0001;Server@node2;Svr;Server@node2;Success (0) in req_runjob2, return value of svr_startjob is 0
05/04/2018 13:38:59;0100;Server@node2;Req;;Type 11 request received from Scheduler@node2.supernodexp.hpc, sock=16
05/04/2018 13:38:59;0008;Server@node2;Job;15938.node2.supernodexp.hpc;Job Modified at request of Scheduler@node2.supernodexp.hpc
05/04/2018 13:41:27;0080;Server@node2;Job;15686.node2.supernodexp.hpc;Obit received momhop:1 serverhop:1 state:4 substate:42
05/04/2018 13:41:28;0010;Server@node2;Job;15686.node2.supernodexp.hpc;Exit_status=0 resources_used.cpupercent=0 resources_used.cput=00:00:00 resources_used.mem=11640kb resources_used.ncpus=12 resources_used.vmem=104700kb resources_used.walltime=00:27:43
05/04/2018 13:41:28;0100;Server@node2;Job;15686.node2.supernodexp.hpc;dequeuing from workq, state 5
05/04/2018 13:41:28;0040;Server@node2;Svr;node2.supernodexp.hpc;Scheduler sent command 2
05/04/2018 13:41:28;0040;Server@node2;Svr;node2.supernodexp.hpc;Scheduler sent command 0
05/04/2018 13:41:28;0100;Server@node2;Req;;Type 21 request received from Scheduler@node2.supernodexp.hpc, sock=16
05/04/2018 13:41:28;0100;Server@node2;Req;;Type 81 request received from Scheduler@node2.supernodexp.hpc, sock=16
05/04/2018 13:41:28;0100;Server@node2;Req;;Type 71 request received from Scheduler@node2.supernodexp.hpc, sock=16
05/04/2018 13:41:28;0100;Server@node2;Req;;Type 58 request received from Scheduler@node2.supernodexp.hpc, sock=16
05/04/2018 13:41:28;0100;Server@node2;Req;;Type 20 request received from Scheduler@node2.supernodexp.hpc, sock=16
05/04/2018 13:41:28;0100;Server@node2;Req;;Type 51 request received from Scheduler@node2.supernodexp.hpc, sock=16
05/04/2018 13:41:28;0100;Server@node2;Req;;Type 23 request received from Scheduler@node2.supernodexp.hpc, sock=16
05/04/2018 13:41:28;0008;Server@node2;Job;15938.node2.supernodexp.hpc;Job Run at request of Scheduler@node2.supernodexp.hpc on exec_vnode (node3:ncpus=12:mem=20971520kb)
05/04/2018 13:41:28;0001;Server@node2;Svr;Server@node2;Success (0) in req_runjob2, return value of svr_startjob is 0
05/04/2018 13:41:28;0100;Server@node2;Req;;Type 11 request received from Scheduler@node2.supernodexp.hpc, sock=16
05/04/2018 13:41:28;0008;Server@node2;Job;15950.node2.supernodexp.hpc;Job Modified at request of Scheduler@node2.supernodexp.hpc
05/04/2018 13:45:39;0080;Server@node2;Job;15689.node2.supernodexp.hpc;Obit received momhop:1 serverhop:1 state:4 substate:42
05/04/2018 13:45:40;0010;Server@node2;Job;15689.node2.supernodexp.hpc;Exit_status=0 resources_used.cpupercent=0 resources_used.cput=00:00:00 resources_used.mem=11700kb resources_used.ncpus=12 resources_used.vmem=36856kb resources_used.walltime=00:27:19
05/04/2018 13:45:40;0100;Server@node2;Job;15689.node2.supernodexp.hpc;dequeuing from workq, state 5
05/04/2018 13:45:40;0040;Server@node2;Svr;node2.supernodexp.hpc;Scheduler sent command 2
05/04/2018 13:45:40;0040;Server@node2;Svr;node2.supernodexp.hpc;Scheduler sent command 0
05/04/2018 13:45:40;0100;Server@node2;Req;;Type 21 request received from Scheduler@node2.supernodexp.hpc, sock=16
05/04/2018 13:45:40;0100;Server@node2;Req;;Type 81 request received from Scheduler@node2.supernodexp.hpc, sock=16
05/04/2018 13:45:40;0100;Server@node2;Req;;Type 71 request received from Scheduler@node2.supernodexp.hpc, sock=16
05/04/2018 13:45:40;0100;Server@node2;Req;;Type 58 request received from Scheduler@node2.supernodexp.hpc, sock=16
05/04/2018 13:45:40;0100;Server@node2;Req;;Type 20 request received from Scheduler@node2.supernodexp.hpc, sock=16
05/04/2018 13:45:40;0100;Server@node2;Req;;Type 51 request received from Scheduler@node2.supernodexp.hpc, sock=16
05/04/2018 13:45:40;0100;Server@node2;Req;;Type 23 request received from Scheduler@node2.supernodexp.hpc, sock=16
05/04/2018 13:45:40;0008;Server@node2;Job;15950.node2.supernodexp.hpc;Job Run at request of Scheduler@node2.supernodexp.hpc on exec_vnode (node3:ncpus=12:mem=20971520kb)
05/04/2018 13:45:40;0001;Server@node2;Svr;Server@node2;Success (0) in req_runjob2, return value of svr_startjob is 0
05/04/2018 13:45:40;0100;Server@node2;Req;;Type 11 request received from Scheduler@node2.supernodexp.hpc, sock=16
05/04/2018 13:45:40;0008;Server@node2;Job;15954.node2.supernodexp.hpc;Job Modified at request of Scheduler@node2.supernodexp.hpc
05/04/2018 13:46:02;0080;Server@node2;Job;15726.node2.supernodexp.hpc;Obit received momhop:1 serverhop:1 state:4 substate:42
05/04/2018 13:46:03;0010;Server@node2;Job;15726.node2.supernodexp.hpc;Exit_status=0 resources_used.cpupercent=0 resources_used.cput=00:00:00 resources_used.mem=9092kb resources_used.ncpus=12 resources_used.vmem=104444kb resources_used.walltime=00:27:26
05/04/2018 13:46:03;0100;Server@node2;Job;15726.node2.supernodexp.hpc;dequeuing from workq, state 5
05/04/2018 13:46:03;0040;Server@node2;Svr;node2.supernodexp.hpc;Scheduler sent command 2
05/04/2018 13:46:03;0040;Server@node2;Svr;node2.supernodexp.hpc;Scheduler sent command 0
05/04/2018 13:46:03;0100;Server@node2;Req;;Type 21 request received from Scheduler@node2.supernodexp.hpc, sock=16
05/04/2018 13:46:03;0100;Server@node2;Req;;Type 81 request received from Scheduler@node2.supernodexp.hpc, sock=16
05/04/2018 13:46:03;0100;Server@node2;Req;;Type 71 request received from Scheduler@node2.supernodexp.hpc, sock=16
05/04/2018 13:46:03;0100;Server@node2;Req;;Type 58 request received from Scheduler@node2.supernodexp.hpc, sock=16
05/04/2018 13:46:03;0100;Server@node2;Req;;Type 20 request received from Scheduler@node2.supernodexp.hpc, sock=16
05/04/2018 13:46:03;0100;Server@node2;Req;;Type 51 request received from Scheduler@node2.supernodexp.hpc, sock=16
05/04/2018 13:46:03;0100;Server@node2;Req;;Type 23 request received from Scheduler@node2.supernodexp.hpc, sock=16
05/04/2018 13:46:03;0008;Server@node2;Job;15954.node2.supernodexp.hpc;Job Run at request of Scheduler@node2.supernodexp.hpc on exec_vnode (node3:ncpus=12:mem=20971520kb)
05/04/2018 13:46:03;0001;Server@node2;Svr;Server@node2;Success (0) in req_runjob2, return value of svr_startjob is 0
05/04/2018 13:46:03;0100;Server@node2;Req;;Type 11 request received from Scheduler@node2.supernodexp.hpc, sock=16
05/04/2018 13:46:03;0008;Server@node2;Job;15990.node2.supernodexp.hpc;Job Modified at request of Scheduler@node2.supernodexp.hpc
05/04/2018 13:46:06;0080;Server@node2;Job;15713.node2.supernodexp.hpc;Obit received momhop:1 serverhop:1 state:4 substate:42
05/04/2018 13:46:07;0010;Server@node2;Job;15713.node2.supernodexp.hpc;Exit_status=0 resources_used.cpupercent=0 resources_used.cput=00:00:00 resources_used.mem=9088kb resources_used.ncpus=12 resources_used.vmem=104444kb resources_used.walltime=00:27:35
05/04/2018 13:46:07;0100;Server@node2;Job;15713.node2.supernodexp.hpc;dequeuing from workq, state 5
05/04/2018 13:46:07;0040;Server@node2;Svr;node2.supernodexp.hpc;Scheduler sent command 2
05/04/2018 13:46:07;0040;Server@node2;Svr;node2.supernodexp.hpc;Scheduler sent command 0
05/04/2018 13:46:07;0100;Server@node2;Req;;Type 21 request received from Scheduler@node2.supernodexp.hpc, sock=16
05/04/2018 13:46:07;0100;Server@node2;Req;;Type 81 request received from Scheduler@node2.supernodexp.hpc, sock=16
05/04/2018 13:46:07;0100;Server@node2;Req;;Type 71 request received from Scheduler@node2.supernodexp.hpc, sock=16
05/04/2018 13:46:07;0100;Server@node2;Req;;Type 58 request received from Scheduler@node2.supernodexp.hpc, sock=16
05/04/2018 13:46:07;0100;Server@node2;Req;;Type 20 request received from Scheduler@node2.supernodexp.hpc, sock=16
05/04/2018 13:46:07;0100;Server@node2;Req;;Type 51 request received from Scheduler@node2.supernodexp.hpc, sock=16
05/04/2018 13:46:07;0100;Server@node2;Req;;Type 23 request received from Scheduler@node2.supernodexp.hpc, sock=16
05/04/2018 13:46:07;0008;Server@node2;Job;15990.node2.supernodexp.hpc;Job Run at request of Scheduler@node2.supernodexp.hpc on exec_vnode (node3:ncpus=12:mem=20971520kb)
05/04/2018 13:46:07;0001;Server@node2;Svr;Server@node2;Success (0) in req_runjob2, return value of svr_startjob is 0
05/04/2018 13:46:07;0100;Server@node2;Req;;Type 11 request received from Scheduler@node2.supernodexp.hpc, sock=16
05/04/2018 13:46:07;0008;Server@node2;Job;16009.node2.supernodexp.hpc;Job Modified at request of Scheduler@node2.supernodexp.hpc
05/04/2018 13:50:21;0080;Server@node2;Job;15740.node2.supernodexp.hpc;Obit received momhop:1 serverhop:1 state:4 substate:42
05/04/2018 13:50:23;0010;Server@node2;Job;15740.node2.supernodexp.hpc;Exit_status=271 resources_used.cpupercent=0 resources_used.cput=00:00:00 resources_used.mem=10236kb resources_used.ncpus=12 resources_used.vmem=171316kb resources_used.walltime=00:27:55
05/04/2018 13:50:23;0100;Server@node2;Job;15740.node2.supernodexp.hpc;dequeuing from workq, state 5
05/04/2018 13:50:23;0040;Server@node2;Svr;node2.supernodexp.hpc;Scheduler sent command 2
05/04/2018 13:50:23;0040;Server@node2;Svr;node2.supernodexp.hpc;Scheduler sent command 0
05/04/2018 13:50:23;0100;Server@node2;Req;;Type 21 request received from Scheduler@node2.supernodexp.hpc, sock=16
05/04/2018 13:50:23;0100;Server@node2;Req;;Type 81 request received from Scheduler@node2.supernodexp.hpc, sock=16
05/04/2018 13:50:23;0100;Server@node2;Req;;Type 71 request received from Scheduler@node2.supernodexp.hpc, sock=16
05/04/2018 13:50:23;0100;Server@node2;Req;;Type 58 request received from Scheduler@node2.supernodexp.hpc, sock=16
05/04/2018 13:50:23;0100;Server@node2;Req;;Type 20 request received from Scheduler@node2.supernodexp.hpc, sock=16
05/04/2018 13:50:23;0100;Server@node2;Req;;Type 51 request received from Scheduler@node2.supernodexp.hpc, sock=16
05/04/2018 13:50:23;0100;Server@node2;Req;;Type 23 request received from Scheduler@node2.supernodexp.hpc, sock=16
05/04/2018 13:50:23;0008;Server@node2;Job;16009.node2.supernodexp.hpc;Job Run at request of Scheduler@node2.supernodexp.hpc on exec_vnode (node14:ncpus=12:mem=20971520kb)
05/04/2018 13:50:23;0001;Server@node2;Svr;Server@node2;Success (0) in req_runjob2, return value of svr_startjob is 0
05/04/2018 13:50:23;0100;Server@node2;Req;;Type 11 request received from Scheduler@node2.supernodexp.hpc, sock=16
05/04/2018 13:50:23;0008;Server@node2;Job;16027.node2.supernodexp.hpc;Job Modified at request of Scheduler@node2.supernodexp.hpc
05/04/2018 13:50:31;0080;Server@node2;Job;15738.node2.supernodexp.hpc;Obit received momhop:1 serverhop:1 state:4 substate:42
05/04/2018 13:50:32;0010;Server@node2;Job;15738.node2.supernodexp.hpc;Exit_status=271 resources_used.cpupercent=0 resources_used.cput=00:00:00 resources_used.mem=10708kb resources_used.ncpus=12 resources_used.vmem=942256kb resources_used.walltime=00:28:06
05/04/2018 13:50:32;0100;Server@node2;Job;15738.node2.supernodexp.hpc;dequeuing from workq, state 5
05/04/2018 13:50:32;0040;Server@node2;Svr;node2.supernodexp.hpc;Scheduler sent command 2
